{"mode":"v10-framework-compare","workers":4,"sequenceNumber":1,"symbol":"SOLUSDT","exchangeEventTimeMillis":1784430134951,"localReceivedEpochMillis":1784430134955,"topSpreadTicks":1,"bid5Volume":142072,"ask5Volume":263684,"bid10Volume":712146,"ask10Volume":1089081,"rawPayload":"{\"stream\":\"solusdt@depth@100ms\",\"data\":{\"e\":\"depthUpdate\",\"E\":1784430134951,\"s\":\"SOLUSDT\",\"U\":1609579785,\"u\":1609579788,\"b\":[],\"a\":[[\"76.26000000\",\"39.52600000\"],[\"76.27000000\",\"3.28300000\"]]}}"}
{"mode":"v10-framework-compare","workers":4,"sequenceNumber":2,"symbol":"ETHUSDT","exchangeEventTimeMillis":1784430134951,"localReceivedEpochMillis":1784430134960,"topSpreadTicks":24,"bid5Volume":4389,"ask5Volume":4148,"bid10Volume":10841,"ask10Volume":19421,"rawPayload":"{\"stream\":\"ethusdt@depth@100ms\",\"data\":{\"e\":\"depthUpdate\",\"E\":1784430134951,\"s\":\"ETHUSDT\",\"U\":2806177759,\"u\":2806177768,\"b\":[[\"1870.55000000\",\"0.00000000\"],[\"1863.43000000\",\"0.00000000\"],[\"1863.39000000\",\"0.00000000\"],[\"1863.36000000\",\"0.00000000\"],[\"1863.32000000\",\"0.00000000\"],[\"1863.22000000\",\"7.84820000\"],[\"1862.07000000\",\"0.00000000\"]],\"a\":[[\"1871.21000000\",\"0.00000000\"],[\"1878.23000000\",\"7.21480000\"],[\"1879.85000000\",\"0.00000000\"]]}}"}
{"mode":"v10-framework-compare","workers":4,"sequenceNumber":3,"symbol":"ETHUSDT","exchangeEventTimeMillis":1784430135051,"localReceivedEpochMillis":1784430135041,"topSpreadTicks":24,"bid5Volume":4389,"ask5Volume":4148,"bid10Volume":10841,"ask10Volume":19421,"rawPayload":"{\"stream\":\"ethusdt@depth@100ms\",\"data\":{\"e\":\"depthUpdate\",\"E\":1784430135051,\"s\":\"ETHUSDT\",\"U\":2806177769,\"u\":2806177769,\"b\":[[\"1863.10000000\",\"8.56050000\"]],\"a\":[]}}"}
{"mode":"v10-framework-compare","workers":4,"sequenceNumber":4,"symbol":"SOLUSDT","exchangeEventTimeMillis":1784430135151,"localReceivedEpochMillis":1784430135141,"topSpreadTicks":1,"bid5Volume":148045,"ask5Volume":263684,"bid10Volume":447126,"ask10Volume":1089965,"rawPayload":"{\"stream\":\"solusdt@depth@100ms\",\"data\":{\"e\":\"depthUpdate\",\"E\":1784430135151,\"s\":\"SOLUSDT\",\"U\":1609579789,\"u\":1609579793,\"b\":[[\"76.20000000\",\"39.57900000\"],[\"76.10000000\",\"8.13200000\"],[\"75.90000000\",\"337.38500000\"]],\"a\":[[\"76.34000000\",\"271.70300000\"],[\"76.52000000\",\"0.00000000\"]]}}"}
{"mode":"v10-framework-compare","workers":4,"sequenceNumber":5,"symbol":"ETHUSDT","exchangeEventTimeMillis":1784430135151,"localReceivedEpochMillis":1784430135142,"topSpreadTicks":7,"bid5Volume":4389,"ask5Volume":2895,"bid10Volume":9634,"ask10Volume":17509,"rawPayload":"{\"stream\":\"ethusdt@depth@100ms\",\"data\":{\"e\":\"depthUpdate\",\"E\":1784430135151,\"s\":\"ETHUSDT\",\"U\":2806177770,\"u\":2806177780,\"b\":[[\"1870.47000000\",\"0.00000000\"],[\"1870.41000000\",\"0.02970000\"],[\"1870.33000000\",\"1.33760000\"],[\"1870.20000000\",\"1.47490000\"],[\"1870.14000000\",\"1.63970000\"],[\"1870.06000000\",\"0.78890000\"],[\"1869.87000000\",\"0.00000000\"],[\"1869.66000000\",\"1.18390000\"]],\"a\":[[\"1870.99000000\",\"1.33710000\"],[\"1871.06000000\",\"0.02960000\"]]}}"}
{"mode":"v10-framework-compare","workers":4,"sequenceNumber":6,"symbol":"BNBUSDT","exchangeEventTimeMillis":1784430135151,"localReceivedEpochMillis":1784430135143,"topSpreadTicks":7,"bid5Volume":4937,"ask5Volume":253512,"bid10Volume":19012,"ask10Volume":257901,"rawPayload":"{\"stream\":\"bnbusdt@depth@100ms\",\"data\":{\"e\":\"depthUpdate\",\"E\":1784430135151,\"s\":\"BNBUSDT\",\"U\":1236331295,\"u\":1236331296,\"b\":[],\"a\":[[\"570.66000000\",\"2.26500000\"],[\"570.68000000\",\"0.00000000\"]]}}"}
{"mode":"v10-framework-compare","workers":4,"sequenceNumber":7,"symbol":"BTCUSDT","exchangeEventTimeMillis":1784430135151,"localReceivedEpochMillis":1784430135143,"topSpreadTicks":489,"bid5Volume":129,"ask5Volume":62,"bid10Volume":257,"ask10Volume":291,"rawPayload":"{\"stream\":\"btcusdt@depth@100ms\",\"data\":{\"e\":\"depthUpdate\",\"E\":1784430135151,\"s\":\"BTCUSDT\",\"U\":3244441137,\"u\":3244441156,\"b\":[[\"64805.09000000\",\"0.00000000\"],[\"64804.79000000\",\"0.00000000\"],[\"64801.28000000\",\"0.04000000\"],[\"64800.92000000\",\"0.00000000\"],[\"64799.71000000\",\"0.03247000\"],[\"64799.60000000\",\"0.03087000\"],[\"64794.69000000\",\"0.03861000\"],[\"64790.74000000\",\"0.00000000\"],[\"64786.96000000\",\"0.00401000\"]],\"a\":[[\"64809.66000000\",\"0.00401000\"],[\"64812.66000000\",\"0.00000000\"],[\"64813.43000000\",\"0.00000000\"],[\"64816.46000000\",\"0.00162000\"],[\"64817.89000000\",\"0.03859000\"],[\"64819.17000000\",\"0.03213000\"],[\"64820.02000000\",\"0.04257000\"],[\"64821.66000000\",\"0.00000000\"],[\"64821.99000000\",\"0.00000000\"],[\"64823.72000000\",\"0.00000000\"],[\"64823.80000000\",\"0.00000000\"],[\"64824.56000000\",\"0.00000000\"]]}}"}
{"mode":"v10-framework-compare","workers":4,"sequenceNumber":8,"symbol":"XRPUSDT","exchangeEventTimeMillis":1784430135151,"localReceivedEpochMillis":1784430135144,"topSpreadTicks":1,"bid5Volume":15059000,"ask5Volume":13332100,"bid10Volume":15429200,"ask10Volume":14538600,"rawPayload":"{\"stream\":\"xrpusdt@depth@100ms\",\"data\":{\"e\":\"depthUpdate\",\"E\":1784430135151,\"s\":\"XRPUSDT\",\"U\":752705114,\"u\":752705116,\"b\":[[\"1.09630000\",\"2327.20000000\"],[\"1.09620000\",\"2679.70000000\"],[\"1.09030000\",\"520.90000000\"],[\"1.09020000\",\"0.00000000\"]],\"a\":[]}}"}
{"mode":"v10-framework-compare","workers":4,"sequenceNumber":9,"symbol":"SOLUSDT","exchangeEventTimeMillis":1784430135251,"localReceivedEpochMillis":1784430135241,"topSpreadTicks":1,"bid5Volume":125365,"ask5Volume":263684,"bid10Volume":424446,"ask10Volume":1089965,"rawPayload":"{\"stream\":\"solusdt@depth@100ms\",\"data\":{\"e\":\"depthUpdate\",\"E\":1784430135251,\"s\":\"SOLUSDT\",\"U\":1609579794,\"u\":1609579794,\"b\":[[\"76.21000000\",\"32.56200000\"]],\"a\":[]}}"}
{"mode":"v10-framework-compare","workers":4,"sequenceNumber":10,"symbol":"ETHUSDT","exchangeEventTimeMillis":1784430135251,"localReceivedEpochMillis":1784430135242,"topSpreadTicks":7,"bid5Volume":4389,"ask5Volume":2895,"bid10Volume":9634,"ask10Volume":17509,"rawPayload":"{\"stream\":\"ethusdt@depth@100ms\",\"data\":{\"e\":\"depthUpdate\",\"E\":1784430135251,\"s\":\"ETHUSDT\",\"U\":2806177781,\"u\":2806177783,\"b\":[[\"1870.11000000\",\"0.00000000\"],[\"1869.89000000\",\"2.46910000\"],[\"1863.22000000\",\"0.00000000\"]],\"a\":[]}}"}
{"mode":"v10-framework-compare","workers":4,"sequenceNumber":11,"symbol":"BNBUSDT","exchangeEventTimeMillis":1784430135251,"localReceivedEpochMillis":1784430135242,"topSpreadTicks":7,"bid5Volume":4937,"ask5Volume":253512,"bid10Volume":15184,"ask10Volume":258840,"rawPayload":"{\"stream\":\"bnbusdt@depth@100ms\",\"data\":{\"e\":\"depthUpdate\",\"E\":1784430135251,\"s\":\"BNBUSDT\",\"U\":1236331297,\"u\":1236331304,\"b\":[[\"570.34000000\",\"0.00000000\"],[\"570.32000000\",\"0.92300000\"],[\"570.27000000\",\"0.00000000\"]],\"a\":[[\"570.68000000\",\"0.00000000\"],[\"570.73000000\",\"1.04500000\"],[\"570.74000000\",\"0.00000000\"]]}}"}
{"mode":"v10-framework-compare","workers":4,"sequenceNumber":12,"symbol":"BTCUSDT","exchangeEventTimeMillis":1784430135251,"localReceivedEpochMillis":1784430135242,"topSpreadTicks":489,"bid5Volume":129,"ask5Volume":62,"bid10Volume":257,"ask10Volume":291,"rawPayload":"{\"stream\":\"btcusdt@depth@100ms\",\"data\":{\"e\":\"depthUpdate\",\"E\":1784430135251,\"s\":\"BTCUSDT\",\"U\":3244441157,\"u\":3244441160,\"b\":[[\"64799.60000000\",\"0.00000000\"],[\"64797.84000000\",\"0.03088000\"],[\"64791.64000000\",\"0.00000000\"],[\"64784.26000000\",\"0.04632000\"]],\"a\":[]}}"}
{"mode":"v10-framework-compare","workers":4,"sequenceNumber":13,"symbol":"XRPUSDT","exchangeEventTimeMillis":1784430135251,"localReceivedEpochMillis":1784430135242,"topSpreadTicks":1,"bid5Volume":6558700,"ask5Volume":724500,"bid10Volume":16837900,"ask10Volume":1922400,"rawPayload":"{\"stream\":\"xrpusdt@depth@100ms\",\"data\":{\"e\":\"depthUpdate\",\"E\":1784430135251,\"s\":\"XRPUSDT\",\"U\":752705117,\"u\":752705126,\"b\":[[\"1.09620000\",\"1508.90000000\"],[\"1.09610000\",\"1408.70000000\"]],\"a\":[[\"1.09670000\",\"6259.20000000\"],[\"1.09680000\",\"432.00000000\"],[\"1.09690000\",\"0.00000000\"]]}}"}
{"mode":"v10-framework-compare","workers":4,"sequenceNumber":14,"symbol":"SOLUSDT","exchangeEventTimeMillis":1784430135351,"localReceivedEpochMillis":1784430135341,"topSpreadTicks":1,"bid5Volume":125919,"ask5Volume":227637,"bid10Volume":425000,"ask10Volume":1053918,"rawPayload":"{\"stream\":\"solusdt@depth@100ms\",\"data\":{\"e\":\"depthUpdate\",\"E\":1784430135351,\"s\":\"SOLUSDT\",\"U\":1609579795,\"u\":1609579796,\"b\":[[\"76.20000000\",\"40.13300000\"]],\"a\":[[\"76.24000000\",\"79.83600000\"]]}}"}
{"mode":"v10-framework-compare","workers":4,"sequenceNumber":15,"symbol":"ETHUSDT","exchangeEventTimeMillis":1784430135351,"localReceivedEpochMillis":1784430135342,"topSpreadTicks":7,"bid5Volume":4389,"ask5Volume":4011,"bid10Volume":9710,"ask10Volume":19119,"rawPayload":"{\"stream\":\"ethusdt@depth@100ms\",\"data\":{\"e\":\"depthUpdate\",\"E\":1784430135351,\"s\":\"ETHUSDT\",\"U\":2806177784,\"u\":2806177787,\"b\":[[\"1870.41000000\",\"0.00000000\"],[\"1863.27000000\",\"0.00000000\"],[\"1863.16000000\",\"0.00000000\"]],\"a\":[[\"1871.06000000\",\"0.00000000\"]]}}"}
{"mode":"v10-framework-compare","workers":4,"sequenceNumber":16,"symbol":"BTCUSDT","exchangeEventTimeMillis":1784430135351,"localReceivedEpochMillis":1784430135342,"topSpreadTicks":436,"bid5Volume":129,"ask5Volume":62,"bid10Volume":257,"ask10Volume":291,"rawPayload":"{\"stream\":\"btcusdt@depth@100ms\",\"data\":{\"e\":\"depthUpdate\",\"E\":1784430135351,\"s\":\"BTCUSDT\",\"U\":3244441161,\"u\":3244441164,\"b\":[[\"64786.96000000\",\"0.00000000\"],[\"64784.61000000\",\"0.00401000\"],[\"64778.52000000\",\"0.00000000\"],[\"64774.25000000\",\"0.04260000\"]],\"a\":[[\"64807.31000000\",\"0.00401000\"],[\"64809.66000000\",\"0.00000000\"],[\"64817.67000000\",\"0.04258000\"],[\"64820.02000000\",\"0.00000000\"]]}}"}
{"mode":"v10-framework-compare","workers":4,"sequenceNumber":17,"symbol":"XRPUSDT","exchangeEventTimeMillis":1784430135451,"localReceivedEpochMillis":1784430135442,"topSpreadTicks":0,"bid5Volume":6570200,"ask5Volume":1147900,"bid10Volume":16849400,"ask10Volume":2354400,"rawPayload":"{\"stream\":\"xrpusdt@depth@100ms\",\"data\":{\"e\":\"depthUpdate\",\"E\":1784430135451,\"s\":\"XRPUSDT\",\"U\":752705127,\"u\":752705134,\"b\":[[\"1.09620000\",\"1508.90000000\"],[\"1.09610000\",\"1420.20000000\"]],\"a\":[[\"1.09670000\",\"6255.50000000\"],[\"1.09680000\",\"432.00000000\"]]}}"}
{"mode":"v10-framework-compare","workers":4,"sequenceNumber":18,"symbol":"SOLUSDT","exchangeEventTimeMillis":1784430135551,"localReceivedEpochMillis":1784430135541,"topSpreadTicks":-1,"bid5Volume":125849,"ask5Volume":213124,"bid10Volume":462011,"ask10Volume":1053192,"rawPayload":"{\"stream\":\"solusdt@depth@100ms\",\"data\":{\"e\":\"depthUpdate\",\"E\":1784430135551,\"s\":\"SOLUSDT\",\"U\":1609579797,\"u\":1609579811,\"b\":[[\"76.21000000\",\"18.63100000\"],[\"76.20000000\",\"17.71700000\"],[\"76.19000000\",\"68.44100000\"],[\"76.17000000\",\"96.61900000\"],[\"76.16000000\",\"42.21100000\"]],\"a\":[[\"76.22000000\",\"36.16100000\"],[\"76.23000000\",\"0.00000000\"],[\"76.25000000\",\"75.20900000\"],[\"76.26000000\",\"18.63500000\"]]}}"}
{"mode":"v10-framework-compare","workers":4,"sequenceNumber":19,"symbol":"ETHUSDT","exchangeEventTimeMillis":1784430135551,"localReceivedEpochMillis":1784430135542,"topSpreadTicks":1,"bid5Volume":4389,"ask5Volume":2895,"bid10Volume":9634,"ask10Volume":17509,"rawPayload":"{\"stream\":\"ethusdt@depth@100ms\",\"data\":{\"e\":\"depthUpdate\",\"E\":1784430135551,\"s\":\"ETHUSDT\",\"U\":2806177788,\"u\":2806177790,\"b\":[[\"1870.27000000\",\"0.02980000\"],[\"1862.06000000\",\"9.13660000\"]],\"a\":[[\"1870.93000000\",\"0.02960000\"]]}}"}
{"mode":"v10-framework-compare","workers":4,"sequenceNumber":20,"symbol":"BTCUSDT","exchangeEventTimeMillis":1784430135552,"localReceivedEpochMillis":1784430135542,"topSpreadTicks":436,"bid5Volume":129,"ask5Volume":62,"bid10Volume":257,"ask10Volume":291,"rawPayload":"{\"stream\":\"btcusdt@depth@100ms\",\"data\":{\"e\":\"depthUpdate\",\"E\":1784430135552,\"s\":\"BTCUSDT\",\"U\":3244441165,\"u\":3244441166,\"b\":[],\"a\":[[\"64817.04000000\",\"0.04632000\"],[\"64823.74000000\",\"0.00000000\"]]}}"}
{"mode":"v10-framework-compare","workers":4,"sequenceNumber":21,"symbol":"BNBUSDT","exchangeEventTimeMillis":1784430135552,"localReceivedEpochMillis":1784430135542,"topSpreadTicks":7,"bid5Volume":4937,"ask5Volume":6087,"bid10Volume":15184,"ask10Volume":257166,"rawPayload":"{\"stream\":\"bnbusdt@depth@100ms\",\"data\":{\"e\":\"depthUpdate\",\"E\":1784430135552,\"s\":\"BNBUSDT\",\"U\":1236331305,\"u\":1236331306,\"b\":[],\"a\":[[\"570.64000000\",\"0.68000000\"],[\"570.66000000\",\"1.59500000\"]]}}"}
{"mode":"v10-framework-compare","workers":4,"sequenceNumber":22,"symbol":"XRPUSDT","exchangeEventTimeMillis":1784430135552,"localReceivedEpochMillis":1784430135543,"topSpreadTicks":1,"bid5Volume":7669000,"ask5Volume":724500,"bid10Volume":17948200,"ask10Volume":1922400,"rawPayload":"{\"stream\":\"xrpusdt@depth@100ms\",\"data\":{\"e\":\"depthUpdate\",\"E\":1784430135552,\"s\":\"XRPUSDT\",\"U\":752705135,\"u\":752705142,\"b\":[[\"1.09640000\",\"1347.90000000\"],[\"1.09620000\",\"161.00000000\"],[\"1.09610000\",\"1183.10000000\"],[\"1.09600000\",\"3843.20000000\"],[\"1.09570000\",\"2177.70000000\"],[\"1.09560000\",\"2519.00000000\"]],\"a\":[[\"1.09660000\",\"182.50000000\"],[\"1.09670000\",\"6310.10000000\"],[\"1.09680000\",\"195.00000000\"],[\"1.09710000\",\"4728.90000000\"],[\"1.09720000\",\"0.00000000\"]]}}"}
{"mode":"v10-framework-compare","workers":4,"sequenceNumber":23,"symbol":"SOLUSDT","exchangeEventTimeMillis":1784430135652,"localReceivedEpochMillis":1784430135641,"topSpreadTicks":-1,"bid5Volume":123881,"ask5Volume":246592,"bid10Volume":460077,"ask10Volume":1039269,"rawPayload":"{\"stream\":\"solusdt@depth@100ms\",\"data\":{\"e\":\"depthUpdate\",\"E\":1784430135652,\"s\":\"SOLUSDT\",\"U\":1609579812,\"u\":1609579820,\"b\":[[\"76.20000000\",\"14.30600000\"],[\"76.19000000\",\"69.88400000\"],[\"76.17000000\",\"60.39000000\"],[\"76.16000000\",\"78.44800000\"],[\"76.13000000\",\"0.00000000\"],[\"76.11000000\",\"99.19000000\"]],\"a\":[[\"76.23000000\",\"0.55800000\"],[\"76.24000000\",\"83.24600000\"],[\"76.25000000\",\"71.80000000\"],[\"76.26000000\",\"54.82700000\"],[\"76.28000000\",\"0.00000000\"],[\"76.31000000\",\"183.93300000\"],[\"76.33000000\",\"60.29500000\"]]}}"}
{"mode":"v10-framework-compare","workers":4,"sequenceNumber":24,"symbol":"ETHUSDT","exchangeEventTimeMillis":1784430135652,"localReceivedEpochMillis":1784430135642,"topSpreadTicks":1,"bid5Volume":4389,"ask5Volume":2895,"bid10Volume":9634,"ask10Volume":17509,"rawPayload":"{\"stream\":\"ethusdt@depth@100ms\",\"data\":{\"e\":\"depthUpdate\",\"E\":1784430135652,\"s\":\"ETHUSDT\",\"U\":2806177791,\"u\":2806177798,\"b\":[[\"1870.06000000\",\"0.00000000\"],[\"1869.99000000\",\"0.00000000\"],[\"1869.94000000\",\"0.79960000\"],[\"1863.10000000\",\"8.21450000\"],[\"1862.84000000\",\"0.33440000\"]],\"a\":[[\"1872.14000000\",\"0.48040000\"],[\"1872.40000000\",\"0.00000000\"]]}}"}
{"mode":"v10-framework-compare","workers":4,"sequenceNumber":25,"symbol":"XRPUSDT","exchangeEventTimeMillis":1784430135652,"localReceivedEpochMillis":1784430135643,"topSpreadTicks":0,"bid5Volume":7669000,"ask5Volume":4744800,"bid10Volume":17948200,"ask10Volume":5951300,"rawPayload":"{\"stream\":\"xrpusdt@depth@100ms\",\"data\":{\"e\":\"depthUpdate\",\"E\":1784430135652,\"s\":\"XRPUSDT\",\"U\":752705143,\"u\":752705145,\"b\":[],\"a\":[[\"1.09650000\",\"45.30000000\"],[\"1.09660000\",\"2463.80000000\"],[\"1.09670000\",\"4028.90000000\"]]}}"}
{"mode":"v10-framework-compare","workers":4,"sequenceNumber":26,"symbol":"SOLUSDT","exchangeEventTimeMillis":1784430135752,"localReceivedEpochMillis":1784430135742,"topSpreadTicks":-1,"bid5Volume":124729,"ask5Volume":245798,"bid10Volume":462895,"ask10Volume":1038475,"rawPayload":"{\"stream\":\"solusdt@depth@100ms\",\"data\":{\"e\":\"depthUpdate\",\"E\":1784430135752,\"s\":\"SOLUSDT\",\"U\":1609579821,\"u\":1609579826,\"b\":[[\"76.21000000\",\"33.23100000\"],[\"76.20000000\",\"0.55400000\"],[\"76.16000000\",\"80.41800000\"]],\"a\":[[\"76.25000000\",\"75.84600000\"],[\"76.26000000\",\"49.98700000\"]]}}"}
{"mode":"v10-framework-compare","workers":4,"sequenceNumber":27,"symbol":"ETHUSDT","exchangeEventTimeMillis":1784430135752,"localReceivedEpochMillis":1784430135743,"topSpreadTicks":4,"bid5Volume":5017,"ask5Volume":5407,"bid10Volume":9365,"ask10Volume":10432,"rawPayload":"{\"stream\":\"ethusdt@depth@100ms\",\"data\":{\"e\":\"depthUpdate\",\"E\":1784430135752,\"s\":\"ETHUSDT\",\"U\":2806177799,\"u\":2806177818,\"b\":[[\"1870.92000000\",\"0.00000000\"],[\"1870.73000000\",\"1.06800000\"],[\"1870.61000000\",\"0.00000000\"],[\"1870.50000000\",\"0.00000000\"],[\"1870.45000000\",\"1.09950000\"],[\"1870.33000000\",\"0.00000000\"],[\"1870.25000000\",\"0.13900000\"],[\"1870.20000000\",\"0.00000000\"],[\"1870.13000000\",\"1.44270000\"],[\"1869.95000000\",\"1.47590000\"],[\"1869.15000000\",\"0.00000000\"],[\"1868.75000000\",\"1.60170000\"],[\"1863.13000000\",\"7.25610000\"]],\"a\":[[\"1870.88000000\",\"1.33720000\"],[\"1870.93000000\",\"0.16850000\"],[\"1870.99000000\",\"0.00000000\"],[\"1871.02000000\",\"1.09290000\"],[\"1871.16000000\",\"0.00000000\"],[\"1871.18000000\",\"0.00000000\"],[\"1871.22000000\",\"1.47490000\"],[\"1871.46000000\",\"0.00000000\"],[\"1871.49000000\",\"1.63970000\"],[\"1871.51000000\",\"1.06180000\"],[\"1872.26000000\",\"9.18670000\"],[\"1872.51000000\",\"0.00000000\"],[\"1878.09000000\",\"7.26200000\"],[\"1879.80000000\",\"0.00000000\"]]}}"}
{"mode":"v10-framework-compare","workers":4,"sequenceNumber":28,"symbol":"BTCUSDT","exchangeEventTimeMillis":1784430135752,"localReceivedEpochMillis":1784430135743,"topSpreadTicks":436,"bid5Volume":127,"ask5Volume":62,"bid10Volume":412,"ask10Volume":291,"rawPayload":"{\"stream\":\"btcusdt@depth@100ms\",\"data\":{\"e\":\"depthUpdate\",\"E\":1784430135752,\"s\":\"BTCUSDT\",\"U\":3244441167,\"u\":3244441167,\"b\":[[\"64801.28000000\",\"0.00000000\"]],\"a\":[]}}"}
{"mode":"v10-framework-compare","workers":4,"sequenceNumber":29,"symbol":"SOLUSDT","exchangeEventTimeMillis":1784430135852,"localReceivedEpochMillis":1784430135841,"topSpreadTicks":-1,"bid5Volume":124729,"ask5Volume":245455,"bid10Volume":462895,"ask10Volume":1038132,"rawPayload":"{\"stream\":\"solusdt@depth@100ms\",\"data\":{\"e\":\"depthUpdate\",\"E\":1784430135852,\"s\":\"SOLUSDT\",\"U\":1609579827,\"u\":1609579832,\"b\":[],\"a\":[[\"76.22000000\",\"3.33900000\"],[\"76.23000000\",\"33.37700000\"],[\"76.26000000\",\"49.64700000\"],[\"76.27000000\",\"3.28300000\"]]}}"}
{"mode":"v10-framework-compare","workers":4,"sequenceNumber":30,"symbol":"ETHUSDT","exchangeEventTimeMillis":1784430135852,"localReceivedEpochMillis":1784430135841,"topSpreadTicks":4,"bid5Volume":5017,"ask5Volume":5407,"bid10Volume":9366,"ask10Volume":10432,"rawPayload":"{\"stream\":\"ethusdt@depth@100ms\",\"data\":{\"e\":\"depthUpdate\",\"E\":1784430135852,\"s\":\"ETHUSDT\",\"U\":2806177819,\"u\":2806177824,\"b\":[[\"1870.27000000\",\"1.36740000\"],[\"1870.13000000\",\"0.10500000\"],[\"1870.00000000\",\"0.00000000\"],[\"1869.94000000\",\"0.00000000\"],[\"1863.13000000\",\"0.00000000\"]],\"a\":[]}}"}
{"mode":"v10-framework-compare","workers":4,"sequenceNumber":31,"symbol":"SOLUSDT","exchangeEventTimeMillis":1784430136052,"localReceivedEpochMillis":1784430136041,"topSpreadTicks":-1,"bid5Volume":124729,"ask5Volume":232000,"bid10Volume":462895,"ask10Volume":1039104,"rawPayload":"{\"stream\":\"solusdt@depth@100ms\",\"data\":{\"e\":\"depthUpdate\",\"E\":1784430136052,\"s\":\"SOLUSDT\",\"U\":1609579833,\"u\":1609579834,\"b\":[],\"a\":[[\"76.26000000\",\"36.19200000\"],[\"76.27000000\",\"17.71000000\"]]}}"}
{"mode":"v10-framework-compare","workers":4,"sequenceNumber":32,"symbol":"ETHUSDT","exchangeEventTimeMillis":1784430136052,"localReceivedEpochMillis":1784430136042,"topSpreadTicks":4,"bid5Volume":5017,"ask5Volume":5407,"bid10Volume":9366,"ask10Volume":10432,"rawPayload":"{\"stream\":\"ethusdt@depth@100ms\",\"data\":{\"e\":\"depthUpdate\",\"E\":1784430136052,\"s\":\"ETHUSDT\",\"U\":2806177825,\"u\":2806177827,\"b\":[[\"1862.00000000\",\"9.08060000\"]],\"a\":[[\"1878.06000000\",\"7.15370000\"],[\"1879.73000000\",\"0.00000000\"]]}}"}
{"mode":"v10-framework-compare","workers":4,"sequenceNumber":33,"symbol":"SOLUSDT","exchangeEventTimeMillis":1784430136152,"localReceivedEpochMillis":1784430136142,"topSpreadTicks":-1,"bid5Volume":124789,"ask5Volume":232000,"bid10Volume":438644,"ask10Volume":1039104,"rawPayload":"{\"stream\":\"solusdt@depth@100ms\",\"data\":{\"e\":\"depthUpdate\",\"E\":1784430136152,\"s\":\"SOLUSDT\",\"U\":1609579835,\"u\":1609579839,\"b\":[[\"76.20000000\",\"4.05700000\"],[\"76.19000000\",\"66.44100000\"],[\"76.12000000\",\"65.72500000\"],[\"76.03000000\",\"525.66700000\"]],\"a\":[[\"76.36000000\",\"0.00000000\"]]}}"}
{"mode":"v10-framework-compare","workers":4,"sequenceNumber":34,"symbol":"ETHUSDT","exchangeEventTimeMillis":1784430136152,"localReceivedEpochMillis":1784430136142,"topSpreadTicks":4,"bid5Volume":5017,"ask5Volume":5407,"bid10Volume":9366,"ask10Volume":10432,"rawPayload":"{\"stream\":\"ethusdt@depth@100ms\",\"data\":{\"e\":\"depthUpdate\",\"E\":1784430136152,\"s\":\"ETHUSDT\",\"U\":2806177828,\"u\":2806177828,\"b\":[[\"1870.09000000\",\"0.80310000\"]],\"a\":[]}}"}
{"mode":"v10-framework-compare","workers":4,"sequenceNumber":35,"symbol":"ETHUSDT","exchangeEventTimeMillis":1784430136252,"localReceivedEpochMillis":1784430136241,"topSpreadTicks":4,"bid5Volume":5017,"ask5Volume":5407,"bid10Volume":9366,"ask10Volume":10432,"rawPayload":"{\"stream\":\"ethusdt@depth@100ms\",\"data\":{\"e\":\"depthUpdate\",\"E\":1784430136252,\"s\":\"ETHUSDT\",\"U\":2806177829,\"u\":2806177829,\"b\":[[\"1861.95000000\",\"9.10800000\"]],\"a\":[]}}"}
{"mode":"v10-framework-compare","workers":4,"sequenceNumber":36,"symbol":"ETHUSDT","exchangeEventTimeMillis":1784430136352,"localReceivedEpochMillis":1784430136342,"topSpreadTicks":-7,"bid5Volume":5017,"ask5Volume":4071,"bid10Volume":9366,"ask10Volume":9371,"rawPayload":"{\"stream\":\"ethusdt@depth@100ms\",\"data\":{\"e\":\"depthUpdate\",\"E\":1784430136352,\"s\":\"ETHUSDT\",\"U\":2806177830,\"u\":2806177836,\"b\":[[\"1870.25000000\",\"0.00000000\"],[\"1870.10000000\",\"0.13900000\"],[\"1869.95000000\",\"0.00000000\"],[\"1869.80000000\",\"1.47600000\"],[\"1868.99000000\",\"0.00000000\"],[\"1868.76000000\",\"9.20390000\"],[\"1861.90000000\",\"9.19830000\"]],\"a\":[[\"1870.77000000\",\"0.13890000\"],[\"1870.93000000\",\"0.02960000\"],[\"1871.07000000\",\"1.47500000\"],[\"1871.22000000\",\"0.00000000\"],[\"1872.11000000\",\"9.18740000\"],[\"1872.26000000\",\"0.00000000\"]]}}"}
{"mode":"v10-framework-compare","workers":4,"sequenceNumber":37,"symbol":"BTCUSDT","exchangeEventTimeMillis":1784430136452,"localReceivedEpochMillis":1784430136473,"topSpreadTicks":436,"bid5Volume":167,"ask5Volume":62,"bid10Volume":452,"ask10Volume":291,"rawPayload":"{\"stream\":\"btcusdt@depth@100ms\",\"data\":{\"e\":\"depthUpdate\",\"E\":1784430136452,\"s\":\"BTCUSDT\",\"U\":3244441168,\"u\":3244441168,\"b\":[[\"64799.71000000\",\"0.07247000\"]],\"a\":[]}}"}
{"mode":"v10-framework-compare","workers":4,"sequenceNumber":38,"symbol":"SOLUSDT","exchangeEventTimeMillis":1784430136552,"localReceivedEpochMillis":1784430136543,"topSpreadTicks":-1,"bid5Volume":124789,"ask5Volume":249707,"bid10Volume":438644,"ask10Volume":1039094,"rawPayload":"{\"stream\":\"solusdt@depth@100ms\",\"data\":{\"e\":\"depthUpdate\",\"E\":1784430136552,\"s\":\"SOLUSDT\",\"U\":1609579840,\"u\":1609579841,\"b\":[],\"a\":[[\"76.26000000\",\"0.00000000\"],[\"76.27000000\",\"53.89900000\"],[\"76.31000000\",\"84.99300000\"],[\"76.32000000\",\"98.93300000\"]]}}"}
{"mode":"v10-framework-compare","workers":4,"sequenceNumber":39,"symbol":"ETHUSDT","exchangeEventTimeMillis":1784430136552,"localReceivedEpochMillis":1784430136543,"topSpreadTicks":-7,"bid5Volume":5017,"ask5Volume":4071,"bid10Volume":9366,"ask10Volume":9371,"rawPayload":"{\"stream\":\"ethusdt@depth@100ms\",\"data\":{\"e\":\"depthUpdate\",\"E\":1784430136552,\"s\":\"ETHUSDT\",\"U\":2806177837,\"u\":2806177837,\"b\":[[\"1861.84000000\",\"9.17040000\"]],\"a\":[]}}"}
{"mode":"v10-framework-compare","workers":4,"sequenceNumber":40,"symbol":"ETHUSDT","exchangeEventTimeMillis":1784430136752,"localReceivedEpochMillis":1784430136741,"topSpreadTicks":-7,"bid5Volume":5017,"ask5Volume":4071,"bid10Volume":9366,"ask10Volume":9371,"rawPayload":"{\"stream\":\"ethusdt@depth@100ms\",\"data\":{\"e\":\"depthUpdate\",\"E\":1784430136752,\"s\":\"ETHUSDT\",\"U\":2806177838,\"u\":2806177838,\"b\":[[\"1861.78000000\",\"9.32600000\"]],\"a\":[]}}"}
{"mode":"v10-framework-compare","workers":4,"sequenceNumber":41,"symbol":"XRPUSDT","exchangeEventTimeMillis":1784430136952,"localReceivedEpochMillis":1784430136942,"topSpreadTicks":1,"bid5Volume":15059000,"ask5Volume":25931800,"bid10Volume":15429200,"ask10Volume":27138300,"rawPayload":"{\"stream\":\"xrpusdt@depth@100ms\",\"data\":{\"e\":\"depthUpdate\",\"E\":1784430136952,\"s\":\"XRPUSDT\",\"U\":752705146,\"u\":752705149,\"b\":[[\"1.09450000\",\"2569.70000000\"],[\"1.09440000\",\"16025.70000000\"],[\"1.09250000\",\"25164.80000000\"],[\"1.09240000\",\"0.00000000\"]],\"a\":[[\"1.09910000\",\"12837.30000000\"],[\"1.09920000\",\"16925.70000000\"],[\"1.10040000\",\"0.00000000\"],[\"1.10050000\",\"8699.40000000\"]]}}"}
{"mode":"v10-framework-compare","workers":4,"sequenceNumber":42,"symbol":"BTCUSDT","exchangeEventTimeMillis":1784430137052,"localReceivedEpochMillis":1784430137042,"topSpreadTicks":436,"bid5Volume":167,"ask5Volume":62,"bid10Volume":452,"ask10Volume":291,"rawPayload":"{\"stream\":\"btcusdt@depth@100ms\",\"data\":{\"e\":\"depthUpdate\",\"E\":1784430137052,\"s\":\"BTCUSDT\",\"U\":3244441169,\"u\":3244441170,\"b\":[],\"a\":[[\"64833.09000000\",\"0.06176000\"],[\"64846.23000000\",\"0.00000000\"]]}}"}
{"mode":"v10-framework-compare","workers":4,"sequenceNumber":43,"symbol":"SOLUSDT","exchangeEventTimeMillis":1784430137153,"localReceivedEpochMillis":1784430137170,"topSpreadTicks":-1,"bid5Volume":124857,"ask5Volume":249707,"bid10Volume":438712,"ask10Volume":1039094,"rawPayload":"{\"stream\":\"solusdt@depth@100ms\",\"data\":{\"e\":\"depthUpdate\",\"E\":1784430137153,\"s\":\"SOLUSDT\",\"U\":1609579842,\"u\":1609579843,\"b\":[[\"76.20000000\",\"0.55400000\"],[\"76.19000000\",\"70.01200000\"]],\"a\":[]}}"}
{"mode":"v10-framework-compare","workers":4,"sequenceNumber":44,"symbol":"SOLUSDT","exchangeEventTimeMillis":1784430137253,"localReceivedEpochMillis":1784430137263,"topSpreadTicks":-1,"bid5Volume":124857,"ask5Volume":235280,"bid10Volume":438712,"ask10Volume":1024667,"rawPayload":"{\"stream\":\"solusdt@depth@100ms\",\"data\":{\"e\":\"depthUpdate\",\"E\":1784430137253,\"s\":\"SOLUSDT\",\"U\":1609579844,\"u\":1609579846,\"b\":[],\"a\":[[\"76.26000000\",\"0.00000000\"],[\"76.27000000\",\"39.47200000\"]]}}"}
{"mode":"v10-framework-compare","workers":4,"sequenceNumber":45,"symbol":"SOLUSDT","exchangeEventTimeMillis":1784430137353,"localReceivedEpochMillis":1784430137342,"topSpreadTicks":-1,"bid5Volume":124857,"ask5Volume":248708,"bid10Volume":438712,"ask10Volume":1038095,"rawPayload":"{\"stream\":\"solusdt@depth@100ms\",\"data\":{\"e\":\"depthUpdate\",\"E\":1784430137353,\"s\":\"SOLUSDT\",\"U\":1609579847,\"u\":1609579847,\"b\":[],\"a\":[[\"76.27000000\",\"52.90000000\"]]}}"}
{"mode":"v10-framework-compare","workers":4,"sequenceNumber":46,"symbol":"BTCUSDT","exchangeEventTimeMillis":1784430137453,"localReceivedEpochMillis":1784430137488,"topSpreadTicks":436,"bid5Volume":129,"ask5Volume":62,"bid10Volume":257,"ask10Volume":291,"rawPayload":"{\"stream\":\"btcusdt@depth@100ms\",\"data\":{\"e\":\"depthUpdate\",\"E\":1784430137453,\"s\":\"BTCUSDT\",\"U\":3244441171,\"u\":3244441172,\"b\":[[\"64799.72000000\",\"0.04000000\"],[\"64799.71000000\",\"0.03247000\"]],\"a\":[]}}"}
{"mode":"v10-framework-compare","workers":4,"sequenceNumber":47,"symbol":"SOLUSDT","exchangeEventTimeMillis":1784430137553,"localReceivedEpochMillis":1784430137541,"topSpreadTicks":-1,"bid5Volume":124857,"ask5Volume":248708,"bid10Volume":438712,"ask10Volume":1038095,"rawPayload":"{\"stream\":\"solusdt@depth@100ms\",\"data\":{\"e\":\"depthUpdate\",\"E\":1784430137553,\"s\":\"SOLUSDT\",\"U\":1609579848,\"u\":1609579848,\"b\":[],\"a\":[[\"76.24000000\",\"101.88100000\"],[\"76.25000000\",\"57.21100000\"]]}}"}
{"mode":"v10-framework-compare","workers":4,"sequenceNumber":48,"symbol":"SOLUSDT","exchangeEventTimeMillis":1784430137653,"localReceivedEpochMillis":1784430137642,"topSpreadTicks":-1,"bid5Volume":124857,"ask5Volume":209453,"bid10Volume":438712,"ask10Volume":764849,"rawPayload":"{\"stream\":\"solusdt@depth@100ms\",\"data\":{\"e\":\"depthUpdate\",\"E\":1784430137653,\"s\":\"SOLUSDT\",\"U\":1609579849,\"u\":1609579850,\"b\":[],\"a\":[[\"76.26000000\",\"13.64500000\"],[\"76.27000000\",\"39.47200000\"]]}}"}
{"mode":"v10-framework-compare","workers":4,"sequenceNumber":49,"symbol":"BTCUSDT","exchangeEventTimeMillis":1784430137753,"localReceivedEpochMillis":1784430137764,"topSpreadTicks":436,"bid5Volume":129,"ask5Volume":62,"bid10Volume":257,"ask10Volume":291,"rawPayload":"{\"stream\":\"btcusdt@depth@100ms\",\"data\":{\"e\":\"depthUpdate\",\"E\":1784430137753,\"s\":\"BTCUSDT\",\"U\":3244441173,\"u\":3244441173,\"b\":[],\"a\":[[\"81055.16000000\",\"0.00030000\"]]}}"}
{"mode":"v10-framework-compare","workers":4,"sequenceNumber":50,"symbol":"SOLUSDT","exchangeEventTimeMillis":1784430137853,"localReceivedEpochMillis":1784430137908,"topSpreadTicks":-1,"bid5Volume":124857,"ask5Volume":210000,"bid10Volume":438712,"ask10Volume":765396,"rawPayload":"{\"stream\":\"solusdt@depth@100ms\",\"data\":{\"e\":\"depthUpdate\",\"E\":1784430137853,\"s\":\"SOLUSDT\",\"U\":1609579851,\"u\":1609579854,\"b\":[],\"a\":[[\"76.26000000\",\"14.19200000\"],[\"76.27000000\",\"39.47200000\"]]}}"}
{"mode":"v10-framework-compare","workers":4,"sequenceNumber":51,"symbol":"BTCUSDT","exchangeEventTimeMillis":1784430137853,"localReceivedEpochMillis":1784430137909,"topSpreadTicks":436,"bid5Volume":129,"ask5Volume":62,"bid10Volume":257,"ask10Volume":291,"rawPayload":"{\"stream\":\"btcusdt@depth@100ms\",\"data\":{\"e\":\"depthUpdate\",\"E\":1784430137853,\"s\":\"BTCUSDT\",\"U\":3244441174,\"u\":3244441175,\"b\":[[\"64797.84000000\",\"0.00000000\"],[\"64795.42000000\",\"0.03088000\"]],\"a\":[]}}"}
{"mode":"v10-framework-compare","workers":4,"sequenceNumber":52,"symbol":"ETHUSDT","exchangeEventTimeMillis":1784430138153,"localReceivedEpochMillis":1784430138174,"topSpreadTicks":-8,"bid5Volume":5017,"ask5Volume":4141,"bid10Volume":9362,"ask10Volume":9441,"rawPayload":"{\"stream\":\"ethusdt@depth@100ms\",\"data\":{\"e\":\"depthUpdate\",\"E\":1784430138153,\"s\":\"ETHUSDT\",\"U\":2806177839,\"u\":2806177846,\"b\":[[\"1870.45000000\",\"0.00000000\"],[\"1870.40000000\",\"1.09570000\"],[\"1870.09000000\",\"0.00000000\"],[\"1870.04000000\",\"0.84740000\"]],\"a\":[[\"1870.76000000\",\"1.33720000\"],[\"1870.88000000\",\"0.00000000\"],[\"1870.97000000\",\"1.16230000\"],[\"1871.02000000\",\"0.00000000\"]]}}"}
{"mode":"v10-framework-compare","workers":4,"sequenceNumber":53,"symbol":"XRPUSDT","exchangeEventTimeMillis":1784430138153,"localReceivedEpochMillis":1784430138175,"topSpreadTicks":0,"bid5Volume":5332500,"ask5Volume":10005900,"bid10Volume":15611700,"ask10Volume":11212400,"rawPayload":"{\"stream\":\"xrpusdt@depth@100ms\",\"data\":{\"e\":\"depthUpdate\",\"E\":1784430138153,\"s\":\"XRPUSDT\",\"U\":752705150,\"u\":752705153,\"b\":[[\"1.09620000\",\"1169.10000000\"],[\"1.09610000\",\"182.50000000\"]],\"a\":[[\"1.09670000\",\"3093.30000000\"],[\"1.09690000\",\"999.80000000\"]]}}"}
{"mode":"v10-framework-compare","workers":4,"sequenceNumber":54,"symbol":"BTCUSDT","exchangeEventTimeMillis":1784430138253,"localReceivedEpochMillis":1784430138266,"topSpreadTicks":436,"bid5Volume":129,"ask5Volume":107,"bid10Volume":257,"ask10Volume":291,"rawPayload":"{\"stream\":\"btcusdt@depth@100ms\",\"data\":{\"e\":\"depthUpdate\",\"E\":1784430138253,\"s\":\"BTCUSDT\",\"U\":3244441176,\"u\":3244441178,\"b\":[],\"a\":[[\"64816.46000000\",\"0.00000000\"],[\"64817.66000000\",\"0.00166000\"],[\"64914.49000000\",\"0.00000000\"]]}}"}
{"mode":"v10-framework-compare","workers":4,"sequenceNumber":55,"symbol":"BTCUSDT","exchangeEventTimeMillis":1784430138353,"localReceivedEpochMillis":1784430138368,"topSpreadTicks":436,"bid5Volume":129,"ask5Volume":107,"bid10Volume":257,"ask10Volume":291,"rawPayload":"{\"stream\":\"btcusdt@depth@100ms\",\"data\":{\"e\":\"depthUpdate\",\"E\":1784430138353,\"s\":\"BTCUSDT\",\"U\":3244441179,\"u\":3244441179,\"b\":[],\"a\":[[\"64914.49000000\",\"0.00011000\"]]}}"}
{"mode":"v10-framework-compare","workers":4,"sequenceNumber":56,"symbol":"BTCUSDT","exchangeEventTimeMillis":1784430138453,"localReceivedEpochMillis":1784430138523,"topSpreadTicks":375,"bid5Volume":127,"ask5Volume":107,"bid10Volume":412,"ask10Volume":291,"rawPayload":"{\"stream\":\"btcusdt@depth@100ms\",\"data\":{\"e\":\"depthUpdate\",\"E\":1784430138453,\"s\":\"BTCUSDT\",\"U\":3244441180,\"u\":3244441181,\"b\":[[\"64799.72000000\",\"0.00000000\"]],\"a\":[[\"64806.70000000\",\"0.00401000\"],[\"64807.31000000\",\"0.00000000\"]]}}"}
{"mode":"v10-framework-compare","workers":4,"sequenceNumber":57,"symbol":"BTCUSDT","exchangeEventTimeMillis":1784430138654,"localReceivedEpochMillis":1784430138727,"topSpreadTicks":374,"bid5Volume":127,"ask5Volume":111,"bid10Volume":412,"ask10Volume":295,"rawPayload":"{\"stream\":\"btcusdt@depth@100ms\",\"data\":{\"e\":\"depthUpdate\",\"E\":1784430138654,\"s\":\"BTCUSDT\",\"U\":3244441182,\"u\":3244441183,\"b\":[],\"a\":[[\"64806.69000000\",\"0.03088000\"],[\"64808.63000000\",\"0.00000000\"]]}}"}
{"mode":"v10-framework-compare","workers":4,"sequenceNumber":58,"symbol":"SOLUSDT","exchangeEventTimeMillis":1784430139054,"localReceivedEpochMillis":1784430139137,"topSpreadTicks":-1,"bid5Volume":124857,"ask5Volume":210000,"bid10Volume":449439,"ask10Volume":765396,"rawPayload":"{\"stream\":\"solusdt@depth@100ms\",\"data\":{\"e\":\"depthUpdate\",\"E\":1784430139054,\"s\":\"SOLUSDT\",\"U\":1609579855,\"u\":1609579860,\"b\":[[\"76.13000000\",\"18.85900000\"],[\"76.10000000\",\"14.90100000\"],[\"76.08000000\",\"320.16000000\"],[\"76.07000000\",\"383.35800000\"],[\"76.03000000\",\"584.30000000\"]],\"a\":[[\"76.31000000\",\"65.56900000\"],[\"76.32000000\",\"118.35700000\"],[\"76.40000000\",\"0.10000000\"],[\"76.41000000\",\"327.88200000\"]]}}"}
{"mode":"v10-framework-compare","workers":4,"sequenceNumber":59,"symbol":"ETHUSDT","exchangeEventTimeMillis":1784430139154,"localReceivedEpochMillis":1784430139143,"topSpreadTicks":-8,"bid5Volume":5044,"ask5Volume":4141,"bid10Volume":9383,"ask10Volume":8863,"rawPayload":"{\"stream\":\"ethusdt@depth@100ms\",\"data\":{\"e\":\"depthUpdate\",\"E\":1784430139154,\"s\":\"ETHUSDT\",\"U\":2806177847,\"u\":2806177848,\"b\":[[\"1870.73000000\",\"0.00000000\"]],\"a\":[[\"1871.33000000\",\"1.06180000\"],[\"1871.51000000\",\"0.00000000\"]]}}"}
{"mode":"v10-framework-compare","workers":4,"sequenceNumber":60,"symbol":"BNBUSDT","exchangeEventTimeMillis":1784430139154,"localReceivedEpochMillis":1784430139143,"topSpreadTicks":7,"bid5Volume":4937,"ask5Volume":6087,"bid10Volume":15184,"ask10Volume":257166,"rawPayload":"{\"stream\":\"bnbusdt@depth@100ms\",\"data\":{\"e\":\"depthUpdate\",\"E\":1784430139154,\"s\":\"BNBUSDT\",\"U\":1236331307,\"u\":1236331308,\"b\":[],\"a\":[[\"570.81000000\",\"1.50200000\"],[\"570.87000000\",\"0.00000000\"]]}}"}
{"mode":"v10-framework-compare","workers":4,"sequenceNumber":61,"symbol":"XRPUSDT","exchangeEventTimeMillis":1784430139154,"localReceivedEpochMillis":1784430139143,"topSpreadTicks":0,"bid5Volume":5332500,"ask5Volume":12281900,"bid10Volume":15611700,"ask10Volume":13488400,"rawPayload":"{\"stream\":\"xrpusdt@depth@100ms\",\"data\":{\"e\":\"depthUpdate\",\"E\":1784430139154,\"s\":\"XRPUSDT\",\"U\":752705154,\"u\":752705155,\"b\":[],\"a\":[[\"1.09660000\",\"2281.30000000\"],[\"1.09670000\",\"3275.80000000\"]]}}"}
{"mode":"v10-framework-compare","workers":4,"sequenceNumber":62,"symbol":"SOLUSDT","exchangeEventTimeMillis":1784430140155,"localReceivedEpochMillis":1784430140144,"topSpreadTicks":-1,"bid5Volume":124857,"ask5Volume":249147,"bid10Volume":449439,"ask10Volume":1038534,"rawPayload":"{\"stream\":\"solusdt@depth@100ms\",\"data\":{\"e\":\"depthUpdate\",\"E\":1784430140155,\"s\":\"SOLUSDT\",\"U\":1609579861,\"u\":1609579862,\"b\":[],\"a\":[[\"76.26000000\",\"0.00000000\"],[\"76.27000000\",\"53.33900000\"]]}}"}
{"mode":"v10-framework-compare","workers":4,"sequenceNumber":63,"symbol":"ETHUSDT","exchangeEventTimeMillis":1784430140155,"localReceivedEpochMillis":1784430140144,"topSpreadTicks":-8,"bid5Volume":5044,"ask5Volume":4141,"bid10Volume":9044,"ask10Volume":8863,"rawPayload":"{\"stream\":\"ethusdt@depth@100ms\",\"data\":{\"e\":\"depthUpdate\",\"E\":1784430140155,\"s\":\"ETHUSDT\",\"U\":2806177849,\"u\":2806177849,\"b\":[[\"1870.39000000\",\"0.75000000\"]],\"a\":[]}}"}
{"mode":"v10-framework-compare","workers":4,"sequenceNumber":64,"symbol":"XRPUSDT","exchangeEventTimeMillis":1784430140155,"localReceivedEpochMillis":1784430140144,"topSpreadTicks":0,"bid5Volume":5332500,"ask5Volume":12099400,"bid10Volume":15611700,"ask10Volume":13305900,"rawPayload":"{\"stream\":\"xrpusdt@depth@100ms\",\"data\":{\"e\":\"depthUpdate\",\"E\":1784430140155,\"s\":\"XRPUSDT\",\"U\":752705156,\"u\":752705157,\"b\":[],\"a\":[[\"1.09660000\",\"2463.80000000\"],[\"1.09670000\",\"3093.30000000\"]]}}"}
{"mode":"v10-framework-compare","workers":4,"sequenceNumber":65,"symbol":"XRPUSDT","exchangeEventTimeMillis":1784430140255,"localReceivedEpochMillis":1784430140244,"topSpreadTicks":1,"bid5Volume":21020600,"ask5Volume":9014700,"bid10Volume":31299800,"ask10Volume":10212600,"rawPayload":"{\"stream\":\"xrpusdt@depth@100ms\",\"data\":{\"e\":\"depthUpdate\",\"E\":1784430140255,\"s\":\"XRPUSDT\",\"U\":752705158,\"u\":752705172,\"b\":[[\"1.09640000\",\"0.00000000\"],[\"1.09630000\",\"1393.20000000\"],[\"1.09620000\",\"2443.10000000\"],[\"1.09610000\",\"0.00000000\"],[\"1.09600000\",\"4981.80000000\"],[\"1.09590000\",\"0.00000000\"],[\"1.09570000\",\"2542.70000000\"],[\"1.09470000\",\"187.30000000\"],[\"1.09130000\",\"15870.60000000\"]],\"a\":[[\"1.09670000\",\"4105.90000000\"],[\"1.09690000\",\"0.00000000\"]]}}"}
{"mode":"v10-framework-compare","workers":4,"sequenceNumber":66,"symbol":"SOLUSDT","exchangeEventTimeMillis":1784430140355,"localReceivedEpochMillis":1784430140344,"topSpreadTicks":-1,"bid5Volume":124857,"ask5Volume":249147,"bid10Volume":449439,"ask10Volume":1038534,"rawPayload":"{\"stream\":\"solusdt@depth@100ms\",\"data\":{\"e\":\"depthUpdate\",\"E\":1784430140355,\"s\":\"SOLUSDT\",\"U\":1609579863,\"u\":1609579863,\"b\":[],\"a\":[[\"76.24000000\",\"83.24600000\"],[\"76.25000000\",\"75.84600000\"]]}}"}
{"mode":"v10-framework-compare","workers":4,"sequenceNumber":67,"symbol":"ETHUSDT","exchangeEventTimeMillis":1784430140355,"localReceivedEpochMillis":1784430140344,"topSpreadTicks":-8,"bid5Volume":5044,"ask5Volume":4141,"bid10Volume":9044,"ask10Volume":8863,"rawPayload":"{\"stream\":\"ethusdt@depth@100ms\",\"data\":{\"e\":\"depthUpdate\",\"E\":1784430140355,\"s\":\"ETHUSDT\",\"U\":2806177850,\"u\":2806177851,\"b\":[[\"1870.04000000\",\"0.00000000\"],[\"1869.99000000\",\"0.90520000\"]],\"a\":[]}}"}
{"mode":"v10-framework-compare","workers":4,"sequenceNumber":68,"symbol":"XRPUSDT","exchangeEventTimeMillis":1784430140355,"localReceivedEpochMillis":1784430140344,"topSpreadTicks":0,"bid5Volume":9353700,"ask5Volume":12976900,"bid10Volume":19632900,"ask10Volume":14174800,"rawPayload":"{\"stream\":\"xrpusdt@depth@100ms\",\"data\":{\"e\":\"depthUpdate\",\"E\":1784430140355,\"s\":\"XRPUSDT\",\"U\":752705173,\"u\":752705180,\"b\":[[\"1.09620000\",\"2282.10000000\"],[\"1.09610000\",\"1012.10000000\"],[\"1.09600000\",\"4203.70000000\"]],\"a\":[[\"1.09650000\",\"227.80000000\"],[\"1.09660000\",\"2281.30000000\"],[\"1.09810000\",\"12661.60000000\"],[\"1.10020000\",\"0.00000000\"]]}}"}
{"mode":"v10-framework-compare","workers":4,"sequenceNumber":69,"symbol":"BTCUSDT","exchangeEventTimeMillis":1784430140455,"localReceivedEpochMillis":1784430140445,"topSpreadTicks":338,"bid5Volume":127,"ask5Volume":66,"bid10Volume":412,"ask10Volume":295,"rawPayload":"{\"stream\":\"btcusdt@depth@100ms\",\"data\":{\"e\":\"depthUpdate\",\"E\":1784430140455,\"s\":\"BTCUSDT\",\"U\":3244441184,\"u\":3244441186,\"b\":[],\"a\":[[\"64806.33000000\",\"0.00401000\"],[\"64806.70000000\",\"0.00000000\"],[\"64816.64000000\",\"0.00171000\"],[\"64817.66000000\",\"0.00000000\"]]}}"}
{"mode":"v10-framework-compare","workers":4,"sequenceNumber":70,"symbol":"SOLUSDT","exchangeEventTimeMillis":1784430140555,"localReceivedEpochMillis":1784430140545,"topSpreadTicks":-1,"bid5Volume":124857,"ask5Volume":209242,"bid10Volume":449439,"ask10Volume":764638,"rawPayload":"{\"stream\":\"solusdt@depth@100ms\",\"data\":{\"e\":\"depthUpdate\",\"E\":1784430140555,\"s\":\"SOLUSDT\",\"U\":1609579864,\"u\":1609579865,\"b\":[],\"a\":[[\"76.26000000\",\"13.43400000\"],[\"76.27000000\",\"39.47200000\"]]}}"}
{"mode":"v10-framework-compare","workers":4,"sequenceNumber":71,"symbol":"XRPUSDT","exchangeEventTimeMillis":1784430140555,"localReceivedEpochMillis":1784430140545,"topSpreadTicks":0,"bid5Volume":6497900,"ask5Volume":12976900,"bid10Volume":16777100,"ask10Volume":14174800,"rawPayload":"{\"stream\":\"xrpusdt@depth@100ms\",\"data\":{\"e\":\"depthUpdate\",\"E\":1784430140555,\"s\":\"XRPUSDT\",\"U\":752705181,\"u\":752705181,\"b\":[[\"1.09630000\",\"1347.90000000\"]],\"a\":[]}}"}
{"mode":"v10-framework-compare","workers":4,"sequenceNumber":72,"symbol":"BTCUSDT","exchangeEventTimeMillis":1784430140655,"localReceivedEpochMillis":1784430140644,"topSpreadTicks":302,"bid5Volume":127,"ask5Volume":66,"bid10Volume":412,"ask10Volume":295,"rawPayload":"{\"stream\":\"btcusdt@depth@100ms\",\"data\":{\"e\":\"depthUpdate\",\"E\":1784430140655,\"s\":\"BTCUSDT\",\"U\":3244441187,\"u\":3244441187,\"b\":[],\"a\":[[\"64805.97000000\",\"0.00401000\"],[\"64806.33000000\",\"0.00000000\"]]}}"}
{"mode":"v10-framework-compare","workers":4,"sequenceNumber":73,"symbol":"BTCUSDT","exchangeEventTimeMillis":1784430140755,"localReceivedEpochMillis":1784430140744,"topSpreadTicks":302,"bid5Volume":127,"ask5Volume":66,"bid10Volume":412,"ask10Volume":295,"rawPayload":"{\"stream\":\"btcusdt@depth@100ms\",\"data\":{\"e\":\"depthUpdate\",\"E\":1784430140755,\"s\":\"BTCUSDT\",\"U\":3244441188,\"u\":3244441188,\"b\":[],\"a\":[[\"81055.16000000\",\"0.00045000\"]]}}"}
{"mode":"v10-framework-compare","workers":4,"sequenceNumber":74,"symbol":"XRPUSDT","exchangeEventTimeMillis":1784430140855,"localReceivedEpochMillis":1784430140844,"topSpreadTicks":0,"bid5Volume":7477700,"ask5Volume":12976900,"bid10Volume":17756900,"ask10Volume":14174800,"rawPayload":"{\"stream\":\"xrpusdt@depth@100ms\",\"data\":{\"e\":\"depthUpdate\",\"E\":1784430140855,\"s\":\"XRPUSDT\",\"U\":752705182,\"u\":752705182,\"b\":[[\"1.09620000\",\"2327.70000000\"]],\"a\":[]}}"}
{"mode":"v10-framework-compare","workers":4,"sequenceNumber":75,"symbol":"XRPUSDT","exchangeEventTimeMillis":1784430141155,"localReceivedEpochMillis":1784430141149,"topSpreadTicks":0,"bid5Volume":7477700,"ask5Volume":2779100,"bid10Volume":17756900,"ask10Volume":3977000,"rawPayload":"{\"stream\":\"xrpusdt@depth@100ms\",\"data\":{\"e\":\"depthUpdate\",\"E\":1784430141155,\"s\":\"XRPUSDT\",\"U\":752705183,\"u\":752705184,\"b\":[],\"a\":[[\"1.09650000\",\"45.30000000\"],[\"1.09660000\",\"2463.80000000\"]]}}"}
{"mode":"v10-framework-compare","workers":4,"sequenceNumber":76,"symbol":"SOLUSDT","exchangeEventTimeMillis":1784430141255,"localReceivedEpochMillis":1784430141245,"topSpreadTicks":-1,"bid5Volume":123674,"ask5Volume":249893,"bid10Volume":448256,"ask10Volume":1039280,"rawPayload":"{\"stream\":\"solusdt@depth@100ms\",\"data\":{\"e\":\"depthUpdate\",\"E\":1784430141255,\"s\":\"SOLUSDT\",\"U\":1609579866,\"u\":1609579871,\"b\":[[\"76.21000000\",\"18.63100000\"],[\"76.20000000\",\"13.97100000\"]],\"a\":[[\"76.22000000\",\"36.16100000\"],[\"76.23000000\",\"0.55800000\"],[\"76.25000000\",\"90.45600000\"],[\"76.26000000\",\"0.00000000\"]]}}"}
{"mode":"v10-framework-compare","workers":4,"sequenceNumber":77,"symbol":"ETHUSDT","exchangeEventTimeMillis":1784430141255,"localReceivedEpochMillis":1784430141245,"topSpreadTicks":-8,"bid5Volume":5044,"ask5Volume":4141,"bid10Volume":8904,"ask10Volume":8863,"rawPayload":"{\"stream\":\"ethusdt@depth@100ms\",\"data\":{\"e\":\"depthUpdate\",\"E\":1784430141255,\"s\":\"ETHUSDT\",\"U\":2806177852,\"u\":2806177857,\"b\":[[\"1870.27000000\",\"0.02980000\"],[\"1870.12000000\",\"1.33770000\"],[\"1869.99000000\",\"0.00000000\"],[\"1869.93000000\",\"0.92810000\"]],\"a\":[[\"1871.60000000\",\"1.85630000\"],[\"1871.98000000\",\"0.00000000\"]]}}"}
{"mode":"v10-framework-compare","workers":4,"sequenceNumber":78,"symbol":"BTCUSDT","exchangeEventTimeMillis":1784430141255,"localReceivedEpochMillis":1784430141245,"topSpreadTicks":302,"bid5Volume":117,"ask5Volume":103,"bid10Volume":412,"ask10Volume":295,"rawPayload":"{\"stream\":\"btcusdt@depth@100ms\",\"data\":{\"e\":\"depthUpdate\",\"E\":1784430141255,\"s\":\"BTCUSDT\",\"U\":3244441189,\"u\":3244441196,\"b\":[[\"64795.42000000\",\"0.00000000\"],[\"64794.69000000\",\"0.00000000\"],[\"64793.00000000\",\"0.03088000\"],[\"64791.55000000\",\"0.00000000\"],[\"64790.83000000\",\"0.02800000\"],[\"64789.06000000\",\"0.03861000\"]],\"a\":[[\"64807.26000000\",\"0.03020000\"],[\"64807.84000000\",\"0.00000000\"],[\"64811.95000000\",\"0.03860000\"],[\"64817.89000000\",\"0.00000000\"]]}}"}
{"mode":"v10-framework-compare","workers":4,"sequenceNumber":79,"symbol":"BNBUSDT","exchangeEventTimeMillis":1784430141355,"localReceivedEpochMillis":1784430141353,"topSpreadTicks":7,"bid5Volume":4937,"ask5Volume":6228,"bid10Volume":15184,"ask10Volume":257219,"rawPayload":"{\"stream\":\"bnbusdt@depth@100ms\",\"data\":{\"e\":\"depthUpdate\",\"E\":1784430141355,\"s\":\"BNBUSDT\",\"U\":1236331309,\"u\":1236331312,\"b\":[],\"a\":[[\"570.62000000\",\"0.82100000\"],[\"570.64000000\",\"0.00000000\"],[\"570.71000000\",\"0.10600000\"],[\"570.73000000\",\"0.93900000\"]]}}"}
{"mode":"v10-framework-compare","workers":4,"sequenceNumber":80,"symbol":"SOLUSDT","exchangeEventTimeMillis":1784430141355,"localReceivedEpochMillis":1784430141354,"topSpreadTicks":-1,"bid5Volume":87507,"ask5Volume":251116,"bid10Volume":344313,"ask10Volume":1316490,"rawPayload":"{\"stream\":\"solusdt@depth@100ms\",\"data\":{\"e\":\"depthUpdate\",\"E\":1784430141355,\"s\":\"SOLUSDT\",\"U\":1609579872,\"u\":1609579887,\"b\":[[\"76.19000000\",\"36.24600000\"],[\"76.18000000\",\"4.05500000\"],[\"76.17000000\",\"95.71000000\"],[\"76.16000000\",\"68.40200000\"],[\"76.15000000\",\"8.11000000\"],[\"76.09000000\",\"3.45300000\"],[\"75.88000000\",\"478.85700000\"]],\"a\":[[\"76.23000000\",\"20.68800000\"],[\"76.24000000\",\"91.35500000\"],[\"76.25000000\",\"63.44000000\"],[\"76.33000000\",\"336.28200000\"],[\"76.50000000\",\"196.99700000\"]]}}"}
{"mode":"v10-framework-compare","workers":4,"sequenceNumber":81,"symbol":"ETHUSDT","exchangeEventTimeMillis":1784430141355,"localReceivedEpochMillis":1784430141354,"topSpreadTicks":-24,"bid5Volume":5044,"ask5Volume":4141,"bid10Volume":8904,"ask10Volume":8863,"rawPayload":"{\"stream\":\"ethusdt@depth@100ms\",\"data\":{\"e\":\"depthUpdate\",\"E\":1784430141355,\"s\":\"ETHUSDT\",\"U\":2806177858,\"u\":2806177866,\"b\":[[\"1869.93000000\",\"0.00000000\"],[\"1869.88000000\",\"1.63970000\"],[\"1869.83000000\",\"0.93060000\"],[\"1869.66000000\",\"0.00000000\"],[\"1869.47000000\",\"1.39600000\"]],\"a\":[[\"1870.60000000\",\"1.33740000\"],[\"1870.76000000\",\"0.00000000\"],[\"1871.24000000\",\"1.06180000\"],[\"1871.33000000\",\"0.00000000\"]]}}"}
{"mode":"v10-framework-compare","workers":4,"sequenceNumber":82,"symbol":"SOLUSDT","exchangeEventTimeMillis":1784430141455,"localReceivedEpochMillis":1784430141445,"topSpreadTicks":-1,"bid5Volume":86953,"ask5Volume":247833,"bid10Volume":343759,"ask10Volume":1313207,"rawPayload":"{\"stream\":\"solusdt@depth@100ms\",\"data\":{\"e\":\"depthUpdate\",\"E\":1784430141455,\"s\":\"SOLUSDT\",\"U\":1609579888,\"u\":1609579889,\"b\":[[\"76.20000000\",\"13.41700000\"]],\"a\":[[\"76.27000000\",\"36.18900000\"]]}}"}
{"mode":"v10-framework-compare","workers":4,"sequenceNumber":83,"symbol":"ETHUSDT","exchangeEventTimeMillis":1784430141455,"localReceivedEpochMillis":1784430141445,"topSpreadTicks":-24,"bid5Volume":5044,"ask5Volume":4200,"bid10Volume":8904,"ask10Volume":8922,"rawPayload":"{\"stream\":\"ethusdt@depth@100ms\",\"data\":{\"e\":\"depthUpdate\",\"E\":1784430141455,\"s\":\"ETHUSDT\",\"U\":2806177867,\"u\":2806177868,\"b\":[],\"a\":[[\"1870.97000000\",\"1.22100000\"],[\"1871.23000000\",\"0.00000000\"]]}}"}
{"mode":"v10-framework-compare","workers":4,"sequenceNumber":84,"symbol":"BNBUSDT","exchangeEventTimeMillis":1784430141455,"localReceivedEpochMillis":1784430141445,"topSpreadTicks":7,"bid5Volume":4937,"ask5Volume":6228,"bid10Volume":15184,"ask10Volume":257219,"rawPayload":"{\"stream\":\"bnbusdt@depth@100ms\",\"data\":{\"e\":\"depthUpdate\",\"E\":1784430141455,\"s\":\"BNBUSDT\",\"U\":1236331313,\"u\":1236331316,\"b\":[[\"568.31000000\",\"0.00000000\"],[\"567.87000000\",\"2.21700000\"]],\"a\":[[\"572.88000000\",\"1.74100000\"],[\"573.65000000\",\"0.00000000\"]]}}"}
{"mode":"v10-framework-compare","workers":4,"sequenceNumber":85,"symbol":"BTCUSDT","exchangeEventTimeMillis":1784430141455,"localReceivedEpochMillis":1784430141445,"topSpreadTicks":302,"bid5Volume":117,"ask5Volume":103,"bid10Volume":412,"ask10Volume":295,"rawPayload":"{\"stream\":\"btcusdt@depth@100ms\",\"data\":{\"e\":\"depthUpdate\",\"E\":1784430141455,\"s\":\"BTCUSDT\",\"U\":3244441197,\"u\":3244441204,\"b\":[[\"64743.28000000\",\"0.05967000\"],[\"64735.70000000\",\"0.00000000\"],[\"64704.39000000\",\"0.08541000\"],[\"64696.81000000\",\"0.00000000\"],[\"64665.49000000\",\"0.18203000\"],[\"64657.92000000\",\"0.00000000\"],[\"64587.71000000\",\"0.40748000\"],[\"64580.14000000\",\"0.00000000\"]],\"a\":[[\"64891.21000000\",\"0.00000000\"],[\"64898.79000000\",\"0.06099000\"],[\"64930.10000000\",\"0.00000000\"],[\"64937.68000000\",\"0.08452000\"],[\"64968.99000000\",\"0.00000000\"],[\"64976.57000000\",\"0.18519000\"],[\"65046.77000000\",\"0.00000000\"],[\"65054.36000000\",\"0.40282000\"]]}}"}
{"mode":"v10-framework-compare","workers":4,"sequenceNumber":86,"symbol":"XRPUSDT","exchangeEventTimeMillis":1784430141455,"localReceivedEpochMillis":1784430141446,"topSpreadTicks":0,"bid5Volume":8825600,"ask5Volume":3177200,"bid10Volume":19104800,"ask10Volume":4375100,"rawPayload":"{\"stream\":\"xrpusdt@depth@100ms\",\"data\":{\"e\":\"depthUpdate\",\"E\":1784430141455,\"s\":\"XRPUSDT\",\"U\":752705185,\"u\":752705188,\"b\":[[\"1.09630000\",\"0.00000000\"],[\"1.09620000\",\"3675.60000000\"]],\"a\":[[\"1.09650000\",\"2326.90000000\"],[\"1.09660000\",\"1426.50000000\"],[\"1.09670000\",\"2861.90000000\"]]}}"}
{"mode":"v10-framework-compare","workers":4,"sequenceNumber":87,"symbol":"SOLUSDT","exchangeEventTimeMillis":1784430141555,"localReceivedEpochMillis":1784430141558,"topSpreadTicks":-1,"bid5Volume":87507,"ask5Volume":250558,"bid10Volume":344313,"ask10Volume":1315932,"rawPayload":"{\"stream\":\"solusdt@depth@100ms\",\"data\":{\"e\":\"depthUpdate\",\"E\":1784430141555,\"s\":\"SOLUSDT\",\"U\":1609579890,\"u\":1609579893,\"b\":[[\"76.19000000\",\"36.80000000\"],[\"76.10000000\",\"8.13200000\"]],\"a\":[[\"76.23000000\",\"20.13000000\"],[\"76.24000000\",\"94.63800000\"]]}}"}
{"mode":"v10-framework-compare","workers":4,"sequenceNumber":88,"symbol":"XRPUSDT","exchangeEventTimeMillis":1784430141556,"localReceivedEpochMillis":1784430141558,"topSpreadTicks":0,"bid5Volume":8825600,"ask5Volume":2596900,"bid10Volume":19104800,"ask10Volume":3794800,"rawPayload":"{\"stream\":\"xrpusdt@depth@100ms\",\"data\":{\"e\":\"depthUpdate\",\"E\":1784430141556,\"s\":\"XRPUSDT\",\"U\":752705189,\"u\":752705189,\"b\":[],\"a\":[[\"1.09650000\",\"2281.60000000\"]]}}"}
{"mode":"v10-framework-compare","workers":4,"sequenceNumber":89,"symbol":"ETHUSDT","exchangeEventTimeMillis":1784430141656,"localReceivedEpochMillis":1784430141651,"topSpreadTicks":-24,"bid5Volume":5044,"ask5Volume":4200,"bid10Volume":8904,"ask10Volume":8922,"rawPayload":"{\"stream\":\"ethusdt@depth@100ms\",\"data\":{\"e\":\"depthUpdate\",\"E\":1784430141656,\"s\":\"ETHUSDT\",\"U\":2806177869,\"u\":2806177869,\"b\":[],\"a\":[[\"1871.22000000\",\"1.06180000\"],[\"1871.24000000\",\"0.00000000\"]]}}"}
{"mode":"v10-framework-compare","workers":4,"sequenceNumber":90,"symbol":"BTCUSDT","exchangeEventTimeMillis":1784430141656,"localReceivedEpochMillis":1784430141651,"topSpreadTicks":302,"bid5Volume":117,"ask5Volume":103,"bid10Volume":412,"ask10Volume":295,"rawPayload":"{\"stream\":\"btcusdt@depth@100ms\",\"data\":{\"e\":\"depthUpdate\",\"E\":1784430141656,\"s\":\"BTCUSDT\",\"U\":3244441205,\"u\":3244441205,\"b\":[],\"a\":[[\"81055.16000000\",\"0.00030000\"]]}}"}
{"mode":"v10-framework-compare","workers":4,"sequenceNumber":91,"symbol":"BTCUSDT","exchangeEventTimeMillis":1784430141756,"localReceivedEpochMillis":1784430141763,"topSpreadTicks":302,"bid5Volume":129,"ask5Volume":103,"bid10Volume":257,"ask10Volume":295,"rawPayload":"{\"stream\":\"btcusdt@depth@100ms\",\"data\":{\"e\":\"depthUpdate\",\"E\":1784430141756,\"s\":\"BTCUSDT\",\"U\":3244441206,\"u\":3244441206,\"b\":[[\"64797.20000000\",\"0.04000000\"]],\"a\":[]}}"}
{"mode":"v10-framework-compare","workers":4,"sequenceNumber":92,"symbol":"SOLUSDT","exchangeEventTimeMillis":1784430141856,"localReceivedEpochMillis":1784430141848,"topSpreadTicks":-1,"bid5Volume":87507,"ask5Volume":251112,"bid10Volume":344313,"ask10Volume":1316486,"rawPayload":"{\"stream\":\"solusdt@depth@100ms\",\"data\":{\"e\":\"depthUpdate\",\"E\":1784430141856,\"s\":\"SOLUSDT\",\"U\":1609579894,\"u\":1609579894,\"b\":[],\"a\":[[\"76.22000000\",\"36.71500000\"]]}}"}
{"mode":"v10-framework-compare","workers":4,"sequenceNumber":93,"symbol":"XRPUSDT","exchangeEventTimeMillis":1784430141856,"localReceivedEpochMillis":1784430141848,"topSpreadTicks":0,"bid5Volume":8825600,"ask5Volume":360800,"bid10Volume":19104800,"ask10Volume":1558700,"rawPayload":"{\"stream\":\"xrpusdt@depth@100ms\",\"data\":{\"e\":\"depthUpdate\",\"E\":1784430141856,\"s\":\"XRPUSDT\",\"U\":752705190,\"u\":752705190,\"b\":[],\"a\":[[\"1.09640000\",\"45.50000000\"]]}}"}
{"mode":"v10-framework-compare","workers":4,"sequenceNumber":94,"symbol":"BTCUSDT","exchangeEventTimeMillis":1784430142056,"localReceivedEpochMillis":1784430142046,"topSpreadTicks":302,"bid5Volume":129,"ask5Volume":103,"bid10Volume":257,"ask10Volume":295,"rawPayload":"{\"stream\":\"btcusdt@depth@100ms\",\"data\":{\"e\":\"depthUpdate\",\"E\":1784430142056,\"s\":\"BTCUSDT\",\"U\":3244441207,\"u\":3244441207,\"b\":[],\"a\":[[\"64914.49000000\",\"0.00000000\"]]}}"}
{"mode":"v10-framework-compare","workers":4,"sequenceNumber":95,"symbol":"SOLUSDT","exchangeEventTimeMillis":1784430142156,"localReceivedEpochMillis":1784430142146,"topSpreadTicks":-1,"bid5Volume":183286,"ask5Volume":251112,"bid10Volume":443572,"ask10Volume":1316486,"rawPayload":"{\"stream\":\"solusdt@depth@100ms\",\"data\":{\"e\":\"depthUpdate\",\"E\":1784430142156,\"s\":\"SOLUSDT\",\"U\":1609579895,\"u\":1609579896,\"b\":[[\"76.19000000\",\"40.92400000\"],[\"76.18000000\",\"0.00000000\"]],\"a\":[]}}"}
{"mode":"v10-framework-compare","workers":4,"sequenceNumber":96,"symbol":"BTCUSDT","exchangeEventTimeMillis":1784430142156,"localReceivedEpochMillis":1784430142146,"topSpreadTicks":302,"bid5Volume":129,"ask5Volume":103,"bid10Volume":257,"ask10Volume":295,"rawPayload":"{\"stream\":\"btcusdt@depth@100ms\",\"data\":{\"e\":\"depthUpdate\",\"E\":1784430142156,\"s\":\"BTCUSDT\",\"U\":3244441208,\"u\":3244441208,\"b\":[],\"a\":[[\"64914.49000000\",\"0.00011000\"]]}}"}
{"mode":"v10-framework-compare","workers":4,"sequenceNumber":97,"symbol":"XRPUSDT","exchangeEventTimeMillis":1784430142156,"localReceivedEpochMillis":1784430142146,"topSpreadTicks":0,"bid5Volume":8825600,"ask5Volume":1559300,"bid10Volume":19104800,"ask10Volume":2757200,"rawPayload":"{\"stream\":\"xrpusdt@depth@100ms\",\"data\":{\"e\":\"depthUpdate\",\"E\":1784430142156,\"s\":\"XRPUSDT\",\"U\":752705191,\"u\":752705192,\"b\":[],\"a\":[[\"1.09650000\",\"2464.10000000\"],[\"1.09660000\",\"1244.00000000\"]]}}"}
{"mode":"v10-framework-compare","workers":4,"sequenceNumber":98,"symbol":"BTCUSDT","exchangeEventTimeMillis":1784430142356,"localReceivedEpochMillis":1784430142346,"topSpreadTicks":302,"bid5Volume":129,"ask5Volume":103,"bid10Volume":257,"ask10Volume":295,"rawPayload":"{\"stream\":\"btcusdt@depth@100ms\",\"data\":{\"e\":\"depthUpdate\",\"E\":1784430142356,\"s\":\"BTCUSDT\",\"U\":3244441209,\"u\":3244441209,\"b\":[],\"a\":[[\"81055.16000000\",\"0.00045000\"]]}}"}
{"mode":"v10-framework-compare","workers":4,"sequenceNumber":99,"symbol":"ETHUSDT","exchangeEventTimeMillis":1784430142356,"localReceivedEpochMillis":1784430142347,"topSpreadTicks":-24,"bid5Volume":5044,"ask5Volume":4200,"bid10Volume":8293,"ask10Volume":8922,"rawPayload":"{\"stream\":\"ethusdt@depth@100ms\",\"data\":{\"e\":\"depthUpdate\",\"E\":1784430142356,\"s\":\"ETHUSDT\",\"U\":2806177870,\"u\":2806177870,\"b\":[[\"1870.39000000\",\"0.00000000\"]],\"a\":[]}}"}
{"mode":"v10-framework-compare","workers":4,"sequenceNumber":100,"symbol":"SOLUSDT","exchangeEventTimeMillis":1784430142456,"localReceivedEpochMillis":1784430142446,"topSpreadTicks":-1,"bid5Volume":251688,"ask5Volume":251112,"bid10Volume":451704,"ask10Volume":1316486,"rawPayload":"{\"stream\":\"solusdt@depth@100ms\",\"data\":{\"e\":\"depthUpdate\",\"E\":1784430142456,\"s\":\"SOLUSDT\",\"U\":1609579897,\"u\":1609579898,\"b\":[[\"76.21000000\",\"0.00000000\"],[\"76.20000000\",\"32.04800000\"]],\"a\":[[\"76.24000000\",\"113.27300000\"],[\"76.25000000\",\"44.80500000\"]]}}"}
{"mode":"v10-framework-compare","workers":4,"sequenceNumber":101,"symbol":"SOLUSDT","exchangeEventTimeMillis":1784430142556,"localReceivedEpochMillis":1784430142546,"topSpreadTicks":-1,"bid5Volume":251688,"ask5Volume":251112,"bid10Volume":451704,"ask10Volume":1316486,"rawPayload":"{\"stream\":\"solusdt@depth@100ms\",\"data\":{\"e\":\"depthUpdate\",\"E\":1784430142556,\"s\":\"SOLUSDT\",\"U\":1609579899,\"u\":1609579899,\"b\":[[\"76.09000000\",\"9.96600000\"]],\"a\":[]}}"}
{"mode":"v10-framework-compare","workers":4,"sequenceNumber":102,"symbol":"SOLUSDT","exchangeEventTimeMillis":1784430142656,"localReceivedEpochMillis":1784430142646,"topSpreadTicks":-2,"bid5Volume":251688,"ask5Volume":215769,"bid10Volume":461661,"ask10Volume":1043869,"rawPayload":"{\"stream\":\"solusdt@depth@100ms\",\"data\":{\"e\":\"depthUpdate\",\"E\":1784430142656,\"s\":\"SOLUSDT\",\"U\":1609579900,\"u\":1609579902,\"b\":[[\"76.12000000\",\"164.90600000\"],[\"76.11000000\",\"0.00000000\"]],\"a\":[[\"76.21000000\",\"4.18500000\"],[\"76.22000000\",\"33.37600000\"]]}}"}
{"mode":"v10-framework-compare","workers":4,"sequenceNumber":103,"symbol":"ETHUSDT","exchangeEventTimeMillis":1784430142656,"localReceivedEpochMillis":1784430142646,"topSpreadTicks":-24,"bid5Volume":5044,"ask5Volume":4200,"bid10Volume":8293,"ask10Volume":8922,"rawPayload":"{\"stream\":\"ethusdt@depth@100ms\",\"data\":{\"e\":\"depthUpdate\",\"E\":1784430142656,\"s\":\"ETHUSDT\",\"U\":2806177871,\"u\":2806177871,\"b\":[],\"a\":[[\"1871.18000000\",\"1.06180000\"],[\"1871.22000000\",\"0.00000000\"]]}}"}
{"mode":"v10-framework-compare","workers":4,"sequenceNumber":104,"symbol":"SOLUSDT","exchangeEventTimeMillis":1784430142856,"localReceivedEpochMillis":1784430142846,"topSpreadTicks":-2,"bid5Volume":251688,"ask5Volume":215774,"bid10Volume":461661,"ask10Volume":1043874,"rawPayload":"{\"stream\":\"solusdt@depth@100ms\",\"data\":{\"e\":\"depthUpdate\",\"E\":1784430142856,\"s\":\"SOLUSDT\",\"U\":1609579903,\"u\":1609579904,\"b\":[],\"a\":[[\"76.21000000\",\"37.01200000\"],[\"76.22000000\",\"0.55400000\"]]}}"}
{"mode":"v10-framework-compare","workers":4,"sequenceNumber":105,"symbol":"BTCUSDT","exchangeEventTimeMillis":1784430142856,"localReceivedEpochMillis":1784430142847,"topSpreadTicks":302,"bid5Volume":127,"ask5Volume":148,"bid10Volume":282,"ask10Volume":295,"rawPayload":"{\"stream\":\"btcusdt@depth@100ms\",\"data\":{\"e\":\"depthUpdate\",\"E\":1784430142856,\"s\":\"BTCUSDT\",\"U\":3244441210,\"u\":3244441224,\"b\":[[\"64793.00000000\",\"0.00000000\"],[\"64791.25000000\",\"0.00000000\"],[\"64788.72000000\",\"0.03088000\"],[\"64784.26000000\",\"0.00000000\"],[\"64783.06000000\",\"0.00000000\"],[\"64777.52000000\",\"0.04632000\"],[\"64776.60000000\",\"0.19576000\"],[\"64745.77000000\",\"0.00000000\"],[\"64744.44000000\",\"0.20679000\"],[\"64546.98000000\",\"0.00000000\"]],\"a\":[[\"64809.63000000\",\"0.04632000\"],[\"64817.04000000\",\"0.00000000\"],[\"64825.01000000\",\"0.00321000\"],[\"64838.16000000\",\"0.00000000\"]]}}"}
{"mode":"v10-framework-compare","workers":4,"sequenceNumber":106,"symbol":"BNBUSDT","exchangeEventTimeMillis":1784430142956,"localReceivedEpochMillis":1784430142947,"topSpreadTicks":7,"bid5Volume":4937,"ask5Volume":6228,"bid10Volume":15184,"ask10Volume":257219,"rawPayload":"{\"stream\":\"bnbusdt@depth@100ms\",\"data\":{\"e\":\"depthUpdate\",\"E\":1784430142956,\"s\":\"BNBUSDT\",\"U\":1236331317,\"u\":1236331318,\"b\":[[\"570.42000000\",\"0.00000000\"],[\"570.41000000\",\"1.74200000\"]],\"a\":[[\"570.60000000\",\"1.71100000\"],[\"570.61000000\",\"0.00000000\"]]}}"}
{"mode":"v10-framework-compare","workers":4,"sequenceNumber":107,"symbol":"BTCUSDT","exchangeEventTimeMillis":1784430142956,"localReceivedEpochMillis":1784430142947,"topSpreadTicks":302,"bid5Volume":127,"ask5Volume":148,"bid10Volume":282,"ask10Volume":297,"rawPayload":"{\"stream\":\"btcusdt@depth@100ms\",\"data\":{\"e\":\"depthUpdate\",\"E\":1784430142956,\"s\":\"BTCUSDT\",\"U\":3244441225,\"u\":3244441225,\"b\":[],\"a\":[[\"64812.48000000\",\"0.00000000\"]]}}"}
{"mode":"v10-framework-compare","workers":4,"sequenceNumber":108,"symbol":"ETHUSDT","exchangeEventTimeMillis":1784430142956,"localReceivedEpochMillis":1784430142947,"topSpreadTicks":-24,"bid5Volume":5044,"ask5Volume":4200,"bid10Volume":8293,"ask10Volume":8922,"rawPayload":"{\"stream\":\"ethusdt@depth@100ms\",\"data\":{\"e\":\"depthUpdate\",\"E\":1784430142956,\"s\":\"ETHUSDT\",\"U\":2806177872,\"u\":2806177877,\"b\":[[\"1868.85000000\",\"0.00000000\"],[\"1868.51000000\",\"2.00910000\"],[\"1867.73000000\",\"0.00000000\"],[\"1867.39000000\",\"3.06430000\"],[\"1866.61000000\",\"0.00000000\"],[\"1866.27000000\",\"6.29250000\"],[\"1864.36000000\",\"0.00000000\"],[\"1864.02000000\",\"13.86920000\"]],\"a\":[[\"1873.01000000\",\"1.97600000\"],[\"1873.35000000\",\"0.00000000\"],[\"1875.25000000\",\"6.19570000\"],[\"1875.60000000\",\"5.43010000\"]]}}"}
{"mode":"v10-framework-compare","workers":4,"sequenceNumber":109,"symbol":"BTCUSDT","exchangeEventTimeMillis":1784430143056,"localReceivedEpochMillis":1784430143046,"topSpreadTicks":302,"bid5Volume":127,"ask5Volume":148,"bid10Volume":282,"ask10Volume":297,"rawPayload":"{\"stream\":\"btcusdt@depth@100ms\",\"data\":{\"e\":\"depthUpdate\",\"E\":1784430143056,\"s\":\"BTCUSDT\",\"U\":3244441226,\"u\":3244441228,\"b\":[[\"64547.07000000\",\"0.26653000\"]],\"a\":[[\"64860.34000000\",\"0.20553000\"],[\"64928.40000000\",\"0.00000000\"]]}}"}
{"mode":"v10-framework-compare","workers":4,"sequenceNumber":110,"symbol":"SOLUSDT","exchangeEventTimeMillis":1784430143157,"localReceivedEpochMillis":1784430143146,"topSpreadTicks":-2,"bid5Volume":183408,"ask5Volume":215774,"bid10Volume":451817,"ask10Volume":1043874,"rawPayload":"{\"stream\":\"solusdt@depth@100ms\",\"data\":{\"e\":\"depthUpdate\",\"E\":1784430143157,\"s\":\"SOLUSDT\",\"U\":1609579905,\"u\":1609579906,\"b\":[[\"76.19000000\",\"36.80000000\"],[\"76.18000000\",\"4.24600000\"]],\"a\":[]}}"}
{"mode":"v10-framework-compare","workers":4,"sequenceNumber":111,"symbol":"XRPUSDT","exchangeEventTimeMillis":1784430143157,"localReceivedEpochMillis":1784430143147,"topSpreadTicks":0,"bid5Volume":8825600,"ask5Volume":1741800,"bid10Volume":19104800,"ask10Volume":2939700,"rawPayload":"{\"stream\":\"xrpusdt@depth@100ms\",\"data\":{\"e\":\"depthUpdate\",\"E\":1784430143157,\"s\":\"XRPUSDT\",\"U\":752705193,\"u\":752705194,\"b\":[],\"a\":[[\"1.09650000\",\"2281.60000000\"],[\"1.09660000\",\"1426.50000000\"]]}}"}
{"mode":"v10-framework-compare","workers":4,"sequenceNumber":112,"symbol":"BTCUSDT","exchangeEventTimeMillis":1784430143257,"localReceivedEpochMillis":1784430143247,"topSpreadTicks":302,"bid5Volume":164,"ask5Volume":148,"bid10Volume":327,"ask10Volume":297,"rawPayload":"{\"stream\":\"btcusdt@depth@100ms\",\"data\":{\"e\":\"depthUpdate\",\"E\":1784430143257,\"s\":\"BTCUSDT\",\"U\":3244441229,\"u\":3244441230,\"b\":[[\"64795.62000000\",\"0.00000000\"]],\"a\":[[\"64809.78000000\",\"0.00079000\"]]}}"}
{"mode":"v10-framework-compare","workers":4,"sequenceNumber":113,"symbol":"BNBUSDT","exchangeEventTimeMillis":1784430143357,"localReceivedEpochMillis":1784430143346,"topSpreadTicks":7,"bid5Volume":4937,"ask5Volume":6387,"bid10Volume":15184,"ask10Volume":257360,"rawPayload":"{\"stream\":\"bnbusdt@depth@100ms\",\"data\":{\"e\":\"depthUpdate\",\"E\":1784430143357,\"s\":\"BNBUSDT\",\"U\":1236331319,\"u\":1236331320,\"b\":[],\"a\":[[\"570.60000000\",\"2.58500000\"],[\"570.62000000\",\"0.00000000\"]]}}"}
{"mode":"v10-framework-compare","workers":4,"sequenceNumber":114,"symbol":"BTCUSDT","exchangeEventTimeMillis":1784430143357,"localReceivedEpochMillis":1784430143347,"topSpreadTicks":302,"bid5Volume":164,"ask5Volume":148,"bid10Volume":327,"ask10Volume":297,"rawPayload":"{\"stream\":\"btcusdt@depth@100ms\",\"data\":{\"e\":\"depthUpdate\",\"E\":1784430143357,\"s\":\"BTCUSDT\",\"U\":3244441231,\"u\":3244441232,\"b\":[[\"64790.83000000\",\"0.00000000\"],[\"64788.94000000\",\"0.02800000\"]],\"a\":[[\"64806.06000000\",\"0.03020000\"],[\"64807.26000000\",\"0.00000000\"]]}}"}
{"mode":"v10-framework-compare","workers":4,"sequenceNumber":115,"symbol":"SOLUSDT","exchangeEventTimeMillis":1784430143757,"localReceivedEpochMillis":1784430143748,"topSpreadTicks":-2,"bid5Volume":183408,"ask5Volume":215774,"bid10Volume":451817,"ask10Volume":1047382,"rawPayload":"{\"stream\":\"solusdt@depth@100ms\",\"data\":{\"e\":\"depthUpdate\",\"E\":1784430143757,\"s\":\"SOLUSDT\",\"U\":1609579907,\"u\":1609579910,\"b\":[],\"a\":[[\"76.29000000\",\"74.27600000\"],[\"76.31000000\",\"0.00000000\"],[\"76.33000000\",\"331.08300000\"]]}}"}
{"mode":"v10-framework-compare","workers":4,"sequenceNumber":116,"symbol":"XRPUSDT","exchangeEventTimeMillis":1784430143757,"localReceivedEpochMillis":1784430143748,"topSpreadTicks":0,"bid5Volume":10318300,"ask5Volume":1559300,"bid10Volume":20597500,"ask10Volume":2757200,"rawPayload":"{\"stream\":\"xrpusdt@depth@100ms\",\"data\":{\"e\":\"depthUpdate\",\"E\":1784430143757,\"s\":\"XRPUSDT\",\"U\":752705195,\"u\":752705198,\"b\":[[\"1.09610000\",\"0.00000000\"],[\"1.09600000\",\"5168.30000000\"]],\"a\":[[\"1.09650000\",\"2464.10000000\"],[\"1.09660000\",\"1244.00000000\"]]}}"}
{"mode":"v10-framework-compare","workers":4,"sequenceNumber":117,"symbol":"SOLUSDT","exchangeEventTimeMillis":1784430143857,"localReceivedEpochMillis":1784430143847,"topSpreadTicks":-2,"bid5Volume":183492,"ask5Volume":214876,"bid10Volume":443778,"ask10Volume":1046484,"rawPayload":"{\"stream\":\"solusdt@depth@100ms\",\"data\":{\"e\":\"depthUpdate\",\"E\":1784430143857,\"s\":\"SOLUSDT\",\"U\":1609579911,\"u\":1609579917,\"b\":[[\"76.20000000\",\"32.13200000\"],[\"76.12000000\",\"65.72500000\"],[\"76.11000000\",\"99.19000000\"]],\"a\":[[\"76.24000000\",\"113.27300000\"],[\"76.25000000\",\"43.90700000\"]]}}"}
{"mode":"v10-framework-compare","workers":4,"sequenceNumber":118,"symbol":"ETHUSDT","exchangeEventTimeMillis":1784430143857,"localReceivedEpochMillis":1784430143847,"topSpreadTicks":-24,"bid5Volume":5082,"ask5Volume":4076,"bid10Volume":8942,"ask10Volume":8798,"rawPayload":"{\"stream\":\"ethusdt@depth@100ms\",\"data\":{\"e\":\"depthUpdate\",\"E\":1784430143857,\"s\":\"ETHUSDT\",\"U\":2806177878,\"u\":2806177888,\"b\":[[\"1870.40000000\",\"0.00000000\"],[\"1870.33000000\",\"1.13370000\"],[\"1870.19000000\",\"0.75000000\"],[\"1870.10000000\",\"0.00000000\"],[\"1870.04000000\",\"0.13900000\"],[\"1862.84000000\",\"0.02970000\"]],\"a\":[[\"1870.70000000\",\"0.13890000\"],[\"1870.77000000\",\"0.00000000\"],[\"1870.90000000\",\"1.09730000\"],[\"1870.97000000\",\"0.00000000\"],[\"1871.00000000\",\"1.47510000\"],[\"1871.07000000\",\"0.00000000\"],[\"1872.14000000\",\"0.00000000\"]]}}"}
{"mode":"v10-framework-compare","workers":4,"sequenceNumber":119,"symbol":"BNBUSDT","exchangeEventTimeMillis":1784430143857,"localReceivedEpochMillis":1784430143848,"topSpreadTicks":7,"bid5Volume":5006,"ask5Volume":6387,"bid10Volume":15253,"ask10Volume":257360,"rawPayload":"{\"stream\":\"bnbusdt@depth@100ms\",\"data\":{\"e\":\"depthUpdate\",\"E\":1784430143857,\"s\":\"BNBUSDT\",\"U\":1236331321,\"u\":1236331322,\"b\":[[\"570.40000000\",\"0.00000000\"],[\"570.33000000\",\"1.75300000\"]],\"a\":[]}}"}
{"mode":"v10-framework-compare","workers":4,"sequenceNumber":120,"symbol":"XRPUSDT","exchangeEventTimeMillis":1784430143857,"localReceivedEpochMillis":1784430143848,"topSpreadTicks":1,"bid5Volume":15059000,"ask5Volume":13324100,"bid10Volume":15429200,"ask10Volume":14522000,"rawPayload":"{\"stream\":\"xrpusdt@depth@100ms\",\"data\":{\"e\":\"depthUpdate\",\"E\":1784430143857,\"s\":\"XRPUSDT\",\"U\":752705199,\"u\":752705216,\"b\":[[\"1.09620000\",\"1393.50000000\"],[\"1.09600000\",\"3837.70000000\"],[\"1.09590000\",\"1358.20000000\"],[\"1.09550000\",\"2074.70000000\"],[\"1.09460000\",\"0.00000000\"],[\"1.09450000\",\"15381.80000000\"],[\"1.09310000\",\"15832.20000000\"],[\"1.09150000\",\"52674.00000000\"],[\"1.09130000\",\"0.00000000\"]],\"a\":[[\"1.09660000\",\"2251.60000000\"],[\"1.09670000\",\"1849.30000000\"],[\"1.09800000\",\"13008.80000000\"],[\"1.10000000\",\"0.00000000\"]]}}"}
{"mode":"v10-framework-compare","workers":4,"sequenceNumber":121,"symbol":"ETHUSDT","exchangeEventTimeMillis":1784430143957,"localReceivedEpochMillis":1784430143946,"topSpreadTicks":-24,"bid5Volume":5082,"ask5Volume":4076,"bid10Volume":8942,"ask10Volume":8798,"rawPayload":"{\"stream\":\"ethusdt@depth@100ms\",\"data\":{\"e\":\"depthUpdate\",\"E\":1784430143957,\"s\":\"ETHUSDT\",\"U\":2806177889,\"u\":2806177890,\"b\":[[\"1862.64000000\",\"9.69270000\"]],\"a\":[[\"1871.94000000\",\"0.40300000\"]]}}"}
{"mode":"v10-framework-compare","workers":4,"sequenceNumber":122,"symbol":"XRPUSDT","exchangeEventTimeMillis":1784430143957,"localReceivedEpochMillis":1784430143947,"topSpreadTicks":2,"bid5Volume":21212500,"ask5Volume":403700,"bid10Volume":31491700,"ask10Volume":1513200,"rawPayload":"{\"stream\":\"xrpusdt@depth@100ms\",\"data\":{\"e\":\"depthUpdate\",\"E\":1784430143957,\"s\":\"XRPUSDT\",\"U\":752705217,\"u\":752705220,\"b\":[[\"1.09620000\",\"1347.90000000\"],[\"1.09570000\",\"2715.90000000\"],[\"1.09130000\",\"16062.50000000\"]],\"a\":[[\"1.09640000\",\"0.00000000\"]]}}"}
{"mode":"v10-framework-compare","workers":4,"sequenceNumber":123,"symbol":"BTCUSDT","exchangeEventTimeMillis":1784430144257,"localReceivedEpochMillis":1784430144247,"topSpreadTicks":302,"bid5Volume":164,"ask5Volume":148,"bid10Volume":327,"ask10Volume":297,"rawPayload":"{\"stream\":\"btcusdt@depth@100ms\",\"data\":{\"e\":\"depthUpdate\",\"E\":1784430144257,\"s\":\"BTCUSDT\",\"U\":3244441233,\"u\":3244441233,\"b\":[[\"64794.21000000\",\"0.00079000\"]],\"a\":[]}}"}
{"mode":"v10-framework-compare","workers":4,"sequenceNumber":124,"symbol":"XRPUSDT","exchangeEventTimeMillis":1784430144257,"localReceivedEpochMillis":1784430144247,"topSpreadTicks":2,"bid5Volume":12045800,"ask5Volume":403700,"bid10Volume":22325000,"ask10Volume":1513200,"rawPayload":"{\"stream\":\"xrpusdt@depth@100ms\",\"data\":{\"e\":\"depthUpdate\",\"E\":1784430144257,\"s\":\"XRPUSDT\",\"U\":752705221,\"u\":752705226,\"b\":[[\"1.09600000\",\"3600.50000000\"],[\"1.09590000\",\"1595.40000000\"],[\"1.09560000\",\"0.00000000\"],[\"1.09550000\",\"4594.00000000\"],[\"1.09500000\",\"267.40000000\"],[\"1.09480000\",\"6895.80000000\"]],\"a\":[[\"1.09660000\",\"2488.70000000\"],[\"1.09670000\",\"1612.30000000\"],[\"1.09700000\",\"5084.70000000\"],[\"1.09710000\",\"2213.00000000\"],[\"1.09770000\",\"6878.50000000\"],[\"1.09790000\",\"0.00000000\"]]}}"}
{"mode":"v10-framework-compare","workers":4,"sequenceNumber":125,"symbol":"SOLUSDT","exchangeEventTimeMillis":1784430144357,"localReceivedEpochMillis":1784430144346,"topSpreadTicks":-2,"bid5Volume":183492,"ask5Volume":214878,"bid10Volume":443778,"ask10Volume":1046486,"rawPayload":"{\"stream\":\"solusdt@depth@100ms\",\"data\":{\"e\":\"depthUpdate\",\"E\":1784430144357,\"s\":\"SOLUSDT\",\"U\":1609579918,\"u\":1609579921,\"b\":[],\"a\":[[\"76.24000000\",\"113.27300000\"],[\"76.25000000\",\"43.90900000\"]]}}"}
{"mode":"v10-framework-compare","workers":4,"sequenceNumber":126,"symbol":"SOLUSDT","exchangeEventTimeMillis":1784430144558,"localReceivedEpochMillis":1784430144547,"topSpreadTicks":-2,"bid5Volume":183492,"ask5Volume":215257,"bid10Volume":443778,"ask10Volume":1046865,"rawPayload":"{\"stream\":\"solusdt@depth@100ms\",\"data\":{\"e\":\"depthUpdate\",\"E\":1784430144558,\"s\":\"SOLUSDT\",\"U\":1609579922,\"u\":1609579925,\"b\":[],\"a\":[[\"76.24000000\",\"113.27300000\"],[\"76.25000000\",\"44.28800000\"]]}}"}
{"mode":"v10-framework-compare","workers":4,"sequenceNumber":127,"symbol":"ETHUSDT","exchangeEventTimeMillis":1784430144658,"localReceivedEpochMillis":1784430144646,"topSpreadTicks":-24,"bid5Volume":5082,"ask5Volume":4076,"bid10Volume":8942,"ask10Volume":8798,"rawPayload":"{\"stream\":\"ethusdt@depth@100ms\",\"data\":{\"e\":\"depthUpdate\",\"E\":1784430144658,\"s\":\"ETHUSDT\",\"U\":2806177891,\"u\":2806177892,\"b\":[[\"1869.90000000\",\"1.01580000\"],[\"1869.83000000\",\"0.00000000\"]],\"a\":[]}}"}
{"mode":"v10-framework-compare","workers":4,"sequenceNumber":128,"symbol":"XRPUSDT","exchangeEventTimeMillis":1784430144858,"localReceivedEpochMillis":1784430144847,"topSpreadTicks":0,"bid5Volume":6543600,"ask5Volume":1560000,"bid10Volume":16822800,"ask10Volume":2757900,"rawPayload":"{\"stream\":\"xrpusdt@depth@100ms\",\"data\":{\"e\":\"depthUpdate\",\"E\":1784430144858,\"s\":\"XRPUSDT\",\"U\":752705227,\"u\":752705230,\"b\":[[\"1.09620000\",\"0.00000000\"],[\"1.09610000\",\"1393.60000000\"]],\"a\":[[\"1.09640000\",\"45.50000000\"],[\"1.09650000\",\"3708.10000000\"],[\"1.09660000\",\"1244.70000000\"]]}}"}
{"mode":"v10-framework-compare","workers":4,"sequenceNumber":129,"symbol":"SOLUSDT","exchangeEventTimeMillis":1784430144958,"localReceivedEpochMillis":1784430144947,"topSpreadTicks":-2,"bid5Volume":183492,"ask5Volume":199742,"bid10Volume":443778,"ask10Volume":1031350,"rawPayload":"{\"stream\":\"solusdt@depth@100ms\",\"data\":{\"e\":\"depthUpdate\",\"E\":1784430144958,\"s\":\"SOLUSDT\",\"U\":1609579926,\"u\":1609579927,\"b\":[],\"a\":[[\"76.21000000\",\"21.49700000\"]]}}"}
{"mode":"v10-framework-compare","workers":4,"sequenceNumber":130,"symbol":"SOLUSDT","exchangeEventTimeMillis":1784430145058,"localReceivedEpochMillis":1784430145047,"topSpreadTicks":-2,"bid5Volume":184377,"ask5Volume":200189,"bid10Volume":444663,"ask10Volume":1031797,"rawPayload":"{\"stream\":\"solusdt@depth@100ms\",\"data\":{\"e\":\"depthUpdate\",\"E\":1784430145058,\"s\":\"SOLUSDT\",\"U\":1609579928,\"u\":1609579931,\"b\":[[\"76.20000000\",\"33.01700000\"]],\"a\":[[\"76.24000000\",\"127.81300000\"],[\"76.25000000\",\"30.19500000\"]]}}"}
{"mode":"v10-framework-compare","workers":4,"sequenceNumber":131,"symbol":"BTCUSDT","exchangeEventTimeMillis":1784430145158,"localReceivedEpochMillis":1784430145148,"topSpreadTicks":302,"bid5Volume":154,"ask5Volume":148,"bid10Volume":482,"ask10Volume":297,"rawPayload":"{\"stream\":\"btcusdt@depth@100ms\",\"data\":{\"e\":\"depthUpdate\",\"E\":1784430145158,\"s\":\"BTCUSDT\",\"U\":3244441234,\"u\":3244441234,\"b\":[[\"64797.20000000\",\"0.00000000\"]],\"a\":[]}}"}
{"mode":"v10-framework-compare","workers":4,"sequenceNumber":132,"symbol":"SOLUSDT","exchangeEventTimeMillis":1784430145258,"localReceivedEpochMillis":1784430145248,"topSpreadTicks":-2,"bid5Volume":184377,"ask5Volume":199464,"bid10Volume":444663,"ask10Volume":1031072,"rawPayload":"{\"stream\":\"solusdt@depth@100ms\",\"data\":{\"e\":\"depthUpdate\",\"E\":1784430145258,\"s\":\"SOLUSDT\",\"U\":1609579932,\"u\":1609579933,\"b\":[],\"a\":[[\"76.24000000\",\"113.27300000\"],[\"76.25000000\",\"44.01000000\"]]}}"}
{"mode":"v10-framework-compare","workers":4,"sequenceNumber":133,"symbol":"BTCUSDT","exchangeEventTimeMillis":1784430145358,"localReceivedEpochMillis":1784430145349,"topSpreadTicks":302,"bid5Volume":154,"ask5Volume":148,"bid10Volume":482,"ask10Volume":297,"rawPayload":"{\"stream\":\"btcusdt@depth@100ms\",\"data\":{\"e\":\"depthUpdate\",\"E\":1784430145358,\"s\":\"BTCUSDT\",\"U\":3244441235,\"u\":3244441235,\"b\":[],\"a\":[[\"81055.16000000\",\"0.00045000\"]]}}"}
{"mode":"v10-framework-compare","workers":4,"sequenceNumber":134,"symbol":"XRPUSDT","exchangeEventTimeMillis":1784430145358,"localReceivedEpochMillis":1784430145349,"topSpreadTicks":0,"bid5Volume":6468100,"ask5Volume":1560000,"bid10Volume":16747300,"ask10Volume":2757900,"rawPayload":"{\"stream\":\"xrpusdt@depth@100ms\",\"data\":{\"e\":\"depthUpdate\",\"E\":1784430145358,\"s\":\"XRPUSDT\",\"U\":752705231,\"u\":752705232,\"b\":[[\"1.09610000\",\"3675.90000000\"],[\"1.09600000\",\"1318.10000000\"]],\"a\":[]}}"}
{"mode":"v10-framework-compare","workers":4,"sequenceNumber":135,"symbol":"BNBUSDT","exchangeEventTimeMillis":1784430145458,"localReceivedEpochMillis":1784430145448,"topSpreadTicks":4,"bid5Volume":5006,"ask5Volume":6281,"bid10Volume":15253,"ask10Volume":257272,"rawPayload":"{\"stream\":\"bnbusdt@depth@100ms\",\"data\":{\"e\":\"depthUpdate\",\"E\":1784430145458,\"s\":\"BNBUSDT\",\"U\":1236331323,\"u\":1236331326,\"b\":[[\"570.41000000\",\"0.00000000\"],[\"570.40000000\",\"1.74200000\"]],\"a\":[[\"570.56000000\",\"1.59500000\"],[\"570.58000000\",\"1.71100000\"],[\"570.59000000\",\"0.00000000\"],[\"570.60000000\",\"0.87400000\"]]}}"}
{"mode":"v10-framework-compare","workers":4,"sequenceNumber":136,"symbol":"XRPUSDT","exchangeEventTimeMillis":1784430145458,"localReceivedEpochMillis":1784430145449,"topSpreadTicks":2,"bid5Volume":6468100,"ask5Volume":403700,"bid10Volume":16747300,"ask10Volume":1513200,"rawPayload":"{\"stream\":\"xrpusdt@depth@100ms\",\"data\":{\"e\":\"depthUpdate\",\"E\":1784430145458,\"s\":\"XRPUSDT\",\"U\":752705233,\"u\":752705233,\"b\":[],\"a\":[[\"1.09640000\",\"0.00000000\"]]}}"}
{"mode":"v10-framework-compare","workers":4,"sequenceNumber":137,"symbol":"ETHUSDT","exchangeEventTimeMillis":1784430145858,"localReceivedEpochMillis":1784430145848,"topSpreadTicks":-24,"bid5Volume":5082,"ask5Volume":4076,"bid10Volume":8942,"ask10Volume":8798,"rawPayload":"{\"stream\":\"ethusdt@depth@100ms\",\"data\":{\"e\":\"depthUpdate\",\"E\":1784430145858,\"s\":\"ETHUSDT\",\"U\":2806177893,\"u\":2806177894,\"b\":[[\"1869.95000000\",\"0.97850000\"],[\"1869.90000000\",\"0.00000000\"]],\"a\":[]}}"}
{"mode":"v10-framework-compare","workers":4,"sequenceNumber":138,"symbol":"XRPUSDT","exchangeEventTimeMillis":1784430145858,"localReceivedEpochMillis":1784430145848,"topSpreadTicks":0,"bid5Volume":6468100,"ask5Volume":360800,"bid10Volume":16747300,"ask10Volume":1558700,"rawPayload":"{\"stream\":\"xrpusdt@depth@100ms\",\"data\":{\"e\":\"depthUpdate\",\"E\":1784430145858,\"s\":\"XRPUSDT\",\"U\":752705234,\"u\":752705234,\"b\":[],\"a\":[[\"1.09630000\",\"45.50000000\"]]}}"}
{"mode":"v10-framework-compare","workers":4,"sequenceNumber":139,"symbol":"SOLUSDT","exchangeEventTimeMillis":1784430145958,"localReceivedEpochMillis":1784430145947,"topSpreadTicks":-2,"bid5Volume":184382,"ask5Volume":199464,"bid10Volume":444668,"ask10Volume":1031072,"rawPayload":"{\"stream\":\"solusdt@depth@100ms\",\"data\":{\"e\":\"depthUpdate\",\"E\":1784430145958,\"s\":\"SOLUSDT\",\"U\":1609579934,\"u\":1609579935,\"b\":[[\"76.19000000\",\"3.96600000\"],[\"76.18000000\",\"37.08500000\"]],\"a\":[]}}"}
{"mode":"v10-framework-compare","workers":4,"sequenceNumber":140,"symbol":"ETHUSDT","exchangeEventTimeMillis":1784430145958,"localReceivedEpochMillis":1784430145947,"topSpreadTicks":-24,"bid5Volume":5082,"ask5Volume":4076,"bid10Volume":8728,"ask10Volume":8798,"rawPayload":"{\"stream\":\"ethusdt@depth@100ms\",\"data\":{\"e\":\"depthUpdate\",\"E\":1784430145958,\"s\":\"ETHUSDT\",\"U\":2806177895,\"u\":2806177901,\"b\":[[\"1870.13000000\",\"0.00000000\"],[\"1870.12000000\",\"0.00000000\"],[\"1869.97000000\",\"1.33780000\"],[\"1863.10000000\",\"0.00000000\"],[\"1863.09000000\",\"7.26880000\"],[\"1863.04000000\",\"0.00000000\"],[\"1861.78000000\",\"0.00000000\"]],\"a\":[]}}"}
{"mode":"v10-framework-compare","workers":4,"sequenceNumber":141,"symbol":"BTCUSDT","exchangeEventTimeMillis":1784430145958,"localReceivedEpochMillis":1784430145947,"topSpreadTicks":185,"bid5Volume":165,"ask5Volume":148,"bid10Volume":493,"ask10Volume":297,"rawPayload":"{\"stream\":\"btcusdt@depth@100ms\",\"data\":{\"e\":\"depthUpdate\",\"E\":1784430145958,\"s\":\"BTCUSDT\",\"U\":3244441236,\"u\":3244441256,\"b\":[[\"64799.71000000\",\"0.00000000\"],[\"64795.98000000\",\"0.03328000\"],[\"64793.28000000\",\"0.04000000\"],[\"64788.72000000\",\"0.00000000\"],[\"64784.61000000\",\"0.00000000\"],[\"64782.12000000\",\"0.00401000\"],[\"64744.44000000\",\"0.00000000\"],[\"64538.30000000\",\"0.26553000\"]],\"a\":[[\"64804.80000000\",\"0.03088000\"],[\"64804.81000000\",\"0.00401000\"],[\"64805.97000000\",\"0.00000000\"],[\"64806.69000000\",\"0.00000000\"],[\"64813.99000000\",\"0.00000000\"],[\"64815.18000000\",\"0.04258000\"],[\"64815.43000000\",\"0.03287000\"],[\"64815.84000000\",\"0.00159000\"],[\"64816.64000000\",\"0.00000000\"],[\"64817.67000000\",\"0.00000000\"],[\"64819.17000000\",\"0.00000000\"],[\"64851.47000000\",\"0.26522000\"],[\"64857.43000000\",\"0.00000000\"],[\"64885.63000000\",\"0.00000000\"],[\"64914.49000000\",\"0.00011000\"]]}}"}
{"mode":"v10-framework-compare","workers":4,"sequenceNumber":142,"symbol":"SOLUSDT","exchangeEventTimeMillis":1784430146059,"localReceivedEpochMillis":1784430146048,"topSpreadTicks":-2,"bid5Volume":184382,"ask5Volume":199065,"bid10Volume":444668,"ask10Volume":1030673,"rawPayload":"{\"stream\":\"solusdt@depth@100ms\",\"data\":{\"e\":\"depthUpdate\",\"E\":1784430146059,\"s\":\"SOLUSDT\",\"U\":1609579936,\"u\":1609579937,\"b\":[],\"a\":[[\"76.24000000\",\"126.68900000\"],[\"76.25000000\",\"30.19500000\"]]}}"}
{"mode":"v10-framework-compare","workers":4,"sequenceNumber":143,"symbol":"ETHUSDT","exchangeEventTimeMillis":1784430146059,"localReceivedEpochMillis":1784430146048,"topSpreadTicks":-24,"bid5Volume":5082,"ask5Volume":4076,"bid10Volume":9926,"ask10Volume":8798,"rawPayload":"{\"stream\":\"ethusdt@depth@100ms\",\"data\":{\"e\":\"depthUpdate\",\"E\":1784430146059,\"s\":\"ETHUSDT\",\"U\":2806177902,\"u\":2806177904,\"b\":[[\"1870.10000000\",\"1.33770000\"],[\"1869.97000000\",\"0.00000000\"],[\"1869.63000000\",\"0.10500000\"]],\"a\":[]}}"}
{"mode":"v10-framework-compare","workers":4,"sequenceNumber":144,"symbol":"BTCUSDT","exchangeEventTimeMillis":1784430146059,"localReceivedEpochMillis":1784430146048,"topSpreadTicks":185,"bid5Volume":165,"ask5Volume":148,"bid10Volume":328,"ask10Volume":297,"rawPayload":"{\"stream\":\"btcusdt@depth@100ms\",\"data\":{\"e\":\"depthUpdate\",\"E\":1784430146059,\"s\":\"BTCUSDT\",\"U\":3244441257,\"u\":3244441262,\"b\":[[\"64788.85000000\",\"0.03088000\"],[\"64786.85000000\",\"0.00000000\"]],\"a\":[[\"64813.17000000\",\"0.00160000\"],[\"64815.84000000\",\"0.00000000\"],[\"64874.90000000\",\"0.01187000\"]]}}"}
{"mode":"v10-framework-compare","workers":4,"sequenceNumber":145,"symbol":"SOLUSDT","exchangeEventTimeMillis":1784430146159,"localReceivedEpochMillis":1784430146149,"topSpreadTicks":-2,"bid5Volume":184382,"ask5Volume":200104,"bid10Volume":444668,"ask10Volume":1031712,"rawPayload":"{\"stream\":\"solusdt@depth@100ms\",\"data\":{\"e\":\"depthUpdate\",\"E\":1784430146159,\"s\":\"SOLUSDT\",\"U\":1609579938,\"u\":1609579939,\"b\":[],\"a\":[[\"76.24000000\",\"113.27300000\"],[\"76.25000000\",\"44.65000000\"]]}}"}
{"mode":"v10-framework-compare","workers":4,"sequenceNumber":146,"symbol":"ETHUSDT","exchangeEventTimeMillis":1784430146159,"localReceivedEpochMillis":1784430146152,"topSpreadTicks":-24,"bid5Volume":5082,"ask5Volume":4076,"bid10Volume":9926,"ask10Volume":8798,"rawPayload":"{\"stream\":\"ethusdt@depth@100ms\",\"data\":{\"e\":\"depthUpdate\",\"E\":1784430146159,\"s\":\"ETHUSDT\",\"U\":2806177905,\"u\":2806177907,\"b\":[[\"1869.95000000\",\"0.00000000\"],[\"1869.88000000\",\"2.62690000\"],[\"1863.09000000\",\"0.00000000\"]],\"a\":[]}}"}
{"mode":"v10-framework-compare","workers":4,"sequenceNumber":147,"symbol":"BTCUSDT","exchangeEventTimeMillis":1784430146159,"localReceivedEpochMillis":1784430146152,"topSpreadTicks":185,"bid5Volume":165,"ask5Volume":148,"bid10Volume":328,"ask10Volume":297,"rawPayload":"{\"stream\":\"btcusdt@depth@100ms\",\"data\":{\"e\":\"depthUpdate\",\"E\":1784430146159,\"s\":\"BTCUSDT\",\"U\":3244441263,\"u\":3244441270,\"b\":[[\"64794.21000000\",\"0.00000000\"]],\"a\":[[\"64809.78000000\",\"0.00000000\"],[\"64813.17000000\",\"0.00158000\"],[\"64813.81000000\",\"0.00000000\"],[\"64858.34000000\",\"0.20585000\"],[\"64923.39000000\",\"0.00000000\"]]}}"}
{"mode":"v10-framework-compare","workers":4,"sequenceNumber":148,"symbol":"BTCUSDT","exchangeEventTimeMillis":1784430146259,"localReceivedEpochMillis":1784430146248,"topSpreadTicks":185,"bid5Volume":165,"ask5Volume":148,"bid10Volume":328,"ask10Volume":297,"rawPayload":"{\"stream\":\"btcusdt@depth@100ms\",\"data\":{\"e\":\"depthUpdate\",\"E\":1784430146259,\"s\":\"BTCUSDT\",\"U\":3244441271,\"u\":3244441272,\"b\":[[\"64792.11000000\",\"0.00077000\"]],\"a\":[[\"64807.88000000\",\"0.00079000\"]]}}"}
{"mode":"v10-framework-compare","workers":4,"sequenceNumber":149,"symbol":"ETHUSDT","exchangeEventTimeMillis":1784430146259,"localReceivedEpochMillis":1784430146248,"topSpreadTicks":-24,"bid5Volume":5082,"ask5Volume":4076,"bid10Volume":9926,"ask10Volume":8798,"rawPayload":"{\"stream\":\"ethusdt@depth@100ms\",\"data\":{\"e\":\"depthUpdate\",\"E\":1784430146259,\"s\":\"ETHUSDT\",\"U\":2806177908,\"u\":2806177912,\"b\":[[\"1869.93000000\",\"1.00100000\"],[\"1869.88000000\",\"1.63970000\"],[\"1861.77000000\",\"9.26890000\"]],\"a\":[[\"1877.99000000\",\"7.22310000\"],[\"1879.67000000\",\"0.00000000\"]]}}"}
{"mode":"v10-framework-compare","workers":4,"sequenceNumber":150,"symbol":"BTCUSDT","exchangeEventTimeMillis":1784430146359,"localReceivedEpochMillis":1784430146348,"topSpreadTicks":185,"bid5Volume":167,"ask5Volume":148,"bid10Volume":328,"ask10Volume":297,"rawPayload":"{\"stream\":\"btcusdt@depth@100ms\",\"data\":{\"e\":\"depthUpdate\",\"E\":1784430146359,\"s\":\"BTCUSDT\",\"U\":3244441273,\"u\":3244441279,\"b\":[[\"64790.88000000\",\"0.00000000\"],[\"64789.18000000\",\"0.03088000\"],[\"64788.85000000\",\"0.00000000\"],[\"64742.06000000\",\"0.00000000\"],[\"64741.13000000\",\"0.20551000\"],[\"64538.30000000\",\"0.00000000\"]],\"a\":[]}}"}
{"mode":"v10-framework-compare","workers":4,"sequenceNumber":151,"symbol":"SOLUSDT","exchangeEventTimeMillis":1784430146459,"localReceivedEpochMillis":1784430146448,"topSpreadTicks":-2,"bid5Volume":184382,"ask5Volume":199801,"bid10Volume":444668,"ask10Volume":1031409,"rawPayload":"{\"stream\":\"solusdt@depth@100ms\",\"data\":{\"e\":\"depthUpdate\",\"E\":1784430146459,\"s\":\"SOLUSDT\",\"U\":1609579940,\"u\":1609579941,\"b\":[],\"a\":[[\"76.24000000\",\"127.42500000\"],[\"76.25000000\",\"30.19500000\"]]}}"}
{"mode":"v10-framework-compare","workers":4,"sequenceNumber":152,"symbol":"ETHUSDT","exchangeEventTimeMillis":1784430146459,"localReceivedEpochMillis":1784430146448,"topSpreadTicks":-24,"bid5Volume":5082,"ask5Volume":4076,"bid10Volume":9926,"ask10Volume":8798,"rawPayload":"{\"stream\":\"ethusdt@depth@100ms\",\"data\":{\"e\":\"depthUpdate\",\"E\":1784430146459,\"s\":\"ETHUSDT\",\"U\":2806177913,\"u\":2806177916,\"b\":[[\"1869.93000000\",\"0.00000000\"],[\"1869.87000000\",\"1.00630000\"],[\"1863.02000000\",\"0.00000000\"],[\"1861.71000000\",\"9.15690000\"]],\"a\":[]}}"}
{"mode":"v10-framework-compare","workers":4,"sequenceNumber":153,"symbol":"BTCUSDT","exchangeEventTimeMillis":1784430146459,"localReceivedEpochMillis":1784430146448,"topSpreadTicks":185,"bid5Volume":165,"ask5Volume":148,"bid10Volume":328,"ask10Volume":297,"rawPayload":"{\"stream\":\"btcusdt@depth@100ms\",\"data\":{\"e\":\"depthUpdate\",\"E\":1784430146459,\"s\":\"BTCUSDT\",\"U\":3244441280,\"u\":3244441281,\"b\":[[\"64789.18000000\",\"0.00000000\"],[\"64787.35000000\",\"0.03088000\"]],\"a\":[]}}"}
{"mode":"v10-framework-compare","workers":4,"sequenceNumber":154,"symbol":"BTCUSDT","exchangeEventTimeMillis":1784430146559,"localReceivedEpochMillis":1784430146548,"topSpreadTicks":-72,"bid5Volume":165,"ask5Volume":148,"bid10Volume":328,"ask10Volume":297,"rawPayload":"{\"stream\":\"btcusdt@depth@100ms\",\"data\":{\"e\":\"depthUpdate\",\"E\":1784430146559,\"s\":\"BTCUSDT\",\"U\":3244441282,\"u\":3244441292,\"b\":[[\"64792.11000000\",\"0.00000000\"],[\"64782.12000000\",\"0.00000000\"],[\"64779.54000000\",\"0.00401000\"],[\"64774.25000000\",\"0.00000000\"],[\"64769.17000000\",\"0.04261000\"],[\"64741.13000000\",\"0.00000000\"],[\"64740.50000000\",\"0.00000000\"],[\"64738.65000000\",\"0.20725000\"],[\"64732.88000000\",\"0.26569000\"]],\"a\":[[\"64802.23000000\",\"0.00401000\"],[\"64804.81000000\",\"0.00000000\"],[\"64807.88000000\",\"0.00000000\"],[\"64812.60000000\",\"0.04258000\"],[\"64815.18000000\",\"0.00000000\"],[\"64855.25000000\",\"0.20571000\"],[\"64921.62000000\",\"0.00000000\"]]}}"}
{"mode":"v10-framework-compare","workers":4,"sequenceNumber":155,"symbol":"BTCUSDT","exchangeEventTimeMillis":1784430146659,"localReceivedEpochMillis":1784430146648,"topSpreadTicks":-72,"bid5Volume":167,"ask5Volume":148,"bid10Volume":328,"ask10Volume":297,"rawPayload":"{\"stream\":\"btcusdt@depth@100ms\",\"data\":{\"e\":\"depthUpdate\",\"E\":1784430146659,\"s\":\"BTCUSDT\",\"U\":3244441293,\"u\":3244441295,\"b\":[[\"64788.94000000\",\"0.00000000\"],[\"64785.93000000\",\"0.02800000\"],[\"64539.78000000\",\"0.26367000\"]],\"a\":[[\"64805.35000000\",\"0.03020000\"],[\"64806.06000000\",\"0.00000000\"]]}}"}
{"mode":"v10-framework-compare","workers":4,"sequenceNumber":156,"symbol":"ETHUSDT","exchangeEventTimeMillis":1784430146659,"localReceivedEpochMillis":1784430146648,"topSpreadTicks":-24,"bid5Volume":5082,"ask5Volume":4076,"bid10Volume":9926,"ask10Volume":8798,"rawPayload":"{\"stream\":\"ethusdt@depth@100ms\",\"data\":{\"e\":\"depthUpdate\",\"E\":1784430146659,\"s\":\"ETHUSDT\",\"U\":2806177917,\"u\":2806177921,\"b\":[[\"1869.87000000\",\"0.00000000\"],[\"1869.82000000\",\"1.02270000\"],[\"1861.65000000\",\"9.30860000\"]],\"a\":[[\"1877.93000000\",\"7.25010000\"],[\"1879.61000000\",\"0.00000000\"]]}}"}
{"mode":"v10-framework-compare","workers":4,"sequenceNumber":157,"symbol":"ETHUSDT","exchangeEventTimeMillis":1784430146759,"localReceivedEpochMillis":1784430146748,"topSpreadTicks":-24,"bid5Volume":5082,"ask5Volume":4240,"bid10Volume":8426,"ask10Volume":9806,"rawPayload":"{\"stream\":\"ethusdt@depth@100ms\",\"data\":{\"e\":\"depthUpdate\",\"E\":1784430146759,\"s\":\"ETHUSDT\",\"U\":2806177922,\"u\":2806177933,\"b\":[[\"1870.14000000\",\"0.00000000\"],[\"1870.03000000\",\"0.00000000\"],[\"1869.89000000\",\"0.00000000\"],[\"1869.75000000\",\"1.09310000\"],[\"1869.66000000\",\"2.78830000\"],[\"1869.28000000\",\"1.63970000\"],[\"1862.97000000\",\"0.00000000\"],[\"1862.91000000\",\"0.00000000\"]],\"a\":[[\"1870.87000000\",\"1.63970000\"],[\"1871.19000000\",\"1.63970000\"],[\"1871.78000000\",\"0.00000000\"],[\"1871.83000000\",\"0.00000000\"]]}}"}
{"mode":"v10-framework-compare","workers":4,"sequenceNumber":158,"symbol":"BTCUSDT","exchangeEventTimeMillis":1784430146759,"localReceivedEpochMillis":1784430146748,"topSpreadTicks":-72,"bid5Volume":157,"ask5Volume":148,"bid10Volume":322,"ask10Volume":297,"rawPayload":"{\"stream\":\"btcusdt@depth@100ms\",\"data\":{\"e\":\"depthUpdate\",\"E\":1784430146759,\"s\":\"BTCUSDT\",\"U\":3244441296,\"u\":3244441302,\"b\":[[\"64789.06000000\",\"0.00000000\"],[\"64786.48000000\",\"0.00000000\"],[\"64783.00000000\",\"0.03861000\"],[\"64779.55000000\",\"0.00645000\"],[\"64620.45000000\",\"0.00000000\"]],\"a\":[[\"64806.31000000\",\"0.03860000\"],[\"64811.95000000\",\"0.00000000\"]]}}"}
{"mode":"v10-framework-compare","workers":4,"sequenceNumber":159,"symbol":"XRPUSDT","exchangeEventTimeMillis":1784430146759,"localReceivedEpochMillis":1784430146748,"topSpreadTicks":0,"bid5Volume":6468100,"ask5Volume":1741800,"bid10Volume":16747300,"ask10Volume":2939700,"rawPayload":"{\"stream\":\"xrpusdt@depth@100ms\",\"data\":{\"e\":\"depthUpdate\",\"E\":1784430146759,\"s\":\"XRPUSDT\",\"U\":752705235,\"u\":752705236,\"b\":[],\"a\":[[\"1.09640000\",\"2281.80000000\"],[\"1.09650000\",\"1426.50000000\"]]}}"}
{"mode":"v10-framework-compare","workers":4,"sequenceNumber":160,"symbol":"BTCUSDT","exchangeEventTimeMillis":1784430146859,"localReceivedEpochMillis":1784430146848,"topSpreadTicks":-72,"bid5Volume":188,"ask5Volume":148,"bid10Volume":477,"ask10Volume":297,"rawPayload":"{\"stream\":\"btcusdt@depth@100ms\",\"data\":{\"e\":\"depthUpdate\",\"E\":1784430146859,\"s\":\"BTCUSDT\",\"U\":3244441303,\"u\":3244441304,\"b\":[[\"64793.28000000\",\"0.00000000\"],[\"64541.18000000\",\"0.00022000\"]],\"a\":[]}}"}
{"mode":"v10-framework-compare","workers":4,"sequenceNumber":161,"symbol":"XRPUSDT","exchangeEventTimeMillis":1784430146859,"localReceivedEpochMillis":1784430146848,"topSpreadTicks":2,"bid5Volume":6468100,"ask5Volume":403700,"bid10Volume":16747300,"ask10Volume":1513200,"rawPayload":"{\"stream\":\"xrpusdt@depth@100ms\",\"data\":{\"e\":\"depthUpdate\",\"E\":1784430146859,\"s\":\"XRPUSDT\",\"U\":752705237,\"u\":752705237,\"b\":[],\"a\":[[\"1.09630000\",\"0.00000000\"]]}}"}
{"mode":"v10-framework-compare","workers":4,"sequenceNumber":162,"symbol":"ETHUSDT","exchangeEventTimeMillis":1784430146959,"localReceivedEpochMillis":1784430146948,"topSpreadTicks":-24,"bid5Volume":5082,"ask5Volume":4240,"bid10Volume":8426,"ask10Volume":9806,"rawPayload":"{\"stream\":\"ethusdt@depth@100ms\",\"data\":{\"e\":\"depthUpdate\",\"E\":1784430146959,\"s\":\"ETHUSDT\",\"U\":2806177934,\"u\":2806177937,\"b\":[[\"1869.80000000\",\"0.00000000\"],[\"1869.72000000\",\"1.47610000\"],[\"1862.89000000\",\"7.28300000\"]],\"a\":[[\"1877.85000000\",\"7.20680000\"],[\"1879.54000000\",\"0.00000000\"]]}}"}
{"mode":"v10-framework-compare","workers":4,"sequenceNumber":163,"symbol":"SOLUSDT","exchangeEventTimeMillis":1784430147059,"localReceivedEpochMillis":1784430147048,"topSpreadTicks":-2,"bid5Volume":184382,"ask5Volume":199801,"bid10Volume":444668,"ask10Volume":1031409,"rawPayload":"{\"stream\":\"solusdt@depth@100ms\",\"data\":{\"e\":\"depthUpdate\",\"E\":1784430147059,\"s\":\"SOLUSDT\",\"U\":1609579942,\"u\":1609579942,\"b\":[],\"a\":[[\"76.23000000\",\"38.76500000\"],[\"76.24000000\",\"108.79000000\"]]}}"}
{"mode":"v10-framework-compare","workers":4,"sequenceNumber":164,"symbol":"ETHUSDT","exchangeEventTimeMillis":1784430147159,"localReceivedEpochMillis":1784430147149,"topSpreadTicks":-24,"bid5Volume":5082,"ask5Volume":4240,"bid10Volume":8426,"ask10Volume":9806,"rawPayload":"{\"stream\":\"ethusdt@depth@100ms\",\"data\":{\"e\":\"depthUpdate\",\"E\":1784430147159,\"s\":\"ETHUSDT\",\"U\":2806177938,\"u\":2806177940,\"b\":[[\"1869.87000000\",\"1.03970000\"],[\"1869.82000000\",\"0.00000000\"],[\"1861.59000000\",\"9.28820000\"]],\"a\":[]}}"}
{"mode":"v10-framework-compare","workers":4,"sequenceNumber":165,"symbol":"BTCUSDT","exchangeEventTimeMillis":1784430147159,"localReceivedEpochMillis":1784430147149,"topSpreadTicks":-72,"bid5Volume":188,"ask5Volume":148,"bid10Volume":477,"ask10Volume":297,"rawPayload":"{\"stream\":\"btcusdt@depth@100ms\",\"data\":{\"e\":\"depthUpdate\",\"E\":1784430147159,\"s\":\"BTCUSDT\",\"U\":3244441305,\"u\":3244441306,\"b\":[],\"a\":[[\"64812.53000000\",\"0.00158000\"],[\"64813.17000000\",\"0.00000000\"]]}}"}
{"mode":"v10-framework-compare","workers":4,"sequenceNumber":166,"symbol":"BTCUSDT","exchangeEventTimeMillis":1784430147259,"localReceivedEpochMillis":1784430147250,"topSpreadTicks":-138,"bid5Volume":188,"ask5Volume":148,"bid10Volume":477,"ask10Volume":296,"rawPayload":"{\"stream\":\"btcusdt@depth@100ms\",\"data\":{\"e\":\"depthUpdate\",\"E\":1784430147259,\"s\":\"BTCUSDT\",\"U\":3244441307,\"u\":3244441318,\"b\":[[\"64795.98000000\",\"0.00000000\"],[\"64793.26000000\",\"0.03333000\"],[\"64788.42000000\",\"0.00079000\"],[\"64698.37000000\",\"0.00000000\"]],\"a\":[[\"64801.57000000\",\"0.00401000\"],[\"64802.23000000\",\"0.00000000\"],[\"64804.19000000\",\"0.00077000\"],[\"64811.28000000\",\"0.00000000\"],[\"64811.46000000\",\"0.00161000\"],[\"64812.53000000\",\"0.00000000\"],[\"64812.73000000\",\"0.03172000\"],[\"64815.43000000\",\"0.00000000\"]]}}"}
{"mode":"v10-framework-compare","workers":4,"sequenceNumber":167,"symbol":"ETHUSDT","exchangeEventTimeMillis":1784430147259,"localReceivedEpochMillis":1784430147250,"topSpreadTicks":-24,"bid5Volume":5082,"ask5Volume":4240,"bid10Volume":8426,"ask10Volume":9806,"rawPayload":"{\"stream\":\"ethusdt@depth@100ms\",\"data\":{\"e\":\"depthUpdate\",\"E\":1784430147259,\"s\":\"ETHUSDT\",\"U\":2806177941,\"u\":2806177941,\"b\":[[\"1861.53000000\",\"9.24840000\"]],\"a\":[]}}"}
{"mode":"v10-framework-compare","workers":4,"sequenceNumber":168,"symbol":"BNBUSDT","exchangeEventTimeMillis":1784430147459,"localReceivedEpochMillis":1784430147449,"topSpreadTicks":4,"bid5Volume":5006,"ask5Volume":6283,"bid10Volume":15253,"ask10Volume":257274,"rawPayload":"{\"stream\":\"bnbusdt@depth@100ms\",\"data\":{\"e\":\"depthUpdate\",\"E\":1784430147459,\"s\":\"BNBUSDT\",\"U\":1236331327,\"u\":1236331328,\"b\":[],\"a\":[[\"570.60000000\",\"0.00000000\"],[\"570.63000000\",\"0.87600000\"]]}}"}
{"mode":"v10-framework-compare","workers":4,"sequenceNumber":169,"symbol":"BTCUSDT","exchangeEventTimeMillis":1784430147559,"localReceivedEpochMillis":1784430147550,"topSpreadTicks":-317,"bid5Volume":188,"ask5Volume":148,"bid10Volume":477,"ask10Volume":296,"rawPayload":"{\"stream\":\"btcusdt@depth@100ms\",\"data\":{\"e\":\"depthUpdate\",\"E\":1784430147559,\"s\":\"BTCUSDT\",\"U\":3244441319,\"u\":3244441321,\"b\":[[\"64779.54000000\",\"0.00000000\"],[\"64777.09000000\",\"0.00401000\"]],\"a\":[[\"64799.78000000\",\"0.00401000\"],[\"64801.57000000\",\"0.00000000\"],[\"64810.14000000\",\"0.04258000\"],[\"64812.60000000\",\"0.00000000\"]]}}"}
{"mode":"v10-framework-compare","workers":4,"sequenceNumber":170,"symbol":"ETHUSDT","exchangeEventTimeMillis":1784430147559,"localReceivedEpochMillis":1784430147550,"topSpreadTicks":-24,"bid5Volume":5082,"ask5Volume":5686,"bid10Volume":10036,"ask10Volume":10922,"rawPayload":"{\"stream\":\"ethusdt@depth@100ms\",\"data\":{\"e\":\"depthUpdate\",\"E\":1784430147559,\"s\":\"ETHUSDT\",\"U\":2806177942,\"u\":2806177943,\"b\":[[\"1870.27000000\",\"0.00000000\"]],\"a\":[[\"1870.93000000\",\"0.00000000\"]]}}"}
{"mode":"v10-framework-compare","workers":4,"sequenceNumber":171,"symbol":"BTCUSDT","exchangeEventTimeMillis":1784430147760,"localReceivedEpochMillis":1784430147749,"topSpreadTicks":-317,"bid5Volume":188,"ask5Volume":148,"bid10Volume":477,"ask10Volume":296,"rawPayload":"{\"stream\":\"btcusdt@depth@100ms\",\"data\":{\"e\":\"depthUpdate\",\"E\":1784430147760,\"s\":\"BTCUSDT\",\"U\":3244441322,\"u\":3244441323,\"b\":[[\"64785.93000000\",\"0.00000000\"],[\"64783.34000000\",\"0.02800000\"]],\"a\":[[\"64803.20000000\",\"0.03020000\"],[\"64805.35000000\",\"0.00000000\"]]}}"}
{"mode":"v10-framework-compare","workers":4,"sequenceNumber":172,"symbol":"SOLUSDT","exchangeEventTimeMillis":1784430147860,"localReceivedEpochMillis":1784430147849,"topSpreadTicks":-2,"bid5Volume":184382,"ask5Volume":199801,"bid10Volume":444670,"ask10Volume":1031414,"rawPayload":"{\"stream\":\"solusdt@depth@100ms\",\"data\":{\"e\":\"depthUpdate\",\"E\":1784430147860,\"s\":\"SOLUSDT\",\"U\":1609579943,\"u\":1609579946,\"b\":[[\"76.19000000\",\"0.55400000\"],[\"76.18000000\",\"40.49700000\"],[\"76.16000000\",\"32.16500000\"],[\"76.15000000\",\"44.34900000\"]],\"a\":[[\"76.23000000\",\"42.17500000\"],[\"76.24000000\",\"105.38000000\"],[\"76.26000000\",\"36.19400000\"],[\"76.27000000\",\"0.00000000\"]]}}"}
{"mode":"v10-framework-compare","workers":4,"sequenceNumber":173,"symbol":"ETHUSDT","exchangeEventTimeMillis":1784430147860,"localReceivedEpochMillis":1784430147850,"topSpreadTicks":-24,"bid5Volume":5082,"ask5Volume":5686,"bid10Volume":10036,"ask10Volume":10922,"rawPayload":"{\"stream\":\"ethusdt@depth@100ms\",\"data\":{\"e\":\"depthUpdate\",\"E\":1784430147860,\"s\":\"ETHUSDT\",\"U\":2806177944,\"u\":2806177944,\"b\":[],\"a\":[[\"1871.13000000\",\"1.06180000\"],[\"1871.18000000\",\"0.00000000\"]]}}"}
{"mode":"v10-framework-compare","workers":4,"sequenceNumber":174,"symbol":"XRPUSDT","exchangeEventTimeMillis":1784430147860,"localReceivedEpochMillis":1784430147850,"topSpreadTicks":0,"bid5Volume":6468100,"ask5Volume":2642300,"bid10Volume":16747300,"ask10Volume":3840200,"rawPayload":"{\"stream\":\"xrpusdt@depth@100ms\",\"data\":{\"e\":\"depthUpdate\",\"E\":1784430147860,\"s\":\"XRPUSDT\",\"U\":752705238,\"u\":752705238,\"b\":[],\"a\":[[\"1.09640000\",\"2327.00000000\"]]}}"}
{"mode":"v10-framework-compare","workers":4,"sequenceNumber":175,"symbol":"ETHUSDT","exchangeEventTimeMillis":1784430147960,"localReceivedEpochMillis":1784430147949,"topSpreadTicks":-24,"bid5Volume":5082,"ask5Volume":5686,"bid10Volume":10036,"ask10Volume":10922,"rawPayload":"{\"stream\":\"ethusdt@depth@100ms\",\"data\":{\"e\":\"depthUpdate\",\"E\":1784430147960,\"s\":\"ETHUSDT\",\"U\":2806177945,\"u\":2806177945,\"b\":[],\"a\":[[\"1871.12000000\",\"1.06180000\"],[\"1871.13000000\",\"0.00000000\"]]}}"}
{"mode":"v10-framework-compare","workers":4,"sequenceNumber":176,"symbol":"XRPUSDT","exchangeEventTimeMillis":1784430147960,"localReceivedEpochMillis":1784430147949,"topSpreadTicks":0,"bid5Volume":30191600,"ask5Volume":13138900,"bid10Volume":40470800,"ask10Volume":14336800,"rawPayload":"{\"stream\":\"xrpusdt@depth@100ms\",\"data\":{\"e\":\"depthUpdate\",\"E\":1784430147960,\"s\":\"XRPUSDT\",\"U\":752705239,\"u\":752705246,\"b\":[[\"1.09510000\",\"4568.90000000\"],[\"1.09490000\",\"1321.80000000\"],[\"1.09450000\",\"12812.10000000\"],[\"1.09430000\",\"2569.70000000\"],[\"1.09380000\",\"15940.50000000\"],[\"1.09360000\",\"27100.40000000\"],[\"1.09250000\",\"16046.90000000\"],[\"1.09230000\",\"25041.60000000\"]],\"a\":[[\"1.09760000\",\"1302.20000000\"],[\"1.09780000\",\"4558.10000000\"],[\"1.09830000\",\"2475.80000000\"],[\"1.09850000\",\"12762.00000000\"],[\"1.09900000\",\"16953.80000000\"],[\"1.09920000\",\"12823.60000000\"],[\"1.10030000\",\"8699.40000000\"],[\"1.10050000\",\"0.00000000\"]]}}"}
{"mode":"v10-framework-compare","workers":4,"sequenceNumber":177,"symbol":"BTCUSDT","exchangeEventTimeMillis":1784430148060,"localReceivedEpochMillis":1784430148048,"topSpreadTicks":-317,"bid5Volume":188,"ask5Volume":148,"bid10Volume":477,"ask10Volume":296,"rawPayload":"{\"stream\":\"btcusdt@depth@100ms\",\"data\":{\"e\":\"depthUpdate\",\"E\":1784430148060,\"s\":\"BTCUSDT\",\"U\":3244441324,\"u\":3244441324,\"b\":[],\"a\":[[\"81055.16000000\",\"0.00060000\"]]}}"}
{"mode":"v10-framework-compare","workers":4,"sequenceNumber":178,"symbol":"BTCUSDT","exchangeEventTimeMillis":1784430148160,"localReceivedEpochMillis":1784430148150,"topSpreadTicks":-318,"bid5Volume":188,"ask5Volume":148,"bid10Volume":477,"ask10Volume":296,"rawPayload":"{\"stream\":\"btcusdt@depth@100ms\",\"data\":{\"e\":\"depthUpdate\",\"E\":1784430148160,\"s\":\"BTCUSDT\",\"U\":3244441325,\"u\":3244441326,\"b\":[],\"a\":[[\"64799.77000000\",\"0.03088000\"],[\"64804.80000000\",\"0.00000000\"]]}}"}
{"mode":"v10-framework-compare","workers":4,"sequenceNumber":179,"symbol":"SOLUSDT","exchangeEventTimeMillis":1784430148260,"localReceivedEpochMillis":1784430148249,"topSpreadTicks":-2,"bid5Volume":184382,"ask5Volume":201582,"bid10Volume":444670,"ask10Volume":1033195,"rawPayload":"{\"stream\":\"solusdt@depth@100ms\",\"data\":{\"e\":\"depthUpdate\",\"E\":1784430148260,\"s\":\"SOLUSDT\",\"U\":1609579947,\"u\":1609579948,\"b\":[],\"a\":[[\"76.23000000\",\"52.06500000\"],[\"76.24000000\",\"97.27100000\"]]}}"}
{"mode":"v10-framework-compare","workers":4,"sequenceNumber":180,"symbol":"ETHUSDT","exchangeEventTimeMillis":1784430148260,"localReceivedEpochMillis":1784430148250,"topSpreadTicks":-24,"bid5Volume":5127,"ask5Volume":4314,"bid10Volume":8471,"ask10Volume":9880,"rawPayload":"{\"stream\":\"ethusdt@depth@100ms\",\"data\":{\"e\":\"depthUpdate\",\"E\":1784430148260,\"s\":\"ETHUSDT\",\"U\":2806177946,\"u\":2806177958,\"b\":[[\"1870.33000000\",\"0.00000000\"],[\"1870.28000000\",\"1.17870000\"],[\"1870.10000000\",\"0.00000000\"],[\"1870.03000000\",\"0.02960000\"],[\"1869.92000000\",\"1.33780000\"],[\"1869.87000000\",\"0.00000000\"],[\"1869.80000000\",\"1.06990000\"],[\"1862.89000000\",\"0.00000000\"]],\"a\":[[\"1870.68000000\",\"0.02940000\"],[\"1870.85000000\",\"1.17170000\"],[\"1870.90000000\",\"0.00000000\"],[\"1877.82000000\",\"7.26940000\"],[\"1879.49000000\",\"0.00000000\"]]}}"}
{"mode":"v10-framework-compare","workers":4,"sequenceNumber":181,"symbol":"SOLUSDT","exchangeEventTimeMillis":1784430148360,"localReceivedEpochMillis":1784430148349,"topSpreadTicks":-2,"bid5Volume":215993,"ask5Volume":201582,"bid10Volume":452248,"ask10Volume":1307423,"rawPayload":"{\"stream\":\"solusdt@depth@100ms\",\"data\":{\"e\":\"depthUpdate\",\"E\":1784430148360,\"s\":\"SOLUSDT\",\"U\":1609579949,\"u\":1609579952,\"b\":[[\"76.19000000\",\"0.00000000\"],[\"76.08000000\",\"46.74600000\"]],\"a\":[[\"76.32000000\",\"392.58500000\"],[\"76.49000000\",\"0.00000000\"]]}}"}
{"mode":"v10-framework-compare","workers":4,"sequenceNumber":182,"symbol":"ETHUSDT","exchangeEventTimeMillis":1784430148360,"localReceivedEpochMillis":1784430148350,"topSpreadTicks":-38,"bid5Volume":5127,"ask5Volume":4314,"bid10Volume":9360,"ask10Volume":9880,"rawPayload":"{\"stream\":\"ethusdt@depth@100ms\",\"data\":{\"e\":\"depthUpdate\",\"E\":1784430148360,\"s\":\"ETHUSDT\",\"U\":2806177959,\"u\":2806177965,\"b\":[[\"1870.19000000\",\"0.00000000\"],[\"1870.04000000\",\"0.00000000\"],[\"1869.96000000\",\"0.13900000\"]],\"a\":[[\"1870.46000000\",\"1.33750000\"],[\"1870.60000000\",\"0.00000000\"],[\"1870.62000000\",\"0.13890000\"],[\"1870.70000000\",\"0.00000000\"],[\"1870.92000000\",\"1.47520000\"],[\"1871.00000000\",\"0.00000000\"],[\"1871.95000000\",\"0.00000000\"]]}}"}
{"mode":"v10-framework-compare","workers":4,"sequenceNumber":183,"symbol":"XRPUSDT","exchangeEventTimeMillis":1784430148360,"localReceivedEpochMillis":1784430148350,"topSpreadTicks":3,"bid5Volume":15059000,"ask5Volume":403700,"bid10Volume":15429200,"ask10Volume":1513200,"rawPayload":"{\"stream\":\"xrpusdt@depth@100ms\",\"data\":{\"e\":\"depthUpdate\",\"E\":1784430148360,\"s\":\"XRPUSDT\",\"U\":752705247,\"u\":752705269,\"b\":[[\"1.09610000\",\"1393.60000000\"],[\"1.09600000\",\"178.00000000\"],[\"1.09590000\",\"3457.70000000\"],[\"1.09580000\",\"3670.10000000\"],[\"1.09550000\",\"2074.70000000\"],[\"1.09540000\",\"2519.40000000\"],[\"1.09450000\",\"0.00000000\"]],\"a\":[[\"1.09640000\",\"2509.50000000\"],[\"1.09650000\",\"2565.60000000\"],[\"1.09660000\",\"0.00000000\"],[\"1.09680000\",\"0.00000000\"],[\"1.09690000\",\"2516.10000000\"],[\"1.09700000\",\"2568.70000000\"],[\"1.09750000\",\"4559.30000000\"],[\"1.09780000\",\"0.00000000\"],[\"1.09790000\",\"12807.00000000\"],[\"1.09990000\",\"0.00000000\"]]}}"}
{"mode":"v10-framework-compare","workers":4,"sequenceNumber":184,"symbol":"SOLUSDT","exchangeEventTimeMillis":1784430148460,"localReceivedEpochMillis":1784430148450,"topSpreadTicks":-2,"bid5Volume":215993,"ask5Volume":201582,"bid10Volume":452248,"ask10Volume":1307423,"rawPayload":"{\"stream\":\"solusdt@depth@100ms\",\"data\":{\"e\":\"depthUpdate\",\"E\":1784430148460,\"s\":\"SOLUSDT\",\"U\":1609579953,\"u\":1609579953,\"b\":[[\"75.86000000\",\"339.27400000\"]],\"a\":[]}}"}
{"mode":"v10-framework-compare","workers":4,"sequenceNumber":185,"symbol":"ETHUSDT","exchangeEventTimeMillis":1784430148460,"localReceivedEpochMillis":1784430148450,"topSpreadTicks":-38,"bid5Volume":5127,"ask5Volume":4314,"bid10Volume":9360,"ask10Volume":10487,"rawPayload":"{\"stream\":\"ethusdt@depth@100ms\",\"data\":{\"e\":\"depthUpdate\",\"E\":1784430148460,\"s\":\"ETHUSDT\",\"U\":2806177966,\"u\":2806177966,\"b\":[],\"a\":[[\"1871.35000000\",\"0.66220000\"]]}}"}
{"mode":"v10-framework-compare","workers":4,"sequenceNumber":186,"symbol":"XRPUSDT","exchangeEventTimeMillis":1784430148460,"localReceivedEpochMillis":1784430148451,"topSpreadTicks":0,"bid5Volume":12537500,"ask5Volume":497800,"bid10Volume":22816700,"ask10Volume":1695700,"rawPayload":"{\"stream\":\"xrpusdt@depth@100ms\",\"data\":{\"e\":\"depthUpdate\",\"E\":1784430148460,\"s\":\"XRPUSDT\",\"U\":752705270,\"u\":752705276,\"b\":[[\"1.09570000\",\"2350.90000000\"],[\"1.09550000\",\"2439.80000000\"],[\"1.09180000\",\"0.00000000\"],[\"1.09160000\",\"7387.50000000\"]],\"a\":[[\"1.09630000\",\"2282.00000000\"],[\"1.09640000\",\"182.50000000\"]]}}"}
{"mode":"v10-framework-compare","workers":4,"sequenceNumber":187,"symbol":"SOLUSDT","exchangeEventTimeMillis":1784430148560,"localReceivedEpochMillis":1784430148549,"topSpreadTicks":-2,"bid5Volume":216546,"ask5Volume":237222,"bid10Volume":452801,"ask10Volume":1580332,"rawPayload":"{\"stream\":\"solusdt@depth@100ms\",\"data\":{\"e\":\"depthUpdate\",\"E\":1784430148560,\"s\":\"SOLUSDT\",\"U\":1609579954,\"u\":1609579955,\"b\":[[\"76.18000000\",\"41.05000000\"]],\"a\":[[\"76.22000000\",\"0.00000000\"]]}}"}
{"mode":"v10-framework-compare","workers":4,"sequenceNumber":188,"symbol":"XRPUSDT","exchangeEventTimeMillis":1784430148560,"localReceivedEpochMillis":1784430148549,"topSpreadTicks":0,"bid5Volume":21078000,"ask5Volume":497800,"bid10Volume":31357200,"ask10Volume":1695700,"rawPayload":"{\"stream\":\"xrpusdt@depth@100ms\",\"data\":{\"e\":\"depthUpdate\",\"E\":1784430148560,\"s\":\"XRPUSDT\",\"U\":752705277,\"u\":752705278,\"b\":[[\"1.09610000\",\"1347.90000000\"],[\"1.09110000\",\"15928.00000000\"]],\"a\":[]}}"}
{"mode":"v10-framework-compare","workers":4,"sequenceNumber":189,"symbol":"SOLUSDT","exchangeEventTimeMillis":1784430148660,"localReceivedEpochMillis":1784430148650,"topSpreadTicks":-2,"bid5Volume":217296,"ask5Volume":237222,"bid10Volume":453551,"ask10Volume":1580332,"rawPayload":"{\"stream\":\"solusdt@depth@100ms\",\"data\":{\"e\":\"depthUpdate\",\"E\":1784430148660,\"s\":\"SOLUSDT\",\"U\":1609579956,\"u\":1609579957,\"b\":[[\"76.18000000\",\"36.80400000\"],[\"76.17000000\",\"100.70600000\"]],\"a\":[]}}"}
{"mode":"v10-framework-compare","workers":4,"sequenceNumber":190,"symbol":"SOLUSDT","exchangeEventTimeMillis":1784430148860,"localReceivedEpochMillis":1784430148850,"topSpreadTicks":-2,"bid5Volume":253535,"ask5Volume":201583,"bid10Volume":453551,"ask10Volume":1307424,"rawPayload":"{\"stream\":\"solusdt@depth@100ms\",\"data\":{\"e\":\"depthUpdate\",\"E\":1784430148860,\"s\":\"SOLUSDT\",\"U\":1609579958,\"u\":1609579959,\"b\":[[\"76.16000000\",\"68.40400000\"],[\"76.15000000\",\"8.11000000\"]],\"a\":[[\"76.22000000\",\"0.55500000\"]]}}"}
{"mode":"v10-framework-compare","workers":4,"sequenceNumber":191,"symbol":"XRPUSDT","exchangeEventTimeMillis":1784430148860,"localReceivedEpochMillis":1784430148851,"topSpreadTicks":0,"bid5Volume":5373700,"ask5Volume":360600,"bid10Volume":15652900,"ask10Volume":1558500,"rawPayload":"{\"stream\":\"xrpusdt@depth@100ms\",\"data\":{\"e\":\"depthUpdate\",\"E\":1784430148860,\"s\":\"XRPUSDT\",\"U\":752705279,\"u\":752705280,\"b\":[[\"1.09600000\",\"223.70000000\"]],\"a\":[[\"1.09620000\",\"45.30000000\"]]}}"}
{"mode":"v10-framework-compare","workers":4,"sequenceNumber":192,"symbol":"XRPUSDT","exchangeEventTimeMillis":1784430149060,"localReceivedEpochMillis":1784430149050,"topSpreadTicks":2,"bid5Volume":9002600,"ask5Volume":403700,"bid10Volume":19281800,"ask10Volume":1513200,"rawPayload":"{\"stream\":\"xrpusdt@depth@100ms\",\"data\":{\"e\":\"depthUpdate\",\"E\":1784430149060,\"s\":\"XRPUSDT\",\"U\":752705281,\"u\":752705284,\"b\":[[\"1.09590000\",\"3275.20000000\"],[\"1.09580000\",\"3852.60000000\"]],\"a\":[[\"1.09630000\",\"2464.50000000\"],[\"1.09640000\",\"0.00000000\"]]}}"}
{"mode":"v10-framework-compare","workers":4,"sequenceNumber":193,"symbol":"BNBUSDT","exchangeEventTimeMillis":1784430149161,"localReceivedEpochMillis":1784430149150,"topSpreadTicks":4,"bid5Volume":5006,"ask5Volume":6283,"bid10Volume":15253,"ask10Volume":257274,"rawPayload":"{\"stream\":\"bnbusdt@depth@100ms\",\"data\":{\"e\":\"depthUpdate\",\"E\":1784430149161,\"s\":\"BNBUSDT\",\"U\":1236331329,\"u\":1236331330,\"b\":[],\"a\":[[\"570.61000000\",\"0.87600000\"],[\"570.63000000\",\"0.00000000\"]]}}"}
{"mode":"v10-framework-compare","workers":4,"sequenceNumber":194,"symbol":"XRPUSDT","exchangeEventTimeMillis":1784430149161,"localReceivedEpochMillis":1784430149150,"topSpreadTicks":2,"bid5Volume":12065900,"ask5Volume":403700,"bid10Volume":22345100,"ask10Volume":1513200,"rawPayload":"{\"stream\":\"xrpusdt@depth@100ms\",\"data\":{\"e\":\"depthUpdate\",\"E\":1784430149161,\"s\":\"XRPUSDT\",\"U\":752705285,\"u\":752705315,\"b\":[[\"1.09610000\",\"0.00000000\"],[\"1.09600000\",\"45.70000000\"],[\"1.09590000\",\"1525.90000000\"],[\"1.09580000\",\"2292.00000000\"],[\"1.09570000\",\"4871.10000000\"],[\"1.09550000\",\"2074.70000000\"],[\"1.09540000\",\"0.00000000\"],[\"1.09530000\",\"2884.60000000\"],[\"1.09510000\",\"0.00000000\"],[\"1.09500000\",\"0.00000000\"],[\"1.09480000\",\"0.00000000\"],[\"1.09470000\",\"4757.80000000\"],[\"1.09460000\",\"6896.80000000\"],[\"1.09450000\",\"542.40000000\"],[\"1.09160000\",\"6915.90000000\"]],\"a\":[[\"1.09620000\",\"2510.10000000\"],[\"1.09630000\",\"0.00000000\"],[\"1.09640000\",\"1220.50000000\"],[\"1.09650000\",\"1394.00000000\"],[\"1.09680000\",\"2516.50000000\"],[\"1.09690000\",\"0.00000000\"],[\"1.09750000\",\"11438.80000000\"],[\"1.09770000\",\"0.00000000\"]]}}"}
{"mode":"v10-framework-compare","workers":4,"sequenceNumber":195,"symbol":"XRPUSDT","exchangeEventTimeMillis":1784430149261,"localReceivedEpochMillis":1784430149250,"topSpreadTicks":1,"bid5Volume":15059000,"ask5Volume":9414300,"bid10Volume":15429200,"ask10Volume":10612200,"rawPayload":"{\"stream\":\"xrpusdt@depth@100ms\",\"data\":{\"e\":\"depthUpdate\",\"E\":1784430149261,\"s\":\"XRPUSDT\",\"U\":752705316,\"u\":752705343,\"b\":[[\"1.09590000\",\"0.00000000\"],[\"1.09580000\",\"1347.90000000\"],[\"1.09570000\",\"3376.00000000\"],[\"1.09560000\",\"1745.60000000\"],[\"1.09550000\",\"2182.00000000\"],[\"1.09530000\",\"2439.80000000\"],[\"1.09520000\",\"4594.50000000\"],[\"1.09440000\",\"0.00000000\"],[\"1.09430000\",\"15587.70000000\"],[\"1.09140000\",\"438.80000000\"],[\"1.09110000\",\"0.00000000\"]],\"a\":[[\"1.09630000\",\"1226.90000000\"],[\"1.09640000\",\"0.00000000\"],[\"1.09670000\",\"4128.90000000\"],[\"1.09680000\",\"0.00000000\"],[\"1.09700000\",\"2074.70000000\"],[\"1.09780000\",\"12786.60000000\"],[\"1.09980000\",\"9099.00000000\"]]}}"}
{"mode":"v10-framework-compare","workers":4,"sequenceNumber":196,"symbol":"XRPUSDT","exchangeEventTimeMillis":1784430149361,"localReceivedEpochMillis":1784430149351,"topSpreadTicks":0,"bid5Volume":7894700,"ask5Volume":809300,"bid10Volume":18173900,"ask10Volume":2007200,"rawPayload":"{\"stream\":\"xrpusdt@depth@100ms\",\"data\":{\"e\":\"depthUpdate\",\"E\":1784430149361,\"s\":\"XRPUSDT\",\"U\":752705344,\"u\":752705349,\"b\":[[\"1.09600000\",\"0.00000000\"],[\"1.09550000\",\"2355.30000000\"],[\"1.09430000\",\"2744.70000000\"]],\"a\":[[\"1.09620000\",\"2327.60000000\"],[\"1.09630000\",\"1334.30000000\"],[\"1.09660000\",\"494.00000000\"]]}}"}
{"mode":"v10-framework-compare","workers":4,"sequenceNumber":197,"symbol":"SOLUSDT","exchangeEventTimeMillis":1784430149461,"localReceivedEpochMillis":1784430149449,"topSpreadTicks":-2,"bid5Volume":253535,"ask5Volume":201583,"bid10Volume":463517,"ask10Volume":1035721,"rawPayload":"{\"stream\":\"solusdt@depth@100ms\",\"data\":{\"e\":\"depthUpdate\",\"E\":1784430149461,\"s\":\"SOLUSDT\",\"U\":1609579960,\"u\":1609579966,\"b\":[[\"76.13000000\",\"0.00000000\"],[\"76.11000000\",\"118.04900000\"],[\"76.08000000\",\"9.50800000\"],[\"76.07000000\",\"420.59600000\"],[\"76.03000000\",\"525.66700000\"],[\"76.02000000\",\"391.23100000\"],[\"75.94000000\",\"333.65900000\"],[\"75.93000000\",\"493.20800000\"]],\"a\":[[\"76.31000000\",\"19.42400000\"],[\"76.32000000\",\"373.16100000\"],[\"76.40000000\",\"53.69800000\"],[\"76.41000000\",\"274.28400000\"],[\"76.49000000\",\"141.90100000\"],[\"76.50000000\",\"55.09600000\"]]}}"}
{"mode":"v10-framework-compare","workers":4,"sequenceNumber":198,"symbol":"XRPUSDT","exchangeEventTimeMillis":1784430149461,"localReceivedEpochMillis":1784430149450,"topSpreadTicks":0,"bid5Volume":6543400,"ask5Volume":2597600,"bid10Volume":16822600,"ask10Volume":3795500,"rawPayload":"{\"stream\":\"xrpusdt@depth@100ms\",\"data\":{\"e\":\"depthUpdate\",\"E\":1784430149461,\"s\":\"XRPUSDT\",\"U\":752705350,\"u\":752705351,\"b\":[[\"1.09580000\",\"1393.40000000\"]],\"a\":[[\"1.09620000\",\"2282.30000000\"]]}}"}
{"mode":"v10-framework-compare","workers":4,"sequenceNumber":199,"symbol":"ETHUSDT","exchangeEventTimeMillis":1784430149561,"localReceivedEpochMillis":1784430149549,"topSpreadTicks":-38,"bid5Volume":5127,"ask5Volume":5760,"bid10Volume":9360,"ask10Volume":10513,"rawPayload":"{\"stream\":\"ethusdt@depth@100ms\",\"data\":{\"e\":\"depthUpdate\",\"E\":1784430149561,\"s\":\"ETHUSDT\",\"U\":2806177967,\"u\":2806177967,\"b\":[],\"a\":[[\"1870.68000000\",\"0.00000000\"]]}}"}
{"mode":"v10-framework-compare","workers":4,"sequenceNumber":200,"symbol":"XRPUSDT","exchangeEventTimeMillis":1784430149561,"localReceivedEpochMillis":1784430149550,"topSpreadTicks":2,"bid5Volume":21178500,"ask5Volume":403700,"bid10Volume":31457700,"ask10Volume":1513200,"rawPayload":"{\"stream\":\"xrpusdt@depth@100ms\",\"data\":{\"e\":\"depthUpdate\",\"E\":1784430149561,\"s\":\"XRPUSDT\",\"U\":752705352,\"u\":752705354,\"b\":[[\"1.09110000\",\"16028.50000000\"]],\"a\":[[\"1.09770000\",\"12804.00000000\"],[\"1.09970000\",\"0.00000000\"]]}}"}
{"mode":"v10-framework-compare","workers":4,"sequenceNumber":201,"symbol":"XRPUSDT","exchangeEventTimeMillis":1784430149661,"localReceivedEpochMillis":1784430149650,"topSpreadTicks":2,"bid5Volume":21273200,"ask5Volume":403700,"bid10Volume":31552400,"ask10Volume":1513200,"rawPayload":"{\"stream\":\"xrpusdt@depth@100ms\",\"data\":{\"e\":\"depthUpdate\",\"E\":1784430149661,\"s\":\"XRPUSDT\",\"U\":752705355,\"u\":752705355,\"b\":[[\"1.09090000\",\"16123.20000000\"]],\"a\":[]}}"}
{"mode":"v10-framework-compare","workers":4,"sequenceNumber":202,"symbol":"BTCUSDT","exchangeEventTimeMillis":1784430149761,"localReceivedEpochMillis":1784430149750,"topSpreadTicks":-318,"bid5Volume":188,"ask5Volume":148,"bid10Volume":477,"ask10Volume":296,"rawPayload":"{\"stream\":\"btcusdt@depth@100ms\",\"data\":{\"e\":\"depthUpdate\",\"E\":1784430149761,\"s\":\"BTCUSDT\",\"U\":3244441327,\"u\":3244441327,\"b\":[],\"a\":[[\"64914.49000000\",\"0.00000000\"]]}}"}
{"mode":"v10-framework-compare","workers":4,"sequenceNumber":203,"symbol":"XRPUSDT","exchangeEventTimeMillis":1784430149761,"localReceivedEpochMillis":1784430149750,"topSpreadTicks":2,"bid5Volume":7398000,"ask5Volume":403700,"bid10Volume":17677200,"ask10Volume":1513200,"rawPayload":"{\"stream\":\"xrpusdt@depth@100ms\",\"data\":{\"e\":\"depthUpdate\",\"E\":1784430149761,\"s\":\"XRPUSDT\",\"U\":752705356,\"u\":752705357,\"b\":[[\"1.09560000\",\"1854.30000000\"],[\"1.09550000\",\"2248.00000000\"]],\"a\":[]}}"}
{"mode":"v10-framework-compare","workers":4,"sequenceNumber":204,"symbol":"BTCUSDT","exchangeEventTimeMillis":1784430149861,"localReceivedEpochMillis":1784430149851,"topSpreadTicks":-318,"bid5Volume":188,"ask5Volume":148,"bid10Volume":477,"ask10Volume":296,"rawPayload":"{\"stream\":\"btcusdt@depth@100ms\",\"data\":{\"e\":\"depthUpdate\",\"E\":1784430149861,\"s\":\"BTCUSDT\",\"U\":3244441328,\"u\":3244441328,\"b\":[],\"a\":[[\"64914.49000000\",\"0.00011000\"]]}}"}
{"mode":"v10-framework-compare","workers":4,"sequenceNumber":205,"symbol":"XRPUSDT","exchangeEventTimeMillis":1784430149861,"localReceivedEpochMillis":1784430149851,"topSpreadTicks":0,"bid5Volume":6243000,"ask5Volume":2831900,"bid10Volume":16522200,"ask10Volume":4029800,"rawPayload":"{\"stream\":\"xrpusdt@depth@100ms\",\"data\":{\"e\":\"depthUpdate\",\"E\":1784430149861,\"s\":\"XRPUSDT\",\"U\":752705358,\"u\":752705362,\"b\":[[\"1.09580000\",\"3676.30000000\"],[\"1.09570000\",\"1093.00000000\"]],\"a\":[[\"1.09610000\",\"45.20000000\"],[\"1.09630000\",\"2946.60000000\"],[\"1.09670000\",\"2516.60000000\"]]}}"}
{"mode":"v10-framework-compare","workers":4,"sequenceNumber":206,"symbol":"XRPUSDT","exchangeEventTimeMillis":1784430149961,"localReceivedEpochMillis":1784430149950,"topSpreadTicks":0,"bid5Volume":12048200,"ask5Volume":4874600,"bid10Volume":22327400,"ask10Volume":6072500,"rawPayload":"{\"stream\":\"xrpusdt@depth@100ms\",\"data\":{\"e\":\"depthUpdate\",\"E\":1784430149961,\"s\":\"XRPUSDT\",\"U\":752705363,\"u\":752705372,\"b\":[[\"1.09560000\",\"1617.10000000\"],[\"1.09550000\",\"2485.30000000\"],[\"1.09520000\",\"2074.70000000\"],[\"1.09510000\",\"2520.00000000\"],[\"1.09460000\",\"0.00000000\"],[\"1.09440000\",\"6898.20000000\"]],\"a\":[[\"1.09620000\",\"2689.40000000\"],[\"1.09630000\",\"1719.70000000\"],[\"1.09640000\",\"1010.80000000\"],[\"1.09650000\",\"1244.00000000\"],[\"1.09660000\",\"3010.90000000\"],[\"1.09670000\",\"0.00000000\"],[\"1.09730000\",\"8955.40000000\"],[\"1.09750000\",\"4559.30000000\"]]}}"}
{"mode":"v10-framework-compare","workers":4,"sequenceNumber":207,"symbol":"XRPUSDT","exchangeEventTimeMillis":1784430150161,"localReceivedEpochMillis":1784430150151,"topSpreadTicks":2,"bid5Volume":12048200,"ask5Volume":403700,"bid10Volume":22327400,"ask10Volume":1513200,"rawPayload":"{\"stream\":\"xrpusdt@depth@100ms\",\"data\":{\"e\":\"depthUpdate\",\"E\":1784430150161,\"s\":\"XRPUSDT\",\"U\":752705373,\"u\":752705374,\"b\":[],\"a\":[[\"1.09630000\",\"2695.60000000\"],[\"1.09640000\",\"0.00000000\"]]}}"}
{"mode":"v10-framework-compare","workers":4,"sequenceNumber":208,"symbol":"SOLUSDT","exchangeEventTimeMillis":1784430150461,"localReceivedEpochMillis":1784430150451,"topSpreadTicks":-2,"bid5Volume":253535,"ask5Volume":201583,"bid10Volume":465817,"ask10Volume":1035721,"rawPayload":"{\"stream\":\"solusdt@depth@100ms\",\"data\":{\"e\":\"depthUpdate\",\"E\":1784430150461,\"s\":\"SOLUSDT\",\"U\":1609579967,\"u\":1609579968,\"b\":[[\"76.15000000\",\"0.00000000\"],[\"76.14000000\",\"10.41000000\"]],\"a\":[]}}"}
{"mode":"v10-framework-compare","workers":4,"sequenceNumber":209,"symbol":"XRPUSDT","exchangeEventTimeMillis":1784430150461,"localReceivedEpochMillis":1784430150451,"topSpreadTicks":0,"bid5Volume":12048200,"ask5Volume":1310800,"bid10Volume":22327400,"ask10Volume":2508700,"rawPayload":"{\"stream\":\"xrpusdt@depth@100ms\",\"data\":{\"e\":\"depthUpdate\",\"E\":1784430150461,\"s\":\"XRPUSDT\",\"U\":752705375,\"u\":752705376,\"b\":[],\"a\":[[\"1.09630000\",\"1719.70000000\"],[\"1.09640000\",\"995.50000000\"]]}}"}
{"mode":"v10-framework-compare","workers":4,"sequenceNumber":210,"symbol":"ETHUSDT","exchangeEventTimeMillis":1784430150561,"localReceivedEpochMillis":1784430150551,"topSpreadTicks":-38,"bid5Volume":5127,"ask5Volume":5790,"bid10Volume":9360,"ask10Volume":10543,"rawPayload":"{\"stream\":\"ethusdt@depth@100ms\",\"data\":{\"e\":\"depthUpdate\",\"E\":1784430150561,\"s\":\"ETHUSDT\",\"U\":2806177968,\"u\":2806177969,\"b\":[],\"a\":[[\"1870.62000000\",\"0.16850000\"],[\"1870.98000000\",\"1.06180000\"],[\"1871.12000000\",\"0.00000000\"]]}}"}
{"mode":"v10-framework-compare","workers":4,"sequenceNumber":211,"symbol":"BTCUSDT","exchangeEventTimeMillis":1784430150762,"localReceivedEpochMillis":1784430150751,"topSpreadTicks":-318,"bid5Volume":198,"ask5Volume":148,"bid10Volume":477,"ask10Volume":296,"rawPayload":"{\"stream\":\"btcusdt@depth@100ms\",\"data\":{\"e\":\"depthUpdate\",\"E\":1784430150762,\"s\":\"BTCUSDT\",\"U\":3244441329,\"u\":3244441330,\"b\":[[\"64783.34000000\",\"0.00000000\"],[\"64782.96000000\",\"0.02800000\"]],\"a\":[[\"64801.33000000\",\"0.03020000\"],[\"64803.20000000\",\"0.00000000\"]]}}"}
{"mode":"v10-framework-compare","workers":4,"sequenceNumber":212,"symbol":"XRPUSDT","exchangeEventTimeMillis":1784430150762,"localReceivedEpochMillis":1784430150751,"topSpreadTicks":2,"bid5Volume":12048200,"ask5Volume":403700,"bid10Volume":22327400,"ask10Volume":1513200,"rawPayload":"{\"stream\":\"xrpusdt@depth@100ms\",\"data\":{\"e\":\"depthUpdate\",\"E\":1784430150762,\"s\":\"XRPUSDT\",\"U\":752705377,\"u\":752705378,\"b\":[],\"a\":[[\"1.09630000\",\"2686.70000000\"],[\"1.09640000\",\"0.00000000\"]]}}"}
{"mode":"v10-framework-compare","workers":4,"sequenceNumber":213,"symbol":"SOLUSDT","exchangeEventTimeMillis":1784430150962,"localReceivedEpochMillis":1784430150950,"topSpreadTicks":-2,"bid5Volume":239152,"ask5Volume":187431,"bid10Volume":451434,"ask10Volume":1021569,"rawPayload":"{\"stream\":\"solusdt@depth@100ms\",\"data\":{\"e\":\"depthUpdate\",\"E\":1784430150962,\"s\":\"SOLUSDT\",\"U\":1609579969,\"u\":1609579974,\"b\":[[\"76.20000000\",\"18.63100000\"],[\"76.18000000\",\"3.96500000\"],[\"76.17000000\",\"133.54800000\"],[\"76.03000000\",\"467.58200000\"]],\"a\":[[\"76.24000000\",\"83.11900000\"],[\"76.45000000\",\"270.83200000\"]]}}"}
{"mode":"v10-framework-compare","workers":4,"sequenceNumber":214,"symbol":"XRPUSDT","exchangeEventTimeMillis":1784430150962,"localReceivedEpochMillis":1784430150950,"topSpreadTicks":0,"bid5Volume":24890800,"ask5Volume":20076900,"bid10Volume":35170000,"ask10Volume":21274800,"rawPayload":"{\"stream\":\"xrpusdt@depth@100ms\",\"data\":{\"e\":\"depthUpdate\",\"E\":1784430150962,\"s\":\"XRPUSDT\",\"U\":752705379,\"u\":752705382,\"b\":[[\"1.09370000\",\"0.00000000\"],[\"1.09320000\",\"19740.80000000\"]],\"a\":[[\"1.09870000\",\"15518.40000000\"],[\"1.09930000\",\"19761.60000000\"]]}}"}
{"mode":"v10-framework-compare","workers":4,"sequenceNumber":215,"symbol":"SOLUSDT","exchangeEventTimeMillis":1784430151062,"localReceivedEpochMillis":1784430151051,"topSpreadTicks":-3,"bid5Volume":217390,"ask5Volume":218194,"bid10Volume":455960,"ask10Volume":721268,"rawPayload":"{\"stream\":\"solusdt@depth@100ms\",\"data\":{\"e\":\"depthUpdate\",\"E\":1784430151062,\"s\":\"SOLUSDT\",\"U\":1609579975,\"u\":1609579992,\"b\":[[\"76.20000000\",\"0.00000000\"],[\"76.19000000\",\"18.63100000\"],[\"76.18000000\",\"18.44200000\"],[\"76.16000000\",\"32.16500000\"],[\"76.15000000\",\"36.24100000\"],[\"76.11000000\",\"18.85900000\"],[\"76.10000000\",\"107.33500000\"],[\"76.09000000\",\"3.45300000\"],[\"76.01000000\",\"56.73300000\"]],\"a\":[[\"76.20000000\",\"38.18200000\"],[\"76.21000000\",\"0.00000000\"],[\"76.22000000\",\"60.34300000\"],[\"76.23000000\",\"55.99600000\"],[\"76.24000000\",\"33.47800000\"],[\"76.30000000\",\"98.95200000\"],[\"76.32000000\",\"274.22800000\"],[\"76.40000000\",\"94.21400000\"]]}}"}
{"mode":"v10-framework-compare","workers":4,"sequenceNumber":216,"symbol":"BNBUSDT","exchangeEventTimeMillis":1784430151062,"localReceivedEpochMillis":1784430151051,"topSpreadTicks":4,"bid5Volume":5006,"ask5Volume":6283,"bid10Volume":15253,"ask10Volume":257274,"rawPayload":"{\"stream\":\"bnbusdt@depth@100ms\",\"data\":{\"e\":\"depthUpdate\",\"E\":1784430151062,\"s\":\"BNBUSDT\",\"U\":1236331331,\"u\":1236331338,\"b\":[[\"569.84000000\",\"0.00000000\"],[\"569.83000000\",\"3.22400000\"],[\"569.50000000\",\"0.00000000\"],[\"569.49000000\",\"5.18800000\"],[\"569.16000000\",\"0.00000000\"],[\"569.15000000\",\"8.52500000\"],[\"568.81000000\",\"0.00000000\"],[\"568.80000000\",\"20.05600000\"]],\"a\":[[\"571.21000000\",\"3.33600000\"],[\"571.22000000\",\"0.00000000\"],[\"571.55000000\",\"5.04300000\"],[\"571.56000000\",\"0.00000000\"],[\"571.89000000\",\"8.30100000\"],[\"571.90000000\",\"0.00000000\"],[\"572.24000000\",\"19.20500000\"],[\"572.25000000\",\"0.00000000\"]]}}"}
{"mode":"v10-framework-compare","workers":4,"sequenceNumber":217,"symbol":"SOLUSDT","exchangeEventTimeMillis":1784430151162,"localReceivedEpochMillis":1784430151152,"topSpreadTicks":-3,"bid5Volume":217390,"ask5Volume":218194,"bid10Volume":455960,"ask10Volume":721268,"rawPayload":"{\"stream\":\"solusdt@depth@100ms\",\"data\":{\"e\":\"depthUpdate\",\"E\":1784430151162,\"s\":\"SOLUSDT\",\"U\":1609579993,\"u\":1609579993,\"b\":[[\"76.08000000\",\"16.54300000\"]],\"a\":[]}}"}
{"mode":"v10-framework-compare","workers":4,"sequenceNumber":218,"symbol":"ETHUSDT","exchangeEventTimeMillis":1784430151162,"localReceivedEpochMillis":1784430151152,"topSpreadTicks":-38,"bid5Volume":5127,"ask5Volume":5790,"bid10Volume":9360,"ask10Volume":10543,"rawPayload":"{\"stream\":\"ethusdt@depth@100ms\",\"data\":{\"e\":\"depthUpdate\",\"E\":1784430151162,\"s\":\"ETHUSDT\",\"U\":2806177970,\"u\":2806177970,\"b\":[[\"1861.48000000\",\"9.28780000\"]],\"a\":[]}}"}
{"mode":"v10-framework-compare","workers":4,"sequenceNumber":219,"symbol":"BTCUSDT","exchangeEventTimeMillis":1784430151162,"localReceivedEpochMillis":1784430151153,"topSpreadTicks":-318,"bid5Volume":198,"ask5Volume":148,"bid10Volume":477,"ask10Volume":296,"rawPayload":"{\"stream\":\"btcusdt@depth@100ms\",\"data\":{\"e\":\"depthUpdate\",\"E\":1784430151162,\"s\":\"BTCUSDT\",\"U\":3244441331,\"u\":3244441333,\"b\":[[\"64787.35000000\",\"0.00000000\"],[\"64785.22000000\",\"0.03088000\"]],\"a\":[[\"81055.16000000\",\"0.00060000\"]]}}"}
{"mode":"v10-framework-compare","workers":4,"sequenceNumber":220,"symbol":"SOLUSDT","exchangeEventTimeMillis":1784430151262,"localReceivedEpochMillis":1784430151251,"topSpreadTicks":-3,"bid5Volume":217390,"ask5Volume":218194,"bid10Volume":447828,"ask10Volume":721268,"rawPayload":"{\"stream\":\"solusdt@depth@100ms\",\"data\":{\"e\":\"depthUpdate\",\"E\":1784430151262,\"s\":\"SOLUSDT\",\"U\":1609579994,\"u\":1609579994,\"b\":[[\"76.10000000\",\"99.20300000\"]],\"a\":[]}}"}
{"mode":"v10-framework-compare","workers":4,"sequenceNumber":221,"symbol":"XRPUSDT","exchangeEventTimeMillis":1784430151262,"localReceivedEpochMillis":1784430151252,"topSpreadTicks":0,"bid5Volume":24890800,"ask5Volume":13035500,"bid10Volume":35170000,"ask10Volume":14233400,"rawPayload":"{\"stream\":\"xrpusdt@depth@100ms\",\"data\":{\"e\":\"depthUpdate\",\"E\":1784430151262,\"s\":\"XRPUSDT\",\"U\":752705383,\"u\":752705383,\"b\":[],\"a\":[[\"1.09860000\",\"12720.20000000\"]]}}"}
{"mode":"v10-framework-compare","workers":4,"sequenceNumber":222,"symbol":"BTCUSDT","exchangeEventTimeMillis":1784430151762,"localReceivedEpochMillis":1784430151752,"topSpreadTicks":-318,"bid5Volume":198,"ask5Volume":148,"bid10Volume":477,"ask10Volume":296,"rawPayload":"{\"stream\":\"btcusdt@depth@100ms\",\"data\":{\"e\":\"depthUpdate\",\"E\":1784430151762,\"s\":\"BTCUSDT\",\"U\":3244441334,\"u\":3244441341,\"b\":[[\"64743.28000000\",\"0.00000000\"],[\"64735.34000000\",\"0.05967000\"],[\"64704.39000000\",\"0.00000000\"],[\"64696.45000000\",\"0.08541000\"],[\"64665.49000000\",\"0.00000000\"],[\"64657.56000000\",\"0.18203000\"],[\"64587.71000000\",\"0.00000000\"],[\"64579.79000000\",\"0.40748000\"]],\"a\":[[\"64890.84000000\",\"0.06099000\"],[\"64898.79000000\",\"0.00000000\"],[\"64929.72000000\",\"0.08452000\"],[\"64937.68000000\",\"0.00000000\"],[\"64968.61000000\",\"0.18519000\"],[\"64976.57000000\",\"0.00000000\"],[\"65046.39000000\",\"0.40282000\"],[\"65054.36000000\",\"0.00000000\"]]}}"}
{"mode":"v10-framework-compare","workers":4,"sequenceNumber":223,"symbol":"SOLUSDT","exchangeEventTimeMillis":1784430151862,"localReceivedEpochMillis":1784430151852,"topSpreadTicks":-3,"bid5Volume":217390,"ask5Volume":188557,"bid10Volume":447828,"ask10Volume":447598,"rawPayload":"{\"stream\":\"solusdt@depth@100ms\",\"data\":{\"e\":\"depthUpdate\",\"E\":1784430151862,\"s\":\"SOLUSDT\",\"U\":1609579995,\"u\":1609579995,\"b\":[],\"a\":[[\"76.21000000\",\"0.55800000\"]]}}"}
{"mode":"v10-framework-compare","workers":4,"sequenceNumber":224,"symbol":"ETHUSDT","exchangeEventTimeMillis":1784430152063,"localReceivedEpochMillis":1784430152052,"topSpreadTicks":-38,"bid5Volume":5127,"ask5Volume":5790,"bid10Volume":9360,"ask10Volume":10543,"rawPayload":"{\"stream\":\"ethusdt@depth@100ms\",\"data\":{\"e\":\"depthUpdate\",\"E\":1784430152063,\"s\":\"ETHUSDT\",\"U\":2806177971,\"u\":2806177975,\"b\":[[\"1869.80000000\",\"0.00000000\"],[\"1869.75000000\",\"2.16310000\"],[\"1862.85000000\",\"0.00000000\"]],\"a\":[[\"1877.80000000\",\"7.20650000\"],[\"1879.43000000\",\"0.00000000\"]]}}"}
{"mode":"v10-framework-compare","workers":4,"sequenceNumber":225,"symbol":"XRPUSDT","exchangeEventTimeMillis":1784430152163,"localReceivedEpochMillis":1784430152152,"topSpreadTicks":2,"bid5Volume":24890800,"ask5Volume":403700,"bid10Volume":35170000,"ask10Volume":1513200,"rawPayload":"{\"stream\":\"xrpusdt@depth@100ms\",\"data\":{\"e\":\"depthUpdate\",\"E\":1784430152163,\"s\":\"XRPUSDT\",\"U\":752705384,\"u\":752705386,\"b\":[],\"a\":[[\"1.09620000\",\"3933.40000000\"],[\"1.09630000\",\"1719.70000000\"],[\"1.09640000\",\"1017.80000000\"],[\"1.09650000\",\"0.00000000\"]]}}"}
{"mode":"v10-framework-compare","workers":4,"sequenceNumber":226,"symbol":"ETHUSDT","exchangeEventTimeMillis":1784430152263,"localReceivedEpochMillis":1784430152252,"topSpreadTicks":-38,"bid5Volume":5127,"ask5Volume":5790,"bid10Volume":9360,"ask10Volume":10543,"rawPayload":"{\"stream\":\"ethusdt@depth@100ms\",\"data\":{\"e\":\"depthUpdate\",\"E\":1784430152263,\"s\":\"ETHUSDT\",\"U\":2806177976,\"u\":2806177976,\"b\":[[\"1862.84000000\",\"7.28870000\"]],\"a\":[]}}"}
{"mode":"v10-framework-compare","workers":4,"sequenceNumber":227,"symbol":"XRPUSDT","exchangeEventTimeMillis":1784430152263,"localReceivedEpochMillis":1784430152252,"topSpreadTicks":0,"bid5Volume":12123300,"ask5Volume":13192200,"bid10Volume":22402500,"ask10Volume":14390100,"rawPayload":"{\"stream\":\"xrpusdt@depth@100ms\",\"data\":{\"e\":\"depthUpdate\",\"E\":1784430152263,\"s\":\"XRPUSDT\",\"U\":752705387,\"u\":752705389,\"b\":[[\"1.09440000\",\"6973.30000000\"]],\"a\":[[\"1.09770000\",\"12976.40000000\"],[\"1.09780000\",\"12876.90000000\"]]}}"}
{"mode":"v10-framework-compare","workers":4,"sequenceNumber":228,"symbol":"BTCUSDT","exchangeEventTimeMillis":1784430152463,"localReceivedEpochMillis":1784430152452,"topSpreadTicks":-318,"bid5Volume":198,"ask5Volume":148,"bid10Volume":477,"ask10Volume":296,"rawPayload":"{\"stream\":\"btcusdt@depth@100ms\",\"data\":{\"e\":\"depthUpdate\",\"E\":1784430152463,\"s\":\"BTCUSDT\",\"U\":3244441342,\"u\":3244441342,\"b\":[],\"a\":[[\"81055.16000000\",\"0.00075000\"]]}}"}
{"mode":"v10-framework-compare","workers":4,"sequenceNumber":229,"symbol":"ETHUSDT","exchangeEventTimeMillis":1784430152563,"localReceivedEpochMillis":1784430152553,"topSpreadTicks":-38,"bid5Volume":5127,"ask5Volume":5790,"bid10Volume":9360,"ask10Volume":10543,"rawPayload":"{\"stream\":\"ethusdt@depth@100ms\",\"data\":{\"e\":\"depthUpdate\",\"E\":1784430152563,\"s\":\"ETHUSDT\",\"U\":2806177977,\"u\":2806177977,\"b\":[],\"a\":[[\"1870.94000000\",\"1.06180000\"],[\"1870.98000000\",\"0.00000000\"]]}}"}
{"mode":"v10-framework-compare","workers":4,"sequenceNumber":230,"symbol":"SOLUSDT","exchangeEventTimeMillis":1784430152663,"localReceivedEpochMillis":1784430152653,"topSpreadTicks":-3,"bid5Volume":216423,"ask5Volume":174733,"bid10Volume":446861,"ask10Volume":447692,"rawPayload":"{\"stream\":\"solusdt@depth@100ms\",\"data\":{\"e\":\"depthUpdate\",\"E\":1784430152663,\"s\":\"SOLUSDT\",\"U\":1609579996,\"u\":1609580003,\"b\":[[\"76.19000000\",\"32.14400000\"],[\"76.18000000\",\"36.80400000\"],[\"76.17000000\",\"100.70600000\"]],\"a\":[[\"76.20000000\",\"5.35100000\"],[\"76.21000000\",\"33.38600000\"],[\"76.23000000\",\"42.17500000\"],[\"76.25000000\",\"44.11300000\"]]}}"}
{"mode":"v10-framework-compare","workers":4,"sequenceNumber":231,"symbol":"ETHUSDT","exchangeEventTimeMillis":1784430152663,"localReceivedEpochMillis":1784430152653,"topSpreadTicks":-23,"bid5Volume":5127,"ask5Volume":5522,"bid10Volume":9116,"ask10Volume":10275,"rawPayload":"{\"stream\":\"ethusdt@depth@100ms\",\"data\":{\"e\":\"depthUpdate\",\"E\":1784430152663,\"s\":\"ETHUSDT\",\"U\":2806177978,\"u\":2806177988,\"b\":[[\"1870.12000000\",\"0.00000000\"],[\"1869.92000000\",\"0.00000000\"],[\"1869.81000000\",\"0.00000000\"],[\"1869.75000000\",\"1.09310000\"]],\"a\":[[\"1870.46000000\",\"0.00000000\"],[\"1870.61000000\",\"1.06990000\"],[\"1870.63000000\",\"0.00000000\"],[\"1870.94000000\",\"0.00000000\"],[\"1871.17000000\",\"1.06180000\"]]}}"}
{"mode":"v10-framework-compare","workers":4,"sequenceNumber":232,"symbol":"BTCUSDT","exchangeEventTimeMillis":1784430152663,"localReceivedEpochMillis":1784430152653,"topSpreadTicks":-318,"bid5Volume":198,"ask5Volume":148,"bid10Volume":477,"ask10Volume":296,"rawPayload":"{\"stream\":\"btcusdt@depth@100ms\",\"data\":{\"e\":\"depthUpdate\",\"E\":1784430152663,\"s\":\"BTCUSDT\",\"U\":3244441343,\"u\":3244441344,\"b\":[[\"64786.88000000\",\"0.03088000\"],[\"64785.22000000\",\"0.00000000\"]],\"a\":[]}}"}
{"mode":"v10-framework-compare","workers":4,"sequenceNumber":233,"symbol":"XRPUSDT","exchangeEventTimeMillis":1784430152663,"localReceivedEpochMillis":1784430152653,"topSpreadTicks":0,"bid5Volume":5253000,"ask5Volume":1305500,"bid10Volume":15532200,"ask10Volume":2503400,"rawPayload":"{\"stream\":\"xrpusdt@depth@100ms\",\"data\":{\"e\":\"depthUpdate\",\"E\":1784430152663,\"s\":\"XRPUSDT\",\"U\":752705390,\"u\":752705393,\"b\":[[\"1.09580000\",\"4632.60000000\"],[\"1.09570000\",\"103.00000000\"]],\"a\":[[\"1.09640000\",\"0.00000000\"],[\"1.09650000\",\"990.20000000\"]]}}"}
{"mode":"v10-framework-compare","workers":4,"sequenceNumber":234,"symbol":"BTCUSDT","exchangeEventTimeMillis":1784430152763,"localReceivedEpochMillis":1784430152752,"topSpreadTicks":-318,"bid5Volume":198,"ask5Volume":148,"bid10Volume":477,"ask10Volume":296,"rawPayload":"{\"stream\":\"btcusdt@depth@100ms\",\"data\":{\"e\":\"depthUpdate\",\"E\":1784430152763,\"s\":\"BTCUSDT\",\"U\":3244441345,\"u\":3244441346,\"b\":[[\"64788.51000000\",\"0.03088000\"],[\"64786.88000000\",\"0.00000000\"]],\"a\":[]}}"}
{"mode":"v10-framework-compare","workers":4,"sequenceNumber":235,"symbol":"SOLUSDT","exchangeEventTimeMillis":1784430152763,"localReceivedEpochMillis":1784430152753,"topSpreadTicks":-3,"bid5Volume":217050,"ask5Volume":174733,"bid10Volume":447488,"ask10Volume":447692,"rawPayload":"{\"stream\":\"solusdt@depth@100ms\",\"data\":{\"e\":\"depthUpdate\",\"E\":1784430152763,\"s\":\"SOLUSDT\",\"U\":1609580004,\"u\":1609580005,\"b\":[[\"76.18000000\",\"42.42700000\"],[\"76.17000000\",\"95.71000000\"]],\"a\":[]}}"}
{"mode":"v10-framework-compare","workers":4,"sequenceNumber":236,"symbol":"ETHUSDT","exchangeEventTimeMillis":1784430152763,"localReceivedEpochMillis":1784430152753,"topSpreadTicks":-7,"bid5Volume":4451,"ask5Volume":5508,"bid10Volume":10090,"ask10Volume":9887,"rawPayload":"{\"stream\":\"ethusdt@depth@100ms\",\"data\":{\"e\":\"depthUpdate\",\"E\":1784430152763,\"s\":\"ETHUSDT\",\"U\":2806177989,\"u\":2806178025,\"b\":[[\"1870.54000000\",\"0.00000000\"],[\"1870.46000000\",\"1.12920000\"],[\"1870.45000000\",\"0.00000000\"],[\"1870.28000000\",\"0.00000000\"],[\"1870.10000000\",\"0.13900000\"],[\"1870.08000000\",\"1.40730000\"],[\"1869.96000000\",\"0.00000000\"],[\"1869.80000000\",\"1.47590000\"],[\"1869.72000000\",\"0.00000000\"],[\"1869.68000000\",\"1.15470000\"],[\"1869.47000000\",\"0.00000000\"]],\"a\":[[\"1870.61000000\",\"0.00000000\"],[\"1870.62000000\",\"0.00000000\"],[\"1870.77000000\",\"0.13890000\"],[\"1870.85000000\",\"0.00000000\"],[\"1870.92000000\",\"0.00000000\"],[\"1871.02000000\",\"0.00000000\"],[\"1871.03000000\",\"1.19590000\"],[\"1871.07000000\",\"1.47500000\"],[\"1871.08000000\",\"0.00000000\"],[\"1871.11000000\",\"0.00000000\"],[\"1871.18000000\",\"0.68720000\"],[\"1871.60000000\",\"0.00000000\"],[\"1872.01000000\",\"1.05410000\"],[\"1877.80000000\",\"0.00000000\"],[\"1877.82000000\",\"0.00000000\"],[\"1878.16000000\",\"8.48660000\"],[\"1879.37000000\",\"0.00000000\"]]}}"}
{"mode":"v10-framework-compare","workers":4,"sequenceNumber":237,"symbol":"XRPUSDT","exchangeEventTimeMillis":1784430152763,"localReceivedEpochMillis":1784430152753,"topSpreadTicks":0,"bid5Volume":6658400,"ask5Volume":584400,"bid10Volume":16937600,"ask10Volume":1782300,"rawPayload":"{\"stream\":\"xrpusdt@depth@100ms\",\"data\":{\"e\":\"depthUpdate\",\"E\":1784430152763,\"s\":\"XRPUSDT\",\"U\":752705394,\"u\":752705401,\"b\":[[\"1.09590000\",\"987.80000000\"],[\"1.09580000\",\"3676.30000000\"],[\"1.09570000\",\"222.10000000\"],[\"1.09560000\",\"1508.40000000\"]],\"a\":[[\"1.09620000\",\"3763.40000000\"],[\"1.09630000\",\"1612.30000000\"],[\"1.09640000\",\"269.10000000\"]]}}"}
{"mode":"v10-framework-compare","workers":4,"sequenceNumber":238,"symbol":"ETHUSDT","exchangeEventTimeMillis":1784430152863,"localReceivedEpochMillis":1784430152854,"topSpreadTicks":-7,"bid5Volume":4451,"ask5Volume":5508,"bid10Volume":9879,"ask10Volume":9887,"rawPayload":"{\"stream\":\"ethusdt@depth@100ms\",\"data\":{\"e\":\"depthUpdate\",\"E\":1784430152863,\"s\":\"ETHUSDT\",\"U\":2806178026,\"u\":2806178029,\"b\":[[\"1870.08000000\",\"0.75000000\"],[\"1870.03000000\",\"0.47560000\"],[\"1861.48000000\",\"0.00000000\"]],\"a\":[[\"1878.31000000\",\"8.51480000\"]]}}"}
{"mode":"v10-framework-compare","workers":4,"sequenceNumber":239,"symbol":"BTCUSDT","exchangeEventTimeMillis":1784430152863,"localReceivedEpochMillis":1784430152854,"topSpreadTicks":-318,"bid5Volume":198,"ask5Volume":148,"bid10Volume":477,"ask10Volume":296,"rawPayload":"{\"stream\":\"btcusdt@depth@100ms\",\"data\":{\"e\":\"depthUpdate\",\"E\":1784430152863,\"s\":\"BTCUSDT\",\"U\":3244441347,\"u\":3244441347,\"b\":[],\"a\":[[\"81055.16000000\",\"0.00075000\"]]}}"}
{"mode":"v10-framework-compare","workers":4,"sequenceNumber":240,"symbol":"XRPUSDT","exchangeEventTimeMillis":1784430152863,"localReceivedEpochMillis":1784430152854,"topSpreadTicks":1,"bid5Volume":15059000,"ask5Volume":25404400,"bid10Volume":15429200,"ask10Volume":26602300,"rawPayload":"{\"stream\":\"xrpusdt@depth@100ms\",\"data\":{\"e\":\"depthUpdate\",\"E\":1784430152863,\"s\":\"XRPUSDT\",\"U\":752705402,\"u\":752705408,\"b\":[[\"1.09590000\",\"3270.60000000\"],[\"1.09580000\",\"1393.40000000\"],[\"1.09090000\",\"0.00000000\"]],\"a\":[[\"1.09620000\",\"1481.10000000\"],[\"1.09640000\",\"2550.90000000\"],[\"1.09770000\",\"172.40000000\"],[\"1.09980000\",\"25089.10000000\"]]}}"}
{"mode":"v10-framework-compare","workers":4,"sequenceNumber":241,"symbol":"SOLUSDT","exchangeEventTimeMillis":1784430152963,"localReceivedEpochMillis":1784430152952,"topSpreadTicks":-3,"bid5Volume":217050,"ask5Volume":164031,"bid10Volume":447488,"ask10Volume":436990,"rawPayload":"{\"stream\":\"solusdt@depth@100ms\",\"data\":{\"e\":\"depthUpdate\",\"E\":1784430152963,\"s\":\"SOLUSDT\",\"U\":1609580006,\"u\":1609580006,\"b\":[],\"a\":[[\"76.22000000\",\"49.64100000\"]]}}"}
{"mode":"v10-framework-compare","workers":4,"sequenceNumber":242,"symbol":"ETHUSDT","exchangeEventTimeMillis":1784430152963,"localReceivedEpochMillis":1784430152952,"topSpreadTicks":-7,"bid5Volume":4451,"ask5Volume":5508,"bid10Volume":9879,"ask10Volume":9887,"rawPayload":"{\"stream\":\"ethusdt@depth@100ms\",\"data\":{\"e\":\"depthUpdate\",\"E\":1784430152963,\"s\":\"ETHUSDT\",\"U\":2806178030,\"u\":2806178035,\"b\":[[\"1868.51000000\",\"0.00000000\"],[\"1868.43000000\",\"2.00910000\"],[\"1867.39000000\",\"0.00000000\"],[\"1867.31000000\",\"3.06430000\"],[\"1866.27000000\",\"0.00000000\"],[\"1866.19000000\",\"6.29250000\"],[\"1864.02000000\",\"0.00000000\"],[\"1863.94000000\",\"13.86920000\"]],\"a\":[[\"1872.93000000\",\"1.97600000\"],[\"1873.01000000\",\"0.00000000\"],[\"1875.17000000\",\"6.19570000\"],[\"1875.25000000\",\"0.00000000\"]]}}"}
{"mode":"v10-framework-compare","workers":4,"sequenceNumber":243,"symbol":"XRPUSDT","exchangeEventTimeMillis":1784430152963,"localReceivedEpochMillis":1784430152952,"topSpreadTicks":1,"bid5Volume":15059000,"ask5Volume":584400,"bid10Volume":15429200,"ask10Volume":1782300,"rawPayload":"{\"stream\":\"xrpusdt@depth@100ms\",\"data\":{\"e\":\"depthUpdate\",\"E\":1784430152963,\"s\":\"XRPUSDT\",\"U\":752705409,\"u\":752705410,\"b\":[],\"a\":[[\"1.09630000\",\"3894.30000000\"],[\"1.09640000\",\"269.10000000\"]]}}"}
{"mode":"v10-framework-compare","workers":4,"sequenceNumber":244,"symbol":"SOLUSDT","exchangeEventTimeMillis":1784430153063,"localReceivedEpochMillis":1784430153053,"topSpreadTicks":-3,"bid5Volume":217050,"ask5Volume":175328,"bid10Volume":447488,"ask10Volume":448287,"rawPayload":"{\"stream\":\"solusdt@depth@100ms\",\"data\":{\"e\":\"depthUpdate\",\"E\":1784430153063,\"s\":\"SOLUSDT\",\"U\":1609580007,\"u\":1609580007,\"b\":[],\"a\":[[\"76.23000000\",\"53.47200000\"]]}}"}
{"mode":"v10-framework-compare","workers":4,"sequenceNumber":245,"symbol":"ETHUSDT","exchangeEventTimeMillis":1784430153063,"localReceivedEpochMillis":1784430153053,"topSpreadTicks":-7,"bid5Volume":5649,"ask5Volume":5784,"bid10Volume":9741,"ask10Volume":11169,"rawPayload":"{\"stream\":\"ethusdt@depth@100ms\",\"data\":{\"e\":\"depthUpdate\",\"E\":1784430153063,\"s\":\"ETHUSDT\",\"U\":2806178036,\"u\":2806178039,\"b\":[[\"1870.29000000\",\"1.33760000\"],[\"1862.89000000\",\"7.21400000\"]],\"a\":[[\"1870.94000000\",\"1.33710000\"],[\"1879.36000000\",\"9.31610000\"]]}}"}
{"mode":"v10-framework-compare","workers":4,"sequenceNumber":246,"symbol":"XRPUSDT","exchangeEventTimeMillis":1784430153063,"localReceivedEpochMillis":1784430153054,"topSpreadTicks":0,"bid5Volume":20731400,"ask5Volume":584400,"bid10Volume":31010600,"ask10Volume":1782300,"rawPayload":"{\"stream\":\"xrpusdt@depth@100ms\",\"data\":{\"e\":\"depthUpdate\",\"E\":1784430153063,\"s\":\"XRPUSDT\",\"U\":752705411,\"u\":752705411,\"b\":[[\"1.09430000\",\"15581.40000000\"]],\"a\":[]}}"}
{"mode":"v10-framework-compare","workers":4,"sequenceNumber":247,"symbol":"BNBUSDT","exchangeEventTimeMillis":1784430153163,"localReceivedEpochMillis":1784430153152,"topSpreadTicks":4,"bid5Volume":5006,"ask5Volume":6283,"bid10Volume":15253,"ask10Volume":257274,"rawPayload":"{\"stream\":\"bnbusdt@depth@100ms\",\"data\":{\"e\":\"depthUpdate\",\"E\":1784430153163,\"s\":\"BNBUSDT\",\"U\":1236331339,\"u\":1236331340,\"b\":[],\"a\":[[\"570.61000000\",\"0.00000000\"],[\"570.63000000\",\"0.87600000\"]]}}"}
{"mode":"v10-framework-compare","workers":4,"sequenceNumber":248,"symbol":"BTCUSDT","exchangeEventTimeMillis":1784430153564,"localReceivedEpochMillis":1784430153553,"topSpreadTicks":-318,"bid5Volume":198,"ask5Volume":148,"bid10Volume":477,"ask10Volume":296,"rawPayload":"{\"stream\":\"btcusdt@depth@100ms\",\"data\":{\"e\":\"depthUpdate\",\"E\":1784430153564,\"s\":\"BTCUSDT\",\"U\":3244441348,\"u\":3244441348,\"b\":[],\"a\":[[\"64914.49000000\",\"0.00000000\"]]}}"}
{"mode":"v10-framework-compare","workers":4,"sequenceNumber":249,"symbol":"ETHUSDT","exchangeEventTimeMillis":1784430153564,"localReceivedEpochMillis":1784430153553,"topSpreadTicks":-18,"bid5Volume":5649,"ask5Volume":11312,"bid10Volume":9741,"ask10Volume":17369,"rawPayload":"{\"stream\":\"ethusdt@depth@100ms\",\"data\":{\"e\":\"depthUpdate\",\"E\":1784430153564,\"s\":\"ETHUSDT\",\"U\":2806178040,\"u\":2806178042,\"b\":[],\"a\":[[\"1870.66000000\",\"0.02960000\"],[\"1871.02000000\",\"8.16940000\"],[\"1871.77000000\",\"0.00000000\"]]}}"}
{"mode":"v10-framework-compare","workers":4,"sequenceNumber":250,"symbol":"BTCUSDT","exchangeEventTimeMillis":1784430153664,"localReceivedEpochMillis":1784430153653,"topSpreadTicks":-318,"bid5Volume":198,"ask5Volume":148,"bid10Volume":477,"ask10Volume":296,"rawPayload":"{\"stream\":\"btcusdt@depth@100ms\",\"data\":{\"e\":\"depthUpdate\",\"E\":1784430153664,\"s\":\"BTCUSDT\",\"U\":3244441349,\"u\":3244441349,\"b\":[],\"a\":[[\"64914.49000000\",\"0.00011000\"]]}}"}
{"mode":"v10-framework-compare","workers":4,"sequenceNumber":251,"symbol":"SOLUSDT","exchangeEventTimeMillis":1784430153764,"localReceivedEpochMillis":1784430153753,"topSpreadTicks":-3,"bid5Volume":217050,"ask5Volume":175328,"bid10Volume":447488,"ask10Volume":448287,"rawPayload":"{\"stream\":\"solusdt@depth@100ms\",\"data\":{\"e\":\"depthUpdate\",\"E\":1784430153764,\"s\":\"SOLUSDT\",\"U\":1609580008,\"u\":1609580008,\"b\":[],\"a\":[[\"76.22000000\",\"68.27600000\"],[\"76.23000000\",\"34.83700000\"]]}}"}
{"mode":"v10-framework-compare","workers":4,"sequenceNumber":252,"symbol":"SOLUSDT","exchangeEventTimeMillis":1784430153864,"localReceivedEpochMillis":1784430153853,"topSpreadTicks":-3,"bid5Volume":217050,"ask5Volume":175328,"bid10Volume":451997,"ask10Volume":448287,"rawPayload":"{\"stream\":\"solusdt@depth@100ms\",\"data\":{\"e\":\"depthUpdate\",\"E\":1784430153864,\"s\":\"SOLUSDT\",\"U\":1609580009,\"u\":1609580010,\"b\":[[\"76.15000000\",\"47.70700000\"],[\"76.14000000\",\"0.00000000\"]],\"a\":[]}}"}
{"mode":"v10-framework-compare","workers":4,"sequenceNumber":253,"symbol":"XRPUSDT","exchangeEventTimeMillis":1784430153864,"localReceivedEpochMillis":1784430153854,"topSpreadTicks":0,"bid5Volume":5195500,"ask5Volume":5453600,"bid10Volume":15474700,"ask10Volume":6651500,"rawPayload":"{\"stream\":\"xrpusdt@depth@100ms\",\"data\":{\"e\":\"depthUpdate\",\"E\":1784430153864,\"s\":\"XRPUSDT\",\"U\":752705412,\"u\":752705413,\"b\":[[\"1.09590000\",\"4618.50000000\"],[\"1.09580000\",\"45.50000000\"]],\"a\":[[\"1.09620000\",\"237.10000000\"],[\"1.09630000\",\"5138.30000000\"]]}}"}
{"mode":"v10-framework-compare","workers":4,"sequenceNumber":254,"symbol":"ETHUSDT","exchangeEventTimeMillis":1784430153964,"localReceivedEpochMillis":1784430153953,"topSpreadTicks":-18,"bid5Volume":5098,"ask5Volume":3600,"bid10Volume":8149,"ask10Volume":16139,"rawPayload":"{\"stream\":\"ethusdt@depth@100ms\",\"data\":{\"e\":\"depthUpdate\",\"E\":1784430153964,\"s\":\"ETHUSDT\",\"U\":2806178043,\"u\":2806178057,\"b\":[[\"1870.46000000\",\"0.00000000\"],[\"1870.42000000\",\"1.16340000\"],[\"1870.36000000\",\"0.00000000\"],[\"1870.30000000\",\"0.75280000\"],[\"1870.08000000\",\"0.00000000\"],[\"1870.03000000\",\"0.02960000\"],[\"1869.93000000\",\"0.45790000\"]],\"a\":[[\"1870.67000000\",\"0.45790000\"],[\"1870.81000000\",\"1.33720000\"],[\"1870.93000000\",\"0.00000000\"],[\"1870.94000000\",\"0.00000000\"],[\"1870.99000000\",\"1.14740000\"],[\"1871.03000000\",\"0.00000000\"]]}}"}
{"mode":"v10-framework-compare","workers":4,"sequenceNumber":255,"symbol":"BTCUSDT","exchangeEventTimeMillis":1784430153964,"localReceivedEpochMillis":1784430153953,"topSpreadTicks":-318,"bid5Volume":198,"ask5Volume":148,"bid10Volume":477,"ask10Volume":296,"rawPayload":"{\"stream\":\"btcusdt@depth@100ms\",\"data\":{\"e\":\"depthUpdate\",\"E\":1784430153964,\"s\":\"BTCUSDT\",\"U\":3244441350,\"u\":3244441351,\"b\":[[\"64788.51000000\",\"0.00000000\"],[\"64786.49000000\",\"0.03088000\"]],\"a\":[]}}"}
{"mode":"v10-framework-compare","workers":4,"sequenceNumber":256,"symbol":"SOLUSDT","exchangeEventTimeMillis":1784430154264,"localReceivedEpochMillis":1784430154253,"topSpreadTicks":-3,"bid5Volume":217050,"ask5Volume":175328,"bid10Volume":451997,"ask10Volume":447913,"rawPayload":"{\"stream\":\"solusdt@depth@100ms\",\"data\":{\"e\":\"depthUpdate\",\"E\":1784430154264,\"s\":\"SOLUSDT\",\"U\":1609580011,\"u\":1609580014,\"b\":[],\"a\":[[\"76.24000000\",\"33.47800000\"],[\"76.25000000\",\"43.73900000\"]]}}"}
{"mode":"v10-framework-compare","workers":4,"sequenceNumber":257,"symbol":"XRPUSDT","exchangeEventTimeMillis":1784430154464,"localReceivedEpochMillis":1784430154453,"topSpreadTicks":0,"bid5Volume":5225100,"ask5Volume":11754400,"bid10Volume":15504300,"ask10Volume":12952300,"rawPayload":"{\"stream\":\"xrpusdt@depth@100ms\",\"data\":{\"e\":\"depthUpdate\",\"E\":1784430154464,\"s\":\"XRPUSDT\",\"U\":752705414,\"u\":752705419,\"b\":[[\"1.09570000\",\"459.30000000\"],[\"1.09550000\",\"2248.00000000\"],[\"1.09530000\",\"4959.40000000\"],[\"1.09510000\",\"0.00000000\"],[\"1.09460000\",\"6897.20000000\"],[\"1.09440000\",\"75.10000000\"]],\"a\":[[\"1.09620000\",\"0.00000000\"],[\"1.09640000\",\"506.20000000\"],[\"1.09660000\",\"494.00000000\"],[\"1.09680000\",\"2516.50000000\"],[\"1.09730000\",\"2074.70000000\"],[\"1.09750000\",\"11439.10000000\"]]}}"}
{"mode":"v10-framework-compare","workers":4,"sequenceNumber":258,"symbol":"ETHUSDT","exchangeEventTimeMillis":1784430154464,"localReceivedEpochMillis":1784430154454,"topSpreadTicks":-18,"bid5Volume":5115,"ask5Volume":3600,"bid10Volume":8166,"ask10Volume":16631,"rawPayload":"{\"stream\":\"ethusdt@depth@100ms\",\"data\":{\"e\":\"depthUpdate\",\"E\":1784430154464,\"s\":\"ETHUSDT\",\"U\":2806178058,\"u\":2806178062,\"b\":[[\"1870.42000000\",\"0.00000000\"],[\"1870.33000000\",\"1.18040000\"]],\"a\":[[\"1870.90000000\",\"0.00000000\"],[\"1870.99000000\",\"0.00000000\"]]}}"}
{"mode":"v10-framework-compare","workers":4,"sequenceNumber":259,"symbol":"ETHUSDT","exchangeEventTimeMillis":1784430154564,"localReceivedEpochMillis":1784430154554,"topSpreadTicks":-18,"bid5Volume":5101,"ask5Volume":3600,"bid10Volume":8152,"ask10Volume":16162,"rawPayload":"{\"stream\":\"ethusdt@depth@100ms\",\"data\":{\"e\":\"depthUpdate\",\"E\":1784430154564,\"s\":\"ETHUSDT\",\"U\":2806178063,\"u\":2806178065,\"b\":[[\"1870.39000000\",\"1.16690000\"],[\"1870.33000000\",\"0.00000000\"]],\"a\":[[\"1870.96000000\",\"1.17080000\"]]}}"}
{"mode":"v10-framework-compare","workers":4,"sequenceNumber":260,"symbol":"XRPUSDT","exchangeEventTimeMillis":1784430154564,"localReceivedEpochMillis":1784430154554,"topSpreadTicks":0,"bid5Volume":6508400,"ask5Volume":1802200,"bid10Volume":16787600,"ask10Volume":3000100,"rawPayload":"{\"stream\":\"xrpusdt@depth@100ms\",\"data\":{\"e\":\"depthUpdate\",\"E\":1784430154564,\"s\":\"XRPUSDT\",\"U\":752705420,\"u\":752705425,\"b\":[[\"1.09600000\",\"1006.80000000\"],[\"1.09590000\",\"3785.70000000\"],[\"1.09560000\",\"1358.40000000\"]],\"a\":[[\"1.09650000\",\"0.00000000\"],[\"1.09660000\",\"1486.90000000\"]]}}"}
{"mode":"v10-framework-compare","workers":4,"sequenceNumber":261,"symbol":"ETHUSDT","exchangeEventTimeMillis":1784430154764,"localReceivedEpochMillis":1784430154754,"topSpreadTicks":-18,"bid5Volume":5101,"ask5Volume":3600,"bid10Volume":8152,"ask10Volume":17114,"rawPayload":"{\"stream\":\"ethusdt@depth@100ms\",\"data\":{\"e\":\"depthUpdate\",\"E\":1784430154764,\"s\":\"ETHUSDT\",\"U\":2806178066,\"u\":2806178066,\"b\":[],\"a\":[[\"1871.18000000\",\"0.00000000\"]]}}"}
{"mode":"v10-framework-compare","workers":4,"sequenceNumber":262,"symbol":"BNBUSDT","exchangeEventTimeMillis":1784430154864,"localReceivedEpochMillis":1784430154854,"topSpreadTicks":4,"bid5Volume":5929,"ask5Volume":6283,"bid10Volume":20004,"ask10Volume":257274,"rawPayload":"{\"stream\":\"bnbusdt@depth@100ms\",\"data\":{\"e\":\"depthUpdate\",\"E\":1784430154864,\"s\":\"BNBUSDT\",\"U\":1236331341,\"u\":1236331344,\"b\":[[\"570.39000000\",\"1.84100000\"],[\"570.33000000\",\"0.00000000\"]],\"a\":[[\"570.63000000\",\"0.00000000\"],[\"570.65000000\",\"0.87600000\"]]}}"}
{"mode":"v10-framework-compare","workers":4,"sequenceNumber":263,"symbol":"XRPUSDT","exchangeEventTimeMillis":1784430154964,"localReceivedEpochMillis":1784430154954,"topSpreadTicks":0,"bid5Volume":9955800,"ask5Volume":1802200,"bid10Volume":20235000,"ask10Volume":3000100,"rawPayload":"{\"stream\":\"xrpusdt@depth@100ms\",\"data\":{\"e\":\"depthUpdate\",\"E\":1784430154964,\"s\":\"XRPUSDT\",\"U\":752705426,\"u\":752705427,\"b\":[[\"1.09600000\",\"0.00000000\"],[\"1.09590000\",\"4805.80000000\"]],\"a\":[]}}"}
{"mode":"v10-framework-compare","workers":4,"sequenceNumber":264,"symbol":"ETHUSDT","exchangeEventTimeMillis":1784430155065,"localReceivedEpochMillis":1784430155054,"topSpreadTicks":-18,"bid5Volume":5101,"ask5Volume":3600,"bid10Volume":8152,"ask10Volume":17114,"rawPayload":"{\"stream\":\"ethusdt@depth@100ms\",\"data\":{\"e\":\"depthUpdate\",\"E\":1784430155065,\"s\":\"ETHUSDT\",\"U\":2806178067,\"u\":2806178067,\"b\":[],\"a\":[[\"1871.16000000\",\"1.06180000\"],[\"1871.17000000\",\"0.00000000\"]]}}"}
{"mode":"v10-framework-compare","workers":4,"sequenceNumber":265,"symbol":"BNBUSDT","exchangeEventTimeMillis":1784430155165,"localReceivedEpochMillis":1784430155154,"topSpreadTicks":4,"bid5Volume":5921,"ask5Volume":6283,"bid10Volume":19996,"ask10Volume":257268,"rawPayload":"{\"stream\":\"bnbusdt@depth@100ms\",\"data\":{\"e\":\"depthUpdate\",\"E\":1784430155165,\"s\":\"BNBUSDT\",\"U\":1236331345,\"u\":1236331352,\"b\":[[\"570.32000000\",\"0.91500000\"],[\"570.27000000\",\"0.00000000\"]],\"a\":[[\"570.68000000\",\"0.00000000\"],[\"570.73000000\",\"0.93300000\"]]}}"}
{"mode":"v10-framework-compare","workers":4,"sequenceNumber":266,"symbol":"XRPUSDT","exchangeEventTimeMillis":1784430155165,"localReceivedEpochMillis":1784430155154,"topSpreadTicks":0,"bid5Volume":5490200,"ask5Volume":1802200,"bid10Volume":15769400,"ask10Volume":3000100,"rawPayload":"{\"stream\":\"xrpusdt@depth@100ms\",\"data\":{\"e\":\"depthUpdate\",\"E\":1784430155165,\"s\":\"XRPUSDT\",\"U\":752705428,\"u\":752705430,\"b\":[[\"1.09590000\",\"3457.90000000\"],[\"1.09580000\",\"1520.90000000\"],[\"1.09570000\",\"340.20000000\"]],\"a\":[]}}"}
{"mode":"v10-framework-compare","workers":4,"sequenceNumber":267,"symbol":"BTCUSDT","exchangeEventTimeMillis":1784430155365,"localReceivedEpochMillis":1784430155354,"topSpreadTicks":-318,"bid5Volume":198,"ask5Volume":148,"bid10Volume":477,"ask10Volume":296,"rawPayload":"{\"stream\":\"btcusdt@depth@100ms\",\"data\":{\"e\":\"depthUpdate\",\"E\":1784430155365,\"s\":\"BTCUSDT\",\"U\":3244441352,\"u\":3244441352,\"b\":[],\"a\":[[\"81055.16000000\",\"0.00060000\"]]}}"}
{"mode":"v10-framework-compare","workers":4,"sequenceNumber":268,"symbol":"ETHUSDT","exchangeEventTimeMillis":1784430155465,"localReceivedEpochMillis":1784430155454,"topSpreadTicks":-18,"bid5Volume":5097,"ask5Volume":3600,"bid10Volume":8148,"ask10Volume":17046,"rawPayload":"{\"stream\":\"ethusdt@depth@100ms\",\"data\":{\"e\":\"depthUpdate\",\"E\":1784430155465,\"s\":\"ETHUSDT\",\"U\":2806178068,\"u\":2806178071,\"b\":[[\"1870.39000000\",\"0.00000000\"],[\"1870.32000000\",\"1.16260000\"]],\"a\":[[\"1870.89000000\",\"1.10230000\"],[\"1870.96000000\",\"0.00000000\"]]}}"}
{"mode":"v10-framework-compare","workers":4,"sequenceNumber":269,"symbol":"ETHUSDT","exchangeEventTimeMillis":1784430155865,"localReceivedEpochMillis":1784430155854,"topSpreadTicks":-18,"bid5Volume":5124,"ask5Volume":3600,"bid10Volume":8175,"ask10Volume":17140,"rawPayload":"{\"stream\":\"ethusdt@depth@100ms\",\"data\":{\"e\":\"depthUpdate\",\"E\":1784430155865,\"s\":\"ETHUSDT\",\"U\":2806178072,\"u\":2806178075,\"b\":[[\"1870.39000000\",\"1.18980000\"],[\"1870.32000000\",\"0.00000000\"]],\"a\":[[\"1870.89000000\",\"0.00000000\"],[\"1870.96000000\",\"1.19600000\"]]}}"}
{"mode":"v10-framework-compare","workers":4,"sequenceNumber":270,"symbol":"BNBUSDT","exchangeEventTimeMillis":1784430156165,"localReceivedEpochMillis":1784430156155,"topSpreadTicks":4,"bid5Volume":5921,"ask5Volume":6283,"bid10Volume":19996,"ask10Volume":257268,"rawPayload":"{\"stream\":\"bnbusdt@depth@100ms\",\"data\":{\"e\":\"depthUpdate\",\"E\":1784430156165,\"s\":\"BNBUSDT\",\"U\":1236331353,\"u\":1236331354,\"b\":[],\"a\":[[\"570.63000000\",\"0.87600000\"],[\"570.65000000\",\"0.00000000\"]]}}"}
{"mode":"v10-framework-compare","workers":4,"sequenceNumber":271,"symbol":"ETHUSDT","exchangeEventTimeMillis":1784430156265,"localReceivedEpochMillis":1784430156256,"topSpreadTicks":-18,"bid5Volume":5057,"ask5Volume":3600,"bid10Volume":8108,"ask10Volume":17083,"rawPayload":"{\"stream\":\"ethusdt@depth@100ms\",\"data\":{\"e\":\"depthUpdate\",\"E\":1784430156265,\"s\":\"ETHUSDT\",\"U\":2806178076,\"u\":2806178083,\"b\":[[\"1870.39000000\",\"0.00000000\"],[\"1870.32000000\",\"1.12230000\"],[\"1870.10000000\",\"0.00000000\"],[\"1870.02000000\",\"0.13900000\"],[\"1869.80000000\",\"0.00000000\"],[\"1869.72000000\",\"1.47610000\"]],\"a\":[[\"1870.68000000\",\"0.13890000\"],[\"1870.77000000\",\"0.00000000\"],[\"1870.89000000\",\"1.13920000\"],[\"1870.96000000\",\"0.00000000\"],[\"1870.98000000\",\"1.47510000\"],[\"1871.07000000\",\"0.00000000\"]]}}"}
{"mode":"v10-framework-compare","workers":4,"sequenceNumber":272,"symbol":"BNBUSDT","exchangeEventTimeMillis":1784430156265,"localReceivedEpochMillis":1784430156256,"topSpreadTicks":4,"bid5Volume":5152,"ask5Volume":6692,"bid10Volume":19992,"ask10Volume":257250,"rawPayload":"{\"stream\":\"bnbusdt@depth@100ms\",\"data\":{\"e\":\"depthUpdate\",\"E\":1784430156265,\"s\":\"BNBUSDT\",\"U\":1236331355,\"u\":1236331358,\"b\":[[\"570.32000000\",\"0.00000000\"],[\"570.27000000\",\"0.91100000\"]],\"a\":[[\"570.68000000\",\"0.91500000\"],[\"570.73000000\",\"0.00000000\"]]}}"}
{"mode":"v10-framework-compare","workers":4,"sequenceNumber":273,"symbol":"SOLUSDT","exchangeEventTimeMillis":1784430156666,"localReceivedEpochMillis":1784430156655,"topSpreadTicks":-3,"bid5Volume":217051,"ask5Volume":175329,"bid10Volume":451998,"ask10Volume":722146,"rawPayload":"{\"stream\":\"solusdt@depth@100ms\",\"data\":{\"e\":\"depthUpdate\",\"E\":1784430156666,\"s\":\"SOLUSDT\",\"U\":1609580015,\"u\":1609580017,\"b\":[[\"76.18000000\",\"39.01500000\"],[\"76.17000000\",\"99.12300000\"]],\"a\":[[\"76.22000000\",\"71.68700000\"],[\"76.23000000\",\"31.42700000\"],[\"76.25000000\",\"79.93700000\"],[\"76.26000000\",\"0.00000000\"]]}}"}
{"mode":"v10-framework-compare","workers":4,"sequenceNumber":274,"symbol":"SOLUSDT","exchangeEventTimeMillis":1784430156766,"localReceivedEpochMillis":1784430156756,"topSpreadTicks":-3,"bid5Volume":217051,"ask5Volume":175329,"bid10Volume":451998,"ask10Volume":722146,"rawPayload":"{\"stream\":\"solusdt@depth@100ms\",\"data\":{\"e\":\"depthUpdate\",\"E\":1784430156766,\"s\":\"SOLUSDT\",\"U\":1609580018,\"u\":1609580018,\"b\":[],\"a\":[[\"76.22000000\",\"53.05200000\"],[\"76.23000000\",\"50.06200000\"]]}}"}
{"mode":"v10-framework-compare","workers":4,"sequenceNumber":275,"symbol":"ETHUSDT","exchangeEventTimeMillis":1784430156766,"localReceivedEpochMillis":1784430156756,"topSpreadTicks":-18,"bid5Volume":5057,"ask5Volume":3600,"bid10Volume":9782,"ask10Volume":17083,"rawPayload":"{\"stream\":\"ethusdt@depth@100ms\",\"data\":{\"e\":\"depthUpdate\",\"E\":1784430156766,\"s\":\"ETHUSDT\",\"U\":2806178084,\"u\":2806178085,\"b\":[[\"1869.93000000\",\"0.00000000\"],[\"1869.88000000\",\"2.13130000\"]],\"a\":[]}}"}
{"mode":"v10-framework-compare","workers":4,"sequenceNumber":276,"symbol":"XRPUSDT","exchangeEventTimeMillis":1784430156766,"localReceivedEpochMillis":1784430156756,"topSpreadTicks":0,"bid5Volume":7758000,"ask5Volume":809300,"bid10Volume":18037200,"ask10Volume":2007200,"rawPayload":"{\"stream\":\"xrpusdt@depth@100ms\",\"data\":{\"e\":\"depthUpdate\",\"E\":1784430156766,\"s\":\"XRPUSDT\",\"U\":752705431,\"u\":752705436,\"b\":[[\"1.09590000\",\"2282.80000000\"],[\"1.09580000\",\"2608.00000000\"]],\"a\":[[\"1.09640000\",\"1509.70000000\"],[\"1.09660000\",\"494.00000000\"]]}}"}
{"mode":"v10-framework-compare","workers":4,"sequenceNumber":277,"symbol":"XRPUSDT","exchangeEventTimeMillis":1784430156866,"localReceivedEpochMillis":1784430156854,"topSpreadTicks":0,"bid5Volume":7773300,"ask5Volume":809300,"bid10Volume":18052500,"ask10Volume":2007200,"rawPayload":"{\"stream\":\"xrpusdt@depth@100ms\",\"data\":{\"e\":\"depthUpdate\",\"E\":1784430156866,\"s\":\"XRPUSDT\",\"U\":752705437,\"u\":752705444,\"b\":[[\"1.09590000\",\"2282.80000000\"],[\"1.09580000\",\"2623.30000000\"]],\"a\":[[\"1.09640000\",\"506.20000000\"],[\"1.09650000\",\"1002.90000000\"],[\"1.09660000\",\"494.00000000\"]]}}"}
{"mode":"v10-framework-compare","workers":4,"sequenceNumber":278,"symbol":"ETHUSDT","exchangeEventTimeMillis":1784430156966,"localReceivedEpochMillis":1784430156954,"topSpreadTicks":-18,"bid5Volume":5110,"ask5Volume":3600,"bid10Volume":9835,"ask10Volume":17102,"rawPayload":"{\"stream\":\"ethusdt@depth@100ms\",\"data\":{\"e\":\"depthUpdate\",\"E\":1784430156966,\"s\":\"ETHUSDT\",\"U\":2806178086,\"u\":2806178089,\"b\":[[\"1870.39000000\",\"1.17580000\"],[\"1870.32000000\",\"0.00000000\"]],\"a\":[[\"1870.89000000\",\"0.00000000\"],[\"1870.96000000\",\"1.15880000\"]]}}"}
{"mode":"v10-framework-compare","workers":4,"sequenceNumber":279,"symbol":"BTCUSDT","exchangeEventTimeMillis":1784430157466,"localReceivedEpochMillis":1784430157456,"topSpreadTicks":-318,"bid5Volume":198,"ask5Volume":148,"bid10Volume":477,"ask10Volume":296,"rawPayload":"{\"stream\":\"btcusdt@depth@100ms\",\"data\":{\"e\":\"depthUpdate\",\"E\":1784430157466,\"s\":\"BTCUSDT\",\"U\":3244441353,\"u\":3244441353,\"b\":[],\"a\":[[\"64914.49000000\",\"0.00000000\"]]}}"}
{"mode":"v10-framework-compare","workers":4,"sequenceNumber":280,"symbol":"BTCUSDT","exchangeEventTimeMillis":1784430157566,"localReceivedEpochMillis":1784430157556,"topSpreadTicks":-318,"bid5Volume":198,"ask5Volume":148,"bid10Volume":477,"ask10Volume":296,"rawPayload":"{\"stream\":\"btcusdt@depth@100ms\",\"data\":{\"e\":\"depthUpdate\",\"E\":1784430157566,\"s\":\"BTCUSDT\",\"U\":3244441354,\"u\":3244441354,\"b\":[],\"a\":[[\"64914.49000000\",\"0.00011000\"]]}}"}
{"mode":"v10-framework-compare","workers":4,"sequenceNumber":281,"symbol":"XRPUSDT","exchangeEventTimeMillis":1784430157766,"localReceivedEpochMillis":1784430157757,"topSpreadTicks":0,"bid5Volume":9744300,"ask5Volume":809300,"bid10Volume":20023500,"ask10Volume":2007200,"rawPayload":"{\"stream\":\"xrpusdt@depth@100ms\",\"data\":{\"e\":\"depthUpdate\",\"E\":1784430157766,\"s\":\"XRPUSDT\",\"U\":752705445,\"u\":752705446,\"b\":[[\"1.09550000\",\"2524.10000000\"],[\"1.09530000\",\"4594.30000000\"]],\"a\":[]}}"}
{"mode":"v10-framework-compare","workers":4,"sequenceNumber":282,"symbol":"ETHUSDT","exchangeEventTimeMillis":1784430158067,"localReceivedEpochMillis":1784430158056,"topSpreadTicks":-18,"bid5Volume":5126,"ask5Volume":3600,"bid10Volume":9851,"ask10Volume":17104,"rawPayload":"{\"stream\":\"ethusdt@depth@100ms\",\"data\":{\"e\":\"depthUpdate\",\"E\":1784430158067,\"s\":\"ETHUSDT\",\"U\":2806178090,\"u\":2806178093,\"b\":[[\"1870.39000000\",\"0.00000000\"],[\"1870.33000000\",\"1.19100000\"]],\"a\":[[\"1870.90000000\",\"1.16000000\"],[\"1870.96000000\",\"0.00000000\"]]}}"}
{"mode":"v10-framework-compare","workers":4,"sequenceNumber":283,"symbol":"XRPUSDT","exchangeEventTimeMillis":1784430158067,"localReceivedEpochMillis":1784430158056,"topSpreadTicks":0,"bid5Volume":14267900,"ask5Volume":13167000,"bid10Volume":24547100,"ask10Volume":14364900,"rawPayload":"{\"stream\":\"xrpusdt@depth@100ms\",\"data\":{\"e\":\"depthUpdate\",\"E\":1784430158067,\"s\":\"XRPUSDT\",\"U\":752705447,\"u\":752705454,\"b\":[[\"1.09490000\",\"0.00000000\"],[\"1.09470000\",\"6079.60000000\"],[\"1.09430000\",\"13011.70000000\"],[\"1.09400000\",\"18483.00000000\"],[\"1.09360000\",\"23045.20000000\"],[\"1.09330000\",\"4055.20000000\"],[\"1.09230000\",\"15923.70000000\"],[\"1.09200000\",\"9117.90000000\"]],\"a\":[[\"1.09740000\",\"1302.20000000\"],[\"1.09760000\",\"0.00000000\"],[\"1.09800000\",\"15484.60000000\"],[\"1.09830000\",\"0.00000000\"],[\"1.09870000\",\"19620.50000000\"],[\"1.09900000\",\"12851.70000000\"],[\"1.10000000\",\"8699.40000000\"],[\"1.10030000\",\"0.00000000\"]]}}"}
{"mode":"v10-framework-compare","workers":4,"sequenceNumber":284,"symbol":"BTCUSDT","exchangeEventTimeMillis":1784430158167,"localReceivedEpochMillis":1784430158156,"topSpreadTicks":-318,"bid5Volume":198,"ask5Volume":148,"bid10Volume":477,"ask10Volume":354,"rawPayload":"{\"stream\":\"btcusdt@depth@100ms\",\"data\":{\"e\":\"depthUpdate\",\"E\":1784430158167,\"s\":\"BTCUSDT\",\"U\":3244441355,\"u\":3244441356,\"b\":[],\"a\":[[\"64820.02000000\",\"0.06177000\"],[\"64833.09000000\",\"0.00000000\"]]}}"}
{"mode":"v10-framework-compare","workers":4,"sequenceNumber":285,"symbol":"XRPUSDT","exchangeEventTimeMillis":1784430158167,"localReceivedEpochMillis":1784430158157,"topSpreadTicks":0,"bid5Volume":6425400,"ask5Volume":13167000,"bid10Volume":16704600,"ask10Volume":14364900,"rawPayload":"{\"stream\":\"xrpusdt@depth@100ms\",\"data\":{\"e\":\"depthUpdate\",\"E\":1784430158167,\"s\":\"XRPUSDT\",\"U\":752705455,\"u\":752705455,\"b\":[[\"1.09590000\",\"3630.70000000\"],[\"1.09580000\",\"1275.40000000\"]],\"a\":[]}}"}
{"mode":"v10-framework-compare","workers":4,"sequenceNumber":286,"symbol":"ETHUSDT","exchangeEventTimeMillis":1784430158267,"localReceivedEpochMillis":1784430158255,"topSpreadTicks":-18,"bid5Volume":5126,"ask5Volume":4761,"bid10Volume":9359,"ask10Volume":18441,"rawPayload":"{\"stream\":\"ethusdt@depth@100ms\",\"data\":{\"e\":\"depthUpdate\",\"E\":1784430158267,\"s\":\"ETHUSDT\",\"U\":2806178094,\"u\":2806178101,\"b\":[[\"1870.29000000\",\"0.00000000\"],[\"1870.11000000\",\"1.33770000\"],[\"1869.88000000\",\"1.63970000\"],[\"1869.83000000\",\"0.51160000\"],[\"1869.68000000\",\"0.00000000\"],[\"1869.47000000\",\"0.76800000\"]],\"a\":[[\"1870.67000000\",\"1.79520000\"],[\"1870.81000000\",\"0.00000000\"]]}}"}
{"mode":"v10-framework-compare","workers":4,"sequenceNumber":287,"symbol":"ETHUSDT","exchangeEventTimeMillis":1784430158567,"localReceivedEpochMillis":1784430158557,"topSpreadTicks":-18,"bid5Volume":5126,"ask5Volume":4761,"bid10Volume":9841,"ask10Volume":18441,"rawPayload":"{\"stream\":\"ethusdt@depth@100ms\",\"data\":{\"e\":\"depthUpdate\",\"E\":1784430158567,\"s\":\"ETHUSDT\",\"U\":2806178102,\"u\":2806178102,\"b\":[[\"1870.03000000\",\"0.00000000\"]],\"a\":[]}}"}
{"mode":"v10-framework-compare","workers":4,"sequenceNumber":288,"symbol":"BTCUSDT","exchangeEventTimeMillis":1784430158867,"localReceivedEpochMillis":1784430158857,"topSpreadTicks":-318,"bid5Volume":198,"ask5Volume":148,"bid10Volume":477,"ask10Volume":354,"rawPayload":"{\"stream\":\"btcusdt@depth@100ms\",\"data\":{\"e\":\"depthUpdate\",\"E\":1784430158867,\"s\":\"BTCUSDT\",\"U\":3244441357,\"u\":3244441357,\"b\":[],\"a\":[[\"81055.16000000\",\"0.00060000\"]]}}"}
{"mode":"v10-framework-compare","workers":4,"sequenceNumber":289,"symbol":"ETHUSDT","exchangeEventTimeMillis":1784430158867,"localReceivedEpochMillis":1784430158857,"topSpreadTicks":-19,"bid5Volume":5126,"ask5Volume":3600,"bid10Volume":8781,"ask10Volume":17104,"rawPayload":"{\"stream\":\"ethusdt@depth@100ms\",\"data\":{\"e\":\"depthUpdate\",\"E\":1784430158867,\"s\":\"ETHUSDT\",\"U\":2806178103,\"u\":2806178105,\"b\":[[\"1870.07000000\",\"0.02980000\"]],\"a\":[[\"1870.65000000\",\"1.33730000\"],[\"1870.67000000\",\"0.45790000\"]]}}"}
{"mode":"v10-framework-compare","workers":4,"sequenceNumber":290,"symbol":"ETHUSDT","exchangeEventTimeMillis":1784430159167,"localReceivedEpochMillis":1784430159157,"topSpreadTicks":-19,"bid5Volume":5126,"ask5Volume":3600,"bid10Volume":8781,"ask10Volume":17104,"rawPayload":"{\"stream\":\"ethusdt@depth@100ms\",\"data\":{\"e\":\"depthUpdate\",\"E\":1784430159167,\"s\":\"ETHUSDT\",\"U\":2806178106,\"u\":2806178107,\"b\":[[\"1870.34000000\",\"0.75280000\"],[\"1870.30000000\",\"0.00000000\"]],\"a\":[]}}"}
{"mode":"v10-framework-compare","workers":4,"sequenceNumber":291,"symbol":"ETHUSDT","exchangeEventTimeMillis":1784430159267,"localReceivedEpochMillis":1784430159257,"topSpreadTicks":-19,"bid5Volume":5126,"ask5Volume":3600,"bid10Volume":9022,"ask10Volume":17104,"rawPayload":"{\"stream\":\"ethusdt@depth@100ms\",\"data\":{\"e\":\"depthUpdate\",\"E\":1784430159267,\"s\":\"ETHUSDT\",\"U\":2806178108,\"u\":2806178108,\"b\":[[\"1870.30000000\",\"0.75280000\"]],\"a\":[]}}"}
{"mode":"v10-framework-compare","workers":4,"sequenceNumber":292,"symbol":"SOLUSDT","exchangeEventTimeMillis":1784430159568,"localReceivedEpochMillis":1784430159558,"topSpreadTicks":-3,"bid5Volume":217051,"ask5Volume":175329,"bid10Volume":451998,"ask10Volume":1053229,"rawPayload":"{\"stream\":\"solusdt@depth@100ms\",\"data\":{\"e\":\"depthUpdate\",\"E\":1784430159568,\"s\":\"SOLUSDT\",\"U\":1609580019,\"u\":1609580020,\"b\":[[\"76.07000000\",\"383.35800000\"],[\"76.06000000\",\"309.19600000\"]],\"a\":[[\"76.30000000\",\"118.37600000\"],[\"76.31000000\",\"0.00000000\"]]}}"}
{"mode":"v10-framework-compare","workers":4,"sequenceNumber":293,"symbol":"BTCUSDT","exchangeEventTimeMillis":1784430159868,"localReceivedEpochMillis":1784430159858,"topSpreadTicks":-318,"bid5Volume":198,"ask5Volume":148,"bid10Volume":477,"ask10Volume":354,"rawPayload":"{\"stream\":\"btcusdt@depth@100ms\",\"data\":{\"e\":\"depthUpdate\",\"E\":1784430159868,\"s\":\"BTCUSDT\",\"U\":3244441358,\"u\":3244441359,\"b\":[[\"64788.32000000\",\"0.03088000\"],[\"64786.49000000\",\"0.00000000\"]],\"a\":[]}}"}
{"mode":"v10-framework-compare","workers":4,"sequenceNumber":294,"symbol":"ETHUSDT","exchangeEventTimeMillis":1784430160268,"localReceivedEpochMillis":1784430160257,"topSpreadTicks":-19,"bid5Volume":5126,"ask5Volume":3600,"bid10Volume":8781,"ask10Volume":17104,"rawPayload":"{\"stream\":\"ethusdt@depth@100ms\",\"data\":{\"e\":\"depthUpdate\",\"E\":1784430160268,\"s\":\"ETHUSDT\",\"U\":2806178109,\"u\":2806178109,\"b\":[[\"1870.34000000\",\"0.00000000\"]],\"a\":[]}}"}
{"mode":"v10-framework-compare","workers":4,"sequenceNumber":295,"symbol":"ETHUSDT","exchangeEventTimeMillis":1784430160468,"localReceivedEpochMillis":1784430160458,"topSpreadTicks":-19,"bid5Volume":5126,"ask5Volume":3600,"bid10Volume":8709,"ask10Volume":17104,"rawPayload":"{\"stream\":\"ethusdt@depth@100ms\",\"data\":{\"e\":\"depthUpdate\",\"E\":1784430160468,\"s\":\"ETHUSDT\",\"U\":2806178110,\"u\":2806178111,\"b\":[[\"1869.83000000\",\"0.00000000\"],[\"1869.78000000\",\"0.43980000\"]],\"a\":[]}}"}
{"mode":"v10-framework-compare","workers":4,"sequenceNumber":296,"symbol":"XRPUSDT","exchangeEventTimeMillis":1784430160468,"localReceivedEpochMillis":1784430160458,"topSpreadTicks":0,"bid5Volume":5612800,"ask5Volume":13167000,"bid10Volume":15892000,"ask10Volume":14364900,"rawPayload":"{\"stream\":\"xrpusdt@depth@100ms\",\"data\":{\"e\":\"depthUpdate\",\"E\":1784430160468,\"s\":\"XRPUSDT\",\"U\":752705456,\"u\":752705457,\"b\":[[\"1.09580000\",\"1147.90000000\"],[\"1.09570000\",\"462.80000000\"]],\"a\":[]}}"}
{"mode":"v10-framework-compare","workers":4,"sequenceNumber":297,"symbol":"XRPUSDT","exchangeEventTimeMillis":1784430160668,"localReceivedEpochMillis":1784430160657,"topSpreadTicks":0,"bid5Volume":5350500,"ask5Volume":1829200,"bid10Volume":15629700,"ask10Volume":3027100,"rawPayload":"{\"stream\":\"xrpusdt@depth@100ms\",\"data\":{\"e\":\"depthUpdate\",\"E\":1784430160668,\"s\":\"XRPUSDT\",\"U\":752705458,\"u\":752705461,\"b\":[[\"1.09600000\",\"1012.10000000\"],[\"1.09580000\",\"200.50000000\"]],\"a\":[[\"1.09650000\",\"0.00000000\"],[\"1.09660000\",\"1513.90000000\"]]}}"}
{"mode":"v10-framework-compare","workers":4,"sequenceNumber":298,"symbol":"ETHUSDT","exchangeEventTimeMillis":1784430160969,"localReceivedEpochMillis":1784430160958,"topSpreadTicks":-20,"bid5Volume":5126,"ask5Volume":3600,"bid10Volume":8709,"ask10Volume":17104,"rawPayload":"{\"stream\":\"ethusdt@depth@100ms\",\"data\":{\"e\":\"depthUpdate\",\"E\":1784430160969,\"s\":\"ETHUSDT\",\"U\":2806178112,\"u\":2806178112,\"b\":[],\"a\":[[\"1870.64000000\",\"0.13890000\"],[\"1870.68000000\",\"0.00000000\"]]}}"}
{"mode":"v10-framework-compare","workers":4,"sequenceNumber":299,"symbol":"SOLUSDT","exchangeEventTimeMillis":1784430161069,"localReceivedEpochMillis":1784430161058,"topSpreadTicks":-3,"bid5Volume":217085,"ask5Volume":175346,"bid10Volume":452032,"ask10Volume":1053246,"rawPayload":"{\"stream\":\"solusdt@depth@100ms\",\"data\":{\"e\":\"depthUpdate\",\"E\":1784430161069,\"s\":\"SOLUSDT\",\"U\":1609580021,\"u\":1609580024,\"b\":[[\"76.18000000\",\"33.39200000\"],[\"76.17000000\",\"104.78000000\"]],\"a\":[[\"76.22000000\",\"64.36600000\"],[\"76.23000000\",\"38.76500000\"]]}}"}
{"mode":"v10-framework-compare","workers":4,"sequenceNumber":300,"symbol":"BNBUSDT","exchangeEventTimeMillis":1784430161169,"localReceivedEpochMillis":1784430161158,"topSpreadTicks":4,"bid5Volume":5152,"ask5Volume":6692,"bid10Volume":19992,"ask10Volume":257250,"rawPayload":"{\"stream\":\"bnbusdt@depth@100ms\",\"data\":{\"e\":\"depthUpdate\",\"E\":1784430161169,\"s\":\"BNBUSDT\",\"U\":1236331359,\"u\":1236331360,\"b\":[],\"a\":[[\"570.61000000\",\"0.87600000\"],[\"570.63000000\",\"0.00000000\"]]}}"}
{"mode":"v10-framework-compare","workers":4,"sequenceNumber":301,"symbol":"SOLUSDT","exchangeEventTimeMillis":1784430161169,"localReceivedEpochMillis":1784430161158,"topSpreadTicks":-3,"bid5Volume":217085,"ask5Volume":175346,"bid10Volume":452032,"ask10Volume":1053246,"rawPayload":"{\"stream\":\"solusdt@depth@100ms\",\"data\":{\"e\":\"depthUpdate\",\"E\":1784430161169,\"s\":\"SOLUSDT\",\"U\":1609580025,\"u\":1609580026,\"b\":[[\"76.18000000\",\"39.04900000\"],[\"76.17000000\",\"99.12300000\"]],\"a\":[]}}"}
{"mode":"v10-framework-compare","workers":4,"sequenceNumber":302,"symbol":"BTCUSDT","exchangeEventTimeMillis":1784430161269,"localReceivedEpochMillis":1784430161258,"topSpreadTicks":-318,"bid5Volume":198,"ask5Volume":148,"bid10Volume":477,"ask10Volume":354,"rawPayload":"{\"stream\":\"btcusdt@depth@100ms\",\"data\":{\"e\":\"depthUpdate\",\"E\":1784430161269,\"s\":\"BTCUSDT\",\"U\":3244441360,\"u\":3244441361,\"b\":[],\"a\":[[\"64914.49000000\",\"0.00000000\"],[\"81055.16000000\",\"0.00045000\"]]}}"}
{"mode":"v10-framework-compare","workers":4,"sequenceNumber":303,"symbol":"XRPUSDT","exchangeEventTimeMillis":1784430161269,"localReceivedEpochMillis":1784430161258,"topSpreadTicks":0,"bid5Volume":5490200,"ask5Volume":1829200,"bid10Volume":15769400,"ask10Volume":3027100,"rawPayload":"{\"stream\":\"xrpusdt@depth@100ms\",\"data\":{\"e\":\"depthUpdate\",\"E\":1784430161269,\"s\":\"XRPUSDT\",\"U\":752705462,\"u\":752705463,\"b\":[[\"1.09580000\",\"322.40000000\"],[\"1.09570000\",\"340.20000000\"]],\"a\":[]}}"}
{"mode":"v10-framework-compare","workers":4,"sequenceNumber":304,"symbol":"BTCUSDT","exchangeEventTimeMillis":1784430161369,"localReceivedEpochMillis":1784430161359,"topSpreadTicks":-318,"bid5Volume":188,"ask5Volume":148,"bid10Volume":477,"ask10Volume":354,"rawPayload":"{\"stream\":\"btcusdt@depth@100ms\",\"data\":{\"e\":\"depthUpdate\",\"E\":1784430161369,\"s\":\"BTCUSDT\",\"U\":3244441362,\"u\":3244441364,\"b\":[[\"64783.89000000\",\"0.02800000\"],[\"64782.96000000\",\"0.00000000\"]],\"a\":[[\"64801.09000000\",\"0.03020000\"],[\"64801.33000000\",\"0.00000000\"],[\"64914.49000000\",\"0.00011000\"]]}}"}
{"mode":"v10-framework-compare","workers":4,"sequenceNumber":305,"symbol":"SOLUSDT","exchangeEventTimeMillis":1784430161769,"localReceivedEpochMillis":1784430161759,"topSpreadTicks":-2,"bid5Volume":217521,"ask5Volume":256897,"bid10Volume":452468,"ask10Volume":1326563,"rawPayload":"{\"stream\":\"solusdt@depth@100ms\",\"data\":{\"e\":\"depthUpdate\",\"E\":1784430161769,\"s\":\"SOLUSDT\",\"U\":1609580027,\"u\":1609580033,\"b\":[[\"76.19000000\",\"38.23700000\"],[\"76.18000000\",\"33.39200000\"],[\"76.08000000\",\"9.50800000\"]],\"a\":[[\"76.20000000\",\"0.00000000\"],[\"76.21000000\",\"39.47900000\"],[\"76.22000000\",\"53.05200000\"],[\"76.23000000\",\"50.95100000\"]]}}"}
{"mode":"v10-framework-compare","workers":4,"sequenceNumber":306,"symbol":"BTCUSDT","exchangeEventTimeMillis":1784430161769,"localReceivedEpochMillis":1784430161759,"topSpreadTicks":-318,"bid5Volume":181,"ask5Volume":148,"bid10Volume":470,"ask10Volume":354,"rawPayload":"{\"stream\":\"btcusdt@depth@100ms\",\"data\":{\"e\":\"depthUpdate\",\"E\":1784430161769,\"s\":\"BTCUSDT\",\"U\":3244441365,\"u\":3244441368,\"b\":[[\"64788.32000000\",\"0.00000000\"],[\"64786.68000000\",\"0.02305000\"],[\"64767.55000000\",\"0.00000000\"],[\"64754.59000000\",\"0.04610000\"]],\"a\":[]}}"}
{"mode":"v10-framework-compare","workers":4,"sequenceNumber":307,"symbol":"SOLUSDT","exchangeEventTimeMillis":1784430161869,"localReceivedEpochMillis":1784430161859,"topSpreadTicks":-2,"bid5Volume":217521,"ask5Volume":256897,"bid10Volume":458553,"ask10Volume":1326563,"rawPayload":"{\"stream\":\"solusdt@depth@100ms\",\"data\":{\"e\":\"depthUpdate\",\"E\":1784430161869,\"s\":\"SOLUSDT\",\"U\":1609580034,\"u\":1609580034,\"b\":[[\"76.09000000\",\"9.53800000\"]],\"a\":[]}}"}
{"mode":"v10-framework-compare","workers":4,"sequenceNumber":308,"symbol":"XRPUSDT","exchangeEventTimeMillis":1784430161869,"localReceivedEpochMillis":1784430161859,"topSpreadTicks":2,"bid5Volume":5426900,"ask5Volume":403700,"bid10Volume":15706100,"ask10Volume":1513200,"rawPayload":"{\"stream\":\"xrpusdt@depth@100ms\",\"data\":{\"e\":\"depthUpdate\",\"E\":1784430161869,\"s\":\"XRPUSDT\",\"U\":752705464,\"u\":752705465,\"b\":[[\"1.09580000\",\"276.90000000\"]],\"a\":[[\"1.09610000\",\"0.00000000\"]]}}"}
{"mode":"v10-framework-compare","workers":4,"sequenceNumber":309,"symbol":"SOLUSDT","exchangeEventTimeMillis":1784430161969,"localReceivedEpochMillis":1784430161959,"topSpreadTicks":-2,"bid5Volume":217657,"ask5Volume":256897,"bid10Volume":458689,"ask10Volume":1326563,"rawPayload":"{\"stream\":\"solusdt@depth@100ms\",\"data\":{\"e\":\"depthUpdate\",\"E\":1784430161969,\"s\":\"SOLUSDT\",\"U\":1609580035,\"u\":1609580036,\"b\":[[\"76.19000000\",\"32.14400000\"],[\"76.18000000\",\"39.62100000\"]],\"a\":[]}}"}
{"mode":"v10-framework-compare","workers":4,"sequenceNumber":310,"symbol":"ETHUSDT","exchangeEventTimeMillis":1784430161969,"localReceivedEpochMillis":1784430161959,"topSpreadTicks":-20,"bid5Volume":5126,"ask5Volume":3600,"bid10Volume":8743,"ask10Volume":17104,"rawPayload":"{\"stream\":\"ethusdt@depth@100ms\",\"data\":{\"e\":\"depthUpdate\",\"E\":1784430161969,\"s\":\"ETHUSDT\",\"U\":2806178113,\"u\":2806178114,\"b\":[[\"1869.83000000\",\"0.47310000\"],[\"1869.78000000\",\"0.00000000\"]],\"a\":[]}}"}
{"mode":"v10-framework-compare","workers":4,"sequenceNumber":311,"symbol":"BNBUSDT","exchangeEventTimeMillis":1784430162169,"localReceivedEpochMillis":1784430162159,"topSpreadTicks":4,"bid5Volume":5152,"ask5Volume":6692,"bid10Volume":19992,"ask10Volume":257250,"rawPayload":"{\"stream\":\"bnbusdt@depth@100ms\",\"data\":{\"e\":\"depthUpdate\",\"E\":1784430162169,\"s\":\"BNBUSDT\",\"U\":1236331361,\"u\":1236331362,\"b\":[],\"a\":[[\"570.61000000\",\"0.00000000\"],[\"570.64000000\",\"0.87600000\"]]}}"}
{"mode":"v10-framework-compare","workers":4,"sequenceNumber":312,"symbol":"BTCUSDT","exchangeEventTimeMillis":1784430162470,"localReceivedEpochMillis":1784430162459,"topSpreadTicks":-318,"bid5Volume":181,"ask5Volume":148,"bid10Volume":470,"ask10Volume":354,"rawPayload":"{\"stream\":\"btcusdt@depth@100ms\",\"data\":{\"e\":\"depthUpdate\",\"E\":1784430162470,\"s\":\"BTCUSDT\",\"U\":3244441369,\"u\":3244441377,\"b\":[[\"64736.04000000\",\"0.05967000\"],[\"64735.34000000\",\"0.00000000\"],[\"64697.15000000\",\"0.08541000\"],[\"64696.45000000\",\"0.00000000\"],[\"64658.26000000\",\"0.18203000\"],[\"64657.56000000\",\"0.00000000\"],[\"64580.49000000\",\"0.40748000\"],[\"64579.79000000\",\"0.00000000\"]],\"a\":[[\"64890.84000000\",\"0.00000000\"],[\"64891.54000000\",\"0.06099000\"],[\"64929.72000000\",\"0.00000000\"],[\"64930.43000000\",\"0.08452000\"],[\"64968.61000000\",\"0.00000000\"],[\"64969.32000000\",\"0.18519000\"],[\"65046.39000000\",\"0.00000000\"],[\"65047.09000000\",\"0.40282000\"],[\"81055.16000000\",\"0.00045000\"]]}}"}
{"mode":"v10-framework-compare","workers":4,"sequenceNumber":313,"symbol":"ETHUSDT","exchangeEventTimeMillis":1784430162770,"localReceivedEpochMillis":1784430162759,"topSpreadTicks":-20,"bid5Volume":5126,"ask5Volume":3600,"bid10Volume":8743,"ask10Volume":17104,"rawPayload":"{\"stream\":\"ethusdt@depth@100ms\",\"data\":{\"e\":\"depthUpdate\",\"E\":1784430162770,\"s\":\"ETHUSDT\",\"U\":2806178115,\"u\":2806178115,\"b\":[],\"a\":[[\"1871.14000000\",\"1.06180000\"],[\"1871.16000000\",\"0.00000000\"]]}}"}
{"mode":"v10-framework-compare","workers":4,"sequenceNumber":314,"symbol":"XRPUSDT","exchangeEventTimeMillis":1784430162870,"localReceivedEpochMillis":1784430162859,"topSpreadTicks":0,"bid5Volume":8826000,"ask5Volume":360600,"bid10Volume":19105200,"ask10Volume":1558500,"rawPayload":"{\"stream\":\"xrpusdt@depth@100ms\",\"data\":{\"e\":\"depthUpdate\",\"E\":1784430162870,\"s\":\"XRPUSDT\",\"U\":752705466,\"u\":752705467,\"b\":[[\"1.09590000\",\"3676.00000000\"]],\"a\":[[\"1.09620000\",\"45.30000000\"]]}}"}
{"mode":"v10-framework-compare","workers":4,"sequenceNumber":315,"symbol":"XRPUSDT","exchangeEventTimeMillis":1784430163170,"localReceivedEpochMillis":1784430163160,"topSpreadTicks":0,"bid5Volume":8826000,"ask5Volume":462300,"bid10Volume":19105200,"ask10Volume":1660200,"rawPayload":"{\"stream\":\"xrpusdt@depth@100ms\",\"data\":{\"e\":\"depthUpdate\",\"E\":1784430163170,\"s\":\"XRPUSDT\",\"U\":752705468,\"u\":752705469,\"b\":[],\"a\":[[\"1.09640000\",\"387.10000000\"],[\"1.09650000\",\"147.00000000\"]]}}"}
{"mode":"v10-framework-compare","workers":4,"sequenceNumber":316,"symbol":"XRPUSDT","exchangeEventTimeMillis":1784430163270,"localReceivedEpochMillis":1784430163259,"topSpreadTicks":2,"bid5Volume":8826000,"ask5Volume":403700,"bid10Volume":19105200,"ask10Volume":1513200,"rawPayload":"{\"stream\":\"xrpusdt@depth@100ms\",\"data\":{\"e\":\"depthUpdate\",\"E\":1784430163270,\"s\":\"XRPUSDT\",\"U\":752705470,\"u\":752705471,\"b\":[],\"a\":[[\"1.09640000\",\"535.70000000\"],[\"1.09650000\",\"0.00000000\"]]}}"}
{"mode":"v10-framework-compare","workers":4,"sequenceNumber":317,"symbol":"SOLUSDT","exchangeEventTimeMillis":1784430163370,"localReceivedEpochMillis":1784430163358,"topSpreadTicks":-3,"bid5Volume":217657,"ask5Volume":177432,"bid10Volume":458689,"ask10Volume":1055332,"rawPayload":"{\"stream\":\"solusdt@depth@100ms\",\"data\":{\"e\":\"depthUpdate\",\"E\":1784430163370,\"s\":\"SOLUSDT\",\"U\":1609580037,\"u\":1609580038,\"b\":[],\"a\":[[\"76.20000000\",\"6.56500000\"],[\"76.21000000\",\"33.38600000\"]]}}"}
{"mode":"v10-framework-compare","workers":4,"sequenceNumber":318,"symbol":"BTCUSDT","exchangeEventTimeMillis":1784430163370,"localReceivedEpochMillis":1784430163359,"topSpreadTicks":-318,"bid5Volume":181,"ask5Volume":148,"bid10Volume":470,"ask10Volume":354,"rawPayload":"{\"stream\":\"btcusdt@depth@100ms\",\"data\":{\"e\":\"depthUpdate\",\"E\":1784430163370,\"s\":\"BTCUSDT\",\"U\":3244441378,\"u\":3244441382,\"b\":[[\"64769.17000000\",\"0.00000000\"],[\"64766.41000000\",\"0.04261000\"]],\"a\":[[\"64810.04000000\",\"0.00168000\"],[\"64811.32000000\",\"0.00000000\"],[\"64811.46000000\",\"0.00000000\"]]}}"}
{"mode":"v10-framework-compare","workers":4,"sequenceNumber":319,"symbol":"BTCUSDT","exchangeEventTimeMillis":1784430163470,"localReceivedEpochMillis":1784430163460,"topSpreadTicks":-369,"bid5Volume":181,"ask5Volume":148,"bid10Volume":346,"ask10Volume":587,"rawPayload":"{\"stream\":\"btcusdt@depth@100ms\",\"data\":{\"e\":\"depthUpdate\",\"E\":1784430163470,\"s\":\"BTCUSDT\",\"U\":3244441383,\"u\":3244441388,\"b\":[[\"64776.60000000\",\"0.00000000\"],[\"64768.01000000\",\"0.03037000\"]],\"a\":[[\"64799.26000000\",\"0.00401000\"],[\"64799.78000000\",\"0.00000000\"],[\"64820.01000000\",\"0.30497000\"],[\"64838.14000000\",\"0.00000000\"],[\"64845.91000000\",\"0.26523000\"],[\"64851.47000000\",\"0.00000000\"]]}}"}
{"mode":"v10-framework-compare","workers":4,"sequenceNumber":320,"symbol":"ETHUSDT","exchangeEventTimeMillis":1784430163470,"localReceivedEpochMillis":1784430163460,"topSpreadTicks":-19,"bid5Volume":5126,"ask5Volume":4761,"bid10Volume":8743,"ask10Volume":18441,"rawPayload":"{\"stream\":\"ethusdt@depth@100ms\",\"data\":{\"e\":\"depthUpdate\",\"E\":1784430163470,\"s\":\"ETHUSDT\",\"U\":2806178116,\"u\":2806178116,\"b\":[],\"a\":[[\"1870.64000000\",\"0.00000000\"],[\"1870.67000000\",\"0.59680000\"]]}}"}
{"mode":"v10-framework-compare","workers":4,"sequenceNumber":321,"symbol":"BTCUSDT","exchangeEventTimeMillis":1784430163770,"localReceivedEpochMillis":1784430163759,"topSpreadTicks":-369,"bid5Volume":181,"ask5Volume":148,"bid10Volume":346,"ask10Volume":587,"rawPayload":"{\"stream\":\"btcusdt@depth@100ms\",\"data\":{\"e\":\"depthUpdate\",\"E\":1784430163770,\"s\":\"BTCUSDT\",\"U\":3244441389,\"u\":3244441389,\"b\":[],\"a\":[[\"81055.16000000\",\"0.00030000\"]]}}"}
{"mode":"v10-framework-compare","workers":4,"sequenceNumber":322,"symbol":"XRPUSDT","exchangeEventTimeMillis":1784430163770,"localReceivedEpochMillis":1784430163760,"topSpreadTicks":2,"bid5Volume":8826000,"ask5Volume":403700,"bid10Volume":19105200,"ask10Volume":1513200,"rawPayload":"{\"stream\":\"xrpusdt@depth@100ms\",\"data\":{\"e\":\"depthUpdate\",\"E\":1784430163770,\"s\":\"XRPUSDT\",\"U\":752705472,\"u\":752705473,\"b\":[],\"a\":[[\"1.09680000\",\"4591.20000000\"],[\"1.09730000\",\"0.00000000\"]]}}"}
{"mode":"v10-framework-compare","workers":4,"sequenceNumber":323,"symbol":"ETHUSDT","exchangeEventTimeMillis":1784430163870,"localReceivedEpochMillis":1784430163860,"topSpreadTicks":-19,"bid5Volume":5126,"ask5Volume":4761,"bid10Volume":8743,"ask10Volume":18441,"rawPayload":"{\"stream\":\"ethusdt@depth@100ms\",\"data\":{\"e\":\"depthUpdate\",\"E\":1784430163870,\"s\":\"ETHUSDT\",\"U\":2806178117,\"u\":2806178122,\"b\":[[\"1868.45000000\",\"2.00910000\"],[\"1868.43000000\",\"0.00000000\"],[\"1867.33000000\",\"3.06430000\"],[\"1867.31000000\",\"0.00000000\"],[\"1866.21000000\",\"6.29250000\"],[\"1866.19000000\",\"0.00000000\"],[\"1863.96000000\",\"13.86920000\"],[\"1863.94000000\",\"0.00000000\"]],\"a\":[[\"1872.93000000\",\"0.00000000\"],[\"1872.95000000\",\"1.97600000\"],[\"1875.17000000\",\"0.00000000\"],[\"1875.20000000\",\"6.19570000\"]]}}"}
{"mode":"v10-framework-compare","workers":4,"sequenceNumber":324,"symbol":"SOLUSDT","exchangeEventTimeMillis":1784430164071,"localReceivedEpochMillis":1784430164060,"topSpreadTicks":-3,"bid5Volume":217654,"ask5Volume":177432,"bid10Volume":458686,"ask10Volume":724247,"rawPayload":"{\"stream\":\"solusdt@depth@100ms\",\"data\":{\"e\":\"depthUpdate\",\"E\":1784430164071,\"s\":\"SOLUSDT\",\"U\":1609580039,\"u\":1609580041,\"b\":[[\"76.18000000\",\"43.03100000\"],[\"76.17000000\",\"95.71000000\"]],\"a\":[[\"76.22000000\",\"49.64100000\"],[\"76.23000000\",\"54.36200000\"],[\"76.25000000\",\"43.73900000\"],[\"76.26000000\",\"36.19600000\"]]}}"}
{"mode":"v10-framework-compare","workers":4,"sequenceNumber":325,"symbol":"ETHUSDT","exchangeEventTimeMillis":1784430164171,"localReceivedEpochMillis":1784430164161,"topSpreadTicks":-19,"bid5Volume":5126,"ask5Volume":4761,"bid10Volume":8822,"ask10Volume":18441,"rawPayload":"{\"stream\":\"ethusdt@depth@100ms\",\"data\":{\"e\":\"depthUpdate\",\"E\":1784430164171,\"s\":\"ETHUSDT\",\"U\":2806178123,\"u\":2806178124,\"b\":[[\"1869.89000000\",\"0.55210000\"],[\"1869.83000000\",\"0.00000000\"]],\"a\":[]}}"}
{"mode":"v10-framework-compare","workers":4,"sequenceNumber":326,"symbol":"BTCUSDT","exchangeEventTimeMillis":1784430164471,"localReceivedEpochMillis":1784430164461,"topSpreadTicks":-369,"bid5Volume":150,"ask5Volume":148,"bid10Volume":315,"ask10Volume":587,"rawPayload":"{\"stream\":\"btcusdt@depth@100ms\",\"data\":{\"e\":\"depthUpdate\",\"E\":1784430164471,\"s\":\"BTCUSDT\",\"U\":3244441390,\"u\":3244441390,\"b\":[[\"64790.29000000\",\"0.04000000\"]],\"a\":[]}}"}
{"mode":"v10-framework-compare","workers":4,"sequenceNumber":327,"symbol":"XRPUSDT","exchangeEventTimeMillis":1784430164471,"localReceivedEpochMillis":1784430164461,"topSpreadTicks":0,"bid5Volume":8826000,"ask5Volume":2390000,"bid10Volume":19105200,"ask10Volume":3587900,"rawPayload":"{\"stream\":\"xrpusdt@depth@100ms\",\"data\":{\"e\":\"depthUpdate\",\"E\":1784430164471,\"s\":\"XRPUSDT\",\"U\":752705474,\"u\":752705474,\"b\":[],\"a\":[[\"1.09710000\",\"2074.70000000\"]]}}"}
{"mode":"v10-framework-compare","workers":4,"sequenceNumber":328,"symbol":"XRPUSDT","exchangeEventTimeMillis":1784430164571,"localReceivedEpochMillis":1784430164561,"topSpreadTicks":0,"bid5Volume":8826000,"ask5Volume":5044800,"bid10Volume":19105200,"ask10Volume":6242700,"rawPayload":"{\"stream\":\"xrpusdt@depth@100ms\",\"data\":{\"e\":\"depthUpdate\",\"E\":1784430164571,\"s\":\"XRPUSDT\",\"U\":752705475,\"u\":752705475,\"b\":[],\"a\":[[\"1.09680000\",\"4729.50000000\"]]}}"}
{"mode":"v10-framework-compare","workers":4,"sequenceNumber":329,"symbol":"ETHUSDT","exchangeEventTimeMillis":1784430164971,"localReceivedEpochMillis":1784430164960,"topSpreadTicks":-19,"bid5Volume":5058,"ask5Volume":4742,"bid10Volume":8754,"ask10Volume":18422,"rawPayload":"{\"stream\":\"ethusdt@depth@100ms\",\"data\":{\"e\":\"depthUpdate\",\"E\":1784430164971,\"s\":\"ETHUSDT\",\"U\":2806178125,\"u\":2806178128,\"b\":[[\"1870.39000000\",\"1.12320000\"],[\"1870.33000000\",\"0.00000000\"]],\"a\":[[\"1870.90000000\",\"0.00000000\"],[\"1870.96000000\",\"1.14100000\"]]}}"}
{"mode":"v10-framework-compare","workers":4,"sequenceNumber":330,"symbol":"BTCUSDT","exchangeEventTimeMillis":1784430165071,"localReceivedEpochMillis":1784430165062,"topSpreadTicks":-369,"bid5Volume":150,"ask5Volume":148,"bid10Volume":315,"ask10Volume":587,"rawPayload":"{\"stream\":\"btcusdt@depth@100ms\",\"data\":{\"e\":\"depthUpdate\",\"E\":1784430165071,\"s\":\"BTCUSDT\",\"U\":3244441391,\"u\":3244441391,\"b\":[],\"a\":[[\"64914.49000000\",\"0.00000000\"]]}}"}
{"mode":"v10-framework-compare","workers":4,"sequenceNumber":331,"symbol":"BNBUSDT","exchangeEventTimeMillis":1784430165171,"localReceivedEpochMillis":1784430165160,"topSpreadTicks":4,"bid5Volume":5152,"ask5Volume":6692,"bid10Volume":19992,"ask10Volume":257250,"rawPayload":"{\"stream\":\"bnbusdt@depth@100ms\",\"data\":{\"e\":\"depthUpdate\",\"E\":1784430165171,\"s\":\"BNBUSDT\",\"U\":1236331363,\"u\":1236331364,\"b\":[],\"a\":[[\"570.61000000\",\"0.87600000\"],[\"570.64000000\",\"0.00000000\"]]}}"}
{"mode":"v10-framework-compare","workers":4,"sequenceNumber":332,"symbol":"BTCUSDT","exchangeEventTimeMillis":1784430165171,"localReceivedEpochMillis":1784430165160,"topSpreadTicks":-369,"bid5Volume":150,"ask5Volume":148,"bid10Volume":315,"ask10Volume":587,"rawPayload":"{\"stream\":\"btcusdt@depth@100ms\",\"data\":{\"e\":\"depthUpdate\",\"E\":1784430165171,\"s\":\"BTCUSDT\",\"U\":3244441392,\"u\":3244441392,\"b\":[],\"a\":[[\"64914.49000000\",\"0.00011000\"]]}}"}
{"mode":"v10-framework-compare","workers":4,"sequenceNumber":333,"symbol":"SOLUSDT","exchangeEventTimeMillis":1784430165271,"localReceivedEpochMillis":1784430165261,"topSpreadTicks":-3,"bid5Volume":253893,"ask5Volume":177432,"bid10Volume":468185,"ask10Volume":724247,"rawPayload":"{\"stream\":\"solusdt@depth@100ms\",\"data\":{\"e\":\"depthUpdate\",\"E\":1784430165271,\"s\":\"SOLUSDT\",\"U\":1609580042,\"u\":1609580043,\"b\":[[\"76.16000000\",\"68.40400000\"],[\"76.15000000\",\"11.46600000\"],[\"76.11000000\",\"118.05500000\"],[\"76.10000000\",\"0.00000000\"]],\"a\":[]}}"}
{"mode":"v10-framework-compare","workers":4,"sequenceNumber":334,"symbol":"ETHUSDT","exchangeEventTimeMillis":1784430165972,"localReceivedEpochMillis":1784430165962,"topSpreadTicks":-19,"bid5Volume":5055,"ask5Volume":5076,"bid10Volume":8751,"ask10Volume":18477,"rawPayload":"{\"stream\":\"ethusdt@depth@100ms\",\"data\":{\"e\":\"depthUpdate\",\"E\":1784430165972,\"s\":\"ETHUSDT\",\"U\":2806178129,\"u\":2806178133,\"b\":[[\"1870.47000000\",\"1.12030000\"],[\"1870.39000000\",\"0.00000000\"]],\"a\":[[\"1870.96000000\",\"0.00000000\"],[\"1871.04000000\",\"1.19670000\"],[\"1871.13000000\",\"1.06180000\"],[\"1871.14000000\",\"0.00000000\"]]}}"}
{"mode":"v10-framework-compare","workers":4,"sequenceNumber":335,"symbol":"ETHUSDT","exchangeEventTimeMillis":1784430166072,"localReceivedEpochMillis":1784430166062,"topSpreadTicks":-19,"bid5Volume":5044,"ask5Volume":3600,"bid10Volume":8740,"ask10Volume":17036,"rawPayload":"{\"stream\":\"ethusdt@depth@100ms\",\"data\":{\"e\":\"depthUpdate\",\"E\":1784430166072,\"s\":\"ETHUSDT\",\"U\":2806178134,\"u\":2806178140,\"b\":[[\"1870.47000000\",\"0.00000000\"],[\"1870.41000000\",\"1.10910000\"],[\"1870.08000000\",\"0.13900000\"],[\"1870.02000000\",\"0.00000000\"]],\"a\":[[\"1870.67000000\",\"0.45790000\"],[\"1870.74000000\",\"0.13890000\"],[\"1870.98000000\",\"1.09290000\"],[\"1871.04000000\",\"1.47510000\"]]}}"}
{"mode":"v10-framework-compare","workers":4,"sequenceNumber":336,"symbol":"SOLUSDT","exchangeEventTimeMillis":1784430166172,"localReceivedEpochMillis":1784430166162,"topSpreadTicks":-3,"bid5Volume":253889,"ask5Volume":177428,"bid10Volume":468181,"ask10Volume":725187,"rawPayload":"{\"stream\":\"solusdt@depth@100ms\",\"data\":{\"e\":\"depthUpdate\",\"E\":1784430166172,\"s\":\"SOLUSDT\",\"U\":1609580044,\"u\":1609580049,\"b\":[[\"76.19000000\",\"64.97900000\"],[\"76.18000000\",\"10.19200000\"]],\"a\":[[\"76.21000000\",\"0.55800000\"],[\"76.22000000\",\"82.46500000\"],[\"76.25000000\",\"30.19500000\"],[\"76.26000000\",\"50.68400000\"]]}}"}
{"mode":"v10-framework-compare","workers":4,"sequenceNumber":337,"symbol":"ETHUSDT","exchangeEventTimeMillis":1784430166172,"localReceivedEpochMillis":1784430166163,"topSpreadTicks":-18,"bid5Volume":6382,"ask5Volume":4860,"bid10Volume":10758,"ask10Volume":18540,"rawPayload":"{\"stream\":\"ethusdt@depth@100ms\",\"data\":{\"e\":\"depthUpdate\",\"E\":1784430166172,\"s\":\"ETHUSDT\",\"U\":2806178141,\"u\":2806178153,\"b\":[[\"1870.30000000\",\"2.09040000\"],[\"1870.11000000\",\"0.00000000\"],[\"1870.01000000\",\"0.00000000\"],[\"1869.94000000\",\"0.00000000\"],[\"1869.89000000\",\"0.00000000\"],[\"1869.68000000\",\"0.93730000\"],[\"1869.47000000\",\"0.00000000\"]],\"a\":[[\"1870.65000000\",\"0.00000000\"],[\"1870.67000000\",\"0.00000000\"],[\"1870.72000000\",\"0.62500000\"],[\"1870.87000000\",\"2.97690000\"]]}}"}
{"mode":"v10-framework-compare","workers":4,"sequenceNumber":338,"symbol":"BTCUSDT","exchangeEventTimeMillis":1784430166172,"localReceivedEpochMillis":1784430166163,"topSpreadTicks":-369,"bid5Volume":145,"ask5Volume":148,"bid10Volume":310,"ask10Volume":587,"rawPayload":"{\"stream\":\"btcusdt@depth@100ms\",\"data\":{\"e\":\"depthUpdate\",\"E\":1784430166172,\"s\":\"BTCUSDT\",\"U\":3244441393,\"u\":3244441395,\"b\":[[\"64788.36000000\",\"0.01811000\"],[\"64786.68000000\",\"0.00000000\"]],\"a\":[[\"81055.16000000\",\"0.00045000\"]]}}"}
{"mode":"v10-framework-compare","workers":4,"sequenceNumber":339,"symbol":"XRPUSDT","exchangeEventTimeMillis":1784430166172,"localReceivedEpochMillis":1784430166163,"topSpreadTicks":0,"bid5Volume":6659100,"ask5Volume":2831100,"bid10Volume":16938300,"ask10Volume":4029000,"rawPayload":"{\"stream\":\"xrpusdt@depth@100ms\",\"data\":{\"e\":\"depthUpdate\",\"E\":1784430166172,\"s\":\"XRPUSDT\",\"U\":752705476,\"u\":752705499,\"b\":[[\"1.09610000\",\"1014.80000000\"],[\"1.09600000\",\"0.00000000\"],[\"1.09590000\",\"224.90000000\"],[\"1.09580000\",\"1740.10000000\"],[\"1.09570000\",\"103.00000000\"],[\"1.09540000\",\"2518.90000000\"],[\"1.09530000\",\"2074.70000000\"],[\"1.09520000\",\"0.00000000\"],[\"1.09510000\",\"4568.90000000\"],[\"1.09470000\",\"1509.10000000\"]],\"a\":[[\"1.09630000\",\"1244.00000000\"],[\"1.09640000\",\"150.00000000\"],[\"1.09650000\",\"237.10000000\"],[\"1.09660000\",\"494.00000000\"],[\"1.09670000\",\"1003.50000000\"],[\"1.09680000\",\"2213.00000000\"],[\"1.09690000\",\"2515.80000000\"]]}}"}
