{"mode":"v9-depth-v5-spsc","workers":4,"sequenceNumber":345,"symbol":"SOLUSDT","exchangeEventTimeMillis":1784429286784,"localReceivedEpochMillis":1784429286775,"topSpreadTicks":1,"bid5Volume":117869,"ask5Volume":195891,"bid10Volume":439823,"ask10Volume":405846,"rawPayload":"{\"stream\":\"solusdt@depth@100ms\",\"data\":{\"e\":\"depthUpdate\",\"E\":1784429286784,\"s\":\"SOLUSDT\",\"U\":1609569845,\"u\":1609569849,\"b\":[],\"a\":[[\"76.26000000\",\"72.56400000\"],[\"76.27000000\",\"14.67300000\"],[\"76.28000000\",\"3.28300000\"],[\"76.32000000\",\"65.56500000\"]]}}"}
{"mode":"v9-depth-v5-spsc","workers":4,"sequenceNumber":346,"symbol":"SOLUSDT","exchangeEventTimeMillis":1784429287384,"localReceivedEpochMillis":1784429287374,"topSpreadTicks":1,"bid5Volume":117869,"ask5Volume":246216,"bid10Volume":439823,"ask10Volume":387469,"rawPayload":"{\"stream\":\"solusdt@depth@100ms\",\"data\":{\"e\":\"depthUpdate\",\"E\":1784429287384,\"s\":\"SOLUSDT\",\"U\":1609569850,\"u\":1609569853,\"b\":[],\"a\":[[\"76.28000000\",\"53.60800000\"],[\"76.31000000\",\"30.19500000\"],[\"76.60000000\",\"55.28300000\"]]}}"}
{"mode":"v9-depth-v5-spsc","workers":4,"sequenceNumber":347,"symbol":"BTCUSDT","exchangeEventTimeMillis":1784429287384,"localReceivedEpochMillis":1784429287376,"topSpreadTicks":268,"bid5Volume":136,"ask5Volume":128,"bid10Volume":290,"ask10Volume":590,"rawPayload":"{\"stream\":\"btcusdt@depth@100ms\",\"data\":{\"e\":\"depthUpdate\",\"E\":1784429287384,\"s\":\"BTCUSDT\",\"U\":3244435327,\"u\":3244435328,\"b\":[],\"a\":[[\"64839.25000000\",\"0.00164000\"],[\"64840.16000000\",\"0.00000000\"]]}}"}
{"mode":"v9-depth-v5-spsc","workers":4,"sequenceNumber":348,"symbol":"BNBUSDT","exchangeEventTimeMillis":1784429287484,"localReceivedEpochMillis":1784429287476,"topSpreadTicks":5,"bid5Volume":4623,"ask5Volume":7622,"bid10Volume":21058,"ask10Volume":263593,"rawPayload":"{\"stream\":\"bnbusdt@depth@100ms\",\"data\":{\"e\":\"depthUpdate\",\"E\":1784429287484,\"s\":\"BNBUSDT\",\"U\":1236328013,\"u\":1236328015,\"b\":[],\"a\":[[\"570.91000000\",\"1.59500000\"],[\"570.93000000\",\"1.61500000\"],[\"570.95000000\",\"0.00000000\"]]}}"}
{"mode":"v9-depth-v5-spsc","workers":4,"sequenceNumber":349,"symbol":"SOLUSDT","exchangeEventTimeMillis":1784429287584,"localReceivedEpochMillis":1784429287575,"topSpreadTicks":1,"bid5Volume":117869,"ask5Volume":246216,"bid10Volume":439823,"ask10Volume":387469,"rawPayload":"{\"stream\":\"solusdt@depth@100ms\",\"data\":{\"e\":\"depthUpdate\",\"E\":1784429287584,\"s\":\"SOLUSDT\",\"U\":1609569854,\"u\":1609569856,\"b\":[],\"a\":[[\"76.26000000\",\"54.58900000\"],[\"76.27000000\",\"32.64800000\"],[\"76.28000000\",\"33.47800000\"],[\"76.29000000\",\"86.50300000\"]]}}"}
{"mode":"v9-depth-v5-spsc","workers":4,"sequenceNumber":350,"symbol":"BTCUSDT","exchangeEventTimeMillis":1784429287684,"localReceivedEpochMillis":1784429287676,"topSpreadTicks":268,"bid5Volume":134,"ask5Volume":128,"bid10Volume":288,"ask10Volume":590,"rawPayload":"{\"stream\":\"btcusdt@depth@100ms\",\"data\":{\"e\":\"depthUpdate\",\"E\":1784429287684,\"s\":\"BTCUSDT\",\"U\":3244435329,\"u\":3244435332,\"b\":[[\"64818.03000000\",\"0.00000000\"],[\"64816.39000000\",\"0.02814000\"]],\"a\":[[\"64838.23000000\",\"0.00166000\"],[\"64839.25000000\",\"0.00000000\"]]}}"}
{"mode":"v9-depth-v5-spsc","workers":4,"sequenceNumber":351,"symbol":"BTCUSDT","exchangeEventTimeMillis":1784429287784,"localReceivedEpochMillis":1784429287775,"topSpreadTicks":268,"bid5Volume":134,"ask5Volume":128,"bid10Volume":288,"ask10Volume":590,"rawPayload":"{\"stream\":\"btcusdt@depth@100ms\",\"data\":{\"e\":\"depthUpdate\",\"E\":1784429287784,\"s\":\"BTCUSDT\",\"U\":3244435333,\"u\":3244435342,\"b\":[],\"a\":[[\"64837.11000000\",\"0.00000000\"],[\"64838.23000000\",\"0.00000000\"],[\"64838.57000000\",\"0.00163000\"],[\"64838.95000000\",\"0.00000000\"],[\"64839.07000000\",\"0.00000000\"],[\"64840.06000000\",\"0.00000000\"]]}}"}
{"mode":"v9-depth-v5-spsc","workers":4,"sequenceNumber":352,"symbol":"BTCUSDT","exchangeEventTimeMillis":1784429287884,"localReceivedEpochMillis":1784429287878,"topSpreadTicks":268,"bid5Volume":134,"ask5Volume":128,"bid10Volume":288,"ask10Volume":590,"rawPayload":"{\"stream\":\"btcusdt@depth@100ms\",\"data\":{\"e\":\"depthUpdate\",\"E\":1784429287884,\"s\":\"BTCUSDT\",\"U\":3244435343,\"u\":3244435344,\"b\":[],\"a\":[[\"64837.29000000\",\"0.00163000\"],[\"64838.57000000\",\"0.00000000\"]]}}"}
{"mode":"v9-depth-v5-spsc","workers":4,"sequenceNumber":353,"symbol":"SOLUSDT","exchangeEventTimeMillis":1784429287985,"localReceivedEpochMillis":1784429287977,"topSpreadTicks":1,"bid5Volume":117869,"ask5Volume":276411,"bid10Volume":439823,"ask10Volume":486366,"rawPayload":"{\"stream\":\"solusdt@depth@100ms\",\"data\":{\"e\":\"depthUpdate\",\"E\":1784429287985,\"s\":\"SOLUSDT\",\"U\":1609569857,\"u\":1609569858,\"b\":[],\"a\":[[\"76.27000000\",\"62.84300000\"],[\"76.31000000\",\"0.00000000\"]]}}"}
{"mode":"v9-depth-v5-spsc","workers":4,"sequenceNumber":354,"symbol":"BTCUSDT","exchangeEventTimeMillis":1784429288085,"localReceivedEpochMillis":1784429288074,"topSpreadTicks":268,"bid5Volume":134,"ask5Volume":128,"bid10Volume":288,"ask10Volume":590,"rawPayload":"{\"stream\":\"btcusdt@depth@100ms\",\"data\":{\"e\":\"depthUpdate\",\"E\":1784429288085,\"s\":\"BTCUSDT\",\"U\":3244435345,\"u\":3244435345,\"b\":[],\"a\":[[\"81072.08000000\",\"0.00030000\"]]}}"}
{"mode":"v9-depth-v5-spsc","workers":4,"sequenceNumber":355,"symbol":"ETHUSDT","exchangeEventTimeMillis":1784429288085,"localReceivedEpochMillis":1784429288075,"topSpreadTicks":18,"bid5Volume":3440,"ask5Volume":8914,"bid10Volume":11400,"ask10Volume":17119,"rawPayload":"{\"stream\":\"ethusdt@depth@100ms\",\"data\":{\"e\":\"depthUpdate\",\"E\":1784429288085,\"s\":\"ETHUSDT\",\"U\":2806164476,\"u\":2806164482,\"b\":[[\"1871.80000000\",\"0.00000000\"],[\"1871.74000000\",\"0.84090000\"],[\"1871.60000000\",\"0.00000000\"],[\"1871.55000000\",\"0.00000000\"],[\"1871.42000000\",\"0.00000000\"],[\"1871.28000000\",\"1.63970000\"],[\"1870.96000000\",\"1.63970000\"]],\"a\":[]}}"}
{"mode":"v9-depth-v5-spsc","workers":4,"sequenceNumber":356,"symbol":"BTCUSDT","exchangeEventTimeMillis":1784429288185,"localReceivedEpochMillis":1784429288175,"topSpreadTicks":268,"bid5Volume":134,"ask5Volume":128,"bid10Volume":288,"ask10Volume":590,"rawPayload":"{\"stream\":\"btcusdt@depth@100ms\",\"data\":{\"e\":\"depthUpdate\",\"E\":1784429288185,\"s\":\"BTCUSDT\",\"U\":3244435346,\"u\":3244435349,\"b\":[],\"a\":[[\"64837.29000000\",\"0.00000000\"],[\"64837.38000000\",\"0.00171000\"],[\"64839.82000000\",\"0.00000000\"]]}}"}
{"mode":"v9-depth-v5-spsc","workers":4,"sequenceNumber":357,"symbol":"SOLUSDT","exchangeEventTimeMillis":1784429288385,"localReceivedEpochMillis":1784429288375,"topSpreadTicks":1,"bid5Volume":117869,"ask5Volume":276411,"bid10Volume":439823,"ask10Volume":486366,"rawPayload":"{\"stream\":\"solusdt@depth@100ms\",\"data\":{\"e\":\"depthUpdate\",\"E\":1784429288385,\"s\":\"SOLUSDT\",\"U\":1609569859,\"u\":1609569860,\"b\":[],\"a\":[[\"76.27000000\",\"82.97300000\"],[\"76.29000000\",\"66.37300000\"]]}}"}
{"mode":"v9-depth-v5-spsc","workers":4,"sequenceNumber":358,"symbol":"ETHUSDT","exchangeEventTimeMillis":1784429288485,"localReceivedEpochMillis":1784429288476,"topSpreadTicks":18,"bid5Volume":3440,"ask5Volume":8914,"bid10Volume":11400,"ask10Volume":17119,"rawPayload":"{\"stream\":\"ethusdt@depth@100ms\",\"data\":{\"e\":\"depthUpdate\",\"E\":1784429288485,\"s\":\"ETHUSDT\",\"U\":2806164483,\"u\":2806164484,\"b\":[[\"1871.57000000\",\"0.00000000\"]],\"a\":[]}}"}
{"mode":"v9-depth-v5-spsc","workers":4,"sequenceNumber":359,"symbol":"ETHUSDT","exchangeEventTimeMillis":1784429288585,"localReceivedEpochMillis":1784429288576,"topSpreadTicks":18,"bid5Volume":3440,"ask5Volume":8914,"bid10Volume":11400,"ask10Volume":17119,"rawPayload":"{\"stream\":\"ethusdt@depth@100ms\",\"data\":{\"e\":\"depthUpdate\",\"E\":1784429288585,\"s\":\"ETHUSDT\",\"U\":2806164485,\"u\":2806164485,\"b\":[[\"1870.63000000\",\"1.63970000\"]],\"a\":[]}}"}
{"mode":"v9-depth-v5-spsc","workers":4,"sequenceNumber":360,"symbol":"BNBUSDT","exchangeEventTimeMillis":1784429288785,"localReceivedEpochMillis":1784429288776,"topSpreadTicks":5,"bid5Volume":4623,"ask5Volume":7622,"bid10Volume":21058,"ask10Volume":263593,"rawPayload":"{\"stream\":\"bnbusdt@depth@100ms\",\"data\":{\"e\":\"depthUpdate\",\"E\":1784429288785,\"s\":\"BNBUSDT\",\"U\":1236328016,\"u\":1236328023,\"b\":[[\"570.17000000\",\"0.00000000\"],[\"570.13000000\",\"3.39500000\"],[\"569.82000000\",\"0.00000000\"],[\"569.79000000\",\"5.04900000\"],[\"569.48000000\",\"0.00000000\"],[\"569.44000000\",\"8.67400000\"],[\"569.14000000\",\"0.00000000\"],[\"569.10000000\",\"19.72800000\"]],\"a\":[[\"571.51000000\",\"3.30600000\"],[\"571.55000000\",\"0.00000000\"],[\"571.85000000\",\"5.04600000\"],[\"571.89000000\",\"0.00000000\"],[\"572.19000000\",\"8.42800000\"],[\"572.23000000\",\"0.00000000\"],[\"572.54000000\",\"20.45700000\"],[\"572.57000000\",\"0.00000000\"]]}}"}
{"mode":"v9-depth-v5-spsc","workers":4,"sequenceNumber":361,"symbol":"BTCUSDT","exchangeEventTimeMillis":1784429288785,"localReceivedEpochMillis":1784429288776,"topSpreadTicks":268,"bid5Volume":134,"ask5Volume":128,"bid10Volume":288,"ask10Volume":590,"rawPayload":"{\"stream\":\"btcusdt@depth@100ms\",\"data\":{\"e\":\"depthUpdate\",\"E\":1784429288785,\"s\":\"BTCUSDT\",\"U\":3244435350,\"u\":3244435350,\"b\":[],\"a\":[[\"81072.08000000\",\"0.00045000\"]]}}"}
{"mode":"v9-depth-v5-spsc","workers":4,"sequenceNumber":362,"symbol":"BTCUSDT","exchangeEventTimeMillis":1784429288885,"localReceivedEpochMillis":1784429288875,"topSpreadTicks":268,"bid5Volume":134,"ask5Volume":128,"bid10Volume":288,"ask10Volume":590,"rawPayload":"{\"stream\":\"btcusdt@depth@100ms\",\"data\":{\"e\":\"depthUpdate\",\"E\":1784429288885,\"s\":\"BTCUSDT\",\"U\":3244435351,\"u\":3244435353,\"b\":[],\"a\":[[\"64825.82000000\",\"0.00401000\"],[\"64826.64000000\",\"0.00000000\"],[\"64914.49000000\",\"0.00011000\"]]}}"}
{"mode":"v9-depth-v5-spsc","workers":4,"sequenceNumber":363,"symbol":"XRPUSDT","exchangeEventTimeMillis":1784429288885,"localReceivedEpochMillis":1784429288876,"topSpreadTicks":0,"bid5Volume":5325000,"ask5Volume":6990900,"bid10Volume":21212800,"ask10Volume":8188800,"rawPayload":"{\"stream\":\"xrpusdt@depth@100ms\",\"data\":{\"e\":\"depthUpdate\",\"E\":1784429288885,\"s\":\"XRPUSDT\",\"U\":752699402,\"u\":752699402,\"b\":[],\"a\":[[\"1.09670000\",\"1295.60000000\"],[\"1.09680000\",\"6675.60000000\"]]}}"}
{"mode":"v9-depth-v5-spsc","workers":4,"sequenceNumber":364,"symbol":"ETHUSDT","exchangeEventTimeMillis":1784429288985,"localReceivedEpochMillis":1784429288977,"topSpreadTicks":18,"bid5Volume":3456,"ask5Volume":3634,"bid10Volume":11416,"ask10Volume":15456,"rawPayload":"{\"stream\":\"ethusdt@depth@100ms\",\"data\":{\"e\":\"depthUpdate\",\"E\":1784429288985,\"s\":\"ETHUSDT\",\"U\":2806164486,\"u\":2806164489,\"b\":[[\"1871.95000000\",\"0.00000000\"],[\"1871.93000000\",\"1.18060000\"]],\"a\":[[\"1872.50000000\",\"1.16570000\"],[\"1872.62000000\",\"1.60330000\"]]}}"}
{"mode":"v9-depth-v5-spsc","workers":4,"sequenceNumber":365,"symbol":"XRPUSDT","exchangeEventTimeMillis":1784429289385,"localReceivedEpochMillis":1784429289377,"topSpreadTicks":0,"bid5Volume":5325000,"ask5Volume":2390000,"bid10Volume":21212800,"ask10Volume":3587900,"rawPayload":"{\"stream\":\"xrpusdt@depth@100ms\",\"data\":{\"e\":\"depthUpdate\",\"E\":1784429289385,\"s\":\"XRPUSDT\",\"U\":752699403,\"u\":752699404,\"b\":[],\"a\":[[\"1.09700000\",\"966.40000000\"],[\"1.09710000\",\"2074.70000000\"]]}}"}
{"mode":"v9-depth-v5-spsc","workers":4,"sequenceNumber":366,"symbol":"ETHUSDT","exchangeEventTimeMillis":1784429289486,"localReceivedEpochMillis":1784429289477,"topSpreadTicks":18,"bid5Volume":3408,"ask5Volume":3632,"bid10Volume":31075,"ask10Volume":15454,"rawPayload":"{\"stream\":\"ethusdt@depth@100ms\",\"data\":{\"e\":\"depthUpdate\",\"E\":1784429289486,\"s\":\"ETHUSDT\",\"U\":2806164490,\"u\":2806164515,\"b\":[[\"1872.00000000\",\"0.00000000\"],[\"1871.93000000\",\"0.00000000\"],[\"1871.87000000\",\"0.00000000\"],[\"1871.84000000\",\"1.13210000\"],[\"1871.75000000\",\"0.00000000\"],[\"1871.74000000\",\"0.00000000\"],[\"1871.68000000\",\"0.00000000\"],[\"1871.66000000\",\"1.33660000\"],[\"1871.59000000\",\"0.91920000\"],[\"1871.41000000\",\"20.72150000\"],[\"1871.29000000\",\"0.00000000\"],[\"1871.28000000\",\"0.00000000\"],[\"1871.03000000\",\"0.00000000\"],[\"1870.75000000\",\"1.09310000\"],[\"1870.28000000\",\"1.63970000\"]],\"a\":[[\"1872.25000000\",\"1.33620000\"],[\"1872.32000000\",\"0.00000000\"],[\"1872.39000000\",\"0.00000000\"],[\"1872.41000000\",\"1.16320000\"],[\"1872.50000000\",\"0.00000000\"],[\"1872.57000000\",\"0.00000000\"]]}}"}
{"mode":"v9-depth-v5-spsc","workers":4,"sequenceNumber":367,"symbol":"XRPUSDT","exchangeEventTimeMillis":1784429289486,"localReceivedEpochMillis":1784429289478,"topSpreadTicks":0,"bid5Volume":6364600,"ask5Volume":6808500,"bid10Volume":22252400,"ask10Volume":8006400,"rawPayload":"{\"stream\":\"xrpusdt@depth@100ms\",\"data\":{\"e\":\"depthUpdate\",\"E\":1784429289486,\"s\":\"XRPUSDT\",\"U\":752699405,\"u\":752699408,\"b\":[[\"1.09640000\",\"3576.80000000\"],[\"1.09630000\",\"1214.60000000\"]],\"a\":[[\"1.09670000\",\"1478.10000000\"],[\"1.09680000\",\"6493.20000000\"]]}}"}
{"mode":"v9-depth-v5-spsc","workers":4,"sequenceNumber":368,"symbol":"SOLUSDT","exchangeEventTimeMillis":1784429289586,"localReceivedEpochMillis":1784429289576,"topSpreadTicks":1,"bid5Volume":87674,"ask5Volume":276411,"bid10Volume":422095,"ask10Volume":486366,"rawPayload":"{\"stream\":\"solusdt@depth@100ms\",\"data\":{\"e\":\"depthUpdate\",\"E\":1784429289586,\"s\":\"SOLUSDT\",\"U\":1609569861,\"u\":1609569862,\"b\":[[\"76.21000000\",\"0.10000000\"],[\"76.17000000\",\"30.19500000\"]],\"a\":[]}}"}
{"mode":"v9-depth-v5-spsc","workers":4,"sequenceNumber":369,"symbol":"ETHUSDT","exchangeEventTimeMillis":1784429289586,"localReceivedEpochMillis":1784429289576,"topSpreadTicks":17,"bid5Volume":3408,"ask5Volume":3632,"bid10Volume":31075,"ask10Volume":15454,"rawPayload":"{\"stream\":\"ethusdt@depth@100ms\",\"data\":{\"e\":\"depthUpdate\",\"E\":1784429289586,\"s\":\"ETHUSDT\",\"U\":2806164516,\"u\":2806164517,\"b\":[[\"1871.49000000\",\"1.02590000\"],[\"1871.44000000\",\"0.00000000\"]],\"a\":[[\"1872.13000000\",\"0.96640000\"],[\"1872.14000000\",\"0.00000000\"]]}}"}
{"mode":"v9-depth-v5-spsc","workers":4,"sequenceNumber":370,"symbol":"XRPUSDT","exchangeEventTimeMillis":1784429289586,"localReceivedEpochMillis":1784429289576,"topSpreadTicks":0,"bid5Volume":5507500,"ask5Volume":6808500,"bid10Volume":21395300,"ask10Volume":8006400,"rawPayload":"{\"stream\":\"xrpusdt@depth@100ms\",\"data\":{\"e\":\"depthUpdate\",\"E\":1784429289586,\"s\":\"XRPUSDT\",\"U\":752699409,\"u\":752699410,\"b\":[[\"1.09630000\",\"1032.20000000\"],[\"1.09620000\",\"357.50000000\"]],\"a\":[]}}"}
{"mode":"v9-depth-v5-spsc","workers":4,"sequenceNumber":371,"symbol":"ETHUSDT","exchangeEventTimeMillis":1784429289686,"localReceivedEpochMillis":1784429289676,"topSpreadTicks":24,"bid5Volume":2811,"ask5Volume":3632,"bid10Volume":30211,"ask10Volume":15454,"rawPayload":"{\"stream\":\"ethusdt@depth@100ms\",\"data\":{\"e\":\"depthUpdate\",\"E\":1784429289686,\"s\":\"ETHUSDT\",\"U\":2806164518,\"u\":2806164520,\"b\":[[\"1871.96000000\",\"0.00000000\"],[\"1871.89000000\",\"0.75690000\"],[\"1871.85000000\",\"0.75690000\"]],\"a\":[]}}"}
{"mode":"v9-depth-v5-spsc","workers":4,"sequenceNumber":372,"symbol":"BTCUSDT","exchangeEventTimeMillis":1784429289686,"localReceivedEpochMillis":1784429289677,"topSpreadTicks":268,"bid5Volume":134,"ask5Volume":128,"bid10Volume":288,"ask10Volume":590,"rawPayload":"{\"stream\":\"btcusdt@depth@100ms\",\"data\":{\"e\":\"depthUpdate\",\"E\":1784429289686,\"s\":\"BTCUSDT\",\"U\":3244435354,\"u\":3244435361,\"b\":[[\"64750.10000000\",\"0.00000000\"],[\"64749.95000000\",\"0.05832000\"],[\"64711.21000000\",\"0.00000000\"],[\"64711.05000000\",\"0.08812000\"],[\"64672.31000000\",\"0.00000000\"],[\"64672.16000000\",\"0.17331000\"],[\"64594.52000000\",\"0.00000000\"],[\"64594.36000000\",\"0.40717000\"]],\"a\":[[\"64905.48000000\",\"0.06043000\"],[\"64905.64000000\",\"0.00000000\"],[\"64944.38000000\",\"0.09239000\"],[\"64944.53000000\",\"0.00000000\"],[\"64983.28000000\",\"0.17644000\"],[\"64983.43000000\",\"0.00000000\"],[\"65061.07000000\",\"0.42827000\"],[\"65061.22000000\",\"0.00000000\"]]}}"}
{"mode":"v9-depth-v5-spsc","workers":4,"sequenceNumber":373,"symbol":"BTCUSDT","exchangeEventTimeMillis":1784429289786,"localReceivedEpochMillis":1784429289777,"topSpreadTicks":268,"bid5Volume":134,"ask5Volume":128,"bid10Volume":288,"ask10Volume":590,"rawPayload":"{\"stream\":\"btcusdt@depth@100ms\",\"data\":{\"e\":\"depthUpdate\",\"E\":1784429289786,\"s\":\"BTCUSDT\",\"U\":3244435362,\"u\":3244435363,\"b\":[[\"64820.96000000\",\"0.00000000\"],[\"64819.08000000\",\"0.04000000\"]],\"a\":[]}}"}
{"mode":"v9-depth-v5-spsc","workers":4,"sequenceNumber":374,"symbol":"BTCUSDT","exchangeEventTimeMillis":1784429289986,"localReceivedEpochMillis":1784429289976,"topSpreadTicks":268,"bid5Volume":134,"ask5Volume":128,"bid10Volume":288,"ask10Volume":590,"rawPayload":"{\"stream\":\"btcusdt@depth@100ms\",\"data\":{\"e\":\"depthUpdate\",\"E\":1784429289986,\"s\":\"BTCUSDT\",\"U\":3244435364,\"u\":3244435364,\"b\":[],\"a\":[[\"81072.08000000\",\"0.00030000\"]]}}"}
{"mode":"v9-depth-v5-spsc","workers":4,"sequenceNumber":375,"symbol":"ETHUSDT","exchangeEventTimeMillis":1784429290186,"localReceivedEpochMillis":1784429290177,"topSpreadTicks":24,"bid5Volume":2811,"ask5Volume":3632,"bid10Volume":31851,"ask10Volume":15454,"rawPayload":"{\"stream\":\"ethusdt@depth@100ms\",\"data\":{\"e\":\"depthUpdate\",\"E\":1784429290186,\"s\":\"ETHUSDT\",\"U\":2806164521,\"u\":2806164524,\"b\":[[\"1871.46000000\",\"5.03950000\"],[\"1871.28000000\",\"1.09310000\"],[\"1870.75000000\",\"0.00000000\"],[\"1870.28000000\",\"0.00000000\"]],\"a\":[]}}"}
{"mode":"v9-depth-v5-spsc","workers":4,"sequenceNumber":376,"symbol":"ETHUSDT","exchangeEventTimeMillis":1784429290286,"localReceivedEpochMillis":1784429290277,"topSpreadTicks":24,"bid5Volume":2811,"ask5Volume":3632,"bid10Volume":12769,"ask10Volume":15454,"rawPayload":"{\"stream\":\"ethusdt@depth@100ms\",\"data\":{\"e\":\"depthUpdate\",\"E\":1784429290286,\"s\":\"ETHUSDT\",\"U\":2806164525,\"u\":2806164526,\"b\":[[\"1871.53000000\",\"1.63970000\"],[\"1870.63000000\",\"0.00000000\"]],\"a\":[]}}"}
{"mode":"v9-depth-v5-spsc","workers":4,"sequenceNumber":377,"symbol":"BTCUSDT","exchangeEventTimeMillis":1784429290486,"localReceivedEpochMillis":1784429290477,"topSpreadTicks":268,"bid5Volume":134,"ask5Volume":128,"bid10Volume":288,"ask10Volume":590,"rawPayload":"{\"stream\":\"btcusdt@depth@100ms\",\"data\":{\"e\":\"depthUpdate\",\"E\":1784429290486,\"s\":\"BTCUSDT\",\"U\":3244435365,\"u\":3244435366,\"b\":[],\"a\":[[\"64850.68000000\",\"0.06174000\"],[\"64863.66000000\",\"0.00000000\"]]}}"}
{"mode":"v9-depth-v5-spsc","workers":4,"sequenceNumber":378,"symbol":"SOLUSDT","exchangeEventTimeMillis":1784429290586,"localReceivedEpochMillis":1784429290577,"topSpreadTicks":1,"bid5Volume":117869,"ask5Volume":246216,"bid10Volume":439823,"ask10Volume":387469,"rawPayload":"{\"stream\":\"solusdt@depth@100ms\",\"data\":{\"e\":\"depthUpdate\",\"E\":1784429290586,\"s\":\"SOLUSDT\",\"U\":1609569863,\"u\":1609569870,\"b\":[[\"76.21000000\",\"30.29500000\"],[\"76.17000000\",\"0.00000000\"],[\"76.15000000\",\"31.06000000\"],[\"76.14000000\",\"176.55600000\"]],\"a\":[[\"76.26000000\",\"72.56400000\"],[\"76.27000000\",\"14.67300000\"],[\"76.29000000\",\"86.50300000\"],[\"76.31000000\",\"30.19500000\"]]}}"}
{"mode":"v9-depth-v5-spsc","workers":4,"sequenceNumber":379,"symbol":"XRPUSDT","exchangeEventTimeMillis":1784429290586,"localReceivedEpochMillis":1784429290577,"topSpreadTicks":0,"bid5Volume":6199500,"ask5Volume":6808500,"bid10Volume":22087300,"ask10Volume":8006400,"rawPayload":"{\"stream\":\"xrpusdt@depth@100ms\",\"data\":{\"e\":\"depthUpdate\",\"E\":1784429290586,\"s\":\"XRPUSDT\",\"U\":752699411,\"u\":752699414,\"b\":[[\"1.09640000\",\"3576.80000000\"],[\"1.09630000\",\"1049.50000000\"]],\"a\":[]}}"}
{"mode":"v9-depth-v5-spsc","workers":4,"sequenceNumber":380,"symbol":"ETHUSDT","exchangeEventTimeMillis":1784429290686,"localReceivedEpochMillis":1784429290677,"topSpreadTicks":24,"bid5Volume":3391,"ask5Volume":3632,"bid10Volume":32804,"ask10Volume":15490,"rawPayload":"{\"stream\":\"ethusdt@depth@100ms\",\"data\":{\"e\":\"depthUpdate\",\"E\":1784429290686,\"s\":\"ETHUSDT\",\"U\":2806164527,\"u\":2806164540,\"b\":[[\"1871.85000000\",\"0.00000000\"],[\"1871.59000000\",\"0.00000000\"],[\"1871.54000000\",\"0.98920000\"],[\"1871.40000000\",\"0.00000000\"],[\"1871.20000000\",\"1.48390000\"],[\"1869.75000000\",\"2.05300000\"],[\"1869.61000000\",\"0.00000000\"],[\"1868.63000000\",\"2.95960000\"],[\"1868.49000000\",\"0.00000000\"],[\"1867.51000000\",\"5.99790000\"],[\"1867.36000000\",\"0.00000000\"],[\"1865.26000000\",\"40.54620000\"],[\"1865.12000000\",\"0.00000000\"]],\"a\":[[\"1872.62000000\",\"0.00000000\"],[\"1873.51000000\",\"0.00000000\"],[\"1874.11000000\",\"0.00000000\"],[\"1874.26000000\",\"7.38780000\"],[\"1875.23000000\",\"0.00000000\"],[\"1875.38000000\",\"3.02900000\"],[\"1876.36000000\",\"0.00000000\"],[\"1876.50000000\",\"6.30890000\"]]}}"}
{"mode":"v9-depth-v5-spsc","workers":4,"sequenceNumber":381,"symbol":"SOLUSDT","exchangeEventTimeMillis":1784429291287,"localReceivedEpochMillis":1784429291278,"topSpreadTicks":1,"bid5Volume":135569,"ask5Volume":246216,"bid10Volume":457523,"ask10Volume":387469,"rawPayload":"{\"stream\":\"solusdt@depth@100ms\",\"data\":{\"e\":\"depthUpdate\",\"E\":1784429291287,\"s\":\"SOLUSDT\",\"U\":1609569871,\"u\":1609569871,\"b\":[[\"76.20000000\",\"31.23700000\"]],\"a\":[]}}"}
{"mode":"v9-depth-v5-spsc","workers":4,"sequenceNumber":382,"symbol":"ETHUSDT","exchangeEventTimeMillis":1784429291687,"localReceivedEpochMillis":1784429291678,"topSpreadTicks":18,"bid5Volume":3391,"ask5Volume":3632,"bid10Volume":32804,"ask10Volume":15490,"rawPayload":"{\"stream\":\"ethusdt@depth@100ms\",\"data\":{\"e\":\"depthUpdate\",\"E\":1784429291687,\"s\":\"ETHUSDT\",\"U\":2806164541,\"u\":2806164542,\"b\":[[\"1871.50000000\",\"1.02590000\"],[\"1871.49000000\",\"0.00000000\"]],\"a\":[[\"1872.07000000\",\"0.96640000\"],[\"1872.13000000\",\"0.00000000\"]]}}"}
{"mode":"v9-depth-v5-spsc","workers":4,"sequenceNumber":383,"symbol":"BTCUSDT","exchangeEventTimeMillis":1784429291687,"localReceivedEpochMillis":1784429291679,"topSpreadTicks":268,"bid5Volume":134,"ask5Volume":128,"bid10Volume":288,"ask10Volume":590,"rawPayload":"{\"stream\":\"btcusdt@depth@100ms\",\"data\":{\"e\":\"depthUpdate\",\"E\":1784429291687,\"s\":\"BTCUSDT\",\"U\":3244435367,\"u\":3244435367,\"b\":[[\"64808.78000000\",\"0.00000000\"],[\"64808.11000000\",\"0.02826000\"]],\"a\":[]}}"}
{"mode":"v9-depth-v5-spsc","workers":4,"sequenceNumber":384,"symbol":"ETHUSDT","exchangeEventTimeMillis":1784429291787,"localReceivedEpochMillis":1784429291779,"topSpreadTicks":17,"bid5Volume":3391,"ask5Volume":4547,"bid10Volume":32804,"ask10Volume":14904,"rawPayload":"{\"stream\":\"ethusdt@depth@100ms\",\"data\":{\"e\":\"depthUpdate\",\"E\":1784429291787,\"s\":\"ETHUSDT\",\"U\":2806164543,\"u\":2806164543,\"b\":[],\"a\":[[\"1872.06000000\",\"1.05360000\"]]}}"}
{"mode":"v9-depth-v5-spsc","workers":4,"sequenceNumber":385,"symbol":"XRPUSDT","exchangeEventTimeMillis":1784429291987,"localReceivedEpochMillis":1784429291978,"topSpreadTicks":0,"bid5Volume":6199500,"ask5Volume":4527600,"bid10Volume":22087300,"ask10Volume":5725500,"rawPayload":"{\"stream\":\"xrpusdt@depth@100ms\",\"data\":{\"e\":\"depthUpdate\",\"E\":1784429291987,\"s\":\"XRPUSDT\",\"U\":752699415,\"u\":752699416,\"b\":[],\"a\":[[\"1.09670000\",\"3759.20000000\"],[\"1.09680000\",\"4212.30000000\"]]}}"}
{"mode":"v9-depth-v5-spsc","workers":4,"sequenceNumber":386,"symbol":"ETHUSDT","exchangeEventTimeMillis":1784429291987,"localReceivedEpochMillis":1784429291979,"topSpreadTicks":17,"bid5Volume":3425,"ask5Volume":3522,"bid10Volume":32942,"ask10Volume":15380,"rawPayload":"{\"stream\":\"ethusdt@depth@100ms\",\"data\":{\"e\":\"depthUpdate\",\"E\":1784429291987,\"s\":\"ETHUSDT\",\"U\":2806164544,\"u\":2806164551,\"b\":[[\"1871.84000000\",\"0.00000000\"],[\"1871.65000000\",\"1.16620000\"],[\"1871.54000000\",\"0.00000000\"],[\"1871.47000000\",\"0.00000000\"]],\"a\":[[\"1872.11000000\",\"1.33630000\"],[\"1872.25000000\",\"0.00000000\"],[\"1872.41000000\",\"0.00000000\"]]}}"}
{"mode":"v9-depth-v5-spsc","workers":4,"sequenceNumber":387,"symbol":"SOLUSDT","exchangeEventTimeMillis":1784429292087,"localReceivedEpochMillis":1784429292078,"topSpreadTicks":1,"bid5Volume":136719,"ask5Volume":260610,"bid10Volume":458673,"ask10Volume":487319,"rawPayload":"{\"stream\":\"solusdt@depth@100ms\",\"data\":{\"e\":\"depthUpdate\",\"E\":1784429292087,\"s\":\"SOLUSDT\",\"U\":1609569872,\"u\":1609569878,\"b\":[[\"76.24000000\",\"13.82200000\"],[\"76.23000000\",\"18.01200000\"],[\"76.22000000\",\"43.35300000\"]],\"a\":[[\"76.26000000\",\"54.58900000\"],[\"76.27000000\",\"32.64800000\"],[\"76.29000000\",\"100.89700000\"],[\"76.30000000\",\"0.00000000\"]]}}"}
{"mode":"v9-depth-v5-spsc","workers":4,"sequenceNumber":388,"symbol":"ETHUSDT","exchangeEventTimeMillis":1784429292087,"localReceivedEpochMillis":1784429292078,"topSpreadTicks":17,"bid5Volume":4926,"ask5Volume":4640,"bid10Volume":32538,"ask10Volume":14859,"rawPayload":"{\"stream\":\"ethusdt@depth@100ms\",\"data\":{\"e\":\"depthUpdate\",\"E\":1784429292087,\"s\":\"ETHUSDT\",\"U\":2806164552,\"u\":2806164571,\"b\":[[\"1871.76000000\",\"0.00000000\"],[\"1871.66000000\",\"0.00000000\"],[\"1871.52000000\",\"1.33670000\"],[\"1871.50000000\",\"1.16480000\"],[\"1871.46000000\",\"3.56480000\"],[\"1871.41000000\",\"0.00000000\"],[\"1871.38000000\",\"1.06910000\"],[\"1871.29000000\",\"20.72280000\"],[\"1871.20000000\",\"1.47490000\"],[\"1870.99000000\",\"1.60360000\"],[\"1870.64000000\",\"0.00000000\"],[\"1870.41000000\",\"0.00000000\"],[\"1870.26000000\",\"2.13820000\"],[\"1870.15000000\",\"9.19690000\"],[\"1864.62000000\",\"0.00000000\"]],\"a\":[[\"1872.17000000\",\"0.13880000\"],[\"1872.23000000\",\"1.14700000\"],[\"1872.37000000\",\"0.00000000\"],[\"1872.47000000\",\"1.33510000\"],[\"1872.73000000\",\"0.00000000\"],[\"1873.52000000\",\"9.18060000\"],[\"1873.78000000\",\"0.00000000\"],[\"1879.55000000\",\"7.23620000\"],[\"1880.86000000\",\"0.00000000\"]]}}"}
{"mode":"v9-depth-v5-spsc","workers":4,"sequenceNumber":389,"symbol":"ETHUSDT","exchangeEventTimeMillis":1784429292187,"localReceivedEpochMillis":1784429292178,"topSpreadTicks":38,"bid5Volume":6660,"ask5Volume":4669,"bid10Volume":31673,"ask10Volume":14888,"rawPayload":"{\"stream\":\"ethusdt@depth@100ms\",\"data\":{\"e\":\"depthUpdate\",\"E\":1784429292187,\"s\":\"ETHUSDT\",\"U\":2806164572,\"u\":2806164584,\"b\":[[\"1871.89000000\",\"0.00000000\"],[\"1871.81000000\",\"0.00000000\"],[\"1871.53000000\",\"0.00000000\"],[\"1871.46000000\",\"1.92510000\"],[\"1871.28000000\",\"0.00000000\"],[\"1870.98000000\",\"1.09310000\"],[\"1870.51000000\",\"1.63970000\"],[\"1864.50000000\",\"7.23920000\"]],\"a\":[[\"1872.03000000\",\"1.33630000\"],[\"1872.11000000\",\"0.00000000\"],[\"1872.23000000\",\"1.17680000\"],[\"1879.46000000\",\"7.18500000\"],[\"1880.80000000\",\"0.00000000\"]]}}"}
{"mode":"v9-depth-v5-spsc","workers":4,"sequenceNumber":390,"symbol":"ETHUSDT","exchangeEventTimeMillis":1784429292388,"localReceivedEpochMillis":1784429292378,"topSpreadTicks":38,"bid5Volume":6660,"ask5Volume":4669,"bid10Volume":31673,"ask10Volume":14888,"rawPayload":"{\"stream\":\"ethusdt@depth@100ms\",\"data\":{\"e\":\"depthUpdate\",\"E\":1784429292388,\"s\":\"ETHUSDT\",\"U\":2806164585,\"u\":2806164585,\"b\":[[\"1864.50000000\",\"0.00000000\"]],\"a\":[]}}"}
{"mode":"v9-depth-v5-spsc","workers":4,"sequenceNumber":391,"symbol":"SOLUSDT","exchangeEventTimeMillis":1784429292488,"localReceivedEpochMillis":1784429292477,"topSpreadTicks":1,"bid5Volume":136719,"ask5Volume":210285,"bid10Volume":458673,"ask10Volume":436994,"rawPayload":"{\"stream\":\"solusdt@depth@100ms\",\"data\":{\"e\":\"depthUpdate\",\"E\":1784429292488,\"s\":\"SOLUSDT\",\"U\":1609569879,\"u\":1609569880,\"b\":[],\"a\":[[\"76.28000000\",\"3.28300000\"],[\"76.29000000\",\"80.76700000\"]]}}"}
{"mode":"v9-depth-v5-spsc","workers":4,"sequenceNumber":392,"symbol":"BTCUSDT","exchangeEventTimeMillis":1784429292488,"localReceivedEpochMillis":1784429292477,"topSpreadTicks":268,"bid5Volume":134,"ask5Volume":128,"bid10Volume":288,"ask10Volume":590,"rawPayload":"{\"stream\":\"btcusdt@depth@100ms\",\"data\":{\"e\":\"depthUpdate\",\"E\":1784429292488,\"s\":\"BTCUSDT\",\"U\":3244435368,\"u\":3244435368,\"b\":[],\"a\":[[\"81072.08000000\",\"0.00045000\"]]}}"}
{"mode":"v9-depth-v5-spsc","workers":4,"sequenceNumber":393,"symbol":"ETHUSDT","exchangeEventTimeMillis":1784429292588,"localReceivedEpochMillis":1784429292580,"topSpreadTicks":38,"bid5Volume":6689,"ask5Volume":4669,"bid10Volume":31702,"ask10Volume":14888,"rawPayload":"{\"stream\":\"ethusdt@depth@100ms\",\"data\":{\"e\":\"depthUpdate\",\"E\":1784429292588,\"s\":\"ETHUSDT\",\"U\":2806164586,\"u\":2806164587,\"b\":[[\"1871.65000000\",\"1.19560000\"],[\"1864.49000000\",\"7.26280000\"]],\"a\":[]}}"}
{"mode":"v9-depth-v5-spsc","workers":4,"sequenceNumber":394,"symbol":"BTCUSDT","exchangeEventTimeMillis":1784429292688,"localReceivedEpochMillis":1784429292678,"topSpreadTicks":268,"bid5Volume":134,"ask5Volume":128,"bid10Volume":288,"ask10Volume":590,"rawPayload":"{\"stream\":\"btcusdt@depth@100ms\",\"data\":{\"e\":\"depthUpdate\",\"E\":1784429292688,\"s\":\"BTCUSDT\",\"U\":3244435369,\"u\":3244435369,\"b\":[],\"a\":[[\"64914.49000000\",\"0.00000000\"]]}}"}
{"mode":"v9-depth-v5-spsc","workers":4,"sequenceNumber":395,"symbol":"ETHUSDT","exchangeEventTimeMillis":1784429292688,"localReceivedEpochMillis":1784429292678,"topSpreadTicks":38,"bid5Volume":7259,"ask5Volume":4669,"bid10Volume":32248,"ask10Volume":14888,"rawPayload":"{\"stream\":\"ethusdt@depth@100ms\",\"data\":{\"e\":\"depthUpdate\",\"E\":1784429292688,\"s\":\"ETHUSDT\",\"U\":2806164588,\"u\":2806164590,\"b\":[[\"1871.47000000\",\"1.63970000\"],[\"1870.84000000\",\"1.63970000\"],[\"1870.51000000\",\"0.00000000\"]],\"a\":[]}}"}
{"mode":"v9-depth-v5-spsc","workers":4,"sequenceNumber":396,"symbol":"BTCUSDT","exchangeEventTimeMillis":1784429292788,"localReceivedEpochMillis":1784429292779,"topSpreadTicks":268,"bid5Volume":134,"ask5Volume":128,"bid10Volume":288,"ask10Volume":590,"rawPayload":"{\"stream\":\"btcusdt@depth@100ms\",\"data\":{\"e\":\"depthUpdate\",\"E\":1784429292788,\"s\":\"BTCUSDT\",\"U\":3244435370,\"u\":3244435370,\"b\":[],\"a\":[[\"64914.49000000\",\"0.00011000\"]]}}"}
{"mode":"v9-depth-v5-spsc","workers":4,"sequenceNumber":397,"symbol":"SOLUSDT","exchangeEventTimeMillis":1784429292888,"localReceivedEpochMillis":1784429292879,"topSpreadTicks":1,"bid5Volume":136719,"ask5Volume":260610,"bid10Volume":458673,"ask10Volume":487319,"rawPayload":"{\"stream\":\"solusdt@depth@100ms\",\"data\":{\"e\":\"depthUpdate\",\"E\":1784429292888,\"s\":\"SOLUSDT\",\"U\":1609569881,\"u\":1609569882,\"b\":[],\"a\":[[\"76.28000000\",\"53.60800000\"]]}}"}
{"mode":"v9-depth-v5-spsc","workers":4,"sequenceNumber":398,"symbol":"ETHUSDT","exchangeEventTimeMillis":1784429292888,"localReceivedEpochMillis":1784429292879,"topSpreadTicks":38,"bid5Volume":6660,"ask5Volume":4640,"bid10Volume":31673,"ask10Volume":14859,"rawPayload":"{\"stream\":\"ethusdt@depth@100ms\",\"data\":{\"e\":\"depthUpdate\",\"E\":1784429292888,\"s\":\"ETHUSDT\",\"U\":2806164591,\"u\":2806164596,\"b\":[[\"1871.65000000\",\"1.16620000\"],[\"1871.47000000\",\"0.00000000\"],[\"1864.49000000\",\"0.00000000\"]],\"a\":[[\"1872.23000000\",\"1.14700000\"],[\"1879.38000000\",\"7.20560000\"],[\"1880.74000000\",\"0.00000000\"]]}}"}
{"mode":"v9-depth-v5-spsc","workers":4,"sequenceNumber":399,"symbol":"BTCUSDT","exchangeEventTimeMillis":1784429292988,"localReceivedEpochMillis":1784429292979,"topSpreadTicks":268,"bid5Volume":136,"ask5Volume":128,"bid10Volume":290,"ask10Volume":590,"rawPayload":"{\"stream\":\"btcusdt@depth@100ms\",\"data\":{\"e\":\"depthUpdate\",\"E\":1784429292988,\"s\":\"BTCUSDT\",\"U\":3244435371,\"u\":3244435372,\"b\":[[\"64816.39000000\",\"0.00000000\"],[\"64814.44000000\",\"0.03087000\"]],\"a\":[]}}"}
{"mode":"v9-depth-v5-spsc","workers":4,"sequenceNumber":400,"symbol":"ETHUSDT","exchangeEventTimeMillis":1784429293088,"localReceivedEpochMillis":1784429293078,"topSpreadTicks":38,"bid5Volume":6660,"ask5Volume":4640,"bid10Volume":31673,"ask10Volume":14859,"rawPayload":"{\"stream\":\"ethusdt@depth@100ms\",\"data\":{\"e\":\"depthUpdate\",\"E\":1784429293088,\"s\":\"ETHUSDT\",\"U\":2806164597,\"u\":2806164597,\"b\":[[\"1863.12000000\",\"9.21790000\"]],\"a\":[]}}"}
{"mode":"v9-depth-v5-spsc","workers":4,"sequenceNumber":401,"symbol":"SOLUSDT","exchangeEventTimeMillis":1784429293188,"localReceivedEpochMillis":1784429293179,"topSpreadTicks":1,"bid5Volume":185122,"ask5Volume":290805,"bid10Volume":721177,"ask10Volume":760016,"rawPayload":"{\"stream\":\"solusdt@depth@100ms\",\"data\":{\"e\":\"depthUpdate\",\"E\":1784429293188,\"s\":\"SOLUSDT\",\"U\":1609569883,\"u\":1609569885,\"b\":[[\"76.23000000\",\"0.00000000\"]],\"a\":[[\"76.27000000\",\"62.84300000\"],[\"76.31000000\",\"0.00000000\"]]}}"}
{"mode":"v9-depth-v5-spsc","workers":4,"sequenceNumber":402,"symbol":"XRPUSDT","exchangeEventTimeMillis":1784429293188,"localReceivedEpochMillis":1784429293179,"topSpreadTicks":0,"bid5Volume":7431700,"ask5Volume":4527600,"bid10Volume":23319500,"ask10Volume":5725500,"rawPayload":"{\"stream\":\"xrpusdt@depth@100ms\",\"data\":{\"e\":\"depthUpdate\",\"E\":1784429293188,\"s\":\"XRPUSDT\",\"U\":752699417,\"u\":752699417,\"b\":[[\"1.09640000\",\"2281.70000000\"]],\"a\":[]}}"}
{"mode":"v9-depth-v5-spsc","workers":4,"sequenceNumber":403,"symbol":"ETHUSDT","exchangeEventTimeMillis":1784429293288,"localReceivedEpochMillis":1784429293279,"topSpreadTicks":36,"bid5Volume":4594,"ask5Volume":3522,"bid10Volume":29170,"ask10Volume":14226,"rawPayload":"{\"stream\":\"ethusdt@depth@100ms\",\"data\":{\"e\":\"depthUpdate\",\"E\":1784429293288,\"s\":\"ETHUSDT\",\"U\":2806164598,\"u\":2806164602,\"b\":[[\"1871.60000000\",\"0.02970000\"],[\"1871.50000000\",\"0.13890000\"],[\"1871.44000000\",\"1.02590000\"],[\"1871.32000000\",\"1.63970000\"]],\"a\":[[\"1872.01000000\",\"0.96640000\"],[\"1872.07000000\",\"0.00000000\"],[\"1872.16000000\",\"0.02960000\"]]}}"}
{"mode":"v9-depth-v5-spsc","workers":4,"sequenceNumber":404,"symbol":"ETHUSDT","exchangeEventTimeMillis":1784429293388,"localReceivedEpochMillis":1784429293379,"topSpreadTicks":35,"bid5Volume":4594,"ask5Volume":3538,"bid10Volume":29170,"ask10Volume":14242,"rawPayload":"{\"stream\":\"ethusdt@depth@100ms\",\"data\":{\"e\":\"depthUpdate\",\"E\":1784429293388,\"s\":\"ETHUSDT\",\"U\":2806164603,\"u\":2806164604,\"b\":[],\"a\":[[\"1872.00000000\",\"1.06900000\"],[\"1872.06000000\",\"0.00000000\"]]}}"}
{"mode":"v9-depth-v5-spsc","workers":4,"sequenceNumber":405,"symbol":"SOLUSDT","exchangeEventTimeMillis":1784429293588,"localReceivedEpochMillis":1784429293579,"topSpreadTicks":1,"bid5Volume":185122,"ask5Volume":290953,"bid10Volume":721177,"ask10Volume":760164,"rawPayload":"{\"stream\":\"solusdt@depth@100ms\",\"data\":{\"e\":\"depthUpdate\",\"E\":1784429293588,\"s\":\"SOLUSDT\",\"U\":1609569886,\"u\":1609569889,\"b\":[],\"a\":[[\"76.28000000\",\"53.60800000\"],[\"76.29000000\",\"80.91500000\"]]}}"}
{"mode":"v9-depth-v5-spsc","workers":4,"sequenceNumber":406,"symbol":"BTCUSDT","exchangeEventTimeMillis":1784429293588,"localReceivedEpochMillis":1784429293579,"topSpreadTicks":268,"bid5Volume":136,"ask5Volume":128,"bid10Volume":290,"ask10Volume":590,"rawPayload":"{\"stream\":\"btcusdt@depth@100ms\",\"data\":{\"e\":\"depthUpdate\",\"E\":1784429293588,\"s\":\"BTCUSDT\",\"U\":3244435373,\"u\":3244435374,\"b\":[[\"64816.25000000\",\"0.03087000\"],[\"64814.44000000\",\"0.00000000\"]],\"a\":[]}}"}
{"mode":"v9-depth-v5-spsc","workers":4,"sequenceNumber":407,"symbol":"SOLUSDT","exchangeEventTimeMillis":1784429293688,"localReceivedEpochMillis":1784429293680,"topSpreadTicks":1,"bid5Volume":185122,"ask5Volume":210433,"bid10Volume":721177,"ask10Volume":358375,"rawPayload":"{\"stream\":\"solusdt@depth@100ms\",\"data\":{\"e\":\"depthUpdate\",\"E\":1784429293688,\"s\":\"SOLUSDT\",\"U\":1609569890,\"u\":1609569894,\"b\":[],\"a\":[[\"76.27000000\",\"32.64800000\"],[\"76.28000000\",\"3.28300000\"],[\"76.30000000\",\"20.13000000\"],[\"76.31000000\",\"30.19500000\"]]}}"}
{"mode":"v9-depth-v5-spsc","workers":4,"sequenceNumber":408,"symbol":"ETHUSDT","exchangeEventTimeMillis":1784429293788,"localReceivedEpochMillis":1784429293779,"topSpreadTicks":35,"bid5Volume":4606,"ask5Volume":3538,"bid10Volume":29182,"ask10Volume":14223,"rawPayload":"{\"stream\":\"ethusdt@depth@100ms\",\"data\":{\"e\":\"depthUpdate\",\"E\":1784429293788,\"s\":\"ETHUSDT\",\"U\":2806164605,\"u\":2806164612,\"b\":[[\"1871.72000000\",\"0.00000000\"],[\"1871.65000000\",\"1.17860000\"]],\"a\":[[\"1872.23000000\",\"1.12860000\"],[\"1872.29000000\",\"0.00000000\"]]}}"}
{"mode":"v9-depth-v5-spsc","workers":4,"sequenceNumber":409,"symbol":"ETHUSDT","exchangeEventTimeMillis":1784429293888,"localReceivedEpochMillis":1784429293879,"topSpreadTicks":11,"bid5Volume":3716,"ask5Volume":3538,"bid10Volume":28983,"ask10Volume":14209,"rawPayload":"{\"stream\":\"ethusdt@depth@100ms\",\"data\":{\"e\":\"depthUpdate\",\"E\":1784429293888,\"s\":\"ETHUSDT\",\"U\":2806164613,\"u\":2806164628,\"b\":[[\"1871.89000000\",\"1.14440000\"],[\"1871.72000000\",\"0.00000000\"],[\"1871.65000000\",\"0.00000000\"],[\"1871.61000000\",\"1.33660000\"],[\"1871.52000000\",\"0.00000000\"],[\"1871.49000000\",\"1.06900000\"],[\"1871.44000000\",\"1.02590000\"],[\"1871.38000000\",\"0.00000000\"],[\"1871.32000000\",\"0.00000000\"],[\"1870.46000000\",\"1.63970000\"]],\"a\":[[\"1872.23000000\",\"0.00000000\"],[\"1872.29000000\",\"0.00000000\"],[\"1872.46000000\",\"1.11400000\"]]}}"}
{"mode":"v9-depth-v5-spsc","workers":4,"sequenceNumber":410,"symbol":"SOLUSDT","exchangeEventTimeMillis":1784429293988,"localReceivedEpochMillis":1784429293978,"topSpreadTicks":1,"bid5Volume":185122,"ask5Volume":195891,"bid10Volume":721177,"ask10Volume":357921,"rawPayload":"{\"stream\":\"solusdt@depth@100ms\",\"data\":{\"e\":\"depthUpdate\",\"E\":1784429293988,\"s\":\"SOLUSDT\",\"U\":1609569895,\"u\":1609569896,\"b\":[],\"a\":[[\"76.29000000\",\"66.37300000\"],[\"76.30000000\",\"34.21800000\"]]}}"}
{"mode":"v9-depth-v5-spsc","workers":4,"sequenceNumber":411,"symbol":"ETHUSDT","exchangeEventTimeMillis":1784429293988,"localReceivedEpochMillis":1784429293981,"topSpreadTicks":20,"bid5Volume":3725,"ask5Volume":3538,"bid10Volume":28992,"ask10Volume":14185,"rawPayload":"{\"stream\":\"ethusdt@depth@100ms\",\"data\":{\"e\":\"depthUpdate\",\"E\":1784429293988,\"s\":\"ETHUSDT\",\"U\":2806164629,\"u\":2806164638,\"b\":[[\"1871.89000000\",\"0.00000000\"],[\"1871.80000000\",\"1.15340000\"],[\"1871.54000000\",\"1.06900000\"],[\"1871.49000000\",\"0.00000000\"],[\"1871.19000000\",\"1.60350000\"],[\"1870.99000000\",\"0.00000000\"]],\"a\":[[\"1872.03000000\",\"0.00000000\"],[\"1872.19000000\",\"1.33620000\"],[\"1872.38000000\",\"1.09060000\"],[\"1872.46000000\",\"0.00000000\"]]}}"}
{"mode":"v9-depth-v5-spsc","workers":4,"sequenceNumber":412,"symbol":"BTCUSDT","exchangeEventTimeMillis":1784429294289,"localReceivedEpochMillis":1784429294279,"topSpreadTicks":268,"bid5Volume":144,"ask5Volume":128,"bid10Volume":288,"ask10Volume":590,"rawPayload":"{\"stream\":\"btcusdt@depth@100ms\",\"data\":{\"e\":\"depthUpdate\",\"E\":1784429294289,\"s\":\"BTCUSDT\",\"U\":3244435375,\"u\":3244435385,\"b\":[[\"64817.95000000\",\"0.00000000\"],[\"64816.25000000\",\"0.00000000\"]],\"a\":[[\"64837.38000000\",\"0.00000000\"],[\"64837.78000000\",\"0.00000000\"],[\"64838.03000000\",\"0.00162000\"],[\"64838.52000000\",\"0.00000000\"],[\"64838.71000000\",\"0.00000000\"]]}}"}
{"mode":"v9-depth-v5-spsc","workers":4,"sequenceNumber":413,"symbol":"ETHUSDT","exchangeEventTimeMillis":1784429294289,"localReceivedEpochMillis":1784429294280,"topSpreadTicks":11,"bid5Volume":3678,"ask5Volume":3538,"bid10Volume":28945,"ask10Volume":14891,"rawPayload":"{\"stream\":\"ethusdt@depth@100ms\",\"data\":{\"e\":\"depthUpdate\",\"E\":1784429294289,\"s\":\"ETHUSDT\",\"U\":2806164639,\"u\":2806164653,\"b\":[[\"1871.90000000\",\"1.10770000\"],[\"1871.80000000\",\"0.00000000\"],[\"1871.75000000\",\"1.33650000\"],[\"1871.61000000\",\"0.00000000\"],[\"1871.59000000\",\"1.06890000\"],[\"1871.57000000\",\"0.13870000\"],[\"1871.54000000\",\"0.00000000\"],[\"1871.50000000\",\"0.00000000\"],[\"1871.27000000\",\"1.47490000\"],[\"1871.20000000\",\"0.00000000\"]],\"a\":[[\"1872.00000000\",\"0.00000000\"],[\"1872.06000000\",\"1.06900000\"],[\"1872.17000000\",\"0.00000000\"],[\"1872.24000000\",\"0.13880000\"],[\"1872.38000000\",\"0.00000000\"],[\"1872.43000000\",\"0.00000000\"],[\"1872.47000000\",\"1.13470000\"],[\"1872.54000000\",\"1.47340000\"]]}}"}
{"mode":"v9-depth-v5-spsc","workers":4,"sequenceNumber":414,"symbol":"XRPUSDT","exchangeEventTimeMillis":1784429294289,"localReceivedEpochMillis":1784429294281,"topSpreadTicks":0,"bid5Volume":5325000,"ask5Volume":4527600,"bid10Volume":21212800,"ask10Volume":5725500,"rawPayload":"{\"stream\":\"xrpusdt@depth@100ms\",\"data\":{\"e\":\"depthUpdate\",\"E\":1784429294289,\"s\":\"XRPUSDT\",\"U\":752699418,\"u\":752699421,\"b\":[[\"1.09640000\",\"3214.30000000\"],[\"1.09630000\",\"227.90000000\"],[\"1.09620000\",\"175.00000000\"]],\"a\":[]}}"}
{"mode":"v9-depth-v5-spsc","workers":4,"sequenceNumber":415,"symbol":"ETHUSDT","exchangeEventTimeMillis":1784429294389,"localReceivedEpochMillis":1784429294379,"topSpreadTicks":11,"bid5Volume":3678,"ask5Volume":3537,"bid10Volume":28945,"ask10Volume":14890,"rawPayload":"{\"stream\":\"ethusdt@depth@100ms\",\"data\":{\"e\":\"depthUpdate\",\"E\":1784429294389,\"s\":\"ETHUSDT\",\"U\":2806164654,\"u\":2806164655,\"b\":[],\"a\":[[\"1872.06000000\",\"0.00000000\"],[\"1872.12000000\",\"1.06890000\"]]}}"}
{"mode":"v9-depth-v5-spsc","workers":4,"sequenceNumber":416,"symbol":"BTCUSDT","exchangeEventTimeMillis":1784429294389,"localReceivedEpochMillis":1784429294379,"topSpreadTicks":268,"bid5Volume":136,"ask5Volume":128,"bid10Volume":290,"ask10Volume":590,"rawPayload":"{\"stream\":\"btcusdt@depth@100ms\",\"data\":{\"e\":\"depthUpdate\",\"E\":1784429294389,\"s\":\"BTCUSDT\",\"U\":3244435386,\"u\":3244435388,\"b\":[[\"64819.77000000\",\"0.03087000\"]],\"a\":[[\"64838.03000000\",\"0.00000000\"],[\"64838.71000000\",\"0.00162000\"]]}}"}
{"mode":"v9-depth-v5-spsc","workers":4,"sequenceNumber":417,"symbol":"SOLUSDT","exchangeEventTimeMillis":1784429294889,"localReceivedEpochMillis":1784429294880,"topSpreadTicks":1,"bid5Volume":118707,"ask5Volume":195891,"bid10Volume":440661,"ask10Volume":357921,"rawPayload":"{\"stream\":\"solusdt@depth@100ms\",\"data\":{\"e\":\"depthUpdate\",\"E\":1784429294889,\"s\":\"SOLUSDT\",\"U\":1609569897,\"u\":1609569898,\"b\":[[\"76.23000000\",\"6.56200000\"],[\"76.22000000\",\"36.79100000\"]],\"a\":[]}}"}
{"mode":"v9-depth-v5-spsc","workers":4,"sequenceNumber":418,"symbol":"BTCUSDT","exchangeEventTimeMillis":1784429294989,"localReceivedEpochMillis":1784429294981,"topSpreadTicks":268,"bid5Volume":136,"ask5Volume":128,"bid10Volume":290,"ask10Volume":590,"rawPayload":"{\"stream\":\"btcusdt@depth@100ms\",\"data\":{\"e\":\"depthUpdate\",\"E\":1784429294989,\"s\":\"BTCUSDT\",\"U\":3244435389,\"u\":3244435389,\"b\":[],\"a\":[[\"81072.08000000\",\"0.00045000\"]]}}"}
{"mode":"v9-depth-v5-spsc","workers":4,"sequenceNumber":419,"symbol":"SOLUSDT","exchangeEventTimeMillis":1784429294989,"localReceivedEpochMillis":1784429294981,"topSpreadTicks":1,"bid5Volume":118707,"ask5Volume":195891,"bid10Volume":440661,"ask10Volume":388116,"rawPayload":"{\"stream\":\"solusdt@depth@100ms\",\"data\":{\"e\":\"depthUpdate\",\"E\":1784429294989,\"s\":\"SOLUSDT\",\"U\":1609569899,\"u\":1609569899,\"b\":[],\"a\":[[\"76.32000000\",\"95.76000000\"]]}}"}
{"mode":"v9-depth-v5-spsc","workers":4,"sequenceNumber":420,"symbol":"ETHUSDT","exchangeEventTimeMillis":1784429294989,"localReceivedEpochMillis":1784429294981,"topSpreadTicks":18,"bid5Volume":3690,"ask5Volume":3537,"bid10Volume":28957,"ask10Volume":14917,"rawPayload":"{\"stream\":\"ethusdt@depth@100ms\",\"data\":{\"e\":\"depthUpdate\",\"E\":1784429294989,\"s\":\"ETHUSDT\",\"U\":2806164656,\"u\":2806164662,\"b\":[[\"1871.90000000\",\"0.00000000\"],[\"1871.83000000\",\"1.11900000\"],[\"1871.45000000\",\"0.00000000\"],[\"1870.46000000\",\"0.00000000\"]],\"a\":[[\"1872.40000000\",\"1.16180000\"],[\"1872.47000000\",\"0.00000000\"]]}}"}
{"mode":"v9-depth-v5-spsc","workers":4,"sequenceNumber":421,"symbol":"XRPUSDT","exchangeEventTimeMillis":1784429294989,"localReceivedEpochMillis":1784429294981,"topSpreadTicks":0,"bid5Volume":9659400,"ask5Volume":4527600,"bid10Volume":25547200,"ask10Volume":5725500,"rawPayload":"{\"stream\":\"xrpusdt@depth@100ms\",\"data\":{\"e\":\"depthUpdate\",\"E\":1784429294989,\"s\":\"XRPUSDT\",\"U\":752699422,\"u\":752699422,\"b\":[[\"1.09640000\",\"4509.40000000\"]],\"a\":[]}}"}
{"mode":"v9-depth-v5-spsc","workers":4,"sequenceNumber":422,"symbol":"SOLUSDT","exchangeEventTimeMillis":1784429295089,"localReceivedEpochMillis":1784429295080,"topSpreadTicks":1,"bid5Volume":118707,"ask5Volume":195891,"bid10Volume":440661,"ask10Volume":388116,"rawPayload":"{\"stream\":\"solusdt@depth@100ms\",\"data\":{\"e\":\"depthUpdate\",\"E\":1784429295089,\"s\":\"SOLUSDT\",\"U\":1609569900,\"u\":1609569900,\"b\":[],\"a\":[[\"76.26000000\",\"72.56400000\"],[\"76.27000000\",\"14.67300000\"]]}}"}
{"mode":"v9-depth-v5-spsc","workers":4,"sequenceNumber":423,"symbol":"ETHUSDT","exchangeEventTimeMillis":1784429295089,"localReceivedEpochMillis":1784429295080,"topSpreadTicks":18,"bid5Volume":3690,"ask5Volume":3537,"bid10Volume":28957,"ask10Volume":14917,"rawPayload":"{\"stream\":\"ethusdt@depth@100ms\",\"data\":{\"e\":\"depthUpdate\",\"E\":1784429295089,\"s\":\"ETHUSDT\",\"U\":2806164663,\"u\":2806164664,\"b\":[],\"a\":[[\"1872.06000000\",\"1.06890000\"],[\"1872.12000000\",\"0.00000000\"]]}}"}
{"mode":"v9-depth-v5-spsc","workers":4,"sequenceNumber":424,"symbol":"BTCUSDT","exchangeEventTimeMillis":1784429295089,"localReceivedEpochMillis":1784429295080,"topSpreadTicks":268,"bid5Volume":136,"ask5Volume":128,"bid10Volume":290,"ask10Volume":590,"rawPayload":"{\"stream\":\"btcusdt@depth@100ms\",\"data\":{\"e\":\"depthUpdate\",\"E\":1784429295089,\"s\":\"BTCUSDT\",\"U\":3244435390,\"u\":3244435391,\"b\":[],\"a\":[[\"64837.96000000\",\"0.00159000\"],[\"64838.71000000\",\"0.00000000\"]]}}"}
{"mode":"v9-depth-v5-spsc","workers":4,"sequenceNumber":425,"symbol":"SOLUSDT","exchangeEventTimeMillis":1784429295189,"localReceivedEpochMillis":1784429295179,"topSpreadTicks":1,"bid5Volume":136719,"ask5Volume":209289,"bid10Volume":458673,"ask10Volume":387426,"rawPayload":"{\"stream\":\"solusdt@depth@100ms\",\"data\":{\"e\":\"depthUpdate\",\"E\":1784429295189,\"s\":\"SOLUSDT\",\"U\":1609569901,\"u\":1609569903,\"b\":[[\"76.23000000\",\"24.57400000\"]],\"a\":[[\"76.29000000\",\"79.77100000\"],[\"76.30000000\",\"20.13000000\"]]}}"}
{"mode":"v9-depth-v5-spsc","workers":4,"sequenceNumber":426,"symbol":"ETHUSDT","exchangeEventTimeMillis":1784429295189,"localReceivedEpochMillis":1784429295180,"topSpreadTicks":24,"bid5Volume":3668,"ask5Volume":3538,"bid10Volume":28935,"ask10Volume":14873,"rawPayload":"{\"stream\":\"ethusdt@depth@100ms\",\"data\":{\"e\":\"depthUpdate\",\"E\":1784429295189,\"s\":\"ETHUSDT\",\"U\":2806164665,\"u\":2806164674,\"b\":[[\"1871.83000000\",\"0.00000000\"],[\"1871.76000000\",\"1.09600000\"],[\"1871.75000000\",\"0.00000000\"],[\"1871.59000000\",\"0.00000000\"],[\"1871.58000000\",\"1.33670000\"],[\"1871.51000000\",\"1.06900000\"]],\"a\":[[\"1872.00000000\",\"1.06900000\"],[\"1872.06000000\",\"0.00000000\"],[\"1872.33000000\",\"1.11610000\"],[\"1872.40000000\",\"0.00000000\"]]}}"}
{"mode":"v9-depth-v5-spsc","workers":4,"sequenceNumber":427,"symbol":"ETHUSDT","exchangeEventTimeMillis":1784429295389,"localReceivedEpochMillis":1784429295379,"topSpreadTicks":35,"bid5Volume":3669,"ask5Volume":4539,"bid10Volume":29565,"ask10Volume":14896,"rawPayload":"{\"stream\":\"ethusdt@depth@100ms\",\"data\":{\"e\":\"depthUpdate\",\"E\":1784429295389,\"s\":\"ETHUSDT\",\"U\":2806164675,\"u\":2806164680,\"b\":[[\"1871.76000000\",\"0.00000000\"],[\"1871.65000000\",\"1.09780000\"],[\"1871.50000000\",\"0.75000000\"],[\"1870.43000000\",\"1.63970000\"]],\"a\":[[\"1872.23000000\",\"1.13920000\"],[\"1872.33000000\",\"0.00000000\"]]}}"}
{"mode":"v9-depth-v5-spsc","workers":4,"sequenceNumber":428,"symbol":"BTCUSDT","exchangeEventTimeMillis":1784429295489,"localReceivedEpochMillis":1784429295480,"topSpreadTicks":268,"bid5Volume":136,"ask5Volume":128,"bid10Volume":290,"ask10Volume":590,"rawPayload":"{\"stream\":\"btcusdt@depth@100ms\",\"data\":{\"e\":\"depthUpdate\",\"E\":1784429295489,\"s\":\"BTCUSDT\",\"U\":3244435392,\"u\":3244435393,\"b\":[[\"64819.77000000\",\"0.00000000\"],[\"64817.89000000\",\"0.03087000\"]],\"a\":[]}}"}
{"mode":"v9-depth-v5-spsc","workers":4,"sequenceNumber":429,"symbol":"ETHUSDT","exchangeEventTimeMillis":1784429295690,"localReceivedEpochMillis":1784429295679,"topSpreadTicks":35,"bid5Volume":3669,"ask5Volume":4539,"bid10Volume":29730,"ask10Volume":14896,"rawPayload":"{\"stream\":\"ethusdt@depth@100ms\",\"data\":{\"e\":\"depthUpdate\",\"E\":1784429295690,\"s\":\"ETHUSDT\",\"U\":2806164681,\"u\":2806164682,\"b\":[[\"1871.36000000\",\"1.63970000\"],[\"1870.43000000\",\"0.00000000\"]],\"a\":[]}}"}
{"mode":"v9-depth-v5-spsc","workers":4,"sequenceNumber":430,"symbol":"ETHUSDT","exchangeEventTimeMillis":1784429295990,"localReceivedEpochMillis":1784429295980,"topSpreadTicks":35,"bid5Volume":3350,"ask5Volume":4539,"bid10Volume":31204,"ask10Volume":14896,"rawPayload":"{\"stream\":\"ethusdt@depth@100ms\",\"data\":{\"e\":\"depthUpdate\",\"E\":1784429295990,\"s\":\"ETHUSDT\",\"U\":2806164683,\"u\":2806164684,\"b\":[[\"1871.51000000\",\"0.00000000\"],[\"1871.44000000\",\"2.09490000\"]],\"a\":[]}}"}
{"mode":"v9-depth-v5-spsc","workers":4,"sequenceNumber":431,"symbol":"XRPUSDT","exchangeEventTimeMillis":1784429295990,"localReceivedEpochMillis":1784429295980,"topSpreadTicks":0,"bid5Volume":6309100,"ask5Volume":4527600,"bid10Volume":22196900,"ask10Volume":5725500,"rawPayload":"{\"stream\":\"xrpusdt@depth@100ms\",\"data\":{\"e\":\"depthUpdate\",\"E\":1784429295990,\"s\":\"XRPUSDT\",\"U\":752699423,\"u\":752699424,\"b\":[[\"1.09640000\",\"3576.80000000\"],[\"1.09630000\",\"1159.10000000\"]],\"a\":[]}}"}
{"mode":"v9-depth-v5-spsc","workers":4,"sequenceNumber":432,"symbol":"ETHUSDT","exchangeEventTimeMillis":1784429296090,"localReceivedEpochMillis":1784429296081,"topSpreadTicks":35,"bid5Volume":4525,"ask5Volume":4539,"bid10Volume":30454,"ask10Volume":14896,"rawPayload":"{\"stream\":\"ethusdt@depth@100ms\",\"data\":{\"e\":\"depthUpdate\",\"E\":1784429296090,\"s\":\"ETHUSDT\",\"U\":2806164685,\"u\":2806164689,\"b\":[[\"1871.50000000\",\"0.00000000\"],[\"1871.44000000\",\"1.02590000\"],[\"1871.38000000\",\"1.06910000\"]],\"a\":[[\"1872.04000000\",\"1.33630000\"],[\"1872.19000000\",\"0.00000000\"]]}}"}
{"mode":"v9-depth-v5-spsc","workers":4,"sequenceNumber":433,"symbol":"SOLUSDT","exchangeEventTimeMillis":1784429296490,"localReceivedEpochMillis":1784429296481,"topSpreadTicks":1,"bid5Volume":136719,"ask5Volume":209289,"bid10Volume":458673,"ask10Volume":387426,"rawPayload":"{\"stream\":\"solusdt@depth@100ms\",\"data\":{\"e\":\"depthUpdate\",\"E\":1784429296490,\"s\":\"SOLUSDT\",\"U\":1609569904,\"u\":1609569905,\"b\":[[\"76.23000000\",\"18.01200000\"],[\"76.22000000\",\"43.35300000\"]],\"a\":[]}}"}
{"mode":"v9-depth-v5-spsc","workers":4,"sequenceNumber":434,"symbol":"BTCUSDT","exchangeEventTimeMillis":1784429296490,"localReceivedEpochMillis":1784429296481,"topSpreadTicks":268,"bid5Volume":136,"ask5Volume":128,"bid10Volume":290,"ask10Volume":590,"rawPayload":"{\"stream\":\"btcusdt@depth@100ms\",\"data\":{\"e\":\"depthUpdate\",\"E\":1784429296490,\"s\":\"BTCUSDT\",\"U\":3244435394,\"u\":3244435394,\"b\":[],\"a\":[[\"64914.49000000\",\"0.00000000\"]]}}"}
{"mode":"v9-depth-v5-spsc","workers":4,"sequenceNumber":435,"symbol":"BTCUSDT","exchangeEventTimeMillis":1784429296590,"localReceivedEpochMillis":1784429296581,"topSpreadTicks":268,"bid5Volume":136,"ask5Volume":128,"bid10Volume":290,"ask10Volume":590,"rawPayload":"{\"stream\":\"btcusdt@depth@100ms\",\"data\":{\"e\":\"depthUpdate\",\"E\":1784429296590,\"s\":\"BTCUSDT\",\"U\":3244435395,\"u\":3244435395,\"b\":[],\"a\":[[\"64914.49000000\",\"0.00011000\"]]}}"}
{"mode":"v9-depth-v5-spsc","workers":4,"sequenceNumber":436,"symbol":"XRPUSDT","exchangeEventTimeMillis":1784429296990,"localReceivedEpochMillis":1784429296982,"topSpreadTicks":0,"bid5Volume":5507500,"ask5Volume":4527600,"bid10Volume":21395300,"ask10Volume":5725500,"rawPayload":"{\"stream\":\"xrpusdt@depth@100ms\",\"data\":{\"e\":\"depthUpdate\",\"E\":1784429296990,\"s\":\"XRPUSDT\",\"U\":752699425,\"u\":752699426,\"b\":[[\"1.09630000\",\"976.70000000\"],[\"1.09620000\",\"357.50000000\"]],\"a\":[]}}"}
{"mode":"v9-depth-v5-spsc","workers":4,"sequenceNumber":437,"symbol":"SOLUSDT","exchangeEventTimeMillis":1784429297091,"localReceivedEpochMillis":1784429297081,"topSpreadTicks":1,"bid5Volume":136719,"ask5Volume":289809,"bid10Volume":458673,"ask10Volume":759020,"rawPayload":"{\"stream\":\"solusdt@depth@100ms\",\"data\":{\"e\":\"depthUpdate\",\"E\":1784429297091,\"s\":\"SOLUSDT\",\"U\":1609569906,\"u\":1609569911,\"b\":[],\"a\":[[\"76.27000000\",\"64.99800000\"],[\"76.28000000\",\"33.47800000\"],[\"76.30000000\",\"0.00000000\"],[\"76.31000000\",\"0.00000000\"],[\"76.32000000\",\"65.56500000\"]]}}"}
{"mode":"v9-depth-v5-spsc","workers":4,"sequenceNumber":438,"symbol":"SOLUSDT","exchangeEventTimeMillis":1784429297191,"localReceivedEpochMillis":1784429297181,"topSpreadTicks":1,"bid5Volume":136719,"ask5Volume":209289,"bid10Volume":458673,"ask10Volume":425933,"rawPayload":"{\"stream\":\"solusdt@depth@100ms\",\"data\":{\"e\":\"depthUpdate\",\"E\":1784429297191,\"s\":\"SOLUSDT\",\"U\":1609569912,\"u\":1609569915,\"b\":[],\"a\":[[\"76.27000000\",\"14.67300000\"],[\"76.28000000\",\"3.28300000\"],[\"76.30000000\",\"20.13000000\"]]}}"}
{"mode":"v9-depth-v5-spsc","workers":4,"sequenceNumber":439,"symbol":"BNBUSDT","exchangeEventTimeMillis":1784429297491,"localReceivedEpochMillis":1784429297482,"topSpreadTicks":5,"bid5Volume":4623,"ask5Volume":7622,"bid10Volume":21058,"ask10Volume":263593,"rawPayload":"{\"stream\":\"bnbusdt@depth@100ms\",\"data\":{\"e\":\"depthUpdate\",\"E\":1784429297491,\"s\":\"BNBUSDT\",\"U\":1236328024,\"u\":1236328024,\"b\":[[\"570.65000000\",\"0.00000000\"],[\"570.64000000\",\"1.73700000\"]],\"a\":[]}}"}
{"mode":"v9-depth-v5-spsc","workers":4,"sequenceNumber":440,"symbol":"ETHUSDT","exchangeEventTimeMillis":1784429297491,"localReceivedEpochMillis":1784429297482,"topSpreadTicks":23,"bid5Volume":4525,"ask5Volume":3528,"bid10Volume":29101,"ask10Volume":14887,"rawPayload":"{\"stream\":\"ethusdt@depth@100ms\",\"data\":{\"e\":\"depthUpdate\",\"E\":1784429297491,\"s\":\"ETHUSDT\",\"U\":2806164690,\"u\":2806164697,\"b\":[[\"1871.57000000\",\"0.00000000\"],[\"1871.44000000\",\"0.00000000\"],[\"1871.43000000\",\"0.13890000\"],[\"1871.37000000\",\"1.02590000\"],[\"1871.27000000\",\"0.00000000\"],[\"1871.13000000\",\"1.47500000\"]],\"a\":[[\"1871.88000000\",\"0.96640000\"],[\"1871.89000000\",\"1.05990000\"],[\"1872.00000000\",\"0.00000000\"],[\"1872.01000000\",\"0.00000000\"],[\"1872.10000000\",\"0.13880000\"],[\"1872.24000000\",\"0.00000000\"],[\"1872.40000000\",\"1.47400000\"],[\"1872.54000000\",\"0.00000000\"]]}}"}
{"mode":"v9-depth-v5-spsc","workers":4,"sequenceNumber":441,"symbol":"SOLUSDT","exchangeEventTimeMillis":1784429297591,"localReceivedEpochMillis":1784429297580,"topSpreadTicks":1,"bid5Volume":185122,"ask5Volume":191314,"bid10Volume":721177,"ask10Volume":407958,"rawPayload":"{\"stream\":\"solusdt@depth@100ms\",\"data\":{\"e\":\"depthUpdate\",\"E\":1784429297591,\"s\":\"SOLUSDT\",\"U\":1609569916,\"u\":1609569917,\"b\":[[\"76.23000000\",\"0.00000000\"]],\"a\":[[\"76.26000000\",\"54.58900000\"]]}}"}
{"mode":"v9-depth-v5-spsc","workers":4,"sequenceNumber":442,"symbol":"ETHUSDT","exchangeEventTimeMillis":1784429297591,"localReceivedEpochMillis":1784429297581,"topSpreadTicks":24,"bid5Volume":4525,"ask5Volume":3701,"bid10Volume":29679,"ask10Volume":15560,"rawPayload":"{\"stream\":\"ethusdt@depth@100ms\",\"data\":{\"e\":\"depthUpdate\",\"E\":1784429297591,\"s\":\"ETHUSDT\",\"U\":2806164698,\"u\":2806164699,\"b\":[[\"1871.37000000\",\"0.00000000\"]],\"a\":[[\"1871.88000000\",\"0.00000000\"]]}}"}
{"mode":"v9-depth-v5-spsc","workers":4,"sequenceNumber":443,"symbol":"BNBUSDT","exchangeEventTimeMillis":1784429297591,"localReceivedEpochMillis":1784429297583,"topSpreadTicks":5,"bid5Volume":3783,"ask5Volume":6096,"bid10Volume":24370,"ask10Volume":264558,"rawPayload":"{\"stream\":\"bnbusdt@depth@100ms\",\"data\":{\"e\":\"depthUpdate\",\"E\":1784429297591,\"s\":\"BNBUSDT\",\"U\":1236328025,\"u\":1236328026,\"b\":[[\"570.64000000\",\"0.00000000\"]],\"a\":[[\"570.93000000\",\"0.00000000\"]]}}"}
{"mode":"v9-depth-v5-spsc","workers":4,"sequenceNumber":444,"symbol":"BTCUSDT","exchangeEventTimeMillis":1784429297591,"localReceivedEpochMillis":1784429297583,"topSpreadTicks":420,"bid5Volume":136,"ask5Volume":101,"bid10Volume":290,"ask10Volume":565,"rawPayload":"{\"stream\":\"btcusdt@depth@100ms\",\"data\":{\"e\":\"depthUpdate\",\"E\":1784429297591,\"s\":\"BTCUSDT\",\"U\":3244435396,\"u\":3244435397,\"b\":[[\"64808.11000000\",\"0.00000000\"]],\"a\":[[\"64824.30000000\",\"0.00000000\"]]}}"}
{"mode":"v9-depth-v5-spsc","workers":4,"sequenceNumber":445,"symbol":"XRPUSDT","exchangeEventTimeMillis":1784429297591,"localReceivedEpochMillis":1784429297583,"topSpreadTicks":0,"bid5Volume":7431700,"ask5Volume":2778900,"bid10Volume":23319500,"ask10Volume":3976800,"rawPayload":"{\"stream\":\"xrpusdt@depth@100ms\",\"data\":{\"e\":\"depthUpdate\",\"E\":1784429297591,\"s\":\"XRPUSDT\",\"U\":752699427,\"u\":752699428,\"b\":[[\"1.09640000\",\"2281.70000000\"]],\"a\":[[\"1.09670000\",\"2463.60000000\"]]}}"}
{"mode":"v9-depth-v5-spsc","workers":4,"sequenceNumber":446,"symbol":"SOLUSDT","exchangeEventTimeMillis":1784429297691,"localReceivedEpochMillis":1784429297681,"topSpreadTicks":1,"bid5Volume":118706,"ask5Volume":177916,"bid10Volume":433812,"ask10Volume":370618,"rawPayload":"{\"stream\":\"solusdt@depth@100ms\",\"data\":{\"e\":\"depthUpdate\",\"E\":1784429297691,\"s\":\"SOLUSDT\",\"U\":1609569918,\"u\":1609569924,\"b\":[[\"76.23000000\",\"6.56100000\"],[\"76.22000000\",\"36.79100000\"],[\"76.12000000\",\"10.88000000\"]],\"a\":[[\"76.29000000\",\"66.37300000\"],[\"76.30000000\",\"34.69500000\"],[\"76.31000000\",\"30.19500000\"],[\"76.32000000\",\"95.76000000\"]]}}"}
{"mode":"v9-depth-v5-spsc","workers":4,"sequenceNumber":447,"symbol":"XRPUSDT","exchangeEventTimeMillis":1784429297691,"localReceivedEpochMillis":1784429297681,"topSpreadTicks":2,"bid5Volume":7431700,"ask5Volume":403700,"bid10Volume":23319500,"ask10Volume":1513200,"rawPayload":"{\"stream\":\"xrpusdt@depth@100ms\",\"data\":{\"e\":\"depthUpdate\",\"E\":1784429297691,\"s\":\"XRPUSDT\",\"U\":752699429,\"u\":752699430,\"b\":[],\"a\":[[\"1.09690000\",\"3051.20000000\"],[\"1.09700000\",\"0.00000000\"]]}}"}
{"mode":"v9-depth-v5-spsc","workers":4,"sequenceNumber":448,"symbol":"ETHUSDT","exchangeEventTimeMillis":1784429297791,"localReceivedEpochMillis":1784429297781,"topSpreadTicks":24,"bid5Volume":4525,"ask5Volume":3701,"bid10Volume":29515,"ask10Volume":15560,"rawPayload":"{\"stream\":\"ethusdt@depth@100ms\",\"data\":{\"e\":\"depthUpdate\",\"E\":1784429297791,\"s\":\"ETHUSDT\",\"U\":2806164700,\"u\":2806164701,\"b\":[[\"1871.36000000\",\"0.00000000\"],[\"1870.56000000\",\"1.63970000\"]],\"a\":[]}}"}
{"mode":"v9-depth-v5-spsc","workers":4,"sequenceNumber":449,"symbol":"SOLUSDT","exchangeEventTimeMillis":1784429297891,"localReceivedEpochMillis":1784429297882,"topSpreadTicks":1,"bid5Volume":88511,"ask5Volume":177916,"bid10Volume":422932,"ask10Volume":370618,"rawPayload":"{\"stream\":\"solusdt@depth@100ms\",\"data\":{\"e\":\"depthUpdate\",\"E\":1784429297891,\"s\":\"SOLUSDT\",\"U\":1609569925,\"u\":1609569926,\"b\":[[\"76.21000000\",\"0.10000000\"],[\"76.17000000\",\"30.19500000\"]],\"a\":[]}}"}
{"mode":"v9-depth-v5-spsc","workers":4,"sequenceNumber":450,"symbol":"BTCUSDT","exchangeEventTimeMillis":1784429297891,"localReceivedEpochMillis":1784429297883,"topSpreadTicks":420,"bid5Volume":136,"ask5Volume":101,"bid10Volume":290,"ask10Volume":565,"rawPayload":"{\"stream\":\"btcusdt@depth@100ms\",\"data\":{\"e\":\"depthUpdate\",\"E\":1784429297891,\"s\":\"BTCUSDT\",\"U\":3244435398,\"u\":3244435399,\"b\":[[\"64817.89000000\",\"0.00000000\"],[\"64815.90000000\",\"0.03087000\"]],\"a\":[]}}"}
{"mode":"v9-depth-v5-spsc","workers":4,"sequenceNumber":451,"symbol":"XRPUSDT","exchangeEventTimeMillis":1784429297891,"localReceivedEpochMillis":1784429297883,"topSpreadTicks":2,"bid5Volume":8408600,"ask5Volume":403700,"bid10Volume":24296400,"ask10Volume":1513200,"rawPayload":"{\"stream\":\"xrpusdt@depth@100ms\",\"data\":{\"e\":\"depthUpdate\",\"E\":1784429297891,\"s\":\"XRPUSDT\",\"U\":752699431,\"u\":752699432,\"b\":[[\"1.09640000\",\"0.00000000\"],[\"1.09630000\",\"3258.60000000\"]],\"a\":[]}}"}
{"mode":"v9-depth-v5-spsc","workers":4,"sequenceNumber":452,"symbol":"ETHUSDT","exchangeEventTimeMillis":1784429297891,"localReceivedEpochMillis":1784429297883,"topSpreadTicks":24,"bid5Volume":5595,"ask5Volume":3701,"bid10Volume":31155,"ask10Volume":15560,"rawPayload":"{\"stream\":\"ethusdt@depth@100ms\",\"data\":{\"e\":\"depthUpdate\",\"E\":1784429297891,\"s\":\"ETHUSDT\",\"U\":2806164702,\"u\":2806164707,\"b\":[[\"1871.58000000\",\"0.00000000\"],[\"1871.43000000\",\"1.47570000\"],[\"1870.98000000\",\"0.00000000\"],[\"1870.96000000\",\"0.00000000\"],[\"1870.67000000\",\"1.09310000\"],[\"1870.18000000\",\"1.63970000\"]],\"a\":[]}}"}
{"mode":"v9-depth-v5-spsc","workers":4,"sequenceNumber":453,"symbol":"SOLUSDT","exchangeEventTimeMillis":1784429298191,"localReceivedEpochMillis":1784429298182,"topSpreadTicks":1,"bid5Volume":88511,"ask5Volume":228241,"bid10Volume":422932,"ask10Volume":370618,"rawPayload":"{\"stream\":\"solusdt@depth@100ms\",\"data\":{\"e\":\"depthUpdate\",\"E\":1784429298191,\"s\":\"SOLUSDT\",\"U\":1609569927,\"u\":1609569930,\"b\":[],\"a\":[[\"76.28000000\",\"53.60800000\"],[\"76.30000000\",\"14.56500000\"],[\"76.32000000\",\"65.56500000\"]]}}"}
{"mode":"v9-depth-v5-spsc","workers":4,"sequenceNumber":454,"symbol":"BTCUSDT","exchangeEventTimeMillis":1784429298191,"localReceivedEpochMillis":1784429298182,"topSpreadTicks":420,"bid5Volume":134,"ask5Volume":101,"bid10Volume":458,"ask10Volume":565,"rawPayload":"{\"stream\":\"btcusdt@depth@100ms\",\"data\":{\"e\":\"depthUpdate\",\"E\":1784429298191,\"s\":\"BTCUSDT\",\"U\":3244435400,\"u\":3244435403,\"b\":[[\"64819.08000000\",\"0.00000000\"],[\"64815.90000000\",\"0.00000000\"],[\"64813.50000000\",\"0.03087000\"]],\"a\":[[\"81072.08000000\",\"0.00060000\"]]}}"}
{"mode":"v9-depth-v5-spsc","workers":4,"sequenceNumber":455,"symbol":"ETHUSDT","exchangeEventTimeMillis":1784429298191,"localReceivedEpochMillis":1784429298182,"topSpreadTicks":23,"bid5Volume":5595,"ask5Volume":3701,"bid10Volume":27868,"ask10Volume":15560,"rawPayload":"{\"stream\":\"ethusdt@depth@100ms\",\"data\":{\"e\":\"depthUpdate\",\"E\":1784429298191,\"s\":\"ETHUSDT\",\"U\":2806164708,\"u\":2806164726,\"b\":[[\"1871.38000000\",\"0.00000000\"],[\"1871.31000000\",\"0.00000000\"],[\"1871.29000000\",\"0.00000000\"],[\"1871.24000000\",\"1.06910000\"],[\"1871.19000000\",\"0.00000000\"],[\"1871.14000000\",\"17.43570000\"],[\"1870.98000000\",\"1.60370000\"],[\"1864.42000000\",\"0.00000000\"],[\"1864.37000000\",\"0.00000000\"],[\"1864.26000000\",\"0.00000000\"],[\"1863.98000000\",\"0.33050000\"]],\"a\":[[\"1871.88000000\",\"1.33640000\"],[\"1872.04000000\",\"0.00000000\"],[\"1872.35000000\",\"1.63970000\"],[\"1873.24000000\",\"0.00000000\"],[\"1873.57000000\",\"0.00000000\"],[\"1879.33000000\",\"7.26400000\"],[\"1880.67000000\",\"0.00000000\"]]}}"}
{"mode":"v9-depth-v5-spsc","workers":4,"sequenceNumber":456,"symbol":"ETHUSDT","exchangeEventTimeMillis":1784429298291,"localReceivedEpochMillis":1784429298282,"topSpreadTicks":23,"bid5Volume":5687,"ask5Volume":5311,"bid10Volume":28932,"ask10Volume":17170,"rawPayload":"{\"stream\":\"ethusdt@depth@100ms\",\"data\":{\"e\":\"depthUpdate\",\"E\":1784429298291,\"s\":\"ETHUSDT\",\"U\":2806164727,\"u\":2806164730,\"b\":[[\"1871.60000000\",\"0.00000000\"],[\"1871.29000000\",\"1.06910000\"],[\"1871.24000000\",\"0.00000000\"]],\"a\":[[\"1872.16000000\",\"0.00000000\"]]}}"}
{"mode":"v9-depth-v5-spsc","workers":4,"sequenceNumber":457,"symbol":"ETHUSDT","exchangeEventTimeMillis":1784429298391,"localReceivedEpochMillis":1784429298382,"topSpreadTicks":23,"bid5Volume":5687,"ask5Volume":5311,"bid10Volume":28932,"ask10Volume":17170,"rawPayload":"{\"stream\":\"ethusdt@depth@100ms\",\"data\":{\"e\":\"depthUpdate\",\"E\":1784429298391,\"s\":\"ETHUSDT\",\"U\":2806164731,\"u\":2806164733,\"b\":[[\"1863.06000000\",\"9.23250000\"]],\"a\":[[\"1879.28000000\",\"7.24320000\"],[\"1880.61000000\",\"0.00000000\"]]}}"}
{"mode":"v9-depth-v5-spsc","workers":4,"sequenceNumber":458,"symbol":"SOLUSDT","exchangeEventTimeMillis":1784429298591,"localReceivedEpochMillis":1784429298583,"topSpreadTicks":1,"bid5Volume":88511,"ask5Volume":228241,"bid10Volume":422932,"ask10Volume":370618,"rawPayload":"{\"stream\":\"solusdt@depth@100ms\",\"data\":{\"e\":\"depthUpdate\",\"E\":1784429298591,\"s\":\"SOLUSDT\",\"U\":1609569931,\"u\":1609569931,\"b\":[[\"76.13000000\",\"6.16700000\"]],\"a\":[]}}"}
{"mode":"v9-depth-v5-spsc","workers":4,"sequenceNumber":459,"symbol":"ETHUSDT","exchangeEventTimeMillis":1784429298591,"localReceivedEpochMillis":1784429298583,"topSpreadTicks":23,"bid5Volume":5595,"ask5Volume":3701,"bid10Volume":27358,"ask10Volume":15560,"rawPayload":"{\"stream\":\"ethusdt@depth@100ms\",\"data\":{\"e\":\"depthUpdate\",\"E\":1784429298591,\"s\":\"ETHUSDT\",\"U\":2806164734,\"u\":2806164740,\"b\":[[\"1871.51000000\",\"0.02970000\"],[\"1871.23000000\",\"1.63970000\"],[\"1871.05000000\",\"1.09310000\"],[\"1870.67000000\",\"0.00000000\"],[\"1870.18000000\",\"0.00000000\"],[\"1862.99000000\",\"9.19090000\"]],\"a\":[[\"1872.06000000\",\"0.02960000\"]]}}"}
{"mode":"v9-depth-v5-spsc","workers":4,"sequenceNumber":460,"symbol":"SOLUSDT","exchangeEventTimeMillis":1784429298792,"localReceivedEpochMillis":1784429298783,"topSpreadTicks":1,"bid5Volume":107325,"ask5Volume":261557,"bid10Volume":441746,"ask10Volume":488266,"rawPayload":"{\"stream\":\"solusdt@depth@100ms\",\"data\":{\"e\":\"depthUpdate\",\"E\":1784429298792,\"s\":\"SOLUSDT\",\"U\":1609569932,\"u\":1609569935,\"b\":[[\"76.23000000\",\"25.37500000\"]],\"a\":[[\"76.27000000\",\"34.11000000\"],[\"76.29000000\",\"80.25200000\"],[\"76.30000000\",\"0.00000000\"]]}}"}
{"mode":"v9-depth-v5-spsc","workers":4,"sequenceNumber":461,"symbol":"BTCUSDT","exchangeEventTimeMillis":1784429298992,"localReceivedEpochMillis":1784429298983,"topSpreadTicks":265,"bid5Volume":134,"ask5Volume":128,"bid10Volume":280,"ask10Volume":590,"rawPayload":"{\"stream\":\"btcusdt@depth@100ms\",\"data\":{\"e\":\"depthUpdate\",\"E\":1784429298992,\"s\":\"BTCUSDT\",\"U\":3244435404,\"u\":3244435405,\"b\":[[\"64805.79000000\",\"0.03086000\"]],\"a\":[[\"64824.27000000\",\"0.02872000\"]]}}"}
{"mode":"v9-depth-v5-spsc","workers":4,"sequenceNumber":462,"symbol":"BNBUSDT","exchangeEventTimeMillis":1784429299092,"localReceivedEpochMillis":1784429299083,"topSpreadTicks":5,"bid5Volume":3783,"ask5Volume":6096,"bid10Volume":24370,"ask10Volume":264558,"rawPayload":"{\"stream\":\"bnbusdt@depth@100ms\",\"data\":{\"e\":\"depthUpdate\",\"E\":1784429299092,\"s\":\"BNBUSDT\",\"U\":1236328027,\"u\":1236328027,\"b\":[[\"569.34000000\",\"4.86400000\"],[\"569.33000000\",\"0.00400000\"]],\"a\":[]}}"}
{"mode":"v9-depth-v5-spsc","workers":4,"sequenceNumber":463,"symbol":"SOLUSDT","exchangeEventTimeMillis":1784429299392,"localReceivedEpochMillis":1784429299383,"topSpreadTicks":1,"bid5Volume":137520,"ask5Volume":291752,"bid10Volume":447913,"ask10Volume":760963,"rawPayload":"{\"stream\":\"solusdt@depth@100ms\",\"data\":{\"e\":\"depthUpdate\",\"E\":1784429299392,\"s\":\"SOLUSDT\",\"U\":1609569936,\"u\":1609569941,\"b\":[[\"76.21000000\",\"30.29500000\"],[\"76.17000000\",\"0.00000000\"]],\"a\":[[\"76.26000000\",\"104.91400000\"],[\"76.28000000\",\"33.47800000\"],[\"76.31000000\",\"0.00000000\"]]}}"}
{"mode":"v9-depth-v5-spsc","workers":4,"sequenceNumber":464,"symbol":"BTCUSDT","exchangeEventTimeMillis":1784429299392,"localReceivedEpochMillis":1784429299383,"topSpreadTicks":265,"bid5Volume":134,"ask5Volume":128,"bid10Volume":280,"ask10Volume":590,"rawPayload":"{\"stream\":\"btcusdt@depth@100ms\",\"data\":{\"e\":\"depthUpdate\",\"E\":1784429299392,\"s\":\"BTCUSDT\",\"U\":3244435406,\"u\":3244435407,\"b\":[[\"64815.24000000\",\"0.03087000\"],[\"64813.50000000\",\"0.00000000\"]],\"a\":[]}}"}
{"mode":"v9-depth-v5-spsc","workers":4,"sequenceNumber":465,"symbol":"BTCUSDT","exchangeEventTimeMillis":1784429299492,"localReceivedEpochMillis":1784429299483,"topSpreadTicks":265,"bid5Volume":117,"ask5Volume":128,"bid10Volume":458,"ask10Volume":590,"rawPayload":"{\"stream\":\"btcusdt@depth@100ms\",\"data\":{\"e\":\"depthUpdate\",\"E\":1784429299492,\"s\":\"BTCUSDT\",\"U\":3244435408,\"u\":3244435410,\"b\":[[\"64815.24000000\",\"0.00000000\"],[\"64813.08000000\",\"0.00000000\"]],\"a\":[]}}"}
{"mode":"v9-depth-v5-spsc","workers":4,"sequenceNumber":466,"symbol":"ETHUSDT","exchangeEventTimeMillis":1784429299492,"localReceivedEpochMillis":1784429299483,"topSpreadTicks":23,"bid5Volume":5556,"ask5Volume":3701,"bid10Volume":27259,"ask10Volume":15560,"rawPayload":"{\"stream\":\"ethusdt@depth@100ms\",\"data\":{\"e\":\"depthUpdate\",\"E\":1784429299492,\"s\":\"ETHUSDT\",\"U\":2806164741,\"u\":2806164744,\"b\":[[\"1871.36000000\",\"1.03090000\"],[\"1871.23000000\",\"0.00000000\"],[\"1871.05000000\",\"0.00000000\"],[\"1870.10000000\",\"1.63970000\"]],\"a\":[]}}"}
{"mode":"v9-depth-v5-spsc","workers":4,"sequenceNumber":467,"symbol":"BNBUSDT","exchangeEventTimeMillis":1784429299592,"localReceivedEpochMillis":1784429299583,"topSpreadTicks":5,"bid5Volume":3783,"ask5Volume":6096,"bid10Volume":24370,"ask10Volume":264558,"rawPayload":"{\"stream\":\"bnbusdt@depth@100ms\",\"data\":{\"e\":\"depthUpdate\",\"E\":1784429299592,\"s\":\"BNBUSDT\",\"U\":1236328028,\"u\":1236328035,\"b\":[[\"570.13000000\",\"0.00000000\"],[\"570.12000000\",\"3.39500000\"],[\"569.79000000\",\"0.00000000\"],[\"569.78000000\",\"5.04900000\"],[\"569.44000000\",\"0.00000000\"],[\"569.43000000\",\"8.67400000\"],[\"569.10000000\",\"0.00000000\"],[\"569.09000000\",\"19.72800000\"]],\"a\":[[\"571.50000000\",\"3.30600000\"],[\"571.51000000\",\"0.00000000\"],[\"571.84000000\",\"5.04600000\"],[\"571.85000000\",\"0.00000000\"],[\"572.18000000\",\"8.42800000\"],[\"572.19000000\",\"0.00000000\"],[\"572.53000000\",\"20.45700000\"],[\"572.54000000\",\"0.00000000\"]]}}"}
{"mode":"v9-depth-v5-spsc","workers":4,"sequenceNumber":468,"symbol":"BTCUSDT","exchangeEventTimeMillis":1784429299592,"localReceivedEpochMillis":1784429299583,"topSpreadTicks":265,"bid5Volume":134,"ask5Volume":128,"bid10Volume":280,"ask10Volume":590,"rawPayload":"{\"stream\":\"btcusdt@depth@100ms\",\"data\":{\"e\":\"depthUpdate\",\"E\":1784429299592,\"s\":\"BTCUSDT\",\"U\":3244435411,\"u\":3244435411,\"b\":[[\"64814.83000000\",\"0.03087000\"]],\"a\":[]}}"}
{"mode":"v9-depth-v5-spsc","workers":4,"sequenceNumber":469,"symbol":"SOLUSDT","exchangeEventTimeMillis":1784429299792,"localReceivedEpochMillis":1784429300441,"topSpreadTicks":1,"bid5Volume":137521,"ask5Volume":291752,"bid10Volume":447914,"ask10Volume":760963,"rawPayload":"{\"stream\":\"solusdt@depth@100ms\",\"data\":{\"e\":\"depthUpdate\",\"E\":1784429299792,\"s\":\"SOLUSDT\",\"U\":1609569942,\"u\":1609569943,\"b\":[[\"76.23000000\",\"18.81400000\"],[\"76.22000000\",\"43.35300000\"]],\"a\":[]}}"}
{"mode":"v9-depth-v5-spsc","workers":4,"sequenceNumber":470,"symbol":"BTCUSDT","exchangeEventTimeMillis":1784429299792,"localReceivedEpochMillis":1784429300441,"topSpreadTicks":265,"bid5Volume":134,"ask5Volume":128,"bid10Volume":280,"ask10Volume":590,"rawPayload":"{\"stream\":\"btcusdt@depth@100ms\",\"data\":{\"e\":\"depthUpdate\",\"E\":1784429299792,\"s\":\"BTCUSDT\",\"U\":3244435412,\"u\":3244435412,\"b\":[],\"a\":[[\"81072.08000000\",\"0.00060000\"]]}}"}
{"mode":"v9-depth-v5-spsc","workers":4,"sequenceNumber":471,"symbol":"ETHUSDT","exchangeEventTimeMillis":1784429299892,"localReceivedEpochMillis":1784429300441,"topSpreadTicks":23,"bid5Volume":5556,"ask5Volume":3701,"bid10Volume":27295,"ask10Volume":15560,"rawPayload":"{\"stream\":\"ethusdt@depth@100ms\",\"data\":{\"e\":\"depthUpdate\",\"E\":1784429299892,\"s\":\"ETHUSDT\",\"U\":2806164745,\"u\":2806164746,\"b\":[[\"1871.00000000\",\"1.63970000\"],[\"1870.10000000\",\"0.00000000\"]],\"a\":[]}}"}
{"mode":"v9-depth-v5-spsc","workers":4,"sequenceNumber":472,"symbol":"BTCUSDT","exchangeEventTimeMillis":1784429300093,"localReceivedEpochMillis":1784429300441,"topSpreadTicks":265,"bid5Volume":134,"ask5Volume":128,"bid10Volume":280,"ask10Volume":590,"rawPayload":"{\"stream\":\"btcusdt@depth@100ms\",\"data\":{\"e\":\"depthUpdate\",\"E\":1784429300093,\"s\":\"BTCUSDT\",\"U\":3244435413,\"u\":3244435420,\"b\":[[\"64749.95000000\",\"0.00000000\"],[\"64748.54000000\",\"0.05832000\"],[\"64711.05000000\",\"0.00000000\"],[\"64709.64000000\",\"0.08812000\"],[\"64672.16000000\",\"0.00000000\"],[\"64670.75000000\",\"0.17331000\"],[\"64594.36000000\",\"0.00000000\"],[\"64592.96000000\",\"0.40717000\"]],\"a\":[[\"64904.07000000\",\"0.06043000\"],[\"64905.48000000\",\"0.00000000\"],[\"64942.97000000\",\"0.09239000\"],[\"64944.38000000\",\"0.00000000\"],[\"64981.86000000\",\"0.17644000\"],[\"64983.28000000\",\"0.00000000\"],[\"65059.65000000\",\"0.42827000\"],[\"65061.07000000\",\"0.00000000\"]]}}"}
{"mode":"v9-depth-v5-spsc","workers":4,"sequenceNumber":473,"symbol":"ETHUSDT","exchangeEventTimeMillis":1784429300093,"localReceivedEpochMillis":1784429300441,"topSpreadTicks":23,"bid5Volume":5556,"ask5Volume":3701,"bid10Volume":27295,"ask10Volume":15560,"rawPayload":"{\"stream\":\"ethusdt@depth@100ms\",\"data\":{\"e\":\"depthUpdate\",\"E\":1784429300093,\"s\":\"ETHUSDT\",\"U\":2806164747,\"u\":2806164747,\"b\":[[\"1870.96000000\",\"1.09310000\"]],\"a\":[]}}"}
{"mode":"v9-depth-v5-spsc","workers":4,"sequenceNumber":474,"symbol":"BTCUSDT","exchangeEventTimeMillis":1784429300393,"localReceivedEpochMillis":1784429300486,"topSpreadTicks":265,"bid5Volume":134,"ask5Volume":128,"bid10Volume":280,"ask10Volume":590,"rawPayload":"{\"stream\":\"btcusdt@depth@100ms\",\"data\":{\"e\":\"depthUpdate\",\"E\":1784429300393,\"s\":\"BTCUSDT\",\"U\":3244435421,\"u\":3244435422,\"b\":[],\"a\":[[\"64914.49000000\",\"0.00011000\"]]}}"}
{"mode":"v9-depth-v5-spsc","workers":4,"sequenceNumber":475,"symbol":"BTCUSDT","exchangeEventTimeMillis":1784429300693,"localReceivedEpochMillis":1784429300684,"topSpreadTicks":265,"bid5Volume":134,"ask5Volume":128,"bid10Volume":280,"ask10Volume":590,"rawPayload":"{\"stream\":\"btcusdt@depth@100ms\",\"data\":{\"e\":\"depthUpdate\",\"E\":1784429300693,\"s\":\"BTCUSDT\",\"U\":3244435423,\"u\":3244435423,\"b\":[],\"a\":[[\"81072.08000000\",\"0.00075000\"]]}}"}
{"mode":"v9-depth-v5-spsc","workers":4,"sequenceNumber":476,"symbol":"SOLUSDT","exchangeEventTimeMillis":1784429300793,"localReceivedEpochMillis":1784429300784,"topSpreadTicks":1,"bid5Volume":137520,"ask5Volume":291752,"bid10Volume":447913,"ask10Volume":1033198,"rawPayload":"{\"stream\":\"solusdt@depth@100ms\",\"data\":{\"e\":\"depthUpdate\",\"E\":1784429300793,\"s\":\"SOLUSDT\",\"U\":1609569944,\"u\":1609569951,\"b\":[[\"76.23000000\",\"25.37500000\"],[\"76.22000000\",\"36.79100000\"],[\"76.11000000\",\"319.30900000\"],[\"76.10000000\",\"335.18100000\"],[\"76.06000000\",\"242.89800000\"],[\"76.05000000\",\"337.95300000\"],[\"75.97000000\",\"632.74800000\"],[\"75.96000000\",\"0.00000000\"]],\"a\":[[\"76.34000000\",\"0.00000000\"],[\"76.35000000\",\"117.82800000\"],[\"76.38000000\",\"275.20700000\"],[\"76.39000000\",\"312.69800000\"],[\"76.43000000\",\"272.84000000\"],[\"76.44000000\",\"329.56700000\"]]}}"}
{"mode":"v9-depth-v5-spsc","workers":4,"sequenceNumber":477,"symbol":"SOLUSDT","exchangeEventTimeMillis":1784429300893,"localReceivedEpochMillis":1784429300884,"topSpreadTicks":1,"bid5Volume":199847,"ask5Volume":214288,"bid10Volume":775208,"ask10Volume":763574,"rawPayload":"{\"stream\":\"solusdt@depth@100ms\",\"data\":{\"e\":\"depthUpdate\",\"E\":1784429300893,\"s\":\"SOLUSDT\",\"U\":1609569952,\"u\":1609569971,\"b\":[[\"76.24000000\",\"0.00000000\"],[\"76.23000000\",\"33.24900000\"],[\"76.22000000\",\"36.79100000\"],[\"76.21000000\",\"30.29500000\"],[\"76.20000000\",\"19.97100000\"],[\"76.19000000\",\"79.54100000\"],[\"76.13000000\",\"0.00000000\"],[\"76.12000000\",\"18.24100000\"]],\"a\":[[\"76.24000000\",\"6.56200000\"],[\"76.25000000\",\"33.36500000\"],[\"76.26000000\",\"118.03900000\"],[\"76.27000000\",\"22.84400000\"],[\"76.28000000\",\"33.47800000\"],[\"76.29000000\",\"80.07500000\"],[\"76.53000000\",\"142.19100000\"]]}}"}
{"mode":"v9-depth-v5-spsc","workers":4,"sequenceNumber":478,"symbol":"ETHUSDT","exchangeEventTimeMillis":1784429300893,"localReceivedEpochMillis":1784429300884,"topSpreadTicks":35,"bid5Volume":5554,"ask5Volume":3756,"bid10Volume":27293,"ask10Volume":15615,"rawPayload":"{\"stream\":\"ethusdt@depth@100ms\",\"data\":{\"e\":\"depthUpdate\",\"E\":1784429300893,\"s\":\"ETHUSDT\",\"U\":2806164748,\"u\":2806164755,\"b\":[[\"1871.65000000\",\"0.00000000\"],[\"1871.53000000\",\"1.09520000\"],[\"1868.63000000\",\"0.00000000\"],[\"1868.41000000\",\"2.95960000\"],[\"1865.26000000\",\"26.82460000\"],[\"1865.04000000\",\"13.72160000\"]],\"a\":[[\"1872.11000000\",\"1.19400000\"],[\"1872.23000000\",\"0.00000000\"],[\"1873.28000000\",\"0.37650000\"],[\"1875.16000000\",\"3.02900000\"],[\"1875.38000000\",\"0.00000000\"]]}}"}
{"mode":"v9-depth-v5-spsc","workers":4,"sequenceNumber":479,"symbol":"XRPUSDT","exchangeEventTimeMillis":1784429300893,"localReceivedEpochMillis":1784429300884,"topSpreadTicks":2,"bid5Volume":8408600,"ask5Volume":403700,"bid10Volume":24296400,"ask10Volume":1513200,"rawPayload":"{\"stream\":\"xrpusdt@depth@100ms\",\"data\":{\"e\":\"depthUpdate\",\"E\":1784429300893,\"s\":\"XRPUSDT\",\"U\":752699433,\"u\":752699433,\"b\":[],\"a\":[[\"1.09710000\",\"4590.30000000\"],[\"1.09720000\",\"0.00000000\"]]}}"}
{"mode":"v9-depth-v5-spsc","workers":4,"sequenceNumber":480,"symbol":"SOLUSDT","exchangeEventTimeMillis":1784429300993,"localReceivedEpochMillis":1784429300984,"topSpreadTicks":1,"bid5Volume":206409,"ask5Volume":214288,"bid10Volume":781770,"ask10Volume":763574,"rawPayload":"{\"stream\":\"solusdt@depth@100ms\",\"data\":{\"e\":\"depthUpdate\",\"E\":1784429300993,\"s\":\"SOLUSDT\",\"U\":1609569972,\"u\":1609569972,\"b\":[[\"76.22000000\",\"43.35300000\"]],\"a\":[]}}"}
{"mode":"v9-depth-v5-spsc","workers":4,"sequenceNumber":481,"symbol":"ETHUSDT","exchangeEventTimeMillis":1784429300993,"localReceivedEpochMillis":1784429300984,"topSpreadTicks":35,"bid5Volume":5554,"ask5Volume":3756,"bid10Volume":27293,"ask10Volume":15615,"rawPayload":"{\"stream\":\"ethusdt@depth@100ms\",\"data\":{\"e\":\"depthUpdate\",\"E\":1784429300993,\"s\":\"ETHUSDT\",\"U\":2806164756,\"u\":2806164759,\"b\":[[\"1869.75000000\",\"0.00000000\"],[\"1869.54000000\",\"2.05300000\"],[\"1867.51000000\",\"0.00000000\"],[\"1867.29000000\",\"5.99790000\"]],\"a\":[[\"1874.04000000\",\"2.04860000\"],[\"1874.26000000\",\"5.33920000\"],[\"1876.28000000\",\"6.30890000\"],[\"1876.50000000\",\"0.00000000\"]]}}"}
{"mode":"v9-depth-v5-spsc","workers":4,"sequenceNumber":482,"symbol":"SOLUSDT","exchangeEventTimeMillis":1784429301593,"localReceivedEpochMillis":1784429301586,"topSpreadTicks":1,"bid5Volume":206409,"ask5Volume":163963,"bid10Volume":781770,"ask10Volume":470747,"rawPayload":"{\"stream\":\"solusdt@depth@100ms\",\"data\":{\"e\":\"depthUpdate\",\"E\":1784429301593,\"s\":\"SOLUSDT\",\"U\":1609569973,\"u\":1609569975,\"b\":[],\"a\":[[\"76.26000000\",\"67.71400000\"],[\"76.30000000\",\"30.19500000\"]]}}"}
{"mode":"v9-depth-v5-spsc","workers":4,"sequenceNumber":483,"symbol":"XRPUSDT","exchangeEventTimeMillis":1784429301794,"localReceivedEpochMillis":1784429301784,"topSpreadTicks":0,"bid5Volume":8408600,"ask5Volume":1255300,"bid10Volume":24296400,"ask10Volume":2453200,"rawPayload":"{\"stream\":\"xrpusdt@depth@100ms\",\"data\":{\"e\":\"depthUpdate\",\"E\":1784429301794,\"s\":\"XRPUSDT\",\"U\":752699434,\"u\":752699435,\"b\":[],\"a\":[[\"1.09690000\",\"2074.70000000\"],[\"1.09700000\",\"940.00000000\"]]}}"}
{"mode":"v9-depth-v5-spsc","workers":4,"sequenceNumber":484,"symbol":"SOLUSDT","exchangeEventTimeMillis":1784429302294,"localReceivedEpochMillis":1784429302285,"topSpreadTicks":1,"bid5Volume":206409,"ask5Volume":214288,"bid10Volume":781770,"ask10Volume":763574,"rawPayload":"{\"stream\":\"solusdt@depth@100ms\",\"data\":{\"e\":\"depthUpdate\",\"E\":1784429302294,\"s\":\"SOLUSDT\",\"U\":1609569976,\"u\":1609569978,\"b\":[],\"a\":[[\"76.26000000\",\"97.90900000\"],[\"76.28000000\",\"53.60800000\"],[\"76.30000000\",\"0.00000000\"]]}}"}
{"mode":"v9-depth-v5-spsc","workers":4,"sequenceNumber":485,"symbol":"BTCUSDT","exchangeEventTimeMillis":1784429302594,"localReceivedEpochMillis":1784429302586,"topSpreadTicks":265,"bid5Volume":134,"ask5Volume":128,"bid10Volume":280,"ask10Volume":590,"rawPayload":"{\"stream\":\"btcusdt@depth@100ms\",\"data\":{\"e\":\"depthUpdate\",\"E\":1784429302594,\"s\":\"BTCUSDT\",\"U\":3244435424,\"u\":3244435424,\"b\":[],\"a\":[[\"81072.08000000\",\"0.00075000\"]]}}"}
{"mode":"v9-depth-v5-spsc","workers":4,"sequenceNumber":486,"symbol":"SOLUSDT","exchangeEventTimeMillis":1784429302594,"localReceivedEpochMillis":1784429302586,"topSpreadTicks":1,"bid5Volume":206409,"ask5Volume":163963,"bid10Volume":781770,"ask10Volume":713249,"rawPayload":"{\"stream\":\"solusdt@depth@100ms\",\"data\":{\"e\":\"depthUpdate\",\"E\":1784429302594,\"s\":\"SOLUSDT\",\"U\":1609569979,\"u\":1609569980,\"b\":[],\"a\":[[\"76.26000000\",\"67.71400000\"],[\"76.28000000\",\"33.47800000\"]]}}"}
{"mode":"v9-depth-v5-spsc","workers":4,"sequenceNumber":487,"symbol":"SOLUSDT","exchangeEventTimeMillis":1784429302694,"localReceivedEpochMillis":1784429302685,"topSpreadTicks":1,"bid5Volume":206409,"ask5Volume":163963,"bid10Volume":781770,"ask10Volume":490877,"rawPayload":"{\"stream\":\"solusdt@depth@100ms\",\"data\":{\"e\":\"depthUpdate\",\"E\":1784429302694,\"s\":\"SOLUSDT\",\"U\":1609569981,\"u\":1609569982,\"b\":[],\"a\":[[\"76.29000000\",\"100.20500000\"],[\"76.31000000\",\"30.19500000\"]]}}"}
{"mode":"v9-depth-v5-spsc","workers":4,"sequenceNumber":488,"symbol":"SOLUSDT","exchangeEventTimeMillis":1784429302894,"localReceivedEpochMillis":1784429302885,"topSpreadTicks":1,"bid5Volume":206409,"ask5Volume":163966,"bid10Volume":781770,"ask10Volume":490880,"rawPayload":"{\"stream\":\"solusdt@depth@100ms\",\"data\":{\"e\":\"depthUpdate\",\"E\":1784429302894,\"s\":\"SOLUSDT\",\"U\":1609569983,\"u\":1609569984,\"b\":[],\"a\":[[\"76.24000000\",\"39.37600000\"],[\"76.25000000\",\"0.55400000\"]]}}"}
{"mode":"v9-depth-v5-spsc","workers":4,"sequenceNumber":489,"symbol":"BNBUSDT","exchangeEventTimeMillis":1784429302994,"localReceivedEpochMillis":1784429302985,"topSpreadTicks":5,"bid5Volume":3783,"ask5Volume":6096,"bid10Volume":24370,"ask10Volume":263730,"rawPayload":"{\"stream\":\"bnbusdt@depth@100ms\",\"data\":{\"e\":\"depthUpdate\",\"E\":1784429302994,\"s\":\"BNBUSDT\",\"U\":1236328036,\"u\":1236328037,\"b\":[],\"a\":[[\"571.45000000\",\"1.75200000\"],[\"571.68000000\",\"0.82800000\"]]}}"}
{"mode":"v9-depth-v5-spsc","workers":4,"sequenceNumber":490,"symbol":"SOLUSDT","exchangeEventTimeMillis":1784429302994,"localReceivedEpochMillis":1784429302985,"topSpreadTicks":1,"bid5Volume":206409,"ask5Volume":178407,"bid10Volume":781770,"ask10Volume":491619,"rawPayload":"{\"stream\":\"solusdt@depth@100ms\",\"data\":{\"e\":\"depthUpdate\",\"E\":1784429302994,\"s\":\"SOLUSDT\",\"U\":1609569985,\"u\":1609569986,\"b\":[],\"a\":[[\"76.28000000\",\"47.91900000\"],[\"76.29000000\",\"86.50300000\"]]}}"}
{"mode":"v9-depth-v5-spsc","workers":4,"sequenceNumber":491,"symbol":"ETHUSDT","exchangeEventTimeMillis":1784429302994,"localReceivedEpochMillis":1784429302985,"topSpreadTicks":35,"bid5Volume":5554,"ask5Volume":3756,"bid10Volume":27257,"ask10Volume":15615,"rawPayload":"{\"stream\":\"ethusdt@depth@100ms\",\"data\":{\"e\":\"depthUpdate\",\"E\":1784429302994,\"s\":\"ETHUSDT\",\"U\":2806164760,\"u\":2806164761,\"b\":[[\"1871.00000000\",\"0.00000000\"],[\"1870.96000000\",\"0.00000000\"]],\"a\":[]}}"}
{"mode":"v9-depth-v5-spsc","workers":4,"sequenceNumber":492,"symbol":"SOLUSDT","exchangeEventTimeMillis":1784429303195,"localReceivedEpochMillis":1784429303186,"topSpreadTicks":1,"bid5Volume":206409,"ask5Volume":228732,"bid10Volume":781770,"ask10Volume":764316,"rawPayload":"{\"stream\":\"solusdt@depth@100ms\",\"data\":{\"e\":\"depthUpdate\",\"E\":1784429303195,\"s\":\"SOLUSDT\",\"U\":1609569987,\"u\":1609569990,\"b\":[],\"a\":[[\"76.27000000\",\"73.16900000\"],[\"76.29000000\",\"66.37300000\"],[\"76.31000000\",\"0.00000000\"]]}}"}
{"mode":"v9-depth-v5-spsc","workers":4,"sequenceNumber":493,"symbol":"SOLUSDT","exchangeEventTimeMillis":1784429303295,"localReceivedEpochMillis":1784429303285,"topSpreadTicks":1,"bid5Volume":173587,"ask5Volume":228732,"bid10Volume":748948,"ask10Volume":764316,"rawPayload":"{\"stream\":\"solusdt@depth@100ms\",\"data\":{\"e\":\"depthUpdate\",\"E\":1784429303295,\"s\":\"SOLUSDT\",\"U\":1609569991,\"u\":1609569991,\"b\":[[\"76.22000000\",\"10.53100000\"]],\"a\":[]}}"}
{"mode":"v9-depth-v5-spsc","workers":4,"sequenceNumber":494,"symbol":"ETHUSDT","exchangeEventTimeMillis":1784429303295,"localReceivedEpochMillis":1784429303286,"topSpreadTicks":35,"bid5Volume":5554,"ask5Volume":3756,"bid10Volume":27257,"ask10Volume":15615,"rawPayload":"{\"stream\":\"ethusdt@depth@100ms\",\"data\":{\"e\":\"depthUpdate\",\"E\":1784429303295,\"s\":\"ETHUSDT\",\"U\":2806164762,\"u\":2806164762,\"b\":[[\"1870.10000000\",\"1.63970000\"]],\"a\":[]}}"}
{"mode":"v9-depth-v5-spsc","workers":4,"sequenceNumber":495,"symbol":"SOLUSDT","exchangeEventTimeMillis":1784429303395,"localReceivedEpochMillis":1784429303385,"topSpreadTicks":1,"bid5Volume":206413,"ask5Volume":228732,"bid10Volume":774413,"ask10Volume":764316,"rawPayload":"{\"stream\":\"solusdt@depth@100ms\",\"data\":{\"e\":\"depthUpdate\",\"E\":1784429303395,\"s\":\"SOLUSDT\",\"U\":1609569992,\"u\":1609569995,\"b\":[[\"76.22000000\",\"3.96900000\"],[\"76.21000000\",\"69.68300000\"],[\"76.12000000\",\"10.88000000\"]],\"a\":[]}}"}
{"mode":"v9-depth-v5-spsc","workers":4,"sequenceNumber":496,"symbol":"BTCUSDT","exchangeEventTimeMillis":1784429303395,"localReceivedEpochMillis":1784429303385,"topSpreadTicks":265,"bid5Volume":134,"ask5Volume":128,"bid10Volume":280,"ask10Volume":555,"rawPayload":"{\"stream\":\"btcusdt@depth@100ms\",\"data\":{\"e\":\"depthUpdate\",\"E\":1784429303395,\"s\":\"BTCUSDT\",\"U\":3244435425,\"u\":3244435427,\"b\":[[\"64814.83000000\",\"0.00000000\"],[\"64813.20000000\",\"0.03087000\"]],\"a\":[[\"64838.60000000\",\"0.00000000\"]]}}"}
{"mode":"v9-depth-v5-spsc","workers":4,"sequenceNumber":497,"symbol":"BTCUSDT","exchangeEventTimeMillis":1784429303495,"localReceivedEpochMillis":1784429303486,"topSpreadTicks":265,"bid5Volume":134,"ask5Volume":124,"bid10Volume":280,"ask10Volume":590,"rawPayload":"{\"stream\":\"btcusdt@depth@100ms\",\"data\":{\"e\":\"depthUpdate\",\"E\":1784429303495,\"s\":\"BTCUSDT\",\"U\":3244435428,\"u\":3244435428,\"b\":[],\"a\":[[\"64833.15000000\",\"0.03858000\"]]}}"}
{"mode":"v9-depth-v5-spsc","workers":4,"sequenceNumber":498,"symbol":"SOLUSDT","exchangeEventTimeMillis":1784429303495,"localReceivedEpochMillis":1784429303486,"topSpreadTicks":1,"bid5Volume":206413,"ask5Volume":228732,"bid10Volume":774413,"ask10Volume":764316,"rawPayload":"{\"stream\":\"solusdt@depth@100ms\",\"data\":{\"e\":\"depthUpdate\",\"E\":1784429303495,\"s\":\"SOLUSDT\",\"U\":1609569996,\"u\":1609569996,\"b\":[[\"76.23000000\",\"14.43500000\"],[\"76.22000000\",\"22.78300000\"]],\"a\":[]}}"}
{"mode":"v9-depth-v5-spsc","workers":4,"sequenceNumber":499,"symbol":"SOLUSDT","exchangeEventTimeMillis":1784429303695,"localReceivedEpochMillis":1784429303686,"topSpreadTicks":1,"bid5Volume":206413,"ask5Volume":148212,"bid10Volume":781125,"ask10Volume":683796,"rawPayload":"{\"stream\":\"solusdt@depth@100ms\",\"data\":{\"e\":\"depthUpdate\",\"E\":1784429303695,\"s\":\"SOLUSDT\",\"U\":1609569997,\"u\":1609570000,\"b\":[[\"76.11000000\",\"326.02100000\"]],\"a\":[[\"76.27000000\",\"22.84400000\"],[\"76.28000000\",\"17.72400000\"]]}}"}
{"mode":"v9-depth-v5-spsc","workers":4,"sequenceNumber":500,"symbol":"ETHUSDT","exchangeEventTimeMillis":1784429303695,"localReceivedEpochMillis":1784429303687,"topSpreadTicks":35,"bid5Volume":4523,"ask5Volume":3756,"bid10Volume":25653,"ask10Volume":15615,"rawPayload":"{\"stream\":\"ethusdt@depth@100ms\",\"data\":{\"e\":\"depthUpdate\",\"E\":1784429303695,\"s\":\"ETHUSDT\",\"U\":2806164763,\"u\":2806164769,\"b\":[[\"1871.43000000\",\"1.33680000\"],[\"1871.36000000\",\"0.00000000\"],[\"1871.31000000\",\"0.13890000\"],[\"1871.27000000\",\"1.03090000\"],[\"1871.13000000\",\"0.00000000\"],[\"1871.01000000\",\"1.47510000\"],[\"1870.15000000\",\"0.00000000\"],[\"1869.97000000\",\"9.19800000\"]],\"a\":[[\"1871.98000000\",\"0.13880000\"],[\"1872.10000000\",\"0.00000000\"],[\"1872.28000000\",\"1.47410000\"],[\"1872.40000000\",\"0.00000000\"],[\"1873.33000000\",\"9.18150000\"],[\"1873.52000000\",\"0.00000000\"]]}}"}
