{"mode":"v9-depth-v5-spsc","workers":4,"sequenceNumber":1,"symbol":"ETHUSDT","exchangeEventTimeMillis":1784429103261,"localReceivedEpochMillis":1784429103256,"topSpreadTicks":23,"bid5Volume":4111,"ask5Volume":5715,"bid10Volume":9798,"ask10Volume":18231,"rawPayload":"{\"stream\":\"ethusdt@depth@100ms\",\"data\":{\"e\":\"depthUpdate\",\"E\":1784429103261,\"s\":\"ETHUSDT\",\"U\":2806161574,\"u\":2806161580,\"b\":[[\"1873.05000000\",\"0.00000000\"],[\"1872.97000000\",\"1.17330000\"],[\"1872.88000000\",\"0.78720000\"]],\"a\":[[\"1873.54000000\",\"2.57480000\"],[\"1873.62000000\",\"0.00000000\"],[\"1873.67000000\",\"6.50210000\"],[\"1873.84000000\",\"0.00000000\"]]}}"}
{"mode":"v9-depth-v5-spsc","workers":4,"sequenceNumber":2,"symbol":"ETHUSDT","exchangeEventTimeMillis":1784429103361,"localReceivedEpochMillis":1784429103356,"topSpreadTicks":23,"bid5Volume":4111,"ask5Volume":5715,"bid10Volume":9798,"ask10Volume":17760,"rawPayload":"{\"stream\":\"ethusdt@depth@100ms\",\"data\":{\"e\":\"depthUpdate\",\"E\":1784429103361,\"s\":\"ETHUSDT\",\"U\":2806161581,\"u\":2806161582,\"b\":[],\"a\":[[\"1873.67000000\",\"6.44710000\"],[\"1873.79000000\",\"0.05530000\"]]}}"}
{"mode":"v9-depth-v5-spsc","workers":4,"sequenceNumber":3,"symbol":"ETHUSDT","exchangeEventTimeMillis":1784429103461,"localReceivedEpochMillis":1784429103456,"topSpreadTicks":23,"bid5Volume":4888,"ask5Volume":5773,"bid10Volume":9130,"ask10Volume":17819,"rawPayload":"{\"stream\":\"ethusdt@depth@100ms\",\"data\":{\"e\":\"depthUpdate\",\"E\":1784429103461,\"s\":\"ETHUSDT\",\"U\":2806161583,\"u\":2806161595,\"b\":[[\"1873.05000000\",\"0.00000000\"],[\"1872.97000000\",\"0.00000000\"],[\"1872.95000000\",\"0.78720000\"],[\"1872.94000000\",\"1.19280000\"]],\"a\":[[\"1873.51000000\",\"2.79870000\"],[\"1873.54000000\",\"1.47310000\"],[\"1873.62000000\",\"0.00000000\"],[\"1873.69000000\",\"0.05670000\"],[\"1873.79000000\",\"0.00000000\"],[\"1873.89000000\",\"0.00000000\"]]}}"}
{"mode":"v9-depth-v5-spsc","workers":4,"sequenceNumber":4,"symbol":"ETHUSDT","exchangeEventTimeMillis":1784429103561,"localReceivedEpochMillis":1784429103555,"topSpreadTicks":23,"bid5Volume":4130,"ask5Volume":5773,"bid10Volume":9817,"ask10Volume":17819,"rawPayload":"{\"stream\":\"ethusdt@depth@100ms\",\"data\":{\"e\":\"depthUpdate\",\"E\":1784429103561,\"s\":\"ETHUSDT\",\"U\":2806161596,\"u\":2806161596,\"b\":[[\"1872.95000000\",\"0.00000000\"]],\"a\":[]}}"}
{"mode":"v9-depth-v5-spsc","workers":4,"sequenceNumber":5,"symbol":"ETHUSDT","exchangeEventTimeMillis":1784429104062,"localReceivedEpochMillis":1784429104057,"topSpreadTicks":23,"bid5Volume":4130,"ask5Volume":5773,"bid10Volume":9817,"ask10Volume":17822,"rawPayload":"{\"stream\":\"ethusdt@depth@100ms\",\"data\":{\"e\":\"depthUpdate\",\"E\":1784429104062,\"s\":\"ETHUSDT\",\"U\":2806161597,\"u\":2806161598,\"b\":[],\"a\":[[\"1873.69000000\",\"0.00000000\"],[\"1873.76000000\",\"0.05900000\"]]}}"}
{"mode":"v9-depth-v5-spsc","workers":4,"sequenceNumber":6,"symbol":"ETHUSDT","exchangeEventTimeMillis":1784429104162,"localReceivedEpochMillis":1784429104155,"topSpreadTicks":23,"bid5Volume":4130,"ask5Volume":5773,"bid10Volume":9380,"ask10Volume":17822,"rawPayload":"{\"stream\":\"ethusdt@depth@100ms\",\"data\":{\"e\":\"depthUpdate\",\"E\":1784429104162,\"s\":\"ETHUSDT\",\"U\":2806161599,\"u\":2806161599,\"b\":[[\"1872.40000000\",\"1.03710000\"],[\"1872.22000000\",\"20.51870000\"]],\"a\":[]}}"}
{"mode":"v9-depth-v5-spsc","workers":4,"sequenceNumber":7,"symbol":"BTCUSDT","exchangeEventTimeMillis":1784429104262,"localReceivedEpochMillis":1784429104256,"topSpreadTicks":498,"bid5Volume":139,"ask5Volume":123,"bid10Volume":298,"ask10Volume":543,"rawPayload":"{\"stream\":\"btcusdt@depth@100ms\",\"data\":{\"e\":\"depthUpdate\",\"E\":1784429104262,\"s\":\"BTCUSDT\",\"U\":3244433923,\"u\":3244433923,\"b\":[],\"a\":[[\"64914.49000000\",\"0.00000000\"]]}}"}
{"mode":"v9-depth-v5-spsc","workers":4,"sequenceNumber":8,"symbol":"BTCUSDT","exchangeEventTimeMillis":1784429104362,"localReceivedEpochMillis":1784429104356,"topSpreadTicks":498,"bid5Volume":139,"ask5Volume":123,"bid10Volume":298,"ask10Volume":543,"rawPayload":"{\"stream\":\"btcusdt@depth@100ms\",\"data\":{\"e\":\"depthUpdate\",\"E\":1784429104362,\"s\":\"BTCUSDT\",\"U\":3244433924,\"u\":3244433924,\"b\":[],\"a\":[[\"64914.49000000\",\"0.00011000\"]]}}"}
{"mode":"v9-depth-v5-spsc","workers":4,"sequenceNumber":9,"symbol":"ETHUSDT","exchangeEventTimeMillis":1784429104562,"localReceivedEpochMillis":1784429104557,"topSpreadTicks":23,"bid5Volume":4130,"ask5Volume":5773,"bid10Volume":9380,"ask10Volume":17822,"rawPayload":"{\"stream\":\"ethusdt@depth@100ms\",\"data\":{\"e\":\"depthUpdate\",\"E\":1784429104562,\"s\":\"ETHUSDT\",\"U\":2806161600,\"u\":2806161601,\"b\":[[\"1872.95000000\",\"0.78720000\"],[\"1872.88000000\",\"0.00000000\"]],\"a\":[]}}"}
{"mode":"v9-depth-v5-spsc","workers":4,"sequenceNumber":10,"symbol":"BTCUSDT","exchangeEventTimeMillis":1784429104562,"localReceivedEpochMillis":1784429104557,"topSpreadTicks":498,"bid5Volume":139,"ask5Volume":123,"bid10Volume":298,"ask10Volume":543,"rawPayload":"{\"stream\":\"btcusdt@depth@100ms\",\"data\":{\"e\":\"depthUpdate\",\"E\":1784429104562,\"s\":\"BTCUSDT\",\"U\":3244433925,\"u\":3244433925,\"b\":[[\"64822.41000000\",\"0.02921000\"],[\"64820.06000000\",\"0.00000000\"]],\"a\":[]}}"}
{"mode":"v9-depth-v5-spsc","workers":4,"sequenceNumber":11,"symbol":"ETHUSDT","exchangeEventTimeMillis":1784429104662,"localReceivedEpochMillis":1784429104655,"topSpreadTicks":23,"bid5Volume":4130,"ask5Volume":5773,"bid10Volume":8694,"ask10Volume":17822,"rawPayload":"{\"stream\":\"ethusdt@depth@100ms\",\"data\":{\"e\":\"depthUpdate\",\"E\":1784429104662,\"s\":\"ETHUSDT\",\"U\":2806161602,\"u\":2806161602,\"b\":[[\"1872.63000000\",\"0.91680000\"]],\"a\":[]}}"}
{"mode":"v9-depth-v5-spsc","workers":4,"sequenceNumber":12,"symbol":"ETHUSDT","exchangeEventTimeMillis":1784429105162,"localReceivedEpochMillis":1784429105157,"topSpreadTicks":23,"bid5Volume":4033,"ask5Volume":4257,"bid10Volume":8597,"ask10Volume":17720,"rawPayload":"{\"stream\":\"ethusdt@depth@100ms\",\"data\":{\"e\":\"depthUpdate\",\"E\":1784429105162,\"s\":\"ETHUSDT\",\"U\":2806161603,\"u\":2806161609,\"b\":[[\"1872.94000000\",\"0.00000000\"],[\"1872.88000000\",\"1.09500000\"]],\"a\":[[\"1873.45000000\",\"1.11620000\"],[\"1873.51000000\",\"1.63970000\"],[\"1873.61000000\",\"0.00000000\"],[\"1873.76000000\",\"0.00000000\"]]}}"}
{"mode":"v9-depth-v5-spsc","workers":4,"sequenceNumber":13,"symbol":"ETHUSDT","exchangeEventTimeMillis":1784429105263,"localReceivedEpochMillis":1784429105257,"topSpreadTicks":23,"bid5Volume":4091,"ask5Volume":5810,"bid10Volume":8655,"ask10Volume":17854,"rawPayload":"{\"stream\":\"ethusdt@depth@100ms\",\"data\":{\"e\":\"depthUpdate\",\"E\":1784429105263,\"s\":\"ETHUSDT\",\"U\":2806161610,\"u\":2806161614,\"b\":[[\"1872.94000000\",\"1.15340000\"],[\"1872.88000000\",\"0.00000000\"]],\"a\":[[\"1873.45000000\",\"0.00000000\"],[\"1873.51000000\",\"2.83500000\"],[\"1873.74000000\",\"0.05470000\"]]}}"}
{"mode":"v9-depth-v5-spsc","workers":4,"sequenceNumber":14,"symbol":"ETHUSDT","exchangeEventTimeMillis":1784429105463,"localReceivedEpochMillis":1784429105457,"topSpreadTicks":23,"bid5Volume":4119,"ask5Volume":4291,"bid10Volume":8683,"ask10Volume":17754,"rawPayload":"{\"stream\":\"ethusdt@depth@100ms\",\"data\":{\"e\":\"depthUpdate\",\"E\":1784429105463,\"s\":\"ETHUSDT\",\"U\":2806161615,\"u\":2806161619,\"b\":[[\"1872.94000000\",\"0.00000000\"],[\"1872.88000000\",\"1.18140000\"]],\"a\":[[\"1873.45000000\",\"1.15000000\"],[\"1873.51000000\",\"1.63970000\"],[\"1873.74000000\",\"0.00000000\"]]}}"}
{"mode":"v9-depth-v5-spsc","workers":4,"sequenceNumber":15,"symbol":"ETHUSDT","exchangeEventTimeMillis":1784429105563,"localReceivedEpochMillis":1784429105557,"topSpreadTicks":23,"bid5Volume":4127,"ask5Volume":4282,"bid10Volume":8691,"ask10Volume":17745,"rawPayload":"{\"stream\":\"ethusdt@depth@100ms\",\"data\":{\"e\":\"depthUpdate\",\"E\":1784429105563,\"s\":\"ETHUSDT\",\"U\":2806161620,\"u\":2806161623,\"b\":[[\"1872.94000000\",\"1.18990000\"],[\"1872.88000000\",\"0.00000000\"]],\"a\":[[\"1873.45000000\",\"0.00000000\"],[\"1873.52000000\",\"1.14110000\"]]}}"}
{"mode":"v9-depth-v5-spsc","workers":4,"sequenceNumber":16,"symbol":"ETHUSDT","exchangeEventTimeMillis":1784429105663,"localReceivedEpochMillis":1784429105656,"topSpreadTicks":25,"bid5Volume":4127,"ask5Volume":4282,"bid10Volume":10165,"ask10Volume":18215,"rawPayload":"{\"stream\":\"ethusdt@depth@100ms\",\"data\":{\"e\":\"depthUpdate\",\"E\":1784429105663,\"s\":\"ETHUSDT\",\"U\":2806161624,\"u\":2806161627,\"b\":[[\"1872.70000000\",\"0.13880000\"],[\"1872.61000000\",\"0.00000000\"],[\"1872.40000000\",\"2.51110000\"],[\"1872.28000000\",\"0.00000000\"]],\"a\":[[\"1873.27000000\",\"0.00000000\"],[\"1873.36000000\",\"0.13870000\"],[\"1873.54000000\",\"0.00000000\"],[\"1873.66000000\",\"2.13460000\"]]}}"}
{"mode":"v9-depth-v5-spsc","workers":4,"sequenceNumber":17,"symbol":"BTCUSDT","exchangeEventTimeMillis":1784429105963,"localReceivedEpochMillis":1784429105957,"topSpreadTicks":498,"bid5Volume":139,"ask5Volume":123,"bid10Volume":298,"ask10Volume":543,"rawPayload":"{\"stream\":\"btcusdt@depth@100ms\",\"data\":{\"e\":\"depthUpdate\",\"E\":1784429105963,\"s\":\"BTCUSDT\",\"U\":3244433926,\"u\":3244433926,\"b\":[],\"a\":[[\"81072.08000000\",\"0.00045000\"]]}}"}
{"mode":"v9-depth-v5-spsc","workers":4,"sequenceNumber":18,"symbol":"BTCUSDT","exchangeEventTimeMillis":1784429106463,"localReceivedEpochMillis":1784429106458,"topSpreadTicks":498,"bid5Volume":139,"ask5Volume":123,"bid10Volume":298,"ask10Volume":543,"rawPayload":"{\"stream\":\"btcusdt@depth@100ms\",\"data\":{\"e\":\"depthUpdate\",\"E\":1784429106463,\"s\":\"BTCUSDT\",\"U\":3244433927,\"u\":3244433928,\"b\":[[\"64687.44000000\",\"0.00000000\"]],\"a\":[[\"64998.64000000\",\"0.00000000\"]]}}"}
{"mode":"v9-depth-v5-spsc","workers":4,"sequenceNumber":19,"symbol":"BTCUSDT","exchangeEventTimeMillis":1784429106563,"localReceivedEpochMillis":1784429106557,"topSpreadTicks":498,"bid5Volume":139,"ask5Volume":123,"bid10Volume":298,"ask10Volume":543,"rawPayload":"{\"stream\":\"btcusdt@depth@100ms\",\"data\":{\"e\":\"depthUpdate\",\"E\":1784429106563,\"s\":\"BTCUSDT\",\"U\":3244433929,\"u\":3244433931,\"b\":[[\"64726.35000000\",\"0.00000000\"],[\"64609.63000000\",\"0.00000000\"]],\"a\":[[\"64959.73000000\",\"0.00000000\"]]}}"}
{"mode":"v9-depth-v5-spsc","workers":4,"sequenceNumber":20,"symbol":"ETHUSDT","exchangeEventTimeMillis":1784429106763,"localReceivedEpochMillis":1784429106758,"topSpreadTicks":25,"bid5Volume":3559,"ask5Volume":5129,"bid10Volume":28486,"ask10Volume":24500,"rawPayload":"{\"stream\":\"ethusdt@depth@100ms\",\"data\":{\"e\":\"depthUpdate\",\"E\":1784429106763,\"s\":\"ETHUSDT\",\"U\":2806161628,\"u\":2806161647,\"b\":[[\"1872.94000000\",\"0.00000000\"],[\"1872.88000000\",\"0.00000000\"],[\"1872.87000000\",\"0.00000000\"],[\"1872.83000000\",\"1.12230000\"],[\"1872.67000000\",\"0.00000000\"],[\"1872.63000000\",\"0.00000000\"],[\"1872.56000000\",\"0.00000000\"],[\"1872.36000000\",\"0.00000000\"],[\"1872.14000000\",\"1.45740000\"]],\"a\":[[\"1873.27000000\",\"0.00000000\"],[\"1873.40000000\",\"1.18990000\"],[\"1873.42000000\",\"0.00000000\"],[\"1873.46000000\",\"0.00000000\"],[\"1873.52000000\",\"0.00000000\"],[\"1873.68000000\",\"1.63970000\"]]}}"}
{"mode":"v9-depth-v5-spsc","workers":4,"sequenceNumber":21,"symbol":"BTCUSDT","exchangeEventTimeMillis":1784429106764,"localReceivedEpochMillis":1784429106758,"topSpreadTicks":498,"bid5Volume":139,"ask5Volume":123,"bid10Volume":298,"ask10Volume":543,"rawPayload":"{\"stream\":\"btcusdt@depth@100ms\",\"data\":{\"e\":\"depthUpdate\",\"E\":1784429106764,\"s\":\"BTCUSDT\",\"U\":3244433932,\"u\":3244433935,\"b\":[],\"a\":[[\"64856.23000000\",\"0.00172000\"],[\"64857.56000000\",\"0.00000000\"],[\"64858.35000000\",\"0.00000000\"]]}}"}
{"mode":"v9-depth-v5-spsc","workers":4,"sequenceNumber":22,"symbol":"ETHUSDT","exchangeEventTimeMillis":1784429106864,"localReceivedEpochMillis":1784429106857,"topSpreadTicks":25,"bid5Volume":3559,"ask5Volume":5129,"bid10Volume":29458,"ask10Volume":24500,"rawPayload":"{\"stream\":\"ethusdt@depth@100ms\",\"data\":{\"e\":\"depthUpdate\",\"E\":1784429106864,\"s\":\"ETHUSDT\",\"U\":2806161648,\"u\":2806161657,\"b\":[[\"1872.40000000\",\"3.48390000\"],[\"1865.55000000\",\"0.00000000\"],[\"1865.41000000\",\"0.00000000\"],[\"1865.39000000\",\"0.00000000\"],[\"1865.38000000\",\"7.22490000\"],[\"1865.26000000\",\"34.85470000\"],[\"1864.24000000\",\"0.00000000\"],[\"1864.19000000\",\"0.00000000\"]],\"a\":[[\"1880.36000000\",\"7.18480000\"],[\"1881.79000000\",\"0.00000000\"]]}}"}
{"mode":"v9-depth-v5-spsc","workers":4,"sequenceNumber":23,"symbol":"ETHUSDT","exchangeEventTimeMillis":1784429106964,"localReceivedEpochMillis":1784429106958,"topSpreadTicks":22,"bid5Volume":4216,"ask5Volume":4188,"bid10Volume":29982,"ask10Volume":17686,"rawPayload":"{\"stream\":\"ethusdt@depth@100ms\",\"data\":{\"e\":\"depthUpdate\",\"E\":1784429106964,\"s\":\"ETHUSDT\",\"U\":2806161658,\"u\":2806161671,\"b\":[[\"1872.95000000\",\"0.00000000\"],[\"1872.88000000\",\"0.00000000\"],[\"1872.84000000\",\"0.00000000\"],[\"1872.77000000\",\"0.00000000\"],[\"1872.60000000\",\"1.33590000\"],[\"1872.45000000\",\"0.97710000\"],[\"1872.40000000\",\"2.51110000\"],[\"1865.17000000\",\"8.47790000\"]],\"a\":[[\"1873.26000000\",\"1.33550000\"],[\"1873.28000000\",\"0.76340000\"],[\"1873.29000000\",\"0.00000000\"],[\"1873.46000000\",\"0.76340000\"]]}}"}
{"mode":"v9-depth-v5-spsc","workers":4,"sequenceNumber":24,"symbol":"ETHUSDT","exchangeEventTimeMillis":1784429107164,"localReceivedEpochMillis":1784429107157,"topSpreadTicks":22,"bid5Volume":4216,"ask5Volume":4188,"bid10Volume":29982,"ask10Volume":17686,"rawPayload":"{\"stream\":\"ethusdt@depth@100ms\",\"data\":{\"e\":\"depthUpdate\",\"E\":1784429107164,\"s\":\"ETHUSDT\",\"U\":2806161672,\"u\":2806161672,\"b\":[[\"1864.24000000\",\"9.22730000\"]],\"a\":[]}}"}
{"mode":"v9-depth-v5-spsc","workers":4,"sequenceNumber":25,"symbol":"ETHUSDT","exchangeEventTimeMillis":1784429107364,"localReceivedEpochMillis":1784429107357,"topSpreadTicks":22,"bid5Volume":5037,"ask5Volume":4093,"bid10Volume":30803,"ask10Volume":17591,"rawPayload":"{\"stream\":\"ethusdt@depth@100ms\",\"data\":{\"e\":\"depthUpdate\",\"E\":1784429107364,\"s\":\"ETHUSDT\",\"U\":2806161673,\"u\":2806161678,\"b\":[[\"1872.93000000\",\"1.19340000\"],[\"1872.83000000\",\"0.00000000\"],[\"1872.70000000\",\"0.88880000\"],[\"1864.19000000\",\"9.19470000\"]],\"a\":[[\"1873.40000000\",\"0.00000000\"],[\"1873.50000000\",\"1.09400000\"]]}}"}
{"mode":"v9-depth-v5-spsc","workers":4,"sequenceNumber":26,"symbol":"ETHUSDT","exchangeEventTimeMillis":1784429107464,"localReceivedEpochMillis":1784429107458,"topSpreadTicks":7,"bid5Volume":5067,"ask5Volume":3028,"bid10Volume":30833,"ask10Volume":15981,"rawPayload":"{\"stream\":\"ethusdt@depth@100ms\",\"data\":{\"e\":\"depthUpdate\",\"E\":1784429107464,\"s\":\"ETHUSDT\",\"U\":2806161679,\"u\":2806161680,\"b\":[[\"1872.60000000\",\"1.36550000\"]],\"a\":[[\"1873.11000000\",\"0.02970000\"]]}}"}
{"mode":"v9-depth-v5-spsc","workers":4,"sequenceNumber":27,"symbol":"ETHUSDT","exchangeEventTimeMillis":1784429107564,"localReceivedEpochMillis":1784429107562,"topSpreadTicks":7,"bid5Volume":4993,"ask5Volume":3357,"bid10Volume":30759,"ask10Volume":15979,"rawPayload":"{\"stream\":\"ethusdt@depth@100ms\",\"data\":{\"e\":\"depthUpdate\",\"E\":1784429107564,\"s\":\"ETHUSDT\",\"U\":2806161681,\"u\":2806161684,\"b\":[[\"1872.93000000\",\"0.00000000\"],[\"1872.86000000\",\"1.11960000\"]],\"a\":[[\"1873.43000000\",\"1.09210000\"],[\"1873.50000000\",\"0.00000000\"]]}}"}
{"mode":"v9-depth-v5-spsc","workers":4,"sequenceNumber":28,"symbol":"ETHUSDT","exchangeEventTimeMillis":1784429107664,"localReceivedEpochMillis":1784429107658,"topSpreadTicks":7,"bid5Volume":4378,"ask5Volume":3357,"bid10Volume":31388,"ask10Volume":15979,"rawPayload":"{\"stream\":\"ethusdt@depth@100ms\",\"data\":{\"e\":\"depthUpdate\",\"E\":1784429107664,\"s\":\"ETHUSDT\",\"U\":2806161685,\"u\":2806161685,\"b\":[[\"1872.71000000\",\"0.75000000\"]],\"a\":[]}}"}
{"mode":"v9-depth-v5-spsc","workers":4,"sequenceNumber":29,"symbol":"BTCUSDT","exchangeEventTimeMillis":1784429107864,"localReceivedEpochMillis":1784429107858,"topSpreadTicks":498,"bid5Volume":139,"ask5Volume":123,"bid10Volume":298,"ask10Volume":543,"rawPayload":"{\"stream\":\"btcusdt@depth@100ms\",\"data\":{\"e\":\"depthUpdate\",\"E\":1784429107864,\"s\":\"BTCUSDT\",\"U\":3244433936,\"u\":3244433941,\"b\":[[\"64766.71000000\",\"0.05625000\"],[\"64765.26000000\",\"0.00000000\"],[\"64727.80000000\",\"0.09097000\"],[\"64688.90000000\",\"0.17358000\"],[\"64611.08000000\",\"0.43131000\"]],\"a\":[[\"64920.83000000\",\"0.00000000\"],[\"64922.28000000\",\"0.06165000\"],[\"65077.91000000\",\"0.42748000\"]]}}"}
{"mode":"v9-depth-v5-spsc","workers":4,"sequenceNumber":30,"symbol":"ETHUSDT","exchangeEventTimeMillis":1784429108164,"localReceivedEpochMillis":1784429108159,"topSpreadTicks":7,"bid5Volume":4378,"ask5Volume":3357,"bid10Volume":10870,"ask10Volume":15979,"rawPayload":"{\"stream\":\"ethusdt@depth@100ms\",\"data\":{\"e\":\"depthUpdate\",\"E\":1784429108164,\"s\":\"ETHUSDT\",\"U\":2806161686,\"u\":2806161686,\"b\":[[\"1872.43000000\",\"1.03710000\"],[\"1872.40000000\",\"1.47400000\"]],\"a\":[]}}"}
{"mode":"v9-depth-v5-spsc","workers":4,"sequenceNumber":31,"symbol":"BTCUSDT","exchangeEventTimeMillis":1784429108164,"localReceivedEpochMillis":1784429108159,"topSpreadTicks":498,"bid5Volume":139,"ask5Volume":123,"bid10Volume":298,"ask10Volume":543,"rawPayload":"{\"stream\":\"btcusdt@depth@100ms\",\"data\":{\"e\":\"depthUpdate\",\"E\":1784429108164,\"s\":\"BTCUSDT\",\"U\":3244433942,\"u\":3244433943,\"b\":[],\"a\":[[\"64914.49000000\",\"0.00011000\"]]}}"}
{"mode":"v9-depth-v5-spsc","workers":4,"sequenceNumber":32,"symbol":"ETHUSDT","exchangeEventTimeMillis":1784429108665,"localReceivedEpochMillis":1784429108659,"topSpreadTicks":7,"bid5Volume":4993,"ask5Volume":3357,"bid10Volume":30638,"ask10Volume":16855,"rawPayload":"{\"stream\":\"ethusdt@depth@100ms\",\"data\":{\"e\":\"depthUpdate\",\"E\":1784429108665,\"s\":\"ETHUSDT\",\"U\":2806161687,\"u\":2806161688,\"b\":[[\"1872.71000000\",\"0.00000000\"]],\"a\":[[\"1873.46000000\",\"0.00000000\"]]}}"}
{"mode":"v9-depth-v5-spsc","workers":4,"sequenceNumber":33,"symbol":"ETHUSDT","exchangeEventTimeMillis":1784429108865,"localReceivedEpochMillis":1784429108859,"topSpreadTicks":7,"bid5Volume":4993,"ask5Volume":3357,"bid10Volume":30638,"ask10Volume":15275,"rawPayload":"{\"stream\":\"ethusdt@depth@100ms\",\"data\":{\"e\":\"depthUpdate\",\"E\":1784429108865,\"s\":\"ETHUSDT\",\"U\":2806161689,\"u\":2806161689,\"b\":[],\"a\":[[\"1873.56000000\",\"0.05950000\"]]}}"}
{"mode":"v9-depth-v5-spsc","workers":4,"sequenceNumber":34,"symbol":"BTCUSDT","exchangeEventTimeMillis":1784429109866,"localReceivedEpochMillis":1784429109860,"topSpreadTicks":498,"bid5Volume":139,"ask5Volume":123,"bid10Volume":298,"ask10Volume":543,"rawPayload":"{\"stream\":\"btcusdt@depth@100ms\",\"data\":{\"e\":\"depthUpdate\",\"E\":1784429109866,\"s\":\"BTCUSDT\",\"U\":3244433944,\"u\":3244433944,\"b\":[],\"a\":[[\"81072.08000000\",\"0.00060000\"]]}}"}
{"mode":"v9-depth-v5-spsc","workers":4,"sequenceNumber":35,"symbol":"ETHUSDT","exchangeEventTimeMillis":1784429109966,"localReceivedEpochMillis":1784429109960,"topSpreadTicks":7,"bid5Volume":4993,"ask5Volume":3357,"bid10Volume":30840,"ask10Volume":15271,"rawPayload":"{\"stream\":\"ethusdt@depth@100ms\",\"data\":{\"e\":\"depthUpdate\",\"E\":1784429109966,\"s\":\"ETHUSDT\",\"U\":2806161690,\"u\":2806161693,\"b\":[[\"1872.45000000\",\"0.00000000\"],[\"1872.40000000\",\"2.53280000\"]],\"a\":[[\"1873.56000000\",\"0.00000000\"],[\"1873.63000000\",\"0.05530000\"]]}}"}
{"mode":"v9-depth-v5-spsc","workers":4,"sequenceNumber":36,"symbol":"ETHUSDT","exchangeEventTimeMillis":1784429110166,"localReceivedEpochMillis":1784429110160,"topSpreadTicks":7,"bid5Volume":4993,"ask5Volume":4997,"bid10Volume":30840,"ask10Volume":16911,"rawPayload":"{\"stream\":\"ethusdt@depth@100ms\",\"data\":{\"e\":\"depthUpdate\",\"E\":1784429110166,\"s\":\"ETHUSDT\",\"U\":2806161694,\"u\":2806161695,\"b\":[],\"a\":[[\"1873.11000000\",\"1.36530000\"],[\"1873.26000000\",\"0.00000000\"]]}}"}
{"mode":"v9-depth-v5-spsc","workers":4,"sequenceNumber":37,"symbol":"BTCUSDT","exchangeEventTimeMillis":1784429110366,"localReceivedEpochMillis":1784429110360,"topSpreadTicks":498,"bid5Volume":139,"ask5Volume":123,"bid10Volume":298,"ask10Volume":543,"rawPayload":"{\"stream\":\"btcusdt@depth@100ms\",\"data\":{\"e\":\"depthUpdate\",\"E\":1784429110366,\"s\":\"BTCUSDT\",\"U\":3244433945,\"u\":3244433945,\"b\":[],\"a\":[[\"81072.08000000\",\"0.00060000\"]]}}"}
{"mode":"v9-depth-v5-spsc","workers":4,"sequenceNumber":38,"symbol":"ETHUSDT","exchangeEventTimeMillis":1784429110366,"localReceivedEpochMillis":1784429110361,"topSpreadTicks":7,"bid5Volume":4869,"ask5Volume":5097,"bid10Volume":9217,"ask10Volume":17011,"rawPayload":"{\"stream\":\"ethusdt@depth@100ms\",\"data\":{\"e\":\"depthUpdate\",\"E\":1784429110366,\"s\":\"ETHUSDT\",\"U\":2806161696,\"u\":2806161708,\"b\":[[\"1872.94000000\",\"1.16300000\"],[\"1872.86000000\",\"0.00000000\"],[\"1872.75000000\",\"0.75000000\"],[\"1872.74000000\",\"1.33580000\"],[\"1872.70000000\",\"0.13880000\"],[\"1872.60000000\",\"0.02960000\"],[\"1872.57000000\",\"1.06840000\"],[\"1872.43000000\",\"0.00000000\"],[\"1872.40000000\",\"1.47400000\"],[\"1872.29000000\",\"1.03710000\"]],\"a\":[[\"1873.11000000\",\"0.02970000\"],[\"1873.40000000\",\"1.33540000\"],[\"1873.43000000\",\"0.00000000\"],[\"1873.51000000\",\"2.83210000\"]]}}"}
{"mode":"v9-depth-v5-spsc","workers":4,"sequenceNumber":39,"symbol":"ETHUSDT","exchangeEventTimeMillis":1784429110466,"localReceivedEpochMillis":1784429110460,"topSpreadTicks":7,"bid5Volume":4869,"ask5Volume":6468,"bid10Volume":9217,"ask10Volume":16721,"rawPayload":"{\"stream\":\"ethusdt@depth@100ms\",\"data\":{\"e\":\"depthUpdate\",\"E\":1784429110466,\"s\":\"ETHUSDT\",\"U\":2806161709,\"u\":2806161711,\"b\":[],\"a\":[[\"1873.28000000\",\"0.00000000\"],[\"1873.63000000\",\"0.00000000\"],[\"1873.71000000\",\"0.05750000\"]]}}"}
{"mode":"v9-depth-v5-spsc","workers":4,"sequenceNumber":40,"symbol":"ETHUSDT","exchangeEventTimeMillis":1784429110566,"localReceivedEpochMillis":1784429110561,"topSpreadTicks":6,"bid5Volume":4802,"ask5Volume":4264,"bid10Volume":9150,"ask10Volume":16180,"rawPayload":"{\"stream\":\"ethusdt@depth@100ms\",\"data\":{\"e\":\"depthUpdate\",\"E\":1784429110566,\"s\":\"ETHUSDT\",\"U\":2806161712,\"u\":2806161717,\"b\":[[\"1873.05000000\",\"1.09680000\"],[\"1872.94000000\",\"0.00000000\"]],\"a\":[[\"1873.51000000\",\"1.63970000\"],[\"1873.62000000\",\"1.12330000\"],[\"1873.71000000\",\"0.00000000\"],[\"1873.90000000\",\"0.05710000\"]]}}"}
{"mode":"v9-depth-v5-spsc","workers":4,"sequenceNumber":41,"symbol":"ETHUSDT","exchangeEventTimeMillis":1784429110666,"localReceivedEpochMillis":1784429110661,"topSpreadTicks":7,"bid5Volume":4898,"ask5Volume":4263,"bid10Volume":9246,"ask10Volume":16177,"rawPayload":"{\"stream\":\"ethusdt@depth@100ms\",\"data\":{\"e\":\"depthUpdate\",\"E\":1784429110666,\"s\":\"ETHUSDT\",\"U\":2806161718,\"u\":2806161726,\"b\":[[\"1873.05000000\",\"0.00000000\"],[\"1872.90000000\",\"1.19230000\"],[\"1872.30000000\",\"1.03710000\"],[\"1872.29000000\",\"0.00000000\"]],\"a\":[[\"1873.48000000\",\"1.12220000\"],[\"1873.62000000\",\"0.00000000\"],[\"1873.63000000\",\"0.05590000\"],[\"1873.64000000\",\"0.00000000\"],[\"1873.90000000\",\"0.00000000\"]]}}"}
{"mode":"v9-depth-v5-spsc","workers":4,"sequenceNumber":42,"symbol":"ETHUSDT","exchangeEventTimeMillis":1784429110766,"localReceivedEpochMillis":1784429110760,"topSpreadTicks":7,"bid5Volume":4898,"ask5Volume":4263,"bid10Volume":9246,"ask10Volume":16650,"rawPayload":"{\"stream\":\"ethusdt@depth@100ms\",\"data\":{\"e\":\"depthUpdate\",\"E\":1784429110766,\"s\":\"ETHUSDT\",\"U\":2806161727,\"u\":2806161728,\"b\":[],\"a\":[[\"1873.63000000\",\"0.00000000\"],[\"1873.66000000\",\"2.19170000\"]]}}"}
{"mode":"v9-depth-v5-spsc","workers":4,"sequenceNumber":43,"symbol":"ETHUSDT","exchangeEventTimeMillis":1784429110866,"localReceivedEpochMillis":1784429110861,"topSpreadTicks":7,"bid5Volume":4898,"ask5Volume":4263,"bid10Volume":9246,"ask10Volume":16178,"rawPayload":"{\"stream\":\"ethusdt@depth@100ms\",\"data\":{\"e\":\"depthUpdate\",\"E\":1784429110866,\"s\":\"ETHUSDT\",\"U\":2806161729,\"u\":2806161730,\"b\":[],\"a\":[[\"1873.61000000\",\"0.05680000\"],[\"1873.66000000\",\"2.13460000\"]]}}"}
{"mode":"v9-depth-v5-spsc","workers":4,"sequenceNumber":44,"symbol":"ETHUSDT","exchangeEventTimeMillis":1784429111367,"localReceivedEpochMillis":1784429111361,"topSpreadTicks":7,"bid5Volume":4898,"ask5Volume":4263,"bid10Volume":9246,"ask10Volume":16178,"rawPayload":"{\"stream\":\"ethusdt@depth@100ms\",\"data\":{\"e\":\"depthUpdate\",\"E\":1784429111367,\"s\":\"ETHUSDT\",\"U\":2806161731,\"u\":2806161734,\"b\":[[\"1872.57000000\",\"0.00000000\"],[\"1872.51000000\",\"1.06840000\"]],\"a\":[[\"1873.26000000\",\"1.33550000\"],[\"1873.40000000\",\"0.00000000\"]]}}"}
{"mode":"v9-depth-v5-spsc","workers":4,"sequenceNumber":45,"symbol":"ETHUSDT","exchangeEventTimeMillis":1784429111767,"localReceivedEpochMillis":1784429111761,"topSpreadTicks":7,"bid5Volume":4895,"ask5Volume":4287,"bid10Volume":9243,"ask10Volume":16202,"rawPayload":"{\"stream\":\"ethusdt@depth@100ms\",\"data\":{\"e\":\"depthUpdate\",\"E\":1784429111767,\"s\":\"ETHUSDT\",\"U\":2806161735,\"u\":2806161738,\"b\":[[\"1872.90000000\",\"0.00000000\"],[\"1872.84000000\",\"1.18910000\"]],\"a\":[[\"1873.41000000\",\"1.14640000\"],[\"1873.48000000\",\"0.00000000\"]]}}"}
{"mode":"v9-depth-v5-spsc","workers":4,"sequenceNumber":46,"symbol":"BTCUSDT","exchangeEventTimeMillis":1784429111967,"localReceivedEpochMillis":1784429111961,"topSpreadTicks":498,"bid5Volume":139,"ask5Volume":123,"bid10Volume":298,"ask10Volume":543,"rawPayload":"{\"stream\":\"btcusdt@depth@100ms\",\"data\":{\"e\":\"depthUpdate\",\"E\":1784429111967,\"s\":\"BTCUSDT\",\"U\":3244433946,\"u\":3244433947,\"b\":[],\"a\":[[\"64914.49000000\",\"0.00000000\"],[\"81072.08000000\",\"0.00075000\"]]}}"}
{"mode":"v9-depth-v5-spsc","workers":4,"sequenceNumber":47,"symbol":"BTCUSDT","exchangeEventTimeMillis":1784429112067,"localReceivedEpochMillis":1784429112061,"topSpreadTicks":498,"bid5Volume":139,"ask5Volume":123,"bid10Volume":298,"ask10Volume":543,"rawPayload":"{\"stream\":\"btcusdt@depth@100ms\",\"data\":{\"e\":\"depthUpdate\",\"E\":1784429112067,\"s\":\"BTCUSDT\",\"U\":3244433948,\"u\":3244433950,\"b\":[],\"a\":[[\"64854.93000000\",\"0.00168000\"],[\"64856.23000000\",\"0.00000000\"],[\"64914.49000000\",\"0.00011000\"]]}}"}
{"mode":"v9-depth-v5-spsc","workers":4,"sequenceNumber":48,"symbol":"ETHUSDT","exchangeEventTimeMillis":1784429112067,"localReceivedEpochMillis":1784429112062,"topSpreadTicks":7,"bid5Volume":4895,"ask5Volume":4287,"bid10Volume":9243,"ask10Volume":16204,"rawPayload":"{\"stream\":\"ethusdt@depth@100ms\",\"data\":{\"e\":\"depthUpdate\",\"E\":1784429112067,\"s\":\"ETHUSDT\",\"U\":2806161739,\"u\":2806161747,\"b\":[[\"1871.16000000\",\"2.00940000\"],[\"1870.64000000\",\"0.00000000\"],[\"1870.04000000\",\"3.17660000\"],[\"1869.52000000\",\"0.00000000\"],[\"1868.92000000\",\"5.91250000\"],[\"1868.39000000\",\"0.00000000\"],[\"1866.67000000\",\"14.53840000\"],[\"1866.14000000\",\"0.00000000\"]],\"a\":[[\"1873.56000000\",\"0.05880000\"],[\"1873.61000000\",\"0.00000000\"],[\"1875.14000000\",\"0.00000000\"],[\"1875.67000000\",\"2.04290000\"],[\"1876.26000000\",\"0.00000000\"],[\"1876.79000000\",\"2.94890000\"],[\"1877.39000000\",\"0.00000000\"],[\"1877.92000000\",\"5.84980000\"]]}}"}
{"mode":"v9-depth-v5-spsc","workers":4,"sequenceNumber":49,"symbol":"ETHUSDT","exchangeEventTimeMillis":1784429112868,"localReceivedEpochMillis":1784429112861,"topSpreadTicks":7,"bid5Volume":4875,"ask5Volume":4294,"bid10Volume":9223,"ask10Volume":16211,"rawPayload":"{\"stream\":\"ethusdt@depth@100ms\",\"data\":{\"e\":\"depthUpdate\",\"E\":1784429112868,\"s\":\"ETHUSDT\",\"U\":2806161748,\"u\":2806161757,\"b\":[[\"1872.91000000\",\"0.00000000\"],[\"1872.85000000\",\"1.16960000\"],[\"1872.84000000\",\"0.00000000\"]],\"a\":[[\"1873.41000000\",\"0.00000000\"],[\"1873.42000000\",\"1.15320000\"],[\"1873.48000000\",\"0.00000000\"],[\"1873.56000000\",\"0.00000000\"],[\"1873.62000000\",\"0.05870000\"]]}}"}
{"mode":"v9-depth-v5-spsc","workers":4,"sequenceNumber":50,"symbol":"ETHUSDT","exchangeEventTimeMillis":1784429113068,"localReceivedEpochMillis":1784429113061,"topSpreadTicks":7,"bid5Volume":4867,"ask5Volume":4322,"bid10Volume":8613,"ask10Volume":16239,"rawPayload":"{\"stream\":\"ethusdt@depth@100ms\",\"data\":{\"e\":\"depthUpdate\",\"E\":1784429113068,\"s\":\"ETHUSDT\",\"U\":2806161758,\"u\":2806161762,\"b\":[[\"1872.93000000\",\"1.16160000\"],[\"1872.85000000\",\"0.00000000\"],[\"1872.39000000\",\"1.03710000\"],[\"1872.30000000\",\"0.00000000\"]],\"a\":[[\"1873.42000000\",\"0.00000000\"],[\"1873.50000000\",\"1.18180000\"]]}}"}
{"mode":"v9-depth-v5-spsc","workers":4,"sequenceNumber":51,"symbol":"ETHUSDT","exchangeEventTimeMillis":1784429113168,"localReceivedEpochMillis":1784429113170,"topSpreadTicks":7,"bid5Volume":4867,"ask5Volume":4322,"bid10Volume":8613,"ask10Volume":16239,"rawPayload":"{\"stream\":\"ethusdt@depth@100ms\",\"data\":{\"e\":\"depthUpdate\",\"E\":1784429113168,\"s\":\"ETHUSDT\",\"U\":2806161763,\"u\":2806161764,\"b\":[[\"1872.56000000\",\"1.06840000\"],[\"1872.51000000\",\"0.00000000\"]],\"a\":[]}}"}
{"mode":"v9-depth-v5-spsc","workers":4,"sequenceNumber":52,"symbol":"ETHUSDT","exchangeEventTimeMillis":1784429113268,"localReceivedEpochMillis":1784429113280,"topSpreadTicks":7,"bid5Volume":4304,"ask5Volume":4315,"bid10Volume":8348,"ask10Volume":16645,"rawPayload":"{\"stream\":\"ethusdt@depth@100ms\",\"data\":{\"e\":\"depthUpdate\",\"E\":1784429113268,\"s\":\"ETHUSDT\",\"U\":2806161765,\"u\":2806161776,\"b\":[[\"1873.05000000\",\"0.00000000\"],[\"1872.97000000\",\"1.18320000\"],[\"1872.93000000\",\"0.00000000\"],[\"1872.88000000\",\"0.75000000\"],[\"1872.75000000\",\"0.75000000\"]],\"a\":[[\"1873.50000000\",\"0.00000000\"],[\"1873.54000000\",\"1.17450000\"],[\"1873.62000000\",\"0.00000000\"]]}}"}
{"mode":"v9-depth-v5-spsc","workers":4,"sequenceNumber":53,"symbol":"BTCUSDT","exchangeEventTimeMillis":1784429113568,"localReceivedEpochMillis":1784429113575,"topSpreadTicks":498,"bid5Volume":139,"ask5Volume":123,"bid10Volume":298,"ask10Volume":543,"rawPayload":"{\"stream\":\"btcusdt@depth@100ms\",\"data\":{\"e\":\"depthUpdate\",\"E\":1784429113568,\"s\":\"BTCUSDT\",\"U\":3244433951,\"u\":3244433951,\"b\":[],\"a\":[[\"81072.08000000\",\"0.00075000\"]]}}"}
{"mode":"v9-depth-v5-spsc","workers":4,"sequenceNumber":54,"symbol":"ETHUSDT","exchangeEventTimeMillis":1784429113668,"localReceivedEpochMillis":1784429113662,"topSpreadTicks":7,"bid5Volume":4236,"ask5Volume":4321,"bid10Volume":8280,"ask10Volume":16651,"rawPayload":"{\"stream\":\"ethusdt@depth@100ms\",\"data\":{\"e\":\"depthUpdate\",\"E\":1784429113668,\"s\":\"ETHUSDT\",\"U\":2806161777,\"u\":2806161780,\"b\":[[\"1872.97000000\",\"0.00000000\"],[\"1872.90000000\",\"1.11580000\"]],\"a\":[[\"1873.47000000\",\"1.18060000\"],[\"1873.54000000\",\"0.00000000\"]]}}"}
{"mode":"v9-depth-v5-spsc","workers":4,"sequenceNumber":55,"symbol":"ETHUSDT","exchangeEventTimeMillis":1784429114269,"localReceivedEpochMillis":1784429114263,"topSpreadTicks":6,"bid5Volume":5899,"ask5Volume":4234,"bid10Volume":10216,"ask10Volume":16564,"rawPayload":"{\"stream\":\"ethusdt@depth@100ms\",\"data\":{\"e\":\"depthUpdate\",\"E\":1784429114269,\"s\":\"ETHUSDT\",\"U\":2806161781,\"u\":2806161804,\"b\":[[\"1873.05000000\",\"1.12580000\"],[\"1872.97000000\",\"0.00000000\"],[\"1872.90000000\",\"0.00000000\"],[\"1872.88000000\",\"2.08570000\"],[\"1872.78000000\",\"1.06830000\"],[\"1872.75000000\",\"0.00000000\"],[\"1872.74000000\",\"0.00000000\"],[\"1872.63000000\",\"0.00000000\"],[\"1872.56000000\",\"0.00000000\"],[\"1872.33000000\",\"1.60250000\"],[\"1872.14000000\",\"0.00000000\"],[\"1865.42000000\",\"7.21760000\"],[\"1864.19000000\",\"0.00000000\"]],\"a\":[[\"1873.26000000\",\"0.00000000\"],[\"1873.44000000\",\"1.33530000\"],[\"1873.47000000\",\"0.00000000\"],[\"1873.54000000\",\"0.00000000\"],[\"1873.62000000\",\"1.09330000\"],[\"1880.36000000\",\"0.00000000\"],[\"1880.40000000\",\"7.15450000\"],[\"1881.74000000\",\"0.00000000\"]]}}"}
{"mode":"v9-depth-v5-spsc","workers":4,"sequenceNumber":56,"symbol":"ETHUSDT","exchangeEventTimeMillis":1784429114369,"localReceivedEpochMillis":1784429114394,"topSpreadTicks":29,"bid5Volume":5899,"ask5Volume":6339,"bid10Volume":11789,"ask10Volume":25710,"rawPayload":"{\"stream\":\"ethusdt@depth@100ms\",\"data\":{\"e\":\"depthUpdate\",\"E\":1784429114369,\"s\":\"ETHUSDT\",\"U\":2806161805,\"u\":2806161807,\"b\":[[\"1872.60000000\",\"0.00000000\"]],\"a\":[[\"1873.11000000\",\"0.00000000\"],[\"1873.34000000\",\"0.13870000\"],[\"1873.36000000\",\"0.00000000\"]]}}"}
{"mode":"v9-depth-v5-spsc","workers":4,"sequenceNumber":57,"symbol":"ETHUSDT","exchangeEventTimeMillis":1784429114469,"localReceivedEpochMillis":1784429114463,"topSpreadTicks":21,"bid5Volume":5105,"ask5Volume":4234,"bid10Volume":8617,"ask10Volume":16564,"rawPayload":"{\"stream\":\"ethusdt@depth@100ms\",\"data\":{\"e\":\"depthUpdate\",\"E\":1784429114469,\"s\":\"ETHUSDT\",\"U\":2806161808,\"u\":2806161813,\"b\":[[\"1873.06000000\",\"0.79090000\"],[\"1872.88000000\",\"1.33570000\"],[\"1872.77000000\",\"0.02940000\"]],\"a\":[[\"1873.27000000\",\"0.02970000\"],[\"1880.40000000\",\"0.00000000\"],[\"1880.54000000\",\"0.00000000\"]]}}"}
{"mode":"v9-depth-v5-spsc","workers":4,"sequenceNumber":58,"symbol":"ETHUSDT","exchangeEventTimeMillis":1784429114669,"localReceivedEpochMillis":1784429114662,"topSpreadTicks":21,"bid5Volume":5105,"ask5Volume":4234,"bid10Volume":8617,"ask10Volume":16564,"rawPayload":"{\"stream\":\"ethusdt@depth@100ms\",\"data\":{\"e\":\"depthUpdate\",\"E\":1784429114669,\"s\":\"ETHUSDT\",\"U\":2806161814,\"u\":2806161817,\"b\":[[\"1872.42000000\",\"1.03710000\"],[\"1872.39000000\",\"0.00000000\"],[\"1865.58000000\",\"7.23750000\"],[\"1864.24000000\",\"0.00000000\"]],\"a\":[[\"1880.56000000\",\"7.22320000\"]]}}"}
{"mode":"v9-depth-v5-spsc","workers":4,"sequenceNumber":59,"symbol":"ETHUSDT","exchangeEventTimeMillis":1784429114769,"localReceivedEpochMillis":1784429114774,"topSpreadTicks":28,"bid5Volume":5105,"ask5Volume":6339,"bid10Volume":10227,"ask10Volume":25710,"rawPayload":"{\"stream\":\"ethusdt@depth@100ms\",\"data\":{\"e\":\"depthUpdate\",\"E\":1784429114769,\"s\":\"ETHUSDT\",\"U\":2806161818,\"u\":2806161825,\"b\":[[\"1872.84000000\",\"1.06820000\"],[\"1872.78000000\",\"0.00000000\"],[\"1872.77000000\",\"0.00000000\"],[\"1872.66000000\",\"1.63970000\"],[\"1871.72000000\",\"0.00000000\"]],\"a\":[[\"1873.27000000\",\"0.00000000\"],[\"1880.56000000\",\"0.00000000\"],[\"1880.59000000\",\"0.00000000\"]]}}"}
{"mode":"v9-depth-v5-spsc","workers":4,"sequenceNumber":60,"symbol":"ETHUSDT","exchangeEventTimeMillis":1784429114869,"localReceivedEpochMillis":1784429114874,"topSpreadTicks":38,"bid5Volume":5105,"ask5Volume":4867,"bid10Volume":10226,"ask10Volume":16535,"rawPayload":"{\"stream\":\"ethusdt@depth@100ms\",\"data\":{\"e\":\"depthUpdate\",\"E\":1784429114869,\"s\":\"ETHUSDT\",\"U\":2806161826,\"u\":2806161830,\"b\":[[\"1872.80000000\",\"0.13880000\"],[\"1872.70000000\",\"0.00000000\"],[\"1872.50000000\",\"1.47330000\"],[\"1872.40000000\",\"0.00000000\"]],\"a\":[[\"1873.34000000\",\"0.00000000\"],[\"1873.47000000\",\"0.13870000\"],[\"1873.66000000\",\"0.66220000\"],[\"1873.77000000\",\"1.47290000\"],[\"1874.59000000\",\"0.00000000\"],[\"1874.82000000\",\"9.17420000\"]]}}"}
{"mode":"v9-depth-v5-spsc","workers":4,"sequenceNumber":61,"symbol":"BTCUSDT","exchangeEventTimeMillis":1784429114969,"localReceivedEpochMillis":1784429114989,"topSpreadTicks":498,"bid5Volume":139,"ask5Volume":123,"bid10Volume":298,"ask10Volume":543,"rawPayload":"{\"stream\":\"btcusdt@depth@100ms\",\"data\":{\"e\":\"depthUpdate\",\"E\":1784429114969,\"s\":\"BTCUSDT\",\"U\":3244433952,\"u\":3244433953,\"b\":[],\"a\":[[\"64854.93000000\",\"0.00000000\"],[\"64857.06000000\",\"0.00168000\"]]}}"}
{"mode":"v9-depth-v5-spsc","workers":4,"sequenceNumber":62,"symbol":"ETHUSDT","exchangeEventTimeMillis":1784429114969,"localReceivedEpochMillis":1784429114990,"topSpreadTicks":38,"bid5Volume":5105,"ask5Volume":4867,"bid10Volume":10226,"ask10Volume":16535,"rawPayload":"{\"stream\":\"ethusdt@depth@100ms\",\"data\":{\"e\":\"depthUpdate\",\"E\":1784429114969,\"s\":\"ETHUSDT\",\"U\":2806161831,\"u\":2806161833,\"b\":[[\"1865.63000000\",\"7.16060000\"],[\"1864.29000000\",\"0.00000000\"]],\"a\":[[\"1880.61000000\",\"7.15650000\"]]}}"}
{"mode":"v9-depth-v5-spsc","workers":4,"sequenceNumber":63,"symbol":"BTCUSDT","exchangeEventTimeMillis":1784429115069,"localReceivedEpochMillis":1784429115104,"topSpreadTicks":493,"bid5Volume":139,"ask5Volume":111,"bid10Volume":298,"ask10Volume":295,"rawPayload":"{\"stream\":\"btcusdt@depth@100ms\",\"data\":{\"e\":\"depthUpdate\",\"E\":1784429115069,\"s\":\"BTCUSDT\",\"U\":3244433954,\"u\":3244433955,\"b\":[[\"64823.06000000\",\"0.02921000\"],[\"64822.41000000\",\"0.00000000\"]],\"a\":[[\"64842.61000000\",\"0.03001000\"]]}}"}
{"mode":"v9-depth-v5-spsc","workers":4,"sequenceNumber":64,"symbol":"ETHUSDT","exchangeEventTimeMillis":1784429115169,"localReceivedEpochMillis":1784429115172,"topSpreadTicks":38,"bid5Volume":5105,"ask5Volume":4867,"bid10Volume":10226,"ask10Volume":16535,"rawPayload":"{\"stream\":\"ethusdt@depth@100ms\",\"data\":{\"e\":\"depthUpdate\",\"E\":1784429115169,\"s\":\"ETHUSDT\",\"U\":2806161834,\"u\":2806161834,\"b\":[],\"a\":[[\"1881.74000000\",\"9.13600000\"]]}}"}
{"mode":"v9-depth-v5-spsc","workers":4,"sequenceNumber":65,"symbol":"ETHUSDT","exchangeEventTimeMillis":1784429115269,"localReceivedEpochMillis":1784429115310,"topSpreadTicks":38,"bid5Volume":5105,"ask5Volume":4867,"bid10Volume":10226,"ask10Volume":16535,"rawPayload":"{\"stream\":\"ethusdt@depth@100ms\",\"data\":{\"e\":\"depthUpdate\",\"E\":1784429115269,\"s\":\"ETHUSDT\",\"U\":2806161835,\"u\":2806161835,\"b\":[],\"a\":[[\"1881.80000000\",\"9.17000000\"]]}}"}
{"mode":"v9-depth-v5-spsc","workers":4,"sequenceNumber":66,"symbol":"ETHUSDT","exchangeEventTimeMillis":1784429115469,"localReceivedEpochMillis":1784429115516,"topSpreadTicks":38,"bid5Volume":5105,"ask5Volume":4867,"bid10Volume":10226,"ask10Volume":16535,"rawPayload":"{\"stream\":\"ethusdt@depth@100ms\",\"data\":{\"e\":\"depthUpdate\",\"E\":1784429115469,\"s\":\"ETHUSDT\",\"U\":2806161836,\"u\":2806161836,\"b\":[],\"a\":[[\"1881.86000000\",\"9.28750000\"]]}}"}
{"mode":"v9-depth-v5-spsc","workers":4,"sequenceNumber":67,"symbol":"ETHUSDT","exchangeEventTimeMillis":1784429115569,"localReceivedEpochMillis":1784429115584,"topSpreadTicks":30,"bid5Volume":4066,"ask5Volume":4234,"bid10Volume":9218,"ask10Volume":16093,"rawPayload":"{\"stream\":\"ethusdt@depth@100ms\",\"data\":{\"e\":\"depthUpdate\",\"E\":1784429115569,\"s\":\"ETHUSDT\",\"U\":2806161837,\"u\":2806161838,\"b\":[[\"1872.86000000\",\"0.02960000\"]],\"a\":[[\"1873.36000000\",\"0.02970000\"]]}}"}
{"mode":"v9-depth-v5-spsc","workers":4,"sequenceNumber":68,"symbol":"BTCUSDT","exchangeEventTimeMillis":1784429115870,"localReceivedEpochMillis":1784429115903,"topSpreadTicks":493,"bid5Volume":139,"ask5Volume":111,"bid10Volume":298,"ask10Volume":295,"rawPayload":"{\"stream\":\"btcusdt@depth@100ms\",\"data\":{\"e\":\"depthUpdate\",\"E\":1784429115870,\"s\":\"BTCUSDT\",\"U\":3244433956,\"u\":3244433957,\"b\":[],\"a\":[[\"64914.49000000\",\"0.00011000\"]]}}"}
{"mode":"v9-depth-v5-spsc","workers":4,"sequenceNumber":69,"symbol":"BTCUSDT","exchangeEventTimeMillis":1784429116070,"localReceivedEpochMillis":1784429116105,"topSpreadTicks":493,"bid5Volume":139,"ask5Volume":111,"bid10Volume":298,"ask10Volume":295,"rawPayload":"{\"stream\":\"btcusdt@depth@100ms\",\"data\":{\"e\":\"depthUpdate\",\"E\":1784429116070,\"s\":\"BTCUSDT\",\"U\":3244433958,\"u\":3244433958,\"b\":[],\"a\":[[\"81072.08000000\",\"0.00060000\"]]}}"}
{"mode":"v9-depth-v5-spsc","workers":4,"sequenceNumber":70,"symbol":"ETHUSDT","exchangeEventTimeMillis":1784429116270,"localReceivedEpochMillis":1784429116268,"topSpreadTicks":30,"bid5Volume":4066,"ask5Volume":4234,"bid10Volume":9218,"ask10Volume":16093,"rawPayload":"{\"stream\":\"ethusdt@depth@100ms\",\"data\":{\"e\":\"depthUpdate\",\"E\":1784429116270,\"s\":\"ETHUSDT\",\"U\":2806161839,\"u\":2806161842,\"b\":[[\"1872.84000000\",\"0.00000000\"],[\"1872.78000000\",\"1.06830000\"],[\"1871.80000000\",\"2.13650000\"],[\"1871.42000000\",\"0.00000000\"]],\"a\":[]}}"}
{"mode":"v9-depth-v5-spsc","workers":4,"sequenceNumber":71,"symbol":"ETHUSDT","exchangeEventTimeMillis":1784429117571,"localReceivedEpochMillis":1784429117588,"topSpreadTicks":27,"bid5Volume":2869,"ask5Volume":4234,"bid10Volume":9218,"ask10Volume":16093,"rawPayload":"{\"stream\":\"ethusdt@depth@100ms\",\"data\":{\"e\":\"depthUpdate\",\"E\":1784429117571,\"s\":\"ETHUSDT\",\"U\":2806161843,\"u\":2806161846,\"b\":[[\"1872.88000000\",\"0.00000000\"],[\"1872.73000000\",\"1.33580000\"]],\"a\":[[\"1873.33000000\",\"1.33540000\"],[\"1873.44000000\",\"0.00000000\"]]}}"}
{"mode":"v9-depth-v5-spsc","workers":4,"sequenceNumber":72,"symbol":"ETHUSDT","exchangeEventTimeMillis":1784429117871,"localReceivedEpochMillis":1784429117864,"topSpreadTicks":27,"bid5Volume":2904,"ask5Volume":4254,"bid10Volume":9253,"ask10Volume":16113,"rawPayload":"{\"stream\":\"ethusdt@depth@100ms\",\"data\":{\"e\":\"depthUpdate\",\"E\":1784429117871,\"s\":\"ETHUSDT\",\"U\":2806161847,\"u\":2806161850,\"b\":[[\"1873.05000000\",\"0.00000000\"],[\"1872.98000000\",\"1.16020000\"]],\"a\":[[\"1873.55000000\",\"1.11350000\"],[\"1873.62000000\",\"0.00000000\"]]}}"}
{"mode":"v9-depth-v5-spsc","workers":4,"sequenceNumber":73,"symbol":"BTCUSDT","exchangeEventTimeMillis":1784429118271,"localReceivedEpochMillis":1784429118273,"topSpreadTicks":493,"bid5Volume":139,"ask5Volume":111,"bid10Volume":298,"ask10Volume":295,"rawPayload":"{\"stream\":\"btcusdt@depth@100ms\",\"data\":{\"e\":\"depthUpdate\",\"E\":1784429118271,\"s\":\"BTCUSDT\",\"U\":3244433959,\"u\":3244433964,\"b\":[[\"64768.35000000\",\"0.05625000\"],[\"64766.71000000\",\"0.00000000\"],[\"64729.44000000\",\"0.09097000\"],[\"64727.80000000\",\"0.00000000\"],[\"64690.53000000\",\"0.17358000\"],[\"64688.90000000\",\"0.00000000\"],[\"64612.72000000\",\"0.43131000\"],[\"64611.08000000\",\"0.00000000\"]],\"a\":[[\"64922.28000000\",\"0.00000000\"],[\"64923.92000000\",\"0.06165000\"],[\"65077.91000000\",\"0.00000000\"],[\"65079.55000000\",\"0.42748000\"]]}}"}
{"mode":"v9-depth-v5-spsc","workers":4,"sequenceNumber":74,"symbol":"ETHUSDT","exchangeEventTimeMillis":1784429118672,"localReceivedEpochMillis":1784429118666,"topSpreadTicks":27,"bid5Volume":3834,"ask5Volume":4254,"bid10Volume":10290,"ask10Volume":16114,"rawPayload":"{\"stream\":\"ethusdt@depth@100ms\",\"data\":{\"e\":\"depthUpdate\",\"E\":1784429118672,\"s\":\"ETHUSDT\",\"U\":2806161851,\"u\":2806161854,\"b\":[[\"1872.80000000\",\"0.00000000\"],[\"1872.72000000\",\"0.13880000\"],[\"1872.50000000\",\"0.00000000\"],[\"1872.42000000\",\"2.51090000\"]],\"a\":[[\"1873.39000000\",\"0.13870000\"],[\"1873.47000000\",\"0.00000000\"],[\"1873.69000000\",\"1.47300000\"],[\"1873.77000000\",\"0.00000000\"]]}}"}
{"mode":"v9-depth-v5-spsc","workers":4,"sequenceNumber":75,"symbol":"ETHUSDT","exchangeEventTimeMillis":1784429118972,"localReceivedEpochMillis":1784429118965,"topSpreadTicks":27,"bid5Volume":3867,"ask5Volume":4265,"bid10Volume":10323,"ask10Volume":16125,"rawPayload":"{\"stream\":\"ethusdt@depth@100ms\",\"data\":{\"e\":\"depthUpdate\",\"E\":1784429118972,\"s\":\"ETHUSDT\",\"U\":2806161855,\"u\":2806161858,\"b\":[[\"1873.05000000\",\"1.19360000\"],[\"1872.98000000\",\"0.00000000\"]],\"a\":[[\"1873.55000000\",\"0.00000000\"],[\"1873.62000000\",\"1.12480000\"]]}}"}
{"mode":"v9-depth-v5-spsc","workers":4,"sequenceNumber":76,"symbol":"ETHUSDT","exchangeEventTimeMillis":1784429119372,"localReceivedEpochMillis":1784429119367,"topSpreadTicks":13,"bid5Volume":3533,"ask5Volume":4304,"bid10Volume":8961,"ask10Volume":16164,"rawPayload":"{\"stream\":\"ethusdt@depth@100ms\",\"data\":{\"e\":\"depthUpdate\",\"E\":1784429119372,\"s\":\"ETHUSDT\",\"U\":2806161859,\"u\":2806161888,\"b\":[[\"1873.05000000\",\"0.00000000\"],[\"1872.98000000\",\"0.00000000\"],[\"1872.92000000\",\"1.09320000\"],[\"1872.78000000\",\"0.00000000\"],[\"1872.73000000\",\"0.00000000\"],[\"1872.72000000\",\"0.13880000\"],[\"1872.66000000\",\"0.00000000\"],[\"1872.58000000\",\"1.33590000\"],[\"1872.45000000\",\"0.84370000\"],[\"1872.42000000\",\"1.47380000\"],[\"1872.33000000\",\"1.03710000\"],[\"1872.14000000\",\"1.30710000\"],[\"1871.80000000\",\"0.00000000\"],[\"1871.42000000\",\"1.98790000\"],[\"1865.63000000\",\"0.00000000\"],[\"1865.61000000\",\"7.19090000\"],[\"1865.58000000\",\"0.00000000\"],[\"1865.50000000\",\"7.94970000\"],[\"1864.42000000\",\"0.00000000\"],[\"1864.36000000\",\"5.46570000\"]],\"a\":[[\"1873.19000000\",\"1.33550000\"],[\"1873.33000000\",\"0.00000000\"],[\"1873.50000000\",\"1.16310000\"],[\"1873.55000000\",\"0.00000000\"],[\"1873.62000000\",\"0.00000000\"],[\"1880.59000000\",\"7.26620000\"],[\"1881.86000000\",\"0.00000000\"]]}}"}
{"mode":"v9-depth-v5-spsc","workers":4,"sequenceNumber":77,"symbol":"BTCUSDT","exchangeEventTimeMillis":1784429119372,"localReceivedEpochMillis":1784429119368,"topSpreadTicks":493,"bid5Volume":143,"ask5Volume":111,"bid10Volume":302,"ask10Volume":295,"rawPayload":"{\"stream\":\"btcusdt@depth@100ms\",\"data\":{\"e\":\"depthUpdate\",\"E\":1784429119372,\"s\":\"BTCUSDT\",\"U\":3244433965,\"u\":3244433966,\"b\":[[\"64834.77000000\",\"0.00000000\"],[\"64833.01000000\",\"0.03086000\"]],\"a\":[]}}"}
{"mode":"v9-depth-v5-spsc","workers":4,"sequenceNumber":78,"symbol":"ETHUSDT","exchangeEventTimeMillis":1784429119472,"localReceivedEpochMillis":1784429119466,"topSpreadTicks":15,"bid5Volume":4187,"ask5Volume":4937,"bid10Volume":29697,"ask10Volume":16606,"rawPayload":"{\"stream\":\"ethusdt@depth@100ms\",\"data\":{\"e\":\"depthUpdate\",\"E\":1784429119472,\"s\":\"ETHUSDT\",\"U\":2806161889,\"u\":2806161891,\"b\":[[\"1873.06000000\",\"0.00000000\"],[\"1872.86000000\",\"0.00000000\"]],\"a\":[[\"1873.36000000\",\"0.00000000\"]]}}"}
{"mode":"v9-depth-v5-spsc","workers":4,"sequenceNumber":79,"symbol":"ETHUSDT","exchangeEventTimeMillis":1784429119572,"localReceivedEpochMillis":1784429119567,"topSpreadTicks":15,"bid5Volume":4187,"ask5Volume":4937,"bid10Volume":29697,"ask10Volume":16606,"rawPayload":"{\"stream\":\"ethusdt@depth@100ms\",\"data\":{\"e\":\"depthUpdate\",\"E\":1784429119572,\"s\":\"ETHUSDT\",\"U\":2806161892,\"u\":2806161893,\"b\":[[\"1865.61000000\",\"0.00000000\"],[\"1865.50000000\",\"0.00000000\"]],\"a\":[]}}"}
{"mode":"v9-depth-v5-spsc","workers":4,"sequenceNumber":80,"symbol":"BTCUSDT","exchangeEventTimeMillis":1784429119572,"localReceivedEpochMillis":1784429119567,"topSpreadTicks":493,"bid5Volume":143,"ask5Volume":103,"bid10Volume":302,"ask10Volume":295,"rawPayload":"{\"stream\":\"btcusdt@depth@100ms\",\"data\":{\"e\":\"depthUpdate\",\"E\":1784429119572,\"s\":\"BTCUSDT\",\"U\":3244433967,\"u\":3244433968,\"b\":[],\"a\":[[\"64849.71000000\",\"0.03857000\"],[\"64855.37000000\",\"0.00000000\"]]}}"}
{"mode":"v9-depth-v5-spsc","workers":4,"sequenceNumber":81,"symbol":"BTCUSDT","exchangeEventTimeMillis":1784429119672,"localReceivedEpochMillis":1784429119667,"topSpreadTicks":493,"bid5Volume":143,"ask5Volume":103,"bid10Volume":302,"ask10Volume":295,"rawPayload":"{\"stream\":\"btcusdt@depth@100ms\",\"data\":{\"e\":\"depthUpdate\",\"E\":1784429119672,\"s\":\"BTCUSDT\",\"U\":3244433969,\"u\":3244433969,\"b\":[],\"a\":[[\"64914.49000000\",\"0.00000000\"]]}}"}
{"mode":"v9-depth-v5-spsc","workers":4,"sequenceNumber":82,"symbol":"ETHUSDT","exchangeEventTimeMillis":1784429119672,"localReceivedEpochMillis":1784429119667,"topSpreadTicks":15,"bid5Volume":4187,"ask5Volume":4937,"bid10Volume":29697,"ask10Volume":16606,"rawPayload":"{\"stream\":\"ethusdt@depth@100ms\",\"data\":{\"e\":\"depthUpdate\",\"E\":1784429119672,\"s\":\"ETHUSDT\",\"U\":2806161894,\"u\":2806161896,\"b\":[[\"1864.41000000\",\"9.13670000\"]],\"a\":[[\"1880.41000000\",\"7.19610000\"],[\"1881.80000000\",\"0.00000000\"]]}}"}
{"mode":"v9-depth-v5-spsc","workers":4,"sequenceNumber":83,"symbol":"BTCUSDT","exchangeEventTimeMillis":1784429119772,"localReceivedEpochMillis":1784429119767,"topSpreadTicks":493,"bid5Volume":143,"ask5Volume":103,"bid10Volume":302,"ask10Volume":295,"rawPayload":"{\"stream\":\"btcusdt@depth@100ms\",\"data\":{\"e\":\"depthUpdate\",\"E\":1784429119772,\"s\":\"BTCUSDT\",\"U\":3244433970,\"u\":3244433970,\"b\":[],\"a\":[[\"64914.49000000\",\"0.00011000\"]]}}"}
{"mode":"v9-depth-v5-spsc","workers":4,"sequenceNumber":84,"symbol":"ETHUSDT","exchangeEventTimeMillis":1784429119772,"localReceivedEpochMillis":1784429119767,"topSpreadTicks":15,"bid5Volume":4187,"ask5Volume":5078,"bid10Volume":29697,"ask10Volume":16938,"rawPayload":"{\"stream\":\"ethusdt@depth@100ms\",\"data\":{\"e\":\"depthUpdate\",\"E\":1784429119772,\"s\":\"ETHUSDT\",\"U\":2806161897,\"u\":2806161897,\"b\":[],\"a\":[[\"1873.27000000\",\"0.80380000\"]]}}"}
{"mode":"v9-depth-v5-spsc","workers":4,"sequenceNumber":85,"symbol":"ETHUSDT","exchangeEventTimeMillis":1784429119872,"localReceivedEpochMillis":1784429119866,"topSpreadTicks":15,"bid5Volume":4187,"ask5Volume":5078,"bid10Volume":29697,"ask10Volume":16938,"rawPayload":"{\"stream\":\"ethusdt@depth@100ms\",\"data\":{\"e\":\"depthUpdate\",\"E\":1784429119872,\"s\":\"ETHUSDT\",\"U\":2806161898,\"u\":2806161899,\"b\":[[\"1871.85000000\",\"1.63970000\"],[\"1864.34000000\",\"9.18420000\"]],\"a\":[]}}"}
{"mode":"v9-depth-v5-spsc","workers":4,"sequenceNumber":86,"symbol":"ETHUSDT","exchangeEventTimeMillis":1784429120072,"localReceivedEpochMillis":1784429120066,"topSpreadTicks":15,"bid5Volume":4187,"ask5Volume":5078,"bid10Volume":29697,"ask10Volume":16938,"rawPayload":"{\"stream\":\"ethusdt@depth@100ms\",\"data\":{\"e\":\"depthUpdate\",\"E\":1784429120072,\"s\":\"ETHUSDT\",\"U\":2806161900,\"u\":2806161900,\"b\":[[\"1864.28000000\",\"9.16900000\"]],\"a\":[]}}"}
{"mode":"v9-depth-v5-spsc","workers":4,"sequenceNumber":87,"symbol":"ETHUSDT","exchangeEventTimeMillis":1784429120173,"localReceivedEpochMillis":1784429120166,"topSpreadTicks":15,"bid5Volume":4187,"ask5Volume":5078,"bid10Volume":29697,"ask10Volume":16938,"rawPayload":"{\"stream\":\"ethusdt@depth@100ms\",\"data\":{\"e\":\"depthUpdate\",\"E\":1784429120173,\"s\":\"ETHUSDT\",\"U\":2806161901,\"u\":2806161901,\"b\":[[\"1864.22000000\",\"9.32280000\"]],\"a\":[]}}"}
{"mode":"v9-depth-v5-spsc","workers":4,"sequenceNumber":88,"symbol":"ETHUSDT","exchangeEventTimeMillis":1784429120373,"localReceivedEpochMillis":1784429120366,"topSpreadTicks":15,"bid5Volume":4187,"ask5Volume":4937,"bid10Volume":29697,"ask10Volume":16606,"rawPayload":"{\"stream\":\"ethusdt@depth@100ms\",\"data\":{\"e\":\"depthUpdate\",\"E\":1784429120373,\"s\":\"ETHUSDT\",\"U\":2806161902,\"u\":2806161902,\"b\":[],\"a\":[[\"1873.27000000\",\"0.00000000\"]]}}"}
{"mode":"v9-depth-v5-spsc","workers":4,"sequenceNumber":89,"symbol":"BTCUSDT","exchangeEventTimeMillis":1784429120573,"localReceivedEpochMillis":1784429120566,"topSpreadTicks":493,"bid5Volume":143,"ask5Volume":103,"bid10Volume":302,"ask10Volume":295,"rawPayload":"{\"stream\":\"btcusdt@depth@100ms\",\"data\":{\"e\":\"depthUpdate\",\"E\":1784429120573,\"s\":\"BTCUSDT\",\"U\":3244433971,\"u\":3244433971,\"b\":[],\"a\":[[\"81072.08000000\",\"0.00060000\"]]}}"}
{"mode":"v9-depth-v5-spsc","workers":4,"sequenceNumber":90,"symbol":"ETHUSDT","exchangeEventTimeMillis":1784429120573,"localReceivedEpochMillis":1784429120566,"topSpreadTicks":11,"bid5Volume":2881,"ask5Volume":4304,"bid10Volume":9208,"ask10Volume":16164,"rawPayload":"{\"stream\":\"ethusdt@depth@100ms\",\"data\":{\"e\":\"depthUpdate\",\"E\":1784429120573,\"s\":\"ETHUSDT\",\"U\":2806161903,\"u\":2806161904,\"b\":[[\"1872.66000000\",\"0.02940000\"]],\"a\":[[\"1873.15000000\",\"0.02940000\"]]}}"}
{"mode":"v9-depth-v5-spsc","workers":4,"sequenceNumber":91,"symbol":"BTCUSDT","exchangeEventTimeMillis":1784429120873,"localReceivedEpochMillis":1784429120867,"topSpreadTicks":493,"bid5Volume":143,"ask5Volume":103,"bid10Volume":302,"ask10Volume":295,"rawPayload":"{\"stream\":\"btcusdt@depth@100ms\",\"data\":{\"e\":\"depthUpdate\",\"E\":1784429120873,\"s\":\"BTCUSDT\",\"U\":3244433972,\"u\":3244433972,\"b\":[],\"a\":[[\"81072.08000000\",\"0.00045000\"]]}}"}
{"mode":"v9-depth-v5-spsc","workers":4,"sequenceNumber":92,"symbol":"ETHUSDT","exchangeEventTimeMillis":1784429120973,"localReceivedEpochMillis":1784429120967,"topSpreadTicks":11,"bid5Volume":2910,"ask5Volume":4265,"bid10Volume":9237,"ask10Volume":16125,"rawPayload":"{\"stream\":\"ethusdt@depth@100ms\",\"data\":{\"e\":\"depthUpdate\",\"E\":1784429120973,\"s\":\"ETHUSDT\",\"U\":2806161905,\"u\":2806161908,\"b\":[[\"1872.92000000\",\"0.00000000\"],[\"1872.83000000\",\"1.12290000\"]],\"a\":[[\"1873.44000000\",\"1.12420000\"],[\"1873.50000000\",\"0.00000000\"]]}}"}
{"mode":"v9-depth-v5-spsc","workers":4,"sequenceNumber":93,"symbol":"BTCUSDT","exchangeEventTimeMillis":1784429121273,"localReceivedEpochMillis":1784429121268,"topSpreadTicks":493,"bid5Volume":143,"ask5Volume":103,"bid10Volume":302,"ask10Volume":295,"rawPayload":"{\"stream\":\"btcusdt@depth@100ms\",\"data\":{\"e\":\"depthUpdate\",\"E\":1784429121273,\"s\":\"BTCUSDT\",\"U\":3244433973,\"u\":3244433973,\"b\":[[\"64823.06000000\",\"0.00000000\"],[\"64820.66000000\",\"0.02921000\"]],\"a\":[]}}"}
{"mode":"v9-depth-v5-spsc","workers":4,"sequenceNumber":94,"symbol":"ETHUSDT","exchangeEventTimeMillis":1784429121874,"localReceivedEpochMillis":1784429121868,"topSpreadTicks":11,"bid5Volume":2910,"ask5Volume":4265,"bid10Volume":9237,"ask10Volume":16125,"rawPayload":"{\"stream\":\"ethusdt@depth@100ms\",\"data\":{\"e\":\"depthUpdate\",\"E\":1784429121874,\"s\":\"ETHUSDT\",\"U\":2806161909,\"u\":2806161909,\"b\":[[\"1872.43000000\",\"1.03710000\"],[\"1872.33000000\",\"0.00000000\"]],\"a\":[]}}"}
{"mode":"v9-depth-v5-spsc","workers":4,"sequenceNumber":95,"symbol":"ETHUSDT","exchangeEventTimeMillis":1784429122274,"localReceivedEpochMillis":1784429122268,"topSpreadTicks":11,"bid5Volume":2910,"ask5Volume":4265,"bid10Volume":9238,"ask10Volume":16125,"rawPayload":"{\"stream\":\"ethusdt@depth@100ms\",\"data\":{\"e\":\"depthUpdate\",\"E\":1784429122274,\"s\":\"ETHUSDT\",\"U\":2806161910,\"u\":2806161914,\"b\":[[\"1872.72000000\",\"0.00000000\"],[\"1872.61000000\",\"0.13880000\"],[\"1872.42000000\",\"0.00000000\"],[\"1872.31000000\",\"1.47410000\"]],\"a\":[[\"1873.28000000\",\"0.13870000\"],[\"1873.39000000\",\"0.00000000\"],[\"1873.58000000\",\"1.47310000\"],[\"1873.69000000\",\"0.00000000\"],[\"1874.63000000\",\"9.17510000\"],[\"1874.82000000\",\"0.00000000\"]]}}"}
{"mode":"v9-depth-v5-spsc","workers":4,"sequenceNumber":96,"symbol":"BTCUSDT","exchangeEventTimeMillis":1784429122674,"localReceivedEpochMillis":1784429122668,"topSpreadTicks":493,"bid5Volume":143,"ask5Volume":103,"bid10Volume":302,"ask10Volume":295,"rawPayload":"{\"stream\":\"btcusdt@depth@100ms\",\"data\":{\"e\":\"depthUpdate\",\"E\":1784429122674,\"s\":\"BTCUSDT\",\"U\":3244433974,\"u\":3244433974,\"b\":[],\"a\":[[\"81072.08000000\",\"0.00045000\"]]}}"}
{"mode":"v9-depth-v5-spsc","workers":4,"sequenceNumber":97,"symbol":"ETHUSDT","exchangeEventTimeMillis":1784429122874,"localReceivedEpochMillis":1784429122869,"topSpreadTicks":11,"bid5Volume":2910,"ask5Volume":4265,"bid10Volume":9238,"ask10Volume":16125,"rawPayload":"{\"stream\":\"ethusdt@depth@100ms\",\"data\":{\"e\":\"depthUpdate\",\"E\":1784429122874,\"s\":\"ETHUSDT\",\"U\":2806161915,\"u\":2806161921,\"b\":[[\"1871.22000000\",\"2.00940000\"],[\"1871.16000000\",\"0.00000000\"],[\"1870.09000000\",\"3.17660000\"],[\"1870.04000000\",\"0.00000000\"],[\"1868.97000000\",\"5.91250000\"],[\"1868.92000000\",\"0.00000000\"],[\"1866.72000000\",\"14.53840000\"],[\"1866.67000000\",\"0.00000000\"]],\"a\":[[\"1875.67000000\",\"0.00000000\"],[\"1875.72000000\",\"2.04290000\"],[\"1876.79000000\",\"0.00000000\"],[\"1876.85000000\",\"2.94890000\"],[\"1877.92000000\",\"0.00000000\"],[\"1877.97000000\",\"5.84980000\"]]}}"}
{"mode":"v9-depth-v5-spsc","workers":4,"sequenceNumber":98,"symbol":"BTCUSDT","exchangeEventTimeMillis":1784429123475,"localReceivedEpochMillis":1784429123467,"topSpreadTicks":493,"bid5Volume":143,"ask5Volume":103,"bid10Volume":302,"ask10Volume":295,"rawPayload":"{\"stream\":\"btcusdt@depth@100ms\",\"data\":{\"e\":\"depthUpdate\",\"E\":1784429123475,\"s\":\"BTCUSDT\",\"U\":3244433975,\"u\":3244433975,\"b\":[],\"a\":[[\"64914.49000000\",\"0.00000000\"]]}}"}
{"mode":"v9-depth-v5-spsc","workers":4,"sequenceNumber":99,"symbol":"BTCUSDT","exchangeEventTimeMillis":1784429123575,"localReceivedEpochMillis":1784429123570,"topSpreadTicks":493,"bid5Volume":143,"ask5Volume":103,"bid10Volume":302,"ask10Volume":295,"rawPayload":"{\"stream\":\"btcusdt@depth@100ms\",\"data\":{\"e\":\"depthUpdate\",\"E\":1784429123575,\"s\":\"BTCUSDT\",\"U\":3244433976,\"u\":3244433976,\"b\":[],\"a\":[[\"64914.49000000\",\"0.00011000\"]]}}"}
{"mode":"v9-depth-v5-spsc","workers":4,"sequenceNumber":100,"symbol":"BTCUSDT","exchangeEventTimeMillis":1784429123975,"localReceivedEpochMillis":1784429123969,"topSpreadTicks":493,"bid5Volume":143,"ask5Volume":103,"bid10Volume":302,"ask10Volume":295,"rawPayload":"{\"stream\":\"btcusdt@depth@100ms\",\"data\":{\"e\":\"depthUpdate\",\"E\":1784429123975,\"s\":\"BTCUSDT\",\"U\":3244433977,\"u\":3244433977,\"b\":[],\"a\":[[\"81072.08000000\",\"0.00030000\"]]}}"}
