{"mode":"v11-raw-disruptor","partitions":4,"sequenceNumber":402,"routingSymbol":"BTCUSDT","localReceivedEpochMillis":1784431341946,"rawPayload":"{\"stream\":\"btcusdt@depth@100ms\",\"data\":{\"e\":\"depthUpdate\",\"E\":1784431341956,\"s\":\"BTCUSDT\",\"U\":3244451821,\"u\":3244451823,\"b\":[[\"64594.91000000\",\"0.20650000\"],[\"64388.73000000\",\"0.00000000\"]],\"a\":[[\"64711.25000000\",\"0.20722000\"]]}}"}
{"mode":"v11-raw-disruptor","partitions":4,"sequenceNumber":403,"routingSymbol":"SOLUSDT","localReceivedEpochMillis":1784431341946,"rawPayload":"{\"stream\":\"solusdt@depth@100ms\",\"data\":{\"e\":\"depthUpdate\",\"E\":1784431341956,\"s\":\"SOLUSDT\",\"U\":1609592178,\"u\":1609592181,\"b\":[[\"75.85000000\",\"60.09500000\"],[\"75.74000000\",\"275.73500000\"]],\"a\":[[\"75.88000000\",\"3.85400000\"],[\"76.14000000\",\"483.20600000\"]]}}"}
{"mode":"v11-raw-disruptor","partitions":4,"sequenceNumber":404,"routingSymbol":"ETHUSDT","localReceivedEpochMillis":1784431341947,"rawPayload":"{\"stream\":\"ethusdt@depth@100ms\",\"data\":{\"e\":\"depthUpdate\",\"E\":1784431341956,\"s\":\"ETHUSDT\",\"U\":2806198500,\"u\":2806198516,\"b\":[[\"1864.42000000\",\"1.93820000\"],[\"1864.37000000\",\"0.00000000\"],[\"1864.31000000\",\"0.00000000\"],[\"1864.11000000\",\"0.00000000\"]],\"a\":[[\"1864.88000000\",\"0.00000000\"],[\"1864.93000000\",\"0.00000000\"],[\"1864.96000000\",\"2.18350000\"],[\"1864.99000000\",\"0.00000000\"],[\"1872.16000000\",\"0.00000000\"],[\"1872.18000000\",\"0.00000000\"],[\"1872.25000000\",\"0.00000000\"],[\"1872.27000000\",\"0.00000000\"]]}}"}
{"mode":"v11-raw-disruptor","partitions":4,"sequenceNumber":405,"routingSymbol":"XRPUSDT","localReceivedEpochMillis":1784431341947,"rawPayload":"{\"stream\":\"xrpusdt@depth@100ms\",\"data\":{\"e\":\"depthUpdate\",\"E\":1784431341957,\"s\":\"XRPUSDT\",\"U\":752712575,\"u\":752712578,\"b\":[[\"1.09360000\",\"2287.40000000\"],[\"1.09350000\",\"2541.10000000\"],[\"1.09330000\",\"189.90000000\"]],\"a\":[[\"1.09740000\",\"16065.50000000\"]]}}"}
{"mode":"v11-raw-disruptor","partitions":4,"sequenceNumber":406,"routingSymbol":"ETHUSDT","localReceivedEpochMillis":1784431342046,"rawPayload":"{\"stream\":\"ethusdt@depth@100ms\",\"data\":{\"e\":\"depthUpdate\",\"E\":1784431342057,\"s\":\"ETHUSDT\",\"U\":2806198517,\"u\":2806198518,\"b\":[[\"1864.42000000\",\"0.81220000\"],[\"1864.35000000\",\"1.18380000\"]],\"a\":[]}}"}
{"mode":"v11-raw-disruptor","partitions":4,"sequenceNumber":407,"routingSymbol":"SOLUSDT","localReceivedEpochMillis":1784431342144,"rawPayload":"{\"stream\":\"solusdt@depth@100ms\",\"data\":{\"e\":\"depthUpdate\",\"E\":1784431342157,\"s\":\"SOLUSDT\",\"U\":1609592182,\"u\":1609592184,\"b\":[],\"a\":[[\"75.88000000\",\"36.82200000\"],[\"75.89000000\",\"0.00000000\"],[\"76.15000000\",\"335.63200000\"]]}}"}
{"mode":"v11-raw-disruptor","partitions":4,"sequenceNumber":408,"routingSymbol":"ETHUSDT","localReceivedEpochMillis":1784431342146,"rawPayload":"{\"stream\":\"ethusdt@depth@100ms\",\"data\":{\"e\":\"depthUpdate\",\"E\":1784431342157,\"s\":\"ETHUSDT\",\"U\":2806198519,\"u\":2806198521,\"b\":[[\"1864.25000000\",\"1.34190000\"],[\"1857.29000000\",\"7.20830000\"],[\"1855.54000000\",\"0.00000000\"]],\"a\":[]}}"}
{"mode":"v11-raw-disruptor","partitions":4,"sequenceNumber":409,"routingSymbol":"BTCUSDT","localReceivedEpochMillis":1784431342146,"rawPayload":"{\"stream\":\"btcusdt@depth@100ms\",\"data\":{\"e\":\"depthUpdate\",\"E\":1784431342157,\"s\":\"BTCUSDT\",\"U\":3244451824,\"u\":3244451824,\"b\":[[\"64642.58000000\",\"0.03870000\"]],\"a\":[]}}"}
{"mode":"v11-raw-disruptor","partitions":4,"sequenceNumber":410,"routingSymbol":"ETHUSDT","localReceivedEpochMillis":1784431342247,"rawPayload":"{\"stream\":\"ethusdt@depth@100ms\",\"data\":{\"e\":\"depthUpdate\",\"E\":1784431342257,\"s\":\"ETHUSDT\",\"U\":2806198522,\"u\":2806198522,\"b\":[[\"1863.07000000\",\"0.00000000\"]],\"a\":[]}}"}
{"mode":"v11-raw-disruptor","partitions":4,"sequenceNumber":411,"routingSymbol":"BTCUSDT","localReceivedEpochMillis":1784431342247,"rawPayload":"{\"stream\":\"btcusdt@depth@100ms\",\"data\":{\"e\":\"depthUpdate\",\"E\":1784431342257,\"s\":\"BTCUSDT\",\"U\":3244451825,\"u\":3244451828,\"b\":[[\"64637.06000000\",\"0.00000000\"],[\"64633.39000000\",\"0.00402000\"],[\"64626.71000000\",\"0.00000000\"],[\"64623.05000000\",\"0.04270000\"]],\"a\":[[\"64656.03000000\",\"0.00402000\"],[\"64659.70000000\",\"0.00000000\"],[\"64666.37000000\",\"0.04268000\"],[\"64670.04000000\",\"0.00000000\"]]}}"}
{"mode":"v11-raw-disruptor","partitions":4,"sequenceNumber":412,"routingSymbol":"XRPUSDT","localReceivedEpochMillis":1784431342247,"rawPayload":"{\"stream\":\"xrpusdt@depth@100ms\",\"data\":{\"e\":\"depthUpdate\",\"E\":1784431342257,\"s\":\"XRPUSDT\",\"U\":752712579,\"u\":752712580,\"b\":[],\"a\":[[\"1.09410000\",\"237.60000000\"],[\"1.09420000\",\"3185.70000000\"]]}}"}
{"mode":"v11-raw-disruptor","partitions":4,"sequenceNumber":413,"routingSymbol":"SOLUSDT","localReceivedEpochMillis":1784431342346,"rawPayload":"{\"stream\":\"solusdt@depth@100ms\",\"data\":{\"e\":\"depthUpdate\",\"E\":1784431342357,\"s\":\"SOLUSDT\",\"U\":1609592185,\"u\":1609592186,\"b\":[[\"75.74000000\",\"284.14000000\"],[\"75.73000000\",\"23.61200000\"]],\"a\":[]}}"}
{"mode":"v11-raw-disruptor","partitions":4,"sequenceNumber":414,"routingSymbol":"ETHUSDT","localReceivedEpochMillis":1784431342349,"rawPayload":"{\"stream\":\"ethusdt@depth@100ms\",\"data\":{\"e\":\"depthUpdate\",\"E\":1784431342357,\"s\":\"ETHUSDT\",\"U\":2806198523,\"u\":2806198527,\"b\":[[\"1864.42000000\",\"1.94980000\"],[\"1864.35000000\",\"0.00000000\"],[\"1863.22000000\",\"0.00000000\"]],\"a\":[[\"1865.68000000\",\"1.63970000\"],[\"1870.20000000\",\"0.00000000\"]]}}"}
{"mode":"v11-raw-disruptor","partitions":4,"sequenceNumber":415,"routingSymbol":"BTCUSDT","localReceivedEpochMillis":1784431342349,"rawPayload":"{\"stream\":\"btcusdt@depth@100ms\",\"data\":{\"e\":\"depthUpdate\",\"E\":1784431342357,\"s\":\"BTCUSDT\",\"U\":3244451829,\"u\":3244451829,\"b\":[[\"64520.07000000\",\"0.29049000\"]],\"a\":[]}}"}
{"mode":"v11-raw-disruptor","partitions":4,"sequenceNumber":416,"routingSymbol":"SOLUSDT","localReceivedEpochMillis":1784431342447,"rawPayload":"{\"stream\":\"solusdt@depth@100ms\",\"data\":{\"e\":\"depthUpdate\",\"E\":1784431342457,\"s\":\"SOLUSDT\",\"U\":1609592187,\"u\":1609592194,\"b\":[[\"75.87000000\",\"0.00000000\"],[\"75.86000000\",\"14.12600000\"],[\"75.85000000\",\"60.09500000\"]],\"a\":[[\"75.90000000\",\"73.65600000\"],[\"75.91000000\",\"18.63500000\"]]}}"}
{"mode":"v11-raw-disruptor","partitions":4,"sequenceNumber":417,"routingSymbol":"ETHUSDT","localReceivedEpochMillis":1784431342447,"rawPayload":"{\"stream\":\"ethusdt@depth@100ms\",\"data\":{\"e\":\"depthUpdate\",\"E\":1784431342457,\"s\":\"ETHUSDT\",\"U\":2806198528,\"u\":2806198528,\"b\":[],\"a\":[[\"1872.19000000\",\"7.23280000\"]]}}"}
{"mode":"v11-raw-disruptor","partitions":4,"sequenceNumber":418,"routingSymbol":"XRPUSDT","localReceivedEpochMillis":1784431342447,"rawPayload":"{\"stream\":\"xrpusdt@depth@100ms\",\"data\":{\"e\":\"depthUpdate\",\"E\":1784431342457,\"s\":\"XRPUSDT\",\"U\":752712581,\"u\":752712583,\"b\":[[\"1.09320000\",\"3517.90000000\"],[\"1.09310000\",\"2074.70000000\"]],\"a\":[[\"1.09510000\",\"7095.80000000\"]]}}"}
{"mode":"v11-raw-disruptor","partitions":4,"sequenceNumber":419,"routingSymbol":"SOLUSDT","localReceivedEpochMillis":1784431342547,"rawPayload":"{\"stream\":\"solusdt@depth@100ms\",\"data\":{\"e\":\"depthUpdate\",\"E\":1784431342557,\"s\":\"SOLUSDT\",\"U\":1609592195,\"u\":1609592195,\"b\":[],\"a\":[[\"76.00000000\",\"367.16700000\"]]}}"}
{"mode":"v11-raw-disruptor","partitions":4,"sequenceNumber":420,"routingSymbol":"ETHUSDT","localReceivedEpochMillis":1784431342547,"rawPayload":"{\"stream\":\"ethusdt@depth@100ms\",\"data\":{\"e\":\"depthUpdate\",\"E\":1784431342557,\"s\":\"ETHUSDT\",\"U\":2806198529,\"u\":2806198529,\"b\":[],\"a\":[[\"1872.26000000\",\"7.90150000\"]]}}"}
{"mode":"v11-raw-disruptor","partitions":4,"sequenceNumber":421,"routingSymbol":"XRPUSDT","localReceivedEpochMillis":1784431342547,"rawPayload":"{\"stream\":\"xrpusdt@depth@100ms\",\"data\":{\"e\":\"depthUpdate\",\"E\":1784431342557,\"s\":\"XRPUSDT\",\"U\":752712584,\"u\":752712591,\"b\":[[\"1.09360000\",\"3245.40000000\"],[\"1.09350000\",\"1535.50000000\"],[\"1.09330000\",\"216.10000000\"],[\"1.09320000\",\"3492.00000000\"]],\"a\":[[\"1.09420000\",\"3203.70000000\"],[\"1.09430000\",\"494.00000000\"],[\"1.09440000\",\"1776.80000000\"]]}}"}
{"mode":"v11-raw-disruptor","partitions":4,"sequenceNumber":422,"routingSymbol":"BNBUSDT","localReceivedEpochMillis":1784431342646,"rawPayload":"{\"stream\":\"bnbusdt@depth@100ms\",\"data\":{\"e\":\"depthUpdate\",\"E\":1784431342657,\"s\":\"BNBUSDT\",\"U\":1236336189,\"u\":1236336189,\"b\":[[\"567.84000000\",\"0.00700000\"]],\"a\":[]}}"}
{"mode":"v11-raw-disruptor","partitions":4,"sequenceNumber":423,"routingSymbol":"SOLUSDT","localReceivedEpochMillis":1784431342646,"rawPayload":"{\"stream\":\"solusdt@depth@100ms\",\"data\":{\"e\":\"depthUpdate\",\"E\":1784431342657,\"s\":\"SOLUSDT\",\"U\":1609592196,\"u\":1609592199,\"b\":[[\"75.86000000\",\"0.00000000\"],[\"75.85000000\",\"74.22900000\"]],\"a\":[[\"75.90000000\",\"87.81700000\"],[\"75.91000000\",\"4.11900000\"]]}}"}
{"mode":"v11-raw-disruptor","partitions":4,"sequenceNumber":424,"routingSymbol":"BTCUSDT","localReceivedEpochMillis":1784431342746,"rawPayload":"{\"stream\":\"btcusdt@depth@100ms\",\"data\":{\"e\":\"depthUpdate\",\"E\":1784431342757,\"s\":\"BTCUSDT\",\"U\":3244451830,\"u\":3244451831,\"b\":[],\"a\":[[\"64668.11000000\",\"0.00752000\"],[\"64674.61000000\",\"0.00000000\"]]}}"}
{"mode":"v11-raw-disruptor","partitions":4,"sequenceNumber":425,"routingSymbol":"ETHUSDT","localReceivedEpochMillis":1784431342747,"rawPayload":"{\"stream\":\"ethusdt@depth@100ms\",\"data\":{\"e\":\"depthUpdate\",\"E\":1784431342757,\"s\":\"ETHUSDT\",\"U\":2806198530,\"u\":2806198530,\"b\":[],\"a\":[[\"1873.28000000\",\"9.10560000\"]]}}"}
{"mode":"v11-raw-disruptor","partitions":4,"sequenceNumber":426,"routingSymbol":"XRPUSDT","localReceivedEpochMillis":1784431342747,"rawPayload":"{\"stream\":\"xrpusdt@depth@100ms\",\"data\":{\"e\":\"depthUpdate\",\"E\":1784431342757,\"s\":\"XRPUSDT\",\"U\":752712592,\"u\":752712595,\"b\":[[\"1.09330000\",\"189.90000000\"],[\"1.09320000\",\"3518.90000000\"]],\"a\":[[\"1.09430000\",\"520.90000000\"],[\"1.09440000\",\"1750.60000000\"]]}}"}
{"mode":"v11-raw-disruptor","partitions":4,"sequenceNumber":427,"routingSymbol":"ETHUSDT","localReceivedEpochMillis":1784431342846,"rawPayload":"{\"stream\":\"ethusdt@depth@100ms\",\"data\":{\"e\":\"depthUpdate\",\"E\":1784431342857,\"s\":\"ETHUSDT\",\"U\":2806198531,\"u\":2806198531,\"b\":[],\"a\":[[\"1873.33000000\",\"9.02740000\"]]}}"}
{"mode":"v11-raw-disruptor","partitions":4,"sequenceNumber":428,"routingSymbol":"BTCUSDT","localReceivedEpochMillis":1784431342846,"rawPayload":"{\"stream\":\"btcusdt@depth@100ms\",\"data\":{\"e\":\"depthUpdate\",\"E\":1784431342857,\"s\":\"BTCUSDT\",\"U\":3244451832,\"u\":3244451834,\"b\":[],\"a\":[[\"64672.64000000\",\"0.00000000\"],[\"64673.82000000\",\"0.00162000\"],[\"64686.85000000\",\"0.07161000\"]]}}"}
{"mode":"v11-raw-disruptor","partitions":4,"sequenceNumber":429,"routingSymbol":"SOLUSDT","localReceivedEpochMillis":1784431343045,"rawPayload":"{\"stream\":\"solusdt@depth@100ms\",\"data\":{\"e\":\"depthUpdate\",\"E\":1784431343057,\"s\":\"SOLUSDT\",\"U\":1609592200,\"u\":1609592204,\"b\":[[\"75.86000000\",\"14.70900000\"],[\"75.85000000\",\"60.09500000\"]],\"a\":[[\"75.90000000\",\"73.65600000\"],[\"75.91000000\",\"48.69700000\"]]}}"}
{"mode":"v11-raw-disruptor","partitions":4,"sequenceNumber":430,"routingSymbol":"ETHUSDT","localReceivedEpochMillis":1784431343045,"rawPayload":"{\"stream\":\"ethusdt@depth@100ms\",\"data\":{\"e\":\"depthUpdate\",\"E\":1784431343057,\"s\":\"ETHUSDT\",\"U\":2806198532,\"u\":2806198534,\"b\":[[\"1864.42000000\",\"0.81220000\"],[\"1864.35000000\",\"1.18510000\"]],\"a\":[[\"1873.38000000\",\"9.14260000\"]]}}"}
{"mode":"v11-raw-disruptor","partitions":4,"sequenceNumber":431,"routingSymbol":"SOLUSDT","localReceivedEpochMillis":1784431343247,"rawPayload":"{\"stream\":\"solusdt@depth@100ms\",\"data\":{\"e\":\"depthUpdate\",\"E\":1784431343257,\"s\":\"SOLUSDT\",\"U\":1609592205,\"u\":1609592206,\"b\":[],\"a\":[[\"75.87000000\",\"2.34300000\"],[\"75.88000000\",\"33.52600000\"]]}}"}
{"mode":"v11-raw-disruptor","partitions":4,"sequenceNumber":432,"routingSymbol":"ETHUSDT","localReceivedEpochMillis":1784431343247,"rawPayload":"{\"stream\":\"ethusdt@depth@100ms\",\"data\":{\"e\":\"depthUpdate\",\"E\":1784431343257,\"s\":\"ETHUSDT\",\"U\":2806198535,\"u\":2806198539,\"b\":[],\"a\":[[\"1864.86000000\",\"0.00000000\"],[\"1864.93000000\",\"1.10420000\"],[\"1864.96000000\",\"1.05640000\"],[\"1873.44000000\",\"9.06900000\"]]}}"}
{"mode":"v11-raw-disruptor","partitions":4,"sequenceNumber":433,"routingSymbol":"XRPUSDT","localReceivedEpochMillis":1784431343247,"rawPayload":"{\"stream\":\"xrpusdt@depth@100ms\",\"data\":{\"e\":\"depthUpdate\",\"E\":1784431343257,\"s\":\"XRPUSDT\",\"U\":752712596,\"u\":752712597,\"b\":[[\"1.09330000\",\"218.20000000\"],[\"1.09320000\",\"3492.00000000\"]],\"a\":[]}}"}
{"mode":"v11-raw-disruptor","partitions":4,"sequenceNumber":434,"routingSymbol":"ETHUSDT","localReceivedEpochMillis":1784431343347,"rawPayload":"{\"stream\":\"ethusdt@depth@100ms\",\"data\":{\"e\":\"depthUpdate\",\"E\":1784431343357,\"s\":\"ETHUSDT\",\"U\":2806198540,\"u\":2806198540,\"b\":[],\"a\":[[\"1873.50000000\",\"9.17580000\"]]}}"}
{"mode":"v11-raw-disruptor","partitions":4,"sequenceNumber":435,"routingSymbol":"BTCUSDT","localReceivedEpochMillis":1784431343347,"rawPayload":"{\"stream\":\"btcusdt@depth@100ms\",\"data\":{\"e\":\"depthUpdate\",\"E\":1784431343357,\"s\":\"BTCUSDT\",\"U\":3244451835,\"u\":3244451836,\"b\":[[\"64647.08000000\",\"0.00000000\"],[\"64645.33000000\",\"0.00557000\"]],\"a\":[]}}"}
{"mode":"v11-raw-disruptor","partitions":4,"sequenceNumber":436,"routingSymbol":"ETHUSDT","localReceivedEpochMillis":1784431343547,"rawPayload":"{\"stream\":\"ethusdt@depth@100ms\",\"data\":{\"e\":\"depthUpdate\",\"E\":1784431343558,\"s\":\"ETHUSDT\",\"U\":2806198541,\"u\":2806198541,\"b\":[],\"a\":[[\"1873.56000000\",\"9.26490000\"]]}}"}
{"mode":"v11-raw-disruptor","partitions":4,"sequenceNumber":437,"routingSymbol":"ETHUSDT","localReceivedEpochMillis":1784431343649,"rawPayload":"{\"stream\":\"ethusdt@depth@100ms\",\"data\":{\"e\":\"depthUpdate\",\"E\":1784431343658,\"s\":\"ETHUSDT\",\"U\":2806198542,\"u\":2806198543,\"b\":[],\"a\":[[\"1864.85000000\",\"0.13940000\"],[\"1864.89000000\",\"0.00000000\"],[\"1873.61000000\",\"9.15080000\"]]}}"}
{"mode":"v11-raw-disruptor","partitions":4,"sequenceNumber":438,"routingSymbol":"XRPUSDT","localReceivedEpochMillis":1784431343747,"rawPayload":"{\"stream\":\"xrpusdt@depth@100ms\",\"data\":{\"e\":\"depthUpdate\",\"E\":1784431343758,\"s\":\"XRPUSDT\",\"U\":752712598,\"u\":752712601,\"b\":[[\"1.09350000\",\"1773.20000000\"],[\"1.09340000\",\"0.00000000\"],[\"1.09310000\",\"4598.90000000\"],[\"1.09300000\",\"0.00000000\"]],\"a\":[[\"1.09410000\",\"0.00000000\"],[\"1.09420000\",\"3441.30000000\"],[\"1.09450000\",\"2074.70000000\"],[\"1.09460000\",\"4595.70000000\"]]}}"}
{"mode":"v11-raw-disruptor","partitions":4,"sequenceNumber":439,"routingSymbol":"ETHUSDT","localReceivedEpochMillis":1784431343847,"rawPayload":"{\"stream\":\"ethusdt@depth@100ms\",\"data\":{\"e\":\"depthUpdate\",\"E\":1784431343858,\"s\":\"ETHUSDT\",\"U\":2806198544,\"u\":2806198545,\"b\":[],\"a\":[[\"1865.34000000\",\"0.97360000\"],[\"1865.48000000\",\"0.00000000\"],[\"1866.47000000\",\"0.00000000\"]]}}"}
{"mode":"v11-raw-disruptor","partitions":4,"sequenceNumber":440,"routingSymbol":"XRPUSDT","localReceivedEpochMillis":1784431343947,"rawPayload":"{\"stream\":\"xrpusdt@depth@100ms\",\"data\":{\"e\":\"depthUpdate\",\"E\":1784431343958,\"s\":\"XRPUSDT\",\"U\":752712602,\"u\":752712602,\"b\":[[\"1.09360000\",\"4555.90000000\"],[\"1.09350000\",\"462.70000000\"]],\"a\":[]}}"}
{"mode":"v11-raw-disruptor","partitions":4,"sequenceNumber":441,"routingSymbol":"SOLUSDT","localReceivedEpochMillis":1784431344047,"rawPayload":"{\"stream\":\"solusdt@depth@100ms\",\"data\":{\"e\":\"depthUpdate\",\"E\":1784431344058,\"s\":\"SOLUSDT\",\"U\":1609592207,\"u\":1609592207,\"b\":[],\"a\":[[\"75.92000000\",\"33.47800000\"]]}}"}
{"mode":"v11-raw-disruptor","partitions":4,"sequenceNumber":442,"routingSymbol":"XRPUSDT","localReceivedEpochMillis":1784431344047,"rawPayload":"{\"stream\":\"xrpusdt@depth@100ms\",\"data\":{\"e\":\"depthUpdate\",\"E\":1784431344058,\"s\":\"XRPUSDT\",\"U\":752712603,\"u\":752712604,\"b\":[[\"1.09300000\",\"59.80000000\"],[\"1.09280000\",\"0.00000000\"]],\"a\":[]}}"}
{"mode":"v11-raw-disruptor","partitions":4,"sequenceNumber":443,"routingSymbol":"BTCUSDT","localReceivedEpochMillis":1784431344148,"rawPayload":"{\"stream\":\"btcusdt@depth@100ms\",\"data\":{\"e\":\"depthUpdate\",\"E\":1784431344158,\"s\":\"BTCUSDT\",\"U\":3244451837,\"u\":3244451837,\"b\":[],\"a\":[[\"80832.52000000\",\"0.00060000\"]]}}"}
{"mode":"v11-raw-disruptor","partitions":4,"sequenceNumber":444,"routingSymbol":"BTCUSDT","localReceivedEpochMillis":1784431344248,"rawPayload":"{\"stream\":\"btcusdt@depth@100ms\",\"data\":{\"e\":\"depthUpdate\",\"E\":1784431344258,\"s\":\"BTCUSDT\",\"U\":3244451838,\"u\":3244451845,\"b\":[[\"64586.20000000\",\"0.05890000\"],[\"64580.42000000\",\"0.00000000\"],[\"64547.40000000\",\"0.08405000\"],[\"64541.63000000\",\"0.00000000\"],[\"64508.60000000\",\"0.18547000\"],[\"64502.83000000\",\"0.00000000\"],[\"64431.01000000\",\"0.39755000\"],[\"64425.24000000\",\"0.00000000\"]],\"a\":[[\"64735.55000000\",\"0.00000000\"],[\"64741.34000000\",\"0.05593000\"],[\"64774.35000000\",\"0.00000000\"],[\"64780.14000000\",\"0.08386000\"],[\"64813.14000000\",\"0.00000000\"],[\"64818.94000000\",\"0.16778000\"],[\"64890.73000000\",\"0.00000000\"],[\"64896.53000000\",\"0.41507000\"]]}}"}
{"mode":"v11-raw-disruptor","partitions":4,"sequenceNumber":445,"routingSymbol":"ETHUSDT","localReceivedEpochMillis":1784431344248,"rawPayload":"{\"stream\":\"ethusdt@depth@100ms\",\"data\":{\"e\":\"depthUpdate\",\"E\":1784431344258,\"s\":\"ETHUSDT\",\"U\":2806198546,\"u\":2806198549,\"b\":[[\"1864.42000000\",\"1.94210000\"],[\"1864.35000000\",\"0.00000000\"]],\"a\":[[\"1864.93000000\",\"0.00000000\"],[\"1864.99000000\",\"1.16280000\"]]}}"}
{"mode":"v11-raw-disruptor","partitions":4,"sequenceNumber":446,"routingSymbol":"ETHUSDT","localReceivedEpochMillis":1784431344347,"rawPayload":"{\"stream\":\"ethusdt@depth@100ms\",\"data\":{\"e\":\"depthUpdate\",\"E\":1784431344358,\"s\":\"ETHUSDT\",\"U\":2806198550,\"u\":2806198562,\"b\":[[\"1864.42000000\",\"0.81220000\"],[\"1864.36000000\",\"1.14680000\"],[\"1864.35000000\",\"0.00000000\"]],\"a\":[[\"1864.92000000\",\"0.00000000\"],[\"1864.93000000\",\"1.11040000\"],[\"1864.99000000\",\"0.00000000\"],[\"1869.39000000\",\"0.06600000\"]]}}"}
{"mode":"v11-raw-disruptor","partitions":4,"sequenceNumber":447,"routingSymbol":"SOLUSDT","localReceivedEpochMillis":1784431344548,"rawPayload":"{\"stream\":\"solusdt@depth@100ms\",\"data\":{\"e\":\"depthUpdate\",\"E\":1784431344558,\"s\":\"SOLUSDT\",\"U\":1609592208,\"u\":1609592209,\"b\":[],\"a\":[[\"75.90000000\",\"79.14200000\"],[\"75.91000000\",\"44.57800000\"]]}}"}
{"mode":"v11-raw-disruptor","partitions":4,"sequenceNumber":448,"routingSymbol":"BTCUSDT","localReceivedEpochMillis":1784431344548,"rawPayload":"{\"stream\":\"btcusdt@depth@100ms\",\"data\":{\"e\":\"depthUpdate\",\"E\":1784431344558,\"s\":\"BTCUSDT\",\"U\":3244451846,\"u\":3244451846,\"b\":[],\"a\":[[\"64685.75000000\",\"0.07161000\"]]}}"}
{"mode":"v11-raw-disruptor","partitions":4,"sequenceNumber":449,"routingSymbol":"SOLUSDT","localReceivedEpochMillis":1784431344647,"rawPayload":"{\"stream\":\"solusdt@depth@100ms\",\"data\":{\"e\":\"depthUpdate\",\"E\":1784431344658,\"s\":\"SOLUSDT\",\"U\":1609592210,\"u\":1609592210,\"b\":[],\"a\":[[\"75.89000000\",\"19.05000000\"],[\"75.90000000\",\"60.09200000\"]]}}"}
{"mode":"v11-raw-disruptor","partitions":4,"sequenceNumber":450,"routingSymbol":"BNBUSDT","localReceivedEpochMillis":1784431344647,"rawPayload":"{\"stream\":\"bnbusdt@depth@100ms\",\"data\":{\"e\":\"depthUpdate\",\"E\":1784431344658,\"s\":\"BNBUSDT\",\"U\":1236336190,\"u\":1236336195,\"b\":[[\"568.63000000\",\"3.46000000\"],[\"568.61000000\",\"0.00000000\"],[\"568.29000000\",\"4.85600000\"],[\"568.27000000\",\"0.00000000\"],[\"567.95000000\",\"8.44100000\"],[\"567.93000000\",\"0.00000000\"],[\"567.61000000\",\"19.23400000\"],[\"567.59000000\",\"0.00000000\"]],\"a\":[[\"569.99000000\",\"0.00000000\"],[\"570.01000000\",\"3.50000000\"],[\"570.33000000\",\"0.00000000\"],[\"570.35000000\",\"4.82900000\"]]}}"}
{"mode":"v11-raw-disruptor","partitions":4,"sequenceNumber":451,"routingSymbol":"BTCUSDT","localReceivedEpochMillis":1784431344647,"rawPayload":"{\"stream\":\"btcusdt@depth@100ms\",\"data\":{\"e\":\"depthUpdate\",\"E\":1784431344658,\"s\":\"BTCUSDT\",\"U\":3244451847,\"u\":3244451847,\"b\":[],\"a\":[[\"80832.52000000\",\"0.00075000\"]]}}"}
{"mode":"v11-raw-disruptor","partitions":4,"sequenceNumber":452,"routingSymbol":"ETHUSDT","localReceivedEpochMillis":1784431344748,"rawPayload":"{\"stream\":\"ethusdt@depth@100ms\",\"data\":{\"e\":\"depthUpdate\",\"E\":1784431344758,\"s\":\"ETHUSDT\",\"U\":2806198563,\"u\":2806198564,\"b\":[[\"1863.98000000\",\"0.64590000\"],[\"1863.91000000\",\"0.00000000\"]],\"a\":[]}}"}
{"mode":"v11-raw-disruptor","partitions":4,"sequenceNumber":453,"routingSymbol":"SOLUSDT","localReceivedEpochMillis":1784431345348,"rawPayload":"{\"stream\":\"solusdt@depth@100ms\",\"data\":{\"e\":\"depthUpdate\",\"E\":1784431345359,\"s\":\"SOLUSDT\",\"U\":1609592211,\"u\":1609592215,\"b\":[[\"75.86000000\",\"0.00000000\"],[\"75.85000000\",\"73.55000000\"]],\"a\":[[\"75.90000000\",\"74.72000000\"],[\"75.91000000\",\"50.32500000\"]]}}"}
{"mode":"v11-raw-disruptor","partitions":4,"sequenceNumber":454,"routingSymbol":"ETHUSDT","localReceivedEpochMillis":1784431345349,"rawPayload":"{\"stream\":\"ethusdt@depth@100ms\",\"data\":{\"e\":\"depthUpdate\",\"E\":1784431345359,\"s\":\"ETHUSDT\",\"U\":2806198565,\"u\":2806198572,\"b\":[[\"1864.36000000\",\"1.12450000\"],[\"1864.28000000\",\"0.00000000\"]],\"a\":[[\"1864.85000000\",\"0.13940000\"],[\"1864.93000000\",\"1.12740000\"]]}}"}
{"mode":"v11-raw-disruptor","partitions":4,"sequenceNumber":455,"routingSymbol":"XRPUSDT","localReceivedEpochMillis":1784431345648,"rawPayload":"{\"stream\":\"xrpusdt@depth@100ms\",\"data\":{\"e\":\"depthUpdate\",\"E\":1784431345659,\"s\":\"XRPUSDT\",\"U\":752712605,\"u\":752712605,\"b\":[[\"1.09330000\",\"2292.90000000\"]],\"a\":[]}}"}
{"mode":"v11-raw-disruptor","partitions":4,"sequenceNumber":456,"routingSymbol":"ETHUSDT","localReceivedEpochMillis":1784431345948,"rawPayload":"{\"stream\":\"ethusdt@depth@100ms\",\"data\":{\"e\":\"depthUpdate\",\"E\":1784431345959,\"s\":\"ETHUSDT\",\"U\":2806198573,\"u\":2806198581,\"b\":[[\"1864.05000000\",\"1.63970000\"],[\"1857.29000000\",\"0.00000000\"],[\"1857.23000000\",\"7.25460000\"],[\"1856.98000000\",\"8.25990000\"],[\"1855.67000000\",\"0.00000000\"],[\"1855.60000000\",\"0.00000000\"]],\"a\":[[\"1864.85000000\",\"0.00000000\"],[\"1864.87000000\",\"0.13940000\"],[\"1872.13000000\",\"7.15080000\"],[\"1873.61000000\",\"0.00000000\"]]}}"}
{"mode":"v11-raw-disruptor","partitions":4,"sequenceNumber":457,"routingSymbol":"ETHUSDT","localReceivedEpochMillis":1784431346049,"rawPayload":"{\"stream\":\"ethusdt@depth@100ms\",\"data\":{\"e\":\"depthUpdate\",\"E\":1784431346059,\"s\":\"ETHUSDT\",\"U\":2806198582,\"u\":2806198583,\"b\":[[\"1864.03000000\",\"0.72900000\"],[\"1863.98000000\",\"0.00000000\"]],\"a\":[]}}"}
{"mode":"v11-raw-disruptor","partitions":4,"sequenceNumber":458,"routingSymbol":"ETHUSDT","localReceivedEpochMillis":1784431346148,"rawPayload":"{\"stream\":\"ethusdt@depth@100ms\",\"data\":{\"e\":\"depthUpdate\",\"E\":1784431346159,\"s\":\"ETHUSDT\",\"U\":2806198584,\"u\":2806198584,\"b\":[[\"1857.14000000\",\"7.94840000\"]],\"a\":[]}}"}
{"mode":"v11-raw-disruptor","partitions":4,"sequenceNumber":459,"routingSymbol":"ETHUSDT","localReceivedEpochMillis":1784431346248,"rawPayload":"{\"stream\":\"ethusdt@depth@100ms\",\"data\":{\"e\":\"depthUpdate\",\"E\":1784431346259,\"s\":\"ETHUSDT\",\"U\":2806198585,\"u\":2806198585,\"b\":[[\"1864.11000000\",\"1.63970000\"]],\"a\":[]}}"}
{"mode":"v11-raw-disruptor","partitions":4,"sequenceNumber":460,"routingSymbol":"SOLUSDT","localReceivedEpochMillis":1784431346348,"rawPayload":"{\"stream\":\"solusdt@depth@100ms\",\"data\":{\"e\":\"depthUpdate\",\"E\":1784431346359,\"s\":\"SOLUSDT\",\"U\":1609592216,\"u\":1609592225,\"b\":[[\"75.86000000\",\"13.64100000\"],[\"75.85000000\",\"60.09500000\"],[\"75.81000000\",\"20.95300000\"],[\"75.78000000\",\"99.62700000\"]],\"a\":[[\"75.90000000\",\"60.09200000\"],[\"75.91000000\",\"13.64900000\"],[\"75.92000000\",\"3.28300000\"],[\"76.00000000\",\"312.37800000\"]]}}"}
{"mode":"v11-raw-disruptor","partitions":4,"sequenceNumber":461,"routingSymbol":"ETHUSDT","localReceivedEpochMillis":1784431346348,"rawPayload":"{\"stream\":\"ethusdt@depth@100ms\",\"data\":{\"e\":\"depthUpdate\",\"E\":1784431346359,\"s\":\"ETHUSDT\",\"U\":2806198586,\"u\":2806198600,\"b\":[[\"1864.36000000\",\"0.00000000\"],[\"1864.27000000\",\"1.14090000\"],[\"1864.03000000\",\"0.00000000\"],[\"1863.96000000\",\"0.74340000\"],[\"1857.23000000\",\"0.00000000\"],[\"1857.14000000\",\"0.00000000\"],[\"1857.11000000\",\"7.23500000\"],[\"1856.80000000\",\"8.32240000\"],[\"1855.79000000\",\"0.00000000\"],[\"1855.73000000\",\"0.00000000\"]],\"a\":[[\"1864.84000000\",\"2.46670000\"],[\"1864.93000000\",\"0.00000000\"],[\"1866.37000000\",\"1.63970000\"],[\"1872.01000000\",\"7.23790000\"],[\"1873.56000000\",\"0.00000000\"]]}}"}
{"mode":"v11-raw-disruptor","partitions":4,"sequenceNumber":462,"routingSymbol":"BTCUSDT","localReceivedEpochMillis":1784431346348,"rawPayload":"{\"stream\":\"btcusdt@depth@100ms\",\"data\":{\"e\":\"depthUpdate\",\"E\":1784431346360,\"s\":\"BTCUSDT\",\"U\":3244451848,\"u\":3244451849,\"b\":[],\"a\":[[\"64664.59000000\",\"0.03868000\"],[\"64670.53000000\",\"0.00000000\"]]}}"}
{"mode":"v11-raw-disruptor","partitions":4,"sequenceNumber":463,"routingSymbol":"XRPUSDT","localReceivedEpochMillis":1784431346348,"rawPayload":"{\"stream\":\"xrpusdt@depth@100ms\",\"data\":{\"e\":\"depthUpdate\",\"E\":1784431346360,\"s\":\"XRPUSDT\",\"U\":752712606,\"u\":752712606,\"b\":[],\"a\":[[\"1.09460000\",\"2521.00000000\"]]}}"}
{"mode":"v11-raw-disruptor","partitions":4,"sequenceNumber":464,"routingSymbol":"SOLUSDT","localReceivedEpochMillis":1784431346449,"rawPayload":"{\"stream\":\"solusdt@depth@100ms\",\"data\":{\"e\":\"depthUpdate\",\"E\":1784431346460,\"s\":\"SOLUSDT\",\"U\":1609592226,\"u\":1609592229,\"b\":[[\"75.86000000\",\"0.00000000\"],[\"75.85000000\",\"73.80000000\"]],\"a\":[[\"75.90000000\",\"74.83600000\"],[\"75.91000000\",\"0.00000000\"]]}}"}
{"mode":"v11-raw-disruptor","partitions":4,"sequenceNumber":465,"routingSymbol":"ETHUSDT","localReceivedEpochMillis":1784431346449,"rawPayload":"{\"stream\":\"ethusdt@depth@100ms\",\"data\":{\"e\":\"depthUpdate\",\"E\":1784431346460,\"s\":\"ETHUSDT\",\"U\":2806198601,\"u\":2806198606,\"b\":[[\"1864.50000000\",\"0.00000000\"],[\"1864.34000000\",\"1.10020000\"],[\"1864.27000000\",\"0.00000000\"]],\"a\":[[\"1864.84000000\",\"1.34150000\"],[\"1864.91000000\",\"1.11260000\"],[\"1865.07000000\",\"0.00000000\"]]}}"}
{"mode":"v11-raw-disruptor","partitions":4,"sequenceNumber":466,"routingSymbol":"BTCUSDT","localReceivedEpochMillis":1784431346449,"rawPayload":"{\"stream\":\"btcusdt@depth@100ms\",\"data\":{\"e\":\"depthUpdate\",\"E\":1784431346460,\"s\":\"BTCUSDT\",\"U\":3244451850,\"u\":3244451851,\"b\":[[\"64645.33000000\",\"0.00000000\"],[\"64643.40000000\",\"0.00748000\"]],\"a\":[]}}"}
{"mode":"v11-raw-disruptor","partitions":4,"sequenceNumber":467,"routingSymbol":"XRPUSDT","localReceivedEpochMillis":1784431346449,"rawPayload":"{\"stream\":\"xrpusdt@depth@100ms\",\"data\":{\"e\":\"depthUpdate\",\"E\":1784431346460,\"s\":\"XRPUSDT\",\"U\":752712607,\"u\":752712608,\"b\":[[\"1.09210000\",\"113.80000000\"],[\"1.09160000\",\"22950.30000000\"]],\"a\":[]}}"}
{"mode":"v11-raw-disruptor","partitions":4,"sequenceNumber":468,"routingSymbol":"ETHUSDT","localReceivedEpochMillis":1784431346550,"rawPayload":"{\"stream\":\"ethusdt@depth@100ms\",\"data\":{\"e\":\"depthUpdate\",\"E\":1784431346560,\"s\":\"ETHUSDT\",\"U\":2806198607,\"u\":2806198607,\"b\":[[\"1855.78000000\",\"9.24610000\"]],\"a\":[]}}"}
{"mode":"v11-raw-disruptor","partitions":4,"sequenceNumber":469,"routingSymbol":"SOLUSDT","localReceivedEpochMillis":1784431346649,"rawPayload":"{\"stream\":\"solusdt@depth@100ms\",\"data\":{\"e\":\"depthUpdate\",\"E\":1784431346660,\"s\":\"SOLUSDT\",\"U\":1609592230,\"u\":1609592230,\"b\":[],\"a\":[[\"76.00000000\",\"342.57300000\"]]}}"}
{"mode":"v11-raw-disruptor","partitions":4,"sequenceNumber":470,"routingSymbol":"BNBUSDT","localReceivedEpochMillis":1784431346649,"rawPayload":"{\"stream\":\"bnbusdt@depth@100ms\",\"data\":{\"e\":\"depthUpdate\",\"E\":1784431346660,\"s\":\"BNBUSDT\",\"U\":1236336196,\"u\":1236336196,\"b\":[],\"a\":[[\"569.41000000\",\"0.00000000\"],[\"569.42000000\",\"1.70900000\"]]}}"}
{"mode":"v11-raw-disruptor","partitions":4,"sequenceNumber":471,"routingSymbol":"BTCUSDT","localReceivedEpochMillis":1784431346649,"rawPayload":"{\"stream\":\"btcusdt@depth@100ms\",\"data\":{\"e\":\"depthUpdate\",\"E\":1784431346660,\"s\":\"BTCUSDT\",\"U\":3244451852,\"u\":3244451852,\"b\":[],\"a\":[[\"80832.52000000\",\"0.00075000\"]]}}"}
{"mode":"v11-raw-disruptor","partitions":4,"sequenceNumber":472,"routingSymbol":"ETHUSDT","localReceivedEpochMillis":1784431346649,"rawPayload":"{\"stream\":\"ethusdt@depth@100ms\",\"data\":{\"e\":\"depthUpdate\",\"E\":1784431346660,\"s\":\"ETHUSDT\",\"U\":2806198608,\"u\":2806198608,\"b\":[[\"1855.73000000\",\"9.32780000\"]],\"a\":[]}}"}
{"mode":"v11-raw-disruptor","partitions":4,"sequenceNumber":473,"routingSymbol":"SOLUSDT","localReceivedEpochMillis":1784431346749,"rawPayload":"{\"stream\":\"solusdt@depth@100ms\",\"data\":{\"e\":\"depthUpdate\",\"E\":1784431346760,\"s\":\"SOLUSDT\",\"U\":1609592231,\"u\":1609592231,\"b\":[],\"a\":[[\"75.97000000\",\"30.19500000\"]]}}"}
{"mode":"v11-raw-disruptor","partitions":4,"sequenceNumber":474,"routingSymbol":"SOLUSDT","localReceivedEpochMillis":1784431346849,"rawPayload":"{\"stream\":\"solusdt@depth@100ms\",\"data\":{\"e\":\"depthUpdate\",\"E\":1784431346860,\"s\":\"SOLUSDT\",\"U\":1609592232,\"u\":1609592235,\"b\":[[\"75.86000000\",\"19.28600000\"],[\"75.85000000\",\"54.51400000\"],[\"75.80000000\",\"0.00000000\"]],\"a\":[[\"75.89000000\",\"0.00000000\"],[\"75.90000000\",\"93.88600000\"],[\"76.00000000\",\"312.37800000\"]]}}"}
{"mode":"v11-raw-disruptor","partitions":4,"sequenceNumber":475,"routingSymbol":"XRPUSDT","localReceivedEpochMillis":1784431346948,"rawPayload":"{\"stream\":\"xrpusdt@depth@100ms\",\"data\":{\"e\":\"depthUpdate\",\"E\":1784431346960,\"s\":\"XRPUSDT\",\"U\":752712609,\"u\":752712609,\"b\":[],\"a\":[[\"1.09450000\",\"4595.70000000\"],[\"1.09460000\",\"0.00000000\"]]}}"}
{"mode":"v11-raw-disruptor","partitions":4,"sequenceNumber":476,"routingSymbol":"BNBUSDT","localReceivedEpochMillis":1784431347050,"rawPayload":"{\"stream\":\"bnbusdt@depth@100ms\",\"data\":{\"e\":\"depthUpdate\",\"E\":1784431347060,\"s\":\"BNBUSDT\",\"U\":1236336197,\"u\":1236336200,\"b\":[[\"569.09000000\",\"0.00000000\"],[\"569.04000000\",\"0.91600000\"]],\"a\":[[\"569.45000000\",\"1.06700000\"],[\"569.50000000\",\"0.00000000\"]]}}"}
{"mode":"v11-raw-disruptor","partitions":4,"sequenceNumber":477,"routingSymbol":"SOLUSDT","localReceivedEpochMillis":1784431347449,"rawPayload":"{\"stream\":\"solusdt@depth@100ms\",\"data\":{\"e\":\"depthUpdate\",\"E\":1784431347460,\"s\":\"SOLUSDT\",\"U\":1609592236,\"u\":1609592238,\"b\":[[\"75.84000000\",\"30.33800000\"]],\"a\":[[\"75.93000000\",\"66.53100000\"],[\"75.97000000\",\"0.00000000\"]]}}"}
{"mode":"v11-raw-disruptor","partitions":4,"sequenceNumber":478,"routingSymbol":"BTCUSDT","localReceivedEpochMillis":1784431347449,"rawPayload":"{\"stream\":\"btcusdt@depth@100ms\",\"data\":{\"e\":\"depthUpdate\",\"E\":1784431347460,\"s\":\"BTCUSDT\",\"U\":3244451853,\"u\":3244451854,\"b\":[[\"64645.07000000\",\"0.00803000\"],[\"64643.40000000\",\"0.00000000\"]],\"a\":[]}}"}
{"mode":"v11-raw-disruptor","partitions":4,"sequenceNumber":479,"routingSymbol":"ETHUSDT","localReceivedEpochMillis":1784431347549,"rawPayload":"{\"stream\":\"ethusdt@depth@100ms\",\"data\":{\"e\":\"depthUpdate\",\"E\":1784431347560,\"s\":\"ETHUSDT\",\"U\":2806198609,\"u\":2806198614,\"b\":[[\"1864.25000000\",\"1.37150000\"],[\"1864.23000000\",\"0.00000000\"],[\"1864.19000000\",\"0.13940000\"],[\"1864.01000000\",\"0.80040000\"],[\"1863.96000000\",\"0.00000000\"]],\"a\":[[\"1864.83000000\",\"0.02940000\"],[\"1866.37000000\",\"0.00000000\"]]}}"}
{"mode":"v11-raw-disruptor","partitions":4,"sequenceNumber":480,"routingSymbol":"XRPUSDT","localReceivedEpochMillis":1784431347549,"rawPayload":"{\"stream\":\"xrpusdt@depth@100ms\",\"data\":{\"e\":\"depthUpdate\",\"E\":1784431347560,\"s\":\"XRPUSDT\",\"U\":752712610,\"u\":752712610,\"b\":[],\"a\":[[\"1.09410000\",\"2074.70000000\"]]}}"}
{"mode":"v11-raw-disruptor","partitions":4,"sequenceNumber":481,"routingSymbol":"ETHUSDT","localReceivedEpochMillis":1784431347850,"rawPayload":"{\"stream\":\"ethusdt@depth@100ms\",\"data\":{\"e\":\"depthUpdate\",\"E\":1784431347860,\"s\":\"ETHUSDT\",\"U\":2806198615,\"u\":2806198615,\"b\":[],\"a\":[[\"1865.11000000\",\"1.63970000\"]]}}"}
{"mode":"v11-raw-disruptor","partitions":4,"sequenceNumber":482,"routingSymbol":"SOLUSDT","localReceivedEpochMillis":1784431347949,"rawPayload":"{\"stream\":\"solusdt@depth@100ms\",\"data\":{\"e\":\"depthUpdate\",\"E\":1784431347960,\"s\":\"SOLUSDT\",\"U\":1609592239,\"u\":1609592242,\"b\":[[\"75.86000000\",\"32.85600000\"],[\"75.85000000\",\"40.80900000\"]],\"a\":[[\"75.90000000\",\"79.14200000\"],[\"75.91000000\",\"14.22300000\"]]}}"}
{"mode":"v11-raw-disruptor","partitions":4,"sequenceNumber":483,"routingSymbol":"ETHUSDT","localReceivedEpochMillis":1784431348049,"rawPayload":"{\"stream\":\"ethusdt@depth@100ms\",\"data\":{\"e\":\"depthUpdate\",\"E\":1784431348061,\"s\":\"ETHUSDT\",\"U\":2806198616,\"u\":2806198616,\"b\":[],\"a\":[[\"1865.43000000\",\"1.63970000\"]]}}"}
{"mode":"v11-raw-disruptor","partitions":4,"sequenceNumber":484,"routingSymbol":"BTCUSDT","localReceivedEpochMillis":1784431348049,"rawPayload":"{\"stream\":\"btcusdt@depth@100ms\",\"data\":{\"e\":\"depthUpdate\",\"E\":1784431348061,\"s\":\"BTCUSDT\",\"U\":3244451855,\"u\":3244451856,\"b\":[[\"64648.71000000\",\"0.00833000\"],[\"64645.07000000\",\"0.00000000\"]],\"a\":[]}}"}
{"mode":"v11-raw-disruptor","partitions":4,"sequenceNumber":485,"routingSymbol":"SOLUSDT","localReceivedEpochMillis":1784431348149,"rawPayload":"{\"stream\":\"solusdt@depth@100ms\",\"data\":{\"e\":\"depthUpdate\",\"E\":1784431348161,\"s\":\"SOLUSDT\",\"U\":1609592243,\"u\":1609592252,\"b\":[[\"75.78000000\",\"119.21400000\"],[\"75.76000000\",\"73.57000000\"],[\"75.73000000\",\"60.66600000\"],[\"75.72000000\",\"273.88500000\"],[\"75.69000000\",\"485.43600000\"],[\"75.67000000\",\"388.92700000\"],[\"75.60000000\",\"154.37400000\"],[\"75.58000000\",\"100.65000000\"]],\"a\":[[\"75.91000000\",\"0.00000000\"],[\"75.92000000\",\"17.72100000\"],[\"75.95000000\",\"65.87900000\"],[\"75.97000000\",\"19.51000000\"],[\"76.00000000\",\"275.50800000\"],[\"76.02000000\",\"311.32800000\"],[\"76.04000000\",\"271.23400000\"],[\"76.06000000\",\"329.05800000\"],[\"76.14000000\",\"335.05600000\"],[\"76.15000000\",\"483.78200000\"]]}}"}
{"mode":"v11-raw-disruptor","partitions":4,"sequenceNumber":486,"routingSymbol":"ETHUSDT","localReceivedEpochMillis":1784431348149,"rawPayload":"{\"stream\":\"ethusdt@depth@100ms\",\"data\":{\"e\":\"depthUpdate\",\"E\":1784431348161,\"s\":\"ETHUSDT\",\"U\":2806198617,\"u\":2806198618,\"b\":[[\"1864.39000000\",\"1.34180000\"],[\"1864.25000000\",\"0.02960000\"]],\"a\":[]}}"}
{"mode":"v11-raw-disruptor","partitions":4,"sequenceNumber":487,"routingSymbol":"XRPUSDT","localReceivedEpochMillis":1784431348149,"rawPayload":"{\"stream\":\"xrpusdt@depth@100ms\",\"data\":{\"e\":\"depthUpdate\",\"E\":1784431348161,\"s\":\"XRPUSDT\",\"U\":752712611,\"u\":752712625,\"b\":[[\"1.09350000\",\"3953.70000000\"],[\"1.09340000\",\"2074.70000000\"],[\"1.09330000\",\"2264.60000000\"],[\"1.09320000\",\"0.00000000\"],[\"1.09290000\",\"0.00000000\"],[\"1.09210000\",\"12775.80000000\"],[\"1.08930000\",\"6915.90000000\"]],\"a\":[[\"1.09410000\",\"3687.00000000\"],[\"1.09430000\",\"494.00000000\"],[\"1.09440000\",\"168.40000000\"],[\"1.09550000\",\"0.00000000\"],[\"1.09760000\",\"15824.50000000\"]]}}"}
{"mode":"v11-raw-disruptor","partitions":4,"sequenceNumber":488,"routingSymbol":"SOLUSDT","localReceivedEpochMillis":1784431348249,"rawPayload":"{\"stream\":\"solusdt@depth@100ms\",\"data\":{\"e\":\"depthUpdate\",\"E\":1784431348261,\"s\":\"SOLUSDT\",\"U\":1609592253,\"u\":1609592253,\"b\":[],\"a\":[[\"75.93000000\",\"36.33600000\"]]}}"}
{"mode":"v11-raw-disruptor","partitions":4,"sequenceNumber":489,"routingSymbol":"BNBUSDT","localReceivedEpochMillis":1784431348249,"rawPayload":"{\"stream\":\"bnbusdt@depth@100ms\",\"data\":{\"e\":\"depthUpdate\",\"E\":1784431348261,\"s\":\"BNBUSDT\",\"U\":1236336201,\"u\":1236336204,\"b\":[[\"569.11000000\",\"0.92800000\"],[\"569.04000000\",\"0.00000000\"]],\"a\":[[\"569.45000000\",\"0.10600000\"],[\"569.52000000\",\"0.90900000\"]]}}"}
{"mode":"v11-raw-disruptor","partitions":4,"sequenceNumber":490,"routingSymbol":"XRPUSDT","localReceivedEpochMillis":1784431348250,"rawPayload":"{\"stream\":\"xrpusdt@depth@100ms\",\"data\":{\"e\":\"depthUpdate\",\"E\":1784431348261,\"s\":\"XRPUSDT\",\"U\":752712626,\"u\":752712626,\"b\":[[\"1.09330000\",\"2294.70000000\"]],\"a\":[]}}"}
{"mode":"v11-raw-disruptor","partitions":4,"sequenceNumber":491,"routingSymbol":"BNBUSDT","localReceivedEpochMillis":1784431348350,"rawPayload":"{\"stream\":\"bnbusdt@depth@100ms\",\"data\":{\"e\":\"depthUpdate\",\"E\":1784431348361,\"s\":\"BNBUSDT\",\"U\":1236336205,\"u\":1236336206,\"b\":[],\"a\":[[\"569.45000000\",\"247.54100000\"],[\"569.60000000\",\"0.00000000\"]]}}"}
{"mode":"v11-raw-disruptor","partitions":4,"sequenceNumber":492,"routingSymbol":"SOLUSDT","localReceivedEpochMillis":1784431348350,"rawPayload":"{\"stream\":\"solusdt@depth@100ms\",\"data\":{\"e\":\"depthUpdate\",\"E\":1784431348361,\"s\":\"SOLUSDT\",\"U\":1609592254,\"u\":1609592255,\"b\":[],\"a\":[[\"75.91000000\",\"14.32500000\"],[\"75.92000000\",\"3.28300000\"]]}}"}
{"mode":"v11-raw-disruptor","partitions":4,"sequenceNumber":493,"routingSymbol":"XRPUSDT","localReceivedEpochMillis":1784431348350,"rawPayload":"{\"stream\":\"xrpusdt@depth@100ms\",\"data\":{\"e\":\"depthUpdate\",\"E\":1784431348361,\"s\":\"XRPUSDT\",\"U\":752712627,\"u\":752712627,\"b\":[],\"a\":[[\"1.09760000\",\"0.00000000\"]]}}"}
{"mode":"v11-raw-disruptor","partitions":4,"sequenceNumber":494,"routingSymbol":"XRPUSDT","localReceivedEpochMillis":1784431348450,"rawPayload":"{\"stream\":\"xrpusdt@depth@100ms\",\"data\":{\"e\":\"depthUpdate\",\"E\":1784431348461,\"s\":\"XRPUSDT\",\"U\":752712628,\"u\":752712629,\"b\":[],\"a\":[[\"1.09400000\",\"2286.70000000\"],[\"1.09410000\",\"4993.10000000\"],[\"1.09750000\",\"15788.00000000\"]]}}"}
{"mode":"v11-raw-disruptor","partitions":4,"sequenceNumber":495,"routingSymbol":"BNBUSDT","localReceivedEpochMillis":1784431348549,"rawPayload":"{\"stream\":\"bnbusdt@depth@100ms\",\"data\":{\"e\":\"depthUpdate\",\"E\":1784431348561,\"s\":\"BNBUSDT\",\"U\":1236336207,\"u\":1236336210,\"b\":[[\"569.11000000\",\"0.00000000\"],[\"569.05000000\",\"0.95100000\"]],\"a\":[[\"569.46000000\",\"2.56900000\"],[\"569.52000000\",\"0.00000000\"]]}}"}
{"mode":"v11-raw-disruptor","partitions":4,"sequenceNumber":496,"routingSymbol":"SOLUSDT","localReceivedEpochMillis":1784431348549,"rawPayload":"{\"stream\":\"solusdt@depth@100ms\",\"data\":{\"e\":\"depthUpdate\",\"E\":1784431348561,\"s\":\"SOLUSDT\",\"U\":1609592256,\"u\":1609592257,\"b\":[],\"a\":[[\"75.91000000\",\"0.00000000\"],[\"75.92000000\",\"17.44500000\"]]}}"}
{"mode":"v11-raw-disruptor","partitions":4,"sequenceNumber":497,"routingSymbol":"ETHUSDT","localReceivedEpochMillis":1784431348549,"rawPayload":"{\"stream\":\"ethusdt@depth@100ms\",\"data\":{\"e\":\"depthUpdate\",\"E\":1784431348561,\"s\":\"ETHUSDT\",\"U\":2806198619,\"u\":2806198619,\"b\":[[\"1863.88000000\",\"1.09310000\"]],\"a\":[]}}"}
{"mode":"v11-raw-disruptor","partitions":4,"sequenceNumber":498,"routingSymbol":"XRPUSDT","localReceivedEpochMillis":1784431348549,"rawPayload":"{\"stream\":\"xrpusdt@depth@100ms\",\"data\":{\"e\":\"depthUpdate\",\"E\":1784431348561,\"s\":\"XRPUSDT\",\"U\":752712630,\"u\":752712631,\"b\":[],\"a\":[[\"1.09410000\",\"5131.40000000\"],[\"1.09440000\",\"30.10000000\"]]}}"}
{"mode":"v11-raw-disruptor","partitions":4,"sequenceNumber":499,"routingSymbol":"SOLUSDT","localReceivedEpochMillis":1784431348650,"rawPayload":"{\"stream\":\"solusdt@depth@100ms\",\"data\":{\"e\":\"depthUpdate\",\"E\":1784431348661,\"s\":\"SOLUSDT\",\"U\":1609592258,\"u\":1609592261,\"b\":[[\"75.86000000\",\"65.83300000\"],[\"75.85000000\",\"7.82700000\"]],\"a\":[[\"75.88000000\",\"0.55800000\"],[\"75.89000000\",\"32.96600000\"]]}}"}
{"mode":"v11-raw-disruptor","partitions":4,"sequenceNumber":500,"routingSymbol":"ETHUSDT","localReceivedEpochMillis":1784431348650,"rawPayload":"{\"stream\":\"ethusdt@depth@100ms\",\"data\":{\"e\":\"depthUpdate\",\"E\":1784431348661,\"s\":\"ETHUSDT\",\"U\":2806198620,\"u\":2806198622,\"b\":[[\"1864.01000000\",\"0.00000000\"]],\"a\":[[\"1864.84000000\",\"0.00000000\"],[\"1865.02000000\",\"1.34130000\"]]}}"}
