{"mode":"v11-raw-disruptor","partitions":4,"sequenceNumber":1,"routingSymbol":"ETHUSDT","localReceivedEpochMillis":1784431313827,"rawPayload":"{\"stream\":\"ethusdt@depth@100ms\",\"data\":{\"e\":\"depthUpdate\",\"E\":1784431313838,\"s\":\"ETHUSDT\",\"U\":2806197736,\"u\":2806197737,\"b\":[[\"1863.07000000\",\"1.63970000\"]],\"a\":[[\"1864.81000000\",\"1.63970000\"]]}}"}
{"mode":"v11-raw-disruptor","partitions":4,"sequenceNumber":2,"routingSymbol":"ETHUSDT","localReceivedEpochMillis":1784431313928,"rawPayload":"{\"stream\":\"ethusdt@depth@100ms\",\"data\":{\"e\":\"depthUpdate\",\"E\":1784431313938,\"s\":\"ETHUSDT\",\"U\":2806197738,\"u\":2806197741,\"b\":[[\"1864.06000000\",\"0.00000000\"],[\"1864.00000000\",\"0.13940000\"],[\"1863.82000000\",\"0.00000000\"],[\"1863.70000000\",\"1.48090000\"]],\"a\":[[\"1864.66000000\",\"0.13940000\"],[\"1864.72000000\",\"1.10950000\"],[\"1864.96000000\",\"1.47990000\"],[\"1865.02000000\",\"0.00000000\"]]}}"}
{"mode":"v11-raw-disruptor","partitions":4,"sequenceNumber":3,"routingSymbol":"XRPUSDT","localReceivedEpochMillis":1784431313929,"rawPayload":"{\"stream\":\"xrpusdt@depth@100ms\",\"data\":{\"e\":\"depthUpdate\",\"E\":1784431313938,\"s\":\"XRPUSDT\",\"U\":752712073,\"u\":752712073,\"b\":[],\"a\":[[\"1.09470000\",\"2521.10000000\"],[\"1.09480000\",\"0.00000000\"]]}}"}
{"mode":"v11-raw-disruptor","partitions":4,"sequenceNumber":4,"routingSymbol":"ETHUSDT","localReceivedEpochMillis":1784431314027,"rawPayload":"{\"stream\":\"ethusdt@depth@100ms\",\"data\":{\"e\":\"depthUpdate\",\"E\":1784431314038,\"s\":\"ETHUSDT\",\"U\":2806197742,\"u\":2806197743,\"b\":[[\"1855.36000000\",\"9.22220000\"]],\"a\":[[\"1864.96000000\",\"1.53500000\"]]}}"}
{"mode":"v11-raw-disruptor","partitions":4,"sequenceNumber":5,"routingSymbol":"SOLUSDT","localReceivedEpochMillis":1784431314128,"rawPayload":"{\"stream\":\"solusdt@depth@100ms\",\"data\":{\"e\":\"depthUpdate\",\"E\":1784431314138,\"s\":\"SOLUSDT\",\"U\":1609591555,\"u\":1609591557,\"b\":[],\"a\":[[\"75.92000000\",\"69.83400000\"],[\"75.93000000\",\"30.19500000\"],[\"90.00000000\",\"193.47100000\"]]}}"}
{"mode":"v11-raw-disruptor","partitions":4,"sequenceNumber":6,"routingSymbol":"ETHUSDT","localReceivedEpochMillis":1784431314128,"rawPayload":"{\"stream\":\"ethusdt@depth@100ms\",\"data\":{\"e\":\"depthUpdate\",\"E\":1784431314138,\"s\":\"ETHUSDT\",\"U\":2806197744,\"u\":2806197745,\"b\":[[\"1863.61000000\",\"0.00000000\"],[\"1863.56000000\",\"0.39450000\"]],\"a\":[]}}"}
{"mode":"v11-raw-disruptor","partitions":4,"sequenceNumber":7,"routingSymbol":"SOLUSDT","localReceivedEpochMillis":1784431314428,"rawPayload":"{\"stream\":\"solusdt@depth@100ms\",\"data\":{\"e\":\"depthUpdate\",\"E\":1784431314438,\"s\":\"SOLUSDT\",\"U\":1609591558,\"u\":1609591565,\"b\":[[\"75.80000000\",\"0.00000000\"],[\"75.77000000\",\"123.73000000\"],[\"75.75000000\",\"16.91000000\"],[\"75.73000000\",\"372.63200000\"],[\"75.70000000\",\"57.20900000\"],[\"75.68000000\",\"189.23400000\"],[\"75.61000000\",\"334.10900000\"],[\"75.59000000\",\"488.91700000\"]],\"a\":[[\"75.97000000\",\"118.89200000\"],[\"75.99000000\",\"274.61300000\"],[\"76.01000000\",\"307.91500000\"],[\"76.03000000\",\"270.82300000\"],[\"76.06000000\",\"329.05800000\"],[\"76.08000000\",\"304.28200000\"],[\"76.15000000\",\"148.15000000\"],[\"76.17000000\",\"0.00000000\"]]}}"}
{"mode":"v11-raw-disruptor","partitions":4,"sequenceNumber":8,"routingSymbol":"ETHUSDT","localReceivedEpochMillis":1784431314529,"rawPayload":"{\"stream\":\"ethusdt@depth@100ms\",\"data\":{\"e\":\"depthUpdate\",\"E\":1784431314538,\"s\":\"ETHUSDT\",\"U\":2806197746,\"u\":2806197746,\"b\":[],\"a\":[[\"1864.47000000\",\"0.02940000\"]]}}"}
{"mode":"v11-raw-disruptor","partitions":4,"sequenceNumber":9,"routingSymbol":"SOLUSDT","localReceivedEpochMillis":1784431314728,"rawPayload":"{\"stream\":\"solusdt@depth@100ms\",\"data\":{\"e\":\"depthUpdate\",\"E\":1784431314739,\"s\":\"SOLUSDT\",\"U\":1609591566,\"u\":1609591569,\"b\":[],\"a\":[[\"75.89000000\",\"70.01400000\"],[\"75.90000000\",\"30.19500000\"],[\"75.93000000\",\"0.00000000\"],[\"75.98000000\",\"54.78900000\"]]}}"}
{"mode":"v11-raw-disruptor","partitions":4,"sequenceNumber":10,"routingSymbol":"ETHUSDT","localReceivedEpochMillis":1784431314728,"rawPayload":"{\"stream\":\"ethusdt@depth@100ms\",\"data\":{\"e\":\"depthUpdate\",\"E\":1784431314739,\"s\":\"ETHUSDT\",\"U\":2806197747,\"u\":2806197748,\"b\":[],\"a\":[[\"1864.47000000\",\"0.44120000\"],[\"1864.61000000\",\"0.00000000\"]]}}"}
{"mode":"v11-raw-disruptor","partitions":4,"sequenceNumber":11,"routingSymbol":"BNBUSDT","localReceivedEpochMillis":1784431315131,"rawPayload":"{\"stream\":\"bnbusdt@depth@100ms\",\"data\":{\"e\":\"depthUpdate\",\"E\":1784431315139,\"s\":\"BNBUSDT\",\"U\":1236336027,\"u\":1236336028,\"b\":[],\"a\":[[\"569.59000000\",\"1.65400000\"],[\"569.66000000\",\"0.00000000\"]]}}"}
{"mode":"v11-raw-disruptor","partitions":4,"sequenceNumber":12,"routingSymbol":"SOLUSDT","localReceivedEpochMillis":1784431315331,"rawPayload":"{\"stream\":\"solusdt@depth@100ms\",\"data\":{\"e\":\"depthUpdate\",\"E\":1784431315339,\"s\":\"SOLUSDT\",\"U\":1609591570,\"u\":1609591571,\"b\":[],\"a\":[[\"75.89000000\",\"80.07900000\"]]}}"}
{"mode":"v11-raw-disruptor","partitions":4,"sequenceNumber":13,"routingSymbol":"BNBUSDT","localReceivedEpochMillis":1784431315331,"rawPayload":"{\"stream\":\"bnbusdt@depth@100ms\",\"data\":{\"e\":\"depthUpdate\",\"E\":1784431315339,\"s\":\"BNBUSDT\",\"U\":1236336029,\"u\":1236336030,\"b\":[[\"569.21000000\",\"0.00000000\"],[\"569.15000000\",\"1.65400000\"]],\"a\":[]}}"}
{"mode":"v11-raw-disruptor","partitions":4,"sequenceNumber":14,"routingSymbol":"BTCUSDT","localReceivedEpochMillis":1784431315430,"rawPayload":"{\"stream\":\"btcusdt@depth@100ms\",\"data\":{\"e\":\"depthUpdate\",\"E\":1784431315439,\"s\":\"BTCUSDT\",\"U\":3244451533,\"u\":3244451533,\"b\":[],\"a\":[[\"80837.82000000\",\"0.00075000\"]]}}"}
{"mode":"v11-raw-disruptor","partitions":4,"sequenceNumber":15,"routingSymbol":"ETHUSDT","localReceivedEpochMillis":1784431315531,"rawPayload":"{\"stream\":\"ethusdt@depth@100ms\",\"data\":{\"e\":\"depthUpdate\",\"E\":1784431315539,\"s\":\"ETHUSDT\",\"U\":2806197749,\"u\":2806197749,\"b\":[],\"a\":[[\"1865.13000000\",\"0.97360000\"],[\"1865.22000000\",\"0.00000000\"]]}}"}
{"mode":"v11-raw-disruptor","partitions":4,"sequenceNumber":16,"routingSymbol":"ETHUSDT","localReceivedEpochMillis":1784431315730,"rawPayload":"{\"stream\":\"ethusdt@depth@100ms\",\"data\":{\"e\":\"depthUpdate\",\"E\":1784431315739,\"s\":\"ETHUSDT\",\"U\":2806197750,\"u\":2806197751,\"b\":[[\"1863.61000000\",\"0.46870000\"],[\"1863.56000000\",\"0.00000000\"]],\"a\":[]}}"}
{"mode":"v11-raw-disruptor","partitions":4,"sequenceNumber":17,"routingSymbol":"BTCUSDT","localReceivedEpochMillis":1784431315829,"rawPayload":"{\"stream\":\"btcusdt@depth@100ms\",\"data\":{\"e\":\"depthUpdate\",\"E\":1784431315839,\"s\":\"BTCUSDT\",\"U\":3244451534,\"u\":3244451534,\"b\":[[\"64390.00000000\",\"0.00000000\"]],\"a\":[]}}"}
{"mode":"v11-raw-disruptor","partitions":4,"sequenceNumber":18,"routingSymbol":"SOLUSDT","localReceivedEpochMillis":1784431316329,"rawPayload":"{\"stream\":\"solusdt@depth@100ms\",\"data\":{\"e\":\"depthUpdate\",\"E\":1784431316340,\"s\":\"SOLUSDT\",\"U\":1609591572,\"u\":1609591572,\"b\":[],\"a\":[[\"75.90000000\",\"50.32500000\"]]}}"}
{"mode":"v11-raw-disruptor","partitions":4,"sequenceNumber":19,"routingSymbol":"SOLUSDT","localReceivedEpochMillis":1784431317131,"rawPayload":"{\"stream\":\"solusdt@depth@100ms\",\"data\":{\"e\":\"depthUpdate\",\"E\":1784431317140,\"s\":\"SOLUSDT\",\"U\":1609591573,\"u\":1609591574,\"b\":[],\"a\":[[\"75.86000000\",\"6.59400000\"],[\"75.87000000\",\"32.97300000\"]]}}"}
{"mode":"v11-raw-disruptor","partitions":4,"sequenceNumber":20,"routingSymbol":"SOLUSDT","localReceivedEpochMillis":1784431317430,"rawPayload":"{\"stream\":\"solusdt@depth@100ms\",\"data\":{\"e\":\"depthUpdate\",\"E\":1784431317440,\"s\":\"SOLUSDT\",\"U\":1609591575,\"u\":1609591579,\"b\":[],\"a\":[[\"75.89000000\",\"49.88400000\"],[\"75.90000000\",\"0.00000000\"],[\"75.92000000\",\"39.63900000\"],[\"75.98000000\",\"0.00000000\"]]}}"}
{"mode":"v11-raw-disruptor","partitions":4,"sequenceNumber":21,"routingSymbol":"SOLUSDT","localReceivedEpochMillis":1784431317532,"rawPayload":"{\"stream\":\"solusdt@depth@100ms\",\"data\":{\"e\":\"depthUpdate\",\"E\":1784431317540,\"s\":\"SOLUSDT\",\"U\":1609591580,\"u\":1609591581,\"b\":[[\"75.85000000\",\"19.84100000\"]],\"a\":[[\"75.89000000\",\"30.83400000\"],[\"75.90000000\",\"19.05000000\"]]}}"}
{"mode":"v11-raw-disruptor","partitions":4,"sequenceNumber":22,"routingSymbol":"ETHUSDT","localReceivedEpochMillis":1784431317533,"rawPayload":"{\"stream\":\"ethusdt@depth@100ms\",\"data\":{\"e\":\"depthUpdate\",\"E\":1784431317540,\"s\":\"ETHUSDT\",\"U\":2806197752,\"u\":2806197753,\"b\":[[\"1863.61000000\",\"0.00000000\"],[\"1863.56000000\",\"0.56240000\"]],\"a\":[]}}"}
{"mode":"v11-raw-disruptor","partitions":4,"sequenceNumber":23,"routingSymbol":"ETHUSDT","localReceivedEpochMillis":1784431317731,"rawPayload":"{\"stream\":\"ethusdt@depth@100ms\",\"data\":{\"e\":\"depthUpdate\",\"E\":1784431317741,\"s\":\"ETHUSDT\",\"U\":2806197754,\"u\":2806197758,\"b\":[[\"1864.46000000\",\"0.00000000\"],[\"1864.44000000\",\"1.01970000\"]],\"a\":[[\"1864.46000000\",\"1.34170000\"],[\"1864.60000000\",\"0.00000000\"],[\"1864.93000000\",\"0.00000000\"],[\"1865.05000000\",\"0.97360000\"],[\"1865.13000000\",\"0.00000000\"]]}}"}
{"mode":"v11-raw-disruptor","partitions":4,"sequenceNumber":24,"routingSymbol":"SOLUSDT","localReceivedEpochMillis":1784431318032,"rawPayload":"{\"stream\":\"solusdt@depth@100ms\",\"data\":{\"e\":\"depthUpdate\",\"E\":1784431318041,\"s\":\"SOLUSDT\",\"U\":1609591582,\"u\":1609591586,\"b\":[],\"a\":[[\"75.93000000\",\"50.32500000\"],[\"75.94000000\",\"43.38400000\"],[\"75.95000000\",\"30.19500000\"],[\"76.27000000\",\"54.78900000\"]]}}"}
{"mode":"v11-raw-disruptor","partitions":4,"sequenceNumber":25,"routingSymbol":"BTCUSDT","localReceivedEpochMillis":1784431318131,"rawPayload":"{\"stream\":\"btcusdt@depth@100ms\",\"data\":{\"e\":\"depthUpdate\",\"E\":1784431318141,\"s\":\"BTCUSDT\",\"U\":3244451535,\"u\":3244451536,\"b\":[[\"64635.89000000\",\"0.00000000\"],[\"64634.02000000\",\"0.01858000\"]],\"a\":[]}}"}
{"mode":"v11-raw-disruptor","partitions":4,"sequenceNumber":26,"routingSymbol":"SOLUSDT","localReceivedEpochMillis":1784431318231,"rawPayload":"{\"stream\":\"solusdt@depth@100ms\",\"data\":{\"e\":\"depthUpdate\",\"E\":1784431318241,\"s\":\"SOLUSDT\",\"U\":1609591587,\"u\":1609591588,\"b\":[],\"a\":[[\"75.98000000\",\"54.78900000\"],[\"76.27000000\",\"0.00000000\"]]}}"}
{"mode":"v11-raw-disruptor","partitions":4,"sequenceNumber":27,"routingSymbol":"ETHUSDT","localReceivedEpochMillis":1784431318231,"rawPayload":"{\"stream\":\"ethusdt@depth@100ms\",\"data\":{\"e\":\"depthUpdate\",\"E\":1784431318241,\"s\":\"ETHUSDT\",\"U\":2806197759,\"u\":2806197760,\"b\":[[\"1863.79000000\",\"0.00000000\"],[\"1863.01000000\",\"1.63970000\"]],\"a\":[]}}"}
{"mode":"v11-raw-disruptor","partitions":4,"sequenceNumber":28,"routingSymbol":"BTCUSDT","localReceivedEpochMillis":1784431318231,"rawPayload":"{\"stream\":\"btcusdt@depth@100ms\",\"data\":{\"e\":\"depthUpdate\",\"E\":1784431318241,\"s\":\"BTCUSDT\",\"U\":3244451537,\"u\":3244451538,\"b\":[],\"a\":[[\"64653.68000000\",\"0.02787000\"],[\"64660.17000000\",\"0.00000000\"]]}}"}
{"mode":"v11-raw-disruptor","partitions":4,"sequenceNumber":29,"routingSymbol":"XRPUSDT","localReceivedEpochMillis":1784431318331,"rawPayload":"{\"stream\":\"xrpusdt@depth@100ms\",\"data\":{\"e\":\"depthUpdate\",\"E\":1784431318341,\"s\":\"XRPUSDT\",\"U\":752712074,\"u\":752712074,\"b\":[],\"a\":[[\"1.09430000\",\"3820.50000000\"]]}}"}
{"mode":"v11-raw-disruptor","partitions":4,"sequenceNumber":30,"routingSymbol":"BTCUSDT","localReceivedEpochMillis":1784431318431,"rawPayload":"{\"stream\":\"btcusdt@depth@100ms\",\"data\":{\"e\":\"depthUpdate\",\"E\":1784431318441,\"s\":\"BTCUSDT\",\"U\":3244451539,\"u\":3244451542,\"b\":[[\"64636.01000000\",\"0.01996000\"],[\"64634.02000000\",\"0.00000000\"]],\"a\":[[\"64651.41000000\",\"0.34755000\"],[\"64664.36000000\",\"0.00000000\"]]}}"}
{"mode":"v11-raw-disruptor","partitions":4,"sequenceNumber":31,"routingSymbol":"BTCUSDT","localReceivedEpochMillis":1784431318631,"rawPayload":"{\"stream\":\"btcusdt@depth@100ms\",\"data\":{\"e\":\"depthUpdate\",\"E\":1784431318641,\"s\":\"BTCUSDT\",\"U\":3244451543,\"u\":3244451544,\"b\":[[\"64636.01000000\",\"0.00000000\"],[\"64634.38000000\",\"0.02044000\"]],\"a\":[]}}"}
{"mode":"v11-raw-disruptor","partitions":4,"sequenceNumber":32,"routingSymbol":"XRPUSDT","localReceivedEpochMillis":1784431318932,"rawPayload":"{\"stream\":\"xrpusdt@depth@100ms\",\"data\":{\"e\":\"depthUpdate\",\"E\":1784431318941,\"s\":\"XRPUSDT\",\"U\":752712075,\"u\":752712076,\"b\":[[\"1.09390000\",\"4185.60000000\"],[\"1.09380000\",\"10979.50000000\"]],\"a\":[]}}"}
{"mode":"v11-raw-disruptor","partitions":4,"sequenceNumber":33,"routingSymbol":"BTCUSDT","localReceivedEpochMillis":1784431319032,"rawPayload":"{\"stream\":\"btcusdt@depth@100ms\",\"data\":{\"e\":\"depthUpdate\",\"E\":1784431319041,\"s\":\"BTCUSDT\",\"U\":3244451545,\"u\":3244451546,\"b\":[],\"a\":[[\"64663.45000000\",\"0.00000000\"],[\"64663.78000000\",\"0.00170000\"]]}}"}
{"mode":"v11-raw-disruptor","partitions":4,"sequenceNumber":34,"routingSymbol":"ETHUSDT","localReceivedEpochMillis":1784431319131,"rawPayload":"{\"stream\":\"ethusdt@depth@100ms\",\"data\":{\"e\":\"depthUpdate\",\"E\":1784431319141,\"s\":\"ETHUSDT\",\"U\":2806197761,\"u\":2806197762,\"b\":[[\"1863.62000000\",\"0.66240000\"],[\"1863.56000000\",\"0.00000000\"]],\"a\":[]}}"}
{"mode":"v11-raw-disruptor","partitions":4,"sequenceNumber":35,"routingSymbol":"BTCUSDT","localReceivedEpochMillis":1784431319131,"rawPayload":"{\"stream\":\"btcusdt@depth@100ms\",\"data\":{\"e\":\"depthUpdate\",\"E\":1784431319141,\"s\":\"BTCUSDT\",\"U\":3244451547,\"u\":3244451548,\"b\":[[\"64636.01000000\",\"0.02145000\"],[\"64634.38000000\",\"0.00000000\"]],\"a\":[]}}"}
{"mode":"v11-raw-disruptor","partitions":4,"sequenceNumber":36,"routingSymbol":"XRPUSDT","localReceivedEpochMillis":1784431319131,"rawPayload":"{\"stream\":\"xrpusdt@depth@100ms\",\"data\":{\"e\":\"depthUpdate\",\"E\":1784431319141,\"s\":\"XRPUSDT\",\"U\":752712077,\"u\":752712081,\"b\":[[\"1.09390000\",\"4002.80000000\"],[\"1.09380000\",\"11162.30000000\"]],\"a\":[[\"1.09420000\",\"182.80000000\"],[\"1.09430000\",\"2331.60000000\"],[\"1.09440000\",\"5230.60000000\"]]}}"}
{"mode":"v11-raw-disruptor","partitions":4,"sequenceNumber":37,"routingSymbol":"ETHUSDT","localReceivedEpochMillis":1784431319231,"rawPayload":"{\"stream\":\"ethusdt@depth@100ms\",\"data\":{\"e\":\"depthUpdate\",\"E\":1784431319242,\"s\":\"ETHUSDT\",\"U\":2806197763,\"u\":2806197768,\"b\":[[\"1864.05000000\",\"1.34200000\"],[\"1863.89000000\",\"0.00000000\"],[\"1863.69000000\",\"0.67390000\"],[\"1863.62000000\",\"0.00000000\"]],\"a\":[[\"1864.46000000\",\"0.00000000\"],[\"1864.62000000\",\"1.34160000\"]]}}"}
{"mode":"v11-raw-disruptor","partitions":4,"sequenceNumber":38,"routingSymbol":"SOLUSDT","localReceivedEpochMillis":1784431319331,"rawPayload":"{\"stream\":\"solusdt@depth@100ms\",\"data\":{\"e\":\"depthUpdate\",\"E\":1784431319342,\"s\":\"SOLUSDT\",\"U\":1609591589,\"u\":1609591598,\"b\":[],\"a\":[[\"75.89000000\",\"61.02900000\"],[\"75.90000000\",\"69.37500000\"],[\"75.91000000\",\"81.37600000\"],[\"75.93000000\",\"0.00000000\"],[\"75.94000000\",\"13.18900000\"],[\"75.95000000\",\"0.00000000\"]]}}"}
{"mode":"v11-raw-disruptor","partitions":4,"sequenceNumber":39,"routingSymbol":"ETHUSDT","localReceivedEpochMillis":1784431319332,"rawPayload":"{\"stream\":\"ethusdt@depth@100ms\",\"data\":{\"e\":\"depthUpdate\",\"E\":1784431319342,\"s\":\"ETHUSDT\",\"U\":2806197769,\"u\":2806197784,\"b\":[[\"1864.05000000\",\"0.00000000\"],[\"1863.87000000\",\"0.70730000\"],[\"1863.80000000\",\"0.00000000\"],[\"1863.69000000\",\"0.00000000\"],[\"1863.40000000\",\"13.36850000\"],[\"1863.19000000\",\"0.00000000\"],[\"1855.36000000\",\"0.00000000\"]],\"a\":[[\"1864.62000000\",\"0.00000000\"],[\"1864.81000000\",\"0.00000000\"],[\"1865.63000000\",\"1.63970000\"],[\"1871.61000000\",\"0.00000000\"],[\"1871.63000000\",\"7.21550000\"],[\"1871.88000000\",\"7.91040000\"],[\"1873.28000000\",\"0.00000000\"],[\"1873.36000000\",\"0.00000000\"]]}}"}
{"mode":"v11-raw-disruptor","partitions":4,"sequenceNumber":40,"routingSymbol":"ETHUSDT","localReceivedEpochMillis":1784431319432,"rawPayload":"{\"stream\":\"ethusdt@depth@100ms\",\"data\":{\"e\":\"depthUpdate\",\"E\":1784431319442,\"s\":\"ETHUSDT\",\"U\":2806197785,\"u\":2806197785,\"b\":[],\"a\":[[\"1864.47000000\",\"0.02940000\"]]}}"}
{"mode":"v11-raw-disruptor","partitions":4,"sequenceNumber":41,"routingSymbol":"ETHUSDT","localReceivedEpochMillis":1784431319532,"rawPayload":"{\"stream\":\"ethusdt@depth@100ms\",\"data\":{\"e\":\"depthUpdate\",\"E\":1784431319542,\"s\":\"ETHUSDT\",\"U\":2806197786,\"u\":2806197786,\"b\":[],\"a\":[[\"1871.63000000\",\"0.00000000\"]]}}"}
{"mode":"v11-raw-disruptor","partitions":4,"sequenceNumber":42,"routingSymbol":"ETHUSDT","localReceivedEpochMillis":1784431319631,"rawPayload":"{\"stream\":\"ethusdt@depth@100ms\",\"data\":{\"e\":\"depthUpdate\",\"E\":1784431319642,\"s\":\"ETHUSDT\",\"U\":2806197787,\"u\":2806197789,\"b\":[[\"1856.83000000\",\"34.19930000\"]],\"a\":[[\"1871.73000000\",\"7.20410000\"],[\"1872.05000000\",\"8.17330000\"]]}}"}
{"mode":"v11-raw-disruptor","partitions":4,"sequenceNumber":43,"routingSymbol":"SOLUSDT","localReceivedEpochMillis":1784431319731,"rawPayload":"{\"stream\":\"solusdt@depth@100ms\",\"data\":{\"e\":\"depthUpdate\",\"E\":1784431319742,\"s\":\"SOLUSDT\",\"U\":1609591599,\"u\":1609591599,\"b\":[],\"a\":[[\"75.89000000\",\"80.07900000\"],[\"75.90000000\",\"50.32500000\"]]}}"}
{"mode":"v11-raw-disruptor","partitions":4,"sequenceNumber":44,"routingSymbol":"ETHUSDT","localReceivedEpochMillis":1784431319732,"rawPayload":"{\"stream\":\"ethusdt@depth@100ms\",\"data\":{\"e\":\"depthUpdate\",\"E\":1784431319742,\"s\":\"ETHUSDT\",\"U\":2806197790,\"u\":2806197792,\"b\":[[\"1864.00000000\",\"0.00000000\"],[\"1863.95000000\",\"0.13940000\"]],\"a\":[[\"1864.61000000\",\"0.13940000\"],[\"1864.66000000\",\"0.00000000\"],[\"1865.95000000\",\"9.21770000\"],[\"1866.12000000\",\"0.00000000\"]]}}"}
{"mode":"v11-raw-disruptor","partitions":4,"sequenceNumber":45,"routingSymbol":"XRPUSDT","localReceivedEpochMillis":1784431319732,"rawPayload":"{\"stream\":\"xrpusdt@depth@100ms\",\"data\":{\"e\":\"depthUpdate\",\"E\":1784431319742,\"s\":\"XRPUSDT\",\"U\":752712082,\"u\":752712083,\"b\":[[\"1.09210000\",\"15833.50000000\"]],\"a\":[[\"1.09610000\",\"12696.70000000\"]]}}"}
{"mode":"v11-raw-disruptor","partitions":4,"sequenceNumber":46,"routingSymbol":"XRPUSDT","localReceivedEpochMillis":1784431319833,"rawPayload":"{\"stream\":\"xrpusdt@depth@100ms\",\"data\":{\"e\":\"depthUpdate\",\"E\":1784431319842,\"s\":\"XRPUSDT\",\"U\":752712084,\"u\":752712089,\"b\":[[\"1.09140000\",\"15998.30000000\"],[\"1.09010000\",\"15840.40000000\"]],\"a\":[[\"1.09470000\",\"0.00000000\"],[\"1.09480000\",\"2521.10000000\"],[\"1.09550000\",\"0.00000000\"],[\"1.09680000\",\"0.00000000\"],[\"1.09810000\",\"0.00000000\"]]}}"}
{"mode":"v11-raw-disruptor","partitions":4,"sequenceNumber":47,"routingSymbol":"ETHUSDT","localReceivedEpochMillis":1784431320132,"rawPayload":"{\"stream\":\"ethusdt@depth@100ms\",\"data\":{\"e\":\"depthUpdate\",\"E\":1784431320142,\"s\":\"ETHUSDT\",\"U\":2806197793,\"u\":2806197794,\"b\":[[\"1864.19000000\",\"1.34190000\"]],\"a\":[[\"1864.78000000\",\"1.34150000\"]]}}"}
{"mode":"v11-raw-disruptor","partitions":4,"sequenceNumber":48,"routingSymbol":"BNBUSDT","localReceivedEpochMillis":1784431320132,"rawPayload":"{\"stream\":\"bnbusdt@depth@100ms\",\"data\":{\"e\":\"depthUpdate\",\"E\":1784431320142,\"s\":\"BNBUSDT\",\"U\":1236336031,\"u\":1236336043,\"b\":[[\"569.34000000\",\"0.00000000\"],[\"569.25000000\",\"0.87800000\"],[\"567.15000000\",\"0.00000000\"],[\"567.13000000\",\"0.00000000\"],[\"567.12000000\",\"0.00000000\"],[\"567.11000000\",\"1.72500000\"],[\"566.74000000\",\"0.00000000\"]],\"a\":[[\"569.40000000\",\"2.47300000\"],[\"569.46000000\",\"3.30400000\"],[\"569.67000000\",\"0.00000000\"],[\"571.67000000\",\"1.72700000\"],[\"572.11000000\",\"0.00000000\"]]}}"}
{"mode":"v11-raw-disruptor","partitions":4,"sequenceNumber":49,"routingSymbol":"BTCUSDT","localReceivedEpochMillis":1784431320132,"rawPayload":"{\"stream\":\"btcusdt@depth@100ms\",\"data\":{\"e\":\"depthUpdate\",\"E\":1784431320142,\"s\":\"BTCUSDT\",\"U\":3244451549,\"u\":3244451549,\"b\":[],\"a\":[[\"80837.82000000\",\"0.00075000\"]]}}"}
{"mode":"v11-raw-disruptor","partitions":4,"sequenceNumber":50,"routingSymbol":"XRPUSDT","localReceivedEpochMillis":1784431320133,"rawPayload":"{\"stream\":\"xrpusdt@depth@100ms\",\"data\":{\"e\":\"depthUpdate\",\"E\":1784431320142,\"s\":\"XRPUSDT\",\"U\":752712090,\"u\":752712091,\"b\":[[\"1.09360000\",\"2074.70000000\"],[\"1.09340000\",\"2440.40000000\"]],\"a\":[]}}"}
{"mode":"v11-raw-disruptor","partitions":4,"sequenceNumber":51,"routingSymbol":"SOLUSDT","localReceivedEpochMillis":1784431320232,"rawPayload":"{\"stream\":\"solusdt@depth@100ms\",\"data\":{\"e\":\"depthUpdate\",\"E\":1784431320242,\"s\":\"SOLUSDT\",\"U\":1609591600,\"u\":1609591605,\"b\":[[\"75.84000000\",\"75.39900000\"]],\"a\":[[\"75.88000000\",\"14.12700000\"],[\"75.89000000\",\"35.66400000\"],[\"75.90000000\",\"30.19500000\"],[\"75.93000000\",\"30.19500000\"]]}}"}
{"mode":"v11-raw-disruptor","partitions":4,"sequenceNumber":52,"routingSymbol":"ETHUSDT","localReceivedEpochMillis":1784431320232,"rawPayload":"{\"stream\":\"ethusdt@depth@100ms\",\"data\":{\"e\":\"depthUpdate\",\"E\":1784431320242,\"s\":\"ETHUSDT\",\"U\":2806197795,\"u\":2806197796,\"b\":[[\"1863.54000000\",\"0.00000000\"],[\"1863.28000000\",\"2.73280000\"]],\"a\":[]}}"}
{"mode":"v11-raw-disruptor","partitions":4,"sequenceNumber":53,"routingSymbol":"BNBUSDT","localReceivedEpochMillis":1784431320232,"rawPayload":"{\"stream\":\"bnbusdt@depth@100ms\",\"data\":{\"e\":\"depthUpdate\",\"E\":1784431320242,\"s\":\"BNBUSDT\",\"U\":1236336044,\"u\":1236336044,\"b\":[[\"566.74000000\",\"2.21600000\"]],\"a\":[]}}"}
{"mode":"v11-raw-disruptor","partitions":4,"sequenceNumber":54,"routingSymbol":"XRPUSDT","localReceivedEpochMillis":1784431320232,"rawPayload":"{\"stream\":\"xrpusdt@depth@100ms\",\"data\":{\"e\":\"depthUpdate\",\"E\":1784431320242,\"s\":\"XRPUSDT\",\"U\":752712092,\"u\":752712093,\"b\":[],\"a\":[[\"1.09440000\",\"6189.00000000\"],[\"1.09450000\",\"2074.70000000\"]]}}"}
{"mode":"v11-raw-disruptor","partitions":4,"sequenceNumber":55,"routingSymbol":"SOLUSDT","localReceivedEpochMillis":1784431320330,"rawPayload":"{\"stream\":\"solusdt@depth@100ms\",\"data\":{\"e\":\"depthUpdate\",\"E\":1784431320342,\"s\":\"SOLUSDT\",\"U\":1609591606,\"u\":1609591610,\"b\":[[\"75.84000000\",\"89.62600000\"],[\"75.82000000\",\"30.19500000\"],[\"75.81000000\",\"68.93500000\"],[\"75.77000000\",\"24.09600000\"],[\"75.76000000\",\"99.64700000\"]],\"a\":[[\"75.88000000\",\"0.55400000\"],[\"75.89000000\",\"49.60800000\"]]}}"}
{"mode":"v11-raw-disruptor","partitions":4,"sequenceNumber":56,"routingSymbol":"ETHUSDT","localReceivedEpochMillis":1784431320332,"rawPayload":"{\"stream\":\"ethusdt@depth@100ms\",\"data\":{\"e\":\"depthUpdate\",\"E\":1784431320342,\"s\":\"ETHUSDT\",\"U\":2806197797,\"u\":2806197812,\"b\":[[\"1864.44000000\",\"0.00000000\"],[\"1864.35000000\",\"1.01970000\"],[\"1864.30000000\",\"1.11130000\"],[\"1864.15000000\",\"0.00000000\"],[\"1863.06000000\",\"0.00000000\"],[\"1862.67000000\",\"2.01670000\"],[\"1861.94000000\",\"0.00000000\"],[\"1861.55000000\",\"2.97580000\"],[\"1860.82000000\",\"0.00000000\"],[\"1860.44000000\",\"5.93290000\"],[\"1858.58000000\",\"0.00000000\"],[\"1858.20000000\",\"14.08700000\"]],\"a\":[[\"1864.72000000\",\"0.00000000\"],[\"1864.86000000\",\"1.13210000\"],[\"1864.92000000\",\"0.00000000\"],[\"1864.96000000\",\"1.47990000\"],[\"1867.16000000\",\"2.09560000\"],[\"1867.55000000\",\"0.00000000\"],[\"1869.40000000\",\"9.63820000\"],[\"1869.78000000\",\"0.00000000\"]]}}"}
{"mode":"v11-raw-disruptor","partitions":4,"sequenceNumber":57,"routingSymbol":"ETHUSDT","localReceivedEpochMillis":1784431320432,"rawPayload":"{\"stream\":\"ethusdt@depth@100ms\",\"data\":{\"e\":\"depthUpdate\",\"E\":1784431320442,\"s\":\"ETHUSDT\",\"U\":2806197813,\"u\":2806197826,\"b\":[[\"1864.30000000\",\"0.00000000\"],[\"1864.23000000\",\"0.00000000\"],[\"1864.19000000\",\"0.00000000\"],[\"1864.17000000\",\"1.10520000\"],[\"1864.04000000\",\"1.34200000\"],[\"1863.87000000\",\"0.02940000\"],[\"1863.81000000\",\"0.74960000\"]],\"a\":[[\"1864.64000000\",\"1.34160000\"],[\"1864.74000000\",\"1.16330000\"],[\"1864.78000000\",\"0.00000000\"],[\"1864.80000000\",\"0.00000000\"],[\"1864.86000000\",\"0.00000000\"]]}}"}
{"mode":"v11-raw-disruptor","partitions":4,"sequenceNumber":58,"routingSymbol":"BNBUSDT","localReceivedEpochMillis":1784431320432,"rawPayload":"{\"stream\":\"bnbusdt@depth@100ms\",\"data\":{\"e\":\"depthUpdate\",\"E\":1784431320442,\"s\":\"BNBUSDT\",\"U\":1236336045,\"u\":1236336045,\"b\":[[\"566.72000000\",\"2.21100000\"]],\"a\":[]}}"}
{"mode":"v11-raw-disruptor","partitions":4,"sequenceNumber":59,"routingSymbol":"SOLUSDT","localReceivedEpochMillis":1784431320532,"rawPayload":"{\"stream\":\"solusdt@depth@100ms\",\"data\":{\"e\":\"depthUpdate\",\"E\":1784431320542,\"s\":\"SOLUSDT\",\"U\":1609591611,\"u\":1609591615,\"b\":[],\"a\":[[\"75.88000000\",\"15.09600000\"],[\"75.89000000\",\"46.80900000\"],[\"75.90000000\",\"49.24500000\"],[\"75.93000000\",\"0.00000000\"]]}}"}
{"mode":"v11-raw-disruptor","partitions":4,"sequenceNumber":60,"routingSymbol":"ETHUSDT","localReceivedEpochMillis":1784431320532,"rawPayload":"{\"stream\":\"ethusdt@depth@100ms\",\"data\":{\"e\":\"depthUpdate\",\"E\":1784431320542,\"s\":\"ETHUSDT\",\"U\":2806197827,\"u\":2806197845,\"b\":[[\"1864.23000000\",\"0.00000000\"],[\"1864.18000000\",\"1.09490000\"],[\"1864.17000000\",\"0.00000000\"],[\"1864.04000000\",\"0.00000000\"],[\"1863.87000000\",\"1.37150000\"],[\"1863.81000000\",\"0.00000000\"],[\"1863.67000000\",\"0.75760000\"]],\"a\":[[\"1864.44000000\",\"1.34170000\"],[\"1864.64000000\",\"0.00000000\"],[\"1864.74000000\",\"0.00000000\"],[\"1864.75000000\",\"1.14660000\"],[\"1864.80000000\",\"0.00000000\"],[\"1864.92000000\",\"0.05930000\"],[\"1864.96000000\",\"1.47990000\"],[\"1865.03000000\",\"0.00000000\"]]}}"}
{"mode":"v11-raw-disruptor","partitions":4,"sequenceNumber":61,"routingSymbol":"BTCUSDT","localReceivedEpochMillis":1784431320532,"rawPayload":"{\"stream\":\"btcusdt@depth@100ms\",\"data\":{\"e\":\"depthUpdate\",\"E\":1784431320542,\"s\":\"BTCUSDT\",\"U\":3244451550,\"u\":3244451553,\"b\":[[\"64636.01000000\",\"0.00000000\"],[\"64634.23000000\",\"0.02480000\"],[\"64625.74000000\",\"0.00000000\"],[\"64619.10000000\",\"0.03720000\"]],\"a\":[]}}"}
{"mode":"v11-raw-disruptor","partitions":4,"sequenceNumber":62,"routingSymbol":"BNBUSDT","localReceivedEpochMillis":1784431320532,"rawPayload":"{\"stream\":\"bnbusdt@depth@100ms\",\"data\":{\"e\":\"depthUpdate\",\"E\":1784431320542,\"s\":\"BNBUSDT\",\"U\":1236336046,\"u\":1236336046,\"b\":[[\"567.65000000\",\"0.00000000\"]],\"a\":[]}}"}
{"mode":"v11-raw-disruptor","partitions":4,"sequenceNumber":63,"routingSymbol":"XRPUSDT","localReceivedEpochMillis":1784431320532,"rawPayload":"{\"stream\":\"xrpusdt@depth@100ms\",\"data\":{\"e\":\"depthUpdate\",\"E\":1784431320542,\"s\":\"XRPUSDT\",\"U\":752712094,\"u\":752712095,\"b\":[],\"a\":[[\"1.09440000\",\"5230.60000000\"],[\"1.09450000\",\"2947.10000000\"]]}}"}
{"mode":"v11-raw-disruptor","partitions":4,"sequenceNumber":64,"routingSymbol":"SOLUSDT","localReceivedEpochMillis":1784431320633,"rawPayload":"{\"stream\":\"solusdt@depth@100ms\",\"data\":{\"e\":\"depthUpdate\",\"E\":1784431320642,\"s\":\"SOLUSDT\",\"U\":1609591616,\"u\":1609591616,\"b\":[],\"a\":[[\"75.91000000\",\"101.50600000\"]]}}"}
{"mode":"v11-raw-disruptor","partitions":4,"sequenceNumber":65,"routingSymbol":"ETHUSDT","localReceivedEpochMillis":1784431320633,"rawPayload":"{\"stream\":\"ethusdt@depth@100ms\",\"data\":{\"e\":\"depthUpdate\",\"E\":1784431320642,\"s\":\"ETHUSDT\",\"U\":2806197846,\"u\":2806197847,\"b\":[[\"1863.67000000\",\"0.00000000\"],[\"1863.62000000\",\"0.75970000\"]],\"a\":[]}}"}
{"mode":"v11-raw-disruptor","partitions":4,"sequenceNumber":66,"routingSymbol":"BTCUSDT","localReceivedEpochMillis":1784431320633,"rawPayload":"{\"stream\":\"btcusdt@depth@100ms\",\"data\":{\"e\":\"depthUpdate\",\"E\":1784431320642,\"s\":\"BTCUSDT\",\"U\":3244451554,\"u\":3244451556,\"b\":[[\"64630.99000000\",\"0.00000000\"]],\"a\":[[\"64650.72000000\",\"0.03869000\"],[\"64656.62000000\",\"0.00000000\"]]}}"}
{"mode":"v11-raw-disruptor","partitions":4,"sequenceNumber":67,"routingSymbol":"BNBUSDT","localReceivedEpochMillis":1784431320633,"rawPayload":"{\"stream\":\"bnbusdt@depth@100ms\",\"data\":{\"e\":\"depthUpdate\",\"E\":1784431320642,\"s\":\"BNBUSDT\",\"U\":1236336047,\"u\":1236336054,\"b\":[[\"569.23000000\",\"0.00000000\"],[\"569.08000000\",\"0.00000000\"],[\"569.02000000\",\"0.95600000\"],[\"567.60000000\",\"0.81300000\"],[\"566.70000000\",\"2.23700000\"]],\"a\":[[\"569.42000000\",\"0.92500000\"],[\"569.49000000\",\"0.00000000\"],[\"569.61000000\",\"1.59500000\"]]}}"}
{"mode":"v11-raw-disruptor","partitions":4,"sequenceNumber":68,"routingSymbol":"SOLUSDT","localReceivedEpochMillis":1784431320732,"rawPayload":"{\"stream\":\"solusdt@depth@100ms\",\"data\":{\"e\":\"depthUpdate\",\"E\":1784431320743,\"s\":\"SOLUSDT\",\"U\":1609591617,\"u\":1609591618,\"b\":[],\"a\":[[\"75.88000000\",\"0.55400000\"],[\"75.89000000\",\"61.27600000\"]]}}"}
{"mode":"v11-raw-disruptor","partitions":4,"sequenceNumber":69,"routingSymbol":"ETHUSDT","localReceivedEpochMillis":1784431320732,"rawPayload":"{\"stream\":\"ethusdt@depth@100ms\",\"data\":{\"e\":\"depthUpdate\",\"E\":1784431320743,\"s\":\"ETHUSDT\",\"U\":2806197848,\"u\":2806197851,\"b\":[[\"1863.62000000\",\"0.00000000\"],[\"1863.57000000\",\"0.76810000\"],[\"1863.40000000\",\"12.35350000\"],[\"1863.19000000\",\"1.14920000\"]],\"a\":[]}}"}
{"mode":"v11-raw-disruptor","partitions":4,"sequenceNumber":70,"routingSymbol":"BNBUSDT","localReceivedEpochMillis":1784431320732,"rawPayload":"{\"stream\":\"bnbusdt@depth@100ms\",\"data\":{\"e\":\"depthUpdate\",\"E\":1784431320743,\"s\":\"BNBUSDT\",\"U\":1236336055,\"u\":1236336059,\"b\":[[\"569.15000000\",\"0.00000000\"],[\"569.09000000\",\"1.75700000\"],[\"567.11000000\",\"0.00000000\"]],\"a\":[[\"569.45000000\",\"0.10600000\"],[\"569.52000000\",\"0.00000000\"]]}}"}
{"mode":"v11-raw-disruptor","partitions":4,"sequenceNumber":71,"routingSymbol":"BTCUSDT","localReceivedEpochMillis":1784431320732,"rawPayload":"{\"stream\":\"btcusdt@depth@100ms\",\"data\":{\"e\":\"depthUpdate\",\"E\":1784431320743,\"s\":\"BTCUSDT\",\"U\":3244451557,\"u\":3244451557,\"b\":[[\"64617.42000000\",\"0.01277000\"]],\"a\":[]}}"}
{"mode":"v11-raw-disruptor","partitions":4,"sequenceNumber":72,"routingSymbol":"BTCUSDT","localReceivedEpochMillis":1784431320832,"rawPayload":"{\"stream\":\"btcusdt@depth@100ms\",\"data\":{\"e\":\"depthUpdate\",\"E\":1784431320843,\"s\":\"BTCUSDT\",\"U\":3244451558,\"u\":3244451558,\"b\":[],\"a\":[[\"80837.82000000\",\"0.00075000\"]]}}"}
{"mode":"v11-raw-disruptor","partitions":4,"sequenceNumber":73,"routingSymbol":"BNBUSDT","localReceivedEpochMillis":1784431320933,"rawPayload":"{\"stream\":\"bnbusdt@depth@100ms\",\"data\":{\"e\":\"depthUpdate\",\"E\":1784431320943,\"s\":\"BNBUSDT\",\"U\":1236336060,\"u\":1236336062,\"b\":[[\"566.68000000\",\"2.23100000\"]],\"a\":[[\"571.66000000\",\"1.74000000\"],[\"572.09000000\",\"0.00000000\"]]}}"}
{"mode":"v11-raw-disruptor","partitions":4,"sequenceNumber":74,"routingSymbol":"ETHUSDT","localReceivedEpochMillis":1784431321033,"rawPayload":"{\"stream\":\"ethusdt@depth@100ms\",\"data\":{\"e\":\"depthUpdate\",\"E\":1784431321043,\"s\":\"ETHUSDT\",\"U\":2806197852,\"u\":2806197855,\"b\":[[\"1863.66000000\",\"1.09310000\"],[\"1863.28000000\",\"1.63970000\"]],\"a\":[[\"1866.26000000\",\"5.43010000\"],[\"1873.42000000\",\"0.00000000\"]]}}"}
{"mode":"v11-raw-disruptor","partitions":4,"sequenceNumber":75,"routingSymbol":"ETHUSDT","localReceivedEpochMillis":1784431321133,"rawPayload":"{\"stream\":\"ethusdt@depth@100ms\",\"data\":{\"e\":\"depthUpdate\",\"E\":1784431321143,\"s\":\"ETHUSDT\",\"U\":2806197856,\"u\":2806197857,\"b\":[[\"1863.62000000\",\"0.76980000\"],[\"1863.57000000\",\"0.00000000\"]],\"a\":[]}}"}
{"mode":"v11-raw-disruptor","partitions":4,"sequenceNumber":76,"routingSymbol":"BNBUSDT","localReceivedEpochMillis":1784431321133,"rawPayload":"{\"stream\":\"bnbusdt@depth@100ms\",\"data\":{\"e\":\"depthUpdate\",\"E\":1784431321143,\"s\":\"BNBUSDT\",\"U\":1236336063,\"u\":1236336064,\"b\":[[\"569.18000000\",\"0.08900000\"]],\"a\":[[\"569.56000000\",\"0.08900000\"]]}}"}
{"mode":"v11-raw-disruptor","partitions":4,"sequenceNumber":77,"routingSymbol":"XRPUSDT","localReceivedEpochMillis":1784431321133,"rawPayload":"{\"stream\":\"xrpusdt@depth@100ms\",\"data\":{\"e\":\"depthUpdate\",\"E\":1784431321143,\"s\":\"XRPUSDT\",\"U\":752712096,\"u\":752712099,\"b\":[[\"1.09390000\",\"4185.60000000\"],[\"1.09380000\",\"10979.50000000\"]],\"a\":[[\"1.09420000\",\"0.00000000\"],[\"1.09430000\",\"2514.40000000\"]]}}"}
{"mode":"v11-raw-disruptor","partitions":4,"sequenceNumber":78,"routingSymbol":"BNBUSDT","localReceivedEpochMillis":1784431321333,"rawPayload":"{\"stream\":\"bnbusdt@depth@100ms\",\"data\":{\"e\":\"depthUpdate\",\"E\":1784431321343,\"s\":\"BNBUSDT\",\"U\":1236336065,\"u\":1236336065,\"b\":[],\"a\":[[\"569.44000000\",\"1.70900000\"],[\"569.46000000\",\"1.59500000\"]]}}"}
{"mode":"v11-raw-disruptor","partitions":4,"sequenceNumber":79,"routingSymbol":"BTCUSDT","localReceivedEpochMillis":1784431321333,"rawPayload":"{\"stream\":\"btcusdt@depth@100ms\",\"data\":{\"e\":\"depthUpdate\",\"E\":1784431321343,\"s\":\"BTCUSDT\",\"U\":3244451559,\"u\":3244451559,\"b\":[[\"64538.30000000\",\"0.00000000\"]],\"a\":[]}}"}
{"mode":"v11-raw-disruptor","partitions":4,"sequenceNumber":80,"routingSymbol":"XRPUSDT","localReceivedEpochMillis":1784431321533,"rawPayload":"{\"stream\":\"xrpusdt@depth@100ms\",\"data\":{\"e\":\"depthUpdate\",\"E\":1784431321543,\"s\":\"XRPUSDT\",\"U\":752712100,\"u\":752712100,\"b\":[],\"a\":[[\"1.09430000\",\"3820.50000000\"],[\"1.09440000\",\"3924.50000000\"]]}}"}
{"mode":"v11-raw-disruptor","partitions":4,"sequenceNumber":81,"routingSymbol":"SOLUSDT","localReceivedEpochMillis":1784431321632,"rawPayload":"{\"stream\":\"solusdt@depth@100ms\",\"data\":{\"e\":\"depthUpdate\",\"E\":1784431321643,\"s\":\"SOLUSDT\",\"U\":1609591619,\"u\":1609591620,\"b\":[],\"a\":[[\"75.89000000\",\"81.40600000\"],[\"75.91000000\",\"81.37600000\"]]}}"}
{"mode":"v11-raw-disruptor","partitions":4,"sequenceNumber":82,"routingSymbol":"XRPUSDT","localReceivedEpochMillis":1784431321632,"rawPayload":"{\"stream\":\"xrpusdt@depth@100ms\",\"data\":{\"e\":\"depthUpdate\",\"E\":1784431321643,\"s\":\"XRPUSDT\",\"U\":752712101,\"u\":752712101,\"b\":[],\"a\":[[\"1.09430000\",\"2514.40000000\"],[\"1.09440000\",\"5230.60000000\"]]}}"}
{"mode":"v11-raw-disruptor","partitions":4,"sequenceNumber":83,"routingSymbol":"ETHUSDT","localReceivedEpochMillis":1784431321632,"rawPayload":"{\"stream\":\"ethusdt@depth@100ms\",\"data\":{\"e\":\"depthUpdate\",\"E\":1784431321643,\"s\":\"ETHUSDT\",\"U\":2806197858,\"u\":2806197861,\"b\":[[\"1864.18000000\",\"0.00000000\"],[\"1864.12000000\",\"1.11210000\"]],\"a\":[[\"1864.69000000\",\"1.16550000\"],[\"1864.75000000\",\"0.00000000\"]]}}"}
{"mode":"v11-raw-disruptor","partitions":4,"sequenceNumber":84,"routingSymbol":"ETHUSDT","localReceivedEpochMillis":1784431321733,"rawPayload":"{\"stream\":\"ethusdt@depth@100ms\",\"data\":{\"e\":\"depthUpdate\",\"E\":1784431321743,\"s\":\"ETHUSDT\",\"U\":2806197862,\"u\":2806197863,\"b\":[[\"1863.66000000\",\"0.00000000\"],[\"1863.45000000\",\"1.09310000\"]],\"a\":[]}}"}
{"mode":"v11-raw-disruptor","partitions":4,"sequenceNumber":85,"routingSymbol":"BNBUSDT","localReceivedEpochMillis":1784431321834,"rawPayload":"{\"stream\":\"bnbusdt@depth@100ms\",\"data\":{\"e\":\"depthUpdate\",\"E\":1784431321843,\"s\":\"BNBUSDT\",\"U\":1236336066,\"u\":1236336067,\"b\":[[\"569.20000000\",\"0.00000000\"],[\"569.15000000\",\"1.58600000\"]],\"a\":[[\"569.43000000\",\"1.70900000\"],[\"569.44000000\",\"0.00000000\"]]}}"}
{"mode":"v11-raw-disruptor","partitions":4,"sequenceNumber":86,"routingSymbol":"SOLUSDT","localReceivedEpochMillis":1784431322133,"rawPayload":"{\"stream\":\"solusdt@depth@100ms\",\"data\":{\"e\":\"depthUpdate\",\"E\":1784431322143,\"s\":\"SOLUSDT\",\"U\":1609591621,\"u\":1609591624,\"b\":[[\"75.85000000\",\"33.87000000\"],[\"75.84000000\",\"75.39900000\"]],\"a\":[[\"75.89000000\",\"66.93900000\"],[\"75.91000000\",\"95.75000000\"]]}}"}
{"mode":"v11-raw-disruptor","partitions":4,"sequenceNumber":87,"routingSymbol":"SOLUSDT","localReceivedEpochMillis":1784431322733,"rawPayload":"{\"stream\":\"solusdt@depth@100ms\",\"data\":{\"e\":\"depthUpdate\",\"E\":1784431322744,\"s\":\"SOLUSDT\",\"U\":1609591625,\"u\":1609591625,\"b\":[],\"a\":[[\"75.89000000\",\"85.98900000\"],[\"75.90000000\",\"30.19500000\"]]}}"}
{"mode":"v11-raw-disruptor","partitions":4,"sequenceNumber":88,"routingSymbol":"BNBUSDT","localReceivedEpochMillis":1784431322933,"rawPayload":"{\"stream\":\"bnbusdt@depth@100ms\",\"data\":{\"e\":\"depthUpdate\",\"E\":1784431322944,\"s\":\"BNBUSDT\",\"U\":1236336068,\"u\":1236336068,\"b\":[],\"a\":[[\"570.17000000\",\"0.00000000\"]]}}"}
{"mode":"v11-raw-disruptor","partitions":4,"sequenceNumber":89,"routingSymbol":"SOLUSDT","localReceivedEpochMillis":1784431323233,"rawPayload":"{\"stream\":\"solusdt@depth@100ms\",\"data\":{\"e\":\"depthUpdate\",\"E\":1784431323244,\"s\":\"SOLUSDT\",\"U\":1609591626,\"u\":1609591632,\"b\":[[\"75.85000000\",\"33.57500000\"],[\"75.84000000\",\"71.97200000\"],[\"75.83000000\",\"33.62300000\"]],\"a\":[[\"75.88000000\",\"3.98000000\"],[\"75.89000000\",\"82.56300000\"],[\"75.90000000\",\"43.97500000\"],[\"75.91000000\",\"117.73600000\"],[\"75.92000000\",\"3.28300000\"]]}}"}
{"mode":"v11-raw-disruptor","partitions":4,"sequenceNumber":90,"routingSymbol":"BTCUSDT","localReceivedEpochMillis":1784431323234,"rawPayload":"{\"stream\":\"btcusdt@depth@100ms\",\"data\":{\"e\":\"depthUpdate\",\"E\":1784431323244,\"s\":\"BTCUSDT\",\"U\":3244451560,\"u\":3244451567,\"b\":[[\"64585.10000000\",\"0.00000000\"],[\"64583.55000000\",\"0.05890000\"],[\"64546.30000000\",\"0.00000000\"],[\"64544.76000000\",\"0.08405000\"],[\"64507.50000000\",\"0.00000000\"],[\"64505.96000000\",\"0.18547000\"],[\"64429.91000000\",\"0.00000000\"],[\"64428.37000000\",\"0.39755000\"]],\"a\":[[\"64738.69000000\",\"0.05593000\"],[\"64740.23000000\",\"0.20595000\"],[\"64777.48000000\",\"0.08386000\"],[\"64779.03000000\",\"0.00000000\"],[\"64816.28000000\",\"0.16778000\"],[\"64817.83000000\",\"0.00000000\"],[\"64893.87000000\",\"0.41507000\"],[\"64895.42000000\",\"0.00000000\"]]}}"}
{"mode":"v11-raw-disruptor","partitions":4,"sequenceNumber":91,"routingSymbol":"BTCUSDT","localReceivedEpochMillis":1784431323334,"rawPayload":"{\"stream\":\"btcusdt@depth@100ms\",\"data\":{\"e\":\"depthUpdate\",\"E\":1784431323344,\"s\":\"BTCUSDT\",\"U\":3244451568,\"u\":3244451568,\"b\":[],\"a\":[[\"80837.82000000\",\"0.00075000\"]]}}"}
{"mode":"v11-raw-disruptor","partitions":4,"sequenceNumber":92,"routingSymbol":"BTCUSDT","localReceivedEpochMillis":1784431323433,"rawPayload":"{\"stream\":\"btcusdt@depth@100ms\",\"data\":{\"e\":\"depthUpdate\",\"E\":1784431323444,\"s\":\"BTCUSDT\",\"U\":3244451569,\"u\":3244451569,\"b\":[],\"a\":[[\"80837.82000000\",\"0.00075000\"]]}}"}
{"mode":"v11-raw-disruptor","partitions":4,"sequenceNumber":93,"routingSymbol":"ETHUSDT","localReceivedEpochMillis":1784431323533,"rawPayload":"{\"stream\":\"ethusdt@depth@100ms\",\"data\":{\"e\":\"depthUpdate\",\"E\":1784431323544,\"s\":\"ETHUSDT\",\"U\":2806197864,\"u\":2806197865,\"b\":[[\"1863.87000000\",\"1.34210000\"]],\"a\":[[\"1864.47000000\",\"0.00000000\"]]}}"}
{"mode":"v11-raw-disruptor","partitions":4,"sequenceNumber":94,"routingSymbol":"BNBUSDT","localReceivedEpochMillis":1784431323834,"rawPayload":"{\"stream\":\"bnbusdt@depth@100ms\",\"data\":{\"e\":\"depthUpdate\",\"E\":1784431323845,\"s\":\"BNBUSDT\",\"U\":1236336069,\"u\":1236336071,\"b\":[[\"569.17000000\",\"1.58600000\"],[\"569.15000000\",\"0.00000000\"],[\"568.66000000\",\"0.00000000\"],[\"568.64000000\",\"3.46000000\"]],\"a\":[[\"569.41000000\",\"1.70900000\"],[\"569.43000000\",\"0.00000000\"]]}}"}
{"mode":"v11-raw-disruptor","partitions":4,"sequenceNumber":95,"routingSymbol":"BNBUSDT","localReceivedEpochMillis":1784431323934,"rawPayload":"{\"stream\":\"bnbusdt@depth@100ms\",\"data\":{\"e\":\"depthUpdate\",\"E\":1784431323945,\"s\":\"BNBUSDT\",\"U\":1236336072,\"u\":1236336076,\"b\":[[\"568.31000000\",\"0.00000000\"],[\"568.30000000\",\"4.85600000\"],[\"567.97000000\",\"0.00000000\"],[\"567.95000000\",\"8.44100000\"],[\"567.63000000\",\"0.00000000\"],[\"567.61000000\",\"19.23400000\"]],\"a\":[[\"570.01000000\",\"3.50000000\"],[\"570.03000000\",\"0.00000000\"],[\"570.36000000\",\"4.82900000\"],[\"570.37000000\",\"0.00000000\"]]}}"}
{"mode":"v11-raw-disruptor","partitions":4,"sequenceNumber":96,"routingSymbol":"BNBUSDT","localReceivedEpochMillis":1784431324134,"rawPayload":"{\"stream\":\"bnbusdt@depth@100ms\",\"data\":{\"e\":\"depthUpdate\",\"E\":1784431324145,\"s\":\"BNBUSDT\",\"U\":1236336077,\"u\":1236336077,\"b\":[[\"567.77000000\",\"0.00400000\"],[\"567.73000000\",\"0.00000000\"]],\"a\":[]}}"}
{"mode":"v11-raw-disruptor","partitions":4,"sequenceNumber":97,"routingSymbol":"BTCUSDT","localReceivedEpochMillis":1784431324134,"rawPayload":"{\"stream\":\"btcusdt@depth@100ms\",\"data\":{\"e\":\"depthUpdate\",\"E\":1784431324145,\"s\":\"BTCUSDT\",\"U\":3244451570,\"u\":3244451573,\"b\":[[\"64644.11000000\",\"0.02577000\"]],\"a\":[[\"64644.37000000\",\"0.00000000\"],[\"64644.53000000\",\"0.00402000\"],[\"64654.88000000\",\"0.04268000\"],[\"64656.24000000\",\"0.00000000\"],[\"64667.55000000\",\"0.02961000\"]]}}"}
{"mode":"v11-raw-disruptor","partitions":4,"sequenceNumber":98,"routingSymbol":"BTCUSDT","localReceivedEpochMillis":1784431324234,"rawPayload":"{\"stream\":\"btcusdt@depth@100ms\",\"data\":{\"e\":\"depthUpdate\",\"E\":1784431324245,\"s\":\"BTCUSDT\",\"U\":3244451574,\"u\":3244451575,\"b\":[],\"a\":[[\"64644.53000000\",\"0.00000000\"],[\"64644.57000000\",\"0.00402000\"]]}}"}
{"mode":"v11-raw-disruptor","partitions":4,"sequenceNumber":99,"routingSymbol":"SOLUSDT","localReceivedEpochMillis":1784431324434,"rawPayload":"{\"stream\":\"solusdt@depth@100ms\",\"data\":{\"e\":\"depthUpdate\",\"E\":1784431324445,\"s\":\"SOLUSDT\",\"U\":1609591633,\"u\":1609591636,\"b\":[[\"75.85000000\",\"19.84100000\"],[\"75.84000000\",\"85.67500000\"]],\"a\":[[\"75.89000000\",\"96.39200000\"],[\"75.90000000\",\"30.19500000\"]]}}"}
{"mode":"v11-raw-disruptor","partitions":4,"sequenceNumber":100,"routingSymbol":"ETHUSDT","localReceivedEpochMillis":1784431324435,"rawPayload":"{\"stream\":\"ethusdt@depth@100ms\",\"data\":{\"e\":\"depthUpdate\",\"E\":1784431324445,\"s\":\"ETHUSDT\",\"U\":2806197866,\"u\":2806197872,\"b\":[[\"1864.35000000\",\"0.00000000\"],[\"1863.98000000\",\"0.02970000\"],[\"1863.94000000\",\"0.00000000\"]],\"a\":[[\"1864.54000000\",\"0.02960000\"],[\"1864.91000000\",\"12.99860000\"],[\"1865.05000000\",\"0.00000000\"],[\"1865.54000000\",\"0.00000000\"]]}}"}
{"mode":"v11-raw-disruptor","partitions":4,"sequenceNumber":101,"routingSymbol":"XRPUSDT","localReceivedEpochMillis":1784431324435,"rawPayload":"{\"stream\":\"xrpusdt@depth@100ms\",\"data\":{\"e\":\"depthUpdate\",\"E\":1784431324445,\"s\":\"XRPUSDT\",\"U\":752712102,\"u\":752712103,\"b\":[[\"1.09360000\",\"2440.40000000\"],[\"1.09340000\",\"2074.70000000\"]],\"a\":[]}}"}
{"mode":"v11-raw-disruptor","partitions":4,"sequenceNumber":102,"routingSymbol":"ETHUSDT","localReceivedEpochMillis":1784431324535,"rawPayload":"{\"stream\":\"ethusdt@depth@100ms\",\"data\":{\"e\":\"depthUpdate\",\"E\":1784431324545,\"s\":\"ETHUSDT\",\"U\":2806197873,\"u\":2806197875,\"b\":[[\"1863.62000000\",\"0.00000000\"],[\"1863.57000000\",\"0.71810000\"],[\"1863.46000000\",\"0.11520000\"]],\"a\":[]}}"}
{"mode":"v11-raw-disruptor","partitions":4,"sequenceNumber":103,"routingSymbol":"SOLUSDT","localReceivedEpochMillis":1784431324634,"rawPayload":"{\"stream\":\"solusdt@depth@100ms\",\"data\":{\"e\":\"depthUpdate\",\"E\":1784431324645,\"s\":\"SOLUSDT\",\"U\":1609591637,\"u\":1609591638,\"b\":[],\"a\":[[\"75.89000000\",\"76.26200000\"],[\"75.90000000\",\"50.32500000\"]]}}"}
{"mode":"v11-raw-disruptor","partitions":4,"sequenceNumber":104,"routingSymbol":"BTCUSDT","localReceivedEpochMillis":1784431324635,"rawPayload":"{\"stream\":\"btcusdt@depth@100ms\",\"data\":{\"e\":\"depthUpdate\",\"E\":1784431324645,\"s\":\"BTCUSDT\",\"U\":3244451576,\"u\":3244451577,\"b\":[],\"a\":[[\"64659.06000000\",\"0.07161000\"],[\"64689.94000000\",\"0.00000000\"]]}}"}
{"mode":"v11-raw-disruptor","partitions":4,"sequenceNumber":105,"routingSymbol":"SOLUSDT","localReceivedEpochMillis":1784431324735,"rawPayload":"{\"stream\":\"solusdt@depth@100ms\",\"data\":{\"e\":\"depthUpdate\",\"E\":1784431324745,\"s\":\"SOLUSDT\",\"U\":1609591639,\"u\":1609591645,\"b\":[],\"a\":[[\"75.89000000\",\"46.06700000\"],[\"75.90000000\",\"0.00000000\"],[\"75.91000000\",\"87.54100000\"],[\"75.96000000\",\"85.38400000\"],[\"75.97000000\",\"99.38200000\"],[\"75.98000000\",\"0.00000000\"],[\"76.05000000\",\"325.97900000\"],[\"76.06000000\",\"273.86200000\"]]}}"}
{"mode":"v11-raw-disruptor","partitions":4,"sequenceNumber":106,"routingSymbol":"SOLUSDT","localReceivedEpochMillis":1784431324935,"rawPayload":"{\"stream\":\"solusdt@depth@100ms\",\"data\":{\"e\":\"depthUpdate\",\"E\":1784431324945,\"s\":\"SOLUSDT\",\"U\":1609591646,\"u\":1609591646,\"b\":[],\"a\":[[\"75.89000000\",\"27.01700000\"],[\"75.90000000\",\"19.05000000\"]]}}"}
{"mode":"v11-raw-disruptor","partitions":4,"sequenceNumber":107,"routingSymbol":"SOLUSDT","localReceivedEpochMillis":1784431325035,"rawPayload":"{\"stream\":\"solusdt@depth@100ms\",\"data\":{\"e\":\"depthUpdate\",\"E\":1784431325045,\"s\":\"SOLUSDT\",\"U\":1609591647,\"u\":1609591655,\"b\":[[\"75.85000000\",\"34.59600000\"],[\"75.84000000\",\"71.97200000\"]],\"a\":[[\"75.89000000\",\"13.18800000\"],[\"75.90000000\",\"33.48600000\"],[\"75.95000000\",\"50.32500000\"],[\"75.97000000\",\"129.57700000\"],[\"75.98000000\",\"30.19500000\"],[\"76.27000000\",\"54.78900000\"]]}}"}
{"mode":"v11-raw-disruptor","partitions":4,"sequenceNumber":108,"routingSymbol":"BNBUSDT","localReceivedEpochMillis":1784431325035,"rawPayload":"{\"stream\":\"bnbusdt@depth@100ms\",\"data\":{\"e\":\"depthUpdate\",\"E\":1784431325045,\"s\":\"BNBUSDT\",\"U\":1236336078,\"u\":1236336085,\"b\":[[\"569.07000000\",\"0.00000000\"],[\"569.03000000\",\"0.97600000\"],[\"569.02000000\",\"0.00000000\"]],\"a\":[[\"569.42000000\",\"0.00000000\"],[\"569.43000000\",\"0.96800000\"],[\"569.48000000\",\"0.00000000\"]]}}"}
{"mode":"v11-raw-disruptor","partitions":4,"sequenceNumber":109,"routingSymbol":"SOLUSDT","localReceivedEpochMillis":1784431325135,"rawPayload":"{\"stream\":\"solusdt@depth@100ms\",\"data\":{\"e\":\"depthUpdate\",\"E\":1784431325145,\"s\":\"SOLUSDT\",\"U\":1609591656,\"u\":1609591671,\"b\":[[\"75.85000000\",\"33.88500000\"],[\"75.84000000\",\"75.39900000\"],[\"75.83000000\",\"30.19500000\"]],\"a\":[[\"75.86000000\",\"0.00000000\"],[\"75.87000000\",\"39.56700000\"],[\"75.89000000\",\"13.18800000\"],[\"75.90000000\",\"84.11400000\"],[\"75.91000000\",\"0.00000000\"],[\"75.92000000\",\"39.64000000\"],[\"75.94000000\",\"43.38400000\"],[\"75.98000000\",\"0.00000000\"]]}}"}
{"mode":"v11-raw-disruptor","partitions":4,"sequenceNumber":110,"routingSymbol":"XRPUSDT","localReceivedEpochMillis":1784431325135,"rawPayload":"{\"stream\":\"xrpusdt@depth@100ms\",\"data\":{\"e\":\"depthUpdate\",\"E\":1784431325145,\"s\":\"XRPUSDT\",\"U\":752712104,\"u\":752712131,\"b\":[[\"1.09390000\",\"1535.50000000\"],[\"1.09380000\",\"2287.10000000\"],[\"1.09370000\",\"0.00000000\"],[\"1.09360000\",\"2312.40000000\"],[\"1.09340000\",\"2440.50000000\"],[\"1.09330000\",\"2074.70000000\"],[\"1.09320000\",\"2524.50000000\"],[\"1.09270000\",\"97.60000000\"],[\"1.09250000\",\"6910.20000000\"]],\"a\":[[\"1.09420000\",\"2257.60000000\"],[\"1.09430000\",\"283.10000000\"],[\"1.09440000\",\"3996.40000000\"],[\"1.09450000\",\"2074.70000000\"],[\"1.09460000\",\"2224.70000000\"],[\"1.09470000\",\"2521.30000000\"],[\"1.09480000\",\"0.00000000\"],[\"1.09520000\",\"6915.90000000\"],[\"1.09950000\",\"0.00000000\"]]}}"}
{"mode":"v11-raw-disruptor","partitions":4,"sequenceNumber":111,"routingSymbol":"SOLUSDT","localReceivedEpochMillis":1784431325234,"rawPayload":"{\"stream\":\"solusdt@depth@100ms\",\"data\":{\"e\":\"depthUpdate\",\"E\":1784431325245,\"s\":\"SOLUSDT\",\"U\":1609591672,\"u\":1609591686,\"b\":[[\"75.85000000\",\"34.08200000\"],[\"75.84000000\",\"75.39900000\"]],\"a\":[[\"75.86000000\",\"6.59400000\"],[\"75.87000000\",\"32.97300000\"],[\"75.88000000\",\"0.55400000\"],[\"75.89000000\",\"30.72900000\"],[\"75.90000000\",\"70.23100000\"],[\"75.93000000\",\"30.19500000\"],[\"75.97000000\",\"99.38200000\"]]}}"}
{"mode":"v11-raw-disruptor","partitions":4,"sequenceNumber":112,"routingSymbol":"XRPUSDT","localReceivedEpochMillis":1784431325235,"rawPayload":"{\"stream\":\"xrpusdt@depth@100ms\",\"data\":{\"e\":\"depthUpdate\",\"E\":1784431325246,\"s\":\"XRPUSDT\",\"U\":752712132,\"u\":752712153,\"b\":[[\"1.09390000\",\"225.00000000\"],[\"1.09380000\",\"3597.60000000\"],[\"1.09360000\",\"3252.00000000\"],[\"1.09350000\",\"88.10000000\"],[\"1.09340000\",\"2074.70000000\"],[\"1.09320000\",\"2764.20000000\"],[\"1.09240000\",\"0.00000000\"],[\"1.09230000\",\"0.00000000\"],[\"1.08950000\",\"0.00000000\"],[\"1.08930000\",\"7349.60000000\"]],\"a\":[[\"1.09420000\",\"4543.90000000\"],[\"1.09430000\",\"2474.50000000\"],[\"1.09440000\",\"1750.60000000\"],[\"1.09500000\",\"0.00000000\"],[\"1.09530000\",\"4568.30000000\"],[\"1.09560000\",\"0.00000000\"],[\"1.09580000\",\"12805.80000000\"],[\"1.09790000\",\"9114.60000000\"],[\"1.10460000\",\"896.10000000\"],[\"1.10800000\",\"0.00000000\"]]}}"}
{"mode":"v11-raw-disruptor","partitions":4,"sequenceNumber":113,"routingSymbol":"XRPUSDT","localReceivedEpochMillis":1784431325335,"rawPayload":"{\"stream\":\"xrpusdt@depth@100ms\",\"data\":{\"e\":\"depthUpdate\",\"E\":1784431325346,\"s\":\"XRPUSDT\",\"U\":752712154,\"u\":752712175,\"b\":[[\"1.09400000\",\"0.00000000\"],[\"1.09390000\",\"0.00000000\"],[\"1.09380000\",\"3597.60000000\"],[\"1.09370000\",\"225.00000000\"],[\"1.09360000\",\"6742.70000000\"],[\"1.09350000\",\"278.00000000\"],[\"1.09270000\",\"0.00000000\"],[\"1.09260000\",\"232.20000000\"],[\"1.09220000\",\"12703.90000000\"]],\"a\":[[\"1.09410000\",\"2286.50000000\"],[\"1.09420000\",\"2074.70000000\"],[\"1.09430000\",\"2658.20000000\"],[\"1.09450000\",\"2568.70000000\"],[\"1.09460000\",\"2074.70000000\"],[\"1.09570000\",\"12790.80000000\"],[\"1.09700000\",\"16038.30000000\"],[\"1.09770000\",\"0.00000000\"],[\"1.09790000\",\"0.00000000\"]]}}"}
{"mode":"v11-raw-disruptor","partitions":4,"sequenceNumber":114,"routingSymbol":"SOLUSDT","localReceivedEpochMillis":1784431325435,"rawPayload":"{\"stream\":\"solusdt@depth@100ms\",\"data\":{\"e\":\"depthUpdate\",\"E\":1784431325446,\"s\":\"SOLUSDT\",\"U\":1609591687,\"u\":1609591694,\"b\":[[\"75.85000000\",\"34.43100000\"]],\"a\":[[\"75.89000000\",\"16.61400000\"],[\"75.90000000\",\"84.64700000\"],[\"75.92000000\",\"59.77000000\"],[\"75.95000000\",\"30.19500000\"],[\"75.98000000\",\"54.78900000\"],[\"76.27000000\",\"0.00000000\"]]}}"}
{"mode":"v11-raw-disruptor","partitions":4,"sequenceNumber":115,"routingSymbol":"XRPUSDT","localReceivedEpochMillis":1784431325436,"rawPayload":"{\"stream\":\"xrpusdt@depth@100ms\",\"data\":{\"e\":\"depthUpdate\",\"E\":1784431325446,\"s\":\"XRPUSDT\",\"U\":752712176,\"u\":752712221,\"b\":[[\"1.09380000\",\"45.30000000\"],[\"1.09370000\",\"1535.50000000\"],[\"1.09360000\",\"0.00000000\"],[\"1.09350000\",\"189.90000000\"],[\"1.09340000\",\"3280.30000000\"],[\"1.09330000\",\"2132.10000000\"],[\"1.09320000\",\"0.00000000\"],[\"1.09310000\",\"2074.70000000\"],[\"1.09300000\",\"2639.50000000\"],[\"1.09260000\",\"0.00000000\"],[\"1.09250000\",\"0.00000000\"],[\"1.09230000\",\"6911.30000000\"],[\"1.09210000\",\"16005.40000000\"],[\"1.09160000\",\"22950.30000000\"],[\"1.09090000\",\"3841.90000000\"],[\"1.08930000\",\"6915.90000000\"]],\"a\":[[\"1.09400000\",\"3189.20000000\"],[\"1.09410000\",\"237.60000000\"],[\"1.09420000\",\"2074.70000000\"],[\"1.09430000\",\"1456.10000000\"],[\"1.09450000\",\"5090.50000000\"],[\"1.09460000\",\"2074.70000000\"],[\"1.09470000\",\"0.00000000\"],[\"1.09520000\",\"13809.80000000\"],[\"1.09540000\",\"0.00000000\"],[\"1.09710000\",\"14898.60000000\"]]}}"}
{"mode":"v11-raw-disruptor","partitions":4,"sequenceNumber":116,"routingSymbol":"SOLUSDT","localReceivedEpochMillis":1784431325534,"rawPayload":"{\"stream\":\"solusdt@depth@100ms\",\"data\":{\"e\":\"depthUpdate\",\"E\":1784431325546,\"s\":\"SOLUSDT\",\"U\":1609591695,\"u\":1609591726,\"b\":[[\"75.85000000\",\"19.84100000\"],[\"75.84000000\",\"17.48100000\"],[\"75.83000000\",\"69.77800000\"],[\"75.79000000\",\"0.00000000\"],[\"75.76000000\",\"165.68600000\"],[\"75.75000000\",\"9.73200000\"],[\"75.74000000\",\"0.00000000\"],[\"75.70000000\",\"0.00000000\"],[\"75.66000000\",\"388.98600000\"]],\"a\":[[\"75.86000000\",\"39.57100000\"],[\"75.87000000\",\"0.00000000\"],[\"75.88000000\",\"27.97300000\"],[\"75.89000000\",\"3.42600000\"],[\"75.90000000\",\"70.23100000\"],[\"75.91000000\",\"60.39000000\"],[\"75.94000000\",\"79.08000000\"],[\"75.95000000\",\"0.00000000\"],[\"75.96000000\",\"19.51000000\"],[\"75.98000000\",\"327.25600000\"],[\"76.13000000\",\"54.78900000\"]]}}"}
{"mode":"v11-raw-disruptor","partitions":4,"sequenceNumber":117,"routingSymbol":"XRPUSDT","localReceivedEpochMillis":1784431325534,"rawPayload":"{\"stream\":\"xrpusdt@depth@100ms\",\"data\":{\"e\":\"depthUpdate\",\"E\":1784431325546,\"s\":\"XRPUSDT\",\"U\":752712222,\"u\":752712272,\"b\":[[\"1.09380000\",\"0.00000000\"],[\"1.09370000\",\"0.00000000\"],[\"1.09360000\",\"0.00000000\"],[\"1.09350000\",\"1310.50000000\"],[\"1.09340000\",\"0.00000000\"],[\"1.09330000\",\"6904.40000000\"],[\"1.09300000\",\"0.00000000\"],[\"1.09290000\",\"4599.70000000\"],[\"1.09280000\",\"0.00000000\"],[\"1.09260000\",\"1409.20000000\"],[\"1.09230000\",\"11491.50000000\"],[\"1.09220000\",\"0.00000000\"],[\"1.09210000\",\"0.00000000\"],[\"1.09190000\",\"18624.00000000\"],[\"1.09160000\",\"23034.70000000\"],[\"1.09130000\",\"29027.00000000\"],[\"1.08990000\",\"24601.60000000\"],[\"1.08910000\",\"9624.00000000\"]],\"a\":[[\"1.09390000\",\"3240.10000000\"],[\"1.09400000\",\"387.60000000\"],[\"1.09410000\",\"47.70000000\"],[\"1.09430000\",\"1306.10000000\"],[\"1.09440000\",\"4272.60000000\"],[\"1.09450000\",\"2568.70000000\"],[\"1.09490000\",\"4569.70000000\"],[\"1.09530000\",\"0.00000000\"],[\"1.09650000\",\"16433.10000000\"]]}}"}
{"mode":"v11-raw-disruptor","partitions":4,"sequenceNumber":118,"routingSymbol":"SOLUSDT","localReceivedEpochMillis":1784431325635,"rawPayload":"{\"stream\":\"solusdt@depth@100ms\",\"data\":{\"e\":\"depthUpdate\",\"E\":1784431325646,\"s\":\"SOLUSDT\",\"U\":1609591727,\"u\":1609591732,\"b\":[[\"75.85000000\",\"19.28600000\"],[\"75.81000000\",\"71.09900000\"],[\"75.52000000\",\"335.42200000\"]],\"a\":[[\"75.88000000\",\"27.41900000\"],[\"75.90000000\",\"90.36100000\"],[\"75.92000000\",\"39.64000000\"]]}}"}
{"mode":"v11-raw-disruptor","partitions":4,"sequenceNumber":119,"routingSymbol":"ETHUSDT","localReceivedEpochMillis":1784431325635,"rawPayload":"{\"stream\":\"ethusdt@depth@100ms\",\"data\":{\"e\":\"depthUpdate\",\"E\":1784431325646,\"s\":\"ETHUSDT\",\"U\":2806197876,\"u\":2806197883,\"b\":[[\"1864.01000000\",\"1.34200000\"],[\"1863.87000000\",\"0.00000000\"],[\"1863.76000000\",\"0.77150000\"],[\"1863.57000000\",\"0.00000000\"],[\"1863.41000000\",\"1.15720000\"],[\"1863.19000000\",\"0.00000000\"]],\"a\":[[\"1864.44000000\",\"0.00000000\"],[\"1864.58000000\",\"1.34160000\"]]}}"}
{"mode":"v11-raw-disruptor","partitions":4,"sequenceNumber":120,"routingSymbol":"XRPUSDT","localReceivedEpochMillis":1784431325635,"rawPayload":"{\"stream\":\"xrpusdt@depth@100ms\",\"data\":{\"e\":\"depthUpdate\",\"E\":1784431325646,\"s\":\"XRPUSDT\",\"U\":752712273,\"u\":752712285,\"b\":[[\"1.09350000\",\"1355.80000000\"],[\"1.09330000\",\"3626.10000000\"],[\"1.09320000\",\"3492.00000000\"],[\"1.09300000\",\"190.00000000\"],[\"1.09290000\",\"4599.70000000\"],[\"1.09280000\",\"2094.00000000\"],[\"1.09190000\",\"2591.90000000\"],[\"1.08890000\",\"897.50000000\"]],\"a\":[[\"1.09370000\",\"45.60000000\"]]}}"}
{"mode":"v11-raw-disruptor","partitions":4,"sequenceNumber":121,"routingSymbol":"ETHUSDT","localReceivedEpochMillis":1784431325735,"rawPayload":"{\"stream\":\"ethusdt@depth@100ms\",\"data\":{\"e\":\"depthUpdate\",\"E\":1784431325746,\"s\":\"ETHUSDT\",\"U\":2806197884,\"u\":2806197885,\"b\":[[\"1863.82000000\",\"0.77380000\"],[\"1863.76000000\",\"0.00000000\"]],\"a\":[]}}"}
{"mode":"v11-raw-disruptor","partitions":4,"sequenceNumber":122,"routingSymbol":"SOLUSDT","localReceivedEpochMillis":1784431325836,"rawPayload":"{\"stream\":\"solusdt@depth@100ms\",\"data\":{\"e\":\"depthUpdate\",\"E\":1784431325846,\"s\":\"SOLUSDT\",\"U\":1609591733,\"u\":1609591736,\"b\":[[\"75.84000000\",\"18.03500000\"],[\"75.81000000\",\"101.29400000\"]],\"a\":[[\"75.87000000\",\"0.55500000\"],[\"75.93000000\",\"0.00000000\"]]}}"}
{"mode":"v11-raw-disruptor","partitions":4,"sequenceNumber":123,"routingSymbol":"XRPUSDT","localReceivedEpochMillis":1784431325836,"rawPayload":"{\"stream\":\"xrpusdt@depth@100ms\",\"data\":{\"e\":\"depthUpdate\",\"E\":1784431325846,\"s\":\"XRPUSDT\",\"U\":752712286,\"u\":752712289,\"b\":[[\"1.09350000\",\"1310.50000000\"],[\"1.08950000\",\"15835.50000000\"]],\"a\":[[\"1.09530000\",\"12616.20000000\"],[\"1.09760000\",\"0.00000000\"]]}}"}
{"mode":"v11-raw-disruptor","partitions":4,"sequenceNumber":124,"routingSymbol":"SOLUSDT","localReceivedEpochMillis":1784431325935,"rawPayload":"{\"stream\":\"solusdt@depth@100ms\",\"data\":{\"e\":\"depthUpdate\",\"E\":1784431325946,\"s\":\"SOLUSDT\",\"U\":1609591737,\"u\":1609591737,\"b\":[],\"a\":[[\"75.89000000\",\"33.62100000\"]]}}"}
{"mode":"v11-raw-disruptor","partitions":4,"sequenceNumber":125,"routingSymbol":"ETHUSDT","localReceivedEpochMillis":1784431325936,"rawPayload":"{\"stream\":\"ethusdt@depth@100ms\",\"data\":{\"e\":\"depthUpdate\",\"E\":1784431325946,\"s\":\"ETHUSDT\",\"U\":2806197886,\"u\":2806197887,\"b\":[[\"1863.82000000\",\"0.00000000\"],[\"1863.75000000\",\"0.78500000\"]],\"a\":[]}}"}
{"mode":"v11-raw-disruptor","partitions":4,"sequenceNumber":126,"routingSymbol":"XRPUSDT","localReceivedEpochMillis":1784431325936,"rawPayload":"{\"stream\":\"xrpusdt@depth@100ms\",\"data\":{\"e\":\"depthUpdate\",\"E\":1784431325946,\"s\":\"XRPUSDT\",\"U\":752712290,\"u\":752712292,\"b\":[[\"1.08930000\",\"22728.50000000\"]],\"a\":[[\"1.09380000\",\"2287.20000000\"],[\"1.09390000\",\"953.00000000\"]]}}"}
{"mode":"v11-raw-disruptor","partitions":4,"sequenceNumber":127,"routingSymbol":"SOLUSDT","localReceivedEpochMillis":1784431326036,"rawPayload":"{\"stream\":\"solusdt@depth@100ms\",\"data\":{\"e\":\"depthUpdate\",\"E\":1784431326046,\"s\":\"SOLUSDT\",\"U\":1609591738,\"u\":1609591787,\"b\":[[\"75.85000000\",\"0.00000000\"],[\"75.84000000\",\"0.14300000\"],[\"75.83000000\",\"22.71400000\"],[\"75.82000000\",\"83.54100000\"],[\"75.81000000\",\"32.42500000\"],[\"75.80000000\",\"36.40800000\"],[\"75.79000000\",\"11.26700000\"],[\"75.78000000\",\"119.93400000\"],[\"75.77000000\",\"19.58700000\"],[\"75.76000000\",\"66.03900000\"],[\"75.75000000\",\"109.39100000\"],[\"75.73000000\",\"57.12000000\"],[\"75.72000000\",\"275.16300000\"],[\"75.52000000\",\"0.00000000\"]],\"a\":[[\"75.85000000\",\"39.57800000\"],[\"75.86000000\",\"0.00000000\"],[\"75.87000000\",\"77.25900000\"],[\"75.88000000\",\"33.62100000\"],[\"75.89000000\",\"49.24500000\"],[\"75.90000000\",\"51.18100000\"],[\"75.91000000\",\"36.36300000\"],[\"75.92000000\",\"3.28300000\"],[\"75.95000000\",\"99.40800000\"],[\"75.97000000\",\"271.66600000\"],[\"76.04000000\",\"325.06000000\"],[\"76.08000000\",\"272.38000000\"],[\"76.12000000\",\"0.00000000\"]]}}"}
{"mode":"v11-raw-disruptor","partitions":4,"sequenceNumber":128,"routingSymbol":"BTCUSDT","localReceivedEpochMillis":1784431326036,"rawPayload":"{\"stream\":\"btcusdt@depth@100ms\",\"data\":{\"e\":\"depthUpdate\",\"E\":1784431326046,\"s\":\"BTCUSDT\",\"U\":3244451578,\"u\":3244451578,\"b\":[],\"a\":[[\"80837.82000000\",\"0.00060000\"]]}}"}
{"mode":"v11-raw-disruptor","partitions":4,"sequenceNumber":129,"routingSymbol":"XRPUSDT","localReceivedEpochMillis":1784431326037,"rawPayload":"{\"stream\":\"xrpusdt@depth@100ms\",\"data\":{\"e\":\"depthUpdate\",\"E\":1784431326046,\"s\":\"XRPUSDT\",\"U\":752712293,\"u\":752712314,\"b\":[[\"1.09350000\",\"0.00000000\"],[\"1.09340000\",\"45.20000000\"],[\"1.09330000\",\"3752.60000000\"],[\"1.09320000\",\"4738.80000000\"],[\"1.09290000\",\"2074.70000000\"],[\"1.09280000\",\"4619.40000000\"],[\"1.09260000\",\"1355.30000000\"],[\"1.09240000\",\"39.60000000\"],[\"1.09230000\",\"4580.20000000\"],[\"1.09210000\",\"6912.70000000\"],[\"1.08890000\",\"521.60000000\"]],\"a\":[[\"1.09370000\",\"2287.30000000\"],[\"1.09380000\",\"966.70000000\"],[\"1.09390000\",\"237.60000000\"],[\"1.09400000\",\"169.70000000\"],[\"1.09410000\",\"0.00000000\"],[\"1.09420000\",\"3380.80000000\"],[\"1.09430000\",\"2522.10000000\"],[\"1.09440000\",\"1750.60000000\"],[\"1.09500000\",\"6895.20000000\"],[\"1.09520000\",\"6915.90000000\"]]}}"}
{"mode":"v11-raw-disruptor","partitions":4,"sequenceNumber":130,"routingSymbol":"SOLUSDT","localReceivedEpochMillis":1784431326136,"rawPayload":"{\"stream\":\"solusdt@depth@100ms\",\"data\":{\"e\":\"depthUpdate\",\"E\":1784431326146,\"s\":\"SOLUSDT\",\"U\":1609591788,\"u\":1609591789,\"b\":[[\"75.83000000\",\"23.27000000\"]],\"a\":[[\"75.86000000\",\"0.55600000\"]]}}"}
{"mode":"v11-raw-disruptor","partitions":4,"sequenceNumber":131,"routingSymbol":"ETHUSDT","localReceivedEpochMillis":1784431326136,"rawPayload":"{\"stream\":\"ethusdt@depth@100ms\",\"data\":{\"e\":\"depthUpdate\",\"E\":1784431326146,\"s\":\"ETHUSDT\",\"U\":2806197888,\"u\":2806197891,\"b\":[[\"1863.75000000\",\"0.00000000\"],[\"1863.70000000\",\"2.27590000\"]],\"a\":[[\"1864.47000000\",\"1.34170000\"],[\"1864.58000000\",\"0.00000000\"]]}}"}
{"mode":"v11-raw-disruptor","partitions":4,"sequenceNumber":132,"routingSymbol":"XRPUSDT","localReceivedEpochMillis":1784431326136,"rawPayload":"{\"stream\":\"xrpusdt@depth@100ms\",\"data\":{\"e\":\"depthUpdate\",\"E\":1784431326146,\"s\":\"XRPUSDT\",\"U\":752712315,\"u\":752712315,\"b\":[[\"1.08920000\",\"15873.50000000\"]],\"a\":[]}}"}
{"mode":"v11-raw-disruptor","partitions":4,"sequenceNumber":133,"routingSymbol":"SOLUSDT","localReceivedEpochMillis":1784431326236,"rawPayload":"{\"stream\":\"solusdt@depth@100ms\",\"data\":{\"e\":\"depthUpdate\",\"E\":1784431326246,\"s\":\"SOLUSDT\",\"U\":1609591790,\"u\":1609591796,\"b\":[[\"75.83000000\",\"43.04600000\"],[\"75.82000000\",\"63.18800000\"],[\"75.53000000\",\"342.85200000\"]],\"a\":[[\"75.87000000\",\"63.51600000\"],[\"75.88000000\",\"48.04100000\"]]}}"}
{"mode":"v11-raw-disruptor","partitions":4,"sequenceNumber":134,"routingSymbol":"XRPUSDT","localReceivedEpochMillis":1784431326236,"rawPayload":"{\"stream\":\"xrpusdt@depth@100ms\",\"data\":{\"e\":\"depthUpdate\",\"E\":1784431326246,\"s\":\"XRPUSDT\",\"U\":752712316,\"u\":752712322,\"b\":[[\"1.09330000\",\"2442.10000000\"],[\"1.09320000\",\"6049.30000000\"],[\"1.09260000\",\"0.00000000\"],[\"1.09230000\",\"5935.50000000\"],[\"1.09190000\",\"0.00000000\"],[\"1.09170000\",\"2591.90000000\"],[\"1.09130000\",\"24953.60000000\"],[\"1.09100000\",\"20060.20000000\"],[\"1.08990000\",\"15829.60000000\"],[\"1.08970000\",\"24856.10000000\"]],\"a\":[[\"1.09400000\",\"150.00000000\"],[\"1.09410000\",\"20.00000000\"]]}}"}
{"mode":"v11-raw-disruptor","partitions":4,"sequenceNumber":135,"routingSymbol":"ETHUSDT","localReceivedEpochMillis":1784431326336,"rawPayload":"{\"stream\":\"ethusdt@depth@100ms\",\"data\":{\"e\":\"depthUpdate\",\"E\":1784431326346,\"s\":\"ETHUSDT\",\"U\":2806197892,\"u\":2806197897,\"b\":[[\"1864.01000000\",\"0.00000000\"],[\"1863.86000000\",\"1.34220000\"],[\"1863.70000000\",\"1.48090000\"],[\"1863.55000000\",\"0.80360000\"],[\"1863.41000000\",\"0.00000000\"],[\"1863.20000000\",\"1.20540000\"]],\"a\":[]}}"}
{"mode":"v11-raw-disruptor","partitions":4,"sequenceNumber":136,"routingSymbol":"XRPUSDT","localReceivedEpochMillis":1784431326336,"rawPayload":"{\"stream\":\"xrpusdt@depth@100ms\",\"data\":{\"e\":\"depthUpdate\",\"E\":1784431326346,\"s\":\"XRPUSDT\",\"U\":752712323,\"u\":752712323,\"b\":[[\"1.08900000\",\"15828.70000000\"]],\"a\":[]}}"}
{"mode":"v11-raw-disruptor","partitions":4,"sequenceNumber":137,"routingSymbol":"SOLUSDT","localReceivedEpochMillis":1784431326535,"rawPayload":"{\"stream\":\"solusdt@depth@100ms\",\"data\":{\"e\":\"depthUpdate\",\"E\":1784431326546,\"s\":\"SOLUSDT\",\"U\":1609591797,\"u\":1609591804,\"b\":[[\"75.83000000\",\"42.24700000\"],[\"75.82000000\",\"63.18800000\"]],\"a\":[[\"75.87000000\",\"63.51600000\"],[\"75.88000000\",\"47.48900000\"]]}}"}
{"mode":"v11-raw-disruptor","partitions":4,"sequenceNumber":138,"routingSymbol":"SOLUSDT","localReceivedEpochMillis":1784431326636,"rawPayload":"{\"stream\":\"solusdt@depth@100ms\",\"data\":{\"e\":\"depthUpdate\",\"E\":1784431326646,\"s\":\"SOLUSDT\",\"U\":1609591805,\"u\":1609591832,\"b\":[[\"75.83000000\",\"19.28600000\"],[\"75.82000000\",\"17.74000000\"],[\"75.81000000\",\"70.92900000\"],[\"75.80000000\",\"0.00000000\"],[\"75.79000000\",\"36.41200000\"],[\"75.78000000\",\"30.29700000\"],[\"75.75000000\",\"9.73200000\"],[\"75.74000000\",\"99.67300000\"],[\"75.72000000\",\"0.00000000\"]],\"a\":[[\"75.86000000\",\"11.01100000\"],[\"75.87000000\",\"68.18600000\"],[\"75.88000000\",\"30.19500000\"],[\"75.90000000\",\"87.54900000\"],[\"75.91000000\",\"0.00000000\"],[\"75.96000000\",\"291.16700000\"],[\"76.11000000\",\"54.78900000\"]]}}"}
{"mode":"v11-raw-disruptor","partitions":4,"sequenceNumber":139,"routingSymbol":"ETHUSDT","localReceivedEpochMillis":1784431326636,"rawPayload":"{\"stream\":\"ethusdt@depth@100ms\",\"data\":{\"e\":\"depthUpdate\",\"E\":1784431326646,\"s\":\"ETHUSDT\",\"U\":2806197898,\"u\":2806197899,\"b\":[[\"1863.62000000\",\"0.82040000\"],[\"1863.55000000\",\"0.00000000\"]],\"a\":[]}}"}
{"mode":"v11-raw-disruptor","partitions":4,"sequenceNumber":140,"routingSymbol":"SOLUSDT","localReceivedEpochMillis":1784431326735,"rawPayload":"{\"stream\":\"solusdt@depth@100ms\",\"data\":{\"e\":\"depthUpdate\",\"E\":1784431326746,\"s\":\"SOLUSDT\",\"U\":1609591833,\"u\":1609591847,\"b\":[[\"75.83000000\",\"0.00000000\"],[\"75.82000000\",\"42.59100000\"],[\"75.81000000\",\"65.42300000\"],[\"75.77000000\",\"0.00000000\"],[\"75.76000000\",\"85.62600000\"],[\"75.73000000\",\"13.19300000\"],[\"75.72000000\",\"7.56200000\"],[\"75.71000000\",\"374.16600000\"],[\"75.68000000\",\"132.22400000\"],[\"75.66000000\",\"445.99600000\"],[\"75.59000000\",\"334.54300000\"],[\"75.57000000\",\"493.61200000\"],[\"75.52000000\",\"340.32800000\"]],\"a\":[[\"75.88000000\",\"49.24500000\"],[\"75.89000000\",\"30.19500000\"],[\"75.95000000\",\"118.91800000\"],[\"75.96000000\",\"271.65700000\"],[\"75.99000000\",\"311.48300000\"],[\"76.01000000\",\"271.04500000\"],[\"76.04000000\",\"380.25600000\"],[\"76.05000000\",\"270.78300000\"],[\"76.13000000\",\"202.93900000\"],[\"76.15000000\",\"0.00000000\"]]}}"}
{"mode":"v11-raw-disruptor","partitions":4,"sequenceNumber":141,"routingSymbol":"SOLUSDT","localReceivedEpochMillis":1784431326835,"rawPayload":"{\"stream\":\"solusdt@depth@100ms\",\"data\":{\"e\":\"depthUpdate\",\"E\":1784431326846,\"s\":\"SOLUSDT\",\"U\":1609591848,\"u\":1609591854,\"b\":[[\"75.82000000\",\"43.14800000\"]],\"a\":[[\"75.86000000\",\"11.56600000\"],[\"75.87000000\",\"17.86100000\"],[\"75.88000000\",\"19.05000000\"],[\"75.89000000\",\"0.00000000\"],[\"75.98000000\",\"272.46700000\"]]}}"}
{"mode":"v11-raw-disruptor","partitions":4,"sequenceNumber":142,"routingSymbol":"ETHUSDT","localReceivedEpochMillis":1784431326837,"rawPayload":"{\"stream\":\"ethusdt@depth@100ms\",\"data\":{\"e\":\"depthUpdate\",\"E\":1784431326847,\"s\":\"ETHUSDT\",\"U\":2806197900,\"u\":2806197901,\"b\":[],\"a\":[[\"1865.19000000\",\"0.00000000\"],[\"1866.26000000\",\"0.00000000\"]]}}"}
{"mode":"v11-raw-disruptor","partitions":4,"sequenceNumber":143,"routingSymbol":"XRPUSDT","localReceivedEpochMillis":1784431326837,"rawPayload":"{\"stream\":\"xrpusdt@depth@100ms\",\"data\":{\"e\":\"depthUpdate\",\"E\":1784431326847,\"s\":\"XRPUSDT\",\"U\":752712324,\"u\":752712325,\"b\":[[\"1.08870000\",\"473.50000000\"]],\"a\":[[\"1.09360000\",\"45.70000000\"]]}}"}
{"mode":"v11-raw-disruptor","partitions":4,"sequenceNumber":144,"routingSymbol":"ETHUSDT","localReceivedEpochMillis":1784431326936,"rawPayload":"{\"stream\":\"ethusdt@depth@100ms\",\"data\":{\"e\":\"depthUpdate\",\"E\":1784431326947,\"s\":\"ETHUSDT\",\"U\":2806197902,\"u\":2806197931,\"b\":[[\"1864.12000000\",\"0.00000000\"],[\"1863.98000000\",\"0.77970000\"],[\"1863.95000000\",\"0.00000000\"],[\"1863.92000000\",\"1.10180000\"],[\"1863.84000000\",\"0.00000000\"],[\"1863.83000000\",\"0.00000000\"],[\"1863.70000000\",\"0.13950000\"],[\"1863.62000000\",\"0.00000000\"],[\"1863.53000000\",\"0.00000000\"],[\"1863.40000000\",\"13.83460000\"],[\"1862.72000000\",\"0.00000000\"],[\"1862.48000000\",\"9.23480000\"]],\"a\":[[\"1864.36000000\",\"0.13940000\"],[\"1864.40000000\",\"1.34180000\"],[\"1864.41000000\",\"0.00000000\"],[\"1864.47000000\",\"0.00000000\"],[\"1864.49000000\",\"1.11050000\"],[\"1864.52000000\",\"0.00000000\"],[\"1864.61000000\",\"0.00000000\"],[\"1864.66000000\",\"1.48010000\"],[\"1864.69000000\",\"0.00000000\"],[\"1864.79000000\",\"0.00000000\"],[\"1864.92000000\",\"0.00000000\"],[\"1864.94000000\",\"0.05980000\"],[\"1864.96000000\",\"0.00000000\"],[\"1865.70000000\",\"9.21890000\"],[\"1865.95000000\",\"0.00000000\"]]}}"}
{"mode":"v11-raw-disruptor","partitions":4,"sequenceNumber":145,"routingSymbol":"BTCUSDT","localReceivedEpochMillis":1784431326936,"rawPayload":"{\"stream\":\"btcusdt@depth@100ms\",\"data\":{\"e\":\"depthUpdate\",\"E\":1784431326947,\"s\":\"BTCUSDT\",\"U\":3244451579,\"u\":3244451579,\"b\":[],\"a\":[[\"64644.57000000\",\"0.00000000\"],[\"64644.61000000\",\"0.00402000\"]]}}"}
{"mode":"v11-raw-disruptor","partitions":4,"sequenceNumber":146,"routingSymbol":"SOLUSDT","localReceivedEpochMillis":1784431327037,"rawPayload":"{\"stream\":\"solusdt@depth@100ms\",\"data\":{\"e\":\"depthUpdate\",\"E\":1784431327047,\"s\":\"SOLUSDT\",\"U\":1609591855,\"u\":1609591855,\"b\":[],\"a\":[[\"75.96000000\",\"301.85200000\"]]}}"}
{"mode":"v11-raw-disruptor","partitions":4,"sequenceNumber":147,"routingSymbol":"ETHUSDT","localReceivedEpochMillis":1784431327037,"rawPayload":"{\"stream\":\"ethusdt@depth@100ms\",\"data\":{\"e\":\"depthUpdate\",\"E\":1784431327047,\"s\":\"ETHUSDT\",\"U\":2806197932,\"u\":2806197978,\"b\":[[\"1863.98000000\",\"0.02970000\"],[\"1863.94000000\",\"0.00000000\"],[\"1863.92000000\",\"0.00000000\"],[\"1863.90000000\",\"0.00000000\"],[\"1863.86000000\",\"0.00000000\"],[\"1863.78000000\",\"0.00000000\"],[\"1863.76000000\",\"0.00000000\"],[\"1863.71000000\",\"1.34230000\"],[\"1863.70000000\",\"1.19510000\"],[\"1863.69000000\",\"0.13910000\"],[\"1863.63000000\",\"0.00000000\"],[\"1863.37000000\",\"0.84370000\"],[\"1863.20000000\",\"0.00000000\"],[\"1863.01000000\",\"2.83330000\"],[\"1862.48000000\",\"0.00000000\"],[\"1862.29000000\",\"9.23590000\"],[\"1860.58000000\",\"0.00000000\"],[\"1858.93000000\",\"26.91520000\"],[\"1856.83000000\",\"26.94580000\"]],\"a\":[[\"1864.27000000\",\"1.17250000\"],[\"1864.29000000\",\"0.00000000\"],[\"1864.32000000\",\"1.26560000\"],[\"1864.33000000\",\"0.00000000\"],[\"1864.35000000\",\"0.13940000\"],[\"1864.36000000\",\"0.00000000\"],[\"1864.38000000\",\"0.00000000\"],[\"1864.39000000\",\"0.84040000\"],[\"1864.40000000\",\"1.34180000\"],[\"1864.47000000\",\"0.00000000\"],[\"1864.49000000\",\"0.00000000\"],[\"1864.59000000\",\"0.00000000\"],[\"1864.61000000\",\"0.05760000\"],[\"1864.65000000\",\"1.48010000\"],[\"1864.66000000\",\"0.00000000\"],[\"1864.79000000\",\"0.00000000\"],[\"1864.88000000\",\"0.97360000\"],[\"1864.91000000\",\"12.02500000\"],[\"1864.94000000\",\"0.00000000\"]]}}"}
{"mode":"v11-raw-disruptor","partitions":4,"sequenceNumber":148,"routingSymbol":"BNBUSDT","localReceivedEpochMillis":1784431327037,"rawPayload":"{\"stream\":\"bnbusdt@depth@100ms\",\"data\":{\"e\":\"depthUpdate\",\"E\":1784431327047,\"s\":\"BNBUSDT\",\"U\":1236336086,\"u\":1236336099,\"b\":[[\"569.03000000\",\"0.00000000\"],[\"568.96000000\",\"0.94300000\"],[\"567.10000000\",\"0.00000000\"],[\"567.09000000\",\"0.00000000\"],[\"567.08000000\",\"0.00000000\"],[\"566.66000000\",\"2.19100000\"]],\"a\":[[\"569.37000000\",\"0.96800000\"],[\"569.43000000\",\"0.00000000\"],[\"569.53000000\",\"1.75700000\"],[\"569.59000000\",\"0.00000000\"],[\"569.61000000\",\"0.00000000\"],[\"570.11000000\",\"0.78400000\"],[\"571.63000000\",\"1.73300000\"],[\"572.07000000\",\"0.00000000\"]]}}"}
{"mode":"v11-raw-disruptor","partitions":4,"sequenceNumber":149,"routingSymbol":"BTCUSDT","localReceivedEpochMillis":1784431327037,"rawPayload":"{\"stream\":\"btcusdt@depth@100ms\",\"data\":{\"e\":\"depthUpdate\",\"E\":1784431327047,\"s\":\"BTCUSDT\",\"U\":3244451580,\"u\":3244451581,\"b\":[[\"64634.23000000\",\"0.00000000\"],[\"64632.21000000\",\"0.02886000\"]],\"a\":[]}}"}
{"mode":"v11-raw-disruptor","partitions":4,"sequenceNumber":150,"routingSymbol":"ETHUSDT","localReceivedEpochMillis":1784431327135,"rawPayload":"{\"stream\":\"ethusdt@depth@100ms\",\"data\":{\"e\":\"depthUpdate\",\"E\":1784431327147,\"s\":\"ETHUSDT\",\"U\":2806197979,\"u\":2806197984,\"b\":[[\"1863.37000000\",\"0.00000000\"],[\"1863.33000000\",\"0.77670000\"]],\"a\":[[\"1864.26000000\",\"2.11820000\"],[\"1864.39000000\",\"0.00000000\"],[\"1864.40000000\",\"0.00000000\"]]}}"}
{"mode":"v11-raw-disruptor","partitions":4,"sequenceNumber":151,"routingSymbol":"BNBUSDT","localReceivedEpochMillis":1784431327135,"rawPayload":"{\"stream\":\"bnbusdt@depth@100ms\",\"data\":{\"e\":\"depthUpdate\",\"E\":1784431327147,\"s\":\"BNBUSDT\",\"U\":1236336100,\"u\":1236336103,\"b\":[[\"569.02000000\",\"0.89800000\"],[\"568.96000000\",\"0.00000000\"]],\"a\":[[\"569.37000000\",\"0.00000000\"],[\"569.43000000\",\"0.92900000\"]]}}"}
{"mode":"v11-raw-disruptor","partitions":4,"sequenceNumber":152,"routingSymbol":"XRPUSDT","localReceivedEpochMillis":1784431327135,"rawPayload":"{\"stream\":\"xrpusdt@depth@100ms\",\"data\":{\"e\":\"depthUpdate\",\"E\":1784431327147,\"s\":\"XRPUSDT\",\"U\":752712326,\"u\":752712328,\"b\":[],\"a\":[[\"1.09400000\",\"171.00000000\"],[\"1.09410000\",\"0.00000000\"],[\"1.09430000\",\"2564.10000000\"]]}}"}
{"mode":"v11-raw-disruptor","partitions":4,"sequenceNumber":153,"routingSymbol":"BNBUSDT","localReceivedEpochMillis":1784431327236,"rawPayload":"{\"stream\":\"bnbusdt@depth@100ms\",\"data\":{\"e\":\"depthUpdate\",\"E\":1784431327247,\"s\":\"BNBUSDT\",\"U\":1236336104,\"u\":1236336104,\"b\":[[\"566.64000000\",\"2.22500000\"]],\"a\":[]}}"}
{"mode":"v11-raw-disruptor","partitions":4,"sequenceNumber":154,"routingSymbol":"SOLUSDT","localReceivedEpochMillis":1784431327237,"rawPayload":"{\"stream\":\"solusdt@depth@100ms\",\"data\":{\"e\":\"depthUpdate\",\"E\":1784431327247,\"s\":\"SOLUSDT\",\"U\":1609591856,\"u\":1609591860,\"b\":[[\"75.82000000\",\"28.83700000\"],[\"75.81000000\",\"79.75400000\"]],\"a\":[[\"75.86000000\",\"25.10800000\"],[\"75.87000000\",\"3.42700000\"],[\"75.92000000\",\"0.00000000\"]]}}"}
{"mode":"v11-raw-disruptor","partitions":4,"sequenceNumber":155,"routingSymbol":"ETHUSDT","localReceivedEpochMillis":1784431327237,"rawPayload":"{\"stream\":\"ethusdt@depth@100ms\",\"data\":{\"e\":\"depthUpdate\",\"E\":1784431327247,\"s\":\"ETHUSDT\",\"U\":2806197985,\"u\":2806198013,\"b\":[[\"1863.98000000\",\"0.00000000\"],[\"1863.69000000\",\"0.00000000\"],[\"1863.68000000\",\"0.00000000\"],[\"1863.54000000\",\"0.13950000\"],[\"1863.40000000\",\"12.35350000\"],[\"1863.33000000\",\"0.00000000\"],[\"1863.25000000\",\"0.00000000\"],[\"1863.24000000\",\"1.48120000\"],[\"1862.53000000\",\"0.00000000\"],[\"1862.25000000\",\"0.00000000\"],[\"1862.14000000\",\"1.56690000\"],[\"1861.49000000\",\"1.95890000\"],[\"1856.71000000\",\"0.00000000\"],[\"1856.68000000\",\"0.00000000\"],[\"1856.46000000\",\"0.00000000\"],[\"1856.21000000\",\"0.28570000\"]],\"a\":[[\"1864.17000000\",\"1.34190000\"],[\"1864.19000000\",\"0.78350000\"],[\"1864.20000000\",\"0.13940000\"],[\"1864.26000000\",\"0.00000000\"],[\"1864.35000000\",\"0.00000000\"],[\"1864.50000000\",\"1.48020000\"],[\"1864.54000000\",\"0.00000000\"],[\"1864.65000000\",\"0.00000000\"],[\"1864.87000000\",\"0.97360000\"],[\"1864.88000000\",\"0.00000000\"],[\"1865.52000000\",\"9.21990000\"],[\"1865.70000000\",\"0.00000000\"],[\"1865.73000000\",\"0.00000000\"],[\"1871.61000000\",\"7.22240000\"],[\"1872.99000000\",\"5.43010000\"],[\"1873.24000000\",\"0.00000000\"]]}}"}
{"mode":"v11-raw-disruptor","partitions":4,"sequenceNumber":156,"routingSymbol":"SOLUSDT","localReceivedEpochMillis":1784431327336,"rawPayload":"{\"stream\":\"solusdt@depth@100ms\",\"data\":{\"e\":\"depthUpdate\",\"E\":1784431327347,\"s\":\"SOLUSDT\",\"U\":1609591861,\"u\":1609591865,\"b\":[[\"75.82000000\",\"43.49300000\"],[\"75.81000000\",\"65.42300000\"]],\"a\":[[\"75.86000000\",\"26.09700000\"],[\"75.89000000\",\"3.28300000\"]]}}"}
{"mode":"v11-raw-disruptor","partitions":4,"sequenceNumber":157,"routingSymbol":"ETHUSDT","localReceivedEpochMillis":1784431327337,"rawPayload":"{\"stream\":\"ethusdt@depth@100ms\",\"data\":{\"e\":\"depthUpdate\",\"E\":1784431327347,\"s\":\"ETHUSDT\",\"U\":2806198014,\"u\":2806198025,\"b\":[[\"1863.81000000\",\"0.02940000\"],[\"1863.70000000\",\"0.00000000\"],[\"1863.63000000\",\"1.16210000\"],[\"1863.32000000\",\"0.00000000\"]],\"a\":[[\"1864.17000000\",\"1.48130000\"],[\"1864.20000000\",\"1.09570000\"],[\"1864.27000000\",\"0.00000000\"],[\"1864.37000000\",\"0.02970000\"],[\"1864.54000000\",\"0.05530000\"],[\"1864.61000000\",\"0.00000000\"],[\"1865.48000000\",\"0.39040000\"]]}}"}
{"mode":"v11-raw-disruptor","partitions":4,"sequenceNumber":158,"routingSymbol":"XRPUSDT","localReceivedEpochMillis":1784431327337,"rawPayload":"{\"stream\":\"xrpusdt@depth@100ms\",\"data\":{\"e\":\"depthUpdate\",\"E\":1784431327347,\"s\":\"XRPUSDT\",\"U\":752712329,\"u\":752712329,\"b\":[],\"a\":[[\"1.09630000\",\"12821.10000000\"]]}}"}
{"mode":"v11-raw-disruptor","partitions":4,"sequenceNumber":159,"routingSymbol":"ETHUSDT","localReceivedEpochMillis":1784431327436,"rawPayload":"{\"stream\":\"ethusdt@depth@100ms\",\"data\":{\"e\":\"depthUpdate\",\"E\":1784431327447,\"s\":\"ETHUSDT\",\"U\":2806198026,\"u\":2806198029,\"b\":[[\"1863.81000000\",\"0.00000000\"],[\"1863.30000000\",\"0.79350000\"]],\"a\":[[\"1864.37000000\",\"0.00000000\"],[\"1865.63000000\",\"0.00000000\"]]}}"}
{"mode":"v11-raw-disruptor","partitions":4,"sequenceNumber":160,"routingSymbol":"BNBUSDT","localReceivedEpochMillis":1784431327437,"rawPayload":"{\"stream\":\"bnbusdt@depth@100ms\",\"data\":{\"e\":\"depthUpdate\",\"E\":1784431327447,\"s\":\"BNBUSDT\",\"U\":1236336105,\"u\":1236336105,\"b\":[[\"566.62000000\",\"2.19400000\"]],\"a\":[]}}"}
{"mode":"v11-raw-disruptor","partitions":4,"sequenceNumber":161,"routingSymbol":"SOLUSDT","localReceivedEpochMillis":1784431327536,"rawPayload":"{\"stream\":\"solusdt@depth@100ms\",\"data\":{\"e\":\"depthUpdate\",\"E\":1784431327547,\"s\":\"SOLUSDT\",\"U\":1609591866,\"u\":1609591866,\"b\":[],\"a\":[[\"75.96000000\",\"271.65700000\"]]}}"}
{"mode":"v11-raw-disruptor","partitions":4,"sequenceNumber":162,"routingSymbol":"ETHUSDT","localReceivedEpochMillis":1784431327537,"rawPayload":"{\"stream\":\"ethusdt@depth@100ms\",\"data\":{\"e\":\"depthUpdate\",\"E\":1784431327547,\"s\":\"ETHUSDT\",\"U\":2806198030,\"u\":2806198037,\"b\":[[\"1863.72000000\",\"0.02960000\"],[\"1863.71000000\",\"0.00000000\"],[\"1863.56000000\",\"1.34240000\"],[\"1863.30000000\",\"0.00000000\"],[\"1863.24000000\",\"1.48120000\"],[\"1856.63000000\",\"0.00000000\"]],\"a\":[[\"1864.28000000\",\"0.02940000\"]]}}"}
{"mode":"v11-raw-disruptor","partitions":4,"sequenceNumber":163,"routingSymbol":"SOLUSDT","localReceivedEpochMillis":1784431327636,"rawPayload":"{\"stream\":\"solusdt@depth@100ms\",\"data\":{\"e\":\"depthUpdate\",\"E\":1784431327647,\"s\":\"SOLUSDT\",\"U\":1609591867,\"u\":1609591868,\"b\":[[\"75.82000000\",\"28.83700000\"],[\"75.81000000\",\"79.25200000\"]],\"a\":[]}}"}
{"mode":"v11-raw-disruptor","partitions":4,"sequenceNumber":164,"routingSymbol":"ETHUSDT","localReceivedEpochMillis":1784431327637,"rawPayload":"{\"stream\":\"ethusdt@depth@100ms\",\"data\":{\"e\":\"depthUpdate\",\"E\":1784431327647,\"s\":\"ETHUSDT\",\"U\":2806198038,\"u\":2806198038,\"b\":[[\"1863.19000000\",\"0.80010000\"]],\"a\":[]}}"}
{"mode":"v11-raw-disruptor","partitions":4,"sequenceNumber":165,"routingSymbol":"SOLUSDT","localReceivedEpochMillis":1784431327738,"rawPayload":"{\"stream\":\"solusdt@depth@100ms\",\"data\":{\"e\":\"depthUpdate\",\"E\":1784431327747,\"s\":\"SOLUSDT\",\"U\":1609591869,\"u\":1609591870,\"b\":[],\"a\":[[\"75.92000000\",\"65.90800000\"],[\"75.94000000\",\"13.18900000\"]]}}"}
{"mode":"v11-raw-disruptor","partitions":4,"sequenceNumber":166,"routingSymbol":"ETHUSDT","localReceivedEpochMillis":1784431327739,"rawPayload":"{\"stream\":\"ethusdt@depth@100ms\",\"data\":{\"e\":\"depthUpdate\",\"E\":1784431327747,\"s\":\"ETHUSDT\",\"U\":2806198039,\"u\":2806198048,\"b\":[[\"1863.54000000\",\"0.00000000\"],[\"1863.48000000\",\"0.13950000\"],[\"1855.35000000\",\"9.17630000\"]],\"a\":[[\"1864.08000000\",\"0.80440000\"],[\"1864.09000000\",\"1.34200000\"],[\"1864.14000000\",\"0.13940000\"],[\"1864.17000000\",\"0.00000000\"],[\"1864.19000000\",\"0.00000000\"],[\"1864.44000000\",\"1.48030000\"],[\"1864.50000000\",\"0.00000000\"],[\"1871.47000000\",\"7.19110000\"],[\"1873.19000000\",\"0.00000000\"]]}}"}
{"mode":"v11-raw-disruptor","partitions":4,"sequenceNumber":167,"routingSymbol":"ETHUSDT","localReceivedEpochMillis":1784431327837,"rawPayload":"{\"stream\":\"ethusdt@depth@100ms\",\"data\":{\"e\":\"depthUpdate\",\"E\":1784431327847,\"s\":\"ETHUSDT\",\"U\":2806198049,\"u\":2806198049,\"b\":[[\"1855.30000000\",\"9.25010000\"]],\"a\":[]}}"}
{"mode":"v11-raw-disruptor","partitions":4,"sequenceNumber":168,"routingSymbol":"ETHUSDT","localReceivedEpochMillis":1784431327937,"rawPayload":"{\"stream\":\"ethusdt@depth@100ms\",\"data\":{\"e\":\"depthUpdate\",\"E\":1784431327947,\"s\":\"ETHUSDT\",\"U\":2806198050,\"u\":2806198052,\"b\":[[\"1863.45000000\",\"0.00000000\"],[\"1863.28000000\",\"0.00000000\"]],\"a\":[[\"1866.10000000\",\"1.63970000\"]]}}"}
{"mode":"v11-raw-disruptor","partitions":4,"sequenceNumber":169,"routingSymbol":"ETHUSDT","localReceivedEpochMillis":1784431328037,"rawPayload":"{\"stream\":\"ethusdt@depth@100ms\",\"data\":{\"e\":\"depthUpdate\",\"E\":1784431328047,\"s\":\"ETHUSDT\",\"U\":2806198053,\"u\":2806198053,\"b\":[[\"1855.24000000\",\"9.27110000\"]],\"a\":[]}}"}
{"mode":"v11-raw-disruptor","partitions":4,"sequenceNumber":170,"routingSymbol":"ETHUSDT","localReceivedEpochMillis":1784431328137,"rawPayload":"{\"stream\":\"ethusdt@depth@100ms\",\"data\":{\"e\":\"depthUpdate\",\"E\":1784431328147,\"s\":\"ETHUSDT\",\"U\":2806198054,\"u\":2806198060,\"b\":[[\"1863.69000000\",\"1.13470000\"],[\"1863.63000000\",\"0.00000000\"],[\"1863.30000000\",\"0.83040000\"],[\"1863.19000000\",\"0.00000000\"]],\"a\":[[\"1864.20000000\",\"0.00000000\"],[\"1864.26000000\",\"1.15340000\"],[\"1865.77000000\",\"1.63970000\"]]}}"}
{"mode":"v11-raw-disruptor","partitions":4,"sequenceNumber":171,"routingSymbol":"XRPUSDT","localReceivedEpochMillis":1784431328137,"rawPayload":"{\"stream\":\"xrpusdt@depth@100ms\",\"data\":{\"e\":\"depthUpdate\",\"E\":1784431328147,\"s\":\"XRPUSDT\",\"U\":752712330,\"u\":752712331,\"b\":[],\"a\":[[\"1.09400000\",\"150.00000000\"],[\"1.09410000\",\"22.40000000\"]]}}"}
{"mode":"v11-raw-disruptor","partitions":4,"sequenceNumber":172,"routingSymbol":"SOLUSDT","localReceivedEpochMillis":1784431328237,"rawPayload":"{\"stream\":\"solusdt@depth@100ms\",\"data\":{\"e\":\"depthUpdate\",\"E\":1784431328247,\"s\":\"SOLUSDT\",\"U\":1609591871,\"u\":1609591872,\"b\":[[\"75.82000000\",\"43.22200000\"],[\"75.81000000\",\"65.42300000\"]],\"a\":[]}}"}
{"mode":"v11-raw-disruptor","partitions":4,"sequenceNumber":173,"routingSymbol":"ETHUSDT","localReceivedEpochMillis":1784431328237,"rawPayload":"{\"stream\":\"ethusdt@depth@100ms\",\"data\":{\"e\":\"depthUpdate\",\"E\":1784431328247,\"s\":\"ETHUSDT\",\"U\":2806198061,\"u\":2806198062,\"b\":[],\"a\":[[\"1864.54000000\",\"0.00000000\"],[\"1864.59000000\",\"0.05820000\"]]}}"}
{"mode":"v11-raw-disruptor","partitions":4,"sequenceNumber":174,"routingSymbol":"BTCUSDT","localReceivedEpochMillis":1784431328237,"rawPayload":"{\"stream\":\"btcusdt@depth@100ms\",\"data\":{\"e\":\"depthUpdate\",\"E\":1784431328247,\"s\":\"BTCUSDT\",\"U\":3244451582,\"u\":3244451584,\"b\":[[\"64644.11000000\",\"0.00000000\"],[\"64635.36000000\",\"0.02839000\"],[\"64633.01000000\",\"0.04000000\"]],\"a\":[[\"64667.55000000\",\"0.00000000\"],[\"64667.56000000\",\"0.02961000\"]]}}"}
{"mode":"v11-raw-disruptor","partitions":4,"sequenceNumber":175,"routingSymbol":"BNBUSDT","localReceivedEpochMillis":1784431328338,"rawPayload":"{\"stream\":\"bnbusdt@depth@100ms\",\"data\":{\"e\":\"depthUpdate\",\"E\":1784431328348,\"s\":\"BNBUSDT\",\"U\":1236336106,\"u\":1236336109,\"b\":[[\"567.77000000\",\"0.00000000\"],[\"567.73000000\",\"0.00400000\"]],\"a\":[[\"569.34000000\",\"2.47300000\"],[\"569.40000000\",\"1.59500000\"]]}}"}
{"mode":"v11-raw-disruptor","partitions":4,"sequenceNumber":176,"routingSymbol":"ETHUSDT","localReceivedEpochMillis":1784431328338,"rawPayload":"{\"stream\":\"ethusdt@depth@100ms\",\"data\":{\"e\":\"depthUpdate\",\"E\":1784431328348,\"s\":\"ETHUSDT\",\"U\":2806198063,\"u\":2806198086,\"b\":[[\"1863.88000000\",\"0.00000000\"],[\"1863.82000000\",\"1.17640000\"],[\"1863.80000000\",\"0.00000000\"],[\"1863.69000000\",\"0.00000000\"],[\"1863.39000000\",\"0.78580000\"],[\"1863.35000000\",\"0.00000000\"],[\"1863.30000000\",\"0.00000000\"]],\"a\":[[\"1864.09000000\",\"0.00000000\"],[\"1864.26000000\",\"0.00000000\"],[\"1864.27000000\",\"1.34190000\"],[\"1864.37000000\",\"0.00000000\"],[\"1864.39000000\",\"1.10810000\"],[\"1864.45000000\",\"0.00000000\"],[\"1864.59000000\",\"0.00000000\"],[\"1864.62000000\",\"0.00000000\"],[\"1864.70000000\",\"0.00000000\"],[\"1866.10000000\",\"0.00000000\"]]}}"}
{"mode":"v11-raw-disruptor","partitions":4,"sequenceNumber":177,"routingSymbol":"XRPUSDT","localReceivedEpochMillis":1784431328338,"rawPayload":"{\"stream\":\"xrpusdt@depth@100ms\",\"data\":{\"e\":\"depthUpdate\",\"E\":1784431328348,\"s\":\"XRPUSDT\",\"U\":752712332,\"u\":752712333,\"b\":[[\"1.09190000\",\"154.20000000\"]],\"a\":[[\"1.09510000\",\"179.90000000\"]]}}"}
{"mode":"v11-raw-disruptor","partitions":4,"sequenceNumber":178,"routingSymbol":"SOLUSDT","localReceivedEpochMillis":1784431328437,"rawPayload":"{\"stream\":\"solusdt@depth@100ms\",\"data\":{\"e\":\"depthUpdate\",\"E\":1784431328448,\"s\":\"SOLUSDT\",\"U\":1609591873,\"u\":1609591879,\"b\":[[\"75.82000000\",\"23.27200000\"],[\"75.81000000\",\"85.40300000\"]],\"a\":[[\"75.85000000\",\"51.98100000\"],[\"75.86000000\",\"14.53100000\"]]}}"}
{"mode":"v11-raw-disruptor","partitions":4,"sequenceNumber":179,"routingSymbol":"ETHUSDT","localReceivedEpochMillis":1784431328438,"rawPayload":"{\"stream\":\"ethusdt@depth@100ms\",\"data\":{\"e\":\"depthUpdate\",\"E\":1784431328448,\"s\":\"ETHUSDT\",\"U\":2806198087,\"u\":2806198091,\"b\":[[\"1863.82000000\",\"0.00000000\"],[\"1863.76000000\",\"1.13120000\"]],\"a\":[[\"1864.33000000\",\"1.19050000\"],[\"1864.39000000\",\"0.00000000\"],[\"1864.70000000\",\"0.05540000\"]]}}"}
{"mode":"v11-raw-disruptor","partitions":4,"sequenceNumber":180,"routingSymbol":"ETHUSDT","localReceivedEpochMillis":1784431328537,"rawPayload":"{\"stream\":\"ethusdt@depth@100ms\",\"data\":{\"e\":\"depthUpdate\",\"E\":1784431328548,\"s\":\"ETHUSDT\",\"U\":2806198092,\"u\":2806198095,\"b\":[[\"1863.82000000\",\"1.15930000\"],[\"1863.76000000\",\"0.00000000\"]],\"a\":[[\"1864.33000000\",\"0.00000000\"],[\"1864.39000000\",\"1.16410000\"]]}}"}
{"mode":"v11-raw-disruptor","partitions":4,"sequenceNumber":181,"routingSymbol":"XRPUSDT","localReceivedEpochMillis":1784431328538,"rawPayload":"{\"stream\":\"xrpusdt@depth@100ms\",\"data\":{\"e\":\"depthUpdate\",\"E\":1784431328548,\"s\":\"XRPUSDT\",\"U\":752712334,\"u\":752712335,\"b\":[[\"1.09330000\",\"3752.60000000\"],[\"1.09320000\",\"4738.80000000\"]],\"a\":[[\"1.09390000\",\"1543.70000000\"],[\"1.09420000\",\"2074.70000000\"]]}}"}
{"mode":"v11-raw-disruptor","partitions":4,"sequenceNumber":182,"routingSymbol":"SOLUSDT","localReceivedEpochMillis":1784431328837,"rawPayload":"{\"stream\":\"solusdt@depth@100ms\",\"data\":{\"e\":\"depthUpdate\",\"E\":1784431328848,\"s\":\"SOLUSDT\",\"U\":1609591880,\"u\":1609591880,\"b\":[],\"a\":[[\"75.86000000\",\"15.08500000\"]]}}"}
{"mode":"v11-raw-disruptor","partitions":4,"sequenceNumber":183,"routingSymbol":"ETHUSDT","localReceivedEpochMillis":1784431328837,"rawPayload":"{\"stream\":\"ethusdt@depth@100ms\",\"data\":{\"e\":\"depthUpdate\",\"E\":1784431328848,\"s\":\"ETHUSDT\",\"U\":2806198096,\"u\":2806198101,\"b\":[[\"1863.82000000\",\"0.00000000\"],[\"1863.76000000\",\"1.16250000\"],[\"1863.33000000\",\"1.63970000\"]],\"a\":[[\"1864.33000000\",\"1.12320000\"],[\"1864.39000000\",\"0.00000000\"],[\"1865.77000000\",\"0.00000000\"]]}}"}
{"mode":"v11-raw-disruptor","partitions":4,"sequenceNumber":184,"routingSymbol":"XRPUSDT","localReceivedEpochMillis":1784431328837,"rawPayload":"{\"stream\":\"xrpusdt@depth@100ms\",\"data\":{\"e\":\"depthUpdate\",\"E\":1784431328848,\"s\":\"XRPUSDT\",\"U\":752712336,\"u\":752712336,\"b\":[],\"a\":[[\"1.09420000\",\"4597.00000000\"],[\"1.09430000\",\"42.00000000\"]]}}"}
{"mode":"v11-raw-disruptor","partitions":4,"sequenceNumber":185,"routingSymbol":"SOLUSDT","localReceivedEpochMillis":1784431328936,"rawPayload":"{\"stream\":\"solusdt@depth@100ms\",\"data\":{\"e\":\"depthUpdate\",\"E\":1784431328948,\"s\":\"SOLUSDT\",\"U\":1609591881,\"u\":1609591881,\"b\":[],\"a\":[[\"75.87000000\",\"22.47700000\"],[\"75.88000000\",\"0.00000000\"]]}}"}
{"mode":"v11-raw-disruptor","partitions":4,"sequenceNumber":186,"routingSymbol":"XRPUSDT","localReceivedEpochMillis":1784431329037,"rawPayload":"{\"stream\":\"xrpusdt@depth@100ms\",\"data\":{\"e\":\"depthUpdate\",\"E\":1784431329048,\"s\":\"XRPUSDT\",\"U\":752712337,\"u\":752712345,\"b\":[[\"1.09320000\",\"3492.00000000\"],[\"1.09310000\",\"3248.90000000\"],[\"1.09280000\",\"2094.00000000\"],[\"1.09270000\",\"2525.50000000\"]],\"a\":[[\"1.09370000\",\"3242.30000000\"],[\"1.09380000\",\"237.70000000\"],[\"1.09390000\",\"1306.10000000\"],[\"1.09400000\",\"173.90000000\"],[\"1.09410000\",\"0.00000000\"]]}}"}
{"mode":"v11-raw-disruptor","partitions":4,"sequenceNumber":187,"routingSymbol":"ETHUSDT","localReceivedEpochMillis":1784431329137,"rawPayload":"{\"stream\":\"ethusdt@depth@100ms\",\"data\":{\"e\":\"depthUpdate\",\"E\":1784431329148,\"s\":\"ETHUSDT\",\"U\":2806198102,\"u\":2806198109,\"b\":[[\"1863.84000000\",\"0.00000000\"],[\"1863.79000000\",\"1.11610000\"],[\"1863.76000000\",\"0.00000000\"]],\"a\":[[\"1864.33000000\",\"0.00000000\"],[\"1864.35000000\",\"1.13070000\"],[\"1864.41000000\",\"0.00000000\"]]}}"}
{"mode":"v11-raw-disruptor","partitions":4,"sequenceNumber":188,"routingSymbol":"ETHUSDT","localReceivedEpochMillis":1784431329238,"rawPayload":"{\"stream\":\"ethusdt@depth@100ms\",\"data\":{\"e\":\"depthUpdate\",\"E\":1784431329248,\"s\":\"ETHUSDT\",\"U\":2806198110,\"u\":2806198110,\"b\":[],\"a\":[[\"1864.72000000\",\"0.97360000\"],[\"1864.87000000\",\"0.00000000\"]]}}"}
{"mode":"v11-raw-disruptor","partitions":4,"sequenceNumber":189,"routingSymbol":"ETHUSDT","localReceivedEpochMillis":1784431329338,"rawPayload":"{\"stream\":\"ethusdt@depth@100ms\",\"data\":{\"e\":\"depthUpdate\",\"E\":1784431329348,\"s\":\"ETHUSDT\",\"U\":2806198111,\"u\":2806198112,\"b\":[],\"a\":[[\"1864.63000000\",\"0.05510000\"],[\"1864.70000000\",\"0.00000000\"]]}}"}
{"mode":"v11-raw-disruptor","partitions":4,"sequenceNumber":190,"routingSymbol":"BNBUSDT","localReceivedEpochMillis":1784431329338,"rawPayload":"{\"stream\":\"bnbusdt@depth@100ms\",\"data\":{\"e\":\"depthUpdate\",\"E\":1784431329348,\"s\":\"BNBUSDT\",\"U\":1236336110,\"u\":1236336111,\"b\":[[\"569.19000000\",\"1.58600000\"],[\"569.17000000\",\"0.00000000\"]],\"a\":[[\"569.39000000\",\"1.70900000\"],[\"569.41000000\",\"0.00000000\"]]}}"}
{"mode":"v11-raw-disruptor","partitions":4,"sequenceNumber":191,"routingSymbol":"BTCUSDT","localReceivedEpochMillis":1784431329338,"rawPayload":"{\"stream\":\"btcusdt@depth@100ms\",\"data\":{\"e\":\"depthUpdate\",\"E\":1784431329348,\"s\":\"BTCUSDT\",\"U\":3244451585,\"u\":3244451586,\"b\":[],\"a\":[[\"64680.52000000\",\"0.07739000\"],[\"64706.75000000\",\"0.00000000\"]]}}"}
{"mode":"v11-raw-disruptor","partitions":4,"sequenceNumber":192,"routingSymbol":"XRPUSDT","localReceivedEpochMillis":1784431329338,"rawPayload":"{\"stream\":\"xrpusdt@depth@100ms\",\"data\":{\"e\":\"depthUpdate\",\"E\":1784431329348,\"s\":\"XRPUSDT\",\"U\":752712346,\"u\":752712347,\"b\":[],\"a\":[[\"1.09410000\",\"2522.50000000\"],[\"1.09420000\",\"2074.70000000\"],[\"1.09480000\",\"6896.20000000\"],[\"1.09500000\",\"0.00000000\"]]}}"}
{"mode":"v11-raw-disruptor","partitions":4,"sequenceNumber":193,"routingSymbol":"XRPUSDT","localReceivedEpochMillis":1784431329538,"rawPayload":"{\"stream\":\"xrpusdt@depth@100ms\",\"data\":{\"e\":\"depthUpdate\",\"E\":1784431329548,\"s\":\"XRPUSDT\",\"U\":752712348,\"u\":752712351,\"b\":[[\"1.09320000\",\"4499.40000000\"],[\"1.09310000\",\"2312.50000000\"]],\"a\":[[\"1.09370000\",\"2287.30000000\"],[\"1.09390000\",\"2265.40000000\"]]}}"}
{"mode":"v11-raw-disruptor","partitions":4,"sequenceNumber":194,"routingSymbol":"ETHUSDT","localReceivedEpochMillis":1784431329638,"rawPayload":"{\"stream\":\"ethusdt@depth@100ms\",\"data\":{\"e\":\"depthUpdate\",\"E\":1784431329648,\"s\":\"ETHUSDT\",\"U\":2806198113,\"u\":2806198113,\"b\":[],\"a\":[[\"1865.10000000\",\"1.63970000\"]]}}"}
{"mode":"v11-raw-disruptor","partitions":4,"sequenceNumber":195,"routingSymbol":"SOLUSDT","localReceivedEpochMillis":1784431329837,"rawPayload":"{\"stream\":\"solusdt@depth@100ms\",\"data\":{\"e\":\"depthUpdate\",\"E\":1784431329849,\"s\":\"SOLUSDT\",\"U\":1609591882,\"u\":1609591882,\"b\":[],\"a\":[[\"75.92000000\",\"96.10300000\"]]}}"}
{"mode":"v11-raw-disruptor","partitions":4,"sequenceNumber":196,"routingSymbol":"XRPUSDT","localReceivedEpochMillis":1784431329838,"rawPayload":"{\"stream\":\"xrpusdt@depth@100ms\",\"data\":{\"e\":\"depthUpdate\",\"E\":1784431329849,\"s\":\"XRPUSDT\",\"U\":752712352,\"u\":752712355,\"b\":[[\"1.09230000\",\"4580.20000000\"],[\"1.09220000\",\"1355.30000000\"],[\"1.09170000\",\"0.00000000\"],[\"1.09150000\",\"2591.90000000\"],[\"1.09100000\",\"15986.80000000\"],[\"1.09090000\",\"7915.30000000\"],[\"1.08970000\",\"16084.10000000\"],[\"1.08960000\",\"8772.00000000\"]],\"a\":[]}}"}
{"mode":"v11-raw-disruptor","partitions":4,"sequenceNumber":197,"routingSymbol":"XRPUSDT","localReceivedEpochMillis":1784431330038,"rawPayload":"{\"stream\":\"xrpusdt@depth@100ms\",\"data\":{\"e\":\"depthUpdate\",\"E\":1784431330049,\"s\":\"XRPUSDT\",\"U\":752712356,\"u\":752712356,\"b\":[[\"1.08890000\",\"0.00000000\"],[\"1.08720000\",\"522.40000000\"]],\"a\":[]}}"}
{"mode":"v11-raw-disruptor","partitions":4,"sequenceNumber":198,"routingSymbol":"XRPUSDT","localReceivedEpochMillis":1784431330238,"rawPayload":"{\"stream\":\"xrpusdt@depth@100ms\",\"data\":{\"e\":\"depthUpdate\",\"E\":1784431330249,\"s\":\"XRPUSDT\",\"U\":752712357,\"u\":752712358,\"b\":[[\"1.09330000\",\"2442.10000000\"],[\"1.09320000\",\"5809.90000000\"]],\"a\":[[\"1.09380000\",\"1543.80000000\"],[\"1.09390000\",\"959.30000000\"]]}}"}
{"mode":"v11-raw-disruptor","partitions":4,"sequenceNumber":199,"routingSymbol":"BTCUSDT","localReceivedEpochMillis":1784431330337,"rawPayload":"{\"stream\":\"btcusdt@depth@100ms\",\"data\":{\"e\":\"depthUpdate\",\"E\":1784431330349,\"s\":\"BTCUSDT\",\"U\":3244451587,\"u\":3244451587,\"b\":[],\"a\":[[\"80837.82000000\",\"0.00045000\"]]}}"}
{"mode":"v11-raw-disruptor","partitions":4,"sequenceNumber":200,"routingSymbol":"XRPUSDT","localReceivedEpochMillis":1784431330439,"rawPayload":"{\"stream\":\"xrpusdt@depth@100ms\",\"data\":{\"e\":\"depthUpdate\",\"E\":1784431330449,\"s\":\"XRPUSDT\",\"U\":752712359,\"u\":752712359,\"b\":[],\"a\":[[\"1.09450000\",\"2074.70000000\"]]}}"}
{"mode":"v11-raw-disruptor","partitions":4,"sequenceNumber":201,"routingSymbol":"BNBUSDT","localReceivedEpochMillis":1784431330539,"rawPayload":"{\"stream\":\"bnbusdt@depth@100ms\",\"data\":{\"e\":\"depthUpdate\",\"E\":1784431330549,\"s\":\"BNBUSDT\",\"U\":1236336112,\"u\":1236336113,\"b\":[],\"a\":[[\"569.85000000\",\"1.75700000\"],[\"570.08000000\",\"0.00000000\"]]}}"}
{"mode":"v11-raw-disruptor","partitions":4,"sequenceNumber":202,"routingSymbol":"XRPUSDT","localReceivedEpochMillis":1784431330539,"rawPayload":"{\"stream\":\"xrpusdt@depth@100ms\",\"data\":{\"e\":\"depthUpdate\",\"E\":1784431330549,\"s\":\"XRPUSDT\",\"U\":752712360,\"u\":752712360,\"b\":[],\"a\":[[\"1.09400000\",\"667.90000000\"]]}}"}
{"mode":"v11-raw-disruptor","partitions":4,"sequenceNumber":203,"routingSymbol":"SOLUSDT","localReceivedEpochMillis":1784431330638,"rawPayload":"{\"stream\":\"solusdt@depth@100ms\",\"data\":{\"e\":\"depthUpdate\",\"E\":1784431330649,\"s\":\"SOLUSDT\",\"U\":1609591883,\"u\":1609591889,\"b\":[[\"75.82000000\",\"19.84300000\"],[\"75.81000000\",\"88.83200000\"]],\"a\":[[\"75.86000000\",\"18.51200000\"],[\"75.87000000\",\"39.18000000\"],[\"75.88000000\",\"30.19500000\"],[\"75.89000000\",\"69.84800000\"],[\"75.90000000\",\"51.18100000\"],[\"75.92000000\",\"65.90800000\"]]}}"}
{"mode":"v11-raw-disruptor","partitions":4,"sequenceNumber":204,"routingSymbol":"XRPUSDT","localReceivedEpochMillis":1784431330838,"rawPayload":"{\"stream\":\"xrpusdt@depth@100ms\",\"data\":{\"e\":\"depthUpdate\",\"E\":1784431330849,\"s\":\"XRPUSDT\",\"U\":752712361,\"u\":752712361,\"b\":[],\"a\":[[\"1.09410000\",\"0.00000000\"],[\"1.09420000\",\"4597.20000000\"]]}}"}
{"mode":"v11-raw-disruptor","partitions":4,"sequenceNumber":205,"routingSymbol":"ETHUSDT","localReceivedEpochMillis":1784431330839,"rawPayload":"{\"stream\":\"ethusdt@depth@100ms\",\"data\":{\"e\":\"depthUpdate\",\"E\":1784431330849,\"s\":\"ETHUSDT\",\"U\":2806198114,\"u\":2806198123,\"b\":[[\"1863.79000000\",\"0.00000000\"],[\"1863.77000000\",\"1.15950000\"],[\"1863.67000000\",\"0.00000000\"],[\"1863.62000000\",\"0.75000000\"],[\"1863.40000000\",\"13.44660000\"]],\"a\":[[\"1864.24000000\",\"0.00000000\"],[\"1864.34000000\",\"1.16620000\"],[\"1864.35000000\",\"0.00000000\"]]}}"}
{"mode":"v11-raw-disruptor","partitions":4,"sequenceNumber":206,"routingSymbol":"BTCUSDT","localReceivedEpochMillis":1784431330939,"rawPayload":"{\"stream\":\"btcusdt@depth@100ms\",\"data\":{\"e\":\"depthUpdate\",\"E\":1784431330949,\"s\":\"BTCUSDT\",\"U\":3244451588,\"u\":3244451588,\"b\":[],\"a\":[[\"80837.82000000\",\"0.00030000\"]]}}"}
{"mode":"v11-raw-disruptor","partitions":4,"sequenceNumber":207,"routingSymbol":"XRPUSDT","localReceivedEpochMillis":1784431331039,"rawPayload":"{\"stream\":\"xrpusdt@depth@100ms\",\"data\":{\"e\":\"depthUpdate\",\"E\":1784431331049,\"s\":\"XRPUSDT\",\"U\":752712362,\"u\":752712363,\"b\":[[\"1.09260000\",\"54.30000000\"],[\"1.09240000\",\"0.00000000\"]],\"a\":[]}}"}
{"mode":"v11-raw-disruptor","partitions":4,"sequenceNumber":208,"routingSymbol":"SOLUSDT","localReceivedEpochMillis":1784431331139,"rawPayload":"{\"stream\":\"solusdt@depth@100ms\",\"data\":{\"e\":\"depthUpdate\",\"E\":1784431331149,\"s\":\"SOLUSDT\",\"U\":1609591890,\"u\":1609591891,\"b\":[[\"75.79000000\",\"66.60700000\"]],\"a\":[[\"75.87000000\",\"19.05000000\"]]}}"}
{"mode":"v11-raw-disruptor","partitions":4,"sequenceNumber":209,"routingSymbol":"ETHUSDT","localReceivedEpochMillis":1784431331139,"rawPayload":"{\"stream\":\"ethusdt@depth@100ms\",\"data\":{\"e\":\"depthUpdate\",\"E\":1784431331149,\"s\":\"ETHUSDT\",\"U\":2806198124,\"u\":2806198135,\"b\":[[\"1863.77000000\",\"0.00000000\"],[\"1863.73000000\",\"1.12250000\"],[\"1863.67000000\",\"0.00000000\"]],\"a\":[[\"1864.24000000\",\"0.00000000\"],[\"1864.30000000\",\"1.16750000\"],[\"1864.34000000\",\"0.00000000\"],[\"1864.55000000\",\"0.00000000\"],[\"1864.63000000\",\"0.00000000\"],[\"1864.67000000\",\"0.05890000\"]]}}"}
{"mode":"v11-raw-disruptor","partitions":4,"sequenceNumber":210,"routingSymbol":"BTCUSDT","localReceivedEpochMillis":1784431331339,"rawPayload":"{\"stream\":\"btcusdt@depth@100ms\",\"data\":{\"e\":\"depthUpdate\",\"E\":1784431331350,\"s\":\"BTCUSDT\",\"U\":3244451589,\"u\":3244451593,\"b\":[[\"64632.21000000\",\"0.00000000\"],[\"64630.42000000\",\"0.03095000\"],[\"64585.29000000\",\"0.00000000\"]],\"a\":[[\"64665.02000000\",\"0.00321000\"],[\"64678.29000000\",\"0.00000000\"]]}}"}
{"mode":"v11-raw-disruptor","partitions":4,"sequenceNumber":211,"routingSymbol":"ETHUSDT","localReceivedEpochMillis":1784431331339,"rawPayload":"{\"stream\":\"ethusdt@depth@100ms\",\"data\":{\"e\":\"depthUpdate\",\"E\":1784431331350,\"s\":\"ETHUSDT\",\"U\":2806198136,\"u\":2806198143,\"b\":[[\"1862.67000000\",\"0.00000000\"],[\"1862.37000000\",\"2.01670000\"],[\"1861.55000000\",\"0.00000000\"],[\"1861.25000000\",\"2.97580000\"],[\"1860.44000000\",\"0.00000000\"],[\"1860.13000000\",\"5.93290000\"],[\"1858.20000000\",\"0.00000000\"],[\"1857.90000000\",\"14.08700000\"]],\"a\":[[\"1864.13000000\",\"1.34200000\"],[\"1864.27000000\",\"0.00000000\"],[\"1866.86000000\",\"2.09560000\"],[\"1867.16000000\",\"0.00000000\"],[\"1869.09000000\",\"5.81330000\"],[\"1869.40000000\",\"3.82490000\"]]}}"}
{"mode":"v11-raw-disruptor","partitions":4,"sequenceNumber":212,"routingSymbol":"BTCUSDT","localReceivedEpochMillis":1784431331539,"rawPayload":"{\"stream\":\"btcusdt@depth@100ms\",\"data\":{\"e\":\"depthUpdate\",\"E\":1784431331550,\"s\":\"BTCUSDT\",\"U\":3244451594,\"u\":3244451597,\"b\":[[\"64582.39000000\",\"0.20855000\"]],\"a\":[[\"64651.71000000\",\"0.00000000\"],[\"64698.71000000\",\"0.20902000\"],[\"64816.50000000\",\"0.00000000\"]]}}"}
{"mode":"v11-raw-disruptor","partitions":4,"sequenceNumber":213,"routingSymbol":"BTCUSDT","localReceivedEpochMillis":1784431331640,"rawPayload":"{\"stream\":\"btcusdt@depth@100ms\",\"data\":{\"e\":\"depthUpdate\",\"E\":1784431331650,\"s\":\"BTCUSDT\",\"U\":3244451598,\"u\":3244451599,\"b\":[[\"64641.30000000\",\"0.02839000\"],[\"64635.36000000\",\"0.00000000\"]],\"a\":[[\"64665.14000000\",\"0.02961000\"],[\"64667.56000000\",\"0.00000000\"]]}}"}
{"mode":"v11-raw-disruptor","partitions":4,"sequenceNumber":214,"routingSymbol":"ETHUSDT","localReceivedEpochMillis":1784431331640,"rawPayload":"{\"stream\":\"ethusdt@depth@100ms\",\"data\":{\"e\":\"depthUpdate\",\"E\":1784431331650,\"s\":\"ETHUSDT\",\"U\":2806198144,\"u\":2806198147,\"b\":[[\"1863.55000000\",\"0.13950000\"],[\"1863.48000000\",\"0.00000000\"]],\"a\":[[\"1864.14000000\",\"0.00000000\"],[\"1864.21000000\",\"0.13940000\"],[\"1864.44000000\",\"0.00000000\"],[\"1864.51000000\",\"1.48000000\"],[\"1864.64000000\",\"0.97360000\"],[\"1864.72000000\",\"0.00000000\"]]}}"}
{"mode":"v11-raw-disruptor","partitions":4,"sequenceNumber":215,"routingSymbol":"SOLUSDT","localReceivedEpochMillis":1784431331739,"rawPayload":"{\"stream\":\"solusdt@depth@100ms\",\"data\":{\"e\":\"depthUpdate\",\"E\":1784431331750,\"s\":\"SOLUSDT\",\"U\":1609591892,\"u\":1609591894,\"b\":[[\"75.52000000\",\"440.97800000\"]],\"a\":[[\"75.88000000\",\"0.00000000\"],[\"75.91000000\",\"30.19500000\"]]}}"}
{"mode":"v11-raw-disruptor","partitions":4,"sequenceNumber":216,"routingSymbol":"BTCUSDT","localReceivedEpochMillis":1784431331739,"rawPayload":"{\"stream\":\"btcusdt@depth@100ms\",\"data\":{\"e\":\"depthUpdate\",\"E\":1784431331750,\"s\":\"BTCUSDT\",\"U\":3244451600,\"u\":3244451601,\"b\":[[\"64635.53000000\",\"0.00000000\"]],\"a\":[[\"64651.42000000\",\"0.00000000\"]]}}"}
{"mode":"v11-raw-disruptor","partitions":4,"sequenceNumber":217,"routingSymbol":"SOLUSDT","localReceivedEpochMillis":1784431331839,"rawPayload":"{\"stream\":\"solusdt@depth@100ms\",\"data\":{\"e\":\"depthUpdate\",\"E\":1784431331850,\"s\":\"SOLUSDT\",\"U\":1609591895,\"u\":1609591896,\"b\":[[\"75.79000000\",\"30.19500000\"],[\"75.78000000\",\"66.71500000\"]],\"a\":[[\"75.93000000\",\"99.43500000\"],[\"75.95000000\",\"19.51000000\"]]}}"}
{"mode":"v11-raw-disruptor","partitions":4,"sequenceNumber":218,"routingSymbol":"ETHUSDT","localReceivedEpochMillis":1784431331839,"rawPayload":"{\"stream\":\"ethusdt@depth@100ms\",\"data\":{\"e\":\"depthUpdate\",\"E\":1784431331850,\"s\":\"ETHUSDT\",\"U\":2806198148,\"u\":2806198150,\"b\":[[\"1863.40000000\",\"12.35350000\"],[\"1863.33000000\",\"0.00000000\"]],\"a\":[[\"1865.53000000\",\"1.63970000\"]]}}"}
{"mode":"v11-raw-disruptor","partitions":4,"sequenceNumber":219,"routingSymbol":"BNBUSDT","localReceivedEpochMillis":1784431331839,"rawPayload":"{\"stream\":\"bnbusdt@depth@100ms\",\"data\":{\"e\":\"depthUpdate\",\"E\":1784431331850,\"s\":\"BNBUSDT\",\"U\":1236336114,\"u\":1236336114,\"b\":[[\"567.75000000\",\"0.00400000\"],[\"567.73000000\",\"0.00000000\"]],\"a\":[]}}"}
{"mode":"v11-raw-disruptor","partitions":4,"sequenceNumber":220,"routingSymbol":"XRPUSDT","localReceivedEpochMillis":1784431331839,"rawPayload":"{\"stream\":\"xrpusdt@depth@100ms\",\"data\":{\"e\":\"depthUpdate\",\"E\":1784431331850,\"s\":\"XRPUSDT\",\"U\":752712364,\"u\":752712365,\"b\":[[\"1.09290000\",\"2103.20000000\"],[\"1.09280000\",\"2074.70000000\"]],\"a\":[]}}"}
{"mode":"v11-raw-disruptor","partitions":4,"sequenceNumber":221,"routingSymbol":"ETHUSDT","localReceivedEpochMillis":1784431332139,"rawPayload":"{\"stream\":\"ethusdt@depth@100ms\",\"data\":{\"e\":\"depthUpdate\",\"E\":1784431332150,\"s\":\"ETHUSDT\",\"U\":2806198151,\"u\":2806198151,\"b\":[[\"1862.32000000\",\"1.63970000\"]],\"a\":[]}}"}
{"mode":"v11-raw-disruptor","partitions":4,"sequenceNumber":222,"routingSymbol":"XRPUSDT","localReceivedEpochMillis":1784431332139,"rawPayload":"{\"stream\":\"xrpusdt@depth@100ms\",\"data\":{\"e\":\"depthUpdate\",\"E\":1784431332150,\"s\":\"XRPUSDT\",\"U\":752712366,\"u\":752712369,\"b\":[[\"1.09290000\",\"2074.70000000\"],[\"1.09280000\",\"2103.20000000\"]],\"a\":[[\"1.09390000\",\"987.80000000\"],[\"1.09400000\",\"644.00000000\"]]}}"}
{"mode":"v11-raw-disruptor","partitions":4,"sequenceNumber":223,"routingSymbol":"BTCUSDT","localReceivedEpochMillis":1784431332239,"rawPayload":"{\"stream\":\"btcusdt@depth@100ms\",\"data\":{\"e\":\"depthUpdate\",\"E\":1784431332250,\"s\":\"BTCUSDT\",\"U\":3244451602,\"u\":3244451603,\"b\":[[\"64632.53000000\",\"0.00079000\"]],\"a\":[[\"64648.61000000\",\"0.00077000\"]]}}"}
{"mode":"v11-raw-disruptor","partitions":4,"sequenceNumber":224,"routingSymbol":"SOLUSDT","localReceivedEpochMillis":1784431332338,"rawPayload":"{\"stream\":\"solusdt@depth@100ms\",\"data\":{\"e\":\"depthUpdate\",\"E\":1784431332350,\"s\":\"SOLUSDT\",\"U\":1609591897,\"u\":1609591905,\"b\":[[\"75.81000000\",\"53.04400000\"],[\"75.80000000\",\"3.42900000\"],[\"75.71000000\",\"37.05400000\"]],\"a\":[[\"75.85000000\",\"55.40800000\"],[\"75.86000000\",\"15.08500000\"],[\"75.88000000\",\"36.37500000\"],[\"75.89000000\",\"3.28300000\"],[\"75.95000000\",\"291.36400000\"],[\"76.10000000\",\"0.00000000\"]]}}"}
{"mode":"v11-raw-disruptor","partitions":4,"sequenceNumber":225,"routingSymbol":"ETHUSDT","localReceivedEpochMillis":1784431332340,"rawPayload":"{\"stream\":\"ethusdt@depth@100ms\",\"data\":{\"e\":\"depthUpdate\",\"E\":1784431332350,\"s\":\"ETHUSDT\",\"U\":2806198152,\"u\":2806198152,\"b\":[[\"1862.32000000\",\"0.00000000\"]],\"a\":[]}}"}
{"mode":"v11-raw-disruptor","partitions":4,"sequenceNumber":226,"routingSymbol":"BTCUSDT","localReceivedEpochMillis":1784431332340,"rawPayload":"{\"stream\":\"btcusdt@depth@100ms\",\"data\":{\"e\":\"depthUpdate\",\"E\":1784431332350,\"s\":\"BTCUSDT\",\"U\":3244451604,\"u\":3244451604,\"b\":[[\"64514.00000000\",\"0.00000000\"]],\"a\":[]}}"}
{"mode":"v11-raw-disruptor","partitions":4,"sequenceNumber":227,"routingSymbol":"SOLUSDT","localReceivedEpochMillis":1784431332439,"rawPayload":"{\"stream\":\"solusdt@depth@100ms\",\"data\":{\"e\":\"depthUpdate\",\"E\":1784431332450,\"s\":\"SOLUSDT\",\"U\":1609591906,\"u\":1609591908,\"b\":[[\"75.79000000\",\"32.36000000\"]],\"a\":[[\"75.86000000\",\"14.53100000\"],[\"75.90000000\",\"71.31100000\"]]}}"}
{"mode":"v11-raw-disruptor","partitions":4,"sequenceNumber":228,"routingSymbol":"SOLUSDT","localReceivedEpochMillis":1784431332538,"rawPayload":"{\"stream\":\"solusdt@depth@100ms\",\"data\":{\"e\":\"depthUpdate\",\"E\":1784431332550,\"s\":\"SOLUSDT\",\"U\":1609591909,\"u\":1609591911,\"b\":[[\"75.82000000\",\"19.28600000\"],[\"75.70000000\",\"270.99000000\"]],\"a\":[[\"75.85000000\",\"55.96600000\"]]}}"}
{"mode":"v11-raw-disruptor","partitions":4,"sequenceNumber":229,"routingSymbol":"BTCUSDT","localReceivedEpochMillis":1784431332540,"rawPayload":"{\"stream\":\"btcusdt@depth@100ms\",\"data\":{\"e\":\"depthUpdate\",\"E\":1784431332550,\"s\":\"BTCUSDT\",\"U\":3244451605,\"u\":3244451606,\"b\":[[\"64641.30000000\",\"0.00000000\"],[\"64637.41000000\",\"0.02839000\"]],\"a\":[[\"64662.75000000\",\"0.02961000\"],[\"64665.14000000\",\"0.00000000\"]]}}"}
{"mode":"v11-raw-disruptor","partitions":4,"sequenceNumber":230,"routingSymbol":"BNBUSDT","localReceivedEpochMillis":1784431332640,"rawPayload":"{\"stream\":\"bnbusdt@depth@100ms\",\"data\":{\"e\":\"depthUpdate\",\"E\":1784431332650,\"s\":\"BNBUSDT\",\"U\":1236336115,\"u\":1236336115,\"b\":[[\"567.75000000\",\"0.00000000\"],[\"567.74000000\",\"0.00400000\"]],\"a\":[]}}"}
{"mode":"v11-raw-disruptor","partitions":4,"sequenceNumber":231,"routingSymbol":"SOLUSDT","localReceivedEpochMillis":1784431332840,"rawPayload":"{\"stream\":\"solusdt@depth@100ms\",\"data\":{\"e\":\"depthUpdate\",\"E\":1784431332851,\"s\":\"SOLUSDT\",\"U\":1609591912,\"u\":1609591913,\"b\":[[\"75.81000000\",\"53.60000000\"]],\"a\":[[\"75.85000000\",\"55.40800000\"]]}}"}
{"mode":"v11-raw-disruptor","partitions":4,"sequenceNumber":232,"routingSymbol":"XRPUSDT","localReceivedEpochMillis":1784431333141,"rawPayload":"{\"stream\":\"xrpusdt@depth@100ms\",\"data\":{\"e\":\"depthUpdate\",\"E\":1784431333151,\"s\":\"XRPUSDT\",\"U\":752712370,\"u\":752712373,\"b\":[[\"1.09290000\",\"2104.10000000\"],[\"1.09280000\",\"2074.70000000\"]],\"a\":[[\"1.09390000\",\"959.30000000\"],[\"1.09400000\",\"673.40000000\"]]}}"}
{"mode":"v11-raw-disruptor","partitions":4,"sequenceNumber":233,"routingSymbol":"SOLUSDT","localReceivedEpochMillis":1784431333340,"rawPayload":"{\"stream\":\"solusdt@depth@100ms\",\"data\":{\"e\":\"depthUpdate\",\"E\":1784431333351,\"s\":\"SOLUSDT\",\"U\":1609591914,\"u\":1609591923,\"b\":[[\"75.82000000\",\"33.79900000\"],[\"75.81000000\",\"39.82100000\"]],\"a\":[[\"75.86000000\",\"0.00000000\"],[\"75.87000000\",\"33.13500000\"],[\"75.90000000\",\"51.18100000\"],[\"75.91000000\",\"0.00000000\"],[\"75.92000000\",\"65.90800000\"]]}}"}
{"mode":"v11-raw-disruptor","partitions":4,"sequenceNumber":234,"routingSymbol":"ETHUSDT","localReceivedEpochMillis":1784431333341,"rawPayload":"{\"stream\":\"ethusdt@depth@100ms\",\"data\":{\"e\":\"depthUpdate\",\"E\":1784431333351,\"s\":\"ETHUSDT\",\"U\":2806198153,\"u\":2806198166,\"b\":[[\"1863.79000000\",\"1.34220000\"],[\"1863.77000000\",\"0.75000000\"],[\"1863.62000000\",\"0.00000000\"],[\"1863.56000000\",\"0.00000000\"],[\"1863.47000000\",\"0.00000000\"],[\"1863.39000000\",\"0.00000000\"],[\"1863.20000000\",\"1.37920000\"],[\"1863.01000000\",\"1.63970000\"]],\"a\":[[\"1864.08000000\",\"0.00000000\"],[\"1864.13000000\",\"0.91950000\"],[\"1864.37000000\",\"1.34180000\"],[\"1865.10000000\",\"0.00000000\"]]}}"}
{"mode":"v11-raw-disruptor","partitions":4,"sequenceNumber":235,"routingSymbol":"BTCUSDT","localReceivedEpochMillis":1784431333341,"rawPayload":"{\"stream\":\"btcusdt@depth@100ms\",\"data\":{\"e\":\"depthUpdate\",\"E\":1784431333351,\"s\":\"BTCUSDT\",\"U\":3244451607,\"u\":3244451608,\"b\":[[\"64632.05000000\",\"0.03095000\"],[\"64630.42000000\",\"0.00000000\"]],\"a\":[]}}"}
{"mode":"v11-raw-disruptor","partitions":4,"sequenceNumber":236,"routingSymbol":"BNBUSDT","localReceivedEpochMillis":1784431333441,"rawPayload":"{\"stream\":\"bnbusdt@depth@100ms\",\"data\":{\"e\":\"depthUpdate\",\"E\":1784431333451,\"s\":\"BNBUSDT\",\"U\":1236336116,\"u\":1236336119,\"b\":[[\"569.06000000\",\"0.97200000\"],[\"569.02000000\",\"0.00000000\"]],\"a\":[[\"569.43000000\",\"0.00000000\"],[\"569.47000000\",\"0.97800000\"]]}}"}
{"mode":"v11-raw-disruptor","partitions":4,"sequenceNumber":237,"routingSymbol":"BTCUSDT","localReceivedEpochMillis":1784431333441,"rawPayload":"{\"stream\":\"btcusdt@depth@100ms\",\"data\":{\"e\":\"depthUpdate\",\"E\":1784431333451,\"s\":\"BTCUSDT\",\"U\":3244451609,\"u\":3244451616,\"b\":[[\"64636.91000000\",\"0.04000000\"],[\"64636.54000000\",\"0.03095000\"],[\"64634.16000000\",\"0.00000000\"],[\"64633.01000000\",\"0.00000000\"],[\"64632.05000000\",\"0.00000000\"]],\"a\":[[\"64650.72000000\",\"0.00000000\"],[\"64656.89000000\",\"0.03869000\"]]}}"}
{"mode":"v11-raw-disruptor","partitions":4,"sequenceNumber":238,"routingSymbol":"SOLUSDT","localReceivedEpochMillis":1784431333441,"rawPayload":"{\"stream\":\"solusdt@depth@100ms\",\"data\":{\"e\":\"depthUpdate\",\"E\":1784431333451,\"s\":\"SOLUSDT\",\"U\":1609591924,\"u\":1609591944,\"b\":[[\"75.83000000\",\"0.00000000\"],[\"75.82000000\",\"40.08700000\"],[\"75.81000000\",\"37.04900000\"],[\"75.80000000\",\"0.00000000\"]],\"a\":[[\"75.85000000\",\"40.13400000\"],[\"75.86000000\",\"16.62100000\"],[\"75.87000000\",\"33.46000000\"],[\"75.88000000\",\"0.00000000\"],[\"75.89000000\",\"39.65600000\"],[\"75.98000000\",\"292.59700000\"]]}}"}
{"mode":"v11-raw-disruptor","partitions":4,"sequenceNumber":239,"routingSymbol":"ETHUSDT","localReceivedEpochMillis":1784431333441,"rawPayload":"{\"stream\":\"ethusdt@depth@100ms\",\"data\":{\"e\":\"depthUpdate\",\"E\":1784431333451,\"s\":\"ETHUSDT\",\"U\":2806198167,\"u\":2806198190,\"b\":[[\"1863.91000000\",\"1.18530000\"],[\"1863.82000000\",\"0.00000000\"],[\"1863.79000000\",\"0.00000000\"],[\"1863.73000000\",\"0.00000000\"],[\"1863.72000000\",\"0.71040000\"],[\"1863.63000000\",\"0.13950000\"],[\"1863.62000000\",\"0.00000000\"],[\"1863.55000000\",\"0.00000000\"],[\"1863.33000000\",\"1.48110000\"],[\"1863.24000000\",\"0.00000000\"],[\"1862.52000000\",\"1.84060000\"],[\"1862.14000000\",\"0.00000000\"]],\"a\":[[\"1864.13000000\",\"0.00000000\"],[\"1864.21000000\",\"0.00000000\"],[\"1864.27000000\",\"0.00000000\"],[\"1864.29000000\",\"0.13940000\"],[\"1864.30000000\",\"0.00000000\"],[\"1864.32000000\",\"0.00000000\"],[\"1864.36000000\",\"0.68080000\"],[\"1864.37000000\",\"0.00000000\"],[\"1864.39000000\",\"0.00000000\"],[\"1864.48000000\",\"1.13070000\"],[\"1864.51000000\",\"0.00000000\"],[\"1864.59000000\",\"1.47960000\"]]}}"}
{"mode":"v11-raw-disruptor","partitions":4,"sequenceNumber":240,"routingSymbol":"BNBUSDT","localReceivedEpochMillis":1784431333541,"rawPayload":"{\"stream\":\"bnbusdt@depth@100ms\",\"data\":{\"e\":\"depthUpdate\",\"E\":1784431333551,\"s\":\"BNBUSDT\",\"U\":1236336120,\"u\":1236336125,\"b\":[[\"569.06000000\",\"0.00000000\"],[\"569.01000000\",\"0.91000000\"]],\"a\":[[\"569.34000000\",\"1.59500000\"],[\"569.36000000\",\"0.87800000\"],[\"569.42000000\",\"0.93000000\"],[\"569.47000000\",\"0.00000000\"]]}}"}
{"mode":"v11-raw-disruptor","partitions":4,"sequenceNumber":241,"routingSymbol":"BTCUSDT","localReceivedEpochMillis":1784431333541,"rawPayload":"{\"stream\":\"btcusdt@depth@100ms\",\"data\":{\"e\":\"depthUpdate\",\"E\":1784431333551,\"s\":\"BTCUSDT\",\"U\":3244451617,\"u\":3244451618,\"b\":[[\"64634.25000000\",\"0.03870000\"],[\"64628.68000000\",\"0.00000000\"]],\"a\":[]}}"}
{"mode":"v11-raw-disruptor","partitions":4,"sequenceNumber":242,"routingSymbol":"SOLUSDT","localReceivedEpochMillis":1784431333542,"rawPayload":"{\"stream\":\"solusdt@depth@100ms\",\"data\":{\"e\":\"depthUpdate\",\"E\":1784431333551,\"s\":\"SOLUSDT\",\"U\":1609591945,\"u\":1609591990,\"b\":[[\"75.84000000\",\"13.83300000\"],[\"75.83000000\",\"9.08300000\"],[\"75.82000000\",\"19.28600000\"],[\"75.81000000\",\"0.06600000\"],[\"75.80000000\",\"49.58700000\"],[\"75.79000000\",\"32.36000000\"],[\"75.78000000\",\"19.28400000\"],[\"75.72000000\",\"0.00000000\"]],\"a\":[[\"75.85000000\",\"0.55600000\"],[\"75.86000000\",\"36.58600000\"],[\"75.87000000\",\"19.05000000\"],[\"75.88000000\",\"11.23500000\"],[\"75.89000000\",\"3.28300000\"],[\"75.90000000\",\"65.28800000\"],[\"75.91000000\",\"36.36300000\"],[\"75.93000000\",\"0.00000000\"],[\"75.94000000\",\"13.18900000\"],[\"75.95000000\",\"118.91800000\"],[\"75.98000000\",\"272.46700000\"],[\"76.10000000\",\"337.40800000\"]]}}"}
{"mode":"v11-raw-disruptor","partitions":4,"sequenceNumber":243,"routingSymbol":"ETHUSDT","localReceivedEpochMillis":1784431333542,"rawPayload":"{\"stream\":\"ethusdt@depth@100ms\",\"data\":{\"e\":\"depthUpdate\",\"E\":1784431333551,\"s\":\"ETHUSDT\",\"U\":2806198191,\"u\":2806198211,\"b\":[[\"1863.88000000\",\"0.76030000\"],[\"1863.86000000\",\"0.65250000\"],[\"1863.77000000\",\"0.75000000\"],[\"1863.74000000\",\"0.13950000\"],[\"1863.72000000\",\"0.02960000\"],[\"1863.63000000\",\"0.00000000\"],[\"1863.44000000\",\"1.48040000\"],[\"1863.41000000\",\"0.97760000\"],[\"1863.33000000\",\"0.00000000\"],[\"1863.20000000\",\"0.00000000\"],[\"1856.21000000\",\"0.00000000\"]],\"a\":[[\"1864.28000000\",\"0.00000000\"],[\"1864.29000000\",\"0.00000000\"],[\"1864.36000000\",\"0.00000000\"],[\"1864.40000000\",\"0.13940000\"],[\"1864.48000000\",\"1.78250000\"],[\"1864.59000000\",\"0.00000000\"],[\"1864.64000000\",\"0.00000000\"],[\"1864.70000000\",\"1.48010000\"],[\"1864.73000000\",\"0.97360000\"],[\"1864.75000000\",\"0.97760000\"],[\"1865.39000000\",\"0.00000000\"],[\"1865.48000000\",\"0.00000000\"],[\"1865.52000000\",\"0.00000000\"],[\"1865.75000000\",\"9.53530000\"]]}}"}
{"mode":"v11-raw-disruptor","partitions":4,"sequenceNumber":244,"routingSymbol":"XRPUSDT","localReceivedEpochMillis":1784431333544,"rawPayload":"{\"stream\":\"xrpusdt@depth@100ms\",\"data\":{\"e\":\"depthUpdate\",\"E\":1784431333551,\"s\":\"XRPUSDT\",\"U\":752712374,\"u\":752712403,\"b\":[[\"1.09350000\",\"960.30000000\"],[\"1.09340000\",\"45.20000000\"],[\"1.09330000\",\"154.00000000\"],[\"1.09320000\",\"5070.20000000\"],[\"1.09310000\",\"2074.70000000\"],[\"1.09300000\",\"190.00000000\"],[\"1.09290000\",\"2074.70000000\"],[\"1.09280000\",\"4659.80000000\"],[\"1.09270000\",\"0.00000000\"],[\"1.09260000\",\"0.00000000\"],[\"1.08870000\",\"0.00000000\"]],\"a\":[[\"1.09360000\",\"0.00000000\"],[\"1.09370000\",\"0.00000000\"],[\"1.09380000\",\"1306.10000000\"],[\"1.09390000\",\"2524.70000000\"],[\"1.09400000\",\"644.00000000\"],[\"1.09410000\",\"974.90000000\"],[\"1.09420000\",\"2074.70000000\"],[\"1.09430000\",\"2552.00000000\"],[\"1.09450000\",\"2134.50000000\"],[\"1.09480000\",\"0.00000000\"],[\"1.09500000\",\"6895.20000000\"]]}}"}
{"mode":"v11-raw-disruptor","partitions":4,"sequenceNumber":245,"routingSymbol":"BNBUSDT","localReceivedEpochMillis":1784431333640,"rawPayload":"{\"stream\":\"bnbusdt@depth@100ms\",\"data\":{\"e\":\"depthUpdate\",\"E\":1784431333651,\"s\":\"BNBUSDT\",\"U\":1236336126,\"u\":1236336137,\"b\":[[\"569.14000000\",\"0.00000000\"],[\"569.08000000\",\"0.00000000\"],[\"569.03000000\",\"0.90100000\"],[\"569.01000000\",\"0.00000000\"]],\"a\":[[\"569.42000000\",\"0.00000000\"],[\"569.43000000\",\"0.96900000\"],[\"569.49000000\",\"0.00000000\"],[\"569.54000000\",\"0.00000000\"]]}}"}
{"mode":"v11-raw-disruptor","partitions":4,"sequenceNumber":246,"routingSymbol":"SOLUSDT","localReceivedEpochMillis":1784431333640,"rawPayload":"{\"stream\":\"solusdt@depth@100ms\",\"data\":{\"e\":\"depthUpdate\",\"E\":1784431333651,\"s\":\"SOLUSDT\",\"U\":1609591991,\"u\":1609591997,\"b\":[[\"75.83000000\",\"5.65500000\"],[\"75.82000000\",\"22.71400000\"],[\"75.74000000\",\"107.40600000\"]],\"a\":[[\"75.85000000\",\"0.00000000\"],[\"75.87000000\",\"3.42600000\"],[\"75.88000000\",\"26.85900000\"],[\"75.90000000\",\"101.65300000\"],[\"75.91000000\",\"0.00000000\"],[\"75.96000000\",\"0.00000000\"]]}}"}
{"mode":"v11-raw-disruptor","partitions":4,"sequenceNumber":247,"routingSymbol":"ETHUSDT","localReceivedEpochMillis":1784431333640,"rawPayload":"{\"stream\":\"ethusdt@depth@100ms\",\"data\":{\"e\":\"depthUpdate\",\"E\":1784431333651,\"s\":\"ETHUSDT\",\"U\":2806198212,\"u\":2806198219,\"b\":[[\"1864.08000000\",\"1.34200000\"],[\"1864.05000000\",\"0.77900000\"],[\"1863.88000000\",\"0.00000000\"],[\"1863.72000000\",\"0.00000000\"],[\"1856.48000000\",\"0.34400000\"]],\"a\":[[\"1864.52000000\",\"0.00000000\"],[\"1871.61000000\",\"0.00000000\"]]}}"}
{"mode":"v11-raw-disruptor","partitions":4,"sequenceNumber":248,"routingSymbol":"XRPUSDT","localReceivedEpochMillis":1784431333640,"rawPayload":"{\"stream\":\"xrpusdt@depth@100ms\",\"data\":{\"e\":\"depthUpdate\",\"E\":1784431333651,\"s\":\"XRPUSDT\",\"U\":752712404,\"u\":752712404,\"b\":[[\"1.08890000\",\"526.60000000\"]],\"a\":[]}}"}
{"mode":"v11-raw-disruptor","partitions":4,"sequenceNumber":249,"routingSymbol":"SOLUSDT","localReceivedEpochMillis":1784431333741,"rawPayload":"{\"stream\":\"solusdt@depth@100ms\",\"data\":{\"e\":\"depthUpdate\",\"E\":1784431333751,\"s\":\"SOLUSDT\",\"U\":1609591998,\"u\":1609591999,\"b\":[[\"75.83000000\",\"39.19900000\"]],\"a\":[]}}"}
{"mode":"v11-raw-disruptor","partitions":4,"sequenceNumber":250,"routingSymbol":"ETHUSDT","localReceivedEpochMillis":1784431333741,"rawPayload":"{\"stream\":\"ethusdt@depth@100ms\",\"data\":{\"e\":\"depthUpdate\",\"E\":1784431333751,\"s\":\"ETHUSDT\",\"U\":2806198220,\"u\":2806198225,\"b\":[[\"1863.86000000\",\"0.00000000\"],[\"1863.85000000\",\"0.02970000\"],[\"1863.79000000\",\"0.65570000\"]],\"a\":[[\"1864.43000000\",\"0.02970000\"],[\"1864.67000000\",\"0.00000000\"],[\"1864.83000000\",\"0.05880000\"]]}}"}
{"mode":"v11-raw-disruptor","partitions":4,"sequenceNumber":251,"routingSymbol":"BTCUSDT","localReceivedEpochMillis":1784431333741,"rawPayload":"{\"stream\":\"btcusdt@depth@100ms\",\"data\":{\"e\":\"depthUpdate\",\"E\":1784431333751,\"s\":\"BTCUSDT\",\"U\":3244451619,\"u\":3244451619,\"b\":[],\"a\":[[\"80837.82000000\",\"0.00015000\"]]}}"}
{"mode":"v11-raw-disruptor","partitions":4,"sequenceNumber":252,"routingSymbol":"XRPUSDT","localReceivedEpochMillis":1784431333741,"rawPayload":"{\"stream\":\"xrpusdt@depth@100ms\",\"data\":{\"e\":\"depthUpdate\",\"E\":1784431333751,\"s\":\"XRPUSDT\",\"U\":752712405,\"u\":752712409,\"b\":[[\"1.09320000\",\"5040.30000000\"],[\"1.09310000\",\"2104.80000000\"]],\"a\":[[\"1.09370000\",\"45.20000000\"],[\"1.09420000\",\"2104.70000000\"],[\"1.09430000\",\"2522.10000000\"]]}}"}
{"mode":"v11-raw-disruptor","partitions":4,"sequenceNumber":253,"routingSymbol":"SOLUSDT","localReceivedEpochMillis":1784431333839,"rawPayload":"{\"stream\":\"solusdt@depth@100ms\",\"data\":{\"e\":\"depthUpdate\",\"E\":1784431333851,\"s\":\"SOLUSDT\",\"U\":1609592000,\"u\":1609592002,\"b\":[[\"75.52000000\",\"100.65000000\"]],\"a\":[[\"75.86000000\",\"37.13900000\"],[\"75.97000000\",\"291.79600000\"]]}}"}
{"mode":"v11-raw-disruptor","partitions":4,"sequenceNumber":254,"routingSymbol":"ETHUSDT","localReceivedEpochMillis":1784431333841,"rawPayload":"{\"stream\":\"ethusdt@depth@100ms\",\"data\":{\"e\":\"depthUpdate\",\"E\":1784431333851,\"s\":\"ETHUSDT\",\"U\":2806198226,\"u\":2806198227,\"b\":[],\"a\":[[\"1864.73000000\",\"0.00000000\"],[\"1864.83000000\",\"1.03240000\"],[\"1871.47000000\",\"0.00000000\"]]}}"}
{"mode":"v11-raw-disruptor","partitions":4,"sequenceNumber":255,"routingSymbol":"BTCUSDT","localReceivedEpochMillis":1784431333841,"rawPayload":"{\"stream\":\"btcusdt@depth@100ms\",\"data\":{\"e\":\"depthUpdate\",\"E\":1784431333851,\"s\":\"BTCUSDT\",\"U\":3244451620,\"u\":3244451627,\"b\":[[\"64583.55000000\",\"0.00000000\"],[\"64580.42000000\",\"0.05890000\"],[\"64544.76000000\",\"0.00000000\"],[\"64541.63000000\",\"0.08405000\"],[\"64505.96000000\",\"0.00000000\"],[\"64502.83000000\",\"0.18547000\"],[\"64428.37000000\",\"0.00000000\"],[\"64425.24000000\",\"0.39755000\"]],\"a\":[[\"64735.55000000\",\"0.05593000\"],[\"64738.69000000\",\"0.00000000\"],[\"64774.35000000\",\"0.08386000\"],[\"64777.48000000\",\"0.00000000\"],[\"64813.14000000\",\"0.16778000\"],[\"64816.28000000\",\"0.00000000\"],[\"64890.73000000\",\"0.41507000\"],[\"64893.87000000\",\"0.00000000\"]]}}"}
{"mode":"v11-raw-disruptor","partitions":4,"sequenceNumber":256,"routingSymbol":"SOLUSDT","localReceivedEpochMillis":1784431333941,"rawPayload":"{\"stream\":\"solusdt@depth@100ms\",\"data\":{\"e\":\"depthUpdate\",\"E\":1784431333951,\"s\":\"SOLUSDT\",\"U\":1609592003,\"u\":1609592005,\"b\":[[\"75.84000000\",\"0.14300000\"]],\"a\":[[\"75.88000000\",\"41.22900000\"],[\"75.90000000\",\"87.54600000\"]]}}"}
{"mode":"v11-raw-disruptor","partitions":4,"sequenceNumber":257,"routingSymbol":"SOLUSDT","localReceivedEpochMillis":1784431334041,"rawPayload":"{\"stream\":\"solusdt@depth@100ms\",\"data\":{\"e\":\"depthUpdate\",\"E\":1784431334051,\"s\":\"SOLUSDT\",\"U\":1609592006,\"u\":1609592013,\"b\":[[\"75.84000000\",\"0.14300000\"],[\"75.83000000\",\"53.84800000\"],[\"75.82000000\",\"52.90900000\"],[\"75.72000000\",\"273.88500000\"]],\"a\":[[\"75.87000000\",\"17.25600000\"],[\"75.88000000\",\"26.85900000\"],[\"76.12000000\",\"333.15600000\"]]}}"}
{"mode":"v11-raw-disruptor","partitions":4,"sequenceNumber":258,"routingSymbol":"ETHUSDT","localReceivedEpochMillis":1784431334041,"rawPayload":"{\"stream\":\"ethusdt@depth@100ms\",\"data\":{\"e\":\"depthUpdate\",\"E\":1784431334051,\"s\":\"ETHUSDT\",\"U\":2806198228,\"u\":2806198235,\"b\":[[\"1863.79000000\",\"0.00000000\"],[\"1863.74000000\",\"0.13950000\"],[\"1863.69000000\",\"0.66090000\"]],\"a\":[[\"1864.42000000\",\"0.65980000\"],[\"1864.48000000\",\"1.13070000\"],[\"1871.62000000\",\"7.16990000\"],[\"1871.78000000\",\"7.94010000\"]]}}"}
{"mode":"v11-raw-disruptor","partitions":4,"sequenceNumber":259,"routingSymbol":"BNBUSDT","localReceivedEpochMillis":1784431334041,"rawPayload":"{\"stream\":\"bnbusdt@depth@100ms\",\"data\":{\"e\":\"depthUpdate\",\"E\":1784431334051,\"s\":\"BNBUSDT\",\"U\":1236336138,\"u\":1236336143,\"b\":[[\"568.64000000\",\"0.00000000\"],[\"568.61000000\",\"3.46000000\"],[\"568.30000000\",\"0.00000000\"],[\"568.27000000\",\"4.85600000\"],[\"567.95000000\",\"0.00000000\"],[\"567.93000000\",\"8.44100000\"],[\"567.61000000\",\"0.00000000\"],[\"567.59000000\",\"19.23400000\"]],\"a\":[[\"569.99000000\",\"3.50000000\"],[\"570.01000000\",\"0.00000000\"],[\"570.33000000\",\"4.82900000\"],[\"570.36000000\",\"0.00000000\"]]}}"}
{"mode":"v11-raw-disruptor","partitions":4,"sequenceNumber":260,"routingSymbol":"BTCUSDT","localReceivedEpochMillis":1784431334041,"rawPayload":"{\"stream\":\"btcusdt@depth@100ms\",\"data\":{\"e\":\"depthUpdate\",\"E\":1784431334051,\"s\":\"BTCUSDT\",\"U\":3244451628,\"u\":3244451628,\"b\":[],\"a\":[[\"80837.82000000\",\"0.00000000\"]]}}"}
{"mode":"v11-raw-disruptor","partitions":4,"sequenceNumber":261,"routingSymbol":"XRPUSDT","localReceivedEpochMillis":1784431334041,"rawPayload":"{\"stream\":\"xrpusdt@depth@100ms\",\"data\":{\"e\":\"depthUpdate\",\"E\":1784431334051,\"s\":\"XRPUSDT\",\"U\":752712410,\"u\":752712413,\"b\":[[\"1.09350000\",\"0.00000000\"],[\"1.09340000\",\"1030.10000000\"]],\"a\":[[\"1.09400000\",\"1653.30000000\"],[\"1.09410000\",\"0.00000000\"]]}}"}
{"mode":"v11-raw-disruptor","partitions":4,"sequenceNumber":262,"routingSymbol":"BNBUSDT","localReceivedEpochMillis":1784431334142,"rawPayload":"{\"stream\":\"bnbusdt@depth@100ms\",\"data\":{\"e\":\"depthUpdate\",\"E\":1784431334151,\"s\":\"BNBUSDT\",\"U\":1236336144,\"u\":1236336145,\"b\":[],\"a\":[[\"569.36000000\",\"0.00000000\"],[\"569.38000000\",\"0.87800000\"]]}}"}
{"mode":"v11-raw-disruptor","partitions":4,"sequenceNumber":263,"routingSymbol":"SOLUSDT","localReceivedEpochMillis":1784431334142,"rawPayload":"{\"stream\":\"solusdt@depth@100ms\",\"data\":{\"e\":\"depthUpdate\",\"E\":1784431334151,\"s\":\"SOLUSDT\",\"U\":1609592014,\"u\":1609592017,\"b\":[],\"a\":[[\"75.85000000\",\"3.11500000\"],[\"75.86000000\",\"33.53200000\"],[\"75.95000000\",\"149.11300000\"],[\"75.97000000\",\"271.66600000\"]]}}"}
{"mode":"v11-raw-disruptor","partitions":4,"sequenceNumber":264,"routingSymbol":"ETHUSDT","localReceivedEpochMillis":1784431334142,"rawPayload":"{\"stream\":\"ethusdt@depth@100ms\",\"data\":{\"e\":\"depthUpdate\",\"E\":1784431334151,\"s\":\"ETHUSDT\",\"U\":2806198236,\"u\":2806198238,\"b\":[],\"a\":[[\"1864.40000000\",\"0.00000000\"],[\"1864.42000000\",\"0.79910000\"],[\"1864.68000000\",\"0.00000000\"]]}}"}
{"mode":"v11-raw-disruptor","partitions":4,"sequenceNumber":265,"routingSymbol":"XRPUSDT","localReceivedEpochMillis":1784431334142,"rawPayload":"{\"stream\":\"xrpusdt@depth@100ms\",\"data\":{\"e\":\"depthUpdate\",\"E\":1784431334151,\"s\":\"XRPUSDT\",\"U\":752712414,\"u\":752712418,\"b\":[[\"1.09350000\",\"2287.70000000\"],[\"1.09330000\",\"391.80000000\"],[\"1.09320000\",\"4802.50000000\"],[\"1.09290000\",\"4599.70000000\"],[\"1.09280000\",\"2134.50000000\"]],\"a\":[[\"1.09390000\",\"2287.10000000\"],[\"1.09400000\",\"1890.90000000\"],[\"1.09430000\",\"0.00000000\"],[\"1.09440000\",\"4272.30000000\"]]}}"}
{"mode":"v11-raw-disruptor","partitions":4,"sequenceNumber":266,"routingSymbol":"ETHUSDT","localReceivedEpochMillis":1784431334242,"rawPayload":"{\"stream\":\"ethusdt@depth@100ms\",\"data\":{\"e\":\"depthUpdate\",\"E\":1784431334251,\"s\":\"ETHUSDT\",\"U\":2806198239,\"u\":2806198239,\"b\":[[\"1855.24000000\",\"0.00000000\"]],\"a\":[]}}"}
{"mode":"v11-raw-disruptor","partitions":4,"sequenceNumber":267,"routingSymbol":"XRPUSDT","localReceivedEpochMillis":1784431334242,"rawPayload":"{\"stream\":\"xrpusdt@depth@100ms\",\"data\":{\"e\":\"depthUpdate\",\"E\":1784431334251,\"s\":\"XRPUSDT\",\"U\":752712419,\"u\":752712429,\"b\":[[\"1.09320000\",\"4833.00000000\"],[\"1.09310000\",\"2074.70000000\"],[\"1.09190000\",\"12808.90000000\"],[\"1.08900000\",\"2.50000000\"]],\"a\":[[\"1.09420000\",\"2074.70000000\"],[\"1.09430000\",\"30.50000000\"],[\"1.09450000\",\"2074.70000000\"],[\"1.09470000\",\"61.00000000\"],[\"1.09530000\",\"0.00000000\"],[\"1.09540000\",\"12650.40000000\"],[\"1.09750000\",\"0.00000000\"]]}}"}
{"mode":"v11-raw-disruptor","partitions":4,"sequenceNumber":268,"routingSymbol":"SOLUSDT","localReceivedEpochMillis":1784431334340,"rawPayload":"{\"stream\":\"solusdt@depth@100ms\",\"data\":{\"e\":\"depthUpdate\",\"E\":1784431334351,\"s\":\"SOLUSDT\",\"U\":1609592018,\"u\":1609592022,\"b\":[[\"75.84000000\",\"13.77600000\"],[\"75.83000000\",\"39.19900000\"]],\"a\":[[\"75.87000000\",\"3.42600000\"],[\"75.89000000\",\"17.63200000\"],[\"76.02000000\",\"274.45800000\"]]}}"}
{"mode":"v11-raw-disruptor","partitions":4,"sequenceNumber":269,"routingSymbol":"BTCUSDT","localReceivedEpochMillis":1784431334340,"rawPayload":"{\"stream\":\"btcusdt@depth@100ms\",\"data\":{\"e\":\"depthUpdate\",\"E\":1784431334351,\"s\":\"BTCUSDT\",\"U\":3244451629,\"u\":3244451629,\"b\":[[\"64520.08000000\",\"0.02014000\"]],\"a\":[]}}"}
{"mode":"v11-raw-disruptor","partitions":4,"sequenceNumber":270,"routingSymbol":"ETHUSDT","localReceivedEpochMillis":1784431334441,"rawPayload":"{\"stream\":\"ethusdt@depth@100ms\",\"data\":{\"e\":\"depthUpdate\",\"E\":1784431334452,\"s\":\"ETHUSDT\",\"U\":2806198240,\"u\":2806198240,\"b\":[[\"1856.72000000\",\"7.17610000\"]],\"a\":[]}}"}
{"mode":"v11-raw-disruptor","partitions":4,"sequenceNumber":271,"routingSymbol":"XRPUSDT","localReceivedEpochMillis":1784431334441,"rawPayload":"{\"stream\":\"xrpusdt@depth@100ms\",\"data\":{\"e\":\"depthUpdate\",\"E\":1784431334452,\"s\":\"XRPUSDT\",\"U\":752712430,\"u\":752712432,\"b\":[[\"1.09340000\",\"984.90000000\"]],\"a\":[[\"1.09370000\",\"0.00000000\"],[\"1.09560000\",\"13837.90000000\"]]}}"}
{"mode":"v11-raw-disruptor","partitions":4,"sequenceNumber":272,"routingSymbol":"BTCUSDT","localReceivedEpochMillis":1784431334641,"rawPayload":"{\"stream\":\"btcusdt@depth@100ms\",\"data\":{\"e\":\"depthUpdate\",\"E\":1784431334652,\"s\":\"BTCUSDT\",\"U\":3244451630,\"u\":3244451631,\"b\":[[\"64642.14000000\",\"0.02839000\"],[\"64637.41000000\",\"0.00000000\"]],\"a\":[[\"64660.47000000\",\"0.02961000\"],[\"64662.75000000\",\"0.00000000\"]]}}"}
{"mode":"v11-raw-disruptor","partitions":4,"sequenceNumber":273,"routingSymbol":"ETHUSDT","localReceivedEpochMillis":1784431334641,"rawPayload":"{\"stream\":\"ethusdt@depth@100ms\",\"data\":{\"e\":\"depthUpdate\",\"E\":1784431334652,\"s\":\"ETHUSDT\",\"U\":2806198241,\"u\":2806198242,\"b\":[[\"1863.77000000\",\"0.00000000\"],[\"1856.65000000\",\"7.89430000\"]],\"a\":[]}}"}
{"mode":"v11-raw-disruptor","partitions":4,"sequenceNumber":274,"routingSymbol":"XRPUSDT","localReceivedEpochMillis":1784431334641,"rawPayload":"{\"stream\":\"xrpusdt@depth@100ms\",\"data\":{\"e\":\"depthUpdate\",\"E\":1784431334652,\"s\":\"XRPUSDT\",\"U\":752712433,\"u\":752712436,\"b\":[[\"1.09330000\",\"1702.30000000\"],[\"1.09320000\",\"3522.50000000\"]],\"a\":[[\"1.09380000\",\"0.00000000\"],[\"1.09390000\",\"3593.20000000\"],[\"1.09400000\",\"1740.90000000\"],[\"1.09420000\",\"2224.70000000\"]]}}"}
{"mode":"v11-raw-disruptor","partitions":4,"sequenceNumber":275,"routingSymbol":"XRPUSDT","localReceivedEpochMillis":1784431334741,"rawPayload":"{\"stream\":\"xrpusdt@depth@100ms\",\"data\":{\"e\":\"depthUpdate\",\"E\":1784431334752,\"s\":\"XRPUSDT\",\"U\":752712437,\"u\":752712438,\"b\":[[\"1.09360000\",\"45.60000000\"]],\"a\":[[\"1.09380000\",\"45.70000000\"]]}}"}
{"mode":"v11-raw-disruptor","partitions":4,"sequenceNumber":276,"routingSymbol":"SOLUSDT","localReceivedEpochMillis":1784431334941,"rawPayload":"{\"stream\":\"solusdt@depth@100ms\",\"data\":{\"e\":\"depthUpdate\",\"E\":1784431334952,\"s\":\"SOLUSDT\",\"U\":1609592023,\"u\":1609592025,\"b\":[],\"a\":[[\"75.90000000\",\"117.74100000\"],[\"75.91000000\",\"30.19500000\"],[\"75.95000000\",\"118.91800000\"]]}}"}
{"mode":"v11-raw-disruptor","partitions":4,"sequenceNumber":277,"routingSymbol":"BNBUSDT","localReceivedEpochMillis":1784431334941,"rawPayload":"{\"stream\":\"bnbusdt@depth@100ms\",\"data\":{\"e\":\"depthUpdate\",\"E\":1784431334952,\"s\":\"BNBUSDT\",\"U\":1236336146,\"u\":1236336146,\"b\":[[\"567.76000000\",\"0.00400000\"],[\"567.74000000\",\"0.00000000\"]],\"a\":[]}}"}
{"mode":"v11-raw-disruptor","partitions":4,"sequenceNumber":278,"routingSymbol":"ETHUSDT","localReceivedEpochMillis":1784431334942,"rawPayload":"{\"stream\":\"ethusdt@depth@100ms\",\"data\":{\"e\":\"depthUpdate\",\"E\":1784431334952,\"s\":\"ETHUSDT\",\"U\":2806198243,\"u\":2806198251,\"b\":[[\"1863.74000000\",\"0.81500000\"],[\"1863.69000000\",\"0.00000000\"],[\"1863.43000000\",\"1.09310000\"],[\"1855.30000000\",\"0.00000000\"]],\"a\":[[\"1871.62000000\",\"0.00000000\"],[\"1871.65000000\",\"7.28990000\"],[\"1872.00000000\",\"8.37900000\"],[\"1873.07000000\",\"0.00000000\"],[\"1873.11000000\",\"0.00000000\"]]}}"}
{"mode":"v11-raw-disruptor","partitions":4,"sequenceNumber":279,"routingSymbol":"ETHUSDT","localReceivedEpochMillis":1784431335141,"rawPayload":"{\"stream\":\"ethusdt@depth@100ms\",\"data\":{\"e\":\"depthUpdate\",\"E\":1784431335152,\"s\":\"ETHUSDT\",\"U\":2806198252,\"u\":2806198255,\"b\":[[\"1863.22000000\",\"1.63970000\"],[\"1856.75000000\",\"7.15780000\"]],\"a\":[[\"1864.53000000\",\"1.34170000\"],[\"1872.11000000\",\"8.68670000\"]]}}"}
{"mode":"v11-raw-disruptor","partitions":4,"sequenceNumber":280,"routingSymbol":"XRPUSDT","localReceivedEpochMillis":1784431335142,"rawPayload":"{\"stream\":\"xrpusdt@depth@100ms\",\"data\":{\"e\":\"depthUpdate\",\"E\":1784431335152,\"s\":\"XRPUSDT\",\"U\":752712439,\"u\":752712444,\"b\":[[\"1.09320000\",\"3492.00000000\"],[\"1.09310000\",\"2105.50000000\"]],\"a\":[[\"1.09420000\",\"2255.50000000\"],[\"1.09430000\",\"0.00000000\"],[\"1.09450000\",\"2136.40000000\"],[\"1.09470000\",\"0.00000000\"]]}}"}
{"mode":"v11-raw-disruptor","partitions":4,"sequenceNumber":281,"routingSymbol":"SOLUSDT","localReceivedEpochMillis":1784431335340,"rawPayload":"{\"stream\":\"solusdt@depth@100ms\",\"data\":{\"e\":\"depthUpdate\",\"E\":1784431335352,\"s\":\"SOLUSDT\",\"U\":1609592026,\"u\":1609592032,\"b\":[[\"75.84000000\",\"0.14300000\"],[\"75.83000000\",\"42.62700000\"],[\"75.82000000\",\"63.18900000\"]],\"a\":[[\"75.87000000\",\"14.35300000\"],[\"75.88000000\",\"30.28500000\"],[\"75.89000000\",\"3.28300000\"],[\"75.90000000\",\"81.37600000\"],[\"75.91000000\",\"66.55800000\"]]}}"}
{"mode":"v11-raw-disruptor","partitions":4,"sequenceNumber":282,"routingSymbol":"ETHUSDT","localReceivedEpochMillis":1784431335340,"rawPayload":"{\"stream\":\"ethusdt@depth@100ms\",\"data\":{\"e\":\"depthUpdate\",\"E\":1784431335352,\"s\":\"ETHUSDT\",\"U\":2806198256,\"u\":2806198277,\"b\":[[\"1864.06000000\",\"1.16170000\"],[\"1863.97000000\",\"0.00000000\"],[\"1863.91000000\",\"0.00000000\"],[\"1863.85000000\",\"0.00000000\"],[\"1863.80000000\",\"0.68290000\"],[\"1863.74000000\",\"0.13950000\"]],\"a\":[[\"1864.42000000\",\"0.00000000\"],[\"1864.43000000\",\"0.00000000\"],[\"1864.44000000\",\"0.13920000\"],[\"1864.47000000\",\"0.68290000\"],[\"1864.48000000\",\"0.00000000\"],[\"1864.54000000\",\"0.00000000\"],[\"1864.63000000\",\"1.11730000\"],[\"1864.83000000\",\"0.97360000\"],[\"1871.65000000\",\"0.00000000\"],[\"1871.66000000\",\"7.25520000\"],[\"1871.73000000\",\"0.00000000\"],[\"1872.33000000\",\"8.88010000\"],[\"1873.00000000\",\"0.00000000\"],[\"1873.02000000\",\"0.00000000\"]]}}"}
{"mode":"v11-raw-disruptor","partitions":4,"sequenceNumber":283,"routingSymbol":"BTCUSDT","localReceivedEpochMillis":1784431335341,"rawPayload":"{\"stream\":\"btcusdt@depth@100ms\",\"data\":{\"e\":\"depthUpdate\",\"E\":1784431335352,\"s\":\"BTCUSDT\",\"U\":3244451632,\"u\":3244451636,\"b\":[[\"64642.97000000\",\"0.02839000\"],[\"64642.14000000\",\"0.00000000\"],[\"64636.54000000\",\"0.00000000\"],[\"64634.28000000\",\"0.03095000\"]],\"a\":[[\"64644.61000000\",\"0.00000000\"],[\"64644.72000000\",\"0.00402000\"],[\"64660.47000000\",\"0.00000000\"],[\"64664.74000000\",\"0.02961000\"]]}}"}
{"mode":"v11-raw-disruptor","partitions":4,"sequenceNumber":284,"routingSymbol":"XRPUSDT","localReceivedEpochMillis":1784431335341,"rawPayload":"{\"stream\":\"xrpusdt@depth@100ms\",\"data\":{\"e\":\"depthUpdate\",\"E\":1784431335352,\"s\":\"XRPUSDT\",\"U\":752712445,\"u\":752712445,\"b\":[[\"1.08750000\",\"522.20000000\"],[\"1.08720000\",\"0.00000000\"]],\"a\":[]}}"}
{"mode":"v11-raw-disruptor","partitions":4,"sequenceNumber":285,"routingSymbol":"ETHUSDT","localReceivedEpochMillis":1784431335441,"rawPayload":"{\"stream\":\"ethusdt@depth@100ms\",\"data\":{\"e\":\"depthUpdate\",\"E\":1784431335452,\"s\":\"ETHUSDT\",\"U\":2806198278,\"u\":2806198281,\"b\":[[\"1864.09000000\",\"0.79440000\"],[\"1864.05000000\",\"0.00000000\"],[\"1863.99000000\",\"0.02960000\"]],\"a\":[[\"1864.57000000\",\"0.02960000\"]]}}"}
{"mode":"v11-raw-disruptor","partitions":4,"sequenceNumber":286,"routingSymbol":"ETHUSDT","localReceivedEpochMillis":1784431335542,"rawPayload":"{\"stream\":\"ethusdt@depth@100ms\",\"data\":{\"e\":\"depthUpdate\",\"E\":1784431335552,\"s\":\"ETHUSDT\",\"U\":2806198282,\"u\":2806198282,\"b\":[],\"a\":[[\"1871.66000000\",\"0.00000000\"]]}}"}
{"mode":"v11-raw-disruptor","partitions":4,"sequenceNumber":287,"routingSymbol":"BTCUSDT","localReceivedEpochMillis":1784431335542,"rawPayload":"{\"stream\":\"btcusdt@depth@100ms\",\"data\":{\"e\":\"depthUpdate\",\"E\":1784431335552,\"s\":\"BTCUSDT\",\"U\":3244451637,\"u\":3244451637,\"b\":[[\"64634.28000000\",\"0.00000000\"]],\"a\":[]}}"}
{"mode":"v11-raw-disruptor","partitions":4,"sequenceNumber":288,"routingSymbol":"XRPUSDT","localReceivedEpochMillis":1784431335542,"rawPayload":"{\"stream\":\"xrpusdt@depth@100ms\",\"data\":{\"e\":\"depthUpdate\",\"E\":1784431335552,\"s\":\"XRPUSDT\",\"U\":752712446,\"u\":752712449,\"b\":[[\"1.09350000\",\"3269.80000000\"],[\"1.09340000\",\"0.00000000\"]],\"a\":[[\"1.09400000\",\"731.60000000\"],[\"1.09410000\",\"971.60000000\"]]}}"}
{"mode":"v11-raw-disruptor","partitions":4,"sequenceNumber":289,"routingSymbol":"SOLUSDT","localReceivedEpochMillis":1784431335642,"rawPayload":"{\"stream\":\"solusdt@depth@100ms\",\"data\":{\"e\":\"depthUpdate\",\"E\":1784431335652,\"s\":\"SOLUSDT\",\"U\":1609592033,\"u\":1609592037,\"b\":[[\"75.83000000\",\"76.10400000\"],[\"75.82000000\",\"30.19500000\"]],\"a\":[[\"75.87000000\",\"0.00000000\"],[\"75.88000000\",\"44.80300000\"]]}}"}
{"mode":"v11-raw-disruptor","partitions":4,"sequenceNumber":290,"routingSymbol":"BTCUSDT","localReceivedEpochMillis":1784431335642,"rawPayload":"{\"stream\":\"btcusdt@depth@100ms\",\"data\":{\"e\":\"depthUpdate\",\"E\":1784431335652,\"s\":\"BTCUSDT\",\"U\":3244451638,\"u\":3244451638,\"b\":[[\"64636.52000000\",\"0.03095000\"]],\"a\":[]}}"}
{"mode":"v11-raw-disruptor","partitions":4,"sequenceNumber":291,"routingSymbol":"ETHUSDT","localReceivedEpochMillis":1784431335642,"rawPayload":"{\"stream\":\"ethusdt@depth@100ms\",\"data\":{\"e\":\"depthUpdate\",\"E\":1784431335652,\"s\":\"ETHUSDT\",\"U\":2806198283,\"u\":2806198290,\"b\":[[\"1864.11000000\",\"1.34200000\"],[\"1864.08000000\",\"0.00000000\"],[\"1863.85000000\",\"0.68850000\"],[\"1863.80000000\",\"0.00000000\"],[\"1855.35000000\",\"0.00000000\"]],\"a\":[[\"1864.53000000\",\"0.00000000\"],[\"1864.71000000\",\"1.34150000\"],[\"1871.74000000\",\"7.21820000\"]]}}"}
{"mode":"v11-raw-disruptor","partitions":4,"sequenceNumber":292,"routingSymbol":"ETHUSDT","localReceivedEpochMillis":1784431335742,"rawPayload":"{\"stream\":\"ethusdt@depth@100ms\",\"data\":{\"e\":\"depthUpdate\",\"E\":1784431335752,\"s\":\"ETHUSDT\",\"U\":2806198291,\"u\":2806198292,\"b\":[[\"1863.43000000\",\"0.00000000\"],[\"1863.14000000\",\"1.09310000\"]],\"a\":[]}}"}
{"mode":"v11-raw-disruptor","partitions":4,"sequenceNumber":293,"routingSymbol":"ETHUSDT","localReceivedEpochMillis":1784431335842,"rawPayload":"{\"stream\":\"ethusdt@depth@100ms\",\"data\":{\"e\":\"depthUpdate\",\"E\":1784431335852,\"s\":\"ETHUSDT\",\"U\":2806198293,\"u\":2806198294,\"b\":[[\"1856.84000000\",\"13.78190000\"]],\"a\":[[\"1873.01000000\",\"9.19690000\"]]}}"}
{"mode":"v11-raw-disruptor","partitions":4,"sequenceNumber":294,"routingSymbol":"XRPUSDT","localReceivedEpochMillis":1784431335842,"rawPayload":"{\"stream\":\"xrpusdt@depth@100ms\",\"data\":{\"e\":\"depthUpdate\",\"E\":1784431335852,\"s\":\"XRPUSDT\",\"U\":752712450,\"u\":752712450,\"b\":[[\"1.09360000\",\"0.00000000\"]],\"a\":[]}}"}
{"mode":"v11-raw-disruptor","partitions":4,"sequenceNumber":295,"routingSymbol":"BNBUSDT","localReceivedEpochMillis":1784431335942,"rawPayload":"{\"stream\":\"bnbusdt@depth@100ms\",\"data\":{\"e\":\"depthUpdate\",\"E\":1784431335952,\"s\":\"BNBUSDT\",\"U\":1236336147,\"u\":1236336150,\"b\":[[\"569.11000000\",\"0.96300000\"],[\"569.03000000\",\"0.00000000\"]],\"a\":[[\"569.43000000\",\"0.00000000\"],[\"569.52000000\",\"0.91300000\"]]}}"}
{"mode":"v11-raw-disruptor","partitions":4,"sequenceNumber":296,"routingSymbol":"ETHUSDT","localReceivedEpochMillis":1784431335942,"rawPayload":"{\"stream\":\"ethusdt@depth@100ms\",\"data\":{\"e\":\"depthUpdate\",\"E\":1784431335953,\"s\":\"ETHUSDT\",\"U\":2806198295,\"u\":2806198295,\"b\":[],\"a\":[[\"1873.07000000\",\"9.19890000\"]]}}"}
{"mode":"v11-raw-disruptor","partitions":4,"sequenceNumber":297,"routingSymbol":"ETHUSDT","localReceivedEpochMillis":1784431336042,"rawPayload":"{\"stream\":\"ethusdt@depth@100ms\",\"data\":{\"e\":\"depthUpdate\",\"E\":1784431336053,\"s\":\"ETHUSDT\",\"U\":2806198296,\"u\":2806198296,\"b\":[],\"a\":[[\"1864.83000000\",\"0.00000000\"],[\"1864.88000000\",\"0.97360000\"]]}}"}
{"mode":"v11-raw-disruptor","partitions":4,"sequenceNumber":298,"routingSymbol":"SOLUSDT","localReceivedEpochMillis":1784431336242,"rawPayload":"{\"stream\":\"solusdt@depth@100ms\",\"data\":{\"e\":\"depthUpdate\",\"E\":1784431336253,\"s\":\"SOLUSDT\",\"U\":1609592038,\"u\":1609592043,\"b\":[],\"a\":[[\"75.86000000\",\"0.55300000\"],[\"75.87000000\",\"32.97500000\"],[\"75.89000000\",\"3.28300000\"],[\"75.90000000\",\"51.18100000\"],[\"75.91000000\",\"36.36300000\"]]}}"}
{"mode":"v11-raw-disruptor","partitions":4,"sequenceNumber":299,"routingSymbol":"ETHUSDT","localReceivedEpochMillis":1784431336243,"rawPayload":"{\"stream\":\"ethusdt@depth@100ms\",\"data\":{\"e\":\"depthUpdate\",\"E\":1784431336253,\"s\":\"ETHUSDT\",\"U\":2806198297,\"u\":2806198322,\"b\":[[\"1864.16000000\",\"1.34190000\"],[\"1864.13000000\",\"1.12770000\"],[\"1864.12000000\",\"0.79440000\"],[\"1864.11000000\",\"0.00000000\"],[\"1864.06000000\",\"0.00000000\"],[\"1863.94000000\",\"0.13890000\"],[\"1863.91000000\",\"0.70030000\"],[\"1863.88000000\",\"0.00000000\"],[\"1863.85000000\",\"0.00000000\"],[\"1863.74000000\",\"0.00000000\"],[\"1863.58000000\",\"1.48100000\"],[\"1863.44000000\",\"0.00000000\"],[\"1863.14000000\",\"0.00000000\"],[\"1862.54000000\",\"9.23460000\"],[\"1862.29000000\",\"0.00000000\"]],\"a\":[[\"1864.44000000\",\"0.00000000\"],[\"1864.47000000\",\"0.00000000\"],[\"1864.54000000\",\"0.00000000\"],[\"1864.60000000\",\"0.13940000\"],[\"1864.63000000\",\"0.00000000\"],[\"1864.70000000\",\"1.15280000\"],[\"1864.71000000\",\"0.00000000\"],[\"1864.84000000\",\"0.00000000\"],[\"1864.87000000\",\"1.34140000\"],[\"1864.90000000\",\"1.47990000\"],[\"1865.53000000\",\"0.00000000\"],[\"1865.75000000\",\"0.31650000\"],[\"1865.94000000\",\"9.21770000\"]]}}"}
{"mode":"v11-raw-disruptor","partitions":4,"sequenceNumber":300,"routingSymbol":"BNBUSDT","localReceivedEpochMillis":1784431336243,"rawPayload":"{\"stream\":\"bnbusdt@depth@100ms\",\"data\":{\"e\":\"depthUpdate\",\"E\":1784431336253,\"s\":\"BNBUSDT\",\"U\":1236336151,\"u\":1236336159,\"b\":[[\"569.11000000\",\"0.00000000\"],[\"569.09000000\",\"2.68400000\"],[\"569.04000000\",\"0.00000000\"],[\"567.77000000\",\"0.00400000\"],[\"567.76000000\",\"0.00000000\"]],\"a\":[[\"569.44000000\",\"0.00000000\"],[\"569.50000000\",\"0.97500000\"],[\"569.52000000\",\"0.00000000\"]]}}"}
{"mode":"v11-raw-disruptor","partitions":4,"sequenceNumber":301,"routingSymbol":"BTCUSDT","localReceivedEpochMillis":1784431336243,"rawPayload":"{\"stream\":\"btcusdt@depth@100ms\",\"data\":{\"e\":\"depthUpdate\",\"E\":1784431336253,\"s\":\"BTCUSDT\",\"U\":3244451639,\"u\":3244451661,\"b\":[[\"64642.28000000\",\"0.03095000\"],[\"64640.21000000\",\"0.03870000\"],[\"64638.63000000\",\"0.00000000\"],[\"64636.52000000\",\"0.00000000\"],[\"64635.58000000\",\"0.00000000\"],[\"64634.25000000\",\"0.00000000\"],[\"64626.00000000\",\"0.04643000\"],[\"64619.10000000\",\"0.00000000\"]],\"a\":[[\"64644.72000000\",\"0.00000000\"],[\"64645.38000000\",\"0.00000000\"],[\"64645.89000000\",\"0.00000000\"],[\"64646.03000000\",\"0.00402000\"],[\"64648.20000000\",\"0.03095000\"],[\"64653.68000000\",\"0.00000000\"],[\"64654.88000000\",\"0.00000000\"],[\"64656.37000000\",\"0.04268000\"],[\"64656.89000000\",\"0.00000000\"],[\"64660.57000000\",\"0.04643000\"],[\"64661.75000000\",\"0.00000000\"],[\"64662.64000000\",\"0.03868000\"],[\"64663.78000000\",\"0.00000000\"],[\"64666.00000000\",\"0.00159000\"]]}}"}
{"mode":"v11-raw-disruptor","partitions":4,"sequenceNumber":302,"routingSymbol":"XRPUSDT","localReceivedEpochMillis":1784431336243,"rawPayload":"{\"stream\":\"xrpusdt@depth@100ms\",\"data\":{\"e\":\"depthUpdate\",\"E\":1784431336253,\"s\":\"XRPUSDT\",\"U\":752712451,\"u\":752712455,\"b\":[[\"1.09360000\",\"2287.50000000\"],[\"1.09350000\",\"1027.30000000\"]],\"a\":[[\"1.09390000\",\"1306.10000000\"],[\"1.09400000\",\"3018.30000000\"]]}}"}
{"mode":"v11-raw-disruptor","partitions":4,"sequenceNumber":303,"routingSymbol":"BNBUSDT","localReceivedEpochMillis":1784431336341,"rawPayload":"{\"stream\":\"bnbusdt@depth@100ms\",\"data\":{\"e\":\"depthUpdate\",\"E\":1784431336353,\"s\":\"BNBUSDT\",\"U\":1236336160,\"u\":1236336176,\"b\":[[\"569.20000000\",\"1.58600000\"],[\"569.19000000\",\"0.00000000\"],[\"569.15000000\",\"1.75700000\"],[\"569.09000000\",\"0.91800000\"],[\"569.04000000\",\"0.00000000\"]],\"a\":[[\"569.38000000\",\"0.00000000\"],[\"569.39000000\",\"0.00000000\"],[\"569.40000000\",\"1.59500000\"],[\"569.41000000\",\"1.70900000\"],[\"569.45000000\",\"0.10600000\"],[\"569.50000000\",\"0.92400000\"],[\"569.53000000\",\"0.00000000\"],[\"569.59000000\",\"1.75700000\"]]}}"}
{"mode":"v11-raw-disruptor","partitions":4,"sequenceNumber":304,"routingSymbol":"BTCUSDT","localReceivedEpochMillis":1784431336341,"rawPayload":"{\"stream\":\"btcusdt@depth@100ms\",\"data\":{\"e\":\"depthUpdate\",\"E\":1784431336353,\"s\":\"BTCUSDT\",\"U\":3244451662,\"u\":3244451681,\"b\":[[\"64642.34000000\",\"0.04190000\"],[\"64640.58000000\",\"0.03274000\"],[\"64636.91000000\",\"0.00000000\"],[\"64632.51000000\",\"0.03514000\"],[\"64627.63000000\",\"0.00402000\"],[\"64626.00000000\",\"0.00000000\"],[\"64623.27000000\",\"0.00000000\"],[\"64617.29000000\",\"0.04271000\"],[\"64612.92000000\",\"0.00000000\"]],\"a\":[[\"64646.03000000\",\"0.00000000\"],[\"64647.78000000\",\"0.00000000\"],[\"64648.20000000\",\"0.00000000\"],[\"64650.27000000\",\"0.00402000\"],[\"64650.29000000\",\"0.00000000\"],[\"64652.24000000\",\"0.02141000\"],[\"64654.99000000\",\"0.00000000\"],[\"64656.37000000\",\"0.00000000\"],[\"64658.12000000\",\"0.00000000\"],[\"64659.99000000\",\"0.03243000\"],[\"64660.61000000\",\"0.04267000\"],[\"64666.00000000\",\"0.00000000\"],[\"64666.75000000\",\"0.00159000\"],[\"80832.52000000\",\"0.00015000\"]]}}"}
{"mode":"v11-raw-disruptor","partitions":4,"sequenceNumber":305,"routingSymbol":"SOLUSDT","localReceivedEpochMillis":1784431336342,"rawPayload":"{\"stream\":\"solusdt@depth@100ms\",\"data\":{\"e\":\"depthUpdate\",\"E\":1784431336353,\"s\":\"SOLUSDT\",\"U\":1609592044,\"u\":1609592047,\"b\":[[\"75.84000000\",\"33.12900000\"],[\"75.83000000\",\"43.11600000\"]],\"a\":[[\"75.85000000\",\"0.00000000\"],[\"75.86000000\",\"3.87900000\"]]}}"}
{"mode":"v11-raw-disruptor","partitions":4,"sequenceNumber":306,"routingSymbol":"ETHUSDT","localReceivedEpochMillis":1784431336342,"rawPayload":"{\"stream\":\"ethusdt@depth@100ms\",\"data\":{\"e\":\"depthUpdate\",\"E\":1784431336353,\"s\":\"ETHUSDT\",\"U\":2806198323,\"u\":2806198337,\"b\":[[\"1863.96000000\",\"0.00000000\"],[\"1863.91000000\",\"0.00000000\"],[\"1863.61000000\",\"1.05130000\"],[\"1863.41000000\",\"0.00000000\"],[\"1862.24000000\",\"1.75330000\"],[\"1861.49000000\",\"0.00000000\"],[\"1856.48000000\",\"0.00000000\"]],\"a\":[[\"1864.57000000\",\"0.02960000\"],[\"1864.66000000\",\"0.70140000\"],[\"1864.75000000\",\"0.00000000\"],[\"1864.88000000\",\"0.00000000\"],[\"1864.99000000\",\"0.97360000\"],[\"1865.75000000\",\"0.00000000\"],[\"1871.75000000\",\"7.28840000\"]]}}"}
{"mode":"v11-raw-disruptor","partitions":4,"sequenceNumber":307,"routingSymbol":"XRPUSDT","localReceivedEpochMillis":1784431336342,"rawPayload":"{\"stream\":\"xrpusdt@depth@100ms\",\"data\":{\"e\":\"depthUpdate\",\"E\":1784431336353,\"s\":\"XRPUSDT\",\"U\":752712456,\"u\":752712464,\"b\":[[\"1.09350000\",\"1003.30000000\"],[\"1.09340000\",\"0.00000000\"]],\"a\":[[\"1.09400000\",\"2524.30000000\"],[\"1.09410000\",\"0.00000000\"],[\"1.09420000\",\"3194.90000000\"]]}}"}
{"mode":"v11-raw-disruptor","partitions":4,"sequenceNumber":308,"routingSymbol":"BNBUSDT","localReceivedEpochMillis":1784431336442,"rawPayload":"{\"stream\":\"bnbusdt@depth@100ms\",\"data\":{\"e\":\"depthUpdate\",\"E\":1784431336453,\"s\":\"BNBUSDT\",\"U\":1236336177,\"u\":1236336178,\"b\":[[\"567.77000000\",\"0.00000000\"]],\"a\":[[\"569.45000000\",\"0.72500000\"]]}}"}
{"mode":"v11-raw-disruptor","partitions":4,"sequenceNumber":309,"routingSymbol":"ETHUSDT","localReceivedEpochMillis":1784431336442,"rawPayload":"{\"stream\":\"ethusdt@depth@100ms\",\"data\":{\"e\":\"depthUpdate\",\"E\":1784431336453,\"s\":\"ETHUSDT\",\"U\":2806198338,\"u\":2806198349,\"b\":[[\"1864.26000000\",\"0.79440000\"],[\"1864.25000000\",\"0.00000000\"],[\"1864.17000000\",\"0.00000000\"],[\"1864.16000000\",\"0.00000000\"],[\"1864.12000000\",\"0.00000000\"],[\"1864.03000000\",\"0.70140000\"],[\"1863.99000000\",\"0.00000000\"],[\"1863.90000000\",\"1.63970000\"],[\"1863.01000000\",\"0.00000000\"]],\"a\":[[\"1864.57000000\",\"0.00000000\"]]}}"}
{"mode":"v11-raw-disruptor","partitions":4,"sequenceNumber":310,"routingSymbol":"XRPUSDT","localReceivedEpochMillis":1784431336442,"rawPayload":"{\"stream\":\"xrpusdt@depth@100ms\",\"data\":{\"e\":\"depthUpdate\",\"E\":1784431336453,\"s\":\"XRPUSDT\",\"U\":752712465,\"u\":752712468,\"b\":[[\"1.09320000\",\"3524.40000000\"],[\"1.09310000\",\"2074.70000000\"]],\"a\":[[\"1.09380000\",\"0.00000000\"],[\"1.09430000\",\"494.00000000\"]]}}"}
{"mode":"v11-raw-disruptor","partitions":4,"sequenceNumber":311,"routingSymbol":"ETHUSDT","localReceivedEpochMillis":1784431336543,"rawPayload":"{\"stream\":\"ethusdt@depth@100ms\",\"data\":{\"e\":\"depthUpdate\",\"E\":1784431336553,\"s\":\"ETHUSDT\",\"U\":2806198350,\"u\":2806198353,\"b\":[[\"1856.74000000\",\"0.40750000\"]],\"a\":[[\"1864.64000000\",\"0.02940000\"],[\"1866.32000000\",\"0.30790000\"],[\"1871.75000000\",\"0.00000000\"]]}}"}
{"mode":"v11-raw-disruptor","partitions":4,"sequenceNumber":312,"routingSymbol":"XRPUSDT","localReceivedEpochMillis":1784431336543,"rawPayload":"{\"stream\":\"xrpusdt@depth@100ms\",\"data\":{\"e\":\"depthUpdate\",\"E\":1784431336553,\"s\":\"XRPUSDT\",\"U\":752712469,\"u\":752712469,\"b\":[[\"1.09350000\",\"958.10000000\"]],\"a\":[]}}"}
{"mode":"v11-raw-disruptor","partitions":4,"sequenceNumber":313,"routingSymbol":"SOLUSDT","localReceivedEpochMillis":1784431336642,"rawPayload":"{\"stream\":\"solusdt@depth@100ms\",\"data\":{\"e\":\"depthUpdate\",\"E\":1784431336653,\"s\":\"SOLUSDT\",\"U\":1609592048,\"u\":1609592049,\"b\":[[\"75.84000000\",\"36.48400000\"],[\"75.83000000\",\"37.46100000\"]],\"a\":[]}}"}
{"mode":"v11-raw-disruptor","partitions":4,"sequenceNumber":314,"routingSymbol":"ETHUSDT","localReceivedEpochMillis":1784431336642,"rawPayload":"{\"stream\":\"ethusdt@depth@100ms\",\"data\":{\"e\":\"depthUpdate\",\"E\":1784431336653,\"s\":\"ETHUSDT\",\"U\":2806198354,\"u\":2806198356,\"b\":[[\"1864.06000000\",\"0.02980000\"]],\"a\":[[\"1871.74000000\",\"0.00000000\"],[\"1873.07000000\",\"0.00000000\"]]}}"}
{"mode":"v11-raw-disruptor","partitions":4,"sequenceNumber":315,"routingSymbol":"XRPUSDT","localReceivedEpochMillis":1784431336642,"rawPayload":"{\"stream\":\"xrpusdt@depth@100ms\",\"data\":{\"e\":\"depthUpdate\",\"E\":1784431336653,\"s\":\"XRPUSDT\",\"U\":752712470,\"u\":752712475,\"b\":[[\"1.09340000\",\"237.70000000\"],[\"1.09330000\",\"1464.50000000\"],[\"1.09300000\",\"2715.00000000\"],[\"1.09290000\",\"2074.70000000\"],[\"1.09230000\",\"11491.90000000\"],[\"1.09210000\",\"0.00000000\"]],\"a\":[[\"1.09400000\",\"2286.70000000\"],[\"1.09410000\",\"237.60000000\"],[\"1.09440000\",\"1750.60000000\"],[\"1.09450000\",\"4658.30000000\"],[\"1.09500000\",\"0.00000000\"],[\"1.09520000\",\"13810.10000000\"]]}}"}
{"mode":"v11-raw-disruptor","partitions":4,"sequenceNumber":316,"routingSymbol":"ETHUSDT","localReceivedEpochMillis":1784431336742,"rawPayload":"{\"stream\":\"ethusdt@depth@100ms\",\"data\":{\"e\":\"depthUpdate\",\"E\":1784431336753,\"s\":\"ETHUSDT\",\"U\":2806198357,\"u\":2806198357,\"b\":[],\"a\":[[\"1871.78000000\",\"0.00000000\"]]}}"}
{"mode":"v11-raw-disruptor","partitions":4,"sequenceNumber":317,"routingSymbol":"BTCUSDT","localReceivedEpochMillis":1784431336743,"rawPayload":"{\"stream\":\"btcusdt@depth@100ms\",\"data\":{\"e\":\"depthUpdate\",\"E\":1784431336753,\"s\":\"BTCUSDT\",\"U\":3244451682,\"u\":3244451683,\"b\":[],\"a\":[[\"64650.45000000\",\"0.01823000\"],[\"64652.24000000\",\"0.00000000\"]]}}"}
{"mode":"v11-raw-disruptor","partitions":4,"sequenceNumber":318,"routingSymbol":"ETHUSDT","localReceivedEpochMillis":1784431336843,"rawPayload":"{\"stream\":\"ethusdt@depth@100ms\",\"data\":{\"e\":\"depthUpdate\",\"E\":1784431336853,\"s\":\"ETHUSDT\",\"U\":2806198358,\"u\":2806198360,\"b\":[[\"1856.91000000\",\"7.26560000\"],[\"1855.41000000\",\"0.00000000\"]],\"a\":[[\"1873.07000000\",\"9.22400000\"]]}}"}
{"mode":"v11-raw-disruptor","partitions":4,"sequenceNumber":319,"routingSymbol":"BTCUSDT","localReceivedEpochMillis":1784431336843,"rawPayload":"{\"stream\":\"btcusdt@depth@100ms\",\"data\":{\"e\":\"depthUpdate\",\"E\":1784431336853,\"s\":\"BTCUSDT\",\"U\":3244451684,\"u\":3244451685,\"b\":[],\"a\":[[\"64648.80000000\",\"0.01829000\"],[\"64650.45000000\",\"0.00000000\"]]}}"}
{"mode":"v11-raw-disruptor","partitions":4,"sequenceNumber":320,"routingSymbol":"XRPUSDT","localReceivedEpochMillis":1784431336843,"rawPayload":"{\"stream\":\"xrpusdt@depth@100ms\",\"data\":{\"e\":\"depthUpdate\",\"E\":1784431336853,\"s\":\"XRPUSDT\",\"U\":752712476,\"u\":752712481,\"b\":[[\"1.09360000\",\"2333.20000000\"],[\"1.09350000\",\"960.60000000\"]],\"a\":[[\"1.09390000\",\"1351.80000000\"],[\"1.09410000\",\"1216.70000000\"],[\"1.09420000\",\"2255.50000000\"]]}}"}
{"mode":"v11-raw-disruptor","partitions":4,"sequenceNumber":321,"routingSymbol":"SOLUSDT","localReceivedEpochMillis":1784431336942,"rawPayload":"{\"stream\":\"solusdt@depth@100ms\",\"data\":{\"e\":\"depthUpdate\",\"E\":1784431336953,\"s\":\"SOLUSDT\",\"U\":1609592050,\"u\":1609592050,\"b\":[],\"a\":[[\"75.94000000\",\"43.38400000\"]]}}"}
{"mode":"v11-raw-disruptor","partitions":4,"sequenceNumber":322,"routingSymbol":"ETHUSDT","localReceivedEpochMillis":1784431336942,"rawPayload":"{\"stream\":\"ethusdt@depth@100ms\",\"data\":{\"e\":\"depthUpdate\",\"E\":1784431336953,\"s\":\"ETHUSDT\",\"U\":2806198361,\"u\":2806198361,\"b\":[[\"1863.52000000\",\"1.09310000\"]],\"a\":[]}}"}
{"mode":"v11-raw-disruptor","partitions":4,"sequenceNumber":323,"routingSymbol":"ETHUSDT","localReceivedEpochMillis":1784431337042,"rawPayload":"{\"stream\":\"ethusdt@depth@100ms\",\"data\":{\"e\":\"depthUpdate\",\"E\":1784431337053,\"s\":\"ETHUSDT\",\"U\":2806198362,\"u\":2806198362,\"b\":[],\"a\":[[\"1873.12000000\",\"9.13110000\"]]}}"}
{"mode":"v11-raw-disruptor","partitions":4,"sequenceNumber":324,"routingSymbol":"SOLUSDT","localReceivedEpochMillis":1784431337142,"rawPayload":"{\"stream\":\"solusdt@depth@100ms\",\"data\":{\"e\":\"depthUpdate\",\"E\":1784431337153,\"s\":\"SOLUSDT\",\"U\":1609592051,\"u\":1609592055,\"b\":[[\"75.85000000\",\"13.93100000\"],[\"75.83000000\",\"23.27000000\"]],\"a\":[[\"75.88000000\",\"30.28500000\"],[\"75.90000000\",\"64.84900000\"],[\"75.93000000\",\"30.19500000\"]]}}"}
{"mode":"v11-raw-disruptor","partitions":4,"sequenceNumber":325,"routingSymbol":"ETHUSDT","localReceivedEpochMillis":1784431337143,"rawPayload":"{\"stream\":\"ethusdt@depth@100ms\",\"data\":{\"e\":\"depthUpdate\",\"E\":1784431337153,\"s\":\"ETHUSDT\",\"U\":2806198363,\"u\":2806198363,\"b\":[[\"1864.27000000\",\"1.34190000\"]],\"a\":[]}}"}
{"mode":"v11-raw-disruptor","partitions":4,"sequenceNumber":326,"routingSymbol":"BTCUSDT","localReceivedEpochMillis":1784431337143,"rawPayload":"{\"stream\":\"btcusdt@depth@100ms\",\"data\":{\"e\":\"depthUpdate\",\"E\":1784431337153,\"s\":\"BTCUSDT\",\"U\":3244451686,\"u\":3244451687,\"b\":[],\"a\":[[\"64648.80000000\",\"0.00000000\"],[\"64650.83000000\",\"0.01843000\"]]}}"}
{"mode":"v11-raw-disruptor","partitions":4,"sequenceNumber":327,"routingSymbol":"ETHUSDT","localReceivedEpochMillis":1784431337242,"rawPayload":"{\"stream\":\"ethusdt@depth@100ms\",\"data\":{\"e\":\"depthUpdate\",\"E\":1784431337253,\"s\":\"ETHUSDT\",\"U\":2806198364,\"u\":2806198364,\"b\":[],\"a\":[[\"1873.17000000\",\"9.25680000\"]]}}"}
{"mode":"v11-raw-disruptor","partitions":4,"sequenceNumber":328,"routingSymbol":"BNBUSDT","localReceivedEpochMillis":1784431337343,"rawPayload":"{\"stream\":\"bnbusdt@depth@100ms\",\"data\":{\"e\":\"depthUpdate\",\"E\":1784431337353,\"s\":\"BNBUSDT\",\"U\":1236336179,\"u\":1236336179,\"b\":[[\"567.78000000\",\"0.00700000\"]],\"a\":[]}}"}
{"mode":"v11-raw-disruptor","partitions":4,"sequenceNumber":329,"routingSymbol":"ETHUSDT","localReceivedEpochMillis":1784431337343,"rawPayload":"{\"stream\":\"ethusdt@depth@100ms\",\"data\":{\"e\":\"depthUpdate\",\"E\":1784431337353,\"s\":\"ETHUSDT\",\"U\":2806198365,\"u\":2806198365,\"b\":[],\"a\":[[\"1864.99000000\",\"0.00000000\"],[\"1865.06000000\",\"0.97360000\"]]}}"}
{"mode":"v11-raw-disruptor","partitions":4,"sequenceNumber":330,"routingSymbol":"ETHUSDT","localReceivedEpochMillis":1784431337443,"rawPayload":"{\"stream\":\"ethusdt@depth@100ms\",\"data\":{\"e\":\"depthUpdate\",\"E\":1784431337454,\"s\":\"ETHUSDT\",\"U\":2806198366,\"u\":2806198378,\"b\":[[\"1864.31000000\",\"0.00000000\"],[\"1864.30000000\",\"1.09690000\"],[\"1864.26000000\",\"0.00000000\"],[\"1864.13000000\",\"0.00000000\"],[\"1864.09000000\",\"0.00000000\"],[\"1864.06000000\",\"0.16920000\"],[\"1863.94000000\",\"0.00000000\"],[\"1863.76000000\",\"1.47990000\"],[\"1863.58000000\",\"0.00000000\"]],\"a\":[[\"1864.60000000\",\"0.00000000\"],[\"1864.70000000\",\"0.00000000\"],[\"1864.72000000\",\"0.13940000\"],[\"1864.87000000\",\"2.45060000\"],[\"1864.90000000\",\"0.00000000\"],[\"1865.02000000\",\"1.47920000\"],[\"1865.30000000\",\"1.63970000\"]]}}"}
{"mode":"v11-raw-disruptor","partitions":4,"sequenceNumber":331,"routingSymbol":"SOLUSDT","localReceivedEpochMillis":1784431337543,"rawPayload":"{\"stream\":\"solusdt@depth@100ms\",\"data\":{\"e\":\"depthUpdate\",\"E\":1784431337554,\"s\":\"SOLUSDT\",\"U\":1609592056,\"u\":1609592056,\"b\":[],\"a\":[[\"75.94000000\",\"13.18900000\"]]}}"}
{"mode":"v11-raw-disruptor","partitions":4,"sequenceNumber":332,"routingSymbol":"BNBUSDT","localReceivedEpochMillis":1784431337543,"rawPayload":"{\"stream\":\"bnbusdt@depth@100ms\",\"data\":{\"e\":\"depthUpdate\",\"E\":1784431337554,\"s\":\"BNBUSDT\",\"U\":1236336180,\"u\":1236336180,\"b\":[[\"567.79000000\",\"0.00600000\"],[\"567.78000000\",\"0.00000000\"]],\"a\":[]}}"}
{"mode":"v11-raw-disruptor","partitions":4,"sequenceNumber":333,"routingSymbol":"BTCUSDT","localReceivedEpochMillis":1784431337543,"rawPayload":"{\"stream\":\"btcusdt@depth@100ms\",\"data\":{\"e\":\"depthUpdate\",\"E\":1784431337554,\"s\":\"BTCUSDT\",\"U\":3244451688,\"u\":3244451689,\"b\":[[\"64646.01000000\",\"0.02839000\"],[\"64642.97000000\",\"0.00000000\"]],\"a\":[[\"64664.74000000\",\"0.00000000\"],[\"64667.26000000\",\"0.02961000\"]]}}"}
{"mode":"v11-raw-disruptor","partitions":4,"sequenceNumber":334,"routingSymbol":"BTCUSDT","localReceivedEpochMillis":1784431337642,"rawPayload":"{\"stream\":\"btcusdt@depth@100ms\",\"data\":{\"e\":\"depthUpdate\",\"E\":1784431337654,\"s\":\"BTCUSDT\",\"U\":3244451690,\"u\":3244451691,\"b\":[[\"64644.43000000\",\"0.01852000\"],[\"64642.28000000\",\"0.00000000\"]],\"a\":[]}}"}
{"mode":"v11-raw-disruptor","partitions":4,"sequenceNumber":335,"routingSymbol":"SOLUSDT","localReceivedEpochMillis":1784431337742,"rawPayload":"{\"stream\":\"solusdt@depth@100ms\",\"data\":{\"e\":\"depthUpdate\",\"E\":1784431337754,\"s\":\"SOLUSDT\",\"U\":1609592057,\"u\":1609592057,\"b\":[[\"75.84000000\",\"55.77000000\"],[\"75.83000000\",\"3.98400000\"]],\"a\":[]}}"}
{"mode":"v11-raw-disruptor","partitions":4,"sequenceNumber":336,"routingSymbol":"SOLUSDT","localReceivedEpochMillis":1784431337842,"rawPayload":"{\"stream\":\"solusdt@depth@100ms\",\"data\":{\"e\":\"depthUpdate\",\"E\":1784431337854,\"s\":\"SOLUSDT\",\"U\":1609592058,\"u\":1609592062,\"b\":[[\"75.72000000\",\"310.93900000\"],[\"75.71000000\",\"0.00000000\"],[\"75.67000000\",\"391.33500000\"],[\"75.66000000\",\"388.98600000\"],[\"75.58000000\",\"255.02400000\"],[\"75.57000000\",\"339.23800000\"]],\"a\":[[\"75.99000000\",\"274.61300000\"],[\"76.00000000\",\"312.37800000\"],[\"76.13000000\",\"54.78900000\"],[\"76.14000000\",\"148.15000000\"]]}}"}
{"mode":"v11-raw-disruptor","partitions":4,"sequenceNumber":337,"routingSymbol":"BNBUSDT","localReceivedEpochMillis":1784431337842,"rawPayload":"{\"stream\":\"bnbusdt@depth@100ms\",\"data\":{\"e\":\"depthUpdate\",\"E\":1784431337854,\"s\":\"BNBUSDT\",\"U\":1236336181,\"u\":1236336182,\"b\":[],\"a\":[[\"569.43000000\",\"0.61500000\"],[\"569.45000000\",\"0.10600000\"]]}}"}
{"mode":"v11-raw-disruptor","partitions":4,"sequenceNumber":338,"routingSymbol":"ETHUSDT","localReceivedEpochMillis":1784431337842,"rawPayload":"{\"stream\":\"ethusdt@depth@100ms\",\"data\":{\"e\":\"depthUpdate\",\"E\":1784431337854,\"s\":\"ETHUSDT\",\"U\":2806198379,\"u\":2806198380,\"b\":[],\"a\":[[\"1864.88000000\",\"1.63970000\"],[\"1865.62000000\",\"1.63970000\"]]}}"}
{"mode":"v11-raw-disruptor","partitions":4,"sequenceNumber":339,"routingSymbol":"SOLUSDT","localReceivedEpochMillis":1784431337943,"rawPayload":"{\"stream\":\"solusdt@depth@100ms\",\"data\":{\"e\":\"depthUpdate\",\"E\":1784431337954,\"s\":\"SOLUSDT\",\"U\":1609592063,\"u\":1609592064,\"b\":[[\"75.81000000\",\"7.01900000\"],[\"75.80000000\",\"36.39400000\"]],\"a\":[]}}"}
{"mode":"v11-raw-disruptor","partitions":4,"sequenceNumber":340,"routingSymbol":"XRPUSDT","localReceivedEpochMillis":1784431337943,"rawPayload":"{\"stream\":\"xrpusdt@depth@100ms\",\"data\":{\"e\":\"depthUpdate\",\"E\":1784431337954,\"s\":\"XRPUSDT\",\"U\":752712482,\"u\":752712482,\"b\":[[\"1.09350000\",\"2271.10000000\"],[\"1.09330000\",\"154.00000000\"]],\"a\":[]}}"}
{"mode":"v11-raw-disruptor","partitions":4,"sequenceNumber":341,"routingSymbol":"SOLUSDT","localReceivedEpochMillis":1784431338144,"rawPayload":"{\"stream\":\"solusdt@depth@100ms\",\"data\":{\"e\":\"depthUpdate\",\"E\":1784431338154,\"s\":\"SOLUSDT\",\"U\":1609592065,\"u\":1609592065,\"b\":[],\"a\":[[\"75.93000000\",\"0.00000000\"]]}}"}
{"mode":"v11-raw-disruptor","partitions":4,"sequenceNumber":342,"routingSymbol":"BTCUSDT","localReceivedEpochMillis":1784431338144,"rawPayload":"{\"stream\":\"btcusdt@depth@100ms\",\"data\":{\"e\":\"depthUpdate\",\"E\":1784431338154,\"s\":\"BTCUSDT\",\"U\":3244451692,\"u\":3244451693,\"b\":[],\"a\":[[\"64649.14000000\",\"0.01907000\"],[\"64650.83000000\",\"0.00000000\"]]}}"}
{"mode":"v11-raw-disruptor","partitions":4,"sequenceNumber":343,"routingSymbol":"ETHUSDT","localReceivedEpochMillis":1784431338344,"rawPayload":"{\"stream\":\"ethusdt@depth@100ms\",\"data\":{\"e\":\"depthUpdate\",\"E\":1784431338354,\"s\":\"ETHUSDT\",\"U\":2806198381,\"u\":2806198385,\"b\":[[\"1864.12000000\",\"0.13940000\"],[\"1864.06000000\",\"0.02980000\"],[\"1862.78000000\",\"9.23330000\"],[\"1862.54000000\",\"0.00000000\"]],\"a\":[[\"1864.72000000\",\"0.00000000\"],[\"1864.78000000\",\"0.13940000\"],[\"1865.02000000\",\"0.00000000\"],[\"1865.08000000\",\"1.47980000\"],[\"1865.94000000\",\"0.00000000\"],[\"1866.13000000\",\"9.21680000\"]]}}"}
{"mode":"v11-raw-disruptor","partitions":4,"sequenceNumber":344,"routingSymbol":"BTCUSDT","localReceivedEpochMillis":1784431338345,"rawPayload":"{\"stream\":\"btcusdt@depth@100ms\",\"data\":{\"e\":\"depthUpdate\",\"E\":1784431338354,\"s\":\"BTCUSDT\",\"U\":3244451694,\"u\":3244451694,\"b\":[[\"64514.58000000\",\"0.00048000\"]],\"a\":[]}}"}
{"mode":"v11-raw-disruptor","partitions":4,"sequenceNumber":345,"routingSymbol":"BNBUSDT","localReceivedEpochMillis":1784431338442,"rawPayload":"{\"stream\":\"bnbusdt@depth@100ms\",\"data\":{\"e\":\"depthUpdate\",\"E\":1784431338454,\"s\":\"BNBUSDT\",\"U\":1236336183,\"u\":1236336184,\"b\":[],\"a\":[[\"569.41000000\",\"2.33700000\"],[\"569.43000000\",\"0.00000000\"]]}}"}
{"mode":"v11-raw-disruptor","partitions":4,"sequenceNumber":346,"routingSymbol":"ETHUSDT","localReceivedEpochMillis":1784431338543,"rawPayload":"{\"stream\":\"ethusdt@depth@100ms\",\"data\":{\"e\":\"depthUpdate\",\"E\":1784431338554,\"s\":\"ETHUSDT\",\"U\":2806198386,\"u\":2806198386,\"b\":[[\"1863.90000000\",\"0.00000000\"]],\"a\":[]}}"}
{"mode":"v11-raw-disruptor","partitions":4,"sequenceNumber":347,"routingSymbol":"SOLUSDT","localReceivedEpochMillis":1784431338644,"rawPayload":"{\"stream\":\"solusdt@depth@100ms\",\"data\":{\"e\":\"depthUpdate\",\"E\":1784431338654,\"s\":\"SOLUSDT\",\"U\":1609592066,\"u\":1609592068,\"b\":[[\"75.80000000\",\"66.58900000\"]],\"a\":[[\"75.89000000\",\"33.47800000\"],[\"75.90000000\",\"95.04400000\"]]}}"}
{"mode":"v11-raw-disruptor","partitions":4,"sequenceNumber":348,"routingSymbol":"BTCUSDT","localReceivedEpochMillis":1784431338644,"rawPayload":"{\"stream\":\"btcusdt@depth@100ms\",\"data\":{\"e\":\"depthUpdate\",\"E\":1784431338654,\"s\":\"BTCUSDT\",\"U\":3244451695,\"u\":3244451696,\"b\":[[\"64644.43000000\",\"0.00000000\"],[\"64642.79000000\",\"0.01937000\"]],\"a\":[]}}"}
{"mode":"v11-raw-disruptor","partitions":4,"sequenceNumber":349,"routingSymbol":"SOLUSDT","localReceivedEpochMillis":1784431338744,"rawPayload":"{\"stream\":\"solusdt@depth@100ms\",\"data\":{\"e\":\"depthUpdate\",\"E\":1784431338754,\"s\":\"SOLUSDT\",\"U\":1609592069,\"u\":1609592069,\"b\":[],\"a\":[[\"75.91000000\",\"66.55800000\"]]}}"}
{"mode":"v11-raw-disruptor","partitions":4,"sequenceNumber":350,"routingSymbol":"ETHUSDT","localReceivedEpochMillis":1784431338744,"rawPayload":"{\"stream\":\"ethusdt@depth@100ms\",\"data\":{\"e\":\"depthUpdate\",\"E\":1784431338754,\"s\":\"ETHUSDT\",\"U\":2806198387,\"u\":2806198390,\"b\":[],\"a\":[[\"1864.88000000\",\"0.00000000\"],[\"1865.30000000\",\"0.00000000\"],[\"1865.62000000\",\"0.00000000\"],[\"1865.83000000\",\"1.63970000\"]]}}"}
{"mode":"v11-raw-disruptor","partitions":4,"sequenceNumber":351,"routingSymbol":"SOLUSDT","localReceivedEpochMillis":1784431338844,"rawPayload":"{\"stream\":\"solusdt@depth@100ms\",\"data\":{\"e\":\"depthUpdate\",\"E\":1784431338854,\"s\":\"SOLUSDT\",\"U\":1609592070,\"u\":1609592072,\"b\":[],\"a\":[[\"75.89000000\",\"3.28300000\"],[\"75.90000000\",\"64.84900000\"],[\"75.91000000\",\"36.36300000\"]]}}"}
{"mode":"v11-raw-disruptor","partitions":4,"sequenceNumber":352,"routingSymbol":"XRPUSDT","localReceivedEpochMillis":1784431338844,"rawPayload":"{\"stream\":\"xrpusdt@depth@100ms\",\"data\":{\"e\":\"depthUpdate\",\"E\":1784431338854,\"s\":\"XRPUSDT\",\"U\":752712483,\"u\":752712483,\"b\":[],\"a\":[[\"1.09390000\",\"1306.10000000\"]]}}"}
{"mode":"v11-raw-disruptor","partitions":4,"sequenceNumber":353,"routingSymbol":"XRPUSDT","localReceivedEpochMillis":1784431338944,"rawPayload":"{\"stream\":\"xrpusdt@depth@100ms\",\"data\":{\"e\":\"depthUpdate\",\"E\":1784431338955,\"s\":\"XRPUSDT\",\"U\":752712484,\"u\":752712485,\"b\":[[\"1.09350000\",\"1310.50000000\"],[\"1.09340000\",\"1223.30000000\"]],\"a\":[]}}"}
{"mode":"v11-raw-disruptor","partitions":4,"sequenceNumber":354,"routingSymbol":"XRPUSDT","localReceivedEpochMillis":1784431339044,"rawPayload":"{\"stream\":\"xrpusdt@depth@100ms\",\"data\":{\"e\":\"depthUpdate\",\"E\":1784431339055,\"s\":\"XRPUSDT\",\"U\":752712486,\"u\":752712491,\"b\":[[\"1.09320000\",\"3492.00000000\"],[\"1.09310000\",\"2109.50000000\"]],\"a\":[[\"1.09400000\",\"3228.30000000\"],[\"1.09410000\",\"272.40000000\"],[\"1.09420000\",\"2224.70000000\"]]}}"}
{"mode":"v11-raw-disruptor","partitions":4,"sequenceNumber":355,"routingSymbol":"ETHUSDT","localReceivedEpochMillis":1784431339144,"rawPayload":"{\"stream\":\"ethusdt@depth@100ms\",\"data\":{\"e\":\"depthUpdate\",\"E\":1784431339155,\"s\":\"ETHUSDT\",\"U\":2806198391,\"u\":2806198392,\"b\":[[\"1862.90000000\",\"1.51080000\"],[\"1862.52000000\",\"0.00000000\"]],\"a\":[]}}"}
{"mode":"v11-raw-disruptor","partitions":4,"sequenceNumber":356,"routingSymbol":"XRPUSDT","localReceivedEpochMillis":1784431339145,"rawPayload":"{\"stream\":\"xrpusdt@depth@100ms\",\"data\":{\"e\":\"depthUpdate\",\"E\":1784431339155,\"s\":\"XRPUSDT\",\"U\":752712492,\"u\":752712495,\"b\":[[\"1.09360000\",\"2287.50000000\"]],\"a\":[[\"1.09380000\",\"45.30000000\"],[\"1.09390000\",\"3593.00000000\"],[\"1.09400000\",\"941.60000000\"]]}}"}
{"mode":"v11-raw-disruptor","partitions":4,"sequenceNumber":357,"routingSymbol":"SOLUSDT","localReceivedEpochMillis":1784431339244,"rawPayload":"{\"stream\":\"solusdt@depth@100ms\",\"data\":{\"e\":\"depthUpdate\",\"E\":1784431339255,\"s\":\"SOLUSDT\",\"U\":1609592073,\"u\":1609592074,\"b\":[],\"a\":[[\"75.95000000\",\"149.11300000\"],[\"75.96000000\",\"30.19500000\"]]}}"}
{"mode":"v11-raw-disruptor","partitions":4,"sequenceNumber":358,"routingSymbol":"ETHUSDT","localReceivedEpochMillis":1784431339344,"rawPayload":"{\"stream\":\"ethusdt@depth@100ms\",\"data\":{\"e\":\"depthUpdate\",\"E\":1784431339355,\"s\":\"ETHUSDT\",\"U\":2806198393,\"u\":2806198394,\"b\":[[\"1864.31000000\",\"0.79440000\"],[\"1863.91000000\",\"1.63970000\"]],\"a\":[]}}"}
{"mode":"v11-raw-disruptor","partitions":4,"sequenceNumber":359,"routingSymbol":"SOLUSDT","localReceivedEpochMillis":1784431339444,"rawPayload":"{\"stream\":\"solusdt@depth@100ms\",\"data\":{\"e\":\"depthUpdate\",\"E\":1784431339455,\"s\":\"SOLUSDT\",\"U\":1609592075,\"u\":1609592077,\"b\":[[\"75.81000000\",\"43.42500000\"],[\"75.80000000\",\"30.19500000\"],[\"75.76000000\",\"185.28000000\"],[\"75.74000000\",\"7.73300000\"]],\"a\":[[\"75.95000000\",\"49.70500000\"],[\"75.96000000\",\"129.59400000\"]]}}"}
{"mode":"v11-raw-disruptor","partitions":4,"sequenceNumber":360,"routingSymbol":"BTCUSDT","localReceivedEpochMillis":1784431339545,"rawPayload":"{\"stream\":\"btcusdt@depth@100ms\",\"data\":{\"e\":\"depthUpdate\",\"E\":1784431339555,\"s\":\"BTCUSDT\",\"U\":3244451697,\"u\":3244451697,\"b\":[[\"64647.70000000\",\"0.02839000\"],[\"64646.01000000\",\"0.00000000\"]],\"a\":[]}}"}
{"mode":"v11-raw-disruptor","partitions":4,"sequenceNumber":361,"routingSymbol":"XRPUSDT","localReceivedEpochMillis":1784431339545,"rawPayload":"{\"stream\":\"xrpusdt@depth@100ms\",\"data\":{\"e\":\"depthUpdate\",\"E\":1784431339555,\"s\":\"XRPUSDT\",\"U\":752712496,\"u\":752712497,\"b\":[[\"1.09320000\",\"3527.30000000\"],[\"1.09310000\",\"2074.70000000\"]],\"a\":[]}}"}
{"mode":"v11-raw-disruptor","partitions":4,"sequenceNumber":362,"routingSymbol":"XRPUSDT","localReceivedEpochMillis":1784431339644,"rawPayload":"{\"stream\":\"xrpusdt@depth@100ms\",\"data\":{\"e\":\"depthUpdate\",\"E\":1784431339655,\"s\":\"XRPUSDT\",\"U\":752712498,\"u\":752712499,\"b\":[],\"a\":[[\"1.09400000\",\"0.00000000\"],[\"1.09410000\",\"1212.30000000\"]]}}"}
{"mode":"v11-raw-disruptor","partitions":4,"sequenceNumber":363,"routingSymbol":"BNBUSDT","localReceivedEpochMillis":1784431339745,"rawPayload":"{\"stream\":\"bnbusdt@depth@100ms\",\"data\":{\"e\":\"depthUpdate\",\"E\":1784431339755,\"s\":\"BNBUSDT\",\"U\":1236336185,\"u\":1236336185,\"b\":[[\"567.80000000\",\"0.00500000\"],[\"567.79000000\",\"0.00000000\"]],\"a\":[]}}"}
{"mode":"v11-raw-disruptor","partitions":4,"sequenceNumber":364,"routingSymbol":"SOLUSDT","localReceivedEpochMillis":1784431339843,"rawPayload":"{\"stream\":\"solusdt@depth@100ms\",\"data\":{\"e\":\"depthUpdate\",\"E\":1784431339855,\"s\":\"SOLUSDT\",\"U\":1609592078,\"u\":1609592078,\"b\":[[\"75.85000000\",\"33.21700000\"],[\"75.84000000\",\"36.48400000\"]],\"a\":[]}}"}
{"mode":"v11-raw-disruptor","partitions":4,"sequenceNumber":365,"routingSymbol":"XRPUSDT","localReceivedEpochMillis":1784431339844,"rawPayload":"{\"stream\":\"xrpusdt@depth@100ms\",\"data\":{\"e\":\"depthUpdate\",\"E\":1784431339855,\"s\":\"XRPUSDT\",\"U\":752712500,\"u\":752712500,\"b\":[[\"1.09350000\",\"1356.20000000\"]],\"a\":[]}}"}
{"mode":"v11-raw-disruptor","partitions":4,"sequenceNumber":366,"routingSymbol":"SOLUSDT","localReceivedEpochMillis":1784431339944,"rawPayload":"{\"stream\":\"solusdt@depth@100ms\",\"data\":{\"e\":\"depthUpdate\",\"E\":1784431339955,\"s\":\"SOLUSDT\",\"U\":1609592079,\"u\":1609592080,\"b\":[],\"a\":[[\"75.95000000\",\"19.51000000\"],[\"75.96000000\",\"99.39900000\"]]}}"}
{"mode":"v11-raw-disruptor","partitions":4,"sequenceNumber":367,"routingSymbol":"ETHUSDT","localReceivedEpochMillis":1784431339944,"rawPayload":"{\"stream\":\"ethusdt@depth@100ms\",\"data\":{\"e\":\"depthUpdate\",\"E\":1784431339955,\"s\":\"ETHUSDT\",\"U\":2806198395,\"u\":2806198401,\"b\":[[\"1864.39000000\",\"0.79440000\"],[\"1864.38000000\",\"1.09800000\"],[\"1864.30000000\",\"0.00000000\"]],\"a\":[[\"1864.87000000\",\"1.34140000\"],[\"1864.95000000\",\"1.09410000\"],[\"1865.25000000\",\"1.63970000\"],[\"1865.83000000\",\"0.00000000\"]]}}"}
{"mode":"v11-raw-disruptor","partitions":4,"sequenceNumber":368,"routingSymbol":"ETHUSDT","localReceivedEpochMillis":1784431340045,"rawPayload":"{\"stream\":\"ethusdt@depth@100ms\",\"data\":{\"e\":\"depthUpdate\",\"E\":1784431340055,\"s\":\"ETHUSDT\",\"U\":2806198402,\"u\":2806198402,\"b\":[],\"a\":[[\"1866.32000000\",\"0.00000000\"]]}}"}
{"mode":"v11-raw-disruptor","partitions":4,"sequenceNumber":369,"routingSymbol":"SOLUSDT","localReceivedEpochMillis":1784431340145,"rawPayload":"{\"stream\":\"solusdt@depth@100ms\",\"data\":{\"e\":\"depthUpdate\",\"E\":1784431340155,\"s\":\"SOLUSDT\",\"U\":1609592081,\"u\":1609592082,\"b\":[],\"a\":[[\"75.91000000\",\"66.55800000\"],[\"75.96000000\",\"154.18800000\"]]}}"}
{"mode":"v11-raw-disruptor","partitions":4,"sequenceNumber":370,"routingSymbol":"ETHUSDT","localReceivedEpochMillis":1784431340145,"rawPayload":"{\"stream\":\"ethusdt@depth@100ms\",\"data\":{\"e\":\"depthUpdate\",\"E\":1784431340155,\"s\":\"ETHUSDT\",\"U\":2806198403,\"u\":2806198403,\"b\":[],\"a\":[[\"1865.57000000\",\"1.63970000\"]]}}"}
{"mode":"v11-raw-disruptor","partitions":4,"sequenceNumber":371,"routingSymbol":"SOLUSDT","localReceivedEpochMillis":1784431340444,"rawPayload":"{\"stream\":\"solusdt@depth@100ms\",\"data\":{\"e\":\"depthUpdate\",\"E\":1784431340456,\"s\":\"SOLUSDT\",\"U\":1609592083,\"u\":1609592083,\"b\":[],\"a\":[[\"75.90000000\",\"95.04400000\"]]}}"}
{"mode":"v11-raw-disruptor","partitions":4,"sequenceNumber":372,"routingSymbol":"BTCUSDT","localReceivedEpochMillis":1784431340444,"rawPayload":"{\"stream\":\"btcusdt@depth@100ms\",\"data\":{\"e\":\"depthUpdate\",\"E\":1784431340456,\"s\":\"BTCUSDT\",\"U\":3244451698,\"u\":3244451698,\"b\":[],\"a\":[[\"80832.52000000\",\"0.00030000\"]]}}"}
{"mode":"v11-raw-disruptor","partitions":4,"sequenceNumber":373,"routingSymbol":"XRPUSDT","localReceivedEpochMillis":1784431340745,"rawPayload":"{\"stream\":\"xrpusdt@depth@100ms\",\"data\":{\"e\":\"depthUpdate\",\"E\":1784431340756,\"s\":\"XRPUSDT\",\"U\":752712501,\"u\":752712504,\"b\":[[\"1.09240000\",\"1355.30000000\"],[\"1.09220000\",\"0.00000000\"],[\"1.09170000\",\"2591.90000000\"],[\"1.09150000\",\"0.00000000\"],[\"1.09100000\",\"20060.20000000\"],[\"1.09090000\",\"3841.90000000\"],[\"1.08970000\",\"24856.10000000\"],[\"1.08960000\",\"0.00000000\"]],\"a\":[]}}"}
{"mode":"v11-raw-disruptor","partitions":4,"sequenceNumber":374,"routingSymbol":"SOLUSDT","localReceivedEpochMillis":1784431340845,"rawPayload":"{\"stream\":\"solusdt@depth@100ms\",\"data\":{\"e\":\"depthUpdate\",\"E\":1784431340856,\"s\":\"SOLUSDT\",\"U\":1609592084,\"u\":1609592084,\"b\":[],\"a\":[[\"75.92000000\",\"96.10300000\"]]}}"}
{"mode":"v11-raw-disruptor","partitions":4,"sequenceNumber":375,"routingSymbol":"XRPUSDT","localReceivedEpochMillis":1784431340845,"rawPayload":"{\"stream\":\"xrpusdt@depth@100ms\",\"data\":{\"e\":\"depthUpdate\",\"E\":1784431340856,\"s\":\"XRPUSDT\",\"U\":752712505,\"u\":752712505,\"b\":[[\"1.08760000\",\"522.20000000\"],[\"1.08750000\",\"0.00000000\"]],\"a\":[]}}"}
{"mode":"v11-raw-disruptor","partitions":4,"sequenceNumber":376,"routingSymbol":"BTCUSDT","localReceivedEpochMillis":1784431340945,"rawPayload":"{\"stream\":\"btcusdt@depth@100ms\",\"data\":{\"e\":\"depthUpdate\",\"E\":1784431340956,\"s\":\"BTCUSDT\",\"U\":3244451699,\"u\":3244451699,\"b\":[],\"a\":[[\"80832.52000000\",\"0.00045000\"]]}}"}
{"mode":"v11-raw-disruptor","partitions":4,"sequenceNumber":377,"routingSymbol":"ETHUSDT","localReceivedEpochMillis":1784431340945,"rawPayload":"{\"stream\":\"ethusdt@depth@100ms\",\"data\":{\"e\":\"depthUpdate\",\"E\":1784431340956,\"s\":\"ETHUSDT\",\"U\":2806198404,\"u\":2806198408,\"b\":[[\"1864.39000000\",\"0.00000000\"],[\"1864.31000000\",\"0.00000000\"],[\"1863.91000000\",\"0.00000000\"],[\"1863.52000000\",\"0.00000000\"],[\"1863.16000000\",\"1.09310000\"]],\"a\":[]}}"}
{"mode":"v11-raw-disruptor","partitions":4,"sequenceNumber":378,"routingSymbol":"ETHUSDT","localReceivedEpochMillis":1784431341045,"rawPayload":"{\"stream\":\"ethusdt@depth@100ms\",\"data\":{\"e\":\"depthUpdate\",\"E\":1784431341056,\"s\":\"ETHUSDT\",\"U\":2806198409,\"u\":2806198409,\"b\":[],\"a\":[[\"1866.06000000\",\"0.44760000\"]]}}"}
{"mode":"v11-raw-disruptor","partitions":4,"sequenceNumber":379,"routingSymbol":"SOLUSDT","localReceivedEpochMillis":1784431341045,"rawPayload":"{\"stream\":\"solusdt@depth@100ms\",\"data\":{\"e\":\"depthUpdate\",\"E\":1784431341056,\"s\":\"SOLUSDT\",\"U\":1609592085,\"u\":1609592085,\"b\":[],\"a\":[[\"75.90000000\",\"115.17400000\"]]}}"}
{"mode":"v11-raw-disruptor","partitions":4,"sequenceNumber":380,"routingSymbol":"ETHUSDT","localReceivedEpochMillis":1784431341345,"rawPayload":"{\"stream\":\"ethusdt@depth@100ms\",\"data\":{\"e\":\"depthUpdate\",\"E\":1784431341356,\"s\":\"ETHUSDT\",\"U\":2806198410,\"u\":2806198413,\"b\":[[\"1863.64000000\",\"1.63970000\"]],\"a\":[[\"1865.25000000\",\"0.00000000\"],[\"1865.57000000\",\"0.00000000\"],[\"1865.83000000\",\"1.63970000\"]]}}"}
{"mode":"v11-raw-disruptor","partitions":4,"sequenceNumber":381,"routingSymbol":"BTCUSDT","localReceivedEpochMillis":1784431341447,"rawPayload":"{\"stream\":\"btcusdt@depth@100ms\",\"data\":{\"e\":\"depthUpdate\",\"E\":1784431341456,\"s\":\"BTCUSDT\",\"U\":3244451700,\"u\":3244451729,\"b\":[[\"64645.93000000\",\"0.03869000\"],[\"64645.09000000\",\"0.00000000\"],[\"64644.80000000\",\"0.03370000\"],[\"64642.79000000\",\"0.00000000\"],[\"64640.58000000\",\"0.00000000\"],[\"64640.41000000\",\"0.03193000\"],[\"64640.21000000\",\"0.00000000\"],[\"64632.51000000\",\"0.00000000\"],[\"64620.21000000\",\"0.04257000\"],[\"64607.01000000\",\"0.00000000\"]],\"a\":[[\"64649.14000000\",\"0.00000000\"],[\"64650.78000000\",\"0.00000000\"],[\"64659.06000000\",\"0.00000000\"],[\"64659.99000000\",\"0.00000000\"],[\"64660.57000000\",\"0.00000000\"],[\"64662.64000000\",\"0.00000000\"],[\"64664.23000000\",\"0.03353000\"],[\"64666.75000000\",\"0.00000000\"],[\"64667.31000000\",\"0.00000000\"],[\"64667.34000000\",\"0.00000000\"],[\"64669.23000000\",\"0.03868000\"],[\"64669.88000000\",\"0.00160000\"],[\"64676.70000000\",\"0.00000000\"],[\"64680.52000000\",\"0.00000000\"],[\"64689.72000000\",\"0.04257000\"],[\"64706.47000000\",\"0.05322000\"]]}}"}
{"mode":"v11-raw-disruptor","partitions":4,"sequenceNumber":382,"routingSymbol":"SOLUSDT","localReceivedEpochMillis":1784431341447,"rawPayload":"{\"stream\":\"solusdt@depth@100ms\",\"data\":{\"e\":\"depthUpdate\",\"E\":1784431341456,\"s\":\"SOLUSDT\",\"U\":1609592086,\"u\":1609592109,\"b\":[[\"75.85000000\",\"19.28600000\"],[\"75.84000000\",\"20.75200000\"],[\"75.83000000\",\"0.55600000\"],[\"75.82000000\",\"37.88400000\"],[\"75.81000000\",\"36.47200000\"],[\"75.79000000\",\"2.16500000\"]],\"a\":[[\"75.86000000\",\"0.55300000\"],[\"75.87000000\",\"3.84400000\"],[\"75.88000000\",\"19.05000000\"],[\"75.89000000\",\"14.39700000\"],[\"75.90000000\",\"51.18100000\"],[\"75.91000000\",\"0.00000000\"],[\"75.92000000\",\"36.35400000\"],[\"75.95000000\",\"85.38900000\"],[\"75.96000000\",\"99.39900000\"]]}}"}
{"mode":"v11-raw-disruptor","partitions":4,"sequenceNumber":383,"routingSymbol":"ETHUSDT","localReceivedEpochMillis":1784431341447,"rawPayload":"{\"stream\":\"ethusdt@depth@100ms\",\"data\":{\"e\":\"depthUpdate\",\"E\":1784431341456,\"s\":\"ETHUSDT\",\"U\":2806198414,\"u\":2806198438,\"b\":[[\"1864.44000000\",\"1.34170000\"],[\"1864.27000000\",\"0.00000000\"],[\"1864.23000000\",\"0.13940000\"],[\"1864.12000000\",\"0.00000000\"],[\"1864.10000000\",\"0.00000000\"],[\"1864.03000000\",\"0.00000000\"],[\"1863.93000000\",\"1.48030000\"],[\"1863.82000000\",\"1.20420000\"],[\"1863.76000000\",\"0.00000000\"],[\"1863.64000000\",\"0.00000000\"],[\"1863.61000000\",\"0.00000000\"],[\"1863.16000000\",\"0.00000000\"],[\"1862.75000000\",\"2.01670000\"],[\"1862.37000000\",\"0.00000000\"],[\"1861.63000000\",\"2.97580000\"],[\"1861.25000000\",\"0.00000000\"],[\"1860.51000000\",\"5.93290000\"],[\"1860.13000000\",\"0.00000000\"],[\"1858.27000000\",\"14.08700000\"],[\"1857.90000000\",\"0.00000000\"]],\"a\":[[\"1864.66000000\",\"0.00000000\"],[\"1864.72000000\",\"0.80280000\"],[\"1864.78000000\",\"0.00000000\"],[\"1864.87000000\",\"0.00000000\"],[\"1864.89000000\",\"0.13940000\"],[\"1864.91000000\",\"0.00000000\"],[\"1865.02000000\",\"1.34130000\"],[\"1865.08000000\",\"0.00000000\"],[\"1865.19000000\",\"1.47930000\"],[\"1865.83000000\",\"0.00000000\"],[\"1866.86000000\",\"0.00000000\"],[\"1867.23000000\",\"2.09560000\"],[\"1869.09000000\",\"0.00000000\"],[\"1869.47000000\",\"5.81330000\"]]}}"}
{"mode":"v11-raw-disruptor","partitions":4,"sequenceNumber":384,"routingSymbol":"XRPUSDT","localReceivedEpochMillis":1784431341448,"rawPayload":"{\"stream\":\"xrpusdt@depth@100ms\",\"data\":{\"e\":\"depthUpdate\",\"E\":1784431341456,\"s\":\"XRPUSDT\",\"U\":752712506,\"u\":752712520,\"b\":[[\"1.09370000\",\"2287.30000000\"],[\"1.09360000\",\"0.00000000\"],[\"1.09350000\",\"2307.50000000\"],[\"1.09340000\",\"237.70000000\"],[\"1.09330000\",\"191.20000000\"],[\"1.09320000\",\"3492.00000000\"],[\"1.09280000\",\"59.80000000\"]],\"a\":[[\"1.09390000\",\"1306.10000000\"],[\"1.09410000\",\"2524.30000000\"],[\"1.09420000\",\"2261.90000000\"],[\"1.09930000\",\"0.00000000\"]]}}"}
{"mode":"v11-raw-disruptor","partitions":4,"sequenceNumber":385,"routingSymbol":"BTCUSDT","localReceivedEpochMillis":1784431341548,"rawPayload":"{\"stream\":\"btcusdt@depth@100ms\",\"data\":{\"e\":\"depthUpdate\",\"E\":1784431341556,\"s\":\"BTCUSDT\",\"U\":3244451730,\"u\":3244451777,\"b\":[[\"64648.58000000\",\"0.03205000\"],[\"64648.11000000\",\"0.02839000\"],[\"64647.97000000\",\"0.02096000\"],[\"64647.96000000\",\"0.00000000\"],[\"64647.70000000\",\"0.00000000\"],[\"64645.93000000\",\"0.00000000\"],[\"64644.80000000\",\"0.00000000\"],[\"64642.35000000\",\"0.01221000\"],[\"64634.93000000\",\"0.00000000\"],[\"64633.13000000\",\"0.00402000\"],[\"64630.79000000\",\"0.00000000\"],[\"64627.63000000\",\"0.00000000\"],[\"64620.45000000\",\"0.04268000\"],[\"64617.29000000\",\"0.00000000\"],[\"64586.58000000\",\"0.26629000\"],[\"64584.86000000\",\"0.20825000\"],[\"64579.14000000\",\"0.00000000\"],[\"64380.41000000\",\"0.00000000\"]],\"a\":[[\"64650.27000000\",\"0.00000000\"],[\"64651.41000000\",\"0.00000000\"],[\"64651.86000000\",\"0.00000000\"],[\"64653.43000000\",\"0.00000000\"],[\"64655.77000000\",\"0.00402000\"],[\"64659.85000000\",\"0.00000000\"],[\"64660.52000000\",\"0.01404000\"],[\"64660.60000000\",\"0.34755000\"],[\"64660.61000000\",\"0.00000000\"],[\"64661.42000000\",\"0.00000000\"],[\"64662.21000000\",\"0.00000000\"],[\"64663.77000000\",\"0.00000000\"],[\"64664.23000000\",\"0.00000000\"],[\"64665.02000000\",\"0.00000000\"],[\"64666.11000000\",\"0.04267000\"],[\"64667.26000000\",\"0.00000000\"],[\"64667.38000000\",\"0.00000000\"],[\"64668.36000000\",\"0.00000000\"],[\"64668.88000000\",\"0.02961000\"],[\"64669.23000000\",\"0.00000000\"],[\"64669.79000000\",\"0.03305000\"],[\"64669.88000000\",\"0.00000000\"],[\"64670.45000000\",\"0.00000000\"],[\"64674.20000000\",\"0.00000000\"],[\"64674.61000000\",\"0.03144000\"],[\"64678.61000000\",\"0.00162000\"],[\"64692.44000000\",\"0.00000000\"],[\"64698.41000000\",\"0.26584000\"],[\"64698.71000000\",\"0.00000000\"],[\"64724.55000000\",\"0.00000000\"],[\"64731.98000000\",\"0.01180000\"],[\"64813.91000000\",\"0.26693000\"]]}}"}
{"mode":"v11-raw-disruptor","partitions":4,"sequenceNumber":386,"routingSymbol":"SOLUSDT","localReceivedEpochMillis":1784431341548,"rawPayload":"{\"stream\":\"solusdt@depth@100ms\",\"data\":{\"e\":\"depthUpdate\",\"E\":1784431341556,\"s\":\"SOLUSDT\",\"U\":1609592110,\"u\":1609592148,\"b\":[[\"75.85000000\",\"54.84500000\"],[\"75.84000000\",\"19.42900000\"],[\"75.83000000\",\"36.95200000\"],[\"75.82000000\",\"37.88400000\"],[\"75.81000000\",\"0.06600000\"],[\"75.79000000\",\"0.00000000\"],[\"75.78000000\",\"118.91100000\"],[\"75.77000000\",\"0.00000000\"],[\"75.76000000\",\"93.15700000\"],[\"75.74000000\",\"0.00000000\"],[\"75.67000000\",\"445.93700000\"],[\"75.66000000\",\"331.22200000\"],[\"75.53000000\",\"5.29500000\"]],\"a\":[[\"75.87000000\",\"0.00000000\"],[\"75.88000000\",\"3.29600000\"],[\"75.89000000\",\"19.05000000\"],[\"75.90000000\",\"62.30300000\"],[\"75.91000000\",\"0.00000000\"],[\"75.92000000\",\"0.00000000\"],[\"75.93000000\",\"50.87700000\"],[\"75.96000000\",\"0.00000000\"],[\"75.97000000\",\"0.00000000\"],[\"75.98000000\",\"371.84300000\"],[\"76.04000000\",\"326.43000000\"],[\"76.08000000\",\"316.59300000\"],[\"76.13000000\",\"393.94800000\"]]}}"}
{"mode":"v11-raw-disruptor","partitions":4,"sequenceNumber":387,"routingSymbol":"ETHUSDT","localReceivedEpochMillis":1784431341548,"rawPayload":"{\"stream\":\"ethusdt@depth@100ms\",\"data\":{\"e\":\"depthUpdate\",\"E\":1784431341556,\"s\":\"ETHUSDT\",\"U\":2806198439,\"u\":2806198457,\"b\":[[\"1864.44000000\",\"0.00000000\"],[\"1864.42000000\",\"0.81220000\"],[\"1864.31000000\",\"0.80340000\"],[\"1863.46000000\",\"0.00000000\"],[\"1857.04000000\",\"7.19840000\"],[\"1856.74000000\",\"0.00000000\"],[\"1855.47000000\",\"0.00000000\"]],\"a\":[[\"1864.72000000\",\"0.00000000\"],[\"1865.02000000\",\"0.00000000\"],[\"1865.06000000\",\"0.00000000\"],[\"1865.15000000\",\"1.20430000\"],[\"1865.26000000\",\"0.97360000\"],[\"1865.34000000\",\"12.45470000\"],[\"1866.33000000\",\"0.00000000\"],[\"1867.00000000\",\"5.35980000\"],[\"1871.82000000\",\"0.00000000\"],[\"1871.88000000\",\"0.00000000\"],[\"1872.00000000\",\"0.00000000\"],[\"1872.05000000\",\"0.00000000\"],[\"1873.23000000\",\"9.19480000\"]]}}"}
{"mode":"v11-raw-disruptor","partitions":4,"sequenceNumber":388,"routingSymbol":"XRPUSDT","localReceivedEpochMillis":1784431341548,"rawPayload":"{\"stream\":\"xrpusdt@depth@100ms\",\"data\":{\"e\":\"depthUpdate\",\"E\":1784431341556,\"s\":\"XRPUSDT\",\"U\":752712521,\"u\":752712537,\"b\":[[\"1.09370000\",\"3290.50000000\"],[\"1.09360000\",\"0.00000000\"],[\"1.09350000\",\"1310.50000000\"],[\"1.09300000\",\"2789.50000000\"],[\"1.09280000\",\"0.00000000\"],[\"1.09200000\",\"12813.40000000\"],[\"1.08920000\",\"0.00000000\"],[\"1.08910000\",\"10022.40000000\"],[\"1.08890000\",\"0.00000000\"]],\"a\":[[\"1.09390000\",\"0.00000000\"],[\"1.09400000\",\"1306.10000000\"],[\"1.09420000\",\"2224.70000000\"],[\"1.09430000\",\"1538.90000000\"],[\"1.09540000\",\"0.00000000\"],[\"1.09550000\",\"12757.40000000\"]]}}"}
{"mode":"v11-raw-disruptor","partitions":4,"sequenceNumber":389,"routingSymbol":"BTCUSDT","localReceivedEpochMillis":1784431341646,"rawPayload":"{\"stream\":\"btcusdt@depth@100ms\",\"data\":{\"e\":\"depthUpdate\",\"E\":1784431341656,\"s\":\"BTCUSDT\",\"U\":3244451778,\"u\":3244451788,\"b\":[[\"64653.16000000\",\"0.03301000\"],[\"64651.44000000\",\"0.00813000\"],[\"64648.58000000\",\"0.00000000\"],[\"64647.97000000\",\"0.00000000\"],[\"64632.53000000\",\"0.00000000\"]],\"a\":[[\"64648.61000000\",\"0.00000000\"],[\"64655.77000000\",\"0.00000000\"],[\"64656.18000000\",\"0.00402000\"],[\"64658.69000000\",\"0.00967000\"],[\"64660.52000000\",\"0.00000000\"],[\"64669.79000000\",\"0.00000000\"],[\"64672.73000000\",\"0.03430000\"]]}}"}
{"mode":"v11-raw-disruptor","partitions":4,"sequenceNumber":390,"routingSymbol":"SOLUSDT","localReceivedEpochMillis":1784431341646,"rawPayload":"{\"stream\":\"solusdt@depth@100ms\",\"data\":{\"e\":\"depthUpdate\",\"E\":1784431341656,\"s\":\"SOLUSDT\",\"U\":1609592149,\"u\":1609592160,\"b\":[[\"75.87000000\",\"14.32300000\"],[\"75.85000000\",\"59.53900000\"],[\"75.84000000\",\"0.14300000\"],[\"75.83000000\",\"36.39600000\"],[\"75.82000000\",\"40.04800000\"]],\"a\":[[\"75.86000000\",\"0.00000000\"],[\"75.89000000\",\"32.96700000\"],[\"75.90000000\",\"81.35300000\"],[\"75.92000000\",\"3.28300000\"],[\"75.94000000\",\"0.00000000\"],[\"75.98000000\",\"377.38200000\"],[\"76.13000000\",\"54.78900000\"]]}}"}
{"mode":"v11-raw-disruptor","partitions":4,"sequenceNumber":391,"routingSymbol":"ETHUSDT","localReceivedEpochMillis":1784431341646,"rawPayload":"{\"stream\":\"ethusdt@depth@100ms\",\"data\":{\"e\":\"depthUpdate\",\"E\":1784431341656,\"s\":\"ETHUSDT\",\"U\":2806198458,\"u\":2806198470,\"b\":[[\"1864.31000000\",\"0.00000000\"],[\"1864.24000000\",\"0.69820000\"],[\"1864.12000000\",\"0.11520000\"],[\"1864.06000000\",\"0.00000000\"],[\"1856.98000000\",\"0.27730000\"]],\"a\":[[\"1864.64000000\",\"0.00000000\"],[\"1865.26000000\",\"0.00000000\"],[\"1865.34000000\",\"0.00000000\"],[\"1865.48000000\",\"0.97360000\"],[\"1866.05000000\",\"12.45470000\"],[\"1866.06000000\",\"0.00000000\"],[\"1866.31000000\",\"0.26920000\"],[\"1866.47000000\",\"1.63970000\"],[\"1872.11000000\",\"0.00000000\"]]}}"}
{"mode":"v11-raw-disruptor","partitions":4,"sequenceNumber":392,"routingSymbol":"XRPUSDT","localReceivedEpochMillis":1784431341646,"rawPayload":"{\"stream\":\"xrpusdt@depth@100ms\",\"data\":{\"e\":\"depthUpdate\",\"E\":1784431341656,\"s\":\"XRPUSDT\",\"U\":752712538,\"u\":752712540,\"b\":[[\"1.09360000\",\"225.00000000\"],[\"1.09330000\",\"37.20000000\"]],\"a\":[[\"1.09380000\",\"0.00000000\"]]}}"}
{"mode":"v11-raw-disruptor","partitions":4,"sequenceNumber":393,"routingSymbol":"BNBUSDT","localReceivedEpochMillis":1784431341747,"rawPayload":"{\"stream\":\"bnbusdt@depth@100ms\",\"data\":{\"e\":\"depthUpdate\",\"E\":1784431341756,\"s\":\"BNBUSDT\",\"U\":1236336186,\"u\":1236336188,\"b\":[[\"567.80000000\",\"0.00000000\"]],\"a\":[[\"569.39000000\",\"0.45100000\"],[\"569.41000000\",\"1.70900000\"]]}}"}
{"mode":"v11-raw-disruptor","partitions":4,"sequenceNumber":394,"routingSymbol":"BTCUSDT","localReceivedEpochMillis":1784431341747,"rawPayload":"{\"stream\":\"btcusdt@depth@100ms\",\"data\":{\"e\":\"depthUpdate\",\"E\":1784431341756,\"s\":\"BTCUSDT\",\"U\":3244451789,\"u\":3244451802,\"b\":[[\"64651.44000000\",\"0.00000000\"],[\"64649.04000000\",\"0.00000000\"],[\"64648.59000000\",\"0.00000000\"],[\"64648.12000000\",\"0.02839000\"],[\"64648.11000000\",\"0.00000000\"],[\"64647.08000000\",\"0.00469000\"],[\"64640.41000000\",\"0.00000000\"],[\"64633.58000000\",\"0.00950000\"]],\"a\":[[\"64656.97000000\",\"0.00631000\"],[\"64658.69000000\",\"0.00000000\"],[\"64668.88000000\",\"0.00000000\"],[\"64670.53000000\",\"0.03868000\"],[\"64672.58000000\",\"0.00321000\"],[\"64676.92000000\",\"0.02961000\"]]}}"}
{"mode":"v11-raw-disruptor","partitions":4,"sequenceNumber":395,"routingSymbol":"SOLUSDT","localReceivedEpochMillis":1784431341747,"rawPayload":"{\"stream\":\"solusdt@depth@100ms\",\"data\":{\"e\":\"depthUpdate\",\"E\":1784431341756,\"s\":\"SOLUSDT\",\"U\":1609592161,\"u\":1609592174,\"b\":[[\"75.87000000\",\"0.00000000\"],[\"75.86000000\",\"0.00000000\"],[\"75.85000000\",\"74.19600000\"]],\"a\":[[\"75.90000000\",\"73.65600000\"],[\"75.91000000\",\"4.11900000\"],[\"75.93000000\",\"36.33600000\"],[\"75.98000000\",\"104.91500000\"]]}}"}
{"mode":"v11-raw-disruptor","partitions":4,"sequenceNumber":396,"routingSymbol":"ETHUSDT","localReceivedEpochMillis":1784431341747,"rawPayload":"{\"stream\":\"ethusdt@depth@100ms\",\"data\":{\"e\":\"depthUpdate\",\"E\":1784431341756,\"s\":\"ETHUSDT\",\"U\":2806198471,\"u\":2806198483,\"b\":[[\"1864.43000000\",\"0.00000000\"],[\"1864.38000000\",\"0.00000000\"],[\"1864.24000000\",\"0.00000000\"],[\"1864.18000000\",\"0.00000000\"],[\"1863.82000000\",\"0.00000000\"],[\"1863.62000000\",\"1.05640000\"]],\"a\":[[\"1864.95000000\",\"0.00000000\"],[\"1864.96000000\",\"1.05640000\"],[\"1865.15000000\",\"0.00000000\"],[\"1865.19000000\",\"1.47930000\"]]}}"}
{"mode":"v11-raw-disruptor","partitions":4,"sequenceNumber":397,"routingSymbol":"XRPUSDT","localReceivedEpochMillis":1784431341747,"rawPayload":"{\"stream\":\"xrpusdt@depth@100ms\",\"data\":{\"e\":\"depthUpdate\",\"E\":1784431341756,\"s\":\"XRPUSDT\",\"U\":752712541,\"u\":752712559,\"b\":[[\"1.09370000\",\"0.00000000\"],[\"1.09360000\",\"1012.80000000\"],[\"1.09350000\",\"3835.70000000\"],[\"1.09340000\",\"0.00000000\"],[\"1.09330000\",\"0.00000000\"],[\"1.09320000\",\"3516.20000000\"],[\"1.09310000\",\"4598.90000000\"],[\"1.09300000\",\"190.00000000\"],[\"1.09280000\",\"48.40000000\"]],\"a\":[[\"1.09400000\",\"3592.80000000\"],[\"1.09410000\",\"0.00000000\"],[\"1.09420000\",\"3429.90000000\"],[\"1.09430000\",\"531.20000000\"],[\"1.09450000\",\"2074.70000000\"],[\"1.09460000\",\"4595.70000000\"],[\"1.09470000\",\"48.40000000\"]]}}"}
{"mode":"v11-raw-disruptor","partitions":4,"sequenceNumber":398,"routingSymbol":"BTCUSDT","localReceivedEpochMillis":1784431341847,"rawPayload":"{\"stream\":\"btcusdt@depth@100ms\",\"data\":{\"e\":\"depthUpdate\",\"E\":1784431341856,\"s\":\"BTCUSDT\",\"U\":3244451803,\"u\":3244451820,\"b\":[[\"64653.16000000\",\"0.00000000\"],[\"64650.21000000\",\"0.04309000\"],[\"64648.55000000\",\"0.03240000\"],[\"64644.94000000\",\"0.00079000\"],[\"64642.34000000\",\"0.00000000\"],[\"64637.06000000\",\"0.00402000\"],[\"64633.13000000\",\"0.00000000\"],[\"64626.71000000\",\"0.04270000\"],[\"64620.45000000\",\"0.00000000\"]],\"a\":[[\"64656.18000000\",\"0.00000000\"],[\"64659.70000000\",\"0.00402000\"],[\"64661.27000000\",\"0.00079000\"],[\"64666.11000000\",\"0.00000000\"],[\"64667.95000000\",\"0.03463000\"],[\"64670.04000000\",\"0.04267000\"],[\"64672.64000000\",\"0.00163000\"],[\"64672.73000000\",\"0.00000000\"],[\"64674.43000000\",\"0.00000000\"],[\"64678.61000000\",\"0.00000000\"],[\"64698.41000000\",\"0.00000000\"],[\"64701.61000000\",\"0.00000000\"],[\"64706.25000000\",\"0.26580000\"]]}}"}
{"mode":"v11-raw-disruptor","partitions":4,"sequenceNumber":399,"routingSymbol":"SOLUSDT","localReceivedEpochMillis":1784431341847,"rawPayload":"{\"stream\":\"solusdt@depth@100ms\",\"data\":{\"e\":\"depthUpdate\",\"E\":1784431341856,\"s\":\"SOLUSDT\",\"U\":1609592175,\"u\":1609592177,\"b\":[[\"75.87000000\",\"14.13200000\"],[\"75.85000000\",\"59.53900000\"]],\"a\":[[\"75.91000000\",\"18.54200000\"]]}}"}
{"mode":"v11-raw-disruptor","partitions":4,"sequenceNumber":400,"routingSymbol":"ETHUSDT","localReceivedEpochMillis":1784431341847,"rawPayload":"{\"stream\":\"ethusdt@depth@100ms\",\"data\":{\"e\":\"depthUpdate\",\"E\":1784431341856,\"s\":\"ETHUSDT\",\"U\":2806198484,\"u\":2806198499,\"b\":[[\"1864.50000000\",\"0.02960000\"],[\"1864.32000000\",\"0.00000000\"],[\"1864.31000000\",\"1.14310000\"],[\"1864.24000000\",\"0.00000000\"],[\"1864.11000000\",\"1.34200000\"],[\"1863.91000000\",\"0.49920000\"]],\"a\":[[\"1864.81000000\",\"0.00000000\"],[\"1864.84000000\",\"1.34150000\"],[\"1864.88000000\",\"1.17720000\"],[\"1864.89000000\",\"0.13940000\"],[\"1865.07000000\",\"0.02940000\"],[\"1871.94000000\",\"0.00000000\"]]}}"}
{"mode":"v11-raw-disruptor","partitions":4,"sequenceNumber":401,"routingSymbol":"XRPUSDT","localReceivedEpochMillis":1784431341848,"rawPayload":"{\"stream\":\"xrpusdt@depth@100ms\",\"data\":{\"e\":\"depthUpdate\",\"E\":1784431341857,\"s\":\"XRPUSDT\",\"U\":752712560,\"u\":752712574,\"b\":[[\"1.09370000\",\"45.20000000\"],[\"1.09360000\",\"0.00000000\"],[\"1.09350000\",\"4828.60000000\"],[\"1.09340000\",\"237.70000000\"],[\"1.09320000\",\"3492.00000000\"],[\"1.09310000\",\"2099.00000000\"],[\"1.09300000\",\"2524.60000000\"]],\"a\":[[\"1.09390000\",\"45.20000000\"],[\"1.09410000\",\"1176.00000000\"],[\"1.09420000\",\"2224.70000000\"],[\"1.09450000\",\"4596.20000000\"],[\"1.09460000\",\"2074.70000000\"],[\"1.09740000\",\"0.00000000\"]]}}"}
