{"mode":"v9-depth-v5-spsc","workers":4,"sequenceNumber":1,"symbol":"ETHUSDT","exchangeEventTimeMillis":1784429248658,"localReceivedEpochMillis":1784429248649,"topSpreadTicks":27,"bid5Volume":3333,"ask5Volume":2666,"bid10Volume":38355,"ask10Volume":9504,"rawPayload":"{\"stream\":\"ethusdt@depth@100ms\",\"data\":{\"e\":\"depthUpdate\",\"E\":1784429248658,\"s\":\"ETHUSDT\",\"U\":2806163975,\"u\":2806163978,\"b\":[[\"1871.52000000\",\"0.00000000\"],[\"1871.43000000\",\"0.13890000\"],[\"1871.27000000\",\"0.48680000\"],[\"1871.13000000\",\"1.47500000\"]],\"a\":[[\"1872.10000000\",\"0.13880000\"],[\"1872.19000000\",\"0.00000000\"],[\"1872.40000000\",\"1.47400000\"],[\"1872.54000000\",\"0.00000000\"]]}}"}
{"mode":"v9-depth-v5-spsc","workers":4,"sequenceNumber":2,"symbol":"ETHUSDT","exchangeEventTimeMillis":1784429248858,"localReceivedEpochMillis":1784429248850,"topSpreadTicks":30,"bid5Volume":5267,"ask5Volume":2666,"bid10Volume":39241,"ask10Volume":9046,"rawPayload":"{\"stream\":\"ethusdt@depth@100ms\",\"data\":{\"e\":\"depthUpdate\",\"E\":1784429248858,\"s\":\"ETHUSDT\",\"U\":2806163979,\"u\":2806164001,\"b\":[[\"1871.80000000\",\"0.00000000\"],[\"1871.72000000\",\"1.10640000\"],[\"1871.70000000\",\"0.00000000\"],[\"1871.53000000\",\"1.33670000\"],[\"1871.46000000\",\"2.67510000\"],[\"1871.39000000\",\"0.00000000\"],[\"1871.34000000\",\"0.63690000\"],[\"1871.27000000\",\"0.00000000\"],[\"1870.99000000\",\"0.95530000\"],[\"1870.80000000\",\"0.00000000\"],[\"1870.56000000\",\"0.00000000\"],[\"1870.38000000\",\"2.05300000\"],[\"1869.43000000\",\"0.00000000\"],[\"1869.25000000\",\"2.95960000\"],[\"1868.31000000\",\"0.00000000\"],[\"1868.13000000\",\"5.99790000\"],[\"1866.06000000\",\"0.00000000\"],[\"1865.88000000\",\"13.72160000\"]],\"a\":[[\"1871.97000000\",\"0.00000000\"],[\"1872.16000000\",\"1.33620000\"],[\"1872.27000000\",\"0.00000000\"],[\"1872.37000000\",\"0.00000000\"],[\"1874.88000000\",\"2.04860000\"],[\"1875.06000000\",\"0.00000000\"],[\"1876.00000000\",\"3.02900000\"],[\"1876.19000000\",\"0.00000000\"],[\"1877.13000000\",\"6.30890000\"],[\"1877.31000000\",\"0.00000000\"]]}}"}
{"mode":"v9-depth-v5-spsc","workers":4,"sequenceNumber":3,"symbol":"ETHUSDT","exchangeEventTimeMillis":1784429248958,"localReceivedEpochMillis":1784429248950,"topSpreadTicks":30,"bid5Volume":5267,"ask5Volume":2666,"bid10Volume":39248,"ask10Volume":9485,"rawPayload":"{\"stream\":\"ethusdt@depth@100ms\",\"data\":{\"e\":\"depthUpdate\",\"E\":1784429248958,\"s\":\"ETHUSDT\",\"U\":2806164002,\"u\":2806164004,\"b\":[[\"1871.39000000\",\"0.64350000\"],[\"1871.34000000\",\"0.00000000\"]],\"a\":[[\"1872.29000000\",\"1.10100000\"]]}}"}
{"mode":"v9-depth-v5-spsc","workers":4,"sequenceNumber":4,"symbol":"SOLUSDT","exchangeEventTimeMillis":1784429249859,"localReceivedEpochMillis":1784429249851,"topSpreadTicks":1,"bid5Volume":148311,"ask5Volume":178772,"bid10Volume":404559,"ask10Volume":764061,"rawPayload":"{\"stream\":\"solusdt@depth@100ms\",\"data\":{\"e\":\"depthUpdate\",\"E\":1784429249859,\"s\":\"SOLUSDT\",\"U\":1609569455,\"u\":1609569461,\"b\":[[\"76.18000000\",\"65.67600000\"],[\"76.16000000\",\"117.06100000\"],[\"76.14000000\",\"6.06800000\"],[\"76.12000000\",\"374.45200000\"],[\"76.09000000\",\"334.12400000\"],[\"76.07000000\",\"490.69300000\"],[\"76.00000000\",\"0.00000000\"],[\"75.98000000\",\"677.56600000\"]],\"a\":[[\"76.36000000\",\"183.34000000\"],[\"76.38000000\",\"275.20700000\"],[\"76.40000000\",\"311.79200000\"],[\"76.42000000\",\"330.23500000\"],[\"76.45000000\",\"333.49400000\"],[\"76.47000000\",\"270.86200000\"]]}}"}
{"mode":"v9-depth-v5-spsc","workers":4,"sequenceNumber":5,"symbol":"ETHUSDT","exchangeEventTimeMillis":1784429249859,"localReceivedEpochMillis":1784429249852,"topSpreadTicks":30,"bid5Volume":5267,"ask5Volume":2666,"bid10Volume":39248,"ask10Volume":9485,"rawPayload":"{\"stream\":\"ethusdt@depth@100ms\",\"data\":{\"e\":\"depthUpdate\",\"E\":1784429249859,\"s\":\"ETHUSDT\",\"U\":2806164005,\"u\":2806164006,\"b\":[[\"1871.40000000\",\"0.00000000\"],[\"1871.27000000\",\"1.02590000\"]],\"a\":[[\"1872.35000000\",\"0.96640000\"],[\"1872.39000000\",\"0.00000000\"]]}}"}
{"mode":"v9-depth-v5-spsc","workers":4,"sequenceNumber":6,"symbol":"BTCUSDT","exchangeEventTimeMillis":1784429249859,"localReceivedEpochMillis":1784429249852,"topSpreadTicks":399,"bid5Volume":145,"ask5Volume":92,"bid10Volume":289,"ask10Volume":643,"rawPayload":"{\"stream\":\"btcusdt@depth@100ms\",\"data\":{\"e\":\"depthUpdate\",\"E\":1784429249859,\"s\":\"BTCUSDT\",\"U\":3244435080,\"u\":3244435080,\"b\":[],\"a\":[[\"81072.08000000\",\"0.00030000\"]]}}"}
{"mode":"v9-depth-v5-spsc","workers":4,"sequenceNumber":7,"symbol":"XRPUSDT","exchangeEventTimeMillis":1784429249859,"localReceivedEpochMillis":1784429249852,"topSpreadTicks":0,"bid5Volume":5670500,"ask5Volume":3027600,"bid10Volume":15852300,"ask10Volume":4234100,"rawPayload":"{\"stream\":\"xrpusdt@depth@100ms\",\"data\":{\"e\":\"depthUpdate\",\"E\":1784429249859,\"s\":\"XRPUSDT\",\"U\":752699220,\"u\":752699220,\"b\":[],\"a\":[[\"1.09690000\",\"3576.30000000\"],[\"1.09700000\",\"2311.70000000\"]]}}"}
{"mode":"v9-depth-v5-spsc","workers":4,"sequenceNumber":8,"symbol":"SOLUSDT","exchangeEventTimeMillis":1784429249959,"localReceivedEpochMillis":1784429249949,"topSpreadTicks":1,"bid5Volume":148311,"ask5Volume":229097,"bid10Volume":404559,"ask10Volume":814386,"rawPayload":"{\"stream\":\"solusdt@depth@100ms\",\"data\":{\"e\":\"depthUpdate\",\"E\":1784429249959,\"s\":\"SOLUSDT\",\"U\":1609569462,\"u\":1609569462,\"b\":[],\"a\":[[\"76.28000000\",\"84.83000000\"],[\"76.29000000\",\"54.58900000\"]]}}"}
{"mode":"v9-depth-v5-spsc","workers":4,"sequenceNumber":9,"symbol":"XRPUSDT","exchangeEventTimeMillis":1784429249959,"localReceivedEpochMillis":1784429249951,"topSpreadTicks":0,"bid5Volume":29584700,"ask5Volume":12947700,"bid10Volume":39766500,"ask10Volume":14145600,"rawPayload":"{\"stream\":\"xrpusdt@depth@100ms\",\"data\":{\"e\":\"depthUpdate\",\"E\":1784429249959,\"s\":\"XRPUSDT\",\"U\":752699221,\"u\":752699228,\"b\":[[\"1.09560000\",\"4566.50000000\"],[\"1.09540000\",\"1243.80000000\"],[\"1.09490000\",\"0.00000000\"],[\"1.09470000\",\"2519.40000000\"],[\"1.09430000\",\"0.00000000\"],[\"1.09410000\",\"3804.90000000\"],[\"1.09290000\",\"0.00000000\"],[\"1.09280000\",\"24434.70000000\"]],\"a\":[[\"1.09810000\",\"12741.00000000\"],[\"1.09830000\",\"0.00000000\"],[\"1.09880000\",\"15394.40000000\"],[\"1.09900000\",\"12778.20000000\"],[\"1.09940000\",\"16770.20000000\"],[\"1.09960000\",\"12632.40000000\"],[\"1.10070000\",\"9393.20000000\"],[\"1.10090000\",\"0.00000000\"]]}}"}
{"mode":"v9-depth-v5-spsc","workers":4,"sequenceNumber":10,"symbol":"BTCUSDT","exchangeEventTimeMillis":1784429250159,"localReceivedEpochMillis":1784429250150,"topSpreadTicks":399,"bid5Volume":150,"ask5Volume":92,"bid10Volume":294,"ask10Volume":643,"rawPayload":"{\"stream\":\"btcusdt@depth@100ms\",\"data\":{\"e\":\"depthUpdate\",\"E\":1784429250159,\"s\":\"BTCUSDT\",\"U\":3244435081,\"u\":3244435084,\"b\":[[\"64821.82000000\",\"0.01217000\"],[\"64820.18000000\",\"0.00000000\"],[\"64781.75000000\",\"0.00000000\"],[\"64759.71000000\",\"0.03960000\"]],\"a\":[]}}"}
{"mode":"v9-depth-v5-spsc","workers":4,"sequenceNumber":11,"symbol":"SOLUSDT","exchangeEventTimeMillis":1784429250259,"localReceivedEpochMillis":1784429250249,"topSpreadTicks":1,"bid5Volume":148311,"ask5Volume":229097,"bid10Volume":404559,"ask10Volume":814386,"rawPayload":"{\"stream\":\"solusdt@depth@100ms\",\"data\":{\"e\":\"depthUpdate\",\"E\":1784429250259,\"s\":\"SOLUSDT\",\"U\":1609569463,\"u\":1609569463,\"b\":[[\"76.14000000\",\"17.76700000\"]],\"a\":[]}}"}
{"mode":"v9-depth-v5-spsc","workers":4,"sequenceNumber":12,"symbol":"XRPUSDT","exchangeEventTimeMillis":1784429250259,"localReceivedEpochMillis":1784429250250,"topSpreadTicks":0,"bid5Volume":29584700,"ask5Volume":13210000,"bid10Volume":39766500,"ask10Volume":14407900,"rawPayload":"{\"stream\":\"xrpusdt@depth@100ms\",\"data\":{\"e\":\"depthUpdate\",\"E\":1784429250259,\"s\":\"XRPUSDT\",\"U\":752699229,\"u\":752699229,\"b\":[],\"a\":[[\"1.09850000\",\"12894.70000000\"]]}}"}
{"mode":"v9-depth-v5-spsc","workers":4,"sequenceNumber":13,"symbol":"BTCUSDT","exchangeEventTimeMillis":1784429250359,"localReceivedEpochMillis":1784429250351,"topSpreadTicks":399,"bid5Volume":150,"ask5Volume":92,"bid10Volume":294,"ask10Volume":643,"rawPayload":"{\"stream\":\"btcusdt@depth@100ms\",\"data\":{\"e\":\"depthUpdate\",\"E\":1784429250359,\"s\":\"BTCUSDT\",\"U\":3244435085,\"u\":3244435085,\"b\":[],\"a\":[[\"64914.49000000\",\"0.00000000\"]]}}"}
{"mode":"v9-depth-v5-spsc","workers":4,"sequenceNumber":14,"symbol":"SOLUSDT","exchangeEventTimeMillis":1784429250459,"localReceivedEpochMillis":1784429250451,"topSpreadTicks":1,"bid5Volume":148311,"ask5Volume":209529,"bid10Volume":404559,"ask10Volume":795486,"rawPayload":"{\"stream\":\"solusdt@depth@100ms\",\"data\":{\"e\":\"depthUpdate\",\"E\":1784429250459,\"s\":\"SOLUSDT\",\"U\":1609569464,\"u\":1609569467,\"b\":[],\"a\":[[\"76.30000000\",\"30.19500000\"],[\"76.31000000\",\"84.09900000\"]]}}"}
{"mode":"v9-depth-v5-spsc","workers":4,"sequenceNumber":15,"symbol":"BTCUSDT","exchangeEventTimeMillis":1784429250459,"localReceivedEpochMillis":1784429250451,"topSpreadTicks":399,"bid5Volume":150,"ask5Volume":92,"bid10Volume":294,"ask10Volume":643,"rawPayload":"{\"stream\":\"btcusdt@depth@100ms\",\"data\":{\"e\":\"depthUpdate\",\"E\":1784429250459,\"s\":\"BTCUSDT\",\"U\":3244435086,\"u\":3244435086,\"b\":[],\"a\":[[\"64914.49000000\",\"0.00011000\"]]}}"}
{"mode":"v9-depth-v5-spsc","workers":4,"sequenceNumber":16,"symbol":"SOLUSDT","exchangeEventTimeMillis":1784429250660,"localReceivedEpochMillis":1784429250650,"topSpreadTicks":1,"bid5Volume":148311,"ask5Volume":209529,"bid10Volume":404559,"ask10Volume":795654,"rawPayload":"{\"stream\":\"solusdt@depth@100ms\",\"data\":{\"e\":\"depthUpdate\",\"E\":1784429250660,\"s\":\"SOLUSDT\",\"U\":1609569468,\"u\":1609569471,\"b\":[],\"a\":[[\"76.30000000\",\"30.19500000\"],[\"76.31000000\",\"84.26700000\"]]}}"}
{"mode":"v9-depth-v5-spsc","workers":4,"sequenceNumber":17,"symbol":"ETHUSDT","exchangeEventTimeMillis":1784429251160,"localReceivedEpochMillis":1784429251151,"topSpreadTicks":30,"bid5Volume":5267,"ask5Volume":2666,"bid10Volume":39248,"ask10Volume":9485,"rawPayload":"{\"stream\":\"ethusdt@depth@100ms\",\"data\":{\"e\":\"depthUpdate\",\"E\":1784429251160,\"s\":\"ETHUSDT\",\"U\":2806164007,\"u\":2806164008,\"b\":[],\"a\":[[\"1872.03000000\",\"1.33630000\"],[\"1872.16000000\",\"0.00000000\"]]}}"}
{"mode":"v9-depth-v5-spsc","workers":4,"sequenceNumber":18,"symbol":"XRPUSDT","exchangeEventTimeMillis":1784429251160,"localReceivedEpochMillis":1784429251152,"topSpreadTicks":0,"bid5Volume":7461800,"ask5Volume":13210000,"bid10Volume":17643600,"ask10Volume":14407900,"rawPayload":"{\"stream\":\"xrpusdt@depth@100ms\",\"data\":{\"e\":\"depthUpdate\",\"E\":1784429251160,\"s\":\"XRPUSDT\",\"U\":752699230,\"u\":752699231,\"b\":[[\"1.09640000\",\"5633.60000000\"],[\"1.09630000\",\"2311.80000000\"]],\"a\":[]}}"}
{"mode":"v9-depth-v5-spsc","workers":4,"sequenceNumber":19,"symbol":"SOLUSDT","exchangeEventTimeMillis":1784429251460,"localReceivedEpochMillis":1784429251452,"topSpreadTicks":1,"bid5Volume":148311,"ask5Volume":223962,"bid10Volume":404559,"ask10Volume":795466,"rawPayload":"{\"stream\":\"solusdt@depth@100ms\",\"data\":{\"e\":\"depthUpdate\",\"E\":1784429251460,\"s\":\"SOLUSDT\",\"U\":1609569472,\"u\":1609569473,\"b\":[],\"a\":[[\"76.30000000\",\"44.62800000\"],[\"76.31000000\",\"69.64600000\"]]}}"}
{"mode":"v9-depth-v5-spsc","workers":4,"sequenceNumber":20,"symbol":"SOLUSDT","exchangeEventTimeMillis":1784429251560,"localReceivedEpochMillis":1784429251551,"topSpreadTicks":1,"bid5Volume":148311,"ask5Volume":209529,"bid10Volume":404559,"ask10Volume":794900,"rawPayload":"{\"stream\":\"solusdt@depth@100ms\",\"data\":{\"e\":\"depthUpdate\",\"E\":1784429251560,\"s\":\"SOLUSDT\",\"U\":1609569474,\"u\":1609569475,\"b\":[],\"a\":[[\"76.30000000\",\"30.19500000\"],[\"76.31000000\",\"83.51300000\"]]}}"}
{"mode":"v9-depth-v5-spsc","workers":4,"sequenceNumber":21,"symbol":"XRPUSDT","exchangeEventTimeMillis":1784429251660,"localReceivedEpochMillis":1784429251652,"topSpreadTicks":0,"bid5Volume":7461800,"ask5Volume":3922600,"bid10Volume":17643600,"ask10Volume":5120500,"rawPayload":"{\"stream\":\"xrpusdt@depth@100ms\",\"data\":{\"e\":\"depthUpdate\",\"E\":1784429251660,\"s\":\"XRPUSDT\",\"U\":752699232,\"u\":752699232,\"b\":[],\"a\":[[\"1.09690000\",\"2280.70000000\"],[\"1.09700000\",\"3607.30000000\"]]}}"}
{"mode":"v9-depth-v5-spsc","workers":4,"sequenceNumber":22,"symbol":"SOLUSDT","exchangeEventTimeMillis":1784429251760,"localReceivedEpochMillis":1784429251751,"topSpreadTicks":1,"bid5Volume":148311,"ask5Volume":222998,"bid10Volume":404559,"ask10Volume":794502,"rawPayload":"{\"stream\":\"solusdt@depth@100ms\",\"data\":{\"e\":\"depthUpdate\",\"E\":1784429251760,\"s\":\"SOLUSDT\",\"U\":1609569476,\"u\":1609569477,\"b\":[],\"a\":[[\"76.30000000\",\"43.66400000\"],[\"76.31000000\",\"69.64600000\"]]}}"}
{"mode":"v9-depth-v5-spsc","workers":4,"sequenceNumber":23,"symbol":"SOLUSDT","exchangeEventTimeMillis":1784429251860,"localReceivedEpochMillis":1784429251851,"topSpreadTicks":1,"bid5Volume":148311,"ask5Volume":192803,"bid10Volume":404559,"ask10Volume":764307,"rawPayload":"{\"stream\":\"solusdt@depth@100ms\",\"data\":{\"e\":\"depthUpdate\",\"E\":1784429251860,\"s\":\"SOLUSDT\",\"U\":1609569478,\"u\":1609569483,\"b\":[[\"76.23000000\",\"25.12100000\"],[\"76.22000000\",\"2.27100000\"],[\"76.19000000\",\"30.19500000\"]],\"a\":[[\"76.28000000\",\"34.50500000\"],[\"76.30000000\",\"63.79400000\"]]}}"}
{"mode":"v9-depth-v5-spsc","workers":4,"sequenceNumber":24,"symbol":"ETHUSDT","exchangeEventTimeMillis":1784429251960,"localReceivedEpochMillis":1784429251951,"topSpreadTicks":30,"bid5Volume":4517,"ask5Volume":2666,"bid10Volume":38498,"ask10Volume":9485,"rawPayload":"{\"stream\":\"ethusdt@depth@100ms\",\"data\":{\"e\":\"depthUpdate\",\"E\":1784429251960,\"s\":\"ETHUSDT\",\"U\":2806164009,\"u\":2806164011,\"b\":[[\"1871.46000000\",\"1.92510000\"],[\"1871.35000000\",\"0.00000000\"],[\"1870.30000000\",\"1.63970000\"]],\"a\":[]}}"}
{"mode":"v9-depth-v5-spsc","workers":4,"sequenceNumber":25,"symbol":"ETHUSDT","exchangeEventTimeMillis":1784429252161,"localReceivedEpochMillis":1784429252151,"topSpreadTicks":37,"bid5Volume":3373,"ask5Volume":2666,"bid10Volume":8579,"ask10Volume":9543,"rawPayload":"{\"stream\":\"ethusdt@depth@100ms\",\"data\":{\"e\":\"depthUpdate\",\"E\":1784429252161,\"s\":\"ETHUSDT\",\"U\":2806164012,\"u\":2806164016,\"b\":[[\"1871.72000000\",\"0.00000000\"],[\"1871.65000000\",\"1.13760000\"],[\"1871.54000000\",\"0.75000000\"]],\"a\":[[\"1872.23000000\",\"1.15910000\"],[\"1872.29000000\",\"0.00000000\"]]}}"}
{"mode":"v9-depth-v5-spsc","workers":4,"sequenceNumber":26,"symbol":"BNBUSDT","exchangeEventTimeMillis":1784429252161,"localReceivedEpochMillis":1784429252152,"topSpreadTicks":10,"bid5Volume":4595,"ask5Volume":6768,"bid10Volume":21069,"ask10Volume":259432,"rawPayload":"{\"stream\":\"bnbusdt@depth@100ms\",\"data\":{\"e\":\"depthUpdate\",\"E\":1784429252161,\"s\":\"BNBUSDT\",\"U\":1236327921,\"u\":1236327921,\"b\":[],\"a\":[[\"571.00000000\",\"1.61500000\"],[\"571.01000000\",\"0.00000000\"]]}}"}
{"mode":"v9-depth-v5-spsc","workers":4,"sequenceNumber":27,"symbol":"SOLUSDT","exchangeEventTimeMillis":1784429252361,"localReceivedEpochMillis":1784429252352,"topSpreadTicks":1,"bid5Volume":148311,"ask5Volume":192803,"bid10Volume":434754,"ask10Volume":764307,"rawPayload":"{\"stream\":\"solusdt@depth@100ms\",\"data\":{\"e\":\"depthUpdate\",\"E\":1784429252361,\"s\":\"SOLUSDT\",\"U\":1609569484,\"u\":1609569485,\"b\":[[\"76.18000000\",\"95.87100000\"]],\"a\":[[\"76.32000000\",\"30.19500000\"]]}}"}
{"mode":"v9-depth-v5-spsc","workers":4,"sequenceNumber":28,"symbol":"BTCUSDT","exchangeEventTimeMillis":1784429252661,"localReceivedEpochMillis":1784429252653,"topSpreadTicks":399,"bid5Volume":150,"ask5Volume":92,"bid10Volume":294,"ask10Volume":643,"rawPayload":"{\"stream\":\"btcusdt@depth@100ms\",\"data\":{\"e\":\"depthUpdate\",\"E\":1784429252661,\"s\":\"BTCUSDT\",\"U\":3244435087,\"u\":3244435087,\"b\":[],\"a\":[[\"81072.08000000\",\"0.00045000\"]]}}"}
{"mode":"v9-depth-v5-spsc","workers":4,"sequenceNumber":29,"symbol":"SOLUSDT","exchangeEventTimeMillis":1784429252761,"localReceivedEpochMillis":1784429252752,"topSpreadTicks":1,"bid5Volume":178506,"ask5Volume":192803,"bid10Volume":434754,"ask10Volume":764307,"rawPayload":"{\"stream\":\"solusdt@depth@100ms\",\"data\":{\"e\":\"depthUpdate\",\"E\":1784429252761,\"s\":\"SOLUSDT\",\"U\":1609569486,\"u\":1609569487,\"b\":[[\"76.22000000\",\"32.46600000\"],[\"76.18000000\",\"65.67600000\"]],\"a\":[]}}"}
{"mode":"v9-depth-v5-spsc","workers":4,"sequenceNumber":30,"symbol":"ETHUSDT","exchangeEventTimeMillis":1784429252761,"localReceivedEpochMillis":1784429252752,"topSpreadTicks":37,"bid5Volume":3373,"ask5Volume":2666,"bid10Volume":8743,"ask10Volume":9543,"rawPayload":"{\"stream\":\"ethusdt@depth@100ms\",\"data\":{\"e\":\"depthUpdate\",\"E\":1784429252761,\"s\":\"ETHUSDT\",\"U\":2806164017,\"u\":2806164018,\"b\":[[\"1871.35000000\",\"1.63970000\"],[\"1870.30000000\",\"0.00000000\"]],\"a\":[]}}"}
{"mode":"v9-depth-v5-spsc","workers":4,"sequenceNumber":31,"symbol":"SOLUSDT","exchangeEventTimeMillis":1784429253061,"localReceivedEpochMillis":1784429253052,"topSpreadTicks":1,"bid5Volume":208701,"ask5Volume":179334,"bid10Volume":452521,"ask10Volume":764659,"rawPayload":"{\"stream\":\"solusdt@depth@100ms\",\"data\":{\"e\":\"depthUpdate\",\"E\":1784429253061,\"s\":\"SOLUSDT\",\"U\":1609569488,\"u\":1609569491,\"b\":[[\"76.23000000\",\"55.31600000\"],[\"76.19000000\",\"0.00000000\"]],\"a\":[[\"76.30000000\",\"50.32500000\"],[\"76.31000000\",\"83.46700000\"]]}}"}
{"mode":"v9-depth-v5-spsc","workers":4,"sequenceNumber":32,"symbol":"ETHUSDT","exchangeEventTimeMillis":1784429253161,"localReceivedEpochMillis":1784429253152,"topSpreadTicks":36,"bid5Volume":3373,"ask5Volume":2666,"bid10Volume":8743,"ask10Volume":9543,"rawPayload":"{\"stream\":\"ethusdt@depth@100ms\",\"data\":{\"e\":\"depthUpdate\",\"E\":1784429253161,\"s\":\"ETHUSDT\",\"U\":2806164019,\"u\":2806164020,\"b\":[[\"1871.66000000\",\"0.75000000\"],[\"1871.54000000\",\"0.00000000\"]],\"a\":[]}}"}
{"mode":"v9-depth-v5-spsc","workers":4,"sequenceNumber":33,"symbol":"BNBUSDT","exchangeEventTimeMillis":1784429253161,"localReceivedEpochMillis":1784429253153,"topSpreadTicks":10,"bid5Volume":4595,"ask5Volume":6768,"bid10Volume":21069,"ask10Volume":259432,"rawPayload":"{\"stream\":\"bnbusdt@depth@100ms\",\"data\":{\"e\":\"depthUpdate\",\"E\":1784429253161,\"s\":\"BNBUSDT\",\"U\":1236327922,\"u\":1236327922,\"b\":[],\"a\":[[\"571.00000000\",\"0.00000000\"],[\"571.01000000\",\"1.61500000\"]]}}"}
{"mode":"v9-depth-v5-spsc","workers":4,"sequenceNumber":34,"symbol":"ETHUSDT","exchangeEventTimeMillis":1784429253561,"localReceivedEpochMillis":1784429253553,"topSpreadTicks":32,"bid5Volume":3373,"ask5Volume":2666,"bid10Volume":8829,"ask10Volume":9543,"rawPayload":"{\"stream\":\"ethusdt@depth@100ms\",\"data\":{\"e\":\"depthUpdate\",\"E\":1784429253561,\"s\":\"ETHUSDT\",\"U\":2806164021,\"u\":2806164027,\"b\":[[\"1871.66000000\",\"0.00000000\"],[\"1871.56000000\",\"0.75000000\"],[\"1871.39000000\",\"0.00000000\"],[\"1871.35000000\",\"0.00000000\"],[\"1871.32000000\",\"0.89350000\"]],\"a\":[[\"1871.97000000\",\"1.33640000\"],[\"1872.03000000\",\"0.00000000\"]]}}"}
{"mode":"v9-depth-v5-spsc","workers":4,"sequenceNumber":35,"symbol":"ETHUSDT","exchangeEventTimeMillis":1784429253662,"localReceivedEpochMillis":1784429253653,"topSpreadTicks":32,"bid5Volume":3373,"ask5Volume":3360,"bid10Volume":8829,"ask10Volume":9740,"rawPayload":"{\"stream\":\"ethusdt@depth@100ms\",\"data\":{\"e\":\"depthUpdate\",\"E\":1784429253662,\"s\":\"ETHUSDT\",\"U\":2806164028,\"u\":2806164028,\"b\":[],\"a\":[[\"1872.02000000\",\"0.00000000\"]]}}"}
{"mode":"v9-depth-v5-spsc","workers":4,"sequenceNumber":36,"symbol":"SOLUSDT","exchangeEventTimeMillis":1784429253862,"localReceivedEpochMillis":1784429253854,"topSpreadTicks":1,"bid5Volume":208701,"ask5Volume":179334,"bid10Volume":452521,"ask10Volume":765137,"rawPayload":"{\"stream\":\"solusdt@depth@100ms\",\"data\":{\"e\":\"depthUpdate\",\"E\":1784429253862,\"s\":\"SOLUSDT\",\"U\":1609569492,\"u\":1609569495,\"b\":[],\"a\":[[\"76.30000000\",\"50.32500000\"],[\"76.31000000\",\"83.94500000\"]]}}"}
{"mode":"v9-depth-v5-spsc","workers":4,"sequenceNumber":37,"symbol":"SOLUSDT","exchangeEventTimeMillis":1784429253962,"localReceivedEpochMillis":1784429253953,"topSpreadTicks":1,"bid5Volume":208701,"ask5Volume":209529,"bid10Volume":452521,"ask10Volume":1040855,"rawPayload":"{\"stream\":\"solusdt@depth@100ms\",\"data\":{\"e\":\"depthUpdate\",\"E\":1784429253962,\"s\":\"SOLUSDT\",\"U\":1609569496,\"u\":1609569501,\"b\":[[\"76.25000000\",\"31.55600000\"],[\"76.24000000\",\"39.93000000\"]],\"a\":[[\"76.28000000\",\"66.85500000\"],[\"76.29000000\",\"72.56400000\"],[\"76.30000000\",\"30.19500000\"],[\"76.32000000\",\"0.00000000\"]]}}"}
{"mode":"v9-depth-v5-spsc","workers":4,"sequenceNumber":38,"symbol":"SOLUSDT","exchangeEventTimeMillis":1784429254062,"localReceivedEpochMillis":1784429254052,"topSpreadTicks":1,"bid5Volume":208701,"ask5Volume":223780,"bid10Volume":452521,"ask10Volume":1040807,"rawPayload":"{\"stream\":\"solusdt@depth@100ms\",\"data\":{\"e\":\"depthUpdate\",\"E\":1784429254062,\"s\":\"SOLUSDT\",\"U\":1609569502,\"u\":1609569503,\"b\":[],\"a\":[[\"76.30000000\",\"44.44600000\"],[\"76.31000000\",\"69.64600000\"]]}}"}
{"mode":"v9-depth-v5-spsc","workers":4,"sequenceNumber":39,"symbol":"BTCUSDT","exchangeEventTimeMillis":1784429254162,"localReceivedEpochMillis":1784429254154,"topSpreadTicks":399,"bid5Volume":150,"ask5Volume":92,"bid10Volume":294,"ask10Volume":643,"rawPayload":"{\"stream\":\"btcusdt@depth@100ms\",\"data\":{\"e\":\"depthUpdate\",\"E\":1784429254162,\"s\":\"BTCUSDT\",\"U\":3244435088,\"u\":3244435088,\"b\":[],\"a\":[[\"64914.49000000\",\"0.00000000\"]]}}"}
{"mode":"v9-depth-v5-spsc","workers":4,"sequenceNumber":40,"symbol":"ETHUSDT","exchangeEventTimeMillis":1784429254162,"localReceivedEpochMillis":1784429254155,"topSpreadTicks":32,"bid5Volume":3373,"ask5Volume":3360,"bid10Volume":8993,"ask10Volume":9740,"rawPayload":"{\"stream\":\"ethusdt@depth@100ms\",\"data\":{\"e\":\"depthUpdate\",\"E\":1784429254162,\"s\":\"ETHUSDT\",\"U\":2806164029,\"u\":2806164029,\"b\":[[\"1871.24000000\",\"1.63970000\"]],\"a\":[]}}"}
{"mode":"v9-depth-v5-spsc","workers":4,"sequenceNumber":41,"symbol":"BTCUSDT","exchangeEventTimeMillis":1784429254262,"localReceivedEpochMillis":1784429254253,"topSpreadTicks":399,"bid5Volume":150,"ask5Volume":92,"bid10Volume":294,"ask10Volume":643,"rawPayload":"{\"stream\":\"btcusdt@depth@100ms\",\"data\":{\"e\":\"depthUpdate\",\"E\":1784429254262,\"s\":\"BTCUSDT\",\"U\":3244435089,\"u\":3244435089,\"b\":[],\"a\":[[\"64914.49000000\",\"0.00011000\"]]}}"}
{"mode":"v9-depth-v5-spsc","workers":4,"sequenceNumber":42,"symbol":"SOLUSDT","exchangeEventTimeMillis":1784429254362,"localReceivedEpochMillis":1784429254354,"topSpreadTicks":1,"bid5Volume":208701,"ask5Volume":179334,"bid10Volume":452521,"ask10Volume":1009760,"rawPayload":"{\"stream\":\"solusdt@depth@100ms\",\"data\":{\"e\":\"depthUpdate\",\"E\":1784429254362,\"s\":\"SOLUSDT\",\"U\":1609569504,\"u\":1609569509,\"b\":[[\"76.25000000\",\"13.54400000\"],[\"76.24000000\",\"57.94200000\"]],\"a\":[[\"76.28000000\",\"16.53000000\"],[\"76.30000000\",\"50.32500000\"],[\"76.31000000\",\"83.04500000\"]]}}"}
{"mode":"v9-depth-v5-spsc","workers":4,"sequenceNumber":43,"symbol":"SOLUSDT","exchangeEventTimeMillis":1784429254562,"localReceivedEpochMillis":1784429254553,"topSpreadTicks":1,"bid5Volume":208701,"ask5Volume":192759,"bid10Volume":452521,"ask10Volume":1009786,"rawPayload":"{\"stream\":\"solusdt@depth@100ms\",\"data\":{\"e\":\"depthUpdate\",\"E\":1784429254562,\"s\":\"SOLUSDT\",\"U\":1609569510,\"u\":1609569511,\"b\":[],\"a\":[[\"76.30000000\",\"63.75000000\"],[\"76.31000000\",\"69.64600000\"]]}}"}
{"mode":"v9-depth-v5-spsc","workers":4,"sequenceNumber":44,"symbol":"SOLUSDT","exchangeEventTimeMillis":1784429255163,"localReceivedEpochMillis":1784429255155,"topSpreadTicks":1,"bid5Volume":208701,"ask5Volume":209529,"bid10Volume":452521,"ask10Volume":1039999,"rawPayload":"{\"stream\":\"solusdt@depth@100ms\",\"data\":{\"e\":\"depthUpdate\",\"E\":1784429255163,\"s\":\"SOLUSDT\",\"U\":1609569512,\"u\":1609569522,\"b\":[],\"a\":[[\"76.28000000\",\"66.85500000\"],[\"76.30000000\",\"30.19500000\"],[\"76.31000000\",\"83.08400000\"],[\"76.33000000\",\"13.12100000\"],[\"76.37000000\",\"0.00000000\"]]}}"}
{"mode":"v9-depth-v5-spsc","workers":4,"sequenceNumber":45,"symbol":"BTCUSDT","exchangeEventTimeMillis":1784429255463,"localReceivedEpochMillis":1784429255454,"topSpreadTicks":399,"bid5Volume":150,"ask5Volume":115,"bid10Volume":294,"ask10Volume":631,"rawPayload":"{\"stream\":\"btcusdt@depth@100ms\",\"data\":{\"e\":\"depthUpdate\",\"E\":1784429255463,\"s\":\"BTCUSDT\",\"U\":3244435090,\"u\":3244435093,\"b\":[],\"a\":[[\"64840.95000000\",\"0.02474000\"],[\"64845.46000000\",\"0.00160000\"],[\"64846.32000000\",\"0.00000000\"],[\"64847.50000000\",\"0.00000000\"]]}}"}
{"mode":"v9-depth-v5-spsc","workers":4,"sequenceNumber":46,"symbol":"SOLUSDT","exchangeEventTimeMillis":1784429256263,"localReceivedEpochMillis":1784429256255,"topSpreadTicks":1,"bid5Volume":208701,"ask5Volume":223335,"bid10Volume":452521,"ask10Volume":1040367,"rawPayload":"{\"stream\":\"solusdt@depth@100ms\",\"data\":{\"e\":\"depthUpdate\",\"E\":1784429256263,\"s\":\"SOLUSDT\",\"U\":1609569523,\"u\":1609569524,\"b\":[],\"a\":[[\"76.30000000\",\"44.00100000\"],[\"76.31000000\",\"69.64600000\"]]}}"}
{"mode":"v9-depth-v5-spsc","workers":4,"sequenceNumber":47,"symbol":"BTCUSDT","exchangeEventTimeMillis":1784429256363,"localReceivedEpochMillis":1784429256355,"topSpreadTicks":399,"bid5Volume":150,"ask5Volume":115,"bid10Volume":294,"ask10Volume":631,"rawPayload":"{\"stream\":\"btcusdt@depth@100ms\",\"data\":{\"e\":\"depthUpdate\",\"E\":1784429256363,\"s\":\"BTCUSDT\",\"U\":3244435094,\"u\":3244435095,\"b\":[],\"a\":[[\"64844.81000000\",\"0.00162000\"],[\"64845.46000000\",\"0.00000000\"]]}}"}
{"mode":"v9-depth-v5-spsc","workers":4,"sequenceNumber":48,"symbol":"SOLUSDT","exchangeEventTimeMillis":1784429256864,"localReceivedEpochMillis":1784429256857,"topSpreadTicks":1,"bid5Volume":208701,"ask5Volume":209529,"bid10Volume":452521,"ask10Volume":765099,"rawPayload":"{\"stream\":\"solusdt@depth@100ms\",\"data\":{\"e\":\"depthUpdate\",\"E\":1784429256864,\"s\":\"SOLUSDT\",\"U\":1609569525,\"u\":1609569528,\"b\":[],\"a\":[[\"76.30000000\",\"30.19500000\"],[\"76.31000000\",\"69.64600000\"],[\"76.32000000\",\"14.25600000\"]]}}"}
{"mode":"v9-depth-v5-spsc","workers":4,"sequenceNumber":49,"symbol":"SOLUSDT","exchangeEventTimeMillis":1784429257064,"localReceivedEpochMillis":1784429257060,"topSpreadTicks":1,"bid5Volume":208701,"ask5Volume":209529,"bid10Volume":452521,"ask10Volume":765099,"rawPayload":"{\"stream\":\"solusdt@depth@100ms\",\"data\":{\"e\":\"depthUpdate\",\"E\":1784429257064,\"s\":\"SOLUSDT\",\"U\":1609569529,\"u\":1609569530,\"b\":[[\"76.25000000\",\"31.55600000\"],[\"76.24000000\",\"39.93000000\"]],\"a\":[[\"76.28000000\",\"84.83000000\"],[\"76.29000000\",\"54.58900000\"]]}}"}
{"mode":"v9-depth-v5-spsc","workers":4,"sequenceNumber":50,"symbol":"BTCUSDT","exchangeEventTimeMillis":1784429257064,"localReceivedEpochMillis":1784429257060,"topSpreadTicks":399,"bid5Volume":150,"ask5Volume":115,"bid10Volume":294,"ask10Volume":631,"rawPayload":"{\"stream\":\"btcusdt@depth@100ms\",\"data\":{\"e\":\"depthUpdate\",\"E\":1784429257064,\"s\":\"BTCUSDT\",\"U\":3244435096,\"u\":3244435099,\"b\":[[\"64683.17000000\",\"0.00000000\"],[\"64678.96000000\",\"0.17331000\"],[\"64605.36000000\",\"0.00000000\"],[\"64601.16000000\",\"0.40717000\"]],\"a\":[[\"64990.12000000\",\"0.17644000\"],[\"64994.34000000\",\"0.00000000\"],[\"65067.92000000\",\"0.42827000\"],[\"65072.15000000\",\"0.00000000\"]]}}"}
{"mode":"v9-depth-v5-spsc","workers":4,"sequenceNumber":51,"symbol":"BTCUSDT","exchangeEventTimeMillis":1784429257164,"localReceivedEpochMillis":1784429257155,"topSpreadTicks":399,"bid5Volume":150,"ask5Volume":115,"bid10Volume":294,"ask10Volume":631,"rawPayload":"{\"stream\":\"btcusdt@depth@100ms\",\"data\":{\"e\":\"depthUpdate\",\"E\":1784429257164,\"s\":\"BTCUSDT\",\"U\":3244435100,\"u\":3244435104,\"b\":[[\"64760.98000000\",\"0.00000000\"],[\"64756.76000000\",\"0.05832000\"],[\"64722.07000000\",\"0.00000000\"],[\"64717.86000000\",\"0.08812000\"]],\"a\":[[\"64912.32000000\",\"0.06043000\"],[\"64916.54000000\",\"0.00000000\"],[\"64951.22000000\",\"0.09239000\"],[\"64955.44000000\",\"0.00000000\"],[\"81072.08000000\",\"0.00030000\"]]}}"}
{"mode":"v9-depth-v5-spsc","workers":4,"sequenceNumber":52,"symbol":"BTCUSDT","exchangeEventTimeMillis":1784429257264,"localReceivedEpochMillis":1784429257255,"topSpreadTicks":399,"bid5Volume":150,"ask5Volume":115,"bid10Volume":294,"ask10Volume":631,"rawPayload":"{\"stream\":\"btcusdt@depth@100ms\",\"data\":{\"e\":\"depthUpdate\",\"E\":1784429257264,\"s\":\"BTCUSDT\",\"U\":3244435105,\"u\":3244435105,\"b\":[],\"a\":[[\"81072.08000000\",\"0.00045000\"]]}}"}
{"mode":"v9-depth-v5-spsc","workers":4,"sequenceNumber":53,"symbol":"ETHUSDT","exchangeEventTimeMillis":1784429257364,"localReceivedEpochMillis":1784429257354,"topSpreadTicks":32,"bid5Volume":3373,"ask5Volume":3360,"bid10Volume":8993,"ask10Volume":9740,"rawPayload":"{\"stream\":\"ethusdt@depth@100ms\",\"data\":{\"e\":\"depthUpdate\",\"E\":1784429257364,\"s\":\"ETHUSDT\",\"U\":2806164030,\"u\":2806164031,\"b\":[[\"1871.34000000\",\"1.02590000\"],[\"1871.27000000\",\"0.00000000\"]],\"a\":[[\"1872.33000000\",\"0.96640000\"],[\"1872.35000000\",\"0.00000000\"]]}}"}
{"mode":"v9-depth-v5-spsc","workers":4,"sequenceNumber":54,"symbol":"SOLUSDT","exchangeEventTimeMillis":1784429258065,"localReceivedEpochMillis":1784429258056,"topSpreadTicks":1,"bid5Volume":208701,"ask5Volume":179334,"bid10Volume":452521,"ask10Volume":765099,"rawPayload":"{\"stream\":\"solusdt@depth@100ms\",\"data\":{\"e\":\"depthUpdate\",\"E\":1784429258065,\"s\":\"SOLUSDT\",\"U\":1609569531,\"u\":1609569536,\"b\":[[\"76.25000000\",\"13.54400000\"],[\"76.24000000\",\"57.94200000\"]],\"a\":[[\"76.28000000\",\"16.53000000\"],[\"76.29000000\",\"72.56400000\"],[\"76.30000000\",\"50.32500000\"],[\"76.32000000\",\"44.45100000\"]]}}"}
{"mode":"v9-depth-v5-spsc","workers":4,"sequenceNumber":55,"symbol":"BTCUSDT","exchangeEventTimeMillis":1784429258065,"localReceivedEpochMillis":1784429258056,"topSpreadTicks":399,"bid5Volume":150,"ask5Volume":115,"bid10Volume":294,"ask10Volume":631,"rawPayload":"{\"stream\":\"btcusdt@depth@100ms\",\"data\":{\"e\":\"depthUpdate\",\"E\":1784429258065,\"s\":\"BTCUSDT\",\"U\":3244435106,\"u\":3244435107,\"b\":[],\"a\":[[\"64914.49000000\",\"0.00011000\"]]}}"}
{"mode":"v9-depth-v5-spsc","workers":4,"sequenceNumber":56,"symbol":"BTCUSDT","exchangeEventTimeMillis":1784429258165,"localReceivedEpochMillis":1784429258156,"topSpreadTicks":344,"bid5Volume":150,"ask5Volume":101,"bid10Volume":304,"ask10Volume":566,"rawPayload":"{\"stream\":\"btcusdt@depth@100ms\",\"data\":{\"e\":\"depthUpdate\",\"E\":1784429258165,\"s\":\"BTCUSDT\",\"U\":3244435108,\"u\":3244435111,\"b\":[[\"64814.88000000\",\"0.00000000\"],[\"64813.91000000\",\"0.02826000\"]],\"a\":[[\"64832.58000000\",\"0.02820000\"],[\"64848.59000000\",\"0.31913000\"],[\"64857.42000000\",\"0.00000000\"]]}}"}
{"mode":"v9-depth-v5-spsc","workers":4,"sequenceNumber":57,"symbol":"BNBUSDT","exchangeEventTimeMillis":1784429258265,"localReceivedEpochMillis":1784429258255,"topSpreadTicks":10,"bid5Volume":4595,"ask5Volume":6768,"bid10Volume":21069,"ask10Volume":259432,"rawPayload":"{\"stream\":\"bnbusdt@depth@100ms\",\"data\":{\"e\":\"depthUpdate\",\"E\":1784429258265,\"s\":\"BNBUSDT\",\"U\":1236327923,\"u\":1236327923,\"b\":[[\"569.41000000\",\"0.00000000\"],[\"569.40000000\",\"0.00400000\"]],\"a\":[]}}"}
{"mode":"v9-depth-v5-spsc","workers":4,"sequenceNumber":58,"symbol":"BNBUSDT","exchangeEventTimeMillis":1784429258465,"localReceivedEpochMillis":1784429258455,"topSpreadTicks":10,"bid5Volume":4595,"ask5Volume":7382,"bid10Volume":25182,"ask10Volume":261757,"rawPayload":"{\"stream\":\"bnbusdt@depth@100ms\",\"data\":{\"e\":\"depthUpdate\",\"E\":1784429258465,\"s\":\"BNBUSDT\",\"U\":1236327924,\"u\":1236327924,\"b\":[[\"570.68000000\",\"0.00000000\"],[\"569.44000000\",\"0.00000000\"],[\"568.15000000\",\"0.00000000\"]],\"a\":[[\"571.09000000\",\"0.00000000\"],[\"572.30000000\",\"0.00000000\"],[\"573.59000000\",\"0.00000000\"]]}}"}
{"mode":"v9-depth-v5-spsc","workers":4,"sequenceNumber":59,"symbol":"BTCUSDT","exchangeEventTimeMillis":1784429258465,"localReceivedEpochMillis":1784429258456,"topSpreadTicks":344,"bid5Volume":150,"ask5Volume":101,"bid10Volume":304,"ask10Volume":566,"rawPayload":"{\"stream\":\"btcusdt@depth@100ms\",\"data\":{\"e\":\"depthUpdate\",\"E\":1784429258465,\"s\":\"BTCUSDT\",\"U\":3244435112,\"u\":3244435112,\"b\":[],\"a\":[[\"81072.08000000\",\"0.00030000\"]]}}"}
{"mode":"v9-depth-v5-spsc","workers":4,"sequenceNumber":60,"symbol":"ETHUSDT","exchangeEventTimeMillis":1784429258565,"localReceivedEpochMillis":1784429258556,"topSpreadTicks":32,"bid5Volume":3392,"ask5Volume":3350,"bid10Volume":9012,"ask10Volume":15511,"rawPayload":"{\"stream\":\"ethusdt@depth@100ms\",\"data\":{\"e\":\"depthUpdate\",\"E\":1784429258565,\"s\":\"ETHUSDT\",\"U\":2806164032,\"u\":2806164041,\"b\":[[\"1871.73000000\",\"0.00000000\"],[\"1871.65000000\",\"1.15620000\"]],\"a\":[[\"1872.23000000\",\"1.14950000\"],[\"1872.30000000\",\"0.00000000\"],[\"1872.39000000\",\"6.44320000\"],[\"1872.92000000\",\"0.00000000\"]]}}"}
{"mode":"v9-depth-v5-spsc","workers":4,"sequenceNumber":61,"symbol":"BTCUSDT","exchangeEventTimeMillis":1784429259065,"localReceivedEpochMillis":1784429259056,"topSpreadTicks":344,"bid5Volume":151,"ask5Volume":101,"bid10Volume":273,"ask10Volume":566,"rawPayload":"{\"stream\":\"btcusdt@depth@100ms\",\"data\":{\"e\":\"depthUpdate\",\"E\":1784429259065,\"s\":\"BTCUSDT\",\"U\":3244435113,\"u\":3244435119,\"b\":[[\"64826.72000000\",\"0.04000000\"],[\"64819.69000000\",\"0.03859000\"],[\"64813.99000000\",\"0.00000000\"]],\"a\":[[\"64844.81000000\",\"0.00000000\"],[\"64844.93000000\",\"0.00161000\"],[\"64846.10000000\",\"0.00000000\"]]}}"}
{"mode":"v9-depth-v5-spsc","workers":4,"sequenceNumber":62,"symbol":"SOLUSDT","exchangeEventTimeMillis":1784429259065,"localReceivedEpochMillis":1784429259056,"topSpreadTicks":1,"bid5Volume":208701,"ask5Volume":209529,"bid10Volume":452521,"ask10Volume":765099,"rawPayload":"{\"stream\":\"solusdt@depth@100ms\",\"data\":{\"e\":\"depthUpdate\",\"E\":1784429259065,\"s\":\"SOLUSDT\",\"U\":1609569537,\"u\":1609569540,\"b\":[],\"a\":[[\"76.28000000\",\"66.85500000\"],[\"76.30000000\",\"30.19500000\"],[\"76.32000000\",\"14.25600000\"]]}}"}
{"mode":"v9-depth-v5-spsc","workers":4,"sequenceNumber":63,"symbol":"ETHUSDT","exchangeEventTimeMillis":1784429259065,"localReceivedEpochMillis":1784429259056,"topSpreadTicks":14,"bid5Volume":4293,"ask5Volume":4210,"bid10Volume":9141,"ask10Volume":15709,"rawPayload":"{\"stream\":\"ethusdt@depth@100ms\",\"data\":{\"e\":\"depthUpdate\",\"E\":1784429259065,\"s\":\"ETHUSDT\",\"U\":2806164042,\"u\":2806164078,\"b\":[[\"1871.92000000\",\"1.11000000\"],[\"1871.85000000\",\"0.00000000\"],[\"1871.78000000\",\"0.00000000\"],[\"1871.72000000\",\"0.00000000\"],[\"1871.66000000\",\"1.33660000\"],[\"1871.65000000\",\"0.00000000\"],[\"1871.64000000\",\"1.06890000\"],[\"1871.53000000\",\"0.00000000\"],[\"1871.38000000\",\"0.00000000\"],[\"1871.32000000\",\"0.00000000\"],[\"1871.20000000\",\"1.60350000\"],[\"1870.99000000\",\"0.00000000\"],[\"1863.00000000\",\"0.00000000\"]],\"a\":[[\"1871.97000000\",\"0.00000000\"],[\"1872.15000000\",\"0.00000000\"],[\"1872.22000000\",\"0.00000000\"],[\"1872.23000000\",\"0.00000000\"],[\"1872.29000000\",\"0.00000000\"],[\"1872.36000000\",\"0.00000000\"],[\"1872.39000000\",\"0.00000000\"],[\"1872.42000000\",\"0.00000000\"],[\"1872.43000000\",\"1.60350000\"],[\"1872.49000000\",\"1.11450000\"],[\"1872.59000000\",\"6.44560000\"],[\"1879.28000000\",\"0.00000000\"],[\"1879.40000000\",\"7.26670000\"],[\"1879.59000000\",\"8.03680000\"],[\"1880.83000000\",\"0.00000000\"],[\"1880.98000000\",\"0.00000000\"]]}}"}
{"mode":"v9-depth-v5-spsc","workers":4,"sequenceNumber":64,"symbol":"XRPUSDT","exchangeEventTimeMillis":1784429259065,"localReceivedEpochMillis":1784429259057,"topSpreadTicks":0,"bid5Volume":5332000,"ask5Volume":2678300,"bid10Volume":15513800,"ask10Volume":3876200,"rawPayload":"{\"stream\":\"xrpusdt@depth@100ms\",\"data\":{\"e\":\"depthUpdate\",\"E\":1784429259065,\"s\":\"XRPUSDT\",\"U\":752699233,\"u\":752699238,\"b\":[[\"1.09660000\",\"4576.40000000\"],[\"1.09650000\",\"182.00000000\"]],\"a\":[[\"1.09690000\",\"0.00000000\"],[\"1.09700000\",\"6027.20000000\"],[\"1.09710000\",\"2363.00000000\"]]}}"}
{"mode":"v9-depth-v5-spsc","workers":4,"sequenceNumber":65,"symbol":"ETHUSDT","exchangeEventTimeMillis":1784429259165,"localReceivedEpochMillis":1784429259157,"topSpreadTicks":18,"bid5Volume":4362,"ask5Volume":5820,"bid10Volume":40804,"ask10Volume":17319,"rawPayload":"{\"stream\":\"ethusdt@depth@100ms\",\"data\":{\"e\":\"depthUpdate\",\"E\":1784429259165,\"s\":\"ETHUSDT\",\"U\":2806164079,\"u\":2806164084,\"b\":[[\"1871.66000000\",\"0.00000000\"],[\"1871.56000000\",\"0.00000000\"],[\"1871.51000000\",\"0.00000000\"],[\"1870.63000000\",\"2.13780000\"],[\"1870.24000000\",\"0.00000000\"]],\"a\":[[\"1872.06000000\",\"0.00000000\"]]}}"}
{"mode":"v9-depth-v5-spsc","workers":4,"sequenceNumber":66,"symbol":"BTCUSDT","exchangeEventTimeMillis":1784429259165,"localReceivedEpochMillis":1784429259158,"topSpreadTicks":344,"bid5Volume":159,"ask5Volume":101,"bid10Volume":281,"ask10Volume":566,"rawPayload":"{\"stream\":\"btcusdt@depth@100ms\",\"data\":{\"e\":\"depthUpdate\",\"E\":1784429259165,\"s\":\"BTCUSDT\",\"U\":3244435120,\"u\":3244435121,\"b\":[[\"64824.05000000\",\"0.02094000\"],[\"64821.82000000\",\"0.00000000\"]],\"a\":[]}}"}
{"mode":"v9-depth-v5-spsc","workers":4,"sequenceNumber":67,"symbol":"ETHUSDT","exchangeEventTimeMillis":1784429259265,"localReceivedEpochMillis":1784429259257,"topSpreadTicks":18,"bid5Volume":4362,"ask5Volume":5820,"bid10Volume":40804,"ask10Volume":17319,"rawPayload":"{\"stream\":\"ethusdt@depth@100ms\",\"data\":{\"e\":\"depthUpdate\",\"E\":1784429259265,\"s\":\"ETHUSDT\",\"U\":2806164085,\"u\":2806164092,\"b\":[[\"1870.38000000\",\"0.00000000\"],[\"1869.82000000\",\"2.05300000\"],[\"1869.25000000\",\"0.00000000\"],[\"1868.70000000\",\"2.95960000\"],[\"1868.13000000\",\"0.00000000\"],[\"1867.57000000\",\"5.99790000\"],[\"1865.88000000\",\"0.00000000\"],[\"1865.33000000\",\"13.72160000\"]],\"a\":[[\"1874.32000000\",\"2.04860000\"],[\"1874.88000000\",\"0.00000000\"],[\"1875.44000000\",\"3.02900000\"],[\"1876.00000000\",\"0.00000000\"],[\"1876.57000000\",\"6.30890000\"],[\"1877.13000000\",\"0.00000000\"],[\"1879.40000000\",\"0.00000000\"]]}}"}
{"mode":"v9-depth-v5-spsc","workers":4,"sequenceNumber":68,"symbol":"XRPUSDT","exchangeEventTimeMillis":1784429259365,"localReceivedEpochMillis":1784429259357,"topSpreadTicks":0,"bid5Volume":5332000,"ask5Volume":5046900,"bid10Volume":15513800,"ask10Volume":6244800,"rawPayload":"{\"stream\":\"xrpusdt@depth@100ms\",\"data\":{\"e\":\"depthUpdate\",\"E\":1784429259365,\"s\":\"XRPUSDT\",\"U\":752699239,\"u\":752699239,\"b\":[],\"a\":[[\"1.09690000\",\"1295.60000000\"],[\"1.09700000\",\"4731.60000000\"]]}}"}
{"mode":"v9-depth-v5-spsc","workers":4,"sequenceNumber":69,"symbol":"ETHUSDT","exchangeEventTimeMillis":1784429259465,"localReceivedEpochMillis":1784429259457,"topSpreadTicks":18,"bid5Volume":4362,"ask5Volume":5820,"bid10Volume":40804,"ask10Volume":17319,"rawPayload":"{\"stream\":\"ethusdt@depth@100ms\",\"data\":{\"e\":\"depthUpdate\",\"E\":1784429259465,\"s\":\"ETHUSDT\",\"U\":2806164093,\"u\":2806164095,\"b\":[[\"1864.46000000\",\"7.26570000\"]],\"a\":[[\"1879.42000000\",\"7.26760000\"],[\"1880.01000000\",\"8.72640000\"]]}}"}
{"mode":"v9-depth-v5-spsc","workers":4,"sequenceNumber":70,"symbol":"XRPUSDT","exchangeEventTimeMillis":1784429259465,"localReceivedEpochMillis":1784429259464,"topSpreadTicks":0,"bid5Volume":5332000,"ask5Volume":2819300,"bid10Volume":15513800,"ask10Volume":4017200,"rawPayload":"{\"stream\":\"xrpusdt@depth@100ms\",\"data\":{\"e\":\"depthUpdate\",\"E\":1784429259465,\"s\":\"XRPUSDT\",\"U\":752699240,\"u\":752699241,\"b\":[],\"a\":[[\"1.09700000\",\"4592.20000000\"],[\"1.09710000\",\"2504.00000000\"]]}}"}
{"mode":"v9-depth-v5-spsc","workers":4,"sequenceNumber":71,"symbol":"ETHUSDT","exchangeEventTimeMillis":1784429259566,"localReceivedEpochMillis":1784429259557,"topSpreadTicks":18,"bid5Volume":4253,"ask5Volume":4210,"bid10Volume":10133,"ask10Volume":15709,"rawPayload":"{\"stream\":\"ethusdt@depth@100ms\",\"data\":{\"e\":\"depthUpdate\",\"E\":1784429259566,\"s\":\"ETHUSDT\",\"U\":2806164096,\"u\":2806164097,\"b\":[[\"1871.65000000\",\"0.02980000\"]],\"a\":[[\"1872.21000000\",\"0.02960000\"]]}}"}
{"mode":"v9-depth-v5-spsc","workers":4,"sequenceNumber":72,"symbol":"SOLUSDT","exchangeEventTimeMillis":1784429259666,"localReceivedEpochMillis":1784429259693,"topSpreadTicks":1,"bid5Volume":208701,"ask5Volume":179334,"bid10Volume":452521,"ask10Volume":765099,"rawPayload":"{\"stream\":\"solusdt@depth@100ms\",\"data\":{\"e\":\"depthUpdate\",\"E\":1784429259666,\"s\":\"SOLUSDT\",\"U\":1609569541,\"u\":1609569544,\"b\":[],\"a\":[[\"76.28000000\",\"16.53000000\"],[\"76.30000000\",\"50.32500000\"],[\"76.32000000\",\"44.45100000\"]]}}"}
{"mode":"v9-depth-v5-spsc","workers":4,"sequenceNumber":73,"symbol":"XRPUSDT","exchangeEventTimeMillis":1784429259766,"localReceivedEpochMillis":1784429259756,"topSpreadTicks":0,"bid5Volume":5332000,"ask5Volume":6203100,"bid10Volume":15513800,"ask10Volume":7401000,"rawPayload":"{\"stream\":\"xrpusdt@depth@100ms\",\"data\":{\"e\":\"depthUpdate\",\"E\":1784429259766,\"s\":\"XRPUSDT\",\"U\":752699242,\"u\":752699242,\"b\":[],\"a\":[[\"1.09690000\",\"0.00000000\"],[\"1.09700000\",\"5887.80000000\"]]}}"}
{"mode":"v9-depth-v5-spsc","workers":4,"sequenceNumber":74,"symbol":"ETHUSDT","exchangeEventTimeMillis":1784429259866,"localReceivedEpochMillis":1784429259857,"topSpreadTicks":10,"bid5Volume":5031,"ask5Volume":4210,"bid10Volume":10529,"ask10Volume":15701,"rawPayload":"{\"stream\":\"ethusdt@depth@100ms\",\"data\":{\"e\":\"depthUpdate\",\"E\":1784429259866,\"s\":\"ETHUSDT\",\"U\":2806164098,\"u\":2806164104,\"b\":[[\"1872.00000000\",\"1.13860000\"],[\"1871.92000000\",\"0.00000000\"],[\"1871.65000000\",\"0.77980000\"],[\"1871.32000000\",\"1.09310000\"],[\"1870.81000000\",\"0.00000000\"]],\"a\":[[\"1872.49000000\",\"0.00000000\"],[\"1872.57000000\",\"1.10680000\"]]}}"}
{"mode":"v9-depth-v5-spsc","workers":4,"sequenceNumber":75,"symbol":"ETHUSDT","exchangeEventTimeMillis":1784429259966,"localReceivedEpochMillis":1784429259957,"topSpreadTicks":18,"bid5Volume":4856,"ask5Volume":4210,"bid10Volume":10354,"ask10Volume":15789,"rawPayload":"{\"stream\":\"ethusdt@depth@100ms\",\"data\":{\"e\":\"depthUpdate\",\"E\":1784429259966,\"s\":\"ETHUSDT\",\"U\":2806164105,\"u\":2806164110,\"b\":[[\"1872.00000000\",\"0.00000000\"],[\"1871.92000000\",\"1.10030000\"],[\"1871.64000000\",\"0.00000000\"],[\"1871.57000000\",\"0.93170000\"]],\"a\":[[\"1872.50000000\",\"1.19460000\"],[\"1872.57000000\",\"0.00000000\"]]}}"}
{"mode":"v9-depth-v5-spsc","workers":4,"sequenceNumber":76,"symbol":"ETHUSDT","exchangeEventTimeMillis":1784429260066,"localReceivedEpochMillis":1784429260057,"topSpreadTicks":18,"bid5Volume":4267,"ask5Volume":3943,"bid10Volume":10087,"ask10Volume":16463,"rawPayload":"{\"stream\":\"ethusdt@depth@100ms\",\"data\":{\"e\":\"depthUpdate\",\"E\":1784429260066,\"s\":\"ETHUSDT\",\"U\":2806164111,\"u\":2806164112,\"b\":[[\"1871.80000000\",\"1.33650000\"]],\"a\":[[\"1872.39000000\",\"1.33610000\"]]}}"}
{"mode":"v9-depth-v5-spsc","workers":4,"sequenceNumber":77,"symbol":"SOLUSDT","exchangeEventTimeMillis":1784429260166,"localReceivedEpochMillis":1784429260157,"topSpreadTicks":1,"bid5Volume":208701,"ask5Volume":179334,"bid10Volume":434754,"ask10Volume":765099,"rawPayload":"{\"stream\":\"solusdt@depth@100ms\",\"data\":{\"e\":\"depthUpdate\",\"E\":1784429260166,\"s\":\"SOLUSDT\",\"U\":1609569545,\"u\":1609569548,\"b\":[[\"76.25000000\",\"31.55600000\"],[\"76.24000000\",\"39.93000000\"],[\"76.17000000\",\"17.93900000\"],[\"76.16000000\",\"99.12200000\"],[\"76.08000000\",\"54.65400000\"],[\"76.07000000\",\"436.03900000\"]],\"a\":[[\"76.40000000\",\"274.81200000\"],[\"76.41000000\",\"310.87600000\"]]}}"}
{"mode":"v9-depth-v5-spsc","workers":4,"sequenceNumber":78,"symbol":"ETHUSDT","exchangeEventTimeMillis":1784429260166,"localReceivedEpochMillis":1784429260157,"topSpreadTicks":18,"bid5Volume":4273,"ask5Volume":3943,"bid10Volume":10093,"ask10Volume":16463,"rawPayload":"{\"stream\":\"ethusdt@depth@100ms\",\"data\":{\"e\":\"depthUpdate\",\"E\":1784429260166,\"s\":\"ETHUSDT\",\"U\":2806164113,\"u\":2806164114,\"b\":[[\"1871.62000000\",\"0.93720000\"],[\"1871.57000000\",\"0.00000000\"]],\"a\":[]}}"}
{"mode":"v9-depth-v5-spsc","workers":4,"sequenceNumber":79,"symbol":"XRPUSDT","exchangeEventTimeMillis":1784429260166,"localReceivedEpochMillis":1784429260157,"topSpreadTicks":0,"bid5Volume":5332000,"ask5Volume":2678300,"bid10Volume":15513800,"ask10Volume":3876200,"rawPayload":"{\"stream\":\"xrpusdt@depth@100ms\",\"data\":{\"e\":\"depthUpdate\",\"E\":1784429260166,\"s\":\"XRPUSDT\",\"U\":752699243,\"u\":752699244,\"b\":[],\"a\":[[\"1.09700000\",\"6031.50000000\"],[\"1.09710000\",\"2363.00000000\"]]}}"}
{"mode":"v9-depth-v5-spsc","workers":4,"sequenceNumber":80,"symbol":"BTCUSDT","exchangeEventTimeMillis":1784429260566,"localReceivedEpochMillis":1784429260557,"topSpreadTicks":344,"bid5Volume":159,"ask5Volume":101,"bid10Volume":281,"ask10Volume":566,"rawPayload":"{\"stream\":\"btcusdt@depth@100ms\",\"data\":{\"e\":\"depthUpdate\",\"E\":1784429260566,\"s\":\"BTCUSDT\",\"U\":3244435122,\"u\":3244435122,\"b\":[],\"a\":[[\"81072.08000000\",\"0.00045000\"]]}}"}
{"mode":"v9-depth-v5-spsc","workers":4,"sequenceNumber":81,"symbol":"ETHUSDT","exchangeEventTimeMillis":1784429260566,"localReceivedEpochMillis":1784429260557,"topSpreadTicks":24,"bid5Volume":5047,"ask5Volume":3943,"bid10Volume":10867,"ask10Volume":17110,"rawPayload":"{\"stream\":\"ethusdt@depth@100ms\",\"data\":{\"e\":\"depthUpdate\",\"E\":1784429260566,\"s\":\"ETHUSDT\",\"U\":2806164115,\"u\":2806164121,\"b\":[[\"1871.92000000\",\"0.00000000\"],[\"1871.86000000\",\"1.12440000\"],[\"1871.80000000\",\"2.08650000\"]],\"a\":[[\"1872.26000000\",\"1.33620000\"],[\"1872.39000000\",\"0.00000000\"],[\"1872.43000000\",\"2.78270000\"],[\"1872.50000000\",\"0.00000000\"]]}}"}
{"mode":"v9-depth-v5-spsc","workers":4,"sequenceNumber":82,"symbol":"XRPUSDT","exchangeEventTimeMillis":1784429260766,"localReceivedEpochMillis":1784429260758,"topSpreadTicks":0,"bid5Volume":13771900,"ask5Volume":2678300,"bid10Volume":23953700,"ask10Volume":3876200,"rawPayload":"{\"stream\":\"xrpusdt@depth@100ms\",\"data\":{\"e\":\"depthUpdate\",\"E\":1784429260766,\"s\":\"XRPUSDT\",\"U\":752699245,\"u\":752699245,\"b\":[[\"1.09280000\",\"15812.80000000\"],[\"1.09270000\",\"8621.90000000\"]],\"a\":[]}}"}
{"mode":"v9-depth-v5-spsc","workers":4,"sequenceNumber":83,"symbol":"ETHUSDT","exchangeEventTimeMillis":1784429260966,"localReceivedEpochMillis":1784429260959,"topSpreadTicks":30,"bid5Volume":3978,"ask5Volume":5069,"bid10Volume":8144,"ask10Volume":17057,"rawPayload":"{\"stream\":\"ethusdt@depth@100ms\",\"data\":{\"e\":\"depthUpdate\",\"E\":1784429260966,\"s\":\"ETHUSDT\",\"U\":2806164122,\"u\":2806164133,\"b\":[[\"1871.86000000\",\"0.00000000\"],[\"1871.80000000\",\"0.75000000\"],[\"1871.77000000\",\"0.75000000\"],[\"1871.76000000\",\"1.11340000\"],[\"1871.66000000\",\"1.33660000\"],[\"1871.65000000\",\"0.02980000\"],[\"1871.62000000\",\"0.00000000\"],[\"1871.52000000\",\"0.95780000\"]],\"a\":[[\"1872.11000000\",\"1.33630000\"],[\"1872.26000000\",\"0.00000000\"],[\"1872.33000000\",\"2.09290000\"],[\"1872.43000000\",\"1.60350000\"]]}}"}
{"mode":"v9-depth-v5-spsc","workers":4,"sequenceNumber":84,"symbol":"ETHUSDT","exchangeEventTimeMillis":1784429261267,"localReceivedEpochMillis":1784429261258,"topSpreadTicks":28,"bid5Volume":4148,"ask5Volume":3617,"bid10Volume":9295,"ask10Volume":16417,"rawPayload":"{\"stream\":\"ethusdt@depth@100ms\",\"data\":{\"e\":\"depthUpdate\",\"E\":1784429261267,\"s\":\"ETHUSDT\",\"U\":2806164134,\"u\":2806164141,\"b\":[[\"1871.76000000\",\"0.00000000\"],[\"1871.65000000\",\"1.19190000\"],[\"1871.52000000\",\"0.00000000\"],[\"1871.45000000\",\"0.96670000\"]],\"a\":[[\"1872.08000000\",\"1.33630000\"],[\"1872.11000000\",\"0.00000000\"],[\"1872.23000000\",\"1.14810000\"],[\"1872.33000000\",\"0.96640000\"]]}}"}
{"mode":"v9-depth-v5-spsc","workers":4,"sequenceNumber":85,"symbol":"ETHUSDT","exchangeEventTimeMillis":1784429261367,"localReceivedEpochMillis":1784429261359,"topSpreadTicks":28,"bid5Volume":4148,"ask5Volume":3617,"bid10Volume":9298,"ask10Volume":16417,"rawPayload":"{\"stream\":\"ethusdt@depth@100ms\",\"data\":{\"e\":\"depthUpdate\",\"E\":1784429261367,\"s\":\"ETHUSDT\",\"U\":2806164142,\"u\":2806164145,\"b\":[[\"1871.66000000\",\"0.00000000\"],[\"1871.50000000\",\"1.33670000\"],[\"1871.45000000\",\"0.00000000\"],[\"1871.38000000\",\"0.96930000\"]],\"a\":[]}}"}
{"mode":"v9-depth-v5-spsc","workers":4,"sequenceNumber":86,"symbol":"ETHUSDT","exchangeEventTimeMillis":1784429261467,"localReceivedEpochMillis":1784429261458,"topSpreadTicks":15,"bid5Volume":4148,"ask5Volume":3617,"bid10Volume":9298,"ask10Volume":16417,"rawPayload":"{\"stream\":\"ethusdt@depth@100ms\",\"data\":{\"e\":\"depthUpdate\",\"E\":1784429261467,\"s\":\"ETHUSDT\",\"U\":2806164146,\"u\":2806164152,\"b\":[[\"1871.39000000\",\"1.02590000\"],[\"1871.34000000\",\"0.00000000\"],[\"1871.20000000\",\"0.00000000\"],[\"1871.00000000\",\"1.45820000\"],[\"1870.63000000\",\"0.00000000\"],[\"1870.25000000\",\"1.94430000\"]],\"a\":[[\"1871.95000000\",\"1.33640000\"],[\"1872.08000000\",\"0.00000000\"]]}}"}
{"mode":"v9-depth-v5-spsc","workers":4,"sequenceNumber":87,"symbol":"SOLUSDT","exchangeEventTimeMillis":1784429261567,"localReceivedEpochMillis":1784429261558,"topSpreadTicks":1,"bid5Volume":208701,"ask5Volume":179334,"bid10Volume":434754,"ask10Volume":764317,"rawPayload":"{\"stream\":\"solusdt@depth@100ms\",\"data\":{\"e\":\"depthUpdate\",\"E\":1784429261567,\"s\":\"SOLUSDT\",\"U\":1609569549,\"u\":1609569550,\"b\":[],\"a\":[[\"76.31000000\",\"83.12000000\"],[\"76.32000000\",\"30.19500000\"]]}}"}
{"mode":"v9-depth-v5-spsc","workers":4,"sequenceNumber":88,"symbol":"ETHUSDT","exchangeEventTimeMillis":1784429261567,"localReceivedEpochMillis":1784429261558,"topSpreadTicks":18,"bid5Volume":5323,"ask5Volume":4110,"bid10Volume":10191,"ask10Volume":16273,"rawPayload":"{\"stream\":\"ethusdt@depth@100ms\",\"data\":{\"e\":\"depthUpdate\",\"E\":1784429261567,\"s\":\"ETHUSDT\",\"U\":2806164153,\"u\":2806164160,\"b\":[[\"1871.80000000\",\"0.00000000\"],[\"1871.38000000\",\"0.00000000\"],[\"1871.33000000\",\"0.97310000\"],[\"1864.46000000\",\"0.00000000\"]],\"a\":[[\"1872.22000000\",\"1.45970000\"],[\"1872.43000000\",\"0.00000000\"],[\"1879.39000000\",\"7.22900000\"],[\"1880.76000000\",\"0.00000000\"]]}}"}
{"mode":"v9-depth-v5-spsc","workers":4,"sequenceNumber":89,"symbol":"ETHUSDT","exchangeEventTimeMillis":1784429261667,"localReceivedEpochMillis":1784429261658,"topSpreadTicks":18,"bid5Volume":5323,"ask5Volume":4110,"bid10Volume":10191,"ask10Volume":16273,"rawPayload":"{\"stream\":\"ethusdt@depth@100ms\",\"data\":{\"e\":\"depthUpdate\",\"E\":1784429261667,\"s\":\"ETHUSDT\",\"U\":2806164161,\"u\":2806164161,\"b\":[[\"1864.43000000\",\"7.27500000\"]],\"a\":[]}}"}
{"mode":"v9-depth-v5-spsc","workers":4,"sequenceNumber":90,"symbol":"BTCUSDT","exchangeEventTimeMillis":1784429261867,"localReceivedEpochMillis":1784429261858,"topSpreadTicks":344,"bid5Volume":159,"ask5Volume":101,"bid10Volume":281,"ask10Volume":566,"rawPayload":"{\"stream\":\"btcusdt@depth@100ms\",\"data\":{\"e\":\"depthUpdate\",\"E\":1784429261867,\"s\":\"BTCUSDT\",\"U\":3244435123,\"u\":3244435123,\"b\":[],\"a\":[[\"64914.49000000\",\"0.00000000\"]]}}"}
{"mode":"v9-depth-v5-spsc","workers":4,"sequenceNumber":91,"symbol":"BTCUSDT","exchangeEventTimeMillis":1784429261967,"localReceivedEpochMillis":1784429261958,"topSpreadTicks":344,"bid5Volume":159,"ask5Volume":101,"bid10Volume":281,"ask10Volume":566,"rawPayload":"{\"stream\":\"btcusdt@depth@100ms\",\"data\":{\"e\":\"depthUpdate\",\"E\":1784429261967,\"s\":\"BTCUSDT\",\"U\":3244435124,\"u\":3244435124,\"b\":[],\"a\":[[\"64914.49000000\",\"0.00011000\"]]}}"}
{"mode":"v9-depth-v5-spsc","workers":4,"sequenceNumber":92,"symbol":"SOLUSDT","exchangeEventTimeMillis":1784429262167,"localReceivedEpochMillis":1784429262157,"topSpreadTicks":1,"bid5Volume":208701,"ask5Volume":209529,"bid10Volume":434754,"ask10Volume":1040035,"rawPayload":"{\"stream\":\"solusdt@depth@100ms\",\"data\":{\"e\":\"depthUpdate\",\"E\":1784429262167,\"s\":\"SOLUSDT\",\"U\":1609569551,\"u\":1609569556,\"b\":[[\"76.25000000\",\"13.54400000\"],[\"76.24000000\",\"57.94200000\"]],\"a\":[[\"76.28000000\",\"84.83000000\"],[\"76.29000000\",\"54.58900000\"],[\"76.30000000\",\"30.19500000\"],[\"76.32000000\",\"0.00000000\"]]}}"}
{"mode":"v9-depth-v5-spsc","workers":4,"sequenceNumber":93,"symbol":"ETHUSDT","exchangeEventTimeMillis":1784429262167,"localReceivedEpochMillis":1784429262158,"topSpreadTicks":18,"bid5Volume":5000,"ask5Volume":5047,"bid10Volume":11532,"ask10Volume":16906,"rawPayload":"{\"stream\":\"ethusdt@depth@100ms\",\"data\":{\"e\":\"depthUpdate\",\"E\":1784429262167,\"s\":\"ETHUSDT\",\"U\":2806164162,\"u\":2806164172,\"b\":[[\"1871.65000000\",\"1.16210000\"],[\"1871.50000000\",\"0.00000000\"],[\"1871.49000000\",\"0.00000000\"],[\"1871.33000000\",\"1.33680000\"],[\"1871.28000000\",\"0.98910000\"],[\"1864.43000000\",\"0.00000000\"],[\"1864.16000000\",\"0.00000000\"]],\"a\":[[\"1872.21000000\",\"0.00000000\"],[\"1879.37000000\",\"7.26310000\"],[\"1880.68000000\",\"0.00000000\"]]}}"}
{"mode":"v9-depth-v5-spsc","workers":4,"sequenceNumber":94,"symbol":"BTCUSDT","exchangeEventTimeMillis":1784429262167,"localReceivedEpochMillis":1784429262158,"topSpreadTicks":344,"bid5Volume":162,"ask5Volume":101,"bid10Volume":284,"ask10Volume":566,"rawPayload":"{\"stream\":\"btcusdt@depth@100ms\",\"data\":{\"e\":\"depthUpdate\",\"E\":1784429262167,\"s\":\"BTCUSDT\",\"U\":3244435125,\"u\":3244435126,\"b\":[[\"64824.05000000\",\"0.00000000\"],[\"64822.28000000\",\"0.02317000\"]],\"a\":[]}}"}
{"mode":"v9-depth-v5-spsc","workers":4,"sequenceNumber":95,"symbol":"XRPUSDT","exchangeEventTimeMillis":1784429262167,"localReceivedEpochMillis":1784429262158,"topSpreadTicks":2,"bid5Volume":7615100,"ask5Volume":403700,"bid10Volume":17796900,"ask10Volume":1513200,"rawPayload":"{\"stream\":\"xrpusdt@depth@100ms\",\"data\":{\"e\":\"depthUpdate\",\"E\":1784429262167,\"s\":\"XRPUSDT\",\"U\":752699246,\"u\":752699259,\"b\":[[\"1.09660000\",\"45.50000000\"],[\"1.09650000\",\"2475.90000000\"],[\"1.09640000\",\"7826.10000000\"],[\"1.09630000\",\"2465.10000000\"]],\"a\":[[\"1.09690000\",\"3729.70000000\"],[\"1.09700000\",\"2311.70000000\"],[\"1.09710000\",\"3319.50000000\"],[\"1.09720000\",\"0.00000000\"]]}}"}
{"mode":"v9-depth-v5-spsc","workers":4,"sequenceNumber":96,"symbol":"SOLUSDT","exchangeEventTimeMillis":1784429262267,"localReceivedEpochMillis":1784429262258,"topSpreadTicks":1,"bid5Volume":208701,"ask5Volume":223050,"bid10Volume":434754,"ask10Volume":1040082,"rawPayload":"{\"stream\":\"solusdt@depth@100ms\",\"data\":{\"e\":\"depthUpdate\",\"E\":1784429262267,\"s\":\"SOLUSDT\",\"U\":1609569557,\"u\":1609569558,\"b\":[],\"a\":[[\"76.30000000\",\"43.71600000\"],[\"76.31000000\",\"69.64600000\"]]}}"}
{"mode":"v9-depth-v5-spsc","workers":4,"sequenceNumber":97,"symbol":"ETHUSDT","exchangeEventTimeMillis":1784429262267,"localReceivedEpochMillis":1784429262259,"topSpreadTicks":30,"bid5Volume":5586,"ask5Volume":5047,"bid10Volume":10903,"ask10Volume":16906,"rawPayload":"{\"stream\":\"ethusdt@depth@100ms\",\"data\":{\"e\":\"depthUpdate\",\"E\":1784429262267,\"s\":\"ETHUSDT\",\"U\":2806164173,\"u\":2806164174,\"b\":[[\"1871.77000000\",\"0.00000000\"],[\"1871.22000000\",\"0.12100000\"]],\"a\":[]}}"}
{"mode":"v9-depth-v5-spsc","workers":4,"sequenceNumber":98,"symbol":"XRPUSDT","exchangeEventTimeMillis":1784429262267,"localReceivedEpochMillis":1784429262259,"topSpreadTicks":1,"bid5Volume":15059000,"ask5Volume":13121300,"bid10Volume":15331800,"ask10Volume":14319200,"rawPayload":"{\"stream\":\"xrpusdt@depth@100ms\",\"data\":{\"e\":\"depthUpdate\",\"E\":1784429262267,\"s\":\"XRPUSDT\",\"U\":752699260,\"u\":752699268,\"b\":[[\"1.09640000\",\"2281.50000000\"],[\"1.09630000\",\"6871.40000000\"],[\"1.09500000\",\"0.00000000\"]],\"a\":[[\"1.09690000\",\"1448.90000000\"],[\"1.09700000\",\"3924.00000000\"],[\"1.09730000\",\"2074.70000000\"],[\"1.09840000\",\"12806.00000000\"],[\"1.10030000\",\"0.00000000\"]]}}"}
{"mode":"v9-depth-v5-spsc","workers":4,"sequenceNumber":99,"symbol":"SOLUSDT","exchangeEventTimeMillis":1784429262367,"localReceivedEpochMillis":1784429262359,"topSpreadTicks":1,"bid5Volume":208701,"ask5Volume":172725,"bid10Volume":434754,"ask10Volume":744234,"rawPayload":"{\"stream\":\"solusdt@depth@100ms\",\"data\":{\"e\":\"depthUpdate\",\"E\":1784429262367,\"s\":\"SOLUSDT\",\"U\":1609569559,\"u\":1609569561,\"b\":[],\"a\":[[\"76.28000000\",\"34.50500000\"],[\"76.32000000\",\"30.19500000\"]]}}"}
{"mode":"v9-depth-v5-spsc","workers":4,"sequenceNumber":100,"symbol":"ETHUSDT","exchangeEventTimeMillis":1784429262367,"localReceivedEpochMillis":1784429262359,"topSpreadTicks":30,"bid5Volume":4279,"ask5Volume":4110,"bid10Volume":9457,"ask10Volume":16273,"rawPayload":"{\"stream\":\"ethusdt@depth@100ms\",\"data\":{\"e\":\"depthUpdate\",\"E\":1784429262367,\"s\":\"ETHUSDT\",\"U\":2806164175,\"u\":2806164179,\"b\":[[\"1871.51000000\",\"0.02940000\"],[\"1863.96000000\",\"0.34290000\"]],\"a\":[[\"1872.06000000\",\"0.02980000\"],[\"1879.28000000\",\"7.15410000\"],[\"1880.63000000\",\"0.00000000\"]]}}"}
{"mode":"v9-depth-v5-spsc","workers":4,"sequenceNumber":101,"symbol":"XRPUSDT","exchangeEventTimeMillis":1784429262367,"localReceivedEpochMillis":1784429262360,"topSpreadTicks":1,"bid5Volume":15059000,"ask5Volume":809300,"bid10Volume":15331800,"ask10Volume":2007200,"rawPayload":"{\"stream\":\"xrpusdt@depth@100ms\",\"data\":{\"e\":\"depthUpdate\",\"E\":1784429262367,\"s\":\"XRPUSDT\",\"U\":752699269,\"u\":752699289,\"b\":[[\"1.09660000\",\"0.00000000\"],[\"1.09650000\",\"1295.10000000\"],[\"1.09640000\",\"3418.30000000\"],[\"1.09630000\",\"6481.00000000\"],[\"1.09620000\",\"2466.10000000\"],[\"1.09590000\",\"0.00000000\"],[\"1.09580000\",\"2518.50000000\"],[\"1.09530000\",\"0.00000000\"],[\"1.09510000\",\"6893.70000000\"],[\"1.09490000\",\"12867.40000000\"],[\"1.09210000\",\"0.00000000\"]],\"a\":[[\"1.09680000\",\"154.30000000\"],[\"1.09690000\",\"3607.30000000\"],[\"1.09700000\",\"2556.50000000\"],[\"1.09710000\",\"2363.00000000\"],[\"1.09730000\",\"4590.00000000\"],[\"1.09740000\",\"494.00000000\"]]}}"}
{"mode":"v9-depth-v5-spsc","workers":4,"sequenceNumber":102,"symbol":"ETHUSDT","exchangeEventTimeMillis":1784429262467,"localReceivedEpochMillis":1784429262458,"topSpreadTicks":30,"bid5Volume":4279,"ask5Volume":4110,"bid10Volume":9457,"ask10Volume":16273,"rawPayload":"{\"stream\":\"ethusdt@depth@100ms\",\"data\":{\"e\":\"depthUpdate\",\"E\":1784429262467,\"s\":\"ETHUSDT\",\"U\":2806164180,\"u\":2806164180,\"b\":[[\"1863.00000000\",\"9.15710000\"]],\"a\":[]}}"}
{"mode":"v9-depth-v5-spsc","workers":4,"sequenceNumber":103,"symbol":"XRPUSDT","exchangeEventTimeMillis":1784429262467,"localReceivedEpochMillis":1784429262458,"topSpreadTicks":0,"bid5Volume":21522700,"ask5Volume":360600,"bid10Volume":31704500,"ask10Volume":1558500,"rawPayload":"{\"stream\":\"xrpusdt@depth@100ms\",\"data\":{\"e\":\"depthUpdate\",\"E\":1784429262467,\"s\":\"XRPUSDT\",\"U\":752699290,\"u\":752699296,\"b\":[[\"1.09650000\",\"1322.90000000\"],[\"1.09630000\",\"0.00000000\"],[\"1.09620000\",\"6872.80000000\"],[\"1.09580000\",\"4593.20000000\"],[\"1.09190000\",\"16372.70000000\"]],\"a\":[[\"1.09670000\",\"45.30000000\"]]}}"}
{"mode":"v9-depth-v5-spsc","workers":4,"sequenceNumber":104,"symbol":"XRPUSDT","exchangeEventTimeMillis":1784429262568,"localReceivedEpochMillis":1784429262559,"topSpreadTicks":1,"bid5Volume":15059000,"ask5Volume":13154200,"bid10Volume":15331800,"ask10Volume":14352100,"rawPayload":"{\"stream\":\"xrpusdt@depth@100ms\",\"data\":{\"e\":\"depthUpdate\",\"E\":1784429262568,\"s\":\"XRPUSDT\",\"U\":752699297,\"u\":752699305,\"b\":[[\"1.09650000\",\"0.00000000\"],[\"1.09640000\",\"4538.40000000\"],[\"1.09620000\",\"7047.80000000\"],[\"1.09590000\",\"2074.70000000\"],[\"1.09490000\",\"0.00000000\"]],\"a\":[[\"1.09670000\",\"0.00000000\"],[\"1.09830000\",\"12838.90000000\"],[\"1.10020000\",\"0.00000000\"]]}}"}
{"mode":"v9-depth-v5-spsc","workers":4,"sequenceNumber":105,"symbol":"SOLUSDT","exchangeEventTimeMillis":1784429262868,"localReceivedEpochMillis":1784429262859,"topSpreadTicks":1,"bid5Volume":182836,"ask5Volume":194404,"bid10Volume":1106920,"ask10Volume":454557,"rawPayload":"{\"stream\":\"solusdt@depth@100ms\",\"data\":{\"e\":\"depthUpdate\",\"E\":1784429262868,\"s\":\"SOLUSDT\",\"U\":1609569562,\"u\":1609569605,\"b\":[[\"76.25000000\",\"0.00000000\"],[\"76.24000000\",\"14.86400000\"],[\"76.23000000\",\"18.01200000\"],[\"76.22000000\",\"53.25300000\"],[\"76.21000000\",\"0.10000000\"],[\"76.20000000\",\"96.60700000\"],[\"76.18000000\",\"0.00000000\"],[\"76.16000000\",\"0.00000000\"],[\"76.15000000\",\"112.25600000\"],[\"76.14000000\",\"77.40800000\"],[\"76.13000000\",\"0.00000000\"],[\"76.12000000\",\"381.30000000\"],[\"76.11000000\",\"0.00000000\"],[\"76.06000000\",\"188.24400000\"]],\"a\":[[\"76.25000000\",\"6.56100000\"],[\"76.26000000\",\"0.00000000\"],[\"76.27000000\",\"14.14900000\"],[\"76.28000000\",\"17.97500000\"],[\"76.29000000\",\"69.22000000\"],[\"76.30000000\",\"86.49900000\"],[\"76.31000000\",\"33.47800000\"],[\"76.34000000\",\"65.55000000\"],[\"76.36000000\",\"117.80900000\"],[\"76.37000000\",\"272.23500000\"],[\"76.46000000\",\"331.58400000\"],[\"76.50000000\",\"275.75900000\"],[\"76.52000000\",\"0.00000000\"]]}}"}
{"mode":"v9-depth-v5-spsc","workers":4,"sequenceNumber":106,"symbol":"ETHUSDT","exchangeEventTimeMillis":1784429262868,"localReceivedEpochMillis":1784429262860,"topSpreadTicks":30,"bid5Volume":4279,"ask5Volume":4110,"bid10Volume":38900,"ask10Volume":16273,"rawPayload":"{\"stream\":\"ethusdt@depth@100ms\",\"data\":{\"e\":\"depthUpdate\",\"E\":1784429262868,\"s\":\"ETHUSDT\",\"U\":2806164181,\"u\":2806164185,\"b\":[[\"1871.32000000\",\"0.00000000\"],[\"1871.24000000\",\"0.00000000\"],[\"1871.06000000\",\"0.00000000\"],[\"1870.33000000\",\"1.63970000\"]],\"a\":[]}}"}
{"mode":"v9-depth-v5-spsc","workers":4,"sequenceNumber":107,"symbol":"XRPUSDT","exchangeEventTimeMillis":1784429262868,"localReceivedEpochMillis":1784429262860,"topSpreadTicks":0,"bid5Volume":23654800,"ask5Volume":469600,"bid10Volume":33836600,"ask10Volume":1667500,"rawPayload":"{\"stream\":\"xrpusdt@depth@100ms\",\"data\":{\"e\":\"depthUpdate\",\"E\":1784429262868,\"s\":\"XRPUSDT\",\"U\":752699306,\"u\":752699314,\"b\":[[\"1.09640000\",\"4583.70000000\"],[\"1.09620000\",\"566.40000000\"],[\"1.09570000\",\"2177.70000000\"],[\"1.09450000\",\"0.00000000\"],[\"1.09350000\",\"18504.80000000\"]],\"a\":[[\"1.09660000\",\"45.70000000\"],[\"1.09680000\",\"154.30000000\"]]}}"}
{"mode":"v9-depth-v5-spsc","workers":4,"sequenceNumber":108,"symbol":"SOLUSDT","exchangeEventTimeMillis":1784429262968,"localReceivedEpochMillis":1784429262958,"topSpreadTicks":1,"bid5Volume":153720,"ask5Volume":194404,"bid10Volume":779519,"ask10Volume":454557,"rawPayload":"{\"stream\":\"solusdt@depth@100ms\",\"data\":{\"e\":\"depthUpdate\",\"E\":1784429262968,\"s\":\"SOLUSDT\",\"U\":1609569606,\"u\":1609569612,\"b\":[[\"76.22000000\",\"24.13700000\"],[\"76.19000000\",\"36.89600000\"]],\"a\":[[\"76.57000000\",\"336.35900000\"],[\"76.67000000\",\"0.00000000\"]]}}"}
{"mode":"v9-depth-v5-spsc","workers":4,"sequenceNumber":109,"symbol":"XRPUSDT","exchangeEventTimeMillis":1784429262968,"localReceivedEpochMillis":1784429262959,"topSpreadTicks":0,"bid5Volume":10057200,"ask5Volume":469600,"bid10Volume":20239000,"ask10Volume":1667500,"rawPayload":"{\"stream\":\"xrpusdt@depth@100ms\",\"data\":{\"e\":\"depthUpdate\",\"E\":1784429262968,\"s\":\"XRPUSDT\",\"U\":752699315,\"u\":752699319,\"b\":[[\"1.09620000\",\"412.10000000\"],[\"1.09610000\",\"4764.10000000\"],[\"1.09600000\",\"0.00000000\"],[\"1.09580000\",\"4907.20000000\"]],\"a\":[]}}"}
{"mode":"v9-depth-v5-spsc","workers":4,"sequenceNumber":110,"symbol":"SOLUSDT","exchangeEventTimeMillis":1784429263068,"localReceivedEpochMillis":1784429263059,"topSpreadTicks":1,"bid5Volume":188259,"ask5Volume":226659,"bid10Volume":478399,"ask10Volume":486812,"rawPayload":"{\"stream\":\"solusdt@depth@100ms\",\"data\":{\"e\":\"depthUpdate\",\"E\":1784429263068,\"s\":\"SOLUSDT\",\"U\":1609569613,\"u\":1609569620,\"b\":[[\"76.24000000\",\"14.30600000\"],[\"76.22000000\",\"39.58200000\"],[\"76.20000000\",\"116.25900000\"],[\"76.12000000\",\"45.64100000\"]],\"a\":[[\"76.25000000\",\"39.37000000\"],[\"76.27000000\",\"13.59500000\"]]}}"}
{"mode":"v9-depth-v5-spsc","workers":4,"sequenceNumber":111,"symbol":"XRPUSDT","exchangeEventTimeMillis":1784429263068,"localReceivedEpochMillis":1784429263059,"topSpreadTicks":0,"bid5Volume":8404300,"ask5Volume":2528300,"bid10Volume":18586100,"ask10Volume":3726200,"rawPayload":"{\"stream\":\"xrpusdt@depth@100ms\",\"data\":{\"e\":\"depthUpdate\",\"E\":1784429263068,\"s\":\"XRPUSDT\",\"U\":752699320,\"u\":752699330,\"b\":[[\"1.09640000\",\"1295.10000000\"],[\"1.09630000\",\"3254.30000000\"]],\"a\":[[\"1.09660000\",\"0.00000000\"],[\"1.09670000\",\"2281.10000000\"],[\"1.09680000\",\"304.30000000\"],[\"1.09690000\",\"4617.50000000\"],[\"1.09700000\",\"1612.30000000\"],[\"1.09710000\",\"2213.00000000\"]]}}"}
{"mode":"v9-depth-v5-spsc","workers":4,"sequenceNumber":112,"symbol":"SOLUSDT","exchangeEventTimeMillis":1784429263168,"localReceivedEpochMillis":1784429263159,"topSpreadTicks":1,"bid5Volume":188817,"ask5Volume":227213,"bid10Volume":478957,"ask10Volume":760063,"rawPayload":"{\"stream\":\"solusdt@depth@100ms\",\"data\":{\"e\":\"depthUpdate\",\"E\":1784429263168,\"s\":\"SOLUSDT\",\"U\":1609569621,\"u\":1609569625,\"b\":[[\"76.22000000\",\"40.14000000\"],[\"76.11000000\",\"271.65300000\"]],\"a\":[[\"76.25000000\",\"39.92400000\"],[\"76.36000000\",\"390.50600000\"],[\"76.50000000\",\"0.00000000\"]]}}"}
{"mode":"v9-depth-v5-spsc","workers":4,"sequenceNumber":113,"symbol":"ETHUSDT","exchangeEventTimeMillis":1784429263168,"localReceivedEpochMillis":1784429263159,"topSpreadTicks":30,"bid5Volume":4279,"ask5Volume":4110,"bid10Volume":40373,"ask10Volume":16273,"rawPayload":"{\"stream\":\"ethusdt@depth@100ms\",\"data\":{\"e\":\"depthUpdate\",\"E\":1784429263168,\"s\":\"ETHUSDT\",\"U\":2806164186,\"u\":2806164187,\"b\":[[\"1871.33000000\",\"2.34040000\"],[\"1871.28000000\",\"0.00000000\"]],\"a\":[]}}"}
{"mode":"v9-depth-v5-spsc","workers":4,"sequenceNumber":114,"symbol":"SOLUSDT","exchangeEventTimeMillis":1784429263268,"localReceivedEpochMillis":1784429263258,"topSpreadTicks":1,"bid5Volume":188817,"ask5Volume":227213,"bid10Volume":489837,"ask10Volume":760063,"rawPayload":"{\"stream\":\"solusdt@depth@100ms\",\"data\":{\"e\":\"depthUpdate\",\"E\":1784429263268,\"s\":\"SOLUSDT\",\"U\":1609569626,\"u\":1609569627,\"b\":[[\"76.12000000\",\"56.52100000\"],[\"76.11000000\",\"280.51600000\"]],\"a\":[]}}"}
{"mode":"v9-depth-v5-spsc","workers":4,"sequenceNumber":115,"symbol":"ETHUSDT","exchangeEventTimeMillis":1784429263268,"localReceivedEpochMillis":1784429263258,"topSpreadTicks":30,"bid5Volume":4279,"ask5Volume":4110,"bid10Volume":40373,"ask10Volume":16273,"rawPayload":"{\"stream\":\"ethusdt@depth@100ms\",\"data\":{\"e\":\"depthUpdate\",\"E\":1784429263268,\"s\":\"ETHUSDT\",\"U\":2806164188,\"u\":2806164188,\"b\":[[\"1870.80000000\",\"1.09310000\"]],\"a\":[]}}"}
{"mode":"v9-depth-v5-spsc","workers":4,"sequenceNumber":116,"symbol":"BTCUSDT","exchangeEventTimeMillis":1784429263268,"localReceivedEpochMillis":1784429263260,"topSpreadTicks":673,"bid5Volume":132,"ask5Volume":101,"bid10Volume":286,"ask10Volume":498,"rawPayload":"{\"stream\":\"btcusdt@depth@100ms\",\"data\":{\"e\":\"depthUpdate\",\"E\":1784429263268,\"s\":\"BTCUSDT\",\"U\":3244435127,\"u\":3244435156,\"b\":[[\"64829.14000000\",\"0.00000000\"],[\"64826.72000000\",\"0.00000000\"],[\"64826.33000000\",\"0.00000000\"],[\"64825.74000000\",\"0.04000000\"],[\"64824.01000000\",\"0.03408000\"],[\"64822.28000000\",\"0.00000000\"],[\"64820.15000000\",\"0.02403000\"],[\"64819.69000000\",\"0.00000000\"],[\"64814.18000000\",\"0.00000000\"],[\"64814.06000000\",\"0.03859000\"],[\"64803.22000000\",\"0.20864000\"],[\"64803.21000000\",\"0.00000000\"],[\"64787.29000000\",\"0.07161000\"],[\"64769.70000000\",\"0.00000000\"],[\"64768.68000000\",\"0.20856000\"],[\"64562.28000000\",\"0.00000000\"]],\"a\":[[\"64832.47000000\",\"0.00401000\"],[\"64833.14000000\",\"0.00000000\"],[\"64841.27000000\",\"0.00171000\"],[\"64843.38000000\",\"0.00000000\"],[\"64843.48000000\",\"0.03295000\"],[\"64843.99000000\",\"0.00000000\"],[\"64844.93000000\",\"0.00000000\"],[\"64845.81000000\",\"0.00000000\"],[\"64848.60000000\",\"0.00000000\"],[\"64850.50000000\",\"0.00321000\"],[\"64863.54000000\",\"0.00000000\"]]}}"}
{"mode":"v9-depth-v5-spsc","workers":4,"sequenceNumber":117,"symbol":"XRPUSDT","exchangeEventTimeMillis":1784429263268,"localReceivedEpochMillis":1784429263260,"topSpreadTicks":1,"bid5Volume":15059000,"ask5Volume":2528300,"bid10Volume":15331800,"ask10Volume":3726200,"rawPayload":"{\"stream\":\"xrpusdt@depth@100ms\",\"data\":{\"e\":\"depthUpdate\",\"E\":1784429263268,\"s\":\"XRPUSDT\",\"U\":752699331,\"u\":752699331,\"b\":[[\"1.09480000\",\"0.00000000\"]],\"a\":[]}}"}
{"mode":"v9-depth-v5-spsc","workers":4,"sequenceNumber":118,"symbol":"SOLUSDT","exchangeEventTimeMillis":1784429263368,"localReceivedEpochMillis":1784429263359,"topSpreadTicks":1,"bid5Volume":188817,"ask5Volume":227213,"bid10Volume":489837,"ask10Volume":756780,"rawPayload":"{\"stream\":\"solusdt@depth@100ms\",\"data\":{\"e\":\"depthUpdate\",\"E\":1784429263368,\"s\":\"SOLUSDT\",\"U\":1609569628,\"u\":1609569629,\"b\":[[\"75.90000000\",\"333.79300000\"]],\"a\":[[\"76.31000000\",\"30.19500000\"]]}}"}
{"mode":"v9-depth-v5-spsc","workers":4,"sequenceNumber":119,"symbol":"ETHUSDT","exchangeEventTimeMillis":1784429263368,"localReceivedEpochMillis":1784429263359,"topSpreadTicks":30,"bid5Volume":4279,"ask5Volume":4110,"bid10Volume":38933,"ask10Volume":16273,"rawPayload":"{\"stream\":\"ethusdt@depth@100ms\",\"data\":{\"e\":\"depthUpdate\",\"E\":1784429263368,\"s\":\"ETHUSDT\",\"U\":2806164189,\"u\":2806164190,\"b\":[[\"1871.33000000\",\"1.33680000\"],[\"1871.28000000\",\"1.02200000\"]],\"a\":[]}}"}
{"mode":"v9-depth-v5-spsc","workers":4,"sequenceNumber":120,"symbol":"BNBUSDT","exchangeEventTimeMillis":1784429263368,"localReceivedEpochMillis":1784429263360,"topSpreadTicks":10,"bid5Volume":4595,"ask5Volume":7382,"bid10Volume":25182,"ask10Volume":261757,"rawPayload":"{\"stream\":\"bnbusdt@depth@100ms\",\"data\":{\"e\":\"depthUpdate\",\"E\":1784429263368,\"s\":\"BNBUSDT\",\"U\":1236327925,\"u\":1236327925,\"b\":[[\"569.40000000\",\"0.00000000\"],[\"569.39000000\",\"0.00400000\"]],\"a\":[]}}"}
{"mode":"v9-depth-v5-spsc","workers":4,"sequenceNumber":121,"symbol":"BTCUSDT","exchangeEventTimeMillis":1784429263368,"localReceivedEpochMillis":1784429263360,"topSpreadTicks":314,"bid5Volume":132,"ask5Volume":136,"bid10Volume":300,"ask10Volume":515,"rawPayload":"{\"stream\":\"btcusdt@depth@100ms\",\"data\":{\"e\":\"depthUpdate\",\"E\":1784429263368,\"s\":\"BTCUSDT\",\"U\":3244435157,\"u\":3244435167,\"b\":[[\"64820.15000000\",\"0.00000000\"],[\"64818.05000000\",\"0.02407000\"],[\"64810.76000000\",\"0.00000000\"],[\"64806.19000000\",\"0.00401000\"],[\"64800.23000000\",\"0.00000000\"],[\"64795.82000000\",\"0.04259000\"],[\"64768.17000000\",\"0.00000000\"],[\"64759.52000000\",\"0.26558000\"]],\"a\":[[\"64828.88000000\",\"0.02407000\"],[\"64828.89000000\",\"0.00401000\"],[\"64832.47000000\",\"0.00000000\"],[\"64833.13000000\",\"0.00000000\"],[\"64839.26000000\",\"0.04256000\"],[\"64840.49000000\",\"0.00163000\"],[\"64841.27000000\",\"0.00000000\"],[\"64843.84000000\",\"0.00000000\"]]}}"}
{"mode":"v9-depth-v5-spsc","workers":4,"sequenceNumber":122,"symbol":"XRPUSDT","exchangeEventTimeMillis":1784429263368,"localReceivedEpochMillis":1784429263360,"topSpreadTicks":1,"bid5Volume":15059000,"ask5Volume":465300,"bid10Volume":15331800,"ask10Volume":1663200,"rawPayload":"{\"stream\":\"xrpusdt@depth@100ms\",\"data\":{\"e\":\"depthUpdate\",\"E\":1784429263368,\"s\":\"XRPUSDT\",\"U\":752699332,\"u\":752699333,\"b\":[],\"a\":[[\"1.09670000\",\"2440.40000000\"],[\"1.09680000\",\"150.00000000\"]]}}"}
{"mode":"v9-depth-v5-spsc","workers":4,"sequenceNumber":123,"symbol":"SOLUSDT","exchangeEventTimeMillis":1784429263468,"localReceivedEpochMillis":1784429263459,"topSpreadTicks":1,"bid5Volume":188817,"ask5Volume":230496,"bid10Volume":489837,"ask10Volume":760063,"rawPayload":"{\"stream\":\"solusdt@depth@100ms\",\"data\":{\"e\":\"depthUpdate\",\"E\":1784429263468,\"s\":\"SOLUSDT\",\"U\":1609569630,\"u\":1609569630,\"b\":[],\"a\":[[\"76.28000000\",\"21.25800000\"]]}}"}
{"mode":"v9-depth-v5-spsc","workers":4,"sequenceNumber":124,"symbol":"BNBUSDT","exchangeEventTimeMillis":1784429263468,"localReceivedEpochMillis":1784429263460,"topSpreadTicks":10,"bid5Volume":4595,"ask5Volume":7382,"bid10Volume":25182,"ask10Volume":261757,"rawPayload":"{\"stream\":\"bnbusdt@depth@100ms\",\"data\":{\"e\":\"depthUpdate\",\"E\":1784429263468,\"s\":\"BNBUSDT\",\"U\":1236327926,\"u\":1236327926,\"b\":[[\"569.39000000\",\"0.00000000\"],[\"569.37000000\",\"0.00400000\"]],\"a\":[]}}"}
{"mode":"v9-depth-v5-spsc","workers":4,"sequenceNumber":125,"symbol":"BTCUSDT","exchangeEventTimeMillis":1784429263468,"localReceivedEpochMillis":1784429263460,"topSpreadTicks":252,"bid5Volume":132,"ask5Volume":136,"bid10Volume":300,"ask10Volume":515,"rawPayload":"{\"stream\":\"btcusdt@depth@100ms\",\"data\":{\"e\":\"depthUpdate\",\"E\":1784429263468,\"s\":\"BTCUSDT\",\"U\":3244435168,\"u\":3244435173,\"b\":[[\"64563.88000000\",\"0.26541000\"]],\"a\":[[\"64828.26000000\",\"0.00401000\"],[\"64828.89000000\",\"0.00000000\"],[\"64874.93000000\",\"0.26512000\"],[\"64880.69000000\",\"0.00000000\"],[\"64884.57000000\",\"0.20613000\"],[\"64975.06000000\",\"0.00000000\"],[\"81072.08000000\",\"0.00045000\"]]}}"}
{"mode":"v9-depth-v5-spsc","workers":4,"sequenceNumber":126,"symbol":"XRPUSDT","exchangeEventTimeMillis":1784429263468,"localReceivedEpochMillis":1784429263460,"topSpreadTicks":0,"bid5Volume":8449800,"ask5Volume":361000,"bid10Volume":18631600,"ask10Volume":1558900,"rawPayload":"{\"stream\":\"xrpusdt@depth@100ms\",\"data\":{\"e\":\"depthUpdate\",\"E\":1784429263468,\"s\":\"XRPUSDT\",\"U\":752699334,\"u\":752699335,\"b\":[[\"1.09630000\",\"3299.80000000\"]],\"a\":[[\"1.09650000\",\"45.70000000\"]]}}"}
{"mode":"v9-depth-v5-spsc","workers":4,"sequenceNumber":127,"symbol":"BTCUSDT","exchangeEventTimeMillis":1784429263568,"localReceivedEpochMillis":1784429263559,"topSpreadTicks":425,"bid5Volume":132,"ask5Volume":136,"bid10Volume":300,"ask10Volume":515,"rawPayload":"{\"stream\":\"btcusdt@depth@100ms\",\"data\":{\"e\":\"depthUpdate\",\"E\":1784429263568,\"s\":\"BTCUSDT\",\"U\":3244435174,\"u\":3244435178,\"b\":[[\"64825.74000000\",\"0.00000000\"],[\"64821.73000000\",\"0.04000000\"],[\"64821.16000000\",\"0.00000000\"],[\"64813.91000000\",\"0.00000000\"],[\"64812.00000000\",\"0.02826000\"]],\"a\":[[\"64834.83000000\",\"0.00000000\"]]}}"}
{"mode":"v9-depth-v5-spsc","workers":4,"sequenceNumber":128,"symbol":"BTCUSDT","exchangeEventTimeMillis":1784429263668,"localReceivedEpochMillis":1784429263660,"topSpreadTicks":425,"bid5Volume":132,"ask5Volume":136,"bid10Volume":300,"ask10Volume":515,"rawPayload":"{\"stream\":\"btcusdt@depth@100ms\",\"data\":{\"e\":\"depthUpdate\",\"E\":1784429263668,\"s\":\"BTCUSDT\",\"U\":3244435179,\"u\":3244435180,\"b\":[[\"64819.37000000\",\"0.00079000\"]],\"a\":[[\"64833.04000000\",\"0.00077000\"]]}}"}
{"mode":"v9-depth-v5-spsc","workers":4,"sequenceNumber":129,"symbol":"XRPUSDT","exchangeEventTimeMillis":1784429263868,"localReceivedEpochMillis":1784429263860,"topSpreadTicks":0,"bid5Volume":20390500,"ask5Volume":13180400,"bid10Volume":30572300,"ask10Volume":14378300,"rawPayload":"{\"stream\":\"xrpusdt@depth@100ms\",\"data\":{\"e\":\"depthUpdate\",\"E\":1784429263868,\"s\":\"XRPUSDT\",\"U\":752699336,\"u\":752699338,\"b\":[[\"1.09470000\",\"15240.50000000\"]],\"a\":[[\"1.09820000\",\"12865.10000000\"],[\"1.10010000\",\"0.00000000\"]]}}"}
{"mode":"v9-depth-v5-spsc","workers":4,"sequenceNumber":130,"symbol":"BNBUSDT","exchangeEventTimeMillis":1784429263968,"localReceivedEpochMillis":1784429263960,"topSpreadTicks":10,"bid5Volume":4595,"ask5Volume":7382,"bid10Volume":25182,"ask10Volume":261757,"rawPayload":"{\"stream\":\"bnbusdt@depth@100ms\",\"data\":{\"e\":\"depthUpdate\",\"E\":1784429263968,\"s\":\"BNBUSDT\",\"U\":1236327927,\"u\":1236327927,\"b\":[[\"569.37000000\",\"0.00000000\"],[\"569.36000000\",\"0.00400000\"]],\"a\":[]}}"}
{"mode":"v9-depth-v5-spsc","workers":4,"sequenceNumber":131,"symbol":"BTCUSDT","exchangeEventTimeMillis":1784429263968,"localReceivedEpochMillis":1784429263960,"topSpreadTicks":653,"bid5Volume":130,"ask5Volume":95,"bid10Volume":298,"ask10Volume":516,"rawPayload":"{\"stream\":\"btcusdt@depth@100ms\",\"data\":{\"e\":\"depthUpdate\",\"E\":1784429263968,\"s\":\"BTCUSDT\",\"U\":3244435181,\"u\":3244435186,\"b\":[[\"64824.01000000\",\"0.00000000\"],[\"64821.62000000\",\"0.03243000\"]],\"a\":[[\"64838.17000000\",\"0.00158000\"],[\"64840.49000000\",\"0.00000000\"],[\"64841.09000000\",\"0.03368000\"],[\"64843.48000000\",\"0.00000000\"]]}}"}
{"mode":"v9-depth-v5-spsc","workers":4,"sequenceNumber":132,"symbol":"SOLUSDT","exchangeEventTimeMillis":1784429264068,"localReceivedEpochMillis":1784429264058,"topSpreadTicks":1,"bid5Volume":122405,"ask5Volume":290886,"bid10Volume":433332,"ask10Volume":1307505,"rawPayload":"{\"stream\":\"solusdt@depth@100ms\",\"data\":{\"e\":\"depthUpdate\",\"E\":1784429264068,\"s\":\"SOLUSDT\",\"U\":1609569631,\"u\":1609569640,\"b\":[[\"76.20000000\",\"49.84700000\"],[\"76.19000000\",\"73.11600000\"],[\"76.18000000\",\"30.19500000\"],[\"76.15000000\",\"13.12100000\"],[\"76.14000000\",\"176.55600000\"]],\"a\":[[\"76.27000000\",\"63.92000000\"],[\"76.28000000\",\"51.45300000\"],[\"76.30000000\",\"66.36900000\"],[\"76.31000000\",\"0.00000000\"],[\"76.32000000\",\"0.00000000\"]]}}"}
{"mode":"v9-depth-v5-spsc","workers":4,"sequenceNumber":133,"symbol":"BNBUSDT","exchangeEventTimeMillis":1784429264069,"localReceivedEpochMillis":1784429264061,"topSpreadTicks":10,"bid5Volume":4595,"ask5Volume":7382,"bid10Volume":25182,"ask10Volume":261757,"rawPayload":"{\"stream\":\"bnbusdt@depth@100ms\",\"data\":{\"e\":\"depthUpdate\",\"E\":1784429264069,\"s\":\"BNBUSDT\",\"U\":1236327928,\"u\":1236327928,\"b\":[[\"569.36000000\",\"0.00000000\"],[\"569.35000000\",\"0.00400000\"]],\"a\":[]}}"}
{"mode":"v9-depth-v5-spsc","workers":4,"sequenceNumber":134,"symbol":"BTCUSDT","exchangeEventTimeMillis":1784429264069,"localReceivedEpochMillis":1784429264061,"topSpreadTicks":653,"bid5Volume":130,"ask5Volume":95,"bid10Volume":298,"ask10Volume":516,"rawPayload":"{\"stream\":\"btcusdt@depth@100ms\",\"data\":{\"e\":\"depthUpdate\",\"E\":1784429264069,\"s\":\"BTCUSDT\",\"U\":3244435187,\"u\":3244435188,\"b\":[],\"a\":[[\"64837.92000000\",\"0.00159000\"],[\"64838.17000000\",\"0.00000000\"]]}}"}
{"mode":"v9-depth-v5-spsc","workers":4,"sequenceNumber":135,"symbol":"XRPUSDT","exchangeEventTimeMillis":1784429264069,"localReceivedEpochMillis":1784429264061,"topSpreadTicks":0,"bid5Volume":21044600,"ask5Volume":13180400,"bid10Volume":31226400,"ask10Volume":14378300,"rawPayload":"{\"stream\":\"xrpusdt@depth@100ms\",\"data\":{\"e\":\"depthUpdate\",\"E\":1784429264069,\"s\":\"XRPUSDT\",\"U\":752699339,\"u\":752699339,\"b\":[[\"1.09170000\",\"15894.60000000\"]],\"a\":[]}}"}
{"mode":"v9-depth-v5-spsc","workers":4,"sequenceNumber":136,"symbol":"SOLUSDT","exchangeEventTimeMillis":1784429264169,"localReceivedEpochMillis":1784429264158,"topSpreadTicks":1,"bid5Volume":122405,"ask5Volume":290886,"bid10Volume":433332,"ask10Volume":1307505,"rawPayload":"{\"stream\":\"solusdt@depth@100ms\",\"data\":{\"e\":\"depthUpdate\",\"E\":1784429264169,\"s\":\"SOLUSDT\",\"U\":1609569641,\"u\":1609569641,\"b\":[],\"a\":[[\"76.63000000\",\"0.00000000\"]]}}"}
{"mode":"v9-depth-v5-spsc","workers":4,"sequenceNumber":137,"symbol":"BTCUSDT","exchangeEventTimeMillis":1784429264169,"localReceivedEpochMillis":1784429264159,"topSpreadTicks":412,"bid5Volume":130,"ask5Volume":99,"bid10Volume":298,"ask10Volume":516,"rawPayload":"{\"stream\":\"btcusdt@depth@100ms\",\"data\":{\"e\":\"depthUpdate\",\"E\":1784429264169,\"s\":\"BTCUSDT\",\"U\":3244435189,\"u\":3244435192,\"b\":[[\"64806.19000000\",\"0.00000000\"],[\"64803.15000000\",\"0.00401000\"],[\"64795.82000000\",\"0.00000000\"],[\"64792.78000000\",\"0.04259000\"]],\"a\":[[\"64825.85000000\",\"0.00401000\"],[\"64828.26000000\",\"0.00000000\"],[\"64836.22000000\",\"0.04256000\"],[\"64839.26000000\",\"0.00000000\"]]}}"}
{"mode":"v9-depth-v5-spsc","workers":4,"sequenceNumber":138,"symbol":"BNBUSDT","exchangeEventTimeMillis":1784429264269,"localReceivedEpochMillis":1784429264260,"topSpreadTicks":10,"bid5Volume":4595,"ask5Volume":7382,"bid10Volume":25182,"ask10Volume":261757,"rawPayload":"{\"stream\":\"bnbusdt@depth@100ms\",\"data\":{\"e\":\"depthUpdate\",\"E\":1784429264269,\"s\":\"BNBUSDT\",\"U\":1236327929,\"u\":1236327929,\"b\":[[\"569.35000000\",\"0.00000000\"],[\"569.34000000\",\"0.00400000\"]],\"a\":[]}}"}
{"mode":"v9-depth-v5-spsc","workers":4,"sequenceNumber":139,"symbol":"SOLUSDT","exchangeEventTimeMillis":1784429264269,"localReceivedEpochMillis":1784429264260,"topSpreadTicks":1,"bid5Volume":122405,"ask5Volume":254712,"bid10Volume":433332,"ask10Volume":1032298,"rawPayload":"{\"stream\":\"solusdt@depth@100ms\",\"data\":{\"e\":\"depthUpdate\",\"E\":1784429264269,\"s\":\"SOLUSDT\",\"U\":1609569642,\"u\":1609569643,\"b\":[],\"a\":[[\"76.26000000\",\"30.19500000\"],[\"76.30000000\",\"36.17400000\"]]}}"}
{"mode":"v9-depth-v5-spsc","workers":4,"sequenceNumber":140,"symbol":"BTCUSDT","exchangeEventTimeMillis":1784429264269,"localReceivedEpochMillis":1784429264260,"topSpreadTicks":412,"bid5Volume":130,"ask5Volume":99,"bid10Volume":298,"ask10Volume":516,"rawPayload":"{\"stream\":\"btcusdt@depth@100ms\",\"data\":{\"e\":\"depthUpdate\",\"E\":1784429264269,\"s\":\"BTCUSDT\",\"U\":3244435193,\"u\":3244435193,\"b\":[[\"64707.04000000\",\"0.26609000\"]],\"a\":[]}}"}
{"mode":"v9-depth-v5-spsc","workers":4,"sequenceNumber":141,"symbol":"BTCUSDT","exchangeEventTimeMillis":1784429264669,"localReceivedEpochMillis":1784429264662,"topSpreadTicks":412,"bid5Volume":130,"ask5Volume":99,"bid10Volume":298,"ask10Volume":516,"rawPayload":"{\"stream\":\"btcusdt@depth@100ms\",\"data\":{\"e\":\"depthUpdate\",\"E\":1784429264669,\"s\":\"BTCUSDT\",\"U\":3244435194,\"u\":3244435194,\"b\":[[\"64713.66000000\",\"0.00000000\"]],\"a\":[]}}"}
{"mode":"v9-depth-v5-spsc","workers":4,"sequenceNumber":142,"symbol":"BNBUSDT","exchangeEventTimeMillis":1784429264769,"localReceivedEpochMillis":1784429264760,"topSpreadTicks":10,"bid5Volume":4595,"ask5Volume":6663,"bid10Volume":25182,"ask10Volume":259327,"rawPayload":"{\"stream\":\"bnbusdt@depth@100ms\",\"data\":{\"e\":\"depthUpdate\",\"E\":1784429264769,\"s\":\"BNBUSDT\",\"U\":1236327930,\"u\":1236327931,\"b\":[],\"a\":[[\"571.00000000\",\"0.87600000\"],[\"571.02000000\",\"0.00000000\"]]}}"}
{"mode":"v9-depth-v5-spsc","workers":4,"sequenceNumber":143,"symbol":"SOLUSDT","exchangeEventTimeMillis":1784429264869,"localReceivedEpochMillis":1784429264861,"topSpreadTicks":2,"bid5Volume":194864,"ask5Volume":290268,"bid10Volume":489196,"ask10Volume":1362196,"rawPayload":"{\"stream\":\"solusdt@depth@100ms\",\"data\":{\"e\":\"depthUpdate\",\"E\":1784429264869,\"s\":\"SOLUSDT\",\"U\":1609569644,\"u\":1609569652,\"b\":[[\"76.24000000\",\"0.00000000\"],[\"76.23000000\",\"31.66000000\"],[\"76.22000000\",\"36.73000000\"],[\"76.21000000\",\"3.51100000\"]],\"a\":[[\"76.26000000\",\"33.60400000\"],[\"76.27000000\",\"60.51200000\"],[\"76.28000000\",\"65.46000000\"],[\"76.29000000\",\"90.76800000\"],[\"76.30000000\",\"0.00000000\"],[\"76.33000000\",\"68.40400000\"],[\"76.34000000\",\"164.45400000\"],[\"76.36000000\",\"291.62800000\"]]}}"}
{"mode":"v9-depth-v5-spsc","workers":4,"sequenceNumber":144,"symbol":"BTCUSDT","exchangeEventTimeMillis":1784429264869,"localReceivedEpochMillis":1784429264862,"topSpreadTicks":412,"bid5Volume":130,"ask5Volume":99,"bid10Volume":298,"ask10Volume":516,"rawPayload":"{\"stream\":\"btcusdt@depth@100ms\",\"data\":{\"e\":\"depthUpdate\",\"E\":1784429264869,\"s\":\"BTCUSDT\",\"U\":3244435195,\"u\":3244435195,\"b\":[[\"64694.14000000\",\"0.00020000\"]],\"a\":[]}}"}
{"mode":"v9-depth-v5-spsc","workers":4,"sequenceNumber":145,"symbol":"SOLUSDT","exchangeEventTimeMillis":1784429264969,"localReceivedEpochMillis":1784429264960,"topSpreadTicks":1,"bid5Volume":194864,"ask5Volume":196149,"bid10Volume":489196,"ask10Volume":1083638,"rawPayload":"{\"stream\":\"solusdt@depth@100ms\",\"data\":{\"e\":\"depthUpdate\",\"E\":1784429264969,\"s\":\"SOLUSDT\",\"U\":1609569653,\"u\":1609569654,\"b\":[],\"a\":[[\"76.24000000\",\"3.21000000\"],[\"76.25000000\",\"33.36300000\"]]}}"}
{"mode":"v9-depth-v5-spsc","workers":4,"sequenceNumber":146,"symbol":"XRPUSDT","exchangeEventTimeMillis":1784429265069,"localReceivedEpochMillis":1784429265059,"topSpreadTicks":0,"bid5Volume":21044600,"ask5Volume":3637200,"bid10Volume":31226400,"ask10Volume":4835100,"rawPayload":"{\"stream\":\"xrpusdt@depth@100ms\",\"data\":{\"e\":\"depthUpdate\",\"E\":1784429265069,\"s\":\"XRPUSDT\",\"U\":752699340,\"u\":752699340,\"b\":[],\"a\":[[\"1.09680000\",\"1445.60000000\"],[\"1.09690000\",\"3321.90000000\"]]}}"}
{"mode":"v9-depth-v5-spsc","workers":4,"sequenceNumber":147,"symbol":"ETHUSDT","exchangeEventTimeMillis":1784429265169,"localReceivedEpochMillis":1784429265160,"topSpreadTicks":30,"bid5Volume":4590,"ask5Volume":4110,"bid10Volume":38933,"ask10Volume":16273,"rawPayload":"{\"stream\":\"ethusdt@depth@100ms\",\"data\":{\"e\":\"depthUpdate\",\"E\":1784429265169,\"s\":\"ETHUSDT\",\"U\":2806164191,\"u\":2806164191,\"b\":[[\"1871.39000000\",\"0.00000000\"],[\"1871.27000000\",\"1.02590000\"]],\"a\":[]}}"}
{"mode":"v9-depth-v5-spsc","workers":4,"sequenceNumber":148,"symbol":"BNBUSDT","exchangeEventTimeMillis":1784429265169,"localReceivedEpochMillis":1784429265160,"topSpreadTicks":10,"bid5Volume":4595,"ask5Volume":8258,"bid10Volume":25182,"ask10Volume":262633,"rawPayload":"{\"stream\":\"bnbusdt@depth@100ms\",\"data\":{\"e\":\"depthUpdate\",\"E\":1784429265169,\"s\":\"BNBUSDT\",\"U\":1236327932,\"u\":1236327939,\"b\":[[\"568.73000000\",\"0.00000000\"],[\"568.27000000\",\"2.20900000\"]],\"a\":[[\"571.00000000\",\"0.00000000\"],[\"571.01000000\",\"2.49100000\"],[\"571.02000000\",\"0.00000000\"],[\"573.30000000\",\"1.72200000\"],[\"573.84000000\",\"0.00000000\"]]}}"}
{"mode":"v9-depth-v5-spsc","workers":4,"sequenceNumber":149,"symbol":"BNBUSDT","exchangeEventTimeMillis":1784429265269,"localReceivedEpochMillis":1784429265260,"topSpreadTicks":10,"bid5Volume":4595,"ask5Volume":8258,"bid10Volume":25182,"ask10Volume":262633,"rawPayload":"{\"stream\":\"bnbusdt@depth@100ms\",\"data\":{\"e\":\"depthUpdate\",\"E\":1784429265269,\"s\":\"BNBUSDT\",\"U\":1236327940,\"u\":1236327940,\"b\":[[\"568.27000000\",\"0.00000000\"]],\"a\":[]}}"}
{"mode":"v9-depth-v5-spsc","workers":4,"sequenceNumber":150,"symbol":"BNBUSDT","exchangeEventTimeMillis":1784429265469,"localReceivedEpochMillis":1784429265461,"topSpreadTicks":10,"bid5Volume":4595,"ask5Volume":8258,"bid10Volume":25182,"ask10Volume":262633,"rawPayload":"{\"stream\":\"bnbusdt@depth@100ms\",\"data\":{\"e\":\"depthUpdate\",\"E\":1784429265469,\"s\":\"BNBUSDT\",\"U\":1236327941,\"u\":1236327941,\"b\":[[\"568.27000000\",\"2.23000000\"]],\"a\":[]}}"}
{"mode":"v9-depth-v5-spsc","workers":4,"sequenceNumber":151,"symbol":"ETHUSDT","exchangeEventTimeMillis":1784429265469,"localReceivedEpochMillis":1784429265462,"topSpreadTicks":30,"bid5Volume":4893,"ask5Volume":4110,"bid10Volume":9872,"ask10Volume":16273,"rawPayload":"{\"stream\":\"ethusdt@depth@100ms\",\"data\":{\"e\":\"depthUpdate\",\"E\":1784429265469,\"s\":\"ETHUSDT\",\"U\":2806164192,\"u\":2806164194,\"b\":[[\"1871.40000000\",\"1.63970000\"],[\"1870.80000000\",\"0.00000000\"],[\"1870.33000000\",\"0.00000000\"]],\"a\":[]}}"}
{"mode":"v9-depth-v5-spsc","workers":4,"sequenceNumber":152,"symbol":"SOLUSDT","exchangeEventTimeMillis":1784429265670,"localReceivedEpochMillis":1784429265661,"topSpreadTicks":1,"bid5Volume":194864,"ask5Volume":196149,"bid10Volume":489196,"ask10Volume":1083638,"rawPayload":"{\"stream\":\"solusdt@depth@100ms\",\"data\":{\"e\":\"depthUpdate\",\"E\":1784429265670,\"s\":\"SOLUSDT\",\"U\":1609569655,\"u\":1609569655,\"b\":[],\"a\":[[\"76.27000000\",\"78.48700000\"],[\"76.28000000\",\"47.48500000\"]]}}"}
{"mode":"v9-depth-v5-spsc","workers":4,"sequenceNumber":153,"symbol":"BTCUSDT","exchangeEventTimeMillis":1784429265770,"localReceivedEpochMillis":1784429265761,"topSpreadTicks":412,"bid5Volume":130,"ask5Volume":99,"bid10Volume":298,"ask10Volume":516,"rawPayload":"{\"stream\":\"btcusdt@depth@100ms\",\"data\":{\"e\":\"depthUpdate\",\"E\":1784429265770,\"s\":\"BTCUSDT\",\"U\":3244435196,\"u\":3244435196,\"b\":[],\"a\":[[\"64914.49000000\",\"0.00000000\"]]}}"}
{"mode":"v9-depth-v5-spsc","workers":4,"sequenceNumber":154,"symbol":"SOLUSDT","exchangeEventTimeMillis":1784429265870,"localReceivedEpochMillis":1784429265860,"topSpreadTicks":1,"bid5Volume":194864,"ask5Volume":182142,"bid10Volume":489196,"ask10Volume":1084122,"rawPayload":"{\"stream\":\"solusdt@depth@100ms\",\"data\":{\"e\":\"depthUpdate\",\"E\":1784429265870,\"s\":\"SOLUSDT\",\"U\":1609569656,\"u\":1609569657,\"b\":[],\"a\":[[\"76.28000000\",\"33.47800000\"],[\"76.29000000\",\"105.25900000\"]]}}"}
{"mode":"v9-depth-v5-spsc","workers":4,"sequenceNumber":155,"symbol":"BTCUSDT","exchangeEventTimeMillis":1784429265870,"localReceivedEpochMillis":1784429265860,"topSpreadTicks":412,"bid5Volume":130,"ask5Volume":99,"bid10Volume":298,"ask10Volume":516,"rawPayload":"{\"stream\":\"btcusdt@depth@100ms\",\"data\":{\"e\":\"depthUpdate\",\"E\":1784429265870,\"s\":\"BTCUSDT\",\"U\":3244435197,\"u\":3244435197,\"b\":[],\"a\":[[\"64914.49000000\",\"0.00011000\"]]}}"}
{"mode":"v9-depth-v5-spsc","workers":4,"sequenceNumber":156,"symbol":"XRPUSDT","exchangeEventTimeMillis":1784429265870,"localReceivedEpochMillis":1784429265860,"topSpreadTicks":2,"bid5Volume":21044600,"ask5Volume":403700,"bid10Volume":31226400,"ask10Volume":1513200,"rawPayload":"{\"stream\":\"xrpusdt@depth@100ms\",\"data\":{\"e\":\"depthUpdate\",\"E\":1784429265870,\"s\":\"XRPUSDT\",\"U\":752699341,\"u\":752699341,\"b\":[],\"a\":[[\"1.09650000\",\"0.00000000\"]]}}"}
{"mode":"v9-depth-v5-spsc","workers":4,"sequenceNumber":157,"symbol":"SOLUSDT","exchangeEventTimeMillis":1784429265970,"localReceivedEpochMillis":1784429265960,"topSpreadTicks":1,"bid5Volume":194864,"ask5Volume":196582,"bid10Volume":489196,"ask10Volume":1084071,"rawPayload":"{\"stream\":\"solusdt@depth@100ms\",\"data\":{\"e\":\"depthUpdate\",\"E\":1784429265970,\"s\":\"SOLUSDT\",\"U\":1609569658,\"u\":1609569659,\"b\":[],\"a\":[[\"76.28000000\",\"47.91800000\"],[\"76.29000000\",\"90.76800000\"]]}}"}
{"mode":"v9-depth-v5-spsc","workers":4,"sequenceNumber":158,"symbol":"SOLUSDT","exchangeEventTimeMillis":1784429266170,"localReceivedEpochMillis":1784429266161,"topSpreadTicks":1,"bid5Volume":194864,"ask5Volume":182142,"bid10Volume":489196,"ask10Volume":1084038,"rawPayload":"{\"stream\":\"solusdt@depth@100ms\",\"data\":{\"e\":\"depthUpdate\",\"E\":1784429266170,\"s\":\"SOLUSDT\",\"U\":1609569660,\"u\":1609569661,\"b\":[],\"a\":[[\"76.28000000\",\"33.47800000\"],[\"76.29000000\",\"105.17500000\"]]}}"}
{"mode":"v9-depth-v5-spsc","workers":4,"sequenceNumber":159,"symbol":"BNBUSDT","exchangeEventTimeMillis":1784429266270,"localReceivedEpochMillis":1784429266260,"topSpreadTicks":10,"bid5Volume":4595,"ask5Volume":8258,"bid10Volume":25182,"ask10Volume":262633,"rawPayload":"{\"stream\":\"bnbusdt@depth@100ms\",\"data\":{\"e\":\"depthUpdate\",\"E\":1784429266270,\"s\":\"BNBUSDT\",\"U\":1236327942,\"u\":1236327946,\"b\":[[\"568.72000000\",\"0.00000000\"],[\"568.71000000\",\"1.72400000\"],[\"568.27000000\",\"0.00000000\"]],\"a\":[[\"573.29000000\",\"1.74000000\"],[\"573.82000000\",\"0.00000000\"]]}}"}
{"mode":"v9-depth-v5-spsc","workers":4,"sequenceNumber":160,"symbol":"BTCUSDT","exchangeEventTimeMillis":1784429266270,"localReceivedEpochMillis":1784429266260,"topSpreadTicks":412,"bid5Volume":130,"ask5Volume":99,"bid10Volume":298,"ask10Volume":516,"rawPayload":"{\"stream\":\"btcusdt@depth@100ms\",\"data\":{\"e\":\"depthUpdate\",\"E\":1784429266270,\"s\":\"BTCUSDT\",\"U\":3244435198,\"u\":3244435198,\"b\":[[\"64698.36000000\",\"0.28908000\"]],\"a\":[]}}"}
{"mode":"v9-depth-v5-spsc","workers":4,"sequenceNumber":161,"symbol":"BNBUSDT","exchangeEventTimeMillis":1784429266470,"localReceivedEpochMillis":1784429266461,"topSpreadTicks":10,"bid5Volume":4595,"ask5Volume":8258,"bid10Volume":25182,"ask10Volume":262633,"rawPayload":"{\"stream\":\"bnbusdt@depth@100ms\",\"data\":{\"e\":\"depthUpdate\",\"E\":1784429266470,\"s\":\"BNBUSDT\",\"U\":1236327947,\"u\":1236327947,\"b\":[[\"568.27000000\",\"2.20700000\"]],\"a\":[]}}"}
{"mode":"v9-depth-v5-spsc","workers":4,"sequenceNumber":162,"symbol":"ETHUSDT","exchangeEventTimeMillis":1784429266570,"localReceivedEpochMillis":1784429266562,"topSpreadTicks":25,"bid5Volume":4602,"ask5Volume":4066,"bid10Volume":11558,"ask10Volume":16090,"rawPayload":"{\"stream\":\"ethusdt@depth@100ms\",\"data\":{\"e\":\"depthUpdate\",\"E\":1784429266570,\"s\":\"ETHUSDT\",\"U\":2806164195,\"u\":2806164212,\"b\":[[\"1871.81000000\",\"1.17480000\"],[\"1871.75000000\",\"0.00000000\"],[\"1871.65000000\",\"0.00000000\"],[\"1871.59000000\",\"1.33660000\"],[\"1871.36000000\",\"0.00000000\"],[\"1871.33000000\",\"0.00000000\"],[\"1871.28000000\",\"0.00000000\"],[\"1871.22000000\",\"1.21410000\"],[\"1871.20000000\",\"1.60350000\"],[\"1871.00000000\",\"0.00000000\"]],\"a\":[[\"1871.95000000\",\"0.00000000\"],[\"1872.23000000\",\"0.00000000\"],[\"1872.32000000\",\"0.00000000\"],[\"1872.54000000\",\"0.00000000\"]]}}"}
{"mode":"v9-depth-v5-spsc","workers":4,"sequenceNumber":163,"symbol":"BTCUSDT","exchangeEventTimeMillis":1784429266570,"localReceivedEpochMillis":1784429266562,"topSpreadTicks":412,"bid5Volume":130,"ask5Volume":99,"bid10Volume":298,"ask10Volume":516,"rawPayload":"{\"stream\":\"btcusdt@depth@100ms\",\"data\":{\"e\":\"depthUpdate\",\"E\":1784429266570,\"s\":\"BTCUSDT\",\"U\":3244435199,\"u\":3244435200,\"b\":[],\"a\":[[\"64837.56000000\",\"0.00168000\"],[\"64837.92000000\",\"0.00000000\"]]}}"}
{"mode":"v9-depth-v5-spsc","workers":4,"sequenceNumber":164,"symbol":"XRPUSDT","exchangeEventTimeMillis":1784429266570,"localReceivedEpochMillis":1784429266562,"topSpreadTicks":0,"bid5Volume":21044600,"ask5Volume":4041800,"bid10Volume":31226400,"ask10Volume":5239700,"rawPayload":"{\"stream\":\"xrpusdt@depth@100ms\",\"data\":{\"e\":\"depthUpdate\",\"E\":1784429266570,\"s\":\"XRPUSDT\",\"U\":752699342,\"u\":752699343,\"b\":[],\"a\":[[\"1.09670000\",\"159.30000000\"],[\"1.09680000\",\"3726.50000000\"]]}}"}
{"mode":"v9-depth-v5-spsc","workers":4,"sequenceNumber":165,"symbol":"SOLUSDT","exchangeEventTimeMillis":1784429266670,"localReceivedEpochMillis":1784429266661,"topSpreadTicks":1,"bid5Volume":122490,"ask5Volume":273072,"bid10Volume":433417,"ask10Volume":1084083,"rawPayload":"{\"stream\":\"solusdt@depth@100ms\",\"data\":{\"e\":\"depthUpdate\",\"E\":1784429266670,\"s\":\"SOLUSDT\",\"U\":1609569662,\"u\":1609569669,\"b\":[[\"76.24000000\",\"14.39000000\"],[\"76.23000000\",\"18.01200000\"]],\"a\":[[\"76.24000000\",\"0.00000000\"],[\"76.25000000\",\"36.73500000\"],[\"76.26000000\",\"88.19300000\"],[\"76.29000000\",\"36.17900000\"],[\"76.30000000\",\"14.29000000\"]]}}"}
{"mode":"v9-depth-v5-spsc","workers":4,"sequenceNumber":166,"symbol":"ETHUSDT","exchangeEventTimeMillis":1784429266670,"localReceivedEpochMillis":1784429266661,"topSpreadTicks":25,"bid5Volume":5532,"ask5Volume":3763,"bid10Volume":11151,"ask10Volume":15787,"rawPayload":"{\"stream\":\"ethusdt@depth@100ms\",\"data\":{\"e\":\"depthUpdate\",\"E\":1784429266670,\"s\":\"ETHUSDT\",\"U\":2806164213,\"u\":2806164215,\"b\":[[\"1871.57000000\",\"1.06890000\"]],\"a\":[[\"1872.22000000\",\"0.00000000\"],[\"1872.38000000\",\"1.15600000\"]]}}"}
{"mode":"v9-depth-v5-spsc","workers":4,"sequenceNumber":167,"symbol":"BTCUSDT","exchangeEventTimeMillis":1784429266670,"localReceivedEpochMillis":1784429266661,"topSpreadTicks":411,"bid5Volume":132,"ask5Volume":138,"bid10Volume":300,"ask10Volume":518,"rawPayload":"{\"stream\":\"btcusdt@depth@100ms\",\"data\":{\"e\":\"depthUpdate\",\"E\":1784429266670,\"s\":\"BTCUSDT\",\"U\":3244435201,\"u\":3244435206,\"b\":[[\"64819.94000000\",\"0.02687000\"],[\"64818.05000000\",\"0.00000000\"]],\"a\":[[\"64825.84000000\",\"0.02687000\"],[\"64828.88000000\",\"0.00000000\"],[\"64837.56000000\",\"0.00000000\"],[\"64839.59000000\",\"0.00164000\"]]}}"}
{"mode":"v9-depth-v5-spsc","workers":4,"sequenceNumber":168,"symbol":"XRPUSDT","exchangeEventTimeMillis":1784429266670,"localReceivedEpochMillis":1784429266662,"topSpreadTicks":0,"bid5Volume":21044600,"ask5Volume":361000,"bid10Volume":31226400,"ask10Volume":1558900,"rawPayload":"{\"stream\":\"xrpusdt@depth@100ms\",\"data\":{\"e\":\"depthUpdate\",\"E\":1784429266670,\"s\":\"XRPUSDT\",\"U\":752699344,\"u\":752699344,\"b\":[],\"a\":[[\"1.09660000\",\"45.70000000\"]]}}"}
{"mode":"v9-depth-v5-spsc","workers":4,"sequenceNumber":169,"symbol":"XRPUSDT","exchangeEventTimeMillis":1784429266770,"localReceivedEpochMillis":1784429266761,"topSpreadTicks":0,"bid5Volume":9756900,"ask5Volume":361000,"bid10Volume":19938700,"ask10Volume":1558900,"rawPayload":"{\"stream\":\"xrpusdt@depth@100ms\",\"data\":{\"e\":\"depthUpdate\",\"E\":1784429266770,\"s\":\"XRPUSDT\",\"U\":752699345,\"u\":752699346,\"b\":[[\"1.09620000\",\"588.80000000\"],[\"1.09610000\",\"4606.90000000\"]],\"a\":[]}}"}
{"mode":"v9-depth-v5-spsc","workers":4,"sequenceNumber":170,"symbol":"SOLUSDT","exchangeEventTimeMillis":1784429266870,"localReceivedEpochMillis":1784429266863,"topSpreadTicks":1,"bid5Volume":122490,"ask5Volume":267020,"bid10Volume":433417,"ask10Volume":1078031,"rawPayload":"{\"stream\":\"solusdt@depth@100ms\",\"data\":{\"e\":\"depthUpdate\",\"E\":1784429266870,\"s\":\"SOLUSDT\",\"U\":1609569670,\"u\":1609569671,\"b\":[],\"a\":[[\"76.27000000\",\"68.30000000\"],[\"76.28000000\",\"37.61300000\"]]}}"}
{"mode":"v9-depth-v5-spsc","workers":4,"sequenceNumber":171,"symbol":"ETHUSDT","exchangeEventTimeMillis":1784429266870,"localReceivedEpochMillis":1784429266864,"topSpreadTicks":25,"bid5Volume":5106,"ask5Volume":3763,"bid10Volume":10725,"ask10Volume":15787,"rawPayload":"{\"stream\":\"ethusdt@depth@100ms\",\"data\":{\"e\":\"depthUpdate\",\"E\":1784429266870,\"s\":\"ETHUSDT\",\"U\":2806164216,\"u\":2806164217,\"b\":[[\"1871.57000000\",\"0.00000000\"],[\"1871.52000000\",\"0.64200000\"]],\"a\":[]}}"}
{"mode":"v9-depth-v5-spsc","workers":4,"sequenceNumber":172,"symbol":"XRPUSDT","exchangeEventTimeMillis":1784429266870,"localReceivedEpochMillis":1784429266864,"topSpreadTicks":0,"bid5Volume":9864700,"ask5Volume":4149600,"bid10Volume":20046500,"ask10Volume":5347500,"rawPayload":"{\"stream\":\"xrpusdt@depth@100ms\",\"data\":{\"e\":\"depthUpdate\",\"E\":1784429266870,\"s\":\"XRPUSDT\",\"U\":752699347,\"u\":752699350,\"b\":[[\"1.09620000\",\"412.10000000\"],[\"1.09610000\",\"4714.70000000\"]],\"a\":[[\"1.09670000\",\"0.00000000\"],[\"1.09680000\",\"3834.30000000\"]]}}"}
{"mode":"v9-depth-v5-spsc","workers":4,"sequenceNumber":173,"symbol":"ETHUSDT","exchangeEventTimeMillis":1784429266970,"localReceivedEpochMillis":1784429266961,"topSpreadTicks":19,"bid5Volume":5808,"ask5Volume":3718,"bid10Volume":11427,"ask10Volume":15742,"rawPayload":"{\"stream\":\"ethusdt@depth@100ms\",\"data\":{\"e\":\"depthUpdate\",\"E\":1784429266970,\"s\":\"ETHUSDT\",\"U\":2806164218,\"u\":2806164227,\"b\":[[\"1871.87000000\",\"1.12660000\"],[\"1871.81000000\",\"0.00000000\"],[\"1871.59000000\",\"2.08660000\"]],\"a\":[[\"1872.38000000\",\"0.00000000\"],[\"1872.44000000\",\"1.11140000\"],[\"1879.28000000\",\"0.00000000\"],[\"1879.29000000\",\"7.24240000\"],[\"1880.20000000\",\"8.99610000\"],[\"1880.51000000\",\"0.00000000\"],[\"1880.57000000\",\"0.00000000\"]]}}"}
{"mode":"v9-depth-v5-spsc","workers":4,"sequenceNumber":174,"symbol":"XRPUSDT","exchangeEventTimeMillis":1784429266970,"localReceivedEpochMillis":1784429266962,"topSpreadTicks":0,"bid5Volume":9846500,"ask5Volume":6180600,"bid10Volume":20028300,"ask10Volume":7378500,"rawPayload":"{\"stream\":\"xrpusdt@depth@100ms\",\"data\":{\"e\":\"depthUpdate\",\"E\":1784429266970,\"s\":\"XRPUSDT\",\"U\":752699351,\"u\":752699359,\"b\":[[\"1.09630000\",\"3346.20000000\"],[\"1.09620000\",\"175.00000000\"],[\"1.09610000\",\"4951.80000000\"],[\"1.09580000\",\"2388.70000000\"],[\"1.09570000\",\"4696.50000000\"]],\"a\":[[\"1.09680000\",\"4071.30000000\"],[\"1.09690000\",\"3084.90000000\"],[\"1.09720000\",\"2515.60000000\"],[\"1.09730000\",\"2074.70000000\"],[\"1.09790000\",\"6877.30000000\"],[\"1.09810000\",\"5865.30000000\"]]}}"}
{"mode":"v9-depth-v5-spsc","workers":4,"sequenceNumber":175,"symbol":"ETHUSDT","exchangeEventTimeMillis":1784429267071,"localReceivedEpochMillis":1784429267061,"topSpreadTicks":23,"bid5Volume":5917,"ask5Volume":5025,"bid10Volume":12873,"ask10Volume":17049,"rawPayload":"{\"stream\":\"ethusdt@depth@100ms\",\"data\":{\"e\":\"depthUpdate\",\"E\":1784429267071,\"s\":\"ETHUSDT\",\"U\":2806164228,\"u\":2806164231,\"b\":[[\"1871.51000000\",\"0.00000000\"]],\"a\":[[\"1872.06000000\",\"0.00000000\"],[\"1872.21000000\",\"1.33620000\"],[\"1879.29000000\",\"0.00000000\"]]}}"}
{"mode":"v9-depth-v5-spsc","workers":4,"sequenceNumber":176,"symbol":"BNBUSDT","exchangeEventTimeMillis":1784429267171,"localReceivedEpochMillis":1784429267161,"topSpreadTicks":10,"bid5Volume":4595,"ask5Volume":8258,"bid10Volume":25182,"ask10Volume":262633,"rawPayload":"{\"stream\":\"bnbusdt@depth@100ms\",\"data\":{\"e\":\"depthUpdate\",\"E\":1784429267171,\"s\":\"BNBUSDT\",\"U\":1236327948,\"u\":1236327949,\"b\":[],\"a\":[[\"571.01000000\",\"1.61500000\"],[\"571.03000000\",\"2.47100000\"]]}}"}
{"mode":"v9-depth-v5-spsc","workers":4,"sequenceNumber":177,"symbol":"BNBUSDT","exchangeEventTimeMillis":1784429267271,"localReceivedEpochMillis":1784429267262,"topSpreadTicks":10,"bid5Volume":4595,"ask5Volume":8258,"bid10Volume":25182,"ask10Volume":262633,"rawPayload":"{\"stream\":\"bnbusdt@depth@100ms\",\"data\":{\"e\":\"depthUpdate\",\"E\":1784429267271,\"s\":\"BNBUSDT\",\"U\":1236327950,\"u\":1236327957,\"b\":[[\"570.21000000\",\"0.00000000\"],[\"570.20000000\",\"3.39500000\"],[\"569.87000000\",\"0.00000000\"],[\"569.86000000\",\"5.04900000\"],[\"569.53000000\",\"0.00000000\"],[\"569.52000000\",\"8.67400000\"],[\"569.18000000\",\"0.00000000\"],[\"569.17000000\",\"19.72800000\"]],\"a\":[[\"571.58000000\",\"3.30600000\"],[\"571.59000000\",\"0.00000000\"],[\"571.92000000\",\"5.04600000\"],[\"571.93000000\",\"0.00000000\"],[\"572.27000000\",\"8.42800000\"],[\"572.28000000\",\"0.00000000\"],[\"572.61000000\",\"20.45700000\"],[\"572.62000000\",\"0.00000000\"]]}}"}
{"mode":"v9-depth-v5-spsc","workers":4,"sequenceNumber":178,"symbol":"BTCUSDT","exchangeEventTimeMillis":1784429267271,"localReceivedEpochMillis":1784429267262,"topSpreadTicks":411,"bid5Volume":132,"ask5Volume":138,"bid10Volume":300,"ask10Volume":518,"rawPayload":"{\"stream\":\"btcusdt@depth@100ms\",\"data\":{\"e\":\"depthUpdate\",\"E\":1784429267271,\"s\":\"BTCUSDT\",\"U\":3244435207,\"u\":3244435207,\"b\":[],\"a\":[[\"81072.08000000\",\"0.00060000\"]]}}"}
{"mode":"v9-depth-v5-spsc","workers":4,"sequenceNumber":179,"symbol":"ETHUSDT","exchangeEventTimeMillis":1784429267271,"localReceivedEpochMillis":1784429267262,"topSpreadTicks":23,"bid5Volume":5917,"ask5Volume":5025,"bid10Volume":12873,"ask10Volume":17049,"rawPayload":"{\"stream\":\"ethusdt@depth@100ms\",\"data\":{\"e\":\"depthUpdate\",\"E\":1784429267271,\"s\":\"ETHUSDT\",\"U\":2806164232,\"u\":2806164233,\"b\":[[\"1863.00000000\",\"0.00000000\"]],\"a\":[[\"1879.33000000\",\"7.19080000\"]]}}"}
{"mode":"v9-depth-v5-spsc","workers":4,"sequenceNumber":180,"symbol":"BTCUSDT","exchangeEventTimeMillis":1784429267471,"localReceivedEpochMillis":1784429267462,"topSpreadTicks":411,"bid5Volume":122,"ask5Volume":138,"bid10Volume":290,"ask10Volume":518,"rawPayload":"{\"stream\":\"btcusdt@depth@100ms\",\"data\":{\"e\":\"depthUpdate\",\"E\":1784429267471,\"s\":\"BTCUSDT\",\"U\":3244435208,\"u\":3244435211,\"b\":[[\"64819.94000000\",\"0.00000000\"],[\"64818.25000000\",\"0.01687000\"],[\"64768.68000000\",\"0.00000000\"],[\"64563.88000000\",\"0.00000000\"]],\"a\":[]}}"}
{"mode":"v9-depth-v5-spsc","workers":4,"sequenceNumber":181,"symbol":"ETHUSDT","exchangeEventTimeMillis":1784429267471,"localReceivedEpochMillis":1784429267462,"topSpreadTicks":23,"bid5Volume":5917,"ask5Volume":5025,"bid10Volume":40841,"ask10Volume":17049,"rawPayload":"{\"stream\":\"ethusdt@depth@100ms\",\"data\":{\"e\":\"depthUpdate\",\"E\":1784429267471,\"s\":\"ETHUSDT\",\"U\":2806164234,\"u\":2806164238,\"b\":[[\"1871.40000000\",\"0.00000000\"],[\"1871.22000000\",\"0.12100000\"],[\"1870.85000000\",\"1.09310000\"],[\"1864.37000000\",\"7.15780000\"]],\"a\":[[\"1880.51000000\",\"9.15890000\"]]}}"}
{"mode":"v9-depth-v5-spsc","workers":4,"sequenceNumber":182,"symbol":"XRPUSDT","exchangeEventTimeMillis":1784429267471,"localReceivedEpochMillis":1784429267462,"topSpreadTicks":0,"bid5Volume":9846500,"ask5Volume":2891800,"bid10Volume":20028300,"ask10Volume":4089700,"rawPayload":"{\"stream\":\"xrpusdt@depth@100ms\",\"data\":{\"e\":\"depthUpdate\",\"E\":1784429267471,\"s\":\"XRPUSDT\",\"U\":752699360,\"u\":752699361,\"b\":[],\"a\":[[\"1.09690000\",\"2074.70000000\"],[\"1.09700000\",\"2576.50000000\"]]}}"}
{"mode":"v9-depth-v5-spsc","workers":4,"sequenceNumber":183,"symbol":"BTCUSDT","exchangeEventTimeMillis":1784429267571,"localReceivedEpochMillis":1784429267561,"topSpreadTicks":411,"bid5Volume":122,"ask5Volume":138,"bid10Volume":290,"ask10Volume":518,"rawPayload":"{\"stream\":\"btcusdt@depth@100ms\",\"data\":{\"e\":\"depthUpdate\",\"E\":1784429267571,\"s\":\"BTCUSDT\",\"U\":3244435212,\"u\":3244435212,\"b\":[],\"a\":[[\"81072.08000000\",\"0.00060000\"]]}}"}
{"mode":"v9-depth-v5-spsc","workers":4,"sequenceNumber":184,"symbol":"ETHUSDT","exchangeEventTimeMillis":1784429267571,"localReceivedEpochMillis":1784429267561,"topSpreadTicks":23,"bid5Volume":5808,"ask5Volume":3943,"bid10Volume":10170,"ask10Volume":15439,"rawPayload":"{\"stream\":\"ethusdt@depth@100ms\",\"data\":{\"e\":\"depthUpdate\",\"E\":1784429267571,\"s\":\"ETHUSDT\",\"U\":2806164239,\"u\":2806164240,\"b\":[[\"1871.56000000\",\"0.02940000\"]],\"a\":[[\"1872.12000000\",\"0.02970000\"]]}}"}
{"mode":"v9-depth-v5-spsc","workers":4,"sequenceNumber":185,"symbol":"SOLUSDT","exchangeEventTimeMillis":1784429267671,"localReceivedEpochMillis":1784429267662,"topSpreadTicks":1,"bid5Volume":122490,"ask5Volume":156305,"bid10Volume":433417,"ask10Volume":912033,"rawPayload":"{\"stream\":\"solusdt@depth@100ms\",\"data\":{\"e\":\"depthUpdate\",\"E\":1784429267671,\"s\":\"SOLUSDT\",\"U\":1609569672,\"u\":1609569676,\"b\":[],\"a\":[[\"76.26000000\",\"57.99800000\"],[\"76.27000000\",\"17.97500000\"],[\"76.28000000\",\"7.41800000\"],[\"76.33000000\",\"13.12100000\"]]}}"}
{"mode":"v9-depth-v5-spsc","workers":4,"sequenceNumber":186,"symbol":"BTCUSDT","exchangeEventTimeMillis":1784429267671,"localReceivedEpochMillis":1784429267662,"topSpreadTicks":411,"bid5Volume":122,"ask5Volume":138,"bid10Volume":290,"ask10Volume":586,"rawPayload":"{\"stream\":\"btcusdt@depth@100ms\",\"data\":{\"e\":\"depthUpdate\",\"E\":1784429267671,\"s\":\"BTCUSDT\",\"U\":3244435213,\"u\":3244435214,\"b\":[],\"a\":[[\"64841.18000000\",\"0.07161000\"],[\"64872.89000000\",\"0.00000000\"]]}}"}
{"mode":"v9-depth-v5-spsc","workers":4,"sequenceNumber":187,"symbol":"ETHUSDT","exchangeEventTimeMillis":1784429267671,"localReceivedEpochMillis":1784429267662,"topSpreadTicks":12,"bid5Volume":5808,"ask5Volume":3943,"bid10Volume":10170,"ask10Volume":15439,"rawPayload":"{\"stream\":\"ethusdt@depth@100ms\",\"data\":{\"e\":\"depthUpdate\",\"E\":1784429267671,\"s\":\"ETHUSDT\",\"U\":2806164241,\"u\":2806164242,\"b\":[[\"1871.29000000\",\"1.02590000\"],[\"1871.27000000\",\"0.00000000\"]],\"a\":[[\"1871.99000000\",\"0.96640000\"],[\"1872.33000000\",\"0.00000000\"]]}}"}
{"mode":"v9-depth-v5-spsc","workers":4,"sequenceNumber":188,"symbol":"BTCUSDT","exchangeEventTimeMillis":1784429267771,"localReceivedEpochMillis":1784429267762,"topSpreadTicks":411,"bid5Volume":122,"ask5Volume":101,"bid10Volume":290,"ask10Volume":586,"rawPayload":"{\"stream\":\"btcusdt@depth@100ms\",\"data\":{\"e\":\"depthUpdate\",\"E\":1784429267771,\"s\":\"BTCUSDT\",\"U\":3244435215,\"u\":3244435216,\"b\":[],\"a\":[[\"64836.74000000\",\"0.00172000\"],[\"64839.59000000\",\"0.00000000\"]]}}"}
{"mode":"v9-depth-v5-spsc","workers":4,"sequenceNumber":189,"symbol":"SOLUSDT","exchangeEventTimeMillis":1784429267871,"localReceivedEpochMillis":1784429267861,"topSpreadTicks":1,"bid5Volume":122490,"ask5Volume":156303,"bid10Volume":433417,"ask10Volume":912031,"rawPayload":"{\"stream\":\"solusdt@depth@100ms\",\"data\":{\"e\":\"depthUpdate\",\"E\":1784429267871,\"s\":\"SOLUSDT\",\"U\":1609569677,\"u\":1609569677,\"b\":[],\"a\":[[\"76.26000000\",\"54.58900000\"],[\"76.27000000\",\"21.38200000\"]]}}"}
{"mode":"v9-depth-v5-spsc","workers":4,"sequenceNumber":190,"symbol":"BTCUSDT","exchangeEventTimeMillis":1784429267871,"localReceivedEpochMillis":1784429267862,"topSpreadTicks":411,"bid5Volume":122,"ask5Volume":101,"bid10Volume":290,"ask10Volume":586,"rawPayload":"{\"stream\":\"btcusdt@depth@100ms\",\"data\":{\"e\":\"depthUpdate\",\"E\":1784429267871,\"s\":\"BTCUSDT\",\"U\":3244435217,\"u\":3244435218,\"b\":[],\"a\":[[\"64836.74000000\",\"0.00000000\"],[\"64837.71000000\",\"0.00158000\"]]}}"}
{"mode":"v9-depth-v5-spsc","workers":4,"sequenceNumber":191,"symbol":"BTCUSDT","exchangeEventTimeMillis":1784429267971,"localReceivedEpochMillis":1784429267963,"topSpreadTicks":411,"bid5Volume":122,"ask5Volume":138,"bid10Volume":290,"ask10Volume":586,"rawPayload":"{\"stream\":\"btcusdt@depth@100ms\",\"data\":{\"e\":\"depthUpdate\",\"E\":1784429267971,\"s\":\"BTCUSDT\",\"U\":3244435219,\"u\":3244435222,\"b\":[],\"a\":[[\"64836.74000000\",\"0.00000000\"],[\"64837.71000000\",\"0.00000000\"],[\"64839.78000000\",\"0.00163000\"]]}}"}
{"mode":"v9-depth-v5-spsc","workers":4,"sequenceNumber":192,"symbol":"ETHUSDT","exchangeEventTimeMillis":1784429267971,"localReceivedEpochMillis":1784429267963,"topSpreadTicks":12,"bid5Volume":5808,"ask5Volume":3943,"bid10Volume":10170,"ask10Volume":15439,"rawPayload":"{\"stream\":\"ethusdt@depth@100ms\",\"data\":{\"e\":\"depthUpdate\",\"E\":1784429267971,\"s\":\"ETHUSDT\",\"U\":2806164243,\"u\":2806164243,\"b\":[[\"1870.38000000\",\"1.63970000\"]],\"a\":[]}}"}
{"mode":"v9-depth-v5-spsc","workers":4,"sequenceNumber":193,"symbol":"SOLUSDT","exchangeEventTimeMillis":1784429268071,"localReceivedEpochMillis":1784429268062,"topSpreadTicks":1,"bid5Volume":122490,"ask5Volume":156303,"bid10Volume":433417,"ask10Volume":720316,"rawPayload":"{\"stream\":\"solusdt@depth@100ms\",\"data\":{\"e\":\"depthUpdate\",\"E\":1784429268071,\"s\":\"SOLUSDT\",\"U\":1609569678,\"u\":1609569681,\"b\":[],\"a\":[[\"76.30000000\",\"64.61500000\"],[\"76.31000000\",\"30.19500000\"],[\"76.62000000\",\"55.28300000\"]]}}"}
{"mode":"v9-depth-v5-spsc","workers":4,"sequenceNumber":194,"symbol":"BTCUSDT","exchangeEventTimeMillis":1784429268071,"localReceivedEpochMillis":1784429268062,"topSpreadTicks":411,"bid5Volume":122,"ask5Volume":138,"bid10Volume":290,"ask10Volume":586,"rawPayload":"{\"stream\":\"btcusdt@depth@100ms\",\"data\":{\"e\":\"depthUpdate\",\"E\":1784429268071,\"s\":\"BTCUSDT\",\"U\":3244435223,\"u\":3244435230,\"b\":[[\"64812.00000000\",\"0.00000000\"],[\"64810.84000000\",\"0.02826000\"]],\"a\":[[\"64825.85000000\",\"0.00000000\"],[\"64826.28000000\",\"0.00000000\"],[\"64826.64000000\",\"0.00401000\"],[\"64828.71000000\",\"0.02820000\"],[\"64832.58000000\",\"0.00000000\"],[\"64839.78000000\",\"0.00000000\"],[\"64839.92000000\",\"0.00168000\"],[\"64840.59000000\",\"0.00000000\"]]}}"}
{"mode":"v9-depth-v5-spsc","workers":4,"sequenceNumber":195,"symbol":"BTCUSDT","exchangeEventTimeMillis":1784429268171,"localReceivedEpochMillis":1784429268162,"topSpreadTicks":411,"bid5Volume":122,"ask5Volume":138,"bid10Volume":290,"ask10Volume":586,"rawPayload":"{\"stream\":\"btcusdt@depth@100ms\",\"data\":{\"e\":\"depthUpdate\",\"E\":1784429268171,\"s\":\"BTCUSDT\",\"U\":3244435231,\"u\":3244435239,\"b\":[[\"64819.37000000\",\"0.00000000\"],[\"64756.76000000\",\"0.00000000\"],[\"64753.61000000\",\"0.05832000\"],[\"64717.86000000\",\"0.00000000\"],[\"64714.72000000\",\"0.08812000\"],[\"64678.96000000\",\"0.00000000\"],[\"64675.82000000\",\"0.17331000\"],[\"64601.16000000\",\"0.00000000\"],[\"64598.02000000\",\"0.40717000\"]],\"a\":[[\"64909.15000000\",\"0.06043000\"],[\"64912.32000000\",\"0.00000000\"],[\"64948.05000000\",\"0.09239000\"],[\"64951.22000000\",\"0.00000000\"],[\"64986.95000000\",\"0.17644000\"],[\"64990.12000000\",\"0.00000000\"],[\"65064.75000000\",\"0.42827000\"],[\"65067.92000000\",\"0.00000000\"]]}}"}
{"mode":"v9-depth-v5-spsc","workers":4,"sequenceNumber":196,"symbol":"BNBUSDT","exchangeEventTimeMillis":1784429268271,"localReceivedEpochMillis":1784429268263,"topSpreadTicks":10,"bid5Volume":4595,"ask5Volume":8258,"bid10Volume":25182,"ask10Volume":262633,"rawPayload":"{\"stream\":\"bnbusdt@depth@100ms\",\"data\":{\"e\":\"depthUpdate\",\"E\":1784429268271,\"s\":\"BNBUSDT\",\"U\":1236327958,\"u\":1236327959,\"b\":[[\"570.74000000\",\"0.00000000\"],[\"570.72000000\",\"1.73700000\"]],\"a\":[[\"571.00000000\",\"1.61500000\"],[\"571.01000000\",\"0.00000000\"]]}}"}
{"mode":"v9-depth-v5-spsc","workers":4,"sequenceNumber":197,"symbol":"ETHUSDT","exchangeEventTimeMillis":1784429268371,"localReceivedEpochMillis":1784429268363,"topSpreadTicks":18,"bid5Volume":5843,"ask5Volume":3577,"bid10Volume":10369,"ask10Volume":15436,"rawPayload":"{\"stream\":\"ethusdt@depth@100ms\",\"data\":{\"e\":\"depthUpdate\",\"E\":1784429268371,\"s\":\"ETHUSDT\",\"U\":2806164244,\"u\":2806164249,\"b\":[[\"1871.87000000\",\"0.00000000\"],[\"1871.81000000\",\"1.16170000\"],[\"1871.30000000\",\"1.63970000\"],[\"1870.38000000\",\"0.00000000\"]],\"a\":[[\"1872.39000000\",\"1.10810000\"],[\"1872.44000000\",\"0.00000000\"]]}}"}
{"mode":"v9-depth-v5-spsc","workers":4,"sequenceNumber":198,"symbol":"BTCUSDT","exchangeEventTimeMillis":1784429268572,"localReceivedEpochMillis":1784429268562,"topSpreadTicks":411,"bid5Volume":124,"ask5Volume":101,"bid10Volume":292,"ask10Volume":586,"rawPayload":"{\"stream\":\"btcusdt@depth@100ms\",\"data\":{\"e\":\"depthUpdate\",\"E\":1784429268572,\"s\":\"BTCUSDT\",\"U\":3244435240,\"u\":3244435243,\"b\":[[\"64818.25000000\",\"0.00000000\"],[\"64816.38000000\",\"0.01868000\"]],\"a\":[[\"64838.50000000\",\"0.00172000\"],[\"64839.92000000\",\"0.00000000\"]]}}"}
{"mode":"v9-depth-v5-spsc","workers":4,"sequenceNumber":199,"symbol":"SOLUSDT","exchangeEventTimeMillis":1784429268672,"localReceivedEpochMillis":1784429268662,"topSpreadTicks":1,"bid5Volume":122490,"ask5Volume":170142,"bid10Volume":433417,"ask10Volume":458432,"rawPayload":"{\"stream\":\"solusdt@depth@100ms\",\"data\":{\"e\":\"depthUpdate\",\"E\":1784429268672,\"s\":\"SOLUSDT\",\"U\":1609569682,\"u\":1609569692,\"b\":[],\"a\":[[\"76.29000000\",\"50.01800000\"],[\"76.30000000\",\"50.32500000\"],[\"76.32000000\",\"30.19500000\"]]}}"}
{"mode":"v9-depth-v5-spsc","workers":4,"sequenceNumber":200,"symbol":"BTCUSDT","exchangeEventTimeMillis":1784429268672,"localReceivedEpochMillis":1784429268662,"topSpreadTicks":411,"bid5Volume":124,"ask5Volume":101,"bid10Volume":278,"ask10Volume":586,"rawPayload":"{\"stream\":\"btcusdt@depth@100ms\",\"data\":{\"e\":\"depthUpdate\",\"E\":1784429268672,\"s\":\"BTCUSDT\",\"U\":3244435244,\"u\":3244435251,\"b\":[[\"64816.38000000\",\"0.00000000\"],[\"64814.53000000\",\"0.01883000\"],[\"64807.16000000\",\"0.00000000\"],[\"64803.22000000\",\"0.00000000\"],[\"64800.52000000\",\"0.02825000\"],[\"64795.94000000\",\"0.20860000\"],[\"64795.69000000\",\"0.00000000\"],[\"64782.06000000\",\"0.03766000\"]],\"a\":[]}}"}
{"mode":"v9-depth-v5-spsc","workers":4,"sequenceNumber":201,"symbol":"ETHUSDT","exchangeEventTimeMillis":1784429268672,"localReceivedEpochMillis":1784429268662,"topSpreadTicks":23,"bid5Volume":5862,"ask5Volume":3609,"bid10Volume":10224,"ask10Volume":15468,"rawPayload":"{\"stream\":\"ethusdt@depth@100ms\",\"data\":{\"e\":\"depthUpdate\",\"E\":1784429268672,\"s\":\"ETHUSDT\",\"U\":2806164250,\"u\":2806164260,\"b\":[[\"1871.81000000\",\"0.00000000\"],[\"1871.76000000\",\"1.09770000\"],[\"1871.60000000\",\"0.75000000\"],[\"1871.59000000\",\"1.33660000\"],[\"1871.52000000\",\"0.00000000\"],[\"1871.46000000\",\"2.65040000\"],[\"1871.30000000\",\"0.00000000\"],[\"1870.85000000\",\"0.00000000\"],[\"1870.25000000\",\"3.58400000\"]],\"a\":[[\"1872.33000000\",\"1.14080000\"],[\"1872.39000000\",\"0.00000000\"]]}}"}
{"mode":"v9-depth-v5-spsc","workers":4,"sequenceNumber":202,"symbol":"XRPUSDT","exchangeEventTimeMillis":1784429268672,"localReceivedEpochMillis":1784429268663,"topSpreadTicks":0,"bid5Volume":9846500,"ask5Volume":2105700,"bid10Volume":20028300,"ask10Volume":3303600,"rawPayload":"{\"stream\":\"xrpusdt@depth@100ms\",\"data\":{\"e\":\"depthUpdate\",\"E\":1784429268672,\"s\":\"XRPUSDT\",\"U\":752699362,\"u\":752699363,\"b\":[],\"a\":[[\"1.09670000\",\"2281.10000000\"],[\"1.09680000\",\"1790.40000000\"]]}}"}
{"mode":"v9-depth-v5-spsc","workers":4,"sequenceNumber":203,"symbol":"SOLUSDT","exchangeEventTimeMillis":1784429268772,"localReceivedEpochMillis":1784429268762,"topSpreadTicks":1,"bid5Volume":92295,"ask5Volume":169737,"bid10Volume":433417,"ask10Volume":458027,"rawPayload":"{\"stream\":\"solusdt@depth@100ms\",\"data\":{\"e\":\"depthUpdate\",\"E\":1784429268772,\"s\":\"SOLUSDT\",\"U\":1609569693,\"u\":1609569696,\"b\":[[\"76.20000000\",\"19.65200000\"],[\"76.17000000\",\"48.13400000\"]],\"a\":[[\"76.29000000\",\"49.61300000\"]]}}"}
{"mode":"v9-depth-v5-spsc","workers":4,"sequenceNumber":204,"symbol":"BTCUSDT","exchangeEventTimeMillis":1784429268772,"localReceivedEpochMillis":1784429268762,"topSpreadTicks":411,"bid5Volume":124,"ask5Volume":128,"bid10Volume":278,"ask10Volume":590,"rawPayload":"{\"stream\":\"btcusdt@depth@100ms\",\"data\":{\"e\":\"depthUpdate\",\"E\":1784429268772,\"s\":\"BTCUSDT\",\"U\":3244435252,\"u\":3244435262,\"b\":[[\"64816.95000000\",\"0.00079000\"],[\"64815.88000000\",\"0.01893000\"],[\"64814.53000000\",\"0.00000000\"],[\"64814.22000000\",\"0.00000000\"],[\"64763.95000000\",\"0.20914000\"]],\"a\":[[\"64833.04000000\",\"0.00000000\"],[\"64834.38000000\",\"0.02835000\"],[\"64840.95000000\",\"0.00000000\"],[\"64880.60000000\",\"0.20746000\"],[\"64968.43000000\",\"0.00000000\"]]}}"}
{"mode":"v9-depth-v5-spsc","workers":4,"sequenceNumber":205,"symbol":"ETHUSDT","exchangeEventTimeMillis":1784429268772,"localReceivedEpochMillis":1784429268763,"topSpreadTicks":23,"bid5Volume":5137,"ask5Volume":3609,"bid10Volume":8753,"ask10Volume":15468,"rawPayload":"{\"stream\":\"ethusdt@depth@100ms\",\"data\":{\"e\":\"depthUpdate\",\"E\":1784429268772,\"s\":\"ETHUSDT\",\"U\":2806164261,\"u\":2806164266,\"b\":[[\"1871.59000000\",\"0.00000000\"],[\"1871.46000000\",\"1.92510000\"],[\"1871.44000000\",\"1.33680000\"],[\"1871.40000000\",\"0.72940000\"]],\"a\":[[\"1872.07000000\",\"1.33630000\"],[\"1872.21000000\",\"0.00000000\"]]}}"}
{"mode":"v9-depth-v5-spsc","workers":4,"sequenceNumber":206,"symbol":"BTCUSDT","exchangeEventTimeMillis":1784429268872,"localReceivedEpochMillis":1784429268862,"topSpreadTicks":411,"bid5Volume":124,"ask5Volume":128,"bid10Volume":278,"ask10Volume":590,"rawPayload":"{\"stream\":\"btcusdt@depth@100ms\",\"data\":{\"e\":\"depthUpdate\",\"E\":1784429268872,\"s\":\"BTCUSDT\",\"U\":3244435263,\"u\":3244435263,\"b\":[[\"64562.64000000\",\"0.26568000\"]],\"a\":[]}}"}
{"mode":"v9-depth-v5-spsc","workers":4,"sequenceNumber":207,"symbol":"BTCUSDT","exchangeEventTimeMillis":1784429268972,"localReceivedEpochMillis":1784429268964,"topSpreadTicks":422,"bid5Volume":124,"ask5Volume":128,"bid10Volume":278,"ask10Volume":590,"rawPayload":"{\"stream\":\"btcusdt@depth@100ms\",\"data\":{\"e\":\"depthUpdate\",\"E\":1784429268972,\"s\":\"BTCUSDT\",\"U\":3244435264,\"u\":3244435266,\"b\":[[\"64821.73000000\",\"0.00000000\"],[\"64820.96000000\",\"0.04000000\"]],\"a\":[[\"81072.08000000\",\"0.00075000\"]]}}"}
{"mode":"v9-depth-v5-spsc","workers":4,"sequenceNumber":208,"symbol":"ETHUSDT","exchangeEventTimeMillis":1784429269072,"localReceivedEpochMillis":1784429269062,"topSpreadTicks":23,"bid5Volume":3939,"ask5Volume":3609,"bid10Volume":8624,"ask10Volume":15467,"rawPayload":"{\"stream\":\"ethusdt@depth@100ms\",\"data\":{\"e\":\"depthUpdate\",\"E\":1784429269072,\"s\":\"ETHUSDT\",\"U\":2806164267,\"u\":2806164273,\"b\":[[\"1871.54000000\",\"0.13890000\"],[\"1871.43000000\",\"0.00000000\"],[\"1871.24000000\",\"1.47490000\"],[\"1871.20000000\",\"0.00000000\"],[\"1871.13000000\",\"0.00000000\"],[\"1871.01000000\",\"1.12150000\"],[\"1870.63000000\",\"1.09310000\"]],\"a\":[[\"1872.10000000\",\"0.00000000\"],[\"1872.20000000\",\"0.13880000\"],[\"1872.40000000\",\"0.00000000\"],[\"1872.50000000\",\"1.47380000\"]]}}"}
{"mode":"v9-depth-v5-spsc","workers":4,"sequenceNumber":209,"symbol":"BTCUSDT","exchangeEventTimeMillis":1784429269072,"localReceivedEpochMillis":1784429269063,"topSpreadTicks":422,"bid5Volume":124,"ask5Volume":128,"bid10Volume":278,"ask10Volume":590,"rawPayload":"{\"stream\":\"btcusdt@depth@100ms\",\"data\":{\"e\":\"depthUpdate\",\"E\":1784429269072,\"s\":\"BTCUSDT\",\"U\":3244435267,\"u\":3244435270,\"b\":[[\"64816.95000000\",\"0.00000000\"],[\"64810.84000000\",\"0.00000000\"],[\"64808.11000000\",\"0.02826000\"]],\"a\":[[\"64827.72000000\",\"0.02820000\"],[\"64828.71000000\",\"0.00000000\"],[\"64829.22000000\",\"0.00079000\"]]}}"}
{"mode":"v9-depth-v5-spsc","workers":4,"sequenceNumber":210,"symbol":"SOLUSDT","exchangeEventTimeMillis":1784429269172,"localReceivedEpochMillis":1784429269163,"topSpreadTicks":1,"bid5Volume":92295,"ask5Volume":156303,"bid10Volume":433417,"ask10Volume":458288,"rawPayload":"{\"stream\":\"solusdt@depth@100ms\",\"data\":{\"e\":\"depthUpdate\",\"E\":1784429269172,\"s\":\"SOLUSDT\",\"U\":1609569697,\"u\":1609569698,\"b\":[],\"a\":[[\"76.29000000\",\"36.17900000\"],[\"76.30000000\",\"64.02000000\"]]}}"}
{"mode":"v9-depth-v5-spsc","workers":4,"sequenceNumber":211,"symbol":"BNBUSDT","exchangeEventTimeMillis":1784429269172,"localReceivedEpochMillis":1784429269164,"topSpreadTicks":10,"bid5Volume":4595,"ask5Volume":8258,"bid10Volume":25182,"ask10Volume":262633,"rawPayload":"{\"stream\":\"bnbusdt@depth@100ms\",\"data\":{\"e\":\"depthUpdate\",\"E\":1784429269172,\"s\":\"BNBUSDT\",\"U\":1236327960,\"u\":1236327960,\"b\":[[\"570.72000000\",\"0.00000000\"],[\"570.67000000\",\"1.73700000\"]],\"a\":[]}}"}
{"mode":"v9-depth-v5-spsc","workers":4,"sequenceNumber":212,"symbol":"BTCUSDT","exchangeEventTimeMillis":1784429269172,"localReceivedEpochMillis":1784429269164,"topSpreadTicks":422,"bid5Volume":124,"ask5Volume":128,"bid10Volume":278,"ask10Volume":590,"rawPayload":"{\"stream\":\"btcusdt@depth@100ms\",\"data\":{\"e\":\"depthUpdate\",\"E\":1784429269172,\"s\":\"BTCUSDT\",\"U\":3244435271,\"u\":3244435271,\"b\":[[\"64815.11000000\",\"0.00077000\"]],\"a\":[]}}"}
{"mode":"v9-depth-v5-spsc","workers":4,"sequenceNumber":213,"symbol":"BTCUSDT","exchangeEventTimeMillis":1784429269272,"localReceivedEpochMillis":1784429269262,"topSpreadTicks":422,"bid5Volume":124,"ask5Volume":128,"bid10Volume":278,"ask10Volume":590,"rawPayload":"{\"stream\":\"btcusdt@depth@100ms\",\"data\":{\"e\":\"depthUpdate\",\"E\":1784429269272,\"s\":\"BTCUSDT\",\"U\":3244435272,\"u\":3244435272,\"b\":[[\"64707.05000000\",\"0.00000000\"]],\"a\":[]}}"}
{"mode":"v9-depth-v5-spsc","workers":4,"sequenceNumber":214,"symbol":"ETHUSDT","exchangeEventTimeMillis":1784429269372,"localReceivedEpochMillis":1784429269363,"topSpreadTicks":23,"bid5Volume":3939,"ask5Volume":3609,"bid10Volume":8624,"ask10Volume":15467,"rawPayload":"{\"stream\":\"ethusdt@depth@100ms\",\"data\":{\"e\":\"depthUpdate\",\"E\":1784429269372,\"s\":\"ETHUSDT\",\"U\":2806164274,\"u\":2806164280,\"b\":[[\"1869.82000000\",\"0.00000000\"],[\"1869.56000000\",\"2.05300000\"],[\"1868.70000000\",\"0.00000000\"],[\"1868.43000000\",\"2.95960000\"],[\"1867.57000000\",\"0.00000000\"],[\"1867.31000000\",\"5.99790000\"],[\"1865.33000000\",\"0.00000000\"],[\"1865.06000000\",\"13.72160000\"]],\"a\":[[\"1874.06000000\",\"2.04860000\"],[\"1874.32000000\",\"0.00000000\"],[\"1875.18000000\",\"3.02900000\"],[\"1875.44000000\",\"0.00000000\"],[\"1876.30000000\",\"6.30890000\"],[\"1876.57000000\",\"0.00000000\"]]}}"}
{"mode":"v9-depth-v5-spsc","workers":4,"sequenceNumber":215,"symbol":"ETHUSDT","exchangeEventTimeMillis":1784429269472,"localReceivedEpochMillis":1784429269464,"topSpreadTicks":23,"bid5Volume":3939,"ask5Volume":3609,"bid10Volume":10142,"ask10Volume":15467,"rawPayload":"{\"stream\":\"ethusdt@depth@100ms\",\"data\":{\"e\":\"depthUpdate\",\"E\":1784429269472,\"s\":\"ETHUSDT\",\"U\":2806164281,\"u\":2806164284,\"b\":[[\"1871.23000000\",\"1.63970000\"],[\"1871.06000000\",\"1.09310000\"],[\"1870.63000000\",\"0.00000000\"],[\"1870.25000000\",\"1.94430000\"]],\"a\":[]}}"}
{"mode":"v9-depth-v5-spsc","workers":4,"sequenceNumber":216,"symbol":"SOLUSDT","exchangeEventTimeMillis":1784429269572,"localReceivedEpochMillis":1784429269564,"topSpreadTicks":1,"bid5Volume":122490,"ask5Volume":156303,"bid10Volume":433417,"ask10Volume":458288,"rawPayload":"{\"stream\":\"solusdt@depth@100ms\",\"data\":{\"e\":\"depthUpdate\",\"E\":1784429269572,\"s\":\"SOLUSDT\",\"U\":1609569699,\"u\":1609569700,\"b\":[[\"76.21000000\",\"33.70600000\"],[\"76.17000000\",\"17.93900000\"]],\"a\":[]}}"}
{"mode":"v9-depth-v5-spsc","workers":4,"sequenceNumber":217,"symbol":"BTCUSDT","exchangeEventTimeMillis":1784429269572,"localReceivedEpochMillis":1784429269564,"topSpreadTicks":422,"bid5Volume":124,"ask5Volume":128,"bid10Volume":278,"ask10Volume":592,"rawPayload":"{\"stream\":\"btcusdt@depth@100ms\",\"data\":{\"e\":\"depthUpdate\",\"E\":1784429269572,\"s\":\"BTCUSDT\",\"U\":3244435273,\"u\":3244435273,\"b\":[],\"a\":[[\"64838.50000000\",\"0.00000000\"]]}}"}
{"mode":"v9-depth-v5-spsc","workers":4,"sequenceNumber":218,"symbol":"ETHUSDT","exchangeEventTimeMillis":1784429269572,"localReceivedEpochMillis":1784429269564,"topSpreadTicks":34,"bid5Volume":4550,"ask5Volume":3600,"bid10Volume":9538,"ask10Volume":15458,"rawPayload":"{\"stream\":\"ethusdt@depth@100ms\",\"data\":{\"e\":\"depthUpdate\",\"E\":1784429269572,\"s\":\"ETHUSDT\",\"U\":2806164285,\"u\":2806164289,\"b\":[[\"1871.76000000\",\"0.00000000\"],[\"1871.65000000\",\"1.12270000\"],[\"1871.60000000\",\"0.00000000\"]],\"a\":[[\"1872.23000000\",\"1.13160000\"],[\"1872.33000000\",\"0.00000000\"]]}}"}
{"mode":"v9-depth-v5-spsc","workers":4,"sequenceNumber":219,"symbol":"BTCUSDT","exchangeEventTimeMillis":1784429269672,"localReceivedEpochMillis":1784429269662,"topSpreadTicks":422,"bid5Volume":124,"ask5Volume":128,"bid10Volume":278,"ask10Volume":590,"rawPayload":"{\"stream\":\"btcusdt@depth@100ms\",\"data\":{\"e\":\"depthUpdate\",\"E\":1784429269672,\"s\":\"BTCUSDT\",\"U\":3244435274,\"u\":3244435278,\"b\":[],\"a\":[[\"64838.24000000\",\"0.00159000\"],[\"64839.92000000\",\"0.00000000\"],[\"64914.49000000\",\"0.00011000\"]]}}"}
{"mode":"v9-depth-v5-spsc","workers":4,"sequenceNumber":220,"symbol":"ETHUSDT","exchangeEventTimeMillis":1784429269672,"localReceivedEpochMillis":1784429269663,"topSpreadTicks":22,"bid5Volume":4550,"ask5Volume":3600,"bid10Volume":9538,"ask10Volume":15458,"rawPayload":"{\"stream\":\"ethusdt@depth@100ms\",\"data\":{\"e\":\"depthUpdate\",\"E\":1784429269672,\"s\":\"ETHUSDT\",\"U\":2806164290,\"u\":2806164291,\"b\":[[\"1871.33000000\",\"1.02590000\"],[\"1871.29000000\",\"0.00000000\"]],\"a\":[[\"1871.87000000\",\"0.96640000\"],[\"1871.99000000\",\"0.00000000\"]]}}"}
{"mode":"v9-depth-v5-spsc","workers":4,"sequenceNumber":221,"symbol":"SOLUSDT","exchangeEventTimeMillis":1784429269772,"localReceivedEpochMillis":1784429269765,"topSpreadTicks":1,"bid5Volume":122490,"ask5Volume":156303,"bid10Volume":433417,"ask10Volume":458288,"rawPayload":"{\"stream\":\"solusdt@depth@100ms\",\"data\":{\"e\":\"depthUpdate\",\"E\":1784429269772,\"s\":\"SOLUSDT\",\"U\":1609569701,\"u\":1609569702,\"b\":[[\"72.01000000\",\"13.87400000\"]],\"a\":[[\"76.26000000\",\"72.56400000\"],[\"76.27000000\",\"3.40700000\"]]}}"}
{"mode":"v9-depth-v5-spsc","workers":4,"sequenceNumber":222,"symbol":"SOLUSDT","exchangeEventTimeMillis":1784429269872,"localReceivedEpochMillis":1784429269863,"topSpreadTicks":1,"bid5Volume":122490,"ask5Volume":156303,"bid10Volume":451145,"ask10Volume":477219,"rawPayload":"{\"stream\":\"solusdt@depth@100ms\",\"data\":{\"e\":\"depthUpdate\",\"E\":1784429269872,\"s\":\"SOLUSDT\",\"U\":1609569703,\"u\":1609569710,\"b\":[[\"76.17000000\",\"0.00000000\"],[\"76.14000000\",\"194.49500000\"],[\"76.12000000\",\"17.72800000\"],[\"76.10000000\",\"373.97400000\"],[\"76.08000000\",\"0.00000000\"],[\"76.05000000\",\"392.60700000\"],[\"75.98000000\",\"526.81500000\"],[\"75.96000000\",\"150.75100000\"]],\"a\":[[\"76.26000000\",\"54.58900000\"],[\"76.27000000\",\"21.38200000\"],[\"76.34000000\",\"183.38500000\"],[\"76.36000000\",\"272.69700000\"],[\"76.38000000\",\"312.18700000\"],[\"76.41000000\",\"273.89600000\"],[\"76.43000000\",\"331.08500000\"],[\"76.45000000\",\"275.24900000\"]]}}"}
{"mode":"v9-depth-v5-spsc","workers":4,"sequenceNumber":223,"symbol":"SOLUSDT","exchangeEventTimeMillis":1784429269972,"localReceivedEpochMillis":1784429269964,"topSpreadTicks":1,"bid5Volume":122490,"ask5Volume":170468,"bid10Volume":451145,"ask10Volume":477689,"rawPayload":"{\"stream\":\"solusdt@depth@100ms\",\"data\":{\"e\":\"depthUpdate\",\"E\":1784429269972,\"s\":\"SOLUSDT\",\"U\":1609569711,\"u\":1609569712,\"b\":[],\"a\":[[\"76.29000000\",\"50.34400000\"],[\"76.30000000\",\"50.32500000\"]]}}"}
{"mode":"v9-depth-v5-spsc","workers":4,"sequenceNumber":224,"symbol":"SOLUSDT","exchangeEventTimeMillis":1784429270273,"localReceivedEpochMillis":1784429270263,"topSpreadTicks":1,"bid5Volume":122490,"ask5Volume":156303,"bid10Volume":451145,"ask10Volume":477923,"rawPayload":"{\"stream\":\"solusdt@depth@100ms\",\"data\":{\"e\":\"depthUpdate\",\"E\":1784429270273,\"s\":\"SOLUSDT\",\"U\":1609569713,\"u\":1609569714,\"b\":[],\"a\":[[\"76.29000000\",\"36.17900000\"],[\"76.30000000\",\"64.72400000\"]]}}"}
{"mode":"v9-depth-v5-spsc","workers":4,"sequenceNumber":225,"symbol":"BTCUSDT","exchangeEventTimeMillis":1784429270673,"localReceivedEpochMillis":1784429270666,"topSpreadTicks":422,"bid5Volume":124,"ask5Volume":128,"bid10Volume":278,"ask10Volume":590,"rawPayload":"{\"stream\":\"btcusdt@depth@100ms\",\"data\":{\"e\":\"depthUpdate\",\"E\":1784429270673,\"s\":\"BTCUSDT\",\"U\":3244435279,\"u\":3244435279,\"b\":[],\"a\":[[\"81072.08000000\",\"0.00075000\"]]}}"}
{"mode":"v9-depth-v5-spsc","workers":4,"sequenceNumber":226,"symbol":"SOLUSDT","exchangeEventTimeMillis":1784429270773,"localReceivedEpochMillis":1784429270763,"topSpreadTicks":1,"bid5Volume":122490,"ask5Volume":169745,"bid10Volume":451145,"ask10Volume":476966,"rawPayload":"{\"stream\":\"solusdt@depth@100ms\",\"data\":{\"e\":\"depthUpdate\",\"E\":1784429270773,\"s\":\"SOLUSDT\",\"U\":1609569715,\"u\":1609569716,\"b\":[],\"a\":[[\"76.29000000\",\"49.62100000\"],[\"76.30000000\",\"50.32500000\"]]}}"}
{"mode":"v9-depth-v5-spsc","workers":4,"sequenceNumber":227,"symbol":"SOLUSDT","exchangeEventTimeMillis":1784429270873,"localReceivedEpochMillis":1784429270864,"topSpreadTicks":1,"bid5Volume":122490,"ask5Volume":156303,"bid10Volume":451145,"ask10Volume":477509,"rawPayload":"{\"stream\":\"solusdt@depth@100ms\",\"data\":{\"e\":\"depthUpdate\",\"E\":1784429270873,\"s\":\"SOLUSDT\",\"U\":1609569717,\"u\":1609569718,\"b\":[],\"a\":[[\"76.29000000\",\"36.17900000\"],[\"76.30000000\",\"64.31000000\"]]}}"}
{"mode":"v9-depth-v5-spsc","workers":4,"sequenceNumber":228,"symbol":"BTCUSDT","exchangeEventTimeMillis":1784429271173,"localReceivedEpochMillis":1784429271164,"topSpreadTicks":422,"bid5Volume":124,"ask5Volume":128,"bid10Volume":278,"ask10Volume":590,"rawPayload":"{\"stream\":\"btcusdt@depth@100ms\",\"data\":{\"e\":\"depthUpdate\",\"E\":1784429271173,\"s\":\"BTCUSDT\",\"U\":3244435280,\"u\":3244435280,\"b\":[[\"64698.37000000\",\"0.02275000\"]],\"a\":[]}}"}
{"mode":"v9-depth-v5-spsc","workers":4,"sequenceNumber":229,"symbol":"XRPUSDT","exchangeEventTimeMillis":1784429271473,"localReceivedEpochMillis":1784429271464,"topSpreadTicks":0,"bid5Volume":13771900,"ask5Volume":13148200,"bid10Volume":23953700,"ask10Volume":14346100,"rawPayload":"{\"stream\":\"xrpusdt@depth@100ms\",\"data\":{\"e\":\"depthUpdate\",\"E\":1784429271473,\"s\":\"XRPUSDT\",\"U\":752699364,\"u\":752699371,\"b\":[[\"1.09540000\",\"0.00000000\"],[\"1.09510000\",\"8137.50000000\"],[\"1.09470000\",\"12721.10000000\"],[\"1.09450000\",\"2519.40000000\"],[\"1.09410000\",\"0.00000000\"],[\"1.09380000\",\"19745.40000000\"],[\"1.09270000\",\"0.00000000\"],[\"1.09250000\",\"8621.90000000\"]],\"a\":[[\"1.09790000\",\"8186.10000000\"],[\"1.09810000\",\"4556.50000000\"],[\"1.09850000\",\"15387.90000000\"],[\"1.09880000\",\"12901.20000000\"],[\"1.09920000\",\"18196.50000000\"],[\"1.09940000\",\"12832.90000000\"],[\"1.10050000\",\"9393.20000000\"],[\"1.10070000\",\"0.00000000\"]]}}"}
{"mode":"v9-depth-v5-spsc","workers":4,"sequenceNumber":230,"symbol":"SOLUSDT","exchangeEventTimeMillis":1784429271674,"localReceivedEpochMillis":1784429271664,"topSpreadTicks":1,"bid5Volume":122490,"ask5Volume":206628,"bid10Volume":451145,"ask10Volume":750206,"rawPayload":"{\"stream\":\"solusdt@depth@100ms\",\"data\":{\"e\":\"depthUpdate\",\"E\":1784429271674,\"s\":\"SOLUSDT\",\"U\":1609569719,\"u\":1609569722,\"b\":[],\"a\":[[\"76.28000000\",\"57.74300000\"],[\"76.30000000\",\"44.18000000\"],[\"76.32000000\",\"0.00000000\"]]}}"}
{"mode":"v9-depth-v5-spsc","workers":4,"sequenceNumber":231,"symbol":"BTCUSDT","exchangeEventTimeMillis":1784429271774,"localReceivedEpochMillis":1784429271764,"topSpreadTicks":422,"bid5Volume":124,"ask5Volume":128,"bid10Volume":278,"ask10Volume":590,"rawPayload":"{\"stream\":\"btcusdt@depth@100ms\",\"data\":{\"e\":\"depthUpdate\",\"E\":1784429271774,\"s\":\"BTCUSDT\",\"U\":3244435281,\"u\":3244435281,\"b\":[],\"a\":[[\"64909.31000000\",\"0.00000000\"]]}}"}
{"mode":"v9-depth-v5-spsc","workers":4,"sequenceNumber":232,"symbol":"ETHUSDT","exchangeEventTimeMillis":1784429272174,"localReceivedEpochMillis":1784429272165,"topSpreadTicks":7,"bid5Volume":4534,"ask5Volume":3565,"bid10Volume":9522,"ask10Volume":15423,"rawPayload":"{\"stream\":\"ethusdt@depth@100ms\",\"data\":{\"e\":\"depthUpdate\",\"E\":1784429272174,\"s\":\"ETHUSDT\",\"U\":2806164292,\"u\":2806164299,\"b\":[[\"1871.80000000\",\"1.10660000\"],[\"1871.72000000\",\"0.00000000\"],[\"1871.65000000\",\"0.00000000\"]],\"a\":[[\"1872.23000000\",\"0.00000000\"],[\"1872.29000000\",\"0.00000000\"],[\"1872.37000000\",\"1.09620000\"]]}}"}
{"mode":"v9-depth-v5-spsc","workers":4,"sequenceNumber":233,"symbol":"ETHUSDT","exchangeEventTimeMillis":1784429272274,"localReceivedEpochMillis":1784429272265,"topSpreadTicks":7,"bid5Volume":5453,"ask5Volume":3565,"bid10Volume":10805,"ask10Volume":15423,"rawPayload":"{\"stream\":\"ethusdt@depth@100ms\",\"data\":{\"e\":\"depthUpdate\",\"E\":1784429272274,\"s\":\"ETHUSDT\",\"U\":2806164300,\"u\":2806164303,\"b\":[[\"1871.59000000\",\"1.33660000\"],[\"1871.46000000\",\"2.84440000\"],[\"1871.44000000\",\"0.00000000\"],[\"1871.40000000\",\"0.00000000\"]],\"a\":[]}}"}
{"mode":"v9-depth-v5-spsc","workers":4,"sequenceNumber":234,"symbol":"SOLUSDT","exchangeEventTimeMillis":1784429272374,"localReceivedEpochMillis":1784429272364,"topSpreadTicks":1,"bid5Volume":122490,"ask5Volume":236823,"bid10Volume":451145,"ask10Volume":1022441,"rawPayload":"{\"stream\":\"solusdt@depth@100ms\",\"data\":{\"e\":\"depthUpdate\",\"E\":1784429272374,\"s\":\"SOLUSDT\",\"U\":1609569723,\"u\":1609569724,\"b\":[],\"a\":[[\"76.27000000\",\"51.57700000\"],[\"76.31000000\",\"0.00000000\"]]}}"}
{"mode":"v9-depth-v5-spsc","workers":4,"sequenceNumber":235,"symbol":"ETHUSDT","exchangeEventTimeMillis":1784429272374,"localReceivedEpochMillis":1784429272365,"topSpreadTicks":13,"bid5Volume":5511,"ask5Volume":3572,"bid10Volume":10863,"ask10Volume":15430,"rawPayload":"{\"stream\":\"ethusdt@depth@100ms\",\"data\":{\"e\":\"depthUpdate\",\"E\":1784429272374,\"s\":\"ETHUSDT\",\"U\":2806164304,\"u\":2806164307,\"b\":[[\"1871.80000000\",\"0.00000000\"],[\"1871.74000000\",\"1.16440000\"]],\"a\":[[\"1872.31000000\",\"1.10350000\"],[\"1872.37000000\",\"0.00000000\"]]}}"}
{"mode":"v9-depth-v5-spsc","workers":4,"sequenceNumber":236,"symbol":"XRPUSDT","exchangeEventTimeMillis":1784429272474,"localReceivedEpochMillis":1784429272465,"topSpreadTicks":0,"bid5Volume":13771900,"ask5Volume":810100,"bid10Volume":23953700,"ask10Volume":2008000,"rawPayload":"{\"stream\":\"xrpusdt@depth@100ms\",\"data\":{\"e\":\"depthUpdate\",\"E\":1784429272474,\"s\":\"XRPUSDT\",\"U\":752699372,\"u\":752699372,\"b\":[],\"a\":[[\"1.09670000\",\"3576.70000000\"],[\"1.09680000\",\"494.80000000\"]]}}"}
{"mode":"v9-depth-v5-spsc","workers":4,"sequenceNumber":237,"symbol":"ETHUSDT","exchangeEventTimeMillis":1784429272674,"localReceivedEpochMillis":1784429272665,"topSpreadTicks":13,"bid5Volume":5511,"ask5Volume":3572,"bid10Volume":39952,"ask10Volume":15430,"rawPayload":"{\"stream\":\"ethusdt@depth@100ms\",\"data\":{\"e\":\"depthUpdate\",\"E\":1784429272674,\"s\":\"ETHUSDT\",\"U\":2806164308,\"u\":2806164309,\"b\":[[\"1871.23000000\",\"0.00000000\"],[\"1871.06000000\",\"0.00000000\"]],\"a\":[]}}"}
{"mode":"v9-depth-v5-spsc","workers":4,"sequenceNumber":238,"symbol":"ETHUSDT","exchangeEventTimeMillis":1784429272774,"localReceivedEpochMillis":1784429272767,"topSpreadTicks":6,"bid5Volume":3572,"ask5Volume":3629,"bid10Volume":9544,"ask10Volume":15487,"rawPayload":"{\"stream\":\"ethusdt@depth@100ms\",\"data\":{\"e\":\"depthUpdate\",\"E\":1784429272774,\"s\":\"ETHUSDT\",\"U\":2806164310,\"u\":2806164338,\"b\":[[\"1871.86000000\",\"0.00000000\"],[\"1871.82000000\",\"0.00000000\"],[\"1871.81000000\",\"1.11850000\"],[\"1871.74000000\",\"0.00000000\"],[\"1871.72000000\",\"1.33660000\"],[\"1871.59000000\",\"0.00000000\"],[\"1871.58000000\",\"0.95180000\"],[\"1871.51000000\",\"0.00000000\"],[\"1871.46000000\",\"1.92510000\"],[\"1871.20000000\",\"1.42710000\"],[\"1871.01000000\",\"0.00000000\"],[\"1870.57000000\",\"1.09310000\"],[\"1870.10000000\",\"1.63970000\"]],\"a\":[[\"1872.05000000\",\"0.00000000\"],[\"1872.07000000\",\"0.00000000\"],[\"1872.24000000\",\"1.33620000\"],[\"1872.31000000\",\"0.00000000\"],[\"1872.38000000\",\"1.16060000\"],[\"1872.39000000\",\"0.00000000\"],[\"1872.46000000\",\"0.00000000\"],[\"1872.60000000\",\"1.63970000\"],[\"1879.37000000\",\"0.00000000\"]]}}"}
{"mode":"v9-depth-v5-spsc","workers":4,"sequenceNumber":239,"symbol":"BTCUSDT","exchangeEventTimeMillis":1784429272774,"localReceivedEpochMillis":1784429272767,"topSpreadTicks":422,"bid5Volume":131,"ask5Volume":128,"bid10Volume":285,"ask10Volume":590,"rawPayload":"{\"stream\":\"btcusdt@depth@100ms\",\"data\":{\"e\":\"depthUpdate\",\"E\":1784429272774,\"s\":\"BTCUSDT\",\"U\":3244435282,\"u\":3244435287,\"b\":[[\"64817.53000000\",\"0.02527000\"],[\"64815.88000000\",\"0.00000000\"]],\"a\":[[\"64838.24000000\",\"0.00000000\"],[\"64838.70000000\",\"0.00163000\"],[\"64840.67000000\",\"0.00000000\"]]}}"}
{"mode":"v9-depth-v5-spsc","workers":4,"sequenceNumber":240,"symbol":"SOLUSDT","exchangeEventTimeMillis":1784429272874,"localReceivedEpochMillis":1784429272866,"topSpreadTicks":1,"bid5Volume":122490,"ask5Volume":236823,"bid10Volume":451145,"ask10Volume":1022441,"rawPayload":"{\"stream\":\"solusdt@depth@100ms\",\"data\":{\"e\":\"depthUpdate\",\"E\":1784429272874,\"s\":\"SOLUSDT\",\"U\":1609569725,\"u\":1609569725,\"b\":[],\"a\":[[\"76.26000000\",\"72.56400000\"],[\"76.27000000\",\"33.60200000\"]]}}"}
{"mode":"v9-depth-v5-spsc","workers":4,"sequenceNumber":241,"symbol":"ETHUSDT","exchangeEventTimeMillis":1784429272874,"localReceivedEpochMillis":1784429272866,"topSpreadTicks":4,"bid5Volume":3556,"ask5Volume":3590,"bid10Volume":9528,"ask10Volume":15448,"rawPayload":"{\"stream\":\"ethusdt@depth@100ms\",\"data\":{\"e\":\"depthUpdate\",\"E\":1784429272874,\"s\":\"ETHUSDT\",\"U\":2806164339,\"u\":2806164349,\"b\":[[\"1871.86000000\",\"0.00000000\"],[\"1871.83000000\",\"1.10250000\"],[\"1871.81000000\",\"0.00000000\"],[\"1863.05000000\",\"0.00000000\"]],\"a\":[[\"1872.38000000\",\"0.00000000\"],[\"1872.40000000\",\"1.12180000\"],[\"1872.47000000\",\"1.63970000\"],[\"1879.33000000\",\"0.00000000\"],[\"1880.56000000\",\"9.20230000\"]]}}"}
{"mode":"v9-depth-v5-spsc","workers":4,"sequenceNumber":242,"symbol":"ETHUSDT","exchangeEventTimeMillis":1784429272974,"localReceivedEpochMillis":1784429272965,"topSpreadTicks":4,"bid5Volume":3556,"ask5Volume":3590,"bid10Volume":9528,"ask10Volume":15448,"rawPayload":"{\"stream\":\"ethusdt@depth@100ms\",\"data\":{\"e\":\"depthUpdate\",\"E\":1784429272974,\"s\":\"ETHUSDT\",\"U\":2806164350,\"u\":2806164351,\"b\":[[\"1864.42000000\",\"7.23850000\"]],\"a\":[[\"1880.61000000\",\"9.15720000\"]]}}"}
{"mode":"v9-depth-v5-spsc","workers":4,"sequenceNumber":243,"symbol":"XRPUSDT","exchangeEventTimeMillis":1784429272974,"localReceivedEpochMillis":1784429272966,"topSpreadTicks":0,"bid5Volume":9994000,"ask5Volume":810100,"bid10Volume":20175800,"ask10Volume":2008000,"rawPayload":"{\"stream\":\"xrpusdt@depth@100ms\",\"data\":{\"e\":\"depthUpdate\",\"E\":1784429272974,\"s\":\"XRPUSDT\",\"U\":752699373,\"u\":752699374,\"b\":[[\"1.09620000\",\"340.80000000\"],[\"1.09610000\",\"4844.00000000\"]],\"a\":[]}}"}
{"mode":"v9-depth-v5-spsc","workers":4,"sequenceNumber":244,"symbol":"XRPUSDT","exchangeEventTimeMillis":1784429273075,"localReceivedEpochMillis":1784429273066,"topSpreadTicks":2,"bid5Volume":9994000,"ask5Volume":403700,"bid10Volume":20175800,"ask10Volume":1513200,"rawPayload":"{\"stream\":\"xrpusdt@depth@100ms\",\"data\":{\"e\":\"depthUpdate\",\"E\":1784429273075,\"s\":\"XRPUSDT\",\"U\":752699375,\"u\":752699376,\"b\":[],\"a\":[[\"1.09680000\",\"2569.50000000\"],[\"1.09730000\",\"0.00000000\"]]}}"}
{"mode":"v9-depth-v5-spsc","workers":4,"sequenceNumber":245,"symbol":"SOLUSDT","exchangeEventTimeMillis":1784429273275,"localReceivedEpochMillis":1784429273266,"topSpreadTicks":1,"bid5Volume":122310,"ask5Volume":236823,"bid10Volume":450965,"ask10Volume":1022441,"rawPayload":"{\"stream\":\"solusdt@depth@100ms\",\"data\":{\"e\":\"depthUpdate\",\"E\":1784429273275,\"s\":\"SOLUSDT\",\"U\":1609569726,\"u\":1609569727,\"b\":[[\"76.23000000\",\"21.18200000\"],[\"76.22000000\",\"33.38000000\"]],\"a\":[]}}"}
{"mode":"v9-depth-v5-spsc","workers":4,"sequenceNumber":246,"symbol":"BTCUSDT","exchangeEventTimeMillis":1784429273475,"localReceivedEpochMillis":1784429273467,"topSpreadTicks":422,"bid5Volume":131,"ask5Volume":128,"bid10Volume":285,"ask10Volume":590,"rawPayload":"{\"stream\":\"btcusdt@depth@100ms\",\"data\":{\"e\":\"depthUpdate\",\"E\":1784429273475,\"s\":\"BTCUSDT\",\"U\":3244435288,\"u\":3244435288,\"b\":[],\"a\":[[\"64914.49000000\",\"0.00000000\"]]}}"}
{"mode":"v9-depth-v5-spsc","workers":4,"sequenceNumber":247,"symbol":"BTCUSDT","exchangeEventTimeMillis":1784429273575,"localReceivedEpochMillis":1784429273568,"topSpreadTicks":422,"bid5Volume":131,"ask5Volume":128,"bid10Volume":285,"ask10Volume":590,"rawPayload":"{\"stream\":\"btcusdt@depth@100ms\",\"data\":{\"e\":\"depthUpdate\",\"E\":1784429273575,\"s\":\"BTCUSDT\",\"U\":3244435289,\"u\":3244435291,\"b\":[],\"a\":[[\"64838.04000000\",\"0.00161000\"],[\"64838.70000000\",\"0.00000000\"],[\"64914.49000000\",\"0.00011000\"]]}}"}
{"mode":"v9-depth-v5-spsc","workers":4,"sequenceNumber":248,"symbol":"ETHUSDT","exchangeEventTimeMillis":1784429273575,"localReceivedEpochMillis":1784429273568,"topSpreadTicks":4,"bid5Volume":5452,"ask5Volume":5200,"bid10Volume":40199,"ask10Volume":17058,"rawPayload":"{\"stream\":\"ethusdt@depth@100ms\",\"data\":{\"e\":\"depthUpdate\",\"E\":1784429273575,\"s\":\"ETHUSDT\",\"U\":2806164352,\"u\":2806164353,\"b\":[[\"1871.56000000\",\"0.00000000\"]],\"a\":[[\"1872.12000000\",\"0.00000000\"]]}}"}
{"mode":"v9-depth-v5-spsc","workers":4,"sequenceNumber":249,"symbol":"ETHUSDT","exchangeEventTimeMillis":1784429273875,"localReceivedEpochMillis":1784429273866,"topSpreadTicks":4,"bid5Volume":5452,"ask5Volume":5200,"bid10Volume":10804,"ask10Volume":17058,"rawPayload":"{\"stream\":\"ethusdt@depth@100ms\",\"data\":{\"e\":\"depthUpdate\",\"E\":1784429273875,\"s\":\"ETHUSDT\",\"U\":2806164354,\"u\":2806164357,\"b\":[[\"1871.45000000\",\"1.63970000\"],[\"1871.28000000\",\"1.09310000\"],[\"1870.57000000\",\"0.00000000\"],[\"1870.10000000\",\"0.00000000\"]],\"a\":[]}}"}
{"mode":"v9-depth-v5-spsc","workers":4,"sequenceNumber":250,"symbol":"ETHUSDT","exchangeEventTimeMillis":1784429273975,"localReceivedEpochMillis":1784429273966,"topSpreadTicks":4,"bid5Volume":5452,"ask5Volume":3618,"bid10Volume":10804,"ask10Volume":15476,"rawPayload":"{\"stream\":\"ethusdt@depth@100ms\",\"data\":{\"e\":\"depthUpdate\",\"E\":1784429273975,\"s\":\"ETHUSDT\",\"U\":2806164358,\"u\":2806164358,\"b\":[],\"a\":[[\"1872.45000000\",\"0.05720000\"]]}}"}
{"mode":"v9-depth-v5-spsc","workers":4,"sequenceNumber":251,"symbol":"XRPUSDT","exchangeEventTimeMillis":1784429273975,"localReceivedEpochMillis":1784429273966,"topSpreadTicks":0,"bid5Volume":9994000,"ask5Volume":2777000,"bid10Volume":20175800,"ask10Volume":3974900,"rawPayload":"{\"stream\":\"xrpusdt@depth@100ms\",\"data\":{\"e\":\"depthUpdate\",\"E\":1784429273975,\"s\":\"XRPUSDT\",\"U\":752699377,\"u\":752699377,\"b\":[],\"a\":[[\"1.09680000\",\"2461.70000000\"]]}}"}
{"mode":"v9-depth-v5-spsc","workers":4,"sequenceNumber":252,"symbol":"BTCUSDT","exchangeEventTimeMillis":1784429274075,"localReceivedEpochMillis":1784429274066,"topSpreadTicks":422,"bid5Volume":133,"ask5Volume":128,"bid10Volume":287,"ask10Volume":590,"rawPayload":"{\"stream\":\"btcusdt@depth@100ms\",\"data\":{\"e\":\"depthUpdate\",\"E\":1784429274075,\"s\":\"BTCUSDT\",\"U\":3244435292,\"u\":3244435295,\"b\":[[\"64819.97000000\",\"0.02774000\"],[\"64817.53000000\",\"0.00000000\"]],\"a\":[[\"64902.70000000\",\"0.01425000\"],[\"81072.08000000\",\"0.00060000\"]]}}"}
{"mode":"v9-depth-v5-spsc","workers":4,"sequenceNumber":253,"symbol":"ETHUSDT","exchangeEventTimeMillis":1784429274075,"localReceivedEpochMillis":1784429274067,"topSpreadTicks":5,"bid5Volume":4182,"ask5Volume":3561,"bid10Volume":10002,"ask10Volume":14814,"rawPayload":"{\"stream\":\"ethusdt@depth@100ms\",\"data\":{\"e\":\"depthUpdate\",\"E\":1784429274075,\"s\":\"ETHUSDT\",\"U\":2806164359,\"u\":2806164369,\"b\":[[\"1871.83000000\",\"0.00000000\"],[\"1871.82000000\",\"1.11640000\"],[\"1871.74000000\",\"0.00000000\"],[\"1871.65000000\",\"0.75000000\"],[\"1871.61000000\",\"0.02940000\"]],\"a\":[[\"1872.16000000\",\"0.02980000\"],[\"1872.31000000\",\"0.00000000\"],[\"1872.39000000\",\"1.09230000\"],[\"1872.40000000\",\"0.00000000\"]]}}"}
{"mode":"v9-depth-v5-spsc","workers":4,"sequenceNumber":254,"symbol":"SOLUSDT","exchangeEventTimeMillis":1784429274175,"localReceivedEpochMillis":1784429274166,"topSpreadTicks":1,"bid5Volume":122310,"ask5Volume":156303,"bid10Volume":450965,"ask10Volume":477509,"rawPayload":"{\"stream\":\"solusdt@depth@100ms\",\"data\":{\"e\":\"depthUpdate\",\"E\":1784429274175,\"s\":\"SOLUSDT\",\"U\":1609569728,\"u\":1609569734,\"b\":[],\"a\":[[\"76.26000000\",\"54.58900000\"],[\"76.27000000\",\"21.38200000\"],[\"76.28000000\",\"7.41800000\"],[\"76.30000000\",\"64.31000000\"],[\"76.31000000\",\"30.19500000\"],[\"76.32000000\",\"30.19500000\"]]}}"}
{"mode":"v9-depth-v5-spsc","workers":4,"sequenceNumber":255,"symbol":"ETHUSDT","exchangeEventTimeMillis":1784429274175,"localReceivedEpochMillis":1784429274167,"topSpreadTicks":5,"bid5Volume":4182,"ask5Volume":3561,"bid10Volume":10002,"ask10Volume":15419,"rawPayload":"{\"stream\":\"ethusdt@depth@100ms\",\"data\":{\"e\":\"depthUpdate\",\"E\":1784429274175,\"s\":\"ETHUSDT\",\"U\":2806164370,\"u\":2806164370,\"b\":[],\"a\":[[\"1872.45000000\",\"0.00000000\"]]}}"}
{"mode":"v9-depth-v5-spsc","workers":4,"sequenceNumber":256,"symbol":"BTCUSDT","exchangeEventTimeMillis":1784429274175,"localReceivedEpochMillis":1784429274167,"topSpreadTicks":422,"bid5Volume":133,"ask5Volume":128,"bid10Volume":287,"ask10Volume":590,"rawPayload":"{\"stream\":\"btcusdt@depth@100ms\",\"data\":{\"e\":\"depthUpdate\",\"E\":1784429274175,\"s\":\"BTCUSDT\",\"U\":3244435296,\"u\":3244435297,\"b\":[[\"64819.97000000\",\"0.00000000\"],[\"64818.21000000\",\"0.02786000\"]],\"a\":[]}}"}
{"mode":"v9-depth-v5-spsc","workers":4,"sequenceNumber":257,"symbol":"ETHUSDT","exchangeEventTimeMillis":1784429274275,"localReceivedEpochMillis":1784429274266,"topSpreadTicks":5,"bid5Volume":4182,"ask5Volume":3561,"bid10Volume":10002,"ask10Volume":14812,"rawPayload":"{\"stream\":\"ethusdt@depth@100ms\",\"data\":{\"e\":\"depthUpdate\",\"E\":1784429274275,\"s\":\"ETHUSDT\",\"U\":2806164371,\"u\":2806164371,\"b\":[],\"a\":[[\"1872.54000000\",\"0.05510000\"]]}}"}
{"mode":"v9-depth-v5-spsc","workers":4,"sequenceNumber":258,"symbol":"SOLUSDT","exchangeEventTimeMillis":1784429274475,"localReceivedEpochMillis":1784429274467,"topSpreadTicks":1,"bid5Volume":122310,"ask5Volume":156303,"bid10Volume":450965,"ask10Volume":478043,"rawPayload":"{\"stream\":\"solusdt@depth@100ms\",\"data\":{\"e\":\"depthUpdate\",\"E\":1784429274475,\"s\":\"SOLUSDT\",\"U\":1609569735,\"u\":1609569738,\"b\":[],\"a\":[[\"76.29000000\",\"36.17900000\"],[\"76.30000000\",\"50.32500000\"],[\"76.31000000\",\"44.71400000\"]]}}"}
{"mode":"v9-depth-v5-spsc","workers":4,"sequenceNumber":259,"symbol":"SOLUSDT","exchangeEventTimeMillis":1784429274576,"localReceivedEpochMillis":1784429274567,"topSpreadTicks":1,"bid5Volume":122309,"ask5Volume":206625,"bid10Volume":450964,"ask10Volume":478033,"rawPayload":"{\"stream\":\"solusdt@depth@100ms\",\"data\":{\"e\":\"depthUpdate\",\"E\":1784429274576,\"s\":\"SOLUSDT\",\"U\":1609569739,\"u\":1609569741,\"b\":[[\"76.22000000\",\"36.79000000\"],[\"76.21000000\",\"30.29500000\"]],\"a\":[[\"76.29000000\",\"0.00000000\"],[\"76.30000000\",\"86.50100000\"],[\"76.34000000\",\"84.48100000\"],[\"76.35000000\",\"98.89700000\"]]}}"}
{"mode":"v9-depth-v5-spsc","workers":4,"sequenceNumber":260,"symbol":"SOLUSDT","exchangeEventTimeMillis":1784429274876,"localReceivedEpochMillis":1784429274867,"topSpreadTicks":1,"bid5Volume":122309,"ask5Volume":133831,"bid10Volume":450964,"ask10Volume":378324,"rawPayload":"{\"stream\":\"solusdt@depth@100ms\",\"data\":{\"e\":\"depthUpdate\",\"E\":1784429274876,\"s\":\"SOLUSDT\",\"U\":1609569742,\"u\":1609569743,\"b\":[],\"a\":[[\"76.29000000\",\"13.70700000\"],[\"76.31000000\",\"30.19500000\"]]}}"}
{"mode":"v9-depth-v5-spsc","workers":4,"sequenceNumber":261,"symbol":"ETHUSDT","exchangeEventTimeMillis":1784429274976,"localReceivedEpochMillis":1784429274966,"topSpreadTicks":5,"bid5Volume":4182,"ask5Volume":3561,"bid10Volume":8865,"ask10Volume":14812,"rawPayload":"{\"stream\":\"ethusdt@depth@100ms\",\"data\":{\"e\":\"depthUpdate\",\"E\":1784429274976,\"s\":\"ETHUSDT\",\"U\":2806164372,\"u\":2806164374,\"b\":[[\"1871.45000000\",\"0.00000000\"],[\"1871.28000000\",\"0.00000000\"],[\"1870.90000000\",\"1.09310000\"]],\"a\":[]}}"}
{"mode":"v9-depth-v5-spsc","workers":4,"sequenceNumber":262,"symbol":"SOLUSDT","exchangeEventTimeMillis":1784429275376,"localReceivedEpochMillis":1784429275367,"topSpreadTicks":1,"bid5Volume":122779,"ask5Volume":133831,"bid10Volume":451434,"ask10Volume":378324,"rawPayload":"{\"stream\":\"solusdt@depth@100ms\",\"data\":{\"e\":\"depthUpdate\",\"E\":1784429275376,\"s\":\"SOLUSDT\",\"U\":1609569744,\"u\":1609569745,\"b\":[[\"76.23000000\",\"18.01200000\"],[\"76.22000000\",\"40.43000000\"]],\"a\":[]}}"}
{"mode":"v9-depth-v5-spsc","workers":4,"sequenceNumber":263,"symbol":"ETHUSDT","exchangeEventTimeMillis":1784429275576,"localReceivedEpochMillis":1784429275567,"topSpreadTicks":5,"bid5Volume":4182,"ask5Volume":3561,"bid10Volume":8865,"ask10Volume":14812,"rawPayload":"{\"stream\":\"ethusdt@depth@100ms\",\"data\":{\"e\":\"depthUpdate\",\"E\":1784429275576,\"s\":\"ETHUSDT\",\"U\":2806164375,\"u\":2806164375,\"b\":[[\"1870.43000000\",\"1.63970000\"]],\"a\":[]}}"}
{"mode":"v9-depth-v5-spsc","workers":4,"sequenceNumber":264,"symbol":"SOLUSDT","exchangeEventTimeMillis":1784429275876,"localReceivedEpochMillis":1784429275869,"topSpreadTicks":1,"bid5Volume":122779,"ask5Volume":133831,"bid10Volume":451434,"ask10Volume":378324,"rawPayload":"{\"stream\":\"solusdt@depth@100ms\",\"data\":{\"e\":\"depthUpdate\",\"E\":1784429275876,\"s\":\"SOLUSDT\",\"U\":1609569746,\"u\":1609569746,\"b\":[[\"70.10000000\",\"0.16800000\"]],\"a\":[]}}"}
{"mode":"v9-depth-v5-spsc","workers":4,"sequenceNumber":265,"symbol":"ETHUSDT","exchangeEventTimeMillis":1784429276377,"localReceivedEpochMillis":1784429276368,"topSpreadTicks":5,"bid5Volume":4182,"ask5Volume":3561,"bid10Volume":10383,"ask10Volume":14812,"rawPayload":"{\"stream\":\"ethusdt@depth@100ms\",\"data\":{\"e\":\"depthUpdate\",\"E\":1784429276377,\"s\":\"ETHUSDT\",\"U\":2806164376,\"u\":2806164377,\"b\":[[\"1871.45000000\",\"1.63970000\"],[\"1870.43000000\",\"0.00000000\"]],\"a\":[]}}"}
{"mode":"v9-depth-v5-spsc","workers":4,"sequenceNumber":266,"symbol":"ETHUSDT","exchangeEventTimeMillis":1784429276977,"localReceivedEpochMillis":1784429276968,"topSpreadTicks":5,"bid5Volume":4182,"ask5Volume":3561,"bid10Volume":10383,"ask10Volume":14812,"rawPayload":"{\"stream\":\"ethusdt@depth@100ms\",\"data\":{\"e\":\"depthUpdate\",\"E\":1784429276977,\"s\":\"ETHUSDT\",\"U\":2806164378,\"u\":2806164378,\"b\":[[\"1871.39000000\",\"1.02590000\"],[\"1871.33000000\",\"0.00000000\"]],\"a\":[]}}"}
{"mode":"v9-depth-v5-spsc","workers":4,"sequenceNumber":267,"symbol":"BNBUSDT","exchangeEventTimeMillis":1784429277077,"localReceivedEpochMillis":1784429277068,"topSpreadTicks":10,"bid5Volume":4595,"ask5Volume":6663,"bid10Volume":25182,"ask10Volume":259327,"rawPayload":"{\"stream\":\"bnbusdt@depth@100ms\",\"data\":{\"e\":\"depthUpdate\",\"E\":1784429277077,\"s\":\"BNBUSDT\",\"U\":1236327961,\"u\":1236327962,\"b\":[],\"a\":[[\"571.01000000\",\"0.87600000\"],[\"571.03000000\",\"1.59500000\"]]}}"}
{"mode":"v9-depth-v5-spsc","workers":4,"sequenceNumber":268,"symbol":"ETHUSDT","exchangeEventTimeMillis":1784429277077,"localReceivedEpochMillis":1784429277069,"topSpreadTicks":5,"bid5Volume":4182,"ask5Volume":3561,"bid10Volume":10383,"ask10Volume":14815,"rawPayload":"{\"stream\":\"ethusdt@depth@100ms\",\"data\":{\"e\":\"depthUpdate\",\"E\":1784429277077,\"s\":\"ETHUSDT\",\"U\":2806164379,\"u\":2806164380,\"b\":[],\"a\":[[\"1872.43000000\",\"0.05840000\"],[\"1872.54000000\",\"0.00000000\"]]}}"}
{"mode":"v9-depth-v5-spsc","workers":4,"sequenceNumber":269,"symbol":"BTCUSDT","exchangeEventTimeMillis":1784429277377,"localReceivedEpochMillis":1784429277368,"topSpreadTicks":422,"bid5Volume":133,"ask5Volume":128,"bid10Volume":287,"ask10Volume":590,"rawPayload":"{\"stream\":\"btcusdt@depth@100ms\",\"data\":{\"e\":\"depthUpdate\",\"E\":1784429277377,\"s\":\"BTCUSDT\",\"U\":3244435298,\"u\":3244435300,\"b\":[],\"a\":[[\"64914.49000000\",\"0.00011000\"],[\"81072.08000000\",\"0.00060000\"]]}}"}
{"mode":"v9-depth-v5-spsc","workers":4,"sequenceNumber":270,"symbol":"SOLUSDT","exchangeEventTimeMillis":1784429277477,"localReceivedEpochMillis":1784429277469,"topSpreadTicks":1,"bid5Volume":122779,"ask5Volume":244546,"bid10Volume":451434,"ask10Volume":805201,"rawPayload":"{\"stream\":\"solusdt@depth@100ms\",\"data\":{\"e\":\"depthUpdate\",\"E\":1784429277477,\"s\":\"SOLUSDT\",\"U\":1609569747,\"u\":1609569756,\"b\":[],\"a\":[[\"76.26000000\",\"104.91400000\"],[\"76.27000000\",\"51.57700000\"],[\"76.28000000\",\"37.61300000\"],[\"76.30000000\",\"36.17600000\"],[\"76.31000000\",\"0.00000000\"],[\"76.32000000\",\"0.00000000\"],[\"76.33000000\",\"68.40400000\"],[\"76.62000000\",\"0.00000000\"]]}}"}
{"mode":"v9-depth-v5-spsc","workers":4,"sequenceNumber":271,"symbol":"XRPUSDT","exchangeEventTimeMillis":1784429277578,"localReceivedEpochMillis":1784429277569,"topSpreadTicks":0,"bid5Volume":6214300,"ask5Volume":2777000,"bid10Volume":16396100,"ask10Volume":3974900,"rawPayload":"{\"stream\":\"xrpusdt@depth@100ms\",\"data\":{\"e\":\"depthUpdate\",\"E\":1784429277578,\"s\":\"XRPUSDT\",\"U\":752699378,\"u\":752699379,\"b\":[[\"1.09640000\",\"3576.80000000\"],[\"1.09630000\",\"1064.30000000\"]],\"a\":[]}}"}
{"mode":"v9-depth-v5-spsc","workers":4,"sequenceNumber":272,"symbol":"SOLUSDT","exchangeEventTimeMillis":1784429277778,"localReceivedEpochMillis":1784429277770,"topSpreadTicks":1,"bid5Volume":122779,"ask5Volume":244546,"bid10Volume":451434,"ask10Volume":805201,"rawPayload":"{\"stream\":\"solusdt@depth@100ms\",\"data\":{\"e\":\"depthUpdate\",\"E\":1784429277778,\"s\":\"SOLUSDT\",\"U\":1609569757,\"u\":1609569757,\"b\":[],\"a\":[[\"76.26000000\",\"122.88900000\"],[\"76.27000000\",\"33.60200000\"]]}}"}
{"mode":"v9-depth-v5-spsc","workers":4,"sequenceNumber":273,"symbol":"BNBUSDT","exchangeEventTimeMillis":1784429277878,"localReceivedEpochMillis":1784429277868,"topSpreadTicks":10,"bid5Volume":4595,"ask5Volume":6663,"bid10Volume":25182,"ask10Volume":259327,"rawPayload":"{\"stream\":\"bnbusdt@depth@100ms\",\"data\":{\"e\":\"depthUpdate\",\"E\":1784429277878,\"s\":\"BNBUSDT\",\"U\":1236327963,\"u\":1236327970,\"b\":[[\"570.20000000\",\"0.00000000\"],[\"570.17000000\",\"3.39500000\"],[\"569.86000000\",\"0.00000000\"],[\"569.82000000\",\"5.04900000\"],[\"569.52000000\",\"0.00000000\"],[\"569.48000000\",\"8.67400000\"],[\"569.17000000\",\"0.00000000\"],[\"569.14000000\",\"19.72800000\"]],\"a\":[[\"571.55000000\",\"3.30600000\"],[\"571.58000000\",\"0.00000000\"],[\"571.89000000\",\"5.04600000\"],[\"571.92000000\",\"0.00000000\"],[\"572.23000000\",\"8.42800000\"],[\"572.27000000\",\"0.00000000\"],[\"572.57000000\",\"20.45700000\"],[\"572.61000000\",\"0.00000000\"]]}}"}
{"mode":"v9-depth-v5-spsc","workers":4,"sequenceNumber":274,"symbol":"BTCUSDT","exchangeEventTimeMillis":1784429278078,"localReceivedEpochMillis":1784429278070,"topSpreadTicks":422,"bid5Volume":133,"ask5Volume":128,"bid10Volume":287,"ask10Volume":590,"rawPayload":"{\"stream\":\"btcusdt@depth@100ms\",\"data\":{\"e\":\"depthUpdate\",\"E\":1784429278078,\"s\":\"BTCUSDT\",\"U\":3244435301,\"u\":3244435301,\"b\":[],\"a\":[[\"81072.08000000\",\"0.00045000\"]]}}"}
{"mode":"v9-depth-v5-spsc","workers":4,"sequenceNumber":275,"symbol":"XRPUSDT","exchangeEventTimeMillis":1784429278078,"localReceivedEpochMillis":1784429278070,"topSpreadTicks":0,"bid5Volume":6214300,"ask5Volume":4074500,"bid10Volume":16396100,"ask10Volume":5272400,"rawPayload":"{\"stream\":\"xrpusdt@depth@100ms\",\"data\":{\"e\":\"depthUpdate\",\"E\":1784429278078,\"s\":\"XRPUSDT\",\"U\":752699380,\"u\":752699380,\"b\":[],\"a\":[[\"1.09670000\",\"3759.20000000\"]]}}"}
{"mode":"v9-depth-v5-spsc","workers":4,"sequenceNumber":276,"symbol":"SOLUSDT","exchangeEventTimeMillis":1784429278778,"localReceivedEpochMillis":1784429278769,"topSpreadTicks":1,"bid5Volume":122779,"ask5Volume":133831,"bid10Volume":451434,"ask10Volume":639203,"rawPayload":"{\"stream\":\"solusdt@depth@100ms\",\"data\":{\"e\":\"depthUpdate\",\"E\":1784429278778,\"s\":\"SOLUSDT\",\"U\":1609569758,\"u\":1609569762,\"b\":[],\"a\":[[\"76.26000000\",\"72.56400000\"],[\"76.27000000\",\"3.40700000\"],[\"76.28000000\",\"7.41800000\"],[\"76.33000000\",\"13.12100000\"]]}}"}
{"mode":"v9-depth-v5-spsc","workers":4,"sequenceNumber":277,"symbol":"BTCUSDT","exchangeEventTimeMillis":1784429279079,"localReceivedEpochMillis":1784429279069,"topSpreadTicks":422,"bid5Volume":133,"ask5Volume":128,"bid10Volume":287,"ask10Volume":590,"rawPayload":"{\"stream\":\"btcusdt@depth@100ms\",\"data\":{\"e\":\"depthUpdate\",\"E\":1784429279079,\"s\":\"BTCUSDT\",\"U\":3244435302,\"u\":3244435309,\"b\":[[\"64753.61000000\",\"0.00000000\"],[\"64750.10000000\",\"0.05832000\"],[\"64714.72000000\",\"0.00000000\"],[\"64711.21000000\",\"0.08812000\"],[\"64675.82000000\",\"0.00000000\"],[\"64672.31000000\",\"0.17331000\"],[\"64598.02000000\",\"0.00000000\"],[\"64594.52000000\",\"0.40717000\"]],\"a\":[[\"64905.64000000\",\"0.06043000\"],[\"64909.15000000\",\"0.00000000\"],[\"64944.53000000\",\"0.09239000\"],[\"64948.05000000\",\"0.00000000\"],[\"64983.43000000\",\"0.17644000\"],[\"64986.95000000\",\"0.00000000\"],[\"65061.22000000\",\"0.42827000\"],[\"65064.75000000\",\"0.00000000\"]]}}"}
{"mode":"v9-depth-v5-spsc","workers":4,"sequenceNumber":278,"symbol":"SOLUSDT","exchangeEventTimeMillis":1784429279179,"localReceivedEpochMillis":1784429279170,"topSpreadTicks":1,"bid5Volume":122779,"ask5Volume":184156,"bid10Volume":451434,"ask10Volume":477221,"rawPayload":"{\"stream\":\"solusdt@depth@100ms\",\"data\":{\"e\":\"depthUpdate\",\"E\":1784429279179,\"s\":\"SOLUSDT\",\"U\":1609569763,\"u\":1609569767,\"b\":[],\"a\":[[\"76.28000000\",\"57.74300000\"],[\"76.30000000\",\"66.37100000\"],[\"76.31000000\",\"30.19500000\"],[\"76.48000000\",\"326.23600000\"]]}}"}
{"mode":"v9-depth-v5-spsc","workers":4,"sequenceNumber":279,"symbol":"BNBUSDT","exchangeEventTimeMillis":1784429279279,"localReceivedEpochMillis":1784429279269,"topSpreadTicks":10,"bid5Volume":4595,"ask5Volume":6663,"bid10Volume":25182,"ask10Volume":259327,"rawPayload":"{\"stream\":\"bnbusdt@depth@100ms\",\"data\":{\"e\":\"depthUpdate\",\"E\":1784429279279,\"s\":\"BNBUSDT\",\"U\":1236327971,\"u\":1236327971,\"b\":[],\"a\":[[\"570.99000000\",\"1.61500000\"],[\"571.00000000\",\"0.00000000\"]]}}"}
{"mode":"v9-depth-v5-spsc","workers":4,"sequenceNumber":280,"symbol":"ETHUSDT","exchangeEventTimeMillis":1784429279379,"localReceivedEpochMillis":1784429279370,"topSpreadTicks":5,"bid5Volume":4182,"ask5Volume":3561,"bid10Volume":8865,"ask10Volume":14815,"rawPayload":"{\"stream\":\"ethusdt@depth@100ms\",\"data\":{\"e\":\"depthUpdate\",\"E\":1784429279379,\"s\":\"ETHUSDT\",\"U\":2806164381,\"u\":2806164382,\"b\":[[\"1871.45000000\",\"0.00000000\"],[\"1870.43000000\",\"1.63970000\"]],\"a\":[]}}"}
{"mode":"v9-depth-v5-spsc","workers":4,"sequenceNumber":281,"symbol":"BTCUSDT","exchangeEventTimeMillis":1784429279579,"localReceivedEpochMillis":1784429279570,"topSpreadTicks":422,"bid5Volume":133,"ask5Volume":128,"bid10Volume":287,"ask10Volume":590,"rawPayload":"{\"stream\":\"btcusdt@depth@100ms\",\"data\":{\"e\":\"depthUpdate\",\"E\":1784429279579,\"s\":\"BTCUSDT\",\"U\":3244435310,\"u\":3244435310,\"b\":[],\"a\":[[\"81072.08000000\",\"0.00045000\"]]}}"}
{"mode":"v9-depth-v5-spsc","workers":4,"sequenceNumber":282,"symbol":"SOLUSDT","exchangeEventTimeMillis":1784429279679,"localReceivedEpochMillis":1784429279716,"topSpreadTicks":1,"bid5Volume":122779,"ask5Volume":244546,"bid10Volume":451434,"ask10Volume":749918,"rawPayload":"{\"stream\":\"solusdt@depth@100ms\",\"data\":{\"e\":\"depthUpdate\",\"E\":1784429279679,\"s\":\"SOLUSDT\",\"U\":1609569768,\"u\":1609569771,\"b\":[],\"a\":[[\"76.26000000\",\"102.75900000\"],[\"76.27000000\",\"33.60200000\"],[\"76.30000000\",\"36.17600000\"],[\"76.31000000\",\"0.00000000\"]]}}"}
{"mode":"v9-depth-v5-spsc","workers":4,"sequenceNumber":283,"symbol":"XRPUSDT","exchangeEventTimeMillis":1784429279679,"localReceivedEpochMillis":1784429279716,"topSpreadTicks":0,"bid5Volume":6214300,"ask5Volume":2390000,"bid10Volume":16396100,"ask10Volume":3587900,"rawPayload":"{\"stream\":\"xrpusdt@depth@100ms\",\"data\":{\"e\":\"depthUpdate\",\"E\":1784429279679,\"s\":\"XRPUSDT\",\"U\":752699381,\"u\":752699382,\"b\":[],\"a\":[[\"1.09680000\",\"2600.00000000\"],[\"1.09710000\",\"2074.70000000\"]]}}"}
{"mode":"v9-depth-v5-spsc","workers":4,"sequenceNumber":284,"symbol":"SOLUSDT","exchangeEventTimeMillis":1784429279779,"localReceivedEpochMillis":1784429279770,"topSpreadTicks":1,"bid5Volume":122779,"ask5Volume":250069,"bid10Volume":451434,"ask10Volume":755441,"rawPayload":"{\"stream\":\"solusdt@depth@100ms\",\"data\":{\"e\":\"depthUpdate\",\"E\":1784429279779,\"s\":\"SOLUSDT\",\"U\":1609569772,\"u\":1609569773,\"b\":[],\"a\":[[\"76.27000000\",\"43.26000000\"],[\"76.28000000\",\"53.60800000\"]]}}"}
{"mode":"v9-depth-v5-spsc","workers":4,"sequenceNumber":285,"symbol":"SOLUSDT","exchangeEventTimeMillis":1784429279979,"localReceivedEpochMillis":1784429279971,"topSpreadTicks":1,"bid5Volume":122779,"ask5Volume":139354,"bid10Volume":451434,"ask10Volume":333522,"rawPayload":"{\"stream\":\"solusdt@depth@100ms\",\"data\":{\"e\":\"depthUpdate\",\"E\":1784429279979,\"s\":\"SOLUSDT\",\"U\":1609569774,\"u\":1609569779,\"b\":[],\"a\":[[\"76.26000000\",\"72.56400000\"],[\"76.27000000\",\"13.06500000\"],[\"76.28000000\",\"3.28300000\"],[\"76.31000000\",\"30.19500000\"],[\"76.32000000\",\"30.19500000\"]]}}"}
{"mode":"v9-depth-v5-spsc","workers":4,"sequenceNumber":286,"symbol":"BTCUSDT","exchangeEventTimeMillis":1784429279979,"localReceivedEpochMillis":1784429279972,"topSpreadTicks":422,"bid5Volume":133,"ask5Volume":128,"bid10Volume":287,"ask10Volume":590,"rawPayload":"{\"stream\":\"btcusdt@depth@100ms\",\"data\":{\"e\":\"depthUpdate\",\"E\":1784429279979,\"s\":\"BTCUSDT\",\"U\":3244435311,\"u\":3244435312,\"b\":[[\"64818.21000000\",\"0.00000000\"],[\"64816.44000000\",\"0.02720000\"]],\"a\":[]}}"}
{"mode":"v9-depth-v5-spsc","workers":4,"sequenceNumber":287,"symbol":"ETHUSDT","exchangeEventTimeMillis":1784429279979,"localReceivedEpochMillis":1784429279972,"topSpreadTicks":5,"bid5Volume":3369,"ask5Volume":3561,"bid10Volume":8865,"ask10Volume":14815,"rawPayload":"{\"stream\":\"ethusdt@depth@100ms\",\"data\":{\"e\":\"depthUpdate\",\"E\":1784429279979,\"s\":\"ETHUSDT\",\"U\":2806164383,\"u\":2806164384,\"b\":[[\"1871.60000000\",\"0.13870000\"],[\"1871.54000000\",\"0.00000000\"]],\"a\":[[\"1872.20000000\",\"0.00000000\"],[\"1872.26000000\",\"0.13840000\"]]}}"}
{"mode":"v9-depth-v5-spsc","workers":4,"sequenceNumber":288,"symbol":"ETHUSDT","exchangeEventTimeMillis":1784429280179,"localReceivedEpochMillis":1784429280170,"topSpreadTicks":5,"bid5Volume":3369,"ask5Volume":3561,"bid10Volume":8865,"ask10Volume":14815,"rawPayload":"{\"stream\":\"ethusdt@depth@100ms\",\"data\":{\"e\":\"depthUpdate\",\"E\":1784429280179,\"s\":\"ETHUSDT\",\"U\":2806164385,\"u\":2806164391,\"b\":[[\"1869.61000000\",\"2.05300000\"],[\"1869.56000000\",\"0.00000000\"],[\"1868.49000000\",\"2.95960000\"],[\"1868.43000000\",\"0.00000000\"],[\"1867.36000000\",\"5.99790000\"],[\"1867.31000000\",\"0.00000000\"],[\"1865.12000000\",\"13.72160000\"],[\"1865.06000000\",\"0.00000000\"]],\"a\":[[\"1874.06000000\",\"0.00000000\"],[\"1874.11000000\",\"2.04860000\"],[\"1875.18000000\",\"0.00000000\"],[\"1875.23000000\",\"3.02900000\"],[\"1876.30000000\",\"0.00000000\"],[\"1876.36000000\",\"6.30890000\"]]}}"}
{"mode":"v9-depth-v5-spsc","workers":4,"sequenceNumber":289,"symbol":"XRPUSDT","exchangeEventTimeMillis":1784429280279,"localReceivedEpochMillis":1784429280270,"topSpreadTicks":0,"bid5Volume":6214300,"ask5Volume":2390000,"bid10Volume":22122100,"ask10Volume":3587900,"rawPayload":"{\"stream\":\"xrpusdt@depth@100ms\",\"data\":{\"e\":\"depthUpdate\",\"E\":1784429280279,\"s\":\"XRPUSDT\",\"U\":752699383,\"u\":752699383,\"b\":[[\"0.60000000\",\"5726.00000000\"]],\"a\":[]}}"}
{"mode":"v9-depth-v5-spsc","workers":4,"sequenceNumber":290,"symbol":"XRPUSDT","exchangeEventTimeMillis":1784429280480,"localReceivedEpochMillis":1784429280471,"topSpreadTicks":0,"bid5Volume":6214300,"ask5Volume":2390000,"bid10Volume":22102100,"ask10Volume":3587900,"rawPayload":"{\"stream\":\"xrpusdt@depth@100ms\",\"data\":{\"e\":\"depthUpdate\",\"E\":1784429280480,\"s\":\"XRPUSDT\",\"U\":752699384,\"u\":752699384,\"b\":[[\"0.60000000\",\"5706.00000000\"]],\"a\":[]}}"}
{"mode":"v9-depth-v5-spsc","workers":4,"sequenceNumber":291,"symbol":"SOLUSDT","exchangeEventTimeMillis":1784429280580,"localReceivedEpochMillis":1784429280570,"topSpreadTicks":1,"bid5Volume":122779,"ask5Volume":139354,"bid10Volume":451434,"ask10Volume":383847,"rawPayload":"{\"stream\":\"solusdt@depth@100ms\",\"data\":{\"e\":\"depthUpdate\",\"E\":1784429280580,\"s\":\"SOLUSDT\",\"U\":1609569780,\"u\":1609569781,\"b\":[],\"a\":[[\"76.30000000\",\"86.50100000\"]]}}"}
{"mode":"v9-depth-v5-spsc","workers":4,"sequenceNumber":292,"symbol":"BTCUSDT","exchangeEventTimeMillis":1784429280680,"localReceivedEpochMillis":1784429280671,"topSpreadTicks":268,"bid5Volume":133,"ask5Volume":128,"bid10Volume":287,"ask10Volume":590,"rawPayload":"{\"stream\":\"btcusdt@depth@100ms\",\"data\":{\"e\":\"depthUpdate\",\"E\":1784429280680,\"s\":\"BTCUSDT\",\"U\":3244435313,\"u\":3244435314,\"b\":[[\"64808.78000000\",\"0.02826000\"],[\"64808.11000000\",\"0.00000000\"]],\"a\":[[\"64824.30000000\",\"0.02820000\"],[\"64827.72000000\",\"0.00000000\"]]}}"}
{"mode":"v9-depth-v5-spsc","workers":4,"sequenceNumber":293,"symbol":"ETHUSDT","exchangeEventTimeMillis":1784429280880,"localReceivedEpochMillis":1784429280870,"topSpreadTicks":5,"bid5Volume":3369,"ask5Volume":3561,"bid10Volume":8865,"ask10Volume":15419,"rawPayload":"{\"stream\":\"ethusdt@depth@100ms\",\"data\":{\"e\":\"depthUpdate\",\"E\":1784429280880,\"s\":\"ETHUSDT\",\"U\":2806164392,\"u\":2806164392,\"b\":[],\"a\":[[\"1872.43000000\",\"0.00000000\"]]}}"}
{"mode":"v9-depth-v5-spsc","workers":4,"sequenceNumber":294,"symbol":"BTCUSDT","exchangeEventTimeMillis":1784429281180,"localReceivedEpochMillis":1784429281171,"topSpreadTicks":268,"bid5Volume":133,"ask5Volume":128,"bid10Volume":287,"ask10Volume":590,"rawPayload":"{\"stream\":\"btcusdt@depth@100ms\",\"data\":{\"e\":\"depthUpdate\",\"E\":1784429281180,\"s\":\"BTCUSDT\",\"U\":3244435315,\"u\":3244435315,\"b\":[],\"a\":[[\"64914.49000000\",\"0.00000000\"]]}}"}
{"mode":"v9-depth-v5-spsc","workers":4,"sequenceNumber":295,"symbol":"SOLUSDT","exchangeEventTimeMillis":1784429281280,"localReceivedEpochMillis":1784429281272,"topSpreadTicks":1,"bid5Volume":122780,"ask5Volume":175532,"bid10Volume":451435,"ask10Volume":383849,"rawPayload":"{\"stream\":\"solusdt@depth@100ms\",\"data\":{\"e\":\"depthUpdate\",\"E\":1784429281280,\"s\":\"SOLUSDT\",\"U\":1609569782,\"u\":1609569784,\"b\":[[\"76.22000000\",\"37.02000000\"],[\"76.21000000\",\"33.70600000\"]],\"a\":[[\"76.26000000\",\"54.58900000\"],[\"76.27000000\",\"31.04000000\"],[\"76.29000000\",\"49.88500000\"],[\"76.30000000\",\"50.32500000\"]]}}"}
{"mode":"v9-depth-v5-spsc","workers":4,"sequenceNumber":296,"symbol":"BTCUSDT","exchangeEventTimeMillis":1784429281280,"localReceivedEpochMillis":1784429281273,"topSpreadTicks":268,"bid5Volume":133,"ask5Volume":128,"bid10Volume":287,"ask10Volume":590,"rawPayload":"{\"stream\":\"btcusdt@depth@100ms\",\"data\":{\"e\":\"depthUpdate\",\"E\":1784429281280,\"s\":\"BTCUSDT\",\"U\":3244435316,\"u\":3244435316,\"b\":[],\"a\":[[\"64914.49000000\",\"0.00011000\"]]}}"}
{"mode":"v9-depth-v5-spsc","workers":4,"sequenceNumber":297,"symbol":"BTCUSDT","exchangeEventTimeMillis":1784429281580,"localReceivedEpochMillis":1784429281571,"topSpreadTicks":268,"bid5Volume":133,"ask5Volume":128,"bid10Volume":287,"ask10Volume":590,"rawPayload":"{\"stream\":\"btcusdt@depth@100ms\",\"data\":{\"e\":\"depthUpdate\",\"E\":1784429281580,\"s\":\"BTCUSDT\",\"U\":3244435317,\"u\":3244435317,\"b\":[],\"a\":[[\"81072.08000000\",\"0.00030000\"]]}}"}
{"mode":"v9-depth-v5-spsc","workers":4,"sequenceNumber":298,"symbol":"SOLUSDT","exchangeEventTimeMillis":1784429281880,"localReceivedEpochMillis":1784429281872,"topSpreadTicks":1,"bid5Volume":122780,"ask5Volume":175532,"bid10Volume":451435,"ask10Volume":383849,"rawPayload":"{\"stream\":\"solusdt@depth@100ms\",\"data\":{\"e\":\"depthUpdate\",\"E\":1784429281880,\"s\":\"SOLUSDT\",\"U\":1609569785,\"u\":1609569785,\"b\":[[\"76.22000000\",\"40.43100000\"],[\"76.21000000\",\"30.29500000\"]],\"a\":[]}}"}
{"mode":"v9-depth-v5-spsc","workers":4,"sequenceNumber":299,"symbol":"ETHUSDT","exchangeEventTimeMillis":1784429281880,"localReceivedEpochMillis":1784429281872,"topSpreadTicks":5,"bid5Volume":4182,"ask5Volume":3561,"bid10Volume":8865,"ask10Volume":15419,"rawPayload":"{\"stream\":\"ethusdt@depth@100ms\",\"data\":{\"e\":\"depthUpdate\",\"E\":1784429281880,\"s\":\"ETHUSDT\",\"U\":2806164393,\"u\":2806164393,\"b\":[[\"1871.60000000\",\"0.00000000\"],[\"1871.57000000\",\"0.13880000\"]],\"a\":[]}}"}
{"mode":"v9-depth-v5-spsc","workers":4,"sequenceNumber":300,"symbol":"BNBUSDT","exchangeEventTimeMillis":1784429281981,"localReceivedEpochMillis":1784429281971,"topSpreadTicks":10,"bid5Volume":6011,"ask5Volume":9134,"bid10Volume":33767,"ask10Volume":268467,"rawPayload":"{\"stream\":\"bnbusdt@depth@100ms\",\"data\":{\"e\":\"depthUpdate\",\"E\":1784429281981,\"s\":\"BNBUSDT\",\"U\":1236327972,\"u\":1236327989,\"b\":[[\"570.84000000\",\"0.00000000\"],[\"570.76000000\",\"0.00000000\"],[\"570.70000000\",\"1.75200000\"],[\"569.22000000\",\"0.00000000\"],[\"568.71000000\",\"0.00000000\"],[\"568.70000000\",\"0.00000000\"],[\"568.68000000\",\"0.00000000\"],[\"568.67000000\",\"0.00000000\"],[\"568.25000000\",\"2.22300000\"]],\"a\":[[\"570.99000000\",\"1.61500000\"],[\"571.01000000\",\"0.00000000\"],[\"571.13000000\",\"3.34700000\"],[\"571.19000000\",\"0.00000000\"],[\"571.20000000\",\"0.00000000\"],[\"571.74000000\",\"0.00000000\"],[\"573.28000000\",\"1.73000000\"],[\"573.80000000\",\"0.00000000\"]]}}"}
{"mode":"v9-depth-v5-spsc","workers":4,"sequenceNumber":301,"symbol":"BNBUSDT","exchangeEventTimeMillis":1784429282081,"localReceivedEpochMillis":1784429282072,"topSpreadTicks":9,"bid5Volume":6039,"ask5Volume":6663,"bid10Volume":33795,"ask10Volume":264297,"rawPayload":"{\"stream\":\"bnbusdt@depth@100ms\",\"data\":{\"e\":\"depthUpdate\",\"E\":1784429282081,\"s\":\"BNBUSDT\",\"U\":1236327990,\"u\":1236327994,\"b\":[[\"570.88000000\",\"0.00000000\"],[\"570.86000000\",\"0.87600000\"]],\"a\":[[\"570.95000000\",\"1.59500000\"],[\"570.97000000\",\"0.87600000\"],[\"570.98000000\",\"0.00000000\"]]}}"}
{"mode":"v9-depth-v5-spsc","workers":4,"sequenceNumber":302,"symbol":"SOLUSDT","exchangeEventTimeMillis":1784429282081,"localReceivedEpochMillis":1784429282072,"topSpreadTicks":1,"bid5Volume":122780,"ask5Volume":225857,"bid10Volume":451435,"ask10Volume":482746,"rawPayload":"{\"stream\":\"solusdt@depth@100ms\",\"data\":{\"e\":\"depthUpdate\",\"E\":1784429282081,\"s\":\"SOLUSDT\",\"U\":1609569786,\"u\":1609569789,\"b\":[],\"a\":[[\"76.28000000\",\"53.60800000\"],[\"76.30000000\",\"30.19500000\"],[\"76.32000000\",\"0.00000000\"]]}}"}
{"mode":"v9-depth-v5-spsc","workers":4,"sequenceNumber":303,"symbol":"ETHUSDT","exchangeEventTimeMillis":1784429282081,"localReceivedEpochMillis":1784429282072,"topSpreadTicks":15,"bid5Volume":3204,"ask5Volume":4108,"bid10Volume":9176,"ask10Volume":15966,"rawPayload":"{\"stream\":\"ethusdt@depth@100ms\",\"data\":{\"e\":\"depthUpdate\",\"E\":1784429282081,\"s\":\"ETHUSDT\",\"U\":2806164394,\"u\":2806164395,\"b\":[[\"1871.82000000\",\"0.00000000\"]],\"a\":[[\"1872.39000000\",\"0.00000000\"]]}}"}
{"mode":"v9-depth-v5-spsc","workers":4,"sequenceNumber":304,"symbol":"ETHUSDT","exchangeEventTimeMillis":1784429282181,"localReceivedEpochMillis":1784429282171,"topSpreadTicks":12,"bid5Volume":4257,"ask5Volume":3661,"bid10Volume":8940,"ask10Volume":15519,"rawPayload":"{\"stream\":\"ethusdt@depth@100ms\",\"data\":{\"e\":\"depthUpdate\",\"E\":1784429282181,\"s\":\"ETHUSDT\",\"U\":2806164396,\"u\":2806164397,\"b\":[[\"1871.75000000\",\"1.19150000\"]],\"a\":[[\"1872.32000000\",\"1.19230000\"]]}}"}
{"mode":"v9-depth-v5-spsc","workers":4,"sequenceNumber":305,"symbol":"BNBUSDT","exchangeEventTimeMillis":1784429282181,"localReceivedEpochMillis":1784429282172,"topSpreadTicks":9,"bid5Volume":6039,"ask5Volume":6663,"bid10Volume":33795,"ask10Volume":265125,"rawPayload":"{\"stream\":\"bnbusdt@depth@100ms\",\"data\":{\"e\":\"depthUpdate\",\"E\":1784429282181,\"s\":\"BNBUSDT\",\"U\":1236327995,\"u\":1236327999,\"b\":[[\"569.16000000\",\"1.02000000\"],[\"568.24000000\",\"2.21900000\"]],\"a\":[[\"571.68000000\",\"2.58000000\"],[\"573.23000000\",\"1.74700000\"],[\"573.79000000\",\"0.00000000\"]]}}"}
{"mode":"v9-depth-v5-spsc","workers":4,"sequenceNumber":306,"symbol":"SOLUSDT","exchangeEventTimeMillis":1784429282181,"localReceivedEpochMillis":1784429282172,"topSpreadTicks":1,"bid5Volume":122780,"ask5Volume":225857,"bid10Volume":451435,"ask10Volume":383864,"rawPayload":"{\"stream\":\"solusdt@depth@100ms\",\"data\":{\"e\":\"depthUpdate\",\"E\":1784429282181,\"s\":\"SOLUSDT\",\"U\":1609569790,\"u\":1609569791,\"b\":[],\"a\":[[\"76.32000000\",\"65.56500000\"],[\"76.34000000\",\"18.93100000\"]]}}"}
{"mode":"v9-depth-v5-spsc","workers":4,"sequenceNumber":307,"symbol":"SOLUSDT","exchangeEventTimeMillis":1784429282381,"localReceivedEpochMillis":1784429282371,"topSpreadTicks":1,"bid5Volume":122780,"ask5Volume":256052,"bid10Volume":451435,"ask10Volume":482761,"rawPayload":"{\"stream\":\"solusdt@depth@100ms\",\"data\":{\"e\":\"depthUpdate\",\"E\":1784429282381,\"s\":\"SOLUSDT\",\"U\":1609569792,\"u\":1609569793,\"b\":[],\"a\":[[\"76.27000000\",\"61.23500000\"],[\"76.31000000\",\"0.00000000\"]]}}"}
{"mode":"v9-depth-v5-spsc","workers":4,"sequenceNumber":308,"symbol":"BNBUSDT","exchangeEventTimeMillis":1784429282381,"localReceivedEpochMillis":1784429282371,"topSpreadTicks":9,"bid5Volume":6039,"ask5Volume":6663,"bid10Volume":33795,"ask10Volume":265125,"rawPayload":"{\"stream\":\"bnbusdt@depth@100ms\",\"data\":{\"e\":\"depthUpdate\",\"E\":1784429282381,\"s\":\"BNBUSDT\",\"U\":1236328000,\"u\":1236328000,\"b\":[[\"568.22000000\",\"2.18800000\"]],\"a\":[]}}"}
{"mode":"v9-depth-v5-spsc","workers":4,"sequenceNumber":309,"symbol":"ETHUSDT","exchangeEventTimeMillis":1784429282381,"localReceivedEpochMillis":1784429282371,"topSpreadTicks":11,"bid5Volume":4257,"ask5Volume":3661,"bid10Volume":8940,"ask10Volume":15519,"rawPayload":"{\"stream\":\"ethusdt@depth@100ms\",\"data\":{\"e\":\"depthUpdate\",\"E\":1784429282381,\"s\":\"ETHUSDT\",\"U\":2806164398,\"u\":2806164399,\"b\":[[\"1871.44000000\",\"1.02590000\"],[\"1871.39000000\",\"0.00000000\"]],\"a\":[[\"1871.86000000\",\"0.96640000\"],[\"1871.87000000\",\"0.00000000\"]]}}"}
{"mode":"v9-depth-v5-spsc","workers":4,"sequenceNumber":310,"symbol":"SOLUSDT","exchangeEventTimeMillis":1784429282481,"localReceivedEpochMillis":1784429282471,"topSpreadTicks":1,"bid5Volume":122783,"ask5Volume":256052,"bid10Volume":451438,"ask10Volume":482761,"rawPayload":"{\"stream\":\"solusdt@depth@100ms\",\"data\":{\"e\":\"depthUpdate\",\"E\":1784429282481,\"s\":\"SOLUSDT\",\"U\":1609569794,\"u\":1609569795,\"b\":[[\"76.22000000\",\"7.60900000\"],[\"76.21000000\",\"63.12000000\"]],\"a\":[]}}"}
{"mode":"v9-depth-v5-spsc","workers":4,"sequenceNumber":311,"symbol":"BNBUSDT","exchangeEventTimeMillis":1784429282481,"localReceivedEpochMillis":1784429282472,"topSpreadTicks":9,"bid5Volume":6039,"ask5Volume":6663,"bid10Volume":33795,"ask10Volume":265125,"rawPayload":"{\"stream\":\"bnbusdt@depth@100ms\",\"data\":{\"e\":\"depthUpdate\",\"E\":1784429282481,\"s\":\"BNBUSDT\",\"U\":1236328001,\"u\":1236328001,\"b\":[[\"568.20000000\",\"2.21200000\"]],\"a\":[]}}"}
{"mode":"v9-depth-v5-spsc","workers":4,"sequenceNumber":312,"symbol":"SOLUSDT","exchangeEventTimeMillis":1784429282581,"localReceivedEpochMillis":1784429282572,"topSpreadTicks":2,"bid5Volume":195617,"ask5Volume":206607,"bid10Volume":731672,"ask10Volume":364614,"rawPayload":"{\"stream\":\"solusdt@depth@100ms\",\"data\":{\"e\":\"depthUpdate\",\"E\":1784429282581,\"s\":\"SOLUSDT\",\"U\":1609569796,\"u\":1609569802,\"b\":[[\"76.24000000\",\"0.00000000\"],[\"76.23000000\",\"32.12000000\"]],\"a\":[[\"76.27000000\",\"31.04000000\"],[\"76.28000000\",\"48.06500000\"],[\"76.29000000\",\"36.17800000\"],[\"76.31000000\",\"30.19500000\"]]}}"}
{"mode":"v9-depth-v5-spsc","workers":4,"sequenceNumber":313,"symbol":"SOLUSDT","exchangeEventTimeMillis":1784429282781,"localReceivedEpochMillis":1784429282772,"topSpreadTicks":1,"bid5Volume":195617,"ask5Volume":173254,"bid10Volume":731672,"ask10Volume":348508,"rawPayload":"{\"stream\":\"solusdt@depth@100ms\",\"data\":{\"e\":\"depthUpdate\",\"E\":1784429282781,\"s\":\"SOLUSDT\",\"U\":1609569803,\"u\":1609569808,\"b\":[],\"a\":[[\"76.24000000\",\"38.09700000\"],[\"76.25000000\",\"0.55400000\"],[\"76.26000000\",\"65.15600000\"],[\"76.27000000\",\"21.38200000\"]]}}"}
{"mode":"v9-depth-v5-spsc","workers":4,"sequenceNumber":314,"symbol":"ETHUSDT","exchangeEventTimeMillis":1784429282881,"localReceivedEpochMillis":1784429282872,"topSpreadTicks":11,"bid5Volume":4257,"ask5Volume":3661,"bid10Volume":10458,"ask10Volume":15519,"rawPayload":"{\"stream\":\"ethusdt@depth@100ms\",\"data\":{\"e\":\"depthUpdate\",\"E\":1784429282881,\"s\":\"ETHUSDT\",\"U\":2806164400,\"u\":2806164403,\"b\":[[\"1871.57000000\",\"0.00000000\"],[\"1871.52000000\",\"0.13890000\"],[\"1871.42000000\",\"1.63970000\"],[\"1870.43000000\",\"0.00000000\"]],\"a\":[[\"1872.19000000\",\"0.13880000\"],[\"1872.26000000\",\"0.00000000\"]]}}"}
{"mode":"v9-depth-v5-spsc","workers":4,"sequenceNumber":315,"symbol":"BNBUSDT","exchangeEventTimeMillis":1784429283181,"localReceivedEpochMillis":1784429283172,"topSpreadTicks":9,"bid5Volume":4623,"ask5Volume":6663,"bid10Volume":25210,"ask10Volume":262634,"rawPayload":"{\"stream\":\"bnbusdt@depth@100ms\",\"data\":{\"e\":\"depthUpdate\",\"E\":1784429283181,\"s\":\"BNBUSDT\",\"U\":1236328002,\"u\":1236328003,\"b\":[[\"570.75000000\",\"0.08900000\"]],\"a\":[[\"571.11000000\",\"0.08900000\"]]}}"}
{"mode":"v9-depth-v5-spsc","workers":4,"sequenceNumber":316,"symbol":"BNBUSDT","exchangeEventTimeMillis":1784429283281,"localReceivedEpochMillis":1784429283272,"topSpreadTicks":9,"bid5Volume":4623,"ask5Volume":6663,"bid10Volume":25210,"ask10Volume":262634,"rawPayload":"{\"stream\":\"bnbusdt@depth@100ms\",\"data\":{\"e\":\"depthUpdate\",\"E\":1784429283281,\"s\":\"BNBUSDT\",\"U\":1236328004,\"u\":1236328004,\"b\":[],\"a\":[[\"570.98000000\",\"1.61500000\"],[\"570.99000000\",\"0.00000000\"]]}}"}
{"mode":"v9-depth-v5-spsc","workers":4,"sequenceNumber":317,"symbol":"SOLUSDT","exchangeEventTimeMillis":1784429283281,"localReceivedEpochMillis":1784429283273,"topSpreadTicks":1,"bid5Volume":165422,"ask5Volume":223579,"bid10Volume":451156,"ask10Volume":387569,"rawPayload":"{\"stream\":\"solusdt@depth@100ms\",\"data\":{\"e\":\"depthUpdate\",\"E\":1784429283281,\"s\":\"SOLUSDT\",\"U\":1609569809,\"u\":1609569813,\"b\":[[\"76.21000000\",\"32.92500000\"],[\"76.17000000\",\"30.19500000\"]],\"a\":[[\"76.27000000\",\"71.70700000\"],[\"76.31000000\",\"0.00000000\"]]}}"}
{"mode":"v9-depth-v5-spsc","workers":4,"sequenceNumber":318,"symbol":"SOLUSDT","exchangeEventTimeMillis":1784429283381,"localReceivedEpochMillis":1784429283372,"topSpreadTicks":1,"bid5Volume":165422,"ask5Volume":223579,"bid10Volume":451156,"ask10Volume":387569,"rawPayload":"{\"stream\":\"solusdt@depth@100ms\",\"data\":{\"e\":\"depthUpdate\",\"E\":1784429283381,\"s\":\"SOLUSDT\",\"U\":1609569814,\"u\":1609569814,\"b\":[],\"a\":[[\"76.26000000\",\"83.13100000\"],[\"76.27000000\",\"53.73200000\"]]}}"}
{"mode":"v9-depth-v5-spsc","workers":4,"sequenceNumber":319,"symbol":"SOLUSDT","exchangeEventTimeMillis":1784429283982,"localReceivedEpochMillis":1784429283972,"topSpreadTicks":1,"bid5Volume":165422,"ask5Volume":208992,"bid10Volume":451156,"ask10Volume":386482,"rawPayload":"{\"stream\":\"solusdt@depth@100ms\",\"data\":{\"e\":\"depthUpdate\",\"E\":1784429283982,\"s\":\"SOLUSDT\",\"U\":1609569815,\"u\":1609569816,\"b\":[],\"a\":[[\"76.28000000\",\"33.47800000\"],[\"76.29000000\",\"49.67800000\"]]}}"}
{"mode":"v9-depth-v5-spsc","workers":4,"sequenceNumber":320,"symbol":"SOLUSDT","exchangeEventTimeMillis":1784429284182,"localReceivedEpochMillis":1784429284173,"topSpreadTicks":1,"bid5Volume":195617,"ask5Volume":253604,"bid10Volume":731672,"ask10Volume":541579,"rawPayload":"{\"stream\":\"solusdt@depth@100ms\",\"data\":{\"e\":\"depthUpdate\",\"E\":1784429284182,\"s\":\"SOLUSDT\",\"U\":1609569817,\"u\":1609569824,\"b\":[[\"76.21000000\",\"63.12000000\"],[\"76.17000000\",\"0.00000000\"]],\"a\":[[\"76.26000000\",\"113.32600000\"],[\"76.28000000\",\"47.89500000\"],[\"76.29000000\",\"36.17800000\"],[\"76.30000000\",\"0.00000000\"],[\"76.32000000\",\"120.84800000\"],[\"76.61000000\",\"0.00000000\"]]}}"}
{"mode":"v9-depth-v5-spsc","workers":4,"sequenceNumber":321,"symbol":"BTCUSDT","exchangeEventTimeMillis":1784429284382,"localReceivedEpochMillis":1784429284373,"topSpreadTicks":268,"bid5Volume":133,"ask5Volume":128,"bid10Volume":287,"ask10Volume":590,"rawPayload":"{\"stream\":\"btcusdt@depth@100ms\",\"data\":{\"e\":\"depthUpdate\",\"E\":1784429284382,\"s\":\"BTCUSDT\",\"U\":3244435318,\"u\":3244435318,\"b\":[],\"a\":[[\"81072.08000000\",\"0.00045000\"]]}}"}
{"mode":"v9-depth-v5-spsc","workers":4,"sequenceNumber":322,"symbol":"BNBUSDT","exchangeEventTimeMillis":1784429284482,"localReceivedEpochMillis":1784429284474,"topSpreadTicks":9,"bid5Volume":4623,"ask5Volume":7622,"bid10Volume":21058,"ask10Volume":263593,"rawPayload":"{\"stream\":\"bnbusdt@depth@100ms\",\"data\":{\"e\":\"depthUpdate\",\"E\":1784429284482,\"s\":\"BNBUSDT\",\"U\":1236328005,\"u\":1236328010,\"b\":[[\"570.56000000\",\"0.89700000\"],[\"569.34000000\",\"4.86800000\"],[\"568.05000000\",\"13.80000000\"]],\"a\":[[\"570.97000000\",\"1.83500000\"],[\"572.20000000\",\"4.74700000\"],[\"573.49000000\",\"13.86000000\"]]}}"}
{"mode":"v9-depth-v5-spsc","workers":4,"sequenceNumber":323,"symbol":"BTCUSDT","exchangeEventTimeMillis":1784429284482,"localReceivedEpochMillis":1784429284474,"topSpreadTicks":268,"bid5Volume":133,"ask5Volume":128,"bid10Volume":287,"ask10Volume":590,"rawPayload":"{\"stream\":\"btcusdt@depth@100ms\",\"data\":{\"e\":\"depthUpdate\",\"E\":1784429284482,\"s\":\"BTCUSDT\",\"U\":3244435319,\"u\":3244435320,\"b\":[],\"a\":[[\"64838.04000000\",\"0.00000000\"],[\"64840.16000000\",\"0.00166000\"]]}}"}
{"mode":"v9-depth-v5-spsc","workers":4,"sequenceNumber":324,"symbol":"SOLUSDT","exchangeEventTimeMillis":1784429284482,"localReceivedEpochMillis":1784429284474,"topSpreadTicks":1,"bid5Volume":195614,"ask5Volume":208989,"bid10Volume":731669,"ask10Volume":411508,"rawPayload":"{\"stream\":\"solusdt@depth@100ms\",\"data\":{\"e\":\"depthUpdate\",\"E\":1784429284482,\"s\":\"SOLUSDT\",\"U\":1609569825,\"u\":1609569831,\"b\":[[\"76.22000000\",\"40.43100000\"],[\"76.21000000\",\"30.29500000\"]],\"a\":[[\"76.24000000\",\"5.28300000\"],[\"76.25000000\",\"33.36500000\"],[\"76.26000000\",\"83.13100000\"],[\"76.28000000\",\"33.47800000\"],[\"76.30000000\",\"13.44100000\"]]}}"}
{"mode":"v9-depth-v5-spsc","workers":4,"sequenceNumber":325,"symbol":"ETHUSDT","exchangeEventTimeMillis":1784429284482,"localReceivedEpochMillis":1784429284474,"topSpreadTicks":11,"bid5Volume":3750,"ask5Volume":4108,"bid10Volume":10906,"ask10Volume":15458,"rawPayload":"{\"stream\":\"ethusdt@depth@100ms\",\"data\":{\"e\":\"depthUpdate\",\"E\":1784429284482,\"s\":\"ETHUSDT\",\"U\":2806164404,\"u\":2806164425,\"b\":[[\"1871.85000000\",\"1.19490000\"],[\"1871.75000000\",\"0.00000000\"],[\"1871.72000000\",\"0.00000000\"],[\"1871.63000000\",\"0.00000000\"],[\"1871.58000000\",\"0.00000000\"],[\"1871.55000000\",\"1.63970000\"],[\"1871.29000000\",\"1.09310000\"],[\"1870.90000000\",\"0.00000000\"],[\"1870.66000000\",\"0.00000000\"],[\"1870.64000000\",\"2.13790000\"],[\"1870.25000000\",\"0.00000000\"],[\"1863.11000000\",\"0.00000000\"]],\"a\":[[\"1871.86000000\",\"0.00000000\"],[\"1871.96000000\",\"0.96640000\"],[\"1872.24000000\",\"0.00000000\"],[\"1872.32000000\",\"0.00000000\"],[\"1872.39000000\",\"1.33610000\"],[\"1872.56000000\",\"1.13110000\"],[\"1879.44000000\",\"0.00000000\"],[\"1880.67000000\",\"9.17670000\"]]}}"}
{"mode":"v9-depth-v5-spsc","workers":4,"sequenceNumber":326,"symbol":"XRPUSDT","exchangeEventTimeMillis":1784429284482,"localReceivedEpochMillis":1784429284474,"topSpreadTicks":0,"bid5Volume":5195500,"ask5Volume":3362900,"bid10Volume":21083300,"ask10Volume":4560800,"rawPayload":"{\"stream\":\"xrpusdt@depth@100ms\",\"data\":{\"e\":\"depthUpdate\",\"E\":1784429284482,\"s\":\"XRPUSDT\",\"U\":752699385,\"u\":752699393,\"b\":[[\"1.09650000\",\"941.00000000\"],[\"1.09640000\",\"3576.80000000\"],[\"1.09630000\",\"45.50000000\"]],\"a\":[[\"1.09670000\",\"1478.10000000\"],[\"1.09680000\",\"4880.90000000\"],[\"1.09700000\",\"0.00000000\"],[\"1.09710000\",\"3047.60000000\"]]}}"}
{"mode":"v9-depth-v5-spsc","workers":4,"sequenceNumber":327,"symbol":"BTCUSDT","exchangeEventTimeMillis":1784429284582,"localReceivedEpochMillis":1784429284574,"topSpreadTicks":268,"bid5Volume":136,"ask5Volume":128,"bid10Volume":290,"ask10Volume":590,"rawPayload":"{\"stream\":\"btcusdt@depth@100ms\",\"data\":{\"e\":\"depthUpdate\",\"E\":1784429284582,\"s\":\"BTCUSDT\",\"U\":3244435321,\"u\":3244435324,\"b\":[[\"64818.66000000\",\"0.00000000\"],[\"64818.03000000\",\"0.03087000\"],[\"64816.44000000\",\"0.00000000\"]],\"a\":[]}}"}
{"mode":"v9-depth-v5-spsc","workers":4,"sequenceNumber":328,"symbol":"SOLUSDT","exchangeEventTimeMillis":1784429284582,"localReceivedEpochMillis":1784429284574,"topSpreadTicks":1,"bid5Volume":117869,"ask5Volume":246216,"bid10Volume":439823,"ask10Volume":511454,"rawPayload":"{\"stream\":\"solusdt@depth@100ms\",\"data\":{\"e\":\"depthUpdate\",\"E\":1784429284582,\"s\":\"SOLUSDT\",\"U\":1609569832,\"u\":1609569843,\"b\":[[\"76.24000000\",\"13.60100000\"],[\"76.23000000\",\"23.64500000\"],[\"76.22000000\",\"36.79100000\"],[\"76.20000000\",\"13.53700000\"],[\"76.19000000\",\"66.41500000\"]],\"a\":[[\"76.24000000\",\"0.00000000\"],[\"76.25000000\",\"38.99800000\"],[\"76.26000000\",\"54.58900000\"],[\"76.27000000\",\"82.97300000\"]]}}"}
{"mode":"v9-depth-v5-spsc","workers":4,"sequenceNumber":329,"symbol":"ETHUSDT","exchangeEventTimeMillis":1784429284582,"localReceivedEpochMillis":1784429284575,"topSpreadTicks":13,"bid5Volume":3735,"ask5Volume":8914,"bid10Volume":13076,"ask10Volume":17119,"rawPayload":"{\"stream\":\"ethusdt@depth@100ms\",\"data\":{\"e\":\"depthUpdate\",\"E\":1784429284582,\"s\":\"ETHUSDT\",\"U\":2806164426,\"u\":2806164459,\"b\":[[\"1871.95000000\",\"1.16440000\"],[\"1871.90000000\",\"0.00000000\"],[\"1871.87000000\",\"1.33640000\"],[\"1871.85000000\",\"1.06880000\"],[\"1871.76000000\",\"0.13890000\"],[\"1871.65000000\",\"0.00000000\"],[\"1871.60000000\",\"1.63970000\"],[\"1871.52000000\",\"0.00000000\"],[\"1871.46000000\",\"3.39980000\"],[\"1871.40000000\",\"1.60330000\"],[\"1871.24000000\",\"0.00000000\"],[\"1871.20000000\",\"0.00000000\"],[\"1870.70000000\",\"0.00000000\"],[\"1870.41000000\",\"9.19570000\"],[\"1870.22000000\",\"0.00000000\"],[\"1864.26000000\",\"0.41380000\"],[\"1863.96000000\",\"0.00000000\"]],\"a\":[[\"1871.96000000\",\"0.00000000\"],[\"1872.08000000\",\"0.96640000\"],[\"1872.19000000\",\"0.00000000\"],[\"1872.43000000\",\"0.13880000\"],[\"1872.47000000\",\"0.00000000\"],[\"1872.50000000\",\"0.00000000\"],[\"1872.56000000\",\"0.00000000\"],[\"1872.62000000\",\"2.79250000\"],[\"1872.73000000\",\"1.47370000\"],[\"1873.11000000\",\"0.00000000\"],[\"1873.24000000\",\"1.63970000\"],[\"1873.38000000\",\"0.00000000\"],[\"1873.51000000\",\"1.91080000\"],[\"1873.53000000\",\"0.00000000\"],[\"1873.57000000\",\"0.27390000\"],[\"1873.78000000\",\"9.17920000\"],[\"1879.39000000\",\"0.00000000\"],[\"1879.42000000\",\"0.00000000\"],[\"1879.50000000\",\"0.00000000\"]]}}"}
{"mode":"v9-depth-v5-spsc","workers":4,"sequenceNumber":330,"symbol":"XRPUSDT","exchangeEventTimeMillis":1784429284582,"localReceivedEpochMillis":1784429284575,"topSpreadTicks":0,"bid5Volume":5195500,"ask5Volume":6808500,"bid10Volume":21083300,"ask10Volume":8006400,"rawPayload":"{\"stream\":\"xrpusdt@depth@100ms\",\"data\":{\"e\":\"depthUpdate\",\"E\":1784429284582,\"s\":\"XRPUSDT\",\"U\":752699394,\"u\":752699394,\"b\":[],\"a\":[[\"1.09680000\",\"6493.20000000\"]]}}"}
{"mode":"v9-depth-v5-spsc","workers":4,"sequenceNumber":331,"symbol":"ETHUSDT","exchangeEventTimeMillis":1784429284682,"localReceivedEpochMillis":1784429284673,"topSpreadTicks":13,"bid5Volume":5345,"ask5Volume":10524,"bid10Volume":14650,"ask10Volume":18729,"rawPayload":"{\"stream\":\"ethusdt@depth@100ms\",\"data\":{\"e\":\"depthUpdate\",\"E\":1784429284682,\"s\":\"ETHUSDT\",\"U\":2806164460,\"u\":2806164461,\"b\":[[\"1871.61000000\",\"0.00000000\"]],\"a\":[[\"1872.16000000\",\"0.00000000\"]]}}"}
{"mode":"v9-depth-v5-spsc","workers":4,"sequenceNumber":332,"symbol":"ETHUSDT","exchangeEventTimeMillis":1784429284782,"localReceivedEpochMillis":1784429284774,"topSpreadTicks":12,"bid5Volume":5251,"ask5Volume":10524,"bid10Volume":14592,"ask10Volume":18729,"rawPayload":"{\"stream\":\"ethusdt@depth@100ms\",\"data\":{\"e\":\"depthUpdate\",\"E\":1784429284782,\"s\":\"ETHUSDT\",\"U\":2806164462,\"u\":2806164465,\"b\":[[\"1871.96000000\",\"0.77270000\"],[\"1871.87000000\",\"2.10910000\"],[\"1864.62000000\",\"7.23390000\"]],\"a\":[[\"1880.74000000\",\"9.26610000\"]]}}"}
{"mode":"v9-depth-v5-spsc","workers":4,"sequenceNumber":333,"symbol":"BNBUSDT","exchangeEventTimeMillis":1784429284882,"localReceivedEpochMillis":1784429284874,"topSpreadTicks":9,"bid5Volume":4623,"ask5Volume":7711,"bid10Volume":21058,"ask10Volume":266173,"rawPayload":"{\"stream\":\"bnbusdt@depth@100ms\",\"data\":{\"e\":\"depthUpdate\",\"E\":1784429284882,\"s\":\"BNBUSDT\",\"U\":1236328011,\"u\":1236328012,\"b\":[[\"570.67000000\",\"0.00000000\"],[\"570.65000000\",\"1.73700000\"]],\"a\":[[\"570.95000000\",\"3.21000000\"],[\"570.98000000\",\"0.00000000\"]]}}"}
{"mode":"v9-depth-v5-spsc","workers":4,"sequenceNumber":334,"symbol":"ETHUSDT","exchangeEventTimeMillis":1784429284883,"localReceivedEpochMillis":1784429284875,"topSpreadTicks":12,"bid5Volume":4756,"ask5Volume":8914,"bid10Volume":12596,"ask10Volume":17119,"rawPayload":"{\"stream\":\"ethusdt@depth@100ms\",\"data\":{\"e\":\"depthUpdate\",\"E\":1784429284883,\"s\":\"ETHUSDT\",\"U\":2806164466,\"u\":2806164470,\"b\":[[\"1871.85000000\",\"0.00000000\"],[\"1871.81000000\",\"0.02960000\"],[\"1871.80000000\",\"0.68230000\"]],\"a\":[[\"1872.37000000\",\"0.02960000\"],[\"1880.80000000\",\"9.12670000\"]]}}"}
{"mode":"v9-depth-v5-spsc","workers":4,"sequenceNumber":335,"symbol":"BTCUSDT","exchangeEventTimeMillis":1784429284983,"localReceivedEpochMillis":1784429284975,"topSpreadTicks":268,"bid5Volume":136,"ask5Volume":128,"bid10Volume":290,"ask10Volume":590,"rawPayload":"{\"stream\":\"btcusdt@depth@100ms\",\"data\":{\"e\":\"depthUpdate\",\"E\":1784429284983,\"s\":\"BTCUSDT\",\"U\":3244435325,\"u\":3244435325,\"b\":[],\"a\":[[\"64914.49000000\",\"0.00000000\"]]}}"}
{"mode":"v9-depth-v5-spsc","workers":4,"sequenceNumber":336,"symbol":"XRPUSDT","exchangeEventTimeMillis":1784429284983,"localReceivedEpochMillis":1784429284975,"topSpreadTicks":0,"bid5Volume":5195500,"ask5Volume":6990900,"bid10Volume":21083300,"ask10Volume":8188800,"rawPayload":"{\"stream\":\"xrpusdt@depth@100ms\",\"data\":{\"e\":\"depthUpdate\",\"E\":1784429284983,\"s\":\"XRPUSDT\",\"U\":752699395,\"u\":752699396,\"b\":[],\"a\":[[\"1.09670000\",\"1295.60000000\"],[\"1.09680000\",\"6675.60000000\"]]}}"}
{"mode":"v9-depth-v5-spsc","workers":4,"sequenceNumber":337,"symbol":"ETHUSDT","exchangeEventTimeMillis":1784429285083,"localReceivedEpochMillis":1784429285074,"topSpreadTicks":12,"bid5Volume":4756,"ask5Volume":8914,"bid10Volume":12596,"ask10Volume":17119,"rawPayload":"{\"stream\":\"ethusdt@depth@100ms\",\"data\":{\"e\":\"depthUpdate\",\"E\":1784429285083,\"s\":\"ETHUSDT\",\"U\":2806164471,\"u\":2806164471,\"b\":[],\"a\":[[\"1880.86000000\",\"9.24200000\"]]}}"}
{"mode":"v9-depth-v5-spsc","workers":4,"sequenceNumber":338,"symbol":"BTCUSDT","exchangeEventTimeMillis":1784429285083,"localReceivedEpochMillis":1784429285074,"topSpreadTicks":268,"bid5Volume":136,"ask5Volume":128,"bid10Volume":290,"ask10Volume":590,"rawPayload":"{\"stream\":\"btcusdt@depth@100ms\",\"data\":{\"e\":\"depthUpdate\",\"E\":1784429285083,\"s\":\"BTCUSDT\",\"U\":3244435326,\"u\":3244435326,\"b\":[],\"a\":[[\"64914.49000000\",\"0.00011000\"]]}}"}
{"mode":"v9-depth-v5-spsc","workers":4,"sequenceNumber":339,"symbol":"ETHUSDT","exchangeEventTimeMillis":1784429285583,"localReceivedEpochMillis":1784429285574,"topSpreadTicks":19,"bid5Volume":4122,"ask5Volume":8914,"bid10Volume":13463,"ask10Volume":17119,"rawPayload":"{\"stream\":\"ethusdt@depth@100ms\",\"data\":{\"e\":\"depthUpdate\",\"E\":1784429285583,\"s\":\"ETHUSDT\",\"U\":2806164472,\"u\":2806164473,\"b\":[[\"1871.96000000\",\"0.00000000\"]],\"a\":[[\"1872.08000000\",\"0.00000000\"],[\"1872.14000000\",\"0.96640000\"]]}}"}
{"mode":"v9-depth-v5-spsc","workers":4,"sequenceNumber":340,"symbol":"XRPUSDT","exchangeEventTimeMillis":1784429285583,"localReceivedEpochMillis":1784429285575,"topSpreadTicks":0,"bid5Volume":9707000,"ask5Volume":6990900,"bid10Volume":25594800,"ask10Volume":8188800,"rawPayload":"{\"stream\":\"xrpusdt@depth@100ms\",\"data\":{\"e\":\"depthUpdate\",\"E\":1784429285583,\"s\":\"XRPUSDT\",\"U\":752699397,\"u\":752699398,\"b\":[[\"1.09650000\",\"0.00000000\"],[\"1.09640000\",\"4557.00000000\"]],\"a\":[]}}"}
{"mode":"v9-depth-v5-spsc","workers":4,"sequenceNumber":341,"symbol":"SOLUSDT","exchangeEventTimeMillis":1784429285983,"localReceivedEpochMillis":1784429285974,"topSpreadTicks":1,"bid5Volume":117869,"ask5Volume":276411,"bid10Volume":439823,"ask10Volume":541649,"rawPayload":"{\"stream\":\"solusdt@depth@100ms\",\"data\":{\"e\":\"depthUpdate\",\"E\":1784429285983,\"s\":\"SOLUSDT\",\"U\":1609569844,\"u\":1609569844,\"b\":[],\"a\":[[\"76.29000000\",\"66.37300000\"]]}}"}
{"mode":"v9-depth-v5-spsc","workers":4,"sequenceNumber":342,"symbol":"XRPUSDT","exchangeEventTimeMillis":1784429285983,"localReceivedEpochMillis":1784429285974,"topSpreadTicks":0,"bid5Volume":9707000,"ask5Volume":8286500,"bid10Volume":25594800,"ask10Volume":9484400,"rawPayload":"{\"stream\":\"xrpusdt@depth@100ms\",\"data\":{\"e\":\"depthUpdate\",\"E\":1784429285983,\"s\":\"XRPUSDT\",\"U\":752699399,\"u\":752699399,\"b\":[],\"a\":[[\"1.09670000\",\"0.00000000\"],[\"1.09680000\",\"7971.20000000\"]]}}"}
{"mode":"v9-depth-v5-spsc","workers":4,"sequenceNumber":343,"symbol":"XRPUSDT","exchangeEventTimeMillis":1784429286083,"localReceivedEpochMillis":1784429286075,"topSpreadTicks":0,"bid5Volume":5325000,"ask5Volume":8286500,"bid10Volume":21212800,"ask10Volume":9484400,"rawPayload":"{\"stream\":\"xrpusdt@depth@100ms\",\"data\":{\"e\":\"depthUpdate\",\"E\":1784429286083,\"s\":\"XRPUSDT\",\"U\":752699400,\"u\":752699401,\"b\":[[\"1.09630000\",\"227.90000000\"],[\"1.09620000\",\"175.00000000\"]],\"a\":[]}}"}
{"mode":"v9-depth-v5-spsc","workers":4,"sequenceNumber":344,"symbol":"ETHUSDT","exchangeEventTimeMillis":1784429286584,"localReceivedEpochMillis":1784429286574,"topSpreadTicks":18,"bid5Volume":3984,"ask5Volume":8914,"bid10Volume":11824,"ask10Volume":17119,"rawPayload":"{\"stream\":\"ethusdt@depth@100ms\",\"data\":{\"e\":\"depthUpdate\",\"E\":1784429286584,\"s\":\"ETHUSDT\",\"U\":2806164474,\"u\":2806164475,\"b\":[[\"1871.96000000\",\"0.77300000\"],[\"1871.87000000\",\"1.33640000\"]],\"a\":[]}}"}
