{"mode":"v10-framework-compare","workers":4,"sequenceNumber":340,"symbol":"SOLUSDT","exchangeEventTimeMillis":1784430166272,"localReceivedEpochMillis":1784430166262,"topSpreadTicks":-2,"bid5Volume":185931,"ask5Volume":207623,"bid10Volume":459119,"ask10Volume":782031,"rawPayload":"{\"stream\":\"solusdt@depth@100ms\",\"data\":{\"e\":\"depthUpdate\",\"E\":1784430166272,\"s\":\"SOLUSDT\",\"U\":1609580050,\"u\":1609580059,\"b\":[[\"76.20000000\",\"13.62300000\"],[\"76.19000000\",\"58.03100000\"],[\"76.18000000\",\"3.96300000\"],[\"75.86000000\",\"0.00000000\"]],\"a\":[[\"76.20000000\",\"0.00000000\"],[\"76.21000000\",\"7.12300000\"],[\"76.30000000\",\"19.42400000\"],[\"76.31000000\",\"98.94100000\"],[\"76.32000000\",\"0.00000000\"],[\"76.49000000\",\"478.36400000\"]]}}"}
{"mode":"v10-framework-compare","workers":4,"sequenceNumber":341,"symbol":"ETHUSDT","exchangeEventTimeMillis":1784430166272,"localReceivedEpochMillis":1784430166262,"topSpreadTicks":-18,"bid5Volume":6382,"ask5Volume":4861,"bid10Volume":9907,"ask10Volume":18541,"rawPayload":"{\"stream\":\"ethusdt@depth@100ms\",\"data\":{\"e\":\"depthUpdate\",\"E\":1784430166272,\"s\":\"ETHUSDT\",\"U\":2806178154,\"u\":2806178157,\"b\":[[\"1870.09000000\",\"0.62510000\"]],\"a\":[[\"1870.72000000\",\"0.00000000\"],[\"1870.77000000\",\"0.62670000\"],[\"1871.13000000\",\"0.00000000\"],[\"1871.25000000\",\"1.06180000\"]]}}"}
{"mode":"v10-framework-compare","workers":4,"sequenceNumber":342,"symbol":"XRPUSDT","exchangeEventTimeMillis":1784430166272,"localReceivedEpochMillis":1784430166262,"topSpreadTicks":1,"bid5Volume":15059000,"ask5Volume":25191000,"bid10Volume":15429200,"ask10Volume":26397500,"rawPayload":"{\"stream\":\"xrpusdt@depth@100ms\",\"data\":{\"e\":\"depthUpdate\",\"E\":1784430166272,\"s\":\"XRPUSDT\",\"U\":752705500,\"u\":752705514,\"b\":[[\"1.09610000\",\"3297.20000000\"],[\"1.09600000\",\"180.10000000\"],[\"1.09590000\",\"45.30000000\"],[\"1.09570000\",\"2177.70000000\"],[\"1.09160000\",\"7377.90000000\"],[\"1.09140000\",\"0.00000000\"],[\"1.09110000\",\"0.00000000\"]],\"a\":[[\"1.09630000\",\"0.00000000\"],[\"1.09640000\",\"1244.00000000\"],[\"1.09650000\",\"4131.00000000\"],[\"1.09660000\",\"674.10000000\"],[\"1.09670000\",\"1153.50000000\"],[\"1.09780000\",\"90.30000000\"],[\"1.10000000\",\"24794.00000000\"]]}}"}
{"mode":"v10-framework-compare","workers":4,"sequenceNumber":343,"symbol":"SOLUSDT","exchangeEventTimeMillis":1784430166372,"localReceivedEpochMillis":1784430166360,"topSpreadTicks":-2,"bid5Volume":185931,"ask5Volume":207065,"bid10Volume":459119,"ask10Volume":781473,"rawPayload":"{\"stream\":\"solusdt@depth@100ms\",\"data\":{\"e\":\"depthUpdate\",\"E\":1784430166372,\"s\":\"SOLUSDT\",\"U\":1609580060,\"u\":1609580061,\"b\":[[\"76.20000000\",\"32.25400000\"],[\"76.19000000\",\"39.40000000\"]],\"a\":[[\"76.21000000\",\"6.56500000\"]]}}"}
{"mode":"v10-framework-compare","workers":4,"sequenceNumber":344,"symbol":"XRPUSDT","exchangeEventTimeMillis":1784430166372,"localReceivedEpochMillis":1784430166360,"topSpreadTicks":0,"bid5Volume":18051900,"ask5Volume":26368700,"bid10Volume":28331100,"ask10Volume":27575200,"rawPayload":"{\"stream\":\"xrpusdt@depth@100ms\",\"data\":{\"e\":\"depthUpdate\",\"E\":1784430166372,\"s\":\"XRPUSDT\",\"U\":752705515,\"u\":752705519,\"b\":[[\"1.09590000\",\"0.00000000\"],[\"1.09440000\",\"12901.90000000\"]],\"a\":[[\"1.09620000\",\"0.00000000\"],[\"1.09660000\",\"494.00000000\"],[\"1.09670000\",\"1268.00000000\"]]}}"}
{"mode":"v10-framework-compare","workers":4,"sequenceNumber":345,"symbol":"SOLUSDT","exchangeEventTimeMillis":1784430166472,"localReceivedEpochMillis":1784430166462,"topSpreadTicks":-2,"bid5Volume":185378,"ask5Volume":207620,"bid10Volume":469738,"ask10Volume":782028,"rawPayload":"{\"stream\":\"solusdt@depth@100ms\",\"data\":{\"e\":\"depthUpdate\",\"E\":1784430166472,\"s\":\"SOLUSDT\",\"U\":1609580062,\"u\":1609580066,\"b\":[[\"76.18000000\",\"3.41000000\"],[\"76.16000000\",\"81.53400000\"],[\"76.15000000\",\"0.00000000\"]],\"a\":[[\"76.22000000\",\"83.02000000\"],[\"76.49000000\",\"141.90100000\"]]}}"}
{"mode":"v10-framework-compare","workers":4,"sequenceNumber":346,"symbol":"XRPUSDT","exchangeEventTimeMillis":1784430166472,"localReceivedEpochMillis":1784430166462,"topSpreadTicks":2,"bid5Volume":15059000,"ask5Volume":25109300,"bid10Volume":15429200,"ask10Volume":26307200,"rawPayload":"{\"stream\":\"xrpusdt@depth@100ms\",\"data\":{\"e\":\"depthUpdate\",\"E\":1784430166472,\"s\":\"XRPUSDT\",\"U\":752705520,\"u\":752705522,\"b\":[[\"1.09580000\",\"3814.80000000\"],[\"1.09530000\",\"0.00000000\"]],\"a\":[[\"1.09790000\",\"0.00000000\"]]}}"}
{"mode":"v10-framework-compare","workers":4,"sequenceNumber":347,"symbol":"SOLUSDT","exchangeEventTimeMillis":1784430166572,"localReceivedEpochMillis":1784430166562,"topSpreadTicks":-2,"bid5Volume":185378,"ask5Volume":207620,"bid10Volume":741694,"ask10Volume":782028,"rawPayload":"{\"stream\":\"solusdt@depth@100ms\",\"data\":{\"e\":\"depthUpdate\",\"E\":1784430166572,\"s\":\"SOLUSDT\",\"U\":1609580067,\"u\":1609580068,\"b\":[[\"76.08000000\",\"281.46400000\"]],\"a\":[[\"76.48000000\",\"333.23500000\"]]}}"}
{"mode":"v10-framework-compare","workers":4,"sequenceNumber":348,"symbol":"BNBUSDT","exchangeEventTimeMillis":1784430166572,"localReceivedEpochMillis":1784430166562,"topSpreadTicks":4,"bid5Volume":5152,"ask5Volume":6689,"bid10Volume":20035,"ask10Volume":257415,"rawPayload":"{\"stream\":\"bnbusdt@depth@100ms\",\"data\":{\"e\":\"depthUpdate\",\"E\":1784430166572,\"s\":\"BNBUSDT\",\"U\":1236331365,\"u\":1236331372,\"b\":[[\"570.37000000\",\"0.00000000\"],[\"570.29000000\",\"0.95400000\"],[\"570.27000000\",\"0.00000000\"]],\"a\":[[\"570.68000000\",\"0.00000000\"],[\"570.70000000\",\"0.91200000\"],[\"570.78000000\",\"0.00000000\"]]}}"}
{"mode":"v10-framework-compare","workers":4,"sequenceNumber":349,"symbol":"XRPUSDT","exchangeEventTimeMillis":1784430166572,"localReceivedEpochMillis":1784430166562,"topSpreadTicks":2,"bid5Volume":15059000,"ask5Volume":16316500,"bid10Volume":15429200,"ask10Volume":17514400,"rawPayload":"{\"stream\":\"xrpusdt@depth@100ms\",\"data\":{\"e\":\"depthUpdate\",\"E\":1784430166572,\"s\":\"XRPUSDT\",\"U\":752705523,\"u\":752705525,\"b\":[[\"1.09450000\",\"13398.60000000\"],[\"1.09130000\",\"0.00000000\"]],\"a\":[[\"1.10020000\",\"16001.20000000\"]]}}"}
{"mode":"v10-framework-compare","workers":4,"sequenceNumber":350,"symbol":"XRPUSDT","exchangeEventTimeMillis":1784430166672,"localReceivedEpochMillis":1784430166664,"topSpreadTicks":0,"bid5Volume":7500800,"ask5Volume":17597200,"bid10Volume":17780000,"ask10Volume":18803700,"rawPayload":"{\"stream\":\"xrpusdt@depth@100ms\",\"data\":{\"e\":\"depthUpdate\",\"E\":1784430166672,\"s\":\"XRPUSDT\",\"U\":752705526,\"u\":752705528,\"b\":[[\"1.09610000\",\"3342.50000000\"],[\"1.09550000\",\"2350.80000000\"]],\"a\":[[\"1.09640000\",\"1289.30000000\"]]}}"}
{"mode":"v10-framework-compare","workers":4,"sequenceNumber":351,"symbol":"SOLUSDT","exchangeEventTimeMillis":1784430166772,"localReceivedEpochMillis":1784430166762,"topSpreadTicks":-2,"bid5Volume":185935,"ask5Volume":207620,"bid10Volume":742251,"ask10Volume":782028,"rawPayload":"{\"stream\":\"solusdt@depth@100ms\",\"data\":{\"e\":\"depthUpdate\",\"E\":1784430166772,\"s\":\"SOLUSDT\",\"U\":1609580069,\"u\":1609580069,\"b\":[[\"76.19000000\",\"39.95700000\"]],\"a\":[]}}"}
{"mode":"v10-framework-compare","workers":4,"sequenceNumber":352,"symbol":"XRPUSDT","exchangeEventTimeMillis":1784430166772,"localReceivedEpochMillis":1784430166762,"topSpreadTicks":0,"bid5Volume":9138000,"ask5Volume":17597200,"bid10Volume":19417200,"ask10Volume":18803700,"rawPayload":"{\"stream\":\"xrpusdt@depth@100ms\",\"data\":{\"e\":\"depthUpdate\",\"E\":1784430166772,\"s\":\"XRPUSDT\",\"U\":752705529,\"u\":752705529,\"b\":[[\"1.09580000\",\"3988.00000000\"]],\"a\":[]}}"}
{"mode":"v10-framework-compare","workers":4,"sequenceNumber":353,"symbol":"SOLUSDT","exchangeEventTimeMillis":1784430166873,"localReceivedEpochMillis":1784430166862,"topSpreadTicks":-2,"bid5Volume":185935,"ask5Volume":207620,"bid10Volume":742251,"ask10Volume":782028,"rawPayload":"{\"stream\":\"solusdt@depth@100ms\",\"data\":{\"e\":\"depthUpdate\",\"E\":1784430166873,\"s\":\"SOLUSDT\",\"U\":1609580070,\"u\":1609580070,\"b\":[],\"a\":[[\"76.23000000\",\"35.72700000\"],[\"76.24000000\",\"52.11300000\"]]}}"}
{"mode":"v10-framework-compare","workers":4,"sequenceNumber":354,"symbol":"BNBUSDT","exchangeEventTimeMillis":1784430167173,"localReceivedEpochMillis":1784430167161,"topSpreadTicks":4,"bid5Volume":5152,"ask5Volume":6689,"bid10Volume":20035,"ask10Volume":257415,"rawPayload":"{\"stream\":\"bnbusdt@depth@100ms\",\"data\":{\"e\":\"depthUpdate\",\"E\":1784430167173,\"s\":\"BNBUSDT\",\"U\":1236331373,\"u\":1236331374,\"b\":[[\"570.41000000\",\"1.74200000\"],[\"570.40000000\",\"0.00000000\"]],\"a\":[[\"570.58000000\",\"0.00000000\"],[\"570.59000000\",\"1.71100000\"]]}}"}
{"mode":"v10-framework-compare","workers":4,"sequenceNumber":355,"symbol":"BTCUSDT","exchangeEventTimeMillis":1784430167173,"localReceivedEpochMillis":1784430167162,"topSpreadTicks":-369,"bid5Volume":145,"ask5Volume":148,"bid10Volume":310,"ask10Volume":587,"rawPayload":"{\"stream\":\"btcusdt@depth@100ms\",\"data\":{\"e\":\"depthUpdate\",\"E\":1784430167173,\"s\":\"BTCUSDT\",\"U\":3244441396,\"u\":3244441397,\"b\":[[\"64790.08000000\",\"0.01847000\"],[\"64788.36000000\",\"0.00000000\"]],\"a\":[]}}"}
{"mode":"v10-framework-compare","workers":4,"sequenceNumber":356,"symbol":"XRPUSDT","exchangeEventTimeMillis":1784430167173,"localReceivedEpochMillis":1784430167162,"topSpreadTicks":0,"bid5Volume":5264600,"ask5Volume":17461400,"bid10Volume":15543800,"ask10Volume":18667900,"rawPayload":"{\"stream\":\"xrpusdt@depth@100ms\",\"data\":{\"e\":\"depthUpdate\",\"E\":1784430167173,\"s\":\"XRPUSDT\",\"U\":752705530,\"u\":752705533,\"b\":[[\"1.09600000\",\"0.00000000\"],[\"1.09590000\",\"114.60000000\"]],\"a\":[[\"1.09660000\",\"608.60000000\"],[\"1.09670000\",\"1153.50000000\"]]}}"}
{"mode":"v10-framework-compare","workers":4,"sequenceNumber":357,"symbol":"ETHUSDT","exchangeEventTimeMillis":1784430167573,"localReceivedEpochMillis":1784430167563,"topSpreadTicks":-10,"bid5Volume":6382,"ask5Volume":13001,"bid10Volume":11354,"ask10Volume":19174,"rawPayload":"{\"stream\":\"ethusdt@depth@100ms\",\"data\":{\"e\":\"depthUpdate\",\"E\":1784430167573,\"s\":\"ETHUSDT\",\"U\":2806178158,\"u\":2806178161,\"b\":[[\"1870.07000000\",\"0.00000000\"],[\"1869.69000000\",\"4.13240000\"],[\"1869.66000000\",\"0.00000000\"]],\"a\":[[\"1870.66000000\",\"0.00000000\"]]}}"}
{"mode":"v10-framework-compare","workers":4,"sequenceNumber":358,"symbol":"ETHUSDT","exchangeEventTimeMillis":1784430168173,"localReceivedEpochMillis":1784430168163,"topSpreadTicks":-10,"bid5Volume":6382,"ask5Volume":13001,"bid10Volume":11388,"ask10Volume":19174,"rawPayload":"{\"stream\":\"ethusdt@depth@100ms\",\"data\":{\"e\":\"depthUpdate\",\"E\":1784430168173,\"s\":\"ETHUSDT\",\"U\":2806178162,\"u\":2806178163,\"b\":[[\"1870.09000000\",\"0.00000000\"],[\"1869.93000000\",\"0.65980000\"]],\"a\":[]}}"}
{"mode":"v10-framework-compare","workers":4,"sequenceNumber":359,"symbol":"BNBUSDT","exchangeEventTimeMillis":1784430168173,"localReceivedEpochMillis":1784430168164,"topSpreadTicks":4,"bid5Volume":5152,"ask5Volume":6689,"bid10Volume":20035,"ask10Volume":257415,"rawPayload":"{\"stream\":\"bnbusdt@depth@100ms\",\"data\":{\"e\":\"depthUpdate\",\"E\":1784430168173,\"s\":\"BNBUSDT\",\"U\":1236331375,\"u\":1236331376,\"b\":[],\"a\":[[\"570.61000000\",\"0.00000000\"],[\"570.63000000\",\"0.87600000\"]]}}"}
{"mode":"v10-framework-compare","workers":4,"sequenceNumber":360,"symbol":"BTCUSDT","exchangeEventTimeMillis":1784430168173,"localReceivedEpochMillis":1784430168164,"topSpreadTicks":-369,"bid5Volume":145,"ask5Volume":103,"bid10Volume":310,"ask10Volume":587,"rawPayload":"{\"stream\":\"btcusdt@depth@100ms\",\"data\":{\"e\":\"depthUpdate\",\"E\":1784430168173,\"s\":\"BTCUSDT\",\"U\":3244441398,\"u\":3244441399,\"b\":[],\"a\":[[\"64809.10000000\",\"0.00161000\"],[\"64810.04000000\",\"0.00000000\"]]}}"}
{"mode":"v10-framework-compare","workers":4,"sequenceNumber":361,"symbol":"ETHUSDT","exchangeEventTimeMillis":1784430168374,"localReceivedEpochMillis":1784430168363,"topSpreadTicks":-10,"bid5Volume":6382,"ask5Volume":13001,"bid10Volume":11393,"ask10Volume":19174,"rawPayload":"{\"stream\":\"ethusdt@depth@100ms\",\"data\":{\"e\":\"depthUpdate\",\"E\":1784430168374,\"s\":\"ETHUSDT\",\"U\":2806178164,\"u\":2806178165,\"b\":[[\"1869.99000000\",\"0.66420000\"],[\"1869.93000000\",\"0.00000000\"]],\"a\":[]}}"}
{"mode":"v10-framework-compare","workers":4,"sequenceNumber":362,"symbol":"ETHUSDT","exchangeEventTimeMillis":1784430168474,"localReceivedEpochMillis":1784430168465,"topSpreadTicks":-7,"bid5Volume":5118,"ask5Volume":13098,"bid10Volume":10372,"ask10Volume":19271,"rawPayload":"{\"stream\":\"ethusdt@depth@100ms\",\"data\":{\"e\":\"depthUpdate\",\"E\":1784430168474,\"s\":\"ETHUSDT\",\"U\":2806178166,\"u\":2806178174,\"b\":[[\"1870.48000000\",\"1.16990000\"],[\"1870.41000000\",\"0.00000000\"],[\"1870.31000000\",\"0.76660000\"],[\"1870.30000000\",\"1.33760000\"],[\"1869.82000000\",\"1.47580000\"],[\"1869.72000000\",\"0.00000000\"]],\"a\":[[\"1870.74000000\",\"0.00000000\"],[\"1870.79000000\",\"0.13880000\"],[\"1870.98000000\",\"0.00000000\"],[\"1871.04000000\",\"0.00000000\"],[\"1871.05000000\",\"1.18910000\"],[\"1871.09000000\",\"1.47500000\"]]}}"}
{"mode":"v10-framework-compare","workers":4,"sequenceNumber":363,"symbol":"XRPUSDT","exchangeEventTimeMillis":1784430168474,"localReceivedEpochMillis":1784430168465,"topSpreadTicks":0,"bid5Volume":7790100,"ask5Volume":17461400,"bid10Volume":18069300,"ask10Volume":18667900,"rawPayload":"{\"stream\":\"xrpusdt@depth@100ms\",\"data\":{\"e\":\"depthUpdate\",\"E\":1784430168474,\"s\":\"XRPUSDT\",\"U\":752705534,\"u\":752705534,\"b\":[[\"1.09600000\",\"1347.90000000\"],[\"1.09580000\",\"2640.10000000\"]],\"a\":[]}}"}
{"mode":"v10-framework-compare","workers":4,"sequenceNumber":364,"symbol":"ETHUSDT","exchangeEventTimeMillis":1784430168574,"localReceivedEpochMillis":1784430168563,"topSpreadTicks":-23,"bid5Volume":5118,"ask5Volume":11976,"bid10Volume":8926,"ask10Volume":18676,"rawPayload":"{\"stream\":\"ethusdt@depth@100ms\",\"data\":{\"e\":\"depthUpdate\",\"E\":1784430168574,\"s\":\"ETHUSDT\",\"U\":2806178175,\"u\":2806178178,\"b\":[[\"1870.11000000\",\"0.02970000\"]],\"a\":[[\"1870.61000000\",\"0.02960000\"],[\"1870.63000000\",\"0.66420000\"],[\"1870.77000000\",\"0.00000000\"]]}}"}
{"mode":"v10-framework-compare","workers":4,"sequenceNumber":365,"symbol":"XRPUSDT","exchangeEventTimeMillis":1784430168574,"localReceivedEpochMillis":1784430168564,"topSpreadTicks":1,"bid5Volume":15059000,"ask5Volume":29109400,"bid10Volume":15429200,"ask10Volume":30315900,"rawPayload":"{\"stream\":\"xrpusdt@depth@100ms\",\"data\":{\"e\":\"depthUpdate\",\"E\":1784430168574,\"s\":\"XRPUSDT\",\"U\":752705535,\"u\":752705542,\"b\":[[\"1.09480000\",\"1321.80000000\"],[\"1.09470000\",\"187.30000000\"],[\"1.09420000\",\"18527.50000000\"],[\"1.09400000\",\"15913.30000000\"],[\"1.09350000\",\"13408.90000000\"],[\"1.09330000\",\"0.00000000\"],[\"1.09220000\",\"9117.90000000\"],[\"1.09200000\",\"0.00000000\"]],\"a\":[[\"1.09740000\",\"0.00000000\"],[\"1.09750000\",\"12741.30000000\"],[\"1.09800000\",\"13008.80000000\"],[\"1.09820000\",\"15095.10000000\"],[\"1.09870000\",\"15518.40000000\"],[\"1.09890000\",\"4102.10000000\"],[\"1.10000000\",\"16094.60000000\"],[\"1.10020000\",\"24700.60000000\"]]}}"}
{"mode":"v10-framework-compare","workers":4,"sequenceNumber":366,"symbol":"SOLUSDT","exchangeEventTimeMillis":1784430168774,"localReceivedEpochMillis":1784430168763,"topSpreadTicks":-2,"bid5Volume":185935,"ask5Volume":207620,"bid10Volume":742251,"ask10Volume":782028,"rawPayload":"{\"stream\":\"solusdt@depth@100ms\",\"data\":{\"e\":\"depthUpdate\",\"E\":1784430168774,\"s\":\"SOLUSDT\",\"U\":1609580071,\"u\":1609580072,\"b\":[[\"76.19000000\",\"33.39200000\"],[\"76.18000000\",\"9.97500000\"]],\"a\":[]}}"}
{"mode":"v10-framework-compare","workers":4,"sequenceNumber":367,"symbol":"SOLUSDT","exchangeEventTimeMillis":1784430168874,"localReceivedEpochMillis":1784430168863,"topSpreadTicks":-2,"bid5Volume":186881,"ask5Volume":222085,"bid10Volume":743197,"ask10Volume":782005,"rawPayload":"{\"stream\":\"solusdt@depth@100ms\",\"data\":{\"e\":\"depthUpdate\",\"E\":1784430168874,\"s\":\"SOLUSDT\",\"U\":1609580073,\"u\":1609580076,\"b\":[[\"76.20000000\",\"33.20000000\"]],\"a\":[[\"76.25000000\",\"44.66000000\"],[\"76.26000000\",\"36.19600000\"]]}}"}
{"mode":"v10-framework-compare","workers":4,"sequenceNumber":368,"symbol":"BTCUSDT","exchangeEventTimeMillis":1784430169074,"localReceivedEpochMillis":1784430169064,"topSpreadTicks":-369,"bid5Volume":145,"ask5Volume":103,"bid10Volume":310,"ask10Volume":587,"rawPayload":"{\"stream\":\"btcusdt@depth@100ms\",\"data\":{\"e\":\"depthUpdate\",\"E\":1784430169074,\"s\":\"BTCUSDT\",\"U\":3244441400,\"u\":3244441401,\"b\":[],\"a\":[[\"64914.49000000\",\"0.00011000\"]]}}"}
{"mode":"v10-framework-compare","workers":4,"sequenceNumber":369,"symbol":"XRPUSDT","exchangeEventTimeMillis":1784430169074,"localReceivedEpochMillis":1784430169064,"topSpreadTicks":1,"bid5Volume":15059000,"ask5Volume":28181900,"bid10Volume":15429200,"ask10Volume":29388400,"rawPayload":"{\"stream\":\"xrpusdt@depth@100ms\",\"data\":{\"e\":\"depthUpdate\",\"E\":1784430169074,\"s\":\"XRPUSDT\",\"U\":752705543,\"u\":752705544,\"b\":[],\"a\":[[\"1.09670000\",\"150.00000000\"],[\"1.09680000\",\"3174.60000000\"]]}}"}
{"mode":"v10-framework-compare","workers":4,"sequenceNumber":370,"symbol":"SOLUSDT","exchangeEventTimeMillis":1784430169174,"localReceivedEpochMillis":1784430169163,"topSpreadTicks":-2,"bid5Volume":186881,"ask5Volume":207620,"bid10Volume":743197,"ask10Volume":782155,"rawPayload":"{\"stream\":\"solusdt@depth@100ms\",\"data\":{\"e\":\"depthUpdate\",\"E\":1784430169174,\"s\":\"SOLUSDT\",\"U\":1609580077,\"u\":1609580078,\"b\":[],\"a\":[[\"76.25000000\",\"30.19500000\"],[\"76.26000000\",\"50.81100000\"]]}}"}
{"mode":"v10-framework-compare","workers":4,"sequenceNumber":371,"symbol":"BTCUSDT","exchangeEventTimeMillis":1784430169174,"localReceivedEpochMillis":1784430169163,"topSpreadTicks":-369,"bid5Volume":145,"ask5Volume":103,"bid10Volume":310,"ask10Volume":587,"rawPayload":"{\"stream\":\"btcusdt@depth@100ms\",\"data\":{\"e\":\"depthUpdate\",\"E\":1784430169174,\"s\":\"BTCUSDT\",\"U\":3244441402,\"u\":3244441402,\"b\":[],\"a\":[[\"81055.16000000\",\"0.00030000\"]]}}"}
{"mode":"v10-framework-compare","workers":4,"sequenceNumber":372,"symbol":"SOLUSDT","exchangeEventTimeMillis":1784430169474,"localReceivedEpochMillis":1784430169464,"topSpreadTicks":-2,"bid5Volume":186881,"ask5Volume":221308,"bid10Volume":743197,"ask10Volume":781228,"rawPayload":"{\"stream\":\"solusdt@depth@100ms\",\"data\":{\"e\":\"depthUpdate\",\"E\":1784430169474,\"s\":\"SOLUSDT\",\"U\":1609580079,\"u\":1609580080,\"b\":[],\"a\":[[\"76.25000000\",\"43.88300000\"],[\"76.26000000\",\"36.19600000\"]]}}"}
{"mode":"v10-framework-compare","workers":4,"sequenceNumber":373,"symbol":"SOLUSDT","exchangeEventTimeMillis":1784430169574,"localReceivedEpochMillis":1784430169562,"topSpreadTicks":-2,"bid5Volume":186484,"ask5Volume":222446,"bid10Volume":742800,"ask10Volume":782366,"rawPayload":"{\"stream\":\"solusdt@depth@100ms\",\"data\":{\"e\":\"depthUpdate\",\"E\":1784430169574,\"s\":\"SOLUSDT\",\"U\":1609580081,\"u\":1609580090,\"b\":[[\"76.20000000\",\"18.63100000\"],[\"76.19000000\",\"14.72600000\"],[\"76.18000000\",\"42.81300000\"]],\"a\":[[\"76.21000000\",\"39.39200000\"],[\"76.22000000\",\"63.32700000\"],[\"76.23000000\",\"23.54100000\"],[\"76.24000000\",\"65.99100000\"],[\"76.25000000\",\"30.19500000\"]]}}"}
{"mode":"v10-framework-compare","workers":4,"sequenceNumber":374,"symbol":"ETHUSDT","exchangeEventTimeMillis":1784430169574,"localReceivedEpochMillis":1784430169563,"topSpreadTicks":-23,"bid5Volume":5071,"ask5Volume":3807,"bid10Volume":10376,"ask10Volume":17287,"rawPayload":"{\"stream\":\"ethusdt@depth@100ms\",\"data\":{\"e\":\"depthUpdate\",\"E\":1784430169574,\"s\":\"ETHUSDT\",\"U\":2806178179,\"u\":2806178192,\"b\":[[\"1870.48000000\",\"0.00000000\"],[\"1870.40000000\",\"1.12250000\"],[\"1870.30000000\",\"0.00000000\"],[\"1870.12000000\",\"0.13900000\"],[\"1870.09000000\",\"1.33770000\"],[\"1870.08000000\",\"0.00000000\"],[\"1869.99000000\",\"0.00000000\"],[\"1869.93000000\",\"0.00000000\"],[\"1869.88000000\",\"2.32510000\"]],\"a\":[[\"1870.73000000\",\"1.33730000\"],[\"1870.87000000\",\"1.63970000\"],[\"1870.97000000\",\"1.13630000\"],[\"1871.05000000\",\"0.00000000\"],[\"1872.01000000\",\"0.00000000\"]]}}"}
{"mode":"v10-framework-compare","workers":4,"sequenceNumber":375,"symbol":"BTCUSDT","exchangeEventTimeMillis":1784430169574,"localReceivedEpochMillis":1784430169563,"topSpreadTicks":-369,"bid5Volume":147,"ask5Volume":103,"bid10Volume":312,"ask10Volume":587,"rawPayload":"{\"stream\":\"btcusdt@depth@100ms\",\"data\":{\"e\":\"depthUpdate\",\"E\":1784430169574,\"s\":\"BTCUSDT\",\"U\":3244441403,\"u\":3244441404,\"b\":[[\"64790.08000000\",\"0.00000000\"],[\"64788.30000000\",\"0.02007000\"]],\"a\":[]}}"}
{"mode":"v10-framework-compare","workers":4,"sequenceNumber":376,"symbol":"SOLUSDT","exchangeEventTimeMillis":1784430169674,"localReceivedEpochMillis":1784430169664,"topSpreadTicks":-2,"bid5Volume":185927,"ask5Volume":221891,"bid10Volume":460781,"ask10Volume":1056636,"rawPayload":"{\"stream\":\"solusdt@depth@100ms\",\"data\":{\"e\":\"depthUpdate\",\"E\":1784430169674,\"s\":\"SOLUSDT\",\"U\":1609580091,\"u\":1609580101,\"b\":[[\"76.19000000\",\"14.16900000\"],[\"76.16000000\",\"68.40400000\"],[\"76.15000000\",\"13.13200000\"],[\"76.12000000\",\"84.58400000\"],[\"76.11000000\",\"99.19600000\"],[\"76.08000000\",\"9.50800000\"],[\"76.07000000\",\"420.59600000\"],[\"76.06000000\",\"271.95800000\"],[\"76.03000000\",\"526.21500000\"],[\"76.02000000\",\"332.59800000\"]],\"a\":[[\"76.22000000\",\"62.77200000\"],[\"76.30000000\",\"0.00000000\"],[\"76.31000000\",\"118.36500000\"],[\"76.32000000\",\"274.82500000\"],[\"76.48000000\",\"0.00000000\"]]}}"}
{"mode":"v10-framework-compare","workers":4,"sequenceNumber":377,"symbol":"SOLUSDT","exchangeEventTimeMillis":1784430169774,"localReceivedEpochMillis":1784430169765,"topSpreadTicks":-2,"bid5Volume":185927,"ask5Volume":221891,"bid10Volume":460781,"ask10Volume":1056636,"rawPayload":"{\"stream\":\"solusdt@depth@100ms\",\"data\":{\"e\":\"depthUpdate\",\"E\":1784430169774,\"s\":\"SOLUSDT\",\"U\":1609580102,\"u\":1609580102,\"b\":[[\"75.87000000\",\"336.80600000\"]],\"a\":[]}}"}
{"mode":"v10-framework-compare","workers":4,"sequenceNumber":378,"symbol":"SOLUSDT","exchangeEventTimeMillis":1784430170075,"localReceivedEpochMillis":1784430170064,"topSpreadTicks":-2,"bid5Volume":186943,"ask5Volume":222448,"bid10Volume":461797,"ask10Volume":1057193,"rawPayload":"{\"stream\":\"solusdt@depth@100ms\",\"data\":{\"e\":\"depthUpdate\",\"E\":1784430170075,\"s\":\"SOLUSDT\",\"U\":1609580103,\"u\":1609580108,\"b\":[[\"76.20000000\",\"18.63100000\"],[\"76.19000000\",\"14.62700000\"],[\"76.18000000\",\"43.37100000\"]],\"a\":[[\"76.21000000\",\"39.94900000\"]]}}"}
{"mode":"v10-framework-compare","workers":4,"sequenceNumber":379,"symbol":"XRPUSDT","exchangeEventTimeMillis":1784430170075,"localReceivedEpochMillis":1784430170064,"topSpreadTicks":1,"bid5Volume":15059000,"ask5Volume":30382300,"bid10Volume":15429200,"ask10Volume":31588800,"rawPayload":"{\"stream\":\"xrpusdt@depth@100ms\",\"data\":{\"e\":\"depthUpdate\",\"E\":1784430170075,\"s\":\"XRPUSDT\",\"U\":752705545,\"u\":752705546,\"b\":[[\"1.09610000\",\"4690.40000000\"],[\"1.09600000\",\"0.00000000\"]],\"a\":[[\"1.09640000\",\"45.30000000\"],[\"1.09650000\",\"5375.00000000\"]]}}"}
{"mode":"v10-framework-compare","workers":4,"sequenceNumber":380,"symbol":"SOLUSDT","exchangeEventTimeMillis":1784430170175,"localReceivedEpochMillis":1784430170164,"topSpreadTicks":-2,"bid5Volume":218510,"ask5Volume":222866,"bid10Volume":470715,"ask10Volume":1057611,"rawPayload":"{\"stream\":\"solusdt@depth@100ms\",\"data\":{\"e\":\"depthUpdate\",\"E\":1784430170175,\"s\":\"SOLUSDT\",\"U\":1609580109,\"u\":1609580114,\"b\":[[\"76.20000000\",\"32.66000000\"],[\"76.19000000\",\"0.00000000\"],[\"76.16000000\",\"32.16500000\"],[\"76.15000000\",\"49.37300000\"],[\"76.11000000\",\"0.00000000\"],[\"76.10000000\",\"99.20200000\"]],\"a\":[[\"76.24000000\",\"52.11300000\"],[\"76.25000000\",\"44.49100000\"]]}}"}
{"mode":"v10-framework-compare","workers":4,"sequenceNumber":381,"symbol":"ETHUSDT","exchangeEventTimeMillis":1784430170175,"localReceivedEpochMillis":1784430170164,"topSpreadTicks":-23,"bid5Volume":5071,"ask5Volume":3807,"bid10Volume":8901,"ask10Volume":17287,"rawPayload":"{\"stream\":\"ethusdt@depth@100ms\",\"data\":{\"e\":\"depthUpdate\",\"E\":1784430170175,\"s\":\"ETHUSDT\",\"U\":2806178193,\"u\":2806178196,\"b\":[[\"1869.88000000\",\"1.63970000\"],[\"1869.83000000\",\"0.68610000\"],[\"1869.68000000\",\"0.00000000\"],[\"1869.48000000\",\"1.02920000\"]],\"a\":[]}}"}
{"mode":"v10-framework-compare","workers":4,"sequenceNumber":382,"symbol":"XRPUSDT","exchangeEventTimeMillis":1784430170175,"localReceivedEpochMillis":1784430170164,"topSpreadTicks":1,"bid5Volume":15059000,"ask5Volume":25501300,"bid10Volume":15429200,"ask10Volume":26707800,"rawPayload":"{\"stream\":\"xrpusdt@depth@100ms\",\"data\":{\"e\":\"depthUpdate\",\"E\":1784430170175,\"s\":\"XRPUSDT\",\"U\":752705547,\"u\":752705548,\"b\":[],\"a\":[[\"1.09650000\",\"5502.40000000\"],[\"1.09660000\",\"494.00000000\"]]}}"}
{"mode":"v10-framework-compare","workers":4,"sequenceNumber":383,"symbol":"ETHUSDT","exchangeEventTimeMillis":1784430170575,"localReceivedEpochMillis":1784430170565,"topSpreadTicks":-23,"bid5Volume":5071,"ask5Volume":3807,"bid10Volume":8901,"ask10Volume":17287,"rawPayload":"{\"stream\":\"ethusdt@depth@100ms\",\"data\":{\"e\":\"depthUpdate\",\"E\":1784430170575,\"s\":\"ETHUSDT\",\"U\":2806178197,\"u\":2806178197,\"b\":[],\"a\":[[\"1871.20000000\",\"1.06180000\"],[\"1871.25000000\",\"0.00000000\"]]}}"}
{"mode":"v10-framework-compare","workers":4,"sequenceNumber":384,"symbol":"SOLUSDT","exchangeEventTimeMillis":1784430170875,"localReceivedEpochMillis":1784430170863,"topSpreadTicks":-2,"bid5Volume":204481,"ask5Volume":221420,"bid10Volume":456686,"ask10Volume":1056165,"rawPayload":"{\"stream\":\"solusdt@depth@100ms\",\"data\":{\"e\":\"depthUpdate\",\"E\":1784430170875,\"s\":\"SOLUSDT\",\"U\":1609580115,\"u\":1609580118,\"b\":[[\"76.20000000\",\"18.63100000\"]],\"a\":[[\"76.21000000\",\"39.39200000\"],[\"76.24000000\",\"65.52000000\"],[\"76.25000000\",\"30.19500000\"]]}}"}
{"mode":"v10-framework-compare","workers":4,"sequenceNumber":385,"symbol":"SOLUSDT","exchangeEventTimeMillis":1784430170975,"localReceivedEpochMillis":1784430170964,"topSpreadTicks":-2,"bid5Volume":185963,"ask5Volume":221973,"bid10Volume":460825,"ask10Volume":1056718,"rawPayload":"{\"stream\":\"solusdt@depth@100ms\",\"data\":{\"e\":\"depthUpdate\",\"E\":1784430170975,\"s\":\"SOLUSDT\",\"U\":1609580119,\"u\":1609580120,\"b\":[[\"76.19000000\",\"13.64700000\"]],\"a\":[[\"76.21000000\",\"39.94500000\"]]}}"}
{"mode":"v10-framework-compare","workers":4,"sequenceNumber":386,"symbol":"SOLUSDT","exchangeEventTimeMillis":1784430171276,"localReceivedEpochMillis":1784430171265,"topSpreadTicks":-2,"bid5Volume":218386,"ask5Volume":222602,"bid10Volume":470591,"ask10Volume":1057347,"rawPayload":"{\"stream\":\"solusdt@depth@100ms\",\"data\":{\"e\":\"depthUpdate\",\"E\":1784430171276,\"s\":\"SOLUSDT\",\"U\":1609580121,\"u\":1609580124,\"b\":[[\"76.20000000\",\"32.53600000\"],[\"76.19000000\",\"0.00000000\"]],\"a\":[[\"76.24000000\",\"52.11300000\"],[\"76.25000000\",\"44.23100000\"]]}}"}
{"mode":"v10-framework-compare","workers":4,"sequenceNumber":387,"symbol":"SOLUSDT","exchangeEventTimeMillis":1784430171576,"localReceivedEpochMillis":1784430171565,"topSpreadTicks":-2,"bid5Volume":186224,"ask5Volume":258800,"bid10Volume":461086,"ask10Volume":1329052,"rawPayload":"{\"stream\":\"solusdt@depth@100ms\",\"data\":{\"e\":\"depthUpdate\",\"E\":1784430171576,\"s\":\"SOLUSDT\",\"U\":1609580125,\"u\":1609580129,\"b\":[[\"76.20000000\",\"13.90500000\"],[\"76.19000000\",\"18.63100000\"],[\"76.18000000\",\"39.96100000\"],[\"76.17000000\",\"99.12300000\"]],\"a\":[[\"76.22000000\",\"66.18300000\"],[\"76.23000000\",\"38.76500000\"],[\"76.24000000\",\"33.47800000\"],[\"76.25000000\",\"80.42900000\"],[\"76.26000000\",\"0.00000000\"]]}}"}
{"mode":"v10-framework-compare","workers":4,"sequenceNumber":388,"symbol":"BNBUSDT","exchangeEventTimeMillis":1784430171676,"localReceivedEpochMillis":1784430171666,"topSpreadTicks":4,"bid5Volume":5152,"ask5Volume":6689,"bid10Volume":20035,"ask10Volume":257415,"rawPayload":"{\"stream\":\"bnbusdt@depth@100ms\",\"data\":{\"e\":\"depthUpdate\",\"E\":1784430171676,\"s\":\"BNBUSDT\",\"U\":1236331377,\"u\":1236331379,\"b\":[[\"568.81000000\",\"20.05600000\"],[\"568.80000000\",\"0.00000000\"]],\"a\":[[\"571.55000000\",\"0.00000000\"],[\"571.56000000\",\"5.04300000\"],[\"571.89000000\",\"0.00000000\"],[\"571.90000000\",\"8.30100000\"]]}}"}
{"mode":"v10-framework-compare","workers":4,"sequenceNumber":389,"symbol":"SOLUSDT","exchangeEventTimeMillis":1784430171776,"localReceivedEpochMillis":1784430171765,"topSpreadTicks":-2,"bid5Volume":186224,"ask5Volume":258247,"bid10Volume":461086,"ask10Volume":1328499,"rawPayload":"{\"stream\":\"solusdt@depth@100ms\",\"data\":{\"e\":\"depthUpdate\",\"E\":1784430171776,\"s\":\"SOLUSDT\",\"U\":1609580130,\"u\":1609580130,\"b\":[],\"a\":[[\"76.21000000\",\"39.39200000\"]]}}"}
{"mode":"v10-framework-compare","workers":4,"sequenceNumber":390,"symbol":"ETHUSDT","exchangeEventTimeMillis":1784430171776,"localReceivedEpochMillis":1784430171765,"topSpreadTicks":-23,"bid5Volume":5071,"ask5Volume":3807,"bid10Volume":8901,"ask10Volume":17287,"rawPayload":"{\"stream\":\"ethusdt@depth@100ms\",\"data\":{\"e\":\"depthUpdate\",\"E\":1784430171776,\"s\":\"ETHUSDT\",\"U\":2806178198,\"u\":2806178199,\"b\":[[\"1870.23000000\",\"1.33760000\"],[\"1870.09000000\",\"0.00000000\"]],\"a\":[]}}"}
{"mode":"v10-framework-compare","workers":4,"sequenceNumber":391,"symbol":"BTCUSDT","exchangeEventTimeMillis":1784430171876,"localReceivedEpochMillis":1784430171865,"topSpreadTicks":-369,"bid5Volume":147,"ask5Volume":103,"bid10Volume":312,"ask10Volume":587,"rawPayload":"{\"stream\":\"btcusdt@depth@100ms\",\"data\":{\"e\":\"depthUpdate\",\"E\":1784430171876,\"s\":\"BTCUSDT\",\"U\":3244441405,\"u\":3244441405,\"b\":[],\"a\":[[\"81055.16000000\",\"0.00045000\"]]}}"}
{"mode":"v10-framework-compare","workers":4,"sequenceNumber":392,"symbol":"BTCUSDT","exchangeEventTimeMillis":1784430172076,"localReceivedEpochMillis":1784430172065,"topSpreadTicks":-369,"bid5Volume":198,"ask5Volume":103,"bid10Volume":363,"ask10Volume":587,"rawPayload":"{\"stream\":\"btcusdt@depth@100ms\",\"data\":{\"e\":\"depthUpdate\",\"E\":1784430172076,\"s\":\"BTCUSDT\",\"U\":3244441406,\"u\":3244441407,\"b\":[[\"64788.30000000\",\"0.00000000\"],[\"64784.01000000\",\"0.02800000\"],[\"64783.89000000\",\"0.00000000\"]],\"a\":[]}}"}
{"mode":"v10-framework-compare","workers":4,"sequenceNumber":393,"symbol":"BTCUSDT","exchangeEventTimeMillis":1784430172176,"localReceivedEpochMillis":1784430172165,"topSpreadTicks":-369,"bid5Volume":148,"ask5Volume":103,"bid10Volume":313,"ask10Volume":587,"rawPayload":"{\"stream\":\"btcusdt@depth@100ms\",\"data\":{\"e\":\"depthUpdate\",\"E\":1784430172176,\"s\":\"BTCUSDT\",\"U\":3244441408,\"u\":3244441408,\"b\":[[\"64786.59000000\",\"0.02160000\"]],\"a\":[]}}"}
{"mode":"v10-framework-compare","workers":4,"sequenceNumber":394,"symbol":"XRPUSDT","exchangeEventTimeMillis":1784430172176,"localReceivedEpochMillis":1784430172166,"topSpreadTicks":1,"bid5Volume":15059000,"ask5Volume":25634800,"bid10Volume":15429200,"ask10Volume":26841300,"rawPayload":"{\"stream\":\"xrpusdt@depth@100ms\",\"data\":{\"e\":\"depthUpdate\",\"E\":1784430172176,\"s\":\"XRPUSDT\",\"U\":752705549,\"u\":752705550,\"b\":[],\"a\":[[\"1.09650000\",\"5375.00000000\"],[\"1.09660000\",\"627.50000000\"]]}}"}
{"mode":"v10-framework-compare","workers":4,"sequenceNumber":395,"symbol":"SOLUSDT","exchangeEventTimeMillis":1784430172476,"localReceivedEpochMillis":1784430172466,"topSpreadTicks":-2,"bid5Volume":218834,"ask5Volume":258597,"bid10Volume":471039,"ask10Volume":1328849,"rawPayload":"{\"stream\":\"solusdt@depth@100ms\",\"data\":{\"e\":\"depthUpdate\",\"E\":1784430172476,\"s\":\"SOLUSDT\",\"U\":1609580131,\"u\":1609580135,\"b\":[[\"76.20000000\",\"0.00000000\"],[\"76.19000000\",\"32.98100000\"]],\"a\":[[\"76.21000000\",\"39.94700000\"],[\"76.24000000\",\"47.30900000\"],[\"76.25000000\",\"66.39300000\"]]}}"}
{"mode":"v10-framework-compare","workers":4,"sequenceNumber":396,"symbol":"SOLUSDT","exchangeEventTimeMillis":1784430172676,"localReceivedEpochMillis":1784430172666,"topSpreadTicks":-3,"bid5Volume":218834,"ask5Volume":192205,"bid10Volume":471039,"ask10Volume":1057147,"rawPayload":"{\"stream\":\"solusdt@depth@100ms\",\"data\":{\"e\":\"depthUpdate\",\"E\":1784430172676,\"s\":\"SOLUSDT\",\"U\":1609580136,\"u\":1609580137,\"b\":[],\"a\":[[\"76.20000000\",\"6.56600000\"],[\"76.21000000\",\"33.38200000\"]]}}"}
{"mode":"v10-framework-compare","workers":4,"sequenceNumber":397,"symbol":"BTCUSDT","exchangeEventTimeMillis":1784430172877,"localReceivedEpochMillis":1784430172867,"topSpreadTicks":-369,"bid5Volume":148,"ask5Volume":103,"bid10Volume":313,"ask10Volume":587,"rawPayload":"{\"stream\":\"btcusdt@depth@100ms\",\"data\":{\"e\":\"depthUpdate\",\"E\":1784430172877,\"s\":\"BTCUSDT\",\"U\":3244441409,\"u\":3244441409,\"b\":[],\"a\":[[\"64914.49000000\",\"0.00000000\"]]}}"}
{"mode":"v10-framework-compare","workers":4,"sequenceNumber":398,"symbol":"BTCUSDT","exchangeEventTimeMillis":1784430172977,"localReceivedEpochMillis":1784430172965,"topSpreadTicks":-369,"bid5Volume":198,"ask5Volume":103,"bid10Volume":363,"ask10Volume":587,"rawPayload":"{\"stream\":\"btcusdt@depth@100ms\",\"data\":{\"e\":\"depthUpdate\",\"E\":1784430172977,\"s\":\"BTCUSDT\",\"U\":3244441410,\"u\":3244441414,\"b\":[[\"64788.28000000\",\"0.00000000\"],[\"64786.59000000\",\"0.00000000\"]],\"a\":[[\"64914.49000000\",\"0.00011000\"],[\"81055.16000000\",\"0.00030000\"]]}}"}
{"mode":"v10-framework-compare","workers":4,"sequenceNumber":399,"symbol":"SOLUSDT","exchangeEventTimeMillis":1784430173077,"localReceivedEpochMillis":1784430173066,"topSpreadTicks":-3,"bid5Volume":212269,"ask5Volume":178374,"bid10Volume":464474,"ask10Volume":1057916,"rawPayload":"{\"stream\":\"solusdt@depth@100ms\",\"data\":{\"e\":\"depthUpdate\",\"E\":1784430173077,\"s\":\"SOLUSDT\",\"U\":1609580138,\"u\":1609580140,\"b\":[[\"76.18000000\",\"33.39600000\"]],\"a\":[[\"76.24000000\",\"33.47800000\"],[\"76.25000000\",\"80.99300000\"]]}}"}
{"mode":"v10-framework-compare","workers":4,"sequenceNumber":400,"symbol":"BTCUSDT","exchangeEventTimeMillis":1784430173077,"localReceivedEpochMillis":1784430173066,"topSpreadTicks":-369,"bid5Volume":149,"ask5Volume":103,"bid10Volume":314,"ask10Volume":587,"rawPayload":"{\"stream\":\"btcusdt@depth@100ms\",\"data\":{\"e\":\"depthUpdate\",\"E\":1784430173077,\"s\":\"BTCUSDT\",\"U\":3244441415,\"u\":3244441423,\"b\":[[\"64786.94000000\",\"0.02221000\"],[\"64736.13000000\",\"0.05967000\"],[\"64736.04000000\",\"0.00000000\"],[\"64697.24000000\",\"0.08541000\"],[\"64697.15000000\",\"0.00000000\"],[\"64658.35000000\",\"0.18203000\"],[\"64658.26000000\",\"0.00000000\"],[\"64580.58000000\",\"0.40748000\"],[\"64580.49000000\",\"0.00000000\"]],\"a\":[[\"64891.54000000\",\"0.00000000\"],[\"64891.63000000\",\"0.06099000\"],[\"64930.43000000\",\"0.00000000\"],[\"64930.52000000\",\"0.08452000\"],[\"64969.32000000\",\"0.00000000\"],[\"64969.41000000\",\"0.18519000\"],[\"65047.09000000\",\"0.00000000\"],[\"65047.19000000\",\"0.40282000\"]]}}"}
{"mode":"v10-framework-compare","workers":4,"sequenceNumber":401,"symbol":"SOLUSDT","exchangeEventTimeMillis":1784430173177,"localReceivedEpochMillis":1784430173165,"topSpreadTicks":-3,"bid5Volume":218835,"ask5Volume":178374,"bid10Volume":471040,"ask10Volume":1057916,"rawPayload":"{\"stream\":\"solusdt@depth@100ms\",\"data\":{\"e\":\"depthUpdate\",\"E\":1784430173177,\"s\":\"SOLUSDT\",\"U\":1609580141,\"u\":1609580141,\"b\":[[\"76.17000000\",\"105.68900000\"]],\"a\":[]}}"}
{"mode":"v10-framework-compare","workers":4,"sequenceNumber":402,"symbol":"XRPUSDT","exchangeEventTimeMillis":1784430173177,"localReceivedEpochMillis":1784430173166,"topSpreadTicks":1,"bid5Volume":15059000,"ask5Volume":29138300,"bid10Volume":15429200,"ask10Volume":30344800,"rawPayload":"{\"stream\":\"xrpusdt@depth@100ms\",\"data\":{\"e\":\"depthUpdate\",\"E\":1784430173177,\"s\":\"XRPUSDT\",\"U\":752705551,\"u\":752705551,\"b\":[],\"a\":[[\"1.09640000\",\"1289.30000000\"],[\"1.09650000\",\"4131.00000000\"]]}}"}
{"mode":"v10-framework-compare","workers":4,"sequenceNumber":403,"symbol":"ETHUSDT","exchangeEventTimeMillis":1784430173777,"localReceivedEpochMillis":1784430173766,"topSpreadTicks":-23,"bid5Volume":5071,"ask5Volume":3807,"bid10Volume":8901,"ask10Volume":17287,"rawPayload":"{\"stream\":\"ethusdt@depth@100ms\",\"data\":{\"e\":\"depthUpdate\",\"E\":1784430173777,\"s\":\"ETHUSDT\",\"U\":2806178200,\"u\":2806178200,\"b\":[],\"a\":[[\"1871.15000000\",\"1.06180000\"],[\"1871.20000000\",\"0.00000000\"]]}}"}
{"mode":"v10-framework-compare","workers":4,"sequenceNumber":404,"symbol":"SOLUSDT","exchangeEventTimeMillis":1784430174077,"localReceivedEpochMillis":1784430174065,"topSpreadTicks":-3,"bid5Volume":218835,"ask5Volume":192698,"bid10Volume":471040,"ask10Volume":1057640,"rawPayload":"{\"stream\":\"solusdt@depth@100ms\",\"data\":{\"e\":\"depthUpdate\",\"E\":1784430174077,\"s\":\"SOLUSDT\",\"U\":1609580142,\"u\":1609580143,\"b\":[],\"a\":[[\"76.24000000\",\"47.80200000\"],[\"76.25000000\",\"66.39300000\"]]}}"}
{"mode":"v10-framework-compare","workers":4,"sequenceNumber":405,"symbol":"ETHUSDT","exchangeEventTimeMillis":1784430174077,"localReceivedEpochMillis":1784430174066,"topSpreadTicks":-23,"bid5Volume":5071,"ask5Volume":3807,"bid10Volume":8985,"ask10Volume":17287,"rawPayload":"{\"stream\":\"ethusdt@depth@100ms\",\"data\":{\"e\":\"depthUpdate\",\"E\":1784430174077,\"s\":\"ETHUSDT\",\"U\":2806178201,\"u\":2806178204,\"b\":[[\"1869.95000000\",\"0.77090000\"],[\"1869.93000000\",\"0.00000000\"],[\"1869.83000000\",\"0.00000000\"]],\"a\":[]}}"}
{"mode":"v10-framework-compare","workers":4,"sequenceNumber":406,"symbol":"SOLUSDT","exchangeEventTimeMillis":1784430174277,"localReceivedEpochMillis":1784430174266,"topSpreadTicks":-3,"bid5Volume":218835,"ask5Volume":178374,"bid10Volume":471040,"ask10Volume":1056948,"rawPayload":"{\"stream\":\"solusdt@depth@100ms\",\"data\":{\"e\":\"depthUpdate\",\"E\":1784430174277,\"s\":\"SOLUSDT\",\"U\":1609580144,\"u\":1609580145,\"b\":[],\"a\":[[\"76.24000000\",\"33.47800000\"],[\"76.25000000\",\"80.02500000\"]]}}"}
{"mode":"v10-framework-compare","workers":4,"sequenceNumber":407,"symbol":"BTCUSDT","exchangeEventTimeMillis":1784430174378,"localReceivedEpochMillis":1784430174366,"topSpreadTicks":-369,"bid5Volume":149,"ask5Volume":103,"bid10Volume":314,"ask10Volume":587,"rawPayload":"{\"stream\":\"btcusdt@depth@100ms\",\"data\":{\"e\":\"depthUpdate\",\"E\":1784430174378,\"s\":\"BTCUSDT\",\"U\":3244441424,\"u\":3244441424,\"b\":[],\"a\":[[\"81055.16000000\",\"0.00045000\"]]}}"}
{"mode":"v10-framework-compare","workers":4,"sequenceNumber":408,"symbol":"SOLUSDT","exchangeEventTimeMillis":1784430174678,"localReceivedEpochMillis":1784430174668,"topSpreadTicks":-3,"bid5Volume":218835,"ask5Volume":193028,"bid10Volume":471040,"ask10Volume":1057970,"rawPayload":"{\"stream\":\"solusdt@depth@100ms\",\"data\":{\"e\":\"depthUpdate\",\"E\":1784430174678,\"s\":\"SOLUSDT\",\"U\":1609580146,\"u\":1609580147,\"b\":[],\"a\":[[\"76.24000000\",\"48.13200000\"],[\"76.25000000\",\"66.39300000\"]]}}"}
{"mode":"v10-framework-compare","workers":4,"sequenceNumber":409,"symbol":"ETHUSDT","exchangeEventTimeMillis":1784430174778,"localReceivedEpochMillis":1784430174767,"topSpreadTicks":-23,"bid5Volume":5071,"ask5Volume":3807,"bid10Volume":8985,"ask10Volume":17287,"rawPayload":"{\"stream\":\"ethusdt@depth@100ms\",\"data\":{\"e\":\"depthUpdate\",\"E\":1784430174778,\"s\":\"ETHUSDT\",\"U\":2806178205,\"u\":2806178210,\"b\":[[\"1868.49000000\",\"2.00910000\"],[\"1868.45000000\",\"0.00000000\"],[\"1867.36000000\",\"3.06430000\"],[\"1867.33000000\",\"0.00000000\"],[\"1866.24000000\",\"6.29250000\"],[\"1866.21000000\",\"0.00000000\"],[\"1864.00000000\",\"13.86920000\"],[\"1863.96000000\",\"0.00000000\"]],\"a\":[[\"1872.95000000\",\"0.00000000\"],[\"1872.98000000\",\"1.97600000\"],[\"1875.20000000\",\"0.00000000\"],[\"1875.23000000\",\"6.19570000\"]]}}"}
{"mode":"v10-framework-compare","workers":4,"sequenceNumber":410,"symbol":"BNBUSDT","exchangeEventTimeMillis":1784430175078,"localReceivedEpochMillis":1784430175068,"topSpreadTicks":4,"bid5Volume":5152,"ask5Volume":6689,"bid10Volume":20035,"ask10Volume":257415,"rawPayload":"{\"stream\":\"bnbusdt@depth@100ms\",\"data\":{\"e\":\"depthUpdate\",\"E\":1784430175078,\"s\":\"BNBUSDT\",\"U\":1236331380,\"u\":1236331381,\"b\":[],\"a\":[[\"570.61000000\",\"0.87600000\"],[\"570.63000000\",\"0.00000000\"]]}}"}
{"mode":"v10-framework-compare","workers":4,"sequenceNumber":411,"symbol":"BTCUSDT","exchangeEventTimeMillis":1784430175078,"localReceivedEpochMillis":1784430175068,"topSpreadTicks":-369,"bid5Volume":149,"ask5Volume":103,"bid10Volume":314,"ask10Volume":589,"rawPayload":"{\"stream\":\"btcusdt@depth@100ms\",\"data\":{\"e\":\"depthUpdate\",\"E\":1784430175078,\"s\":\"BTCUSDT\",\"U\":3244441425,\"u\":3244441430,\"b\":[[\"64793.26000000\",\"0.00000000\"],[\"64790.84000000\",\"0.03390000\"]],\"a\":[[\"64808.06000000\",\"0.00170000\"],[\"64809.10000000\",\"0.00000000\"],[\"64810.31000000\",\"0.03342000\"],[\"64812.73000000\",\"0.00000000\"]]}}"}
{"mode":"v10-framework-compare","workers":4,"sequenceNumber":412,"symbol":"ETHUSDT","exchangeEventTimeMillis":1784430175078,"localReceivedEpochMillis":1784430175068,"topSpreadTicks":-23,"bid5Volume":5071,"ask5Volume":3807,"bid10Volume":10482,"ask10Volume":17287,"rawPayload":"{\"stream\":\"ethusdt@depth@100ms\",\"data\":{\"e\":\"depthUpdate\",\"E\":1784430175078,\"s\":\"ETHUSDT\",\"U\":2806178211,\"u\":2806178212,\"b\":[[\"1869.95000000\",\"0.00000000\"],[\"1869.88000000\",\"2.43120000\"]],\"a\":[]}}"}
{"mode":"v10-framework-compare","workers":4,"sequenceNumber":413,"symbol":"BTCUSDT","exchangeEventTimeMillis":1784430175178,"localReceivedEpochMillis":1784430175168,"topSpreadTicks":-450,"bid5Volume":149,"ask5Volume":103,"bid10Volume":314,"ask10Volume":589,"rawPayload":"{\"stream\":\"btcusdt@depth@100ms\",\"data\":{\"e\":\"depthUpdate\",\"E\":1784430175178,\"s\":\"BTCUSDT\",\"U\":3244441431,\"u\":3244441431,\"b\":[],\"a\":[[\"64798.45000000\",\"0.00401000\"],[\"64799.26000000\",\"0.00000000\"]]}}"}
{"mode":"v10-framework-compare","workers":4,"sequenceNumber":414,"symbol":"BTCUSDT","exchangeEventTimeMillis":1784430175678,"localReceivedEpochMillis":1784430175668,"topSpreadTicks":-450,"bid5Volume":149,"ask5Volume":103,"bid10Volume":314,"ask10Volume":589,"rawPayload":"{\"stream\":\"btcusdt@depth@100ms\",\"data\":{\"e\":\"depthUpdate\",\"E\":1784430175678,\"s\":\"BTCUSDT\",\"U\":3244441432,\"u\":3244441432,\"b\":[[\"64678.27000000\",\"0.00000000\"]],\"a\":[]}}"}
{"mode":"v10-framework-compare","workers":4,"sequenceNumber":415,"symbol":"BTCUSDT","exchangeEventTimeMillis":1784430175879,"localReceivedEpochMillis":1784430175868,"topSpreadTicks":-450,"bid5Volume":149,"ask5Volume":103,"bid10Volume":314,"ask10Volume":589,"rawPayload":"{\"stream\":\"btcusdt@depth@100ms\",\"data\":{\"e\":\"depthUpdate\",\"E\":1784430175879,\"s\":\"BTCUSDT\",\"U\":3244441433,\"u\":3244441433,\"b\":[[\"64665.05000000\",\"0.00020000\"]],\"a\":[]}}"}
{"mode":"v10-framework-compare","workers":4,"sequenceNumber":416,"symbol":"BNBUSDT","exchangeEventTimeMillis":1784430176079,"localReceivedEpochMillis":1784430176068,"topSpreadTicks":4,"bid5Volume":5152,"ask5Volume":6689,"bid10Volume":20035,"ask10Volume":257415,"rawPayload":"{\"stream\":\"bnbusdt@depth@100ms\",\"data\":{\"e\":\"depthUpdate\",\"E\":1784430176079,\"s\":\"BNBUSDT\",\"U\":1236331382,\"u\":1236331383,\"b\":[],\"a\":[[\"570.61000000\",\"0.00000000\"],[\"570.63000000\",\"0.87600000\"]]}}"}
{"mode":"v10-framework-compare","workers":4,"sequenceNumber":417,"symbol":"XRPUSDT","exchangeEventTimeMillis":1784430176079,"localReceivedEpochMillis":1784430176068,"topSpreadTicks":1,"bid5Volume":15059000,"ask5Volume":25501300,"bid10Volume":15429200,"ask10Volume":26707800,"rawPayload":"{\"stream\":\"xrpusdt@depth@100ms\",\"data\":{\"e\":\"depthUpdate\",\"E\":1784430176079,\"s\":\"XRPUSDT\",\"U\":752705552,\"u\":752705553,\"b\":[],\"a\":[[\"1.09650000\",\"4282.30000000\"],[\"1.09660000\",\"494.00000000\"]]}}"}
{"mode":"v10-framework-compare","workers":4,"sequenceNumber":418,"symbol":"SOLUSDT","exchangeEventTimeMillis":1784430176279,"localReceivedEpochMillis":1784430176269,"topSpreadTicks":-3,"bid5Volume":218835,"ask5Volume":178374,"bid10Volume":471040,"ask10Volume":1056898,"rawPayload":"{\"stream\":\"solusdt@depth@100ms\",\"data\":{\"e\":\"depthUpdate\",\"E\":1784430176279,\"s\":\"SOLUSDT\",\"U\":1609580148,\"u\":1609580149,\"b\":[],\"a\":[[\"76.24000000\",\"33.47800000\"],[\"76.25000000\",\"79.97500000\"]]}}"}
{"mode":"v10-framework-compare","workers":4,"sequenceNumber":419,"symbol":"SOLUSDT","exchangeEventTimeMillis":1784430176379,"localReceivedEpochMillis":1784430176368,"topSpreadTicks":-3,"bid5Volume":218835,"ask5Volume":192714,"bid10Volume":471040,"ask10Volume":1057656,"rawPayload":"{\"stream\":\"solusdt@depth@100ms\",\"data\":{\"e\":\"depthUpdate\",\"E\":1784430176379,\"s\":\"SOLUSDT\",\"U\":1609580150,\"u\":1609580151,\"b\":[],\"a\":[[\"76.24000000\",\"47.81800000\"],[\"76.25000000\",\"66.39300000\"]]}}"}
{"mode":"v10-framework-compare","workers":4,"sequenceNumber":420,"symbol":"BTCUSDT","exchangeEventTimeMillis":1784430176679,"localReceivedEpochMillis":1784430176669,"topSpreadTicks":-450,"bid5Volume":149,"ask5Volume":103,"bid10Volume":314,"ask10Volume":589,"rawPayload":"{\"stream\":\"btcusdt@depth@100ms\",\"data\":{\"e\":\"depthUpdate\",\"E\":1784430176679,\"s\":\"BTCUSDT\",\"U\":3244441434,\"u\":3244441434,\"b\":[],\"a\":[[\"64914.49000000\",\"0.00000000\"]]}}"}
{"mode":"v10-framework-compare","workers":4,"sequenceNumber":421,"symbol":"BNBUSDT","exchangeEventTimeMillis":1784430176779,"localReceivedEpochMillis":1784430176768,"topSpreadTicks":4,"bid5Volume":5152,"ask5Volume":6689,"bid10Volume":20035,"ask10Volume":257415,"rawPayload":"{\"stream\":\"bnbusdt@depth@100ms\",\"data\":{\"e\":\"depthUpdate\",\"E\":1784430176779,\"s\":\"BNBUSDT\",\"U\":1236331384,\"u\":1236331385,\"b\":[[\"570.41000000\",\"0.00000000\"],[\"570.32000000\",\"1.74200000\"]],\"a\":[[\"570.58000000\",\"1.71100000\"],[\"570.59000000\",\"0.00000000\"]]}}"}
{"mode":"v10-framework-compare","workers":4,"sequenceNumber":422,"symbol":"BTCUSDT","exchangeEventTimeMillis":1784430176779,"localReceivedEpochMillis":1784430176768,"topSpreadTicks":-450,"bid5Volume":149,"ask5Volume":103,"bid10Volume":314,"ask10Volume":589,"rawPayload":"{\"stream\":\"btcusdt@depth@100ms\",\"data\":{\"e\":\"depthUpdate\",\"E\":1784430176779,\"s\":\"BTCUSDT\",\"U\":3244441435,\"u\":3244441436,\"b\":[],\"a\":[[\"64914.49000000\",\"0.00011000\"],[\"81055.16000000\",\"0.00045000\"]]}}"}
{"mode":"v10-framework-compare","workers":4,"sequenceNumber":423,"symbol":"BNBUSDT","exchangeEventTimeMillis":1784430177079,"localReceivedEpochMillis":1784430177068,"topSpreadTicks":4,"bid5Volume":5152,"ask5Volume":6689,"bid10Volume":20035,"ask10Volume":257415,"rawPayload":"{\"stream\":\"bnbusdt@depth@100ms\",\"data\":{\"e\":\"depthUpdate\",\"E\":1784430177079,\"s\":\"BNBUSDT\",\"U\":1236331386,\"u\":1236331387,\"b\":[],\"a\":[[\"570.61000000\",\"0.87600000\"],[\"570.63000000\",\"0.00000000\"]]}}"}
{"mode":"v10-framework-compare","workers":4,"sequenceNumber":424,"symbol":"XRPUSDT","exchangeEventTimeMillis":1784430177079,"localReceivedEpochMillis":1784430177069,"topSpreadTicks":0,"bid5Volume":7224700,"ask5Volume":25657400,"bid10Volume":17503900,"ask10Volume":26863900,"rawPayload":"{\"stream\":\"xrpusdt@depth@100ms\",\"data\":{\"e\":\"depthUpdate\",\"E\":1784430177079,\"s\":\"XRPUSDT\",\"U\":752705554,\"u\":752705559,\"b\":[[\"1.09600000\",\"156.10000000\"],[\"1.09590000\",\"0.00000000\"],[\"1.09570000\",\"2490.00000000\"],[\"1.09550000\",\"2074.70000000\"]],\"a\":[[\"1.09650000\",\"4131.00000000\"],[\"1.09660000\",\"650.10000000\"]]}}"}
{"mode":"v10-framework-compare","workers":4,"sequenceNumber":425,"symbol":"ETHUSDT","exchangeEventTimeMillis":1784430177079,"localReceivedEpochMillis":1784430177069,"topSpreadTicks":-23,"bid5Volume":5071,"ask5Volume":3807,"bid10Volume":10482,"ask10Volume":17287,"rawPayload":"{\"stream\":\"ethusdt@depth@100ms\",\"data\":{\"e\":\"depthUpdate\",\"E\":1784430177079,\"s\":\"ETHUSDT\",\"U\":2806178213,\"u\":2806178213,\"b\":[],\"a\":[[\"1870.76000000\",\"0.13890000\"],[\"1870.79000000\",\"0.00000000\"]]}}"}
{"mode":"v10-framework-compare","workers":4,"sequenceNumber":426,"symbol":"ETHUSDT","exchangeEventTimeMillis":1784430177480,"localReceivedEpochMillis":1784430177469,"topSpreadTicks":-23,"bid5Volume":5071,"ask5Volume":3807,"bid10Volume":10482,"ask10Volume":17287,"rawPayload":"{\"stream\":\"ethusdt@depth@100ms\",\"data\":{\"e\":\"depthUpdate\",\"E\":1784430177480,\"s\":\"ETHUSDT\",\"U\":2806178214,\"u\":2806178214,\"b\":[[\"1837.69000000\",\"0.00000000\"]],\"a\":[]}}"}
{"mode":"v10-framework-compare","workers":4,"sequenceNumber":427,"symbol":"XRPUSDT","exchangeEventTimeMillis":1784430177480,"localReceivedEpochMillis":1784430177469,"topSpreadTicks":1,"bid5Volume":15059000,"ask5Volume":25657400,"bid10Volume":15429200,"ask10Volume":26863900,"rawPayload":"{\"stream\":\"xrpusdt@depth@100ms\",\"data\":{\"e\":\"depthUpdate\",\"E\":1784430177480,\"s\":\"XRPUSDT\",\"U\":752705560,\"u\":752705562,\"b\":[[\"1.09620000\",\"979.40000000\"],[\"1.09610000\",\"3675.60000000\"],[\"1.09560000\",\"0.00000000\"]],\"a\":[]}}"}
{"mode":"v10-framework-compare","workers":4,"sequenceNumber":428,"symbol":"BTCUSDT","exchangeEventTimeMillis":1784430177580,"localReceivedEpochMillis":1784430177568,"topSpreadTicks":-450,"bid5Volume":198,"ask5Volume":103,"bid10Volume":363,"ask10Volume":589,"rawPayload":"{\"stream\":\"btcusdt@depth@100ms\",\"data\":{\"e\":\"depthUpdate\",\"E\":1784430177580,\"s\":\"BTCUSDT\",\"U\":3244441437,\"u\":3244441439,\"b\":[[\"64786.94000000\",\"0.00000000\"],[\"64785.16000000\",\"0.00000000\"]],\"a\":[]}}"}
{"mode":"v10-framework-compare","workers":4,"sequenceNumber":429,"symbol":"ETHUSDT","exchangeEventTimeMillis":1784430177580,"localReceivedEpochMillis":1784430177568,"topSpreadTicks":-23,"bid5Volume":5068,"ask5Volume":3807,"bid10Volume":10479,"ask10Volume":17336,"rawPayload":"{\"stream\":\"ethusdt@depth@100ms\",\"data\":{\"e\":\"depthUpdate\",\"E\":1784430177580,\"s\":\"ETHUSDT\",\"U\":2806178215,\"u\":2806178218,\"b\":[[\"1870.40000000\",\"0.00000000\"],[\"1870.34000000\",\"1.11900000\"]],\"a\":[[\"1870.91000000\",\"1.18580000\"],[\"1870.97000000\",\"0.00000000\"]]}}"}
{"mode":"v10-framework-compare","workers":4,"sequenceNumber":430,"symbol":"XRPUSDT","exchangeEventTimeMillis":1784430177580,"localReceivedEpochMillis":1784430177568,"topSpreadTicks":1,"bid5Volume":15059000,"ask5Volume":30382300,"bid10Volume":15429200,"ask10Volume":31588800,"rawPayload":"{\"stream\":\"xrpusdt@depth@100ms\",\"data\":{\"e\":\"depthUpdate\",\"E\":1784430177580,\"s\":\"XRPUSDT\",\"U\":752705563,\"u\":752705563,\"b\":[],\"a\":[[\"1.09640000\",\"45.30000000\"],[\"1.09650000\",\"5375.00000000\"]]}}"}
{"mode":"v10-framework-compare","workers":4,"sequenceNumber":431,"symbol":"ETHUSDT","exchangeEventTimeMillis":1784430177680,"localReceivedEpochMillis":1784430177669,"topSpreadTicks":-23,"bid5Volume":5114,"ask5Volume":3353,"bid10Volume":10525,"ask10Volume":17336,"rawPayload":"{\"stream\":\"ethusdt@depth@100ms\",\"data\":{\"e\":\"depthUpdate\",\"E\":1784430177680,\"s\":\"ETHUSDT\",\"U\":2806178219,\"u\":2806178222,\"b\":[[\"1870.34000000\",\"0.00000000\"],[\"1870.28000000\",\"1.16580000\"]],\"a\":[[\"1870.86000000\",\"1.18580000\"],[\"1870.91000000\",\"0.00000000\"]]}}"}
{"mode":"v10-framework-compare","workers":4,"sequenceNumber":432,"symbol":"BTCUSDT","exchangeEventTimeMillis":1784430177680,"localReceivedEpochMillis":1784430177669,"topSpreadTicks":-450,"bid5Volume":146,"ask5Volume":103,"bid10Volume":311,"ask10Volume":589,"rawPayload":"{\"stream\":\"btcusdt@depth@100ms\",\"data\":{\"e\":\"depthUpdate\",\"E\":1784430177680,\"s\":\"BTCUSDT\",\"U\":3244441440,\"u\":3244441440,\"b\":[[\"64785.74000000\",\"0.01942000\"]],\"a\":[]}}"}
{"mode":"v10-framework-compare","workers":4,"sequenceNumber":433,"symbol":"ETHUSDT","exchangeEventTimeMillis":1784430177980,"localReceivedEpochMillis":1784430177970,"topSpreadTicks":-23,"bid5Volume":5114,"ask5Volume":3353,"bid10Volume":10525,"ask10Volume":17336,"rawPayload":"{\"stream\":\"ethusdt@depth@100ms\",\"data\":{\"e\":\"depthUpdate\",\"E\":1784430177980,\"s\":\"ETHUSDT\",\"U\":2806178223,\"u\":2806178223,\"b\":[[\"1833.09000000\",\"0.05460000\"]],\"a\":[]}}"}
{"mode":"v10-framework-compare","workers":4,"sequenceNumber":434,"symbol":"BTCUSDT","exchangeEventTimeMillis":1784430178180,"localReceivedEpochMillis":1784430178169,"topSpreadTicks":-450,"bid5Volume":189,"ask5Volume":103,"bid10Volume":311,"ask10Volume":589,"rawPayload":"{\"stream\":\"btcusdt@depth@100ms\",\"data\":{\"e\":\"depthUpdate\",\"E\":1784430178180,\"s\":\"BTCUSDT\",\"U\":3244441441,\"u\":3244441441,\"b\":[[\"64784.01000000\",\"0.00000000\"],[\"64781.10000000\",\"0.02800000\"]],\"a\":[]}}"}
{"mode":"v10-framework-compare","workers":4,"sequenceNumber":435,"symbol":"SOLUSDT","exchangeEventTimeMillis":1784430178280,"localReceivedEpochMillis":1784430178270,"topSpreadTicks":-3,"bid5Volume":218835,"ask5Volume":178374,"bid10Volume":471040,"ask10Volume":1057957,"rawPayload":"{\"stream\":\"solusdt@depth@100ms\",\"data\":{\"e\":\"depthUpdate\",\"E\":1784430178280,\"s\":\"SOLUSDT\",\"U\":1609580152,\"u\":1609580153,\"b\":[],\"a\":[[\"76.24000000\",\"33.47800000\"],[\"76.25000000\",\"81.03400000\"]]}}"}
{"mode":"v10-framework-compare","workers":4,"sequenceNumber":436,"symbol":"ETHUSDT","exchangeEventTimeMillis":1784430178280,"localReceivedEpochMillis":1784430178270,"topSpreadTicks":-23,"bid5Volume":5045,"ask5Volume":3807,"bid10Volume":10456,"ask10Volume":17334,"rawPayload":"{\"stream\":\"ethusdt@depth@100ms\",\"data\":{\"e\":\"depthUpdate\",\"E\":1784430178280,\"s\":\"ETHUSDT\",\"U\":2806178224,\"u\":2806178227,\"b\":[[\"1870.35000000\",\"1.09650000\"],[\"1870.28000000\",\"0.00000000\"]],\"a\":[[\"1870.86000000\",\"0.00000000\"],[\"1870.92000000\",\"1.18340000\"]]}}"}
{"mode":"v10-framework-compare","workers":4,"sequenceNumber":437,"symbol":"SOLUSDT","exchangeEventTimeMillis":1784430178580,"localReceivedEpochMillis":1784430178570,"topSpreadTicks":-3,"bid5Volume":218835,"ask5Volume":192893,"bid10Volume":471040,"ask10Volume":1057835,"rawPayload":"{\"stream\":\"solusdt@depth@100ms\",\"data\":{\"e\":\"depthUpdate\",\"E\":1784430178580,\"s\":\"SOLUSDT\",\"U\":1609580154,\"u\":1609580155,\"b\":[],\"a\":[[\"76.24000000\",\"47.99700000\"],[\"76.25000000\",\"66.39300000\"]]}}"}
{"mode":"v10-framework-compare","workers":4,"sequenceNumber":438,"symbol":"XRPUSDT","exchangeEventTimeMillis":1784430178781,"localReceivedEpochMillis":1784430178770,"topSpreadTicks":1,"bid5Volume":15059000,"ask5Volume":27483100,"bid10Volume":15429200,"ask10Volume":28689600,"rawPayload":"{\"stream\":\"xrpusdt@depth@100ms\",\"data\":{\"e\":\"depthUpdate\",\"E\":1784430178781,\"s\":\"XRPUSDT\",\"U\":752705564,\"u\":752705566,\"b\":[[\"1.09490000\",\"1321.80000000\"],[\"1.09480000\",\"0.00000000\"]],\"a\":[[\"1.09750000\",\"11439.10000000\"],[\"1.09760000\",\"1302.20000000\"],[\"1.09820000\",\"12619.30000000\"],[\"1.09830000\",\"2475.80000000\"]]}}"}
{"mode":"v10-framework-compare","workers":4,"sequenceNumber":439,"symbol":"ETHUSDT","exchangeEventTimeMillis":1784430178881,"localReceivedEpochMillis":1784430178869,"topSpreadTicks":-23,"bid5Volume":5045,"ask5Volume":3807,"bid10Volume":10074,"ask10Volume":17334,"rawPayload":"{\"stream\":\"ethusdt@depth@100ms\",\"data\":{\"e\":\"depthUpdate\",\"E\":1784430178881,\"s\":\"ETHUSDT\",\"U\":2806178228,\"u\":2806178231,\"b\":[[\"1870.12000000\",\"0.00000000\"],[\"1869.98000000\",\"0.13900000\"],[\"1869.82000000\",\"0.00000000\"],[\"1869.68000000\",\"1.47610000\"]],\"a\":[[\"1870.65000000\",\"0.13890000\"],[\"1870.76000000\",\"0.00000000\"],[\"1870.95000000\",\"1.47510000\"],[\"1871.09000000\",\"0.00000000\"]]}}"}
{"mode":"v10-framework-compare","workers":4,"sequenceNumber":440,"symbol":"SOLUSDT","exchangeEventTimeMillis":1784430179081,"localReceivedEpochMillis":1784430179068,"topSpreadTicks":-3,"bid5Volume":218835,"ask5Volume":192893,"bid10Volume":464955,"ask10Volume":1057835,"rawPayload":"{\"stream\":\"solusdt@depth@100ms\",\"data\":{\"e\":\"depthUpdate\",\"E\":1784430179081,\"s\":\"SOLUSDT\",\"U\":1609580156,\"u\":1609580156,\"b\":[[\"76.09000000\",\"3.45300000\"]],\"a\":[]}}"}
{"mode":"v10-framework-compare","workers":4,"sequenceNumber":441,"symbol":"BNBUSDT","exchangeEventTimeMillis":1784430179081,"localReceivedEpochMillis":1784430179070,"topSpreadTicks":4,"bid5Volume":5152,"ask5Volume":6689,"bid10Volume":20035,"ask10Volume":257415,"rawPayload":"{\"stream\":\"bnbusdt@depth@100ms\",\"data\":{\"e\":\"depthUpdate\",\"E\":1784430179081,\"s\":\"BNBUSDT\",\"U\":1236331388,\"u\":1236331389,\"b\":[],\"a\":[[\"570.61000000\",\"0.00000000\"],[\"570.64000000\",\"0.87600000\"]]}}"}
{"mode":"v10-framework-compare","workers":4,"sequenceNumber":442,"symbol":"XRPUSDT","exchangeEventTimeMillis":1784430179081,"localReceivedEpochMillis":1784430179070,"topSpreadTicks":0,"bid5Volume":5317000,"ask5Volume":25501300,"bid10Volume":15596200,"ask10Volume":26707800,"rawPayload":"{\"stream\":\"xrpusdt@depth@100ms\",\"data\":{\"e\":\"depthUpdate\",\"E\":1784430179081,\"s\":\"XRPUSDT\",\"U\":752705567,\"u\":752705569,\"b\":[[\"1.09600000\",\"0.00000000\"],[\"1.09590000\",\"167.00000000\"]],\"a\":[[\"1.09660000\",\"494.00000000\"]]}}"}
{"mode":"v10-framework-compare","workers":4,"sequenceNumber":443,"symbol":"BTCUSDT","exchangeEventTimeMillis":1784430179381,"localReceivedEpochMillis":1784430179371,"topSpreadTicks":-450,"bid5Volume":189,"ask5Volume":103,"bid10Volume":311,"ask10Volume":589,"rawPayload":"{\"stream\":\"btcusdt@depth@100ms\",\"data\":{\"e\":\"depthUpdate\",\"E\":1784430179381,\"s\":\"BTCUSDT\",\"U\":3244441442,\"u\":3244441442,\"b\":[],\"a\":[[\"81055.16000000\",\"0.00060000\"]]}}"}
{"mode":"v10-framework-compare","workers":4,"sequenceNumber":444,"symbol":"SOLUSDT","exchangeEventTimeMillis":1784430179781,"localReceivedEpochMillis":1784430179771,"topSpreadTicks":-3,"bid5Volume":218835,"ask5Volume":192893,"bid10Volume":455447,"ask10Volume":726752,"rawPayload":"{\"stream\":\"solusdt@depth@100ms\",\"data\":{\"e\":\"depthUpdate\",\"E\":1784430179781,\"s\":\"SOLUSDT\",\"U\":1609580157,\"u\":1609580164,\"b\":[[\"76.18000000\",\"39.96200000\"],[\"76.17000000\",\"99.12300000\"],[\"76.12000000\",\"65.72500000\"],[\"76.11000000\",\"18.85900000\"],[\"76.07000000\",\"383.35800000\"],[\"76.06000000\",\"309.19600000\"],[\"76.03000000\",\"467.58200000\"],[\"76.02000000\",\"391.23100000\"]],\"a\":[[\"76.30000000\",\"19.42400000\"],[\"76.31000000\",\"98.94100000\"],[\"76.39000000\",\"325.78300000\"],[\"76.40000000\",\"40.61600000\"],[\"76.48000000\",\"141.90100000\"],[\"76.49000000\",\"0.00000000\"]]}}"}
{"mode":"v10-framework-compare","workers":4,"sequenceNumber":445,"symbol":"ETHUSDT","exchangeEventTimeMillis":1784430179881,"localReceivedEpochMillis":1784430179871,"topSpreadTicks":-23,"bid5Volume":5124,"ask5Volume":3807,"bid10Volume":10153,"ask10Volume":17269,"rawPayload":"{\"stream\":\"ethusdt@depth@100ms\",\"data\":{\"e\":\"depthUpdate\",\"E\":1784430179881,\"s\":\"ETHUSDT\",\"U\":2806178232,\"u\":2806178239,\"b\":[[\"1870.35000000\",\"1.17510000\"],[\"1870.28000000\",\"0.00000000\"]],\"a\":[[\"1870.85000000\",\"0.00000000\"],[\"1870.92000000\",\"1.11820000\"]]}}"}
{"mode":"v10-framework-compare","workers":4,"sequenceNumber":446,"symbol":"ETHUSDT","exchangeEventTimeMillis":1784430179981,"localReceivedEpochMillis":1784430179970,"topSpreadTicks":-23,"bid5Volume":5124,"ask5Volume":3807,"bid10Volume":10153,"ask10Volume":15685,"rawPayload":"{\"stream\":\"ethusdt@depth@100ms\",\"data\":{\"e\":\"depthUpdate\",\"E\":1784430179981,\"s\":\"ETHUSDT\",\"U\":2806178240,\"u\":2806178240,\"b\":[],\"a\":[[\"1870.97000000\",\"0.05580000\"]]}}"}
{"mode":"v10-framework-compare","workers":4,"sequenceNumber":447,"symbol":"XRPUSDT","exchangeEventTimeMillis":1784430179981,"localReceivedEpochMillis":1784430179970,"topSpreadTicks":0,"bid5Volume":6497900,"ask5Volume":25501300,"bid10Volume":16777100,"ask10Volume":26707800,"rawPayload":"{\"stream\":\"xrpusdt@depth@100ms\",\"data\":{\"e\":\"depthUpdate\",\"E\":1784430179981,\"s\":\"XRPUSDT\",\"U\":752705570,\"u\":752705570,\"b\":[[\"1.09610000\",\"2327.70000000\"],[\"1.09600000\",\"1347.90000000\"]],\"a\":[]}}"}
{"mode":"v10-framework-compare","workers":4,"sequenceNumber":448,"symbol":"SOLUSDT","exchangeEventTimeMillis":1784430180081,"localReceivedEpochMillis":1784430180069,"topSpreadTicks":-3,"bid5Volume":218835,"ask5Volume":192893,"bid10Volume":455447,"ask10Volume":726752,"rawPayload":"{\"stream\":\"solusdt@depth@100ms\",\"data\":{\"e\":\"depthUpdate\",\"E\":1784430180081,\"s\":\"SOLUSDT\",\"U\":1609580165,\"u\":1609580165,\"b\":[[\"76.08000000\",\"17.21300000\"]],\"a\":[]}}"}
{"mode":"v10-framework-compare","workers":4,"sequenceNumber":449,"symbol":"XRPUSDT","exchangeEventTimeMillis":1784430180081,"localReceivedEpochMillis":1784430180070,"topSpreadTicks":1,"bid5Volume":15059000,"ask5Volume":32058200,"bid10Volume":15429200,"ask10Volume":33264700,"rawPayload":"{\"stream\":\"xrpusdt@depth@100ms\",\"data\":{\"e\":\"depthUpdate\",\"E\":1784430180081,\"s\":\"XRPUSDT\",\"U\":752705571,\"u\":752705578,\"b\":[[\"1.09600000\",\"1520.30000000\"],[\"1.09590000\",\"237.20000000\"],[\"1.09580000\",\"2402.90000000\"],[\"1.09550000\",\"4594.00000000\"],[\"1.09540000\",\"0.00000000\"],[\"1.09480000\",\"6895.90000000\"],[\"1.09460000\",\"0.00000000\"]],\"a\":[[\"1.09650000\",\"5137.90000000\"],[\"1.09660000\",\"731.10000000\"],[\"1.09690000\",\"0.00000000\"],[\"1.09700000\",\"4590.70000000\"],[\"1.09750000\",\"4559.30000000\"],[\"1.09770000\",\"7050.90000000\"]]}}"}
{"mode":"v10-framework-compare","workers":4,"sequenceNumber":450,"symbol":"BTCUSDT","exchangeEventTimeMillis":1784430180482,"localReceivedEpochMillis":1784430180471,"topSpreadTicks":-450,"bid5Volume":189,"ask5Volume":103,"bid10Volume":311,"ask10Volume":589,"rawPayload":"{\"stream\":\"btcusdt@depth@100ms\",\"data\":{\"e\":\"depthUpdate\",\"E\":1784430180482,\"s\":\"BTCUSDT\",\"U\":3244441443,\"u\":3244441443,\"b\":[],\"a\":[[\"64914.49000000\",\"0.00000000\"]]}}"}
{"mode":"v10-framework-compare","workers":4,"sequenceNumber":451,"symbol":"BTCUSDT","exchangeEventTimeMillis":1784430180582,"localReceivedEpochMillis":1784430180572,"topSpreadTicks":-450,"bid5Volume":189,"ask5Volume":103,"bid10Volume":311,"ask10Volume":589,"rawPayload":"{\"stream\":\"btcusdt@depth@100ms\",\"data\":{\"e\":\"depthUpdate\",\"E\":1784430180582,\"s\":\"BTCUSDT\",\"U\":3244441444,\"u\":3244441444,\"b\":[],\"a\":[[\"64914.49000000\",\"0.00011000\"]]}}"}
{"mode":"v10-framework-compare","workers":4,"sequenceNumber":452,"symbol":"BTCUSDT","exchangeEventTimeMillis":1784430181783,"localReceivedEpochMillis":1784430181772,"topSpreadTicks":-450,"bid5Volume":191,"ask5Volume":103,"bid10Volume":313,"ask10Volume":589,"rawPayload":"{\"stream\":\"btcusdt@depth@100ms\",\"data\":{\"e\":\"depthUpdate\",\"E\":1784430181783,\"s\":\"BTCUSDT\",\"U\":3244441445,\"u\":3244441446,\"b\":[[\"64787.54000000\",\"0.02196000\"],[\"64785.74000000\",\"0.00000000\"]],\"a\":[]}}"}
{"mode":"v10-framework-compare","workers":4,"sequenceNumber":453,"symbol":"BTCUSDT","exchangeEventTimeMillis":1784430182183,"localReceivedEpochMillis":1784430182172,"topSpreadTicks":-450,"bid5Volume":191,"ask5Volume":103,"bid10Volume":313,"ask10Volume":589,"rawPayload":"{\"stream\":\"btcusdt@depth@100ms\",\"data\":{\"e\":\"depthUpdate\",\"E\":1784430182183,\"s\":\"BTCUSDT\",\"U\":3244441447,\"u\":3244441447,\"b\":[],\"a\":[[\"81055.16000000\",\"0.00060000\"]]}}"}
{"mode":"v10-framework-compare","workers":4,"sequenceNumber":454,"symbol":"SOLUSDT","exchangeEventTimeMillis":1784430182283,"localReceivedEpochMillis":1784430182271,"topSpreadTicks":-3,"bid5Volume":218835,"ask5Volume":178374,"bid10Volume":455447,"ask10Volume":726619,"rawPayload":"{\"stream\":\"solusdt@depth@100ms\",\"data\":{\"e\":\"depthUpdate\",\"E\":1784430182283,\"s\":\"SOLUSDT\",\"U\":1609580166,\"u\":1609580167,\"b\":[],\"a\":[[\"76.24000000\",\"33.47800000\"],[\"76.25000000\",\"80.77900000\"]]}}"}
{"mode":"v10-framework-compare","workers":4,"sequenceNumber":455,"symbol":"BTCUSDT","exchangeEventTimeMillis":1784430182283,"localReceivedEpochMillis":1784430182271,"topSpreadTicks":-450,"bid5Volume":191,"ask5Volume":103,"bid10Volume":313,"ask10Volume":589,"rawPayload":"{\"stream\":\"btcusdt@depth@100ms\",\"data\":{\"e\":\"depthUpdate\",\"E\":1784430182283,\"s\":\"BTCUSDT\",\"U\":3244441448,\"u\":3244441448,\"b\":[[\"64783.04000000\",\"0.02800000\"],[\"64781.10000000\",\"0.00000000\"]],\"a\":[]}}"}
{"mode":"v10-framework-compare","workers":4,"sequenceNumber":456,"symbol":"BNBUSDT","exchangeEventTimeMillis":1784430182383,"localReceivedEpochMillis":1784430182373,"topSpreadTicks":4,"bid5Volume":5152,"ask5Volume":6689,"bid10Volume":20035,"ask10Volume":257415,"rawPayload":"{\"stream\":\"bnbusdt@depth@100ms\",\"data\":{\"e\":\"depthUpdate\",\"E\":1784430182383,\"s\":\"BNBUSDT\",\"U\":1236331390,\"u\":1236331397,\"b\":[[\"569.83000000\",\"0.00000000\"],[\"569.78000000\",\"3.22400000\"],[\"569.49000000\",\"0.00000000\"],[\"569.44000000\",\"5.18800000\"],[\"569.15000000\",\"0.00000000\"],[\"569.10000000\",\"8.52500000\"],[\"568.81000000\",\"0.00000000\"],[\"568.76000000\",\"20.05600000\"]],\"a\":[[\"571.16000000\",\"3.33600000\"],[\"571.21000000\",\"0.00000000\"],[\"571.50000000\",\"5.04300000\"],[\"571.56000000\",\"0.00000000\"],[\"571.85000000\",\"8.30100000\"],[\"571.90000000\",\"0.00000000\"],[\"572.19000000\",\"19.20500000\"],[\"572.24000000\",\"0.00000000\"]]}}"}
{"mode":"v10-framework-compare","workers":4,"sequenceNumber":457,"symbol":"XRPUSDT","exchangeEventTimeMillis":1784430182583,"localReceivedEpochMillis":1784430182573,"topSpreadTicks":0,"bid5Volume":5322400,"ask5Volume":32058200,"bid10Volume":15601600,"ask10Volume":33264700,"rawPayload":"{\"stream\":\"xrpusdt@depth@100ms\",\"data\":{\"e\":\"depthUpdate\",\"E\":1784430182583,\"s\":\"XRPUSDT\",\"U\":752705579,\"u\":752705579,\"b\":[[\"1.09610000\",\"3675.60000000\"],[\"1.09600000\",\"172.40000000\"]],\"a\":[]}}"}
{"mode":"v10-framework-compare","workers":4,"sequenceNumber":458,"symbol":"SOLUSDT","exchangeEventTimeMillis":1784430182783,"localReceivedEpochMillis":1784430182771,"topSpreadTicks":-3,"bid5Volume":218835,"ask5Volume":178374,"bid10Volume":455447,"ask10Volume":726619,"rawPayload":"{\"stream\":\"solusdt@depth@100ms\",\"data\":{\"e\":\"depthUpdate\",\"E\":1784430182783,\"s\":\"SOLUSDT\",\"U\":1609580168,\"u\":1609580168,\"b\":[[\"75.93000000\",\"337.56600000\"]],\"a\":[]}}"}
{"mode":"v10-framework-compare","workers":4,"sequenceNumber":459,"symbol":"ETHUSDT","exchangeEventTimeMillis":1784430183083,"localReceivedEpochMillis":1784430183073,"topSpreadTicks":-23,"bid5Volume":5124,"ask5Volume":3807,"bid10Volume":9248,"ask10Volume":15685,"rawPayload":"{\"stream\":\"ethusdt@depth@100ms\",\"data\":{\"e\":\"depthUpdate\",\"E\":1784430183083,\"s\":\"ETHUSDT\",\"U\":2806178241,\"u\":2806178245,\"b\":[[\"1869.88000000\",\"1.63970000\"],[\"1869.81000000\",\"0.98080000\"],[\"1862.89000000\",\"0.00000000\"],[\"1862.88000000\",\"7.21970000\"],[\"1861.53000000\",\"0.00000000\"]],\"a\":[]}}"}
{"mode":"v10-framework-compare","workers":4,"sequenceNumber":460,"symbol":"XRPUSDT","exchangeEventTimeMillis":1784430183083,"localReceivedEpochMillis":1784430183073,"topSpreadTicks":0,"bid5Volume":5322400,"ask5Volume":25920900,"bid10Volume":15601600,"ask10Volume":27127400,"rawPayload":"{\"stream\":\"xrpusdt@depth@100ms\",\"data\":{\"e\":\"depthUpdate\",\"E\":1784430183083,\"s\":\"XRPUSDT\",\"U\":752705580,\"u\":752705580,\"b\":[],\"a\":[[\"1.09660000\",\"913.60000000\"]]}}"}
{"mode":"v10-framework-compare","workers":4,"sequenceNumber":461,"symbol":"ETHUSDT","exchangeEventTimeMillis":1784430183184,"localReceivedEpochMillis":1784430183173,"topSpreadTicks":-23,"bid5Volume":5124,"ask5Volume":3807,"bid10Volume":9248,"ask10Volume":15685,"rawPayload":"{\"stream\":\"ethusdt@depth@100ms\",\"data\":{\"e\":\"depthUpdate\",\"E\":1784430183184,\"s\":\"ETHUSDT\",\"U\":2806178246,\"u\":2806178247,\"b\":[[\"1870.23000000\",\"0.00000000\"],[\"1870.07000000\",\"1.33770000\"]],\"a\":[]}}"}
{"mode":"v10-framework-compare","workers":4,"sequenceNumber":462,"symbol":"XRPUSDT","exchangeEventTimeMillis":1784430183184,"localReceivedEpochMillis":1784430183173,"topSpreadTicks":0,"bid5Volume":9776100,"ask5Volume":25920900,"bid10Volume":20055300,"ask10Volume":27127400,"rawPayload":"{\"stream\":\"xrpusdt@depth@100ms\",\"data\":{\"e\":\"depthUpdate\",\"E\":1784430183184,\"s\":\"XRPUSDT\",\"U\":752705581,\"u\":752705582,\"b\":[[\"1.09620000\",\"0.00000000\"],[\"1.09610000\",\"4626.10000000\"]],\"a\":[]}}"}
{"mode":"v10-framework-compare","workers":4,"sequenceNumber":463,"symbol":"ETHUSDT","exchangeEventTimeMillis":1784430183284,"localReceivedEpochMillis":1784430183273,"topSpreadTicks":-23,"bid5Volume":5124,"ask5Volume":3807,"bid10Volume":9248,"ask10Volume":15685,"rawPayload":"{\"stream\":\"ethusdt@depth@100ms\",\"data\":{\"e\":\"depthUpdate\",\"E\":1784430183284,\"s\":\"ETHUSDT\",\"U\":2806178248,\"u\":2806178248,\"b\":[[\"1861.53000000\",\"9.20570000\"]],\"a\":[]}}"}
{"mode":"v10-framework-compare","workers":4,"sequenceNumber":464,"symbol":"XRPUSDT","exchangeEventTimeMillis":1784430183284,"localReceivedEpochMillis":1784430183273,"topSpreadTicks":0,"bid5Volume":7200100,"ask5Volume":25920900,"bid10Volume":17479300,"ask10Volume":27127400,"rawPayload":"{\"stream\":\"xrpusdt@depth@100ms\",\"data\":{\"e\":\"depthUpdate\",\"E\":1784430183284,\"s\":\"XRPUSDT\",\"U\":752705583,\"u\":752705583,\"b\":[[\"1.09590000\",\"2050.10000000\"]],\"a\":[]}}"}
{"mode":"v10-framework-compare","workers":4,"sequenceNumber":465,"symbol":"SOLUSDT","exchangeEventTimeMillis":1784430183384,"localReceivedEpochMillis":1784430183373,"topSpreadTicks":-3,"bid5Volume":218835,"ask5Volume":192658,"bid10Volume":455447,"ask10Volume":726517,"rawPayload":"{\"stream\":\"solusdt@depth@100ms\",\"data\":{\"e\":\"depthUpdate\",\"E\":1784430183384,\"s\":\"SOLUSDT\",\"U\":1609580169,\"u\":1609580170,\"b\":[],\"a\":[[\"76.24000000\",\"47.76200000\"],[\"76.25000000\",\"66.39300000\"]]}}"}
{"mode":"v10-framework-compare","workers":4,"sequenceNumber":466,"symbol":"BTCUSDT","exchangeEventTimeMillis":1784430183384,"localReceivedEpochMillis":1784430183374,"topSpreadTicks":-318,"bid5Volume":191,"ask5Volume":134,"bid10Volume":313,"ask10Volume":645,"rawPayload":"{\"stream\":\"btcusdt@depth@100ms\",\"data\":{\"e\":\"depthUpdate\",\"E\":1784430183384,\"s\":\"BTCUSDT\",\"U\":3244441449,\"u\":3244441457,\"b\":[[\"64736.13000000\",\"0.00000000\"],[\"64736.03000000\",\"0.05967000\"],[\"64697.24000000\",\"0.00000000\"],[\"64697.14000000\",\"0.08541000\"],[\"64658.35000000\",\"0.00000000\"],[\"64658.25000000\",\"0.18203000\"],[\"64580.58000000\",\"0.00000000\"],[\"64580.47000000\",\"0.40748000\"]],\"a\":[[\"64798.45000000\",\"0.00000000\"],[\"64799.77000000\",\"0.01946000\"],[\"64891.53000000\",\"0.06099000\"],[\"64891.63000000\",\"0.00000000\"],[\"64930.41000000\",\"0.08452000\"],[\"64930.52000000\",\"0.00000000\"],[\"64969.30000000\",\"0.18519000\"],[\"64969.41000000\",\"0.00000000\"],[\"65047.08000000\",\"0.40282000\"],[\"65047.19000000\",\"0.00000000\"]]}}"}
{"mode":"v10-framework-compare","workers":4,"sequenceNumber":467,"symbol":"SOLUSDT","exchangeEventTimeMillis":1784430183484,"localReceivedEpochMillis":1784430183473,"topSpreadTicks":-3,"bid5Volume":215422,"ask5Volume":189247,"bid10Volume":333804,"ask10Volume":919050,"rawPayload":"{\"stream\":\"solusdt@depth@100ms\",\"data\":{\"e\":\"depthUpdate\",\"E\":1784430183484,\"s\":\"SOLUSDT\",\"U\":1609580171,\"u\":1609580171,\"b\":[[\"76.17000000\",\"95.71000000\"],[\"76.15000000\",\"13.13200000\"],[\"76.10000000\",\"0.00000000\"]],\"a\":[[\"76.22000000\",\"62.77200000\"],[\"76.25000000\",\"30.19500000\"],[\"76.31000000\",\"0.00000000\"]]}}"}
{"mode":"v10-framework-compare","workers":4,"sequenceNumber":468,"symbol":"BTCUSDT","exchangeEventTimeMillis":1784430183484,"localReceivedEpochMillis":1784430183473,"topSpreadTicks":-318,"bid5Volume":191,"ask5Volume":134,"bid10Volume":380,"ask10Volume":606,"rawPayload":"{\"stream\":\"btcusdt@depth@100ms\",\"data\":{\"e\":\"depthUpdate\",\"E\":1784430183484,\"s\":\"BTCUSDT\",\"U\":3244441458,\"u\":3244441460,\"b\":[[\"64777.09000000\",\"0.00000000\"],[\"64766.41000000\",\"0.00000000\"],[\"64732.88000000\",\"0.00000000\"]],\"a\":[[\"64798.59000000\",\"0.00000000\"],[\"64810.14000000\",\"0.00000000\"],[\"64845.91000000\",\"0.00000000\"]]}}"}
{"mode":"v10-framework-compare","workers":4,"sequenceNumber":469,"symbol":"ETHUSDT","exchangeEventTimeMillis":1784430183484,"localReceivedEpochMillis":1784430183473,"topSpreadTicks":-23,"bid5Volume":5124,"ask5Volume":4787,"bid10Volume":10202,"ask10Volume":17047,"rawPayload":"{\"stream\":\"ethusdt@depth@100ms\",\"data\":{\"e\":\"depthUpdate\",\"E\":1784430183484,\"s\":\"ETHUSDT\",\"U\":2806178249,\"u\":2806178250,\"b\":[[\"1869.98000000\",\"0.00000000\"],[\"1869.68000000\",\"0.00000000\"],[\"1868.76000000\",\"0.00000000\"]],\"a\":[[\"1870.65000000\",\"0.00000000\"],[\"1870.95000000\",\"0.00000000\"],[\"1872.11000000\",\"0.00000000\"]]}}"}
{"mode":"v10-framework-compare","workers":4,"sequenceNumber":470,"symbol":"XRPUSDT","exchangeEventTimeMillis":1784430183484,"localReceivedEpochMillis":1784430183473,"topSpreadTicks":1,"bid5Volume":15059000,"ask5Volume":25179700,"bid10Volume":15429200,"ask10Volume":26386200,"rawPayload":"{\"stream\":\"xrpusdt@depth@100ms\",\"data\":{\"e\":\"depthUpdate\",\"E\":1784430183484,\"s\":\"XRPUSDT\",\"U\":752705584,\"u\":752705589,\"b\":[[\"1.09590000\",\"1812.90000000\"],[\"1.09550000\",\"2074.70000000\"],[\"1.09480000\",\"0.00000000\"]],\"a\":[[\"1.09660000\",\"676.50000000\"],[\"1.09700000\",\"2074.70000000\"],[\"1.09770000\",\"172.40000000\"]]}}"}
{"mode":"v10-framework-compare","workers":4,"sequenceNumber":471,"symbol":"BTCUSDT","exchangeEventTimeMillis":1784430183584,"localReceivedEpochMillis":1784430183573,"topSpreadTicks":-318,"bid5Volume":191,"ask5Volume":134,"bid10Volume":380,"ask10Volume":606,"rawPayload":"{\"stream\":\"btcusdt@depth@100ms\",\"data\":{\"e\":\"depthUpdate\",\"E\":1784430183584,\"s\":\"BTCUSDT\",\"U\":3244441461,\"u\":3244441461,\"b\":[],\"a\":[[\"80999.45000000\",\"0.00015000\"]]}}"}
{"mode":"v10-framework-compare","workers":4,"sequenceNumber":472,"symbol":"SOLUSDT","exchangeEventTimeMillis":1784430183684,"localReceivedEpochMillis":1784430183673,"topSpreadTicks":-3,"bid5Volume":218835,"ask5Volume":192658,"bid10Volume":455455,"ask10Volume":1057617,"rawPayload":"{\"stream\":\"solusdt@depth@100ms\",\"data\":{\"e\":\"depthUpdate\",\"E\":1784430183684,\"s\":\"SOLUSDT\",\"U\":1609580172,\"u\":1609580177,\"b\":[[\"76.17000000\",\"99.12300000\"],[\"76.15000000\",\"49.37500000\"],[\"76.10000000\",\"99.20800000\"]],\"a\":[[\"76.22000000\",\"66.18300000\"],[\"76.25000000\",\"66.39300000\"],[\"76.30000000\",\"118.38200000\"]]}}"}
{"mode":"v10-framework-compare","workers":4,"sequenceNumber":473,"symbol":"ETHUSDT","exchangeEventTimeMillis":1784430183684,"localReceivedEpochMillis":1784430183673,"topSpreadTicks":-23,"bid5Volume":5124,"ask5Volume":3807,"bid10Volume":9248,"ask10Volume":15685,"rawPayload":"{\"stream\":\"ethusdt@depth@100ms\",\"data\":{\"e\":\"depthUpdate\",\"E\":1784430183684,\"s\":\"ETHUSDT\",\"U\":2806178251,\"u\":2806178256,\"b\":[[\"1869.99000000\",\"0.13900000\"],[\"1869.69000000\",\"5.60850000\"],[\"1868.64000000\",\"9.20450000\"]],\"a\":[[\"1870.65000000\",\"0.13890000\"],[\"1870.95000000\",\"1.47510000\"],[\"1872.00000000\",\"9.18800000\"]]}}"}
{"mode":"v10-framework-compare","workers":4,"sequenceNumber":474,"symbol":"XRPUSDT","exchangeEventTimeMillis":1784430183684,"localReceivedEpochMillis":1784430183673,"topSpreadTicks":0,"bid5Volume":12046000,"ask5Volume":32058200,"bid10Volume":22325200,"ask10Volume":33264700,"rawPayload":"{\"stream\":\"xrpusdt@depth@100ms\",\"data\":{\"e\":\"depthUpdate\",\"E\":1784430183684,\"s\":\"XRPUSDT\",\"U\":752705590,\"u\":752705595,\"b\":[[\"1.09590000\",\"2050.10000000\"],[\"1.09550000\",\"4594.00000000\"],[\"1.09480000\",\"6896.00000000\"]],\"a\":[[\"1.09660000\",\"913.60000000\"],[\"1.09700000\",\"4590.80000000\"],[\"1.09770000\",\"7050.90000000\"]]}}"}
{"mode":"v10-framework-compare","workers":4,"sequenceNumber":475,"symbol":"ETHUSDT","exchangeEventTimeMillis":1784430184184,"localReceivedEpochMillis":1784430184173,"topSpreadTicks":-23,"bid5Volume":5124,"ask5Volume":3807,"bid10Volume":9248,"ask10Volume":15684,"rawPayload":"{\"stream\":\"ethusdt@depth@100ms\",\"data\":{\"e\":\"depthUpdate\",\"E\":1784430184184,\"s\":\"ETHUSDT\",\"U\":2806178257,\"u\":2806178258,\"b\":[],\"a\":[[\"1870.91000000\",\"0.05490000\"],[\"1870.97000000\",\"0.00000000\"]]}}"}
{"mode":"v10-framework-compare","workers":4,"sequenceNumber":476,"symbol":"BTCUSDT","exchangeEventTimeMillis":1784430184284,"localReceivedEpochMillis":1784430184273,"topSpreadTicks":-318,"bid5Volume":191,"ask5Volume":134,"bid10Volume":380,"ask10Volume":606,"rawPayload":"{\"stream\":\"btcusdt@depth@100ms\",\"data\":{\"e\":\"depthUpdate\",\"E\":1784430184284,\"s\":\"BTCUSDT\",\"U\":3244441462,\"u\":3244441462,\"b\":[[\"64677.07000000\",\"0.02197000\"]],\"a\":[]}}"}
{"mode":"v10-framework-compare","workers":4,"sequenceNumber":477,"symbol":"ETHUSDT","exchangeEventTimeMillis":1784430184284,"localReceivedEpochMillis":1784430184274,"topSpreadTicks":-23,"bid5Volume":5124,"ask5Volume":3807,"bid10Volume":9248,"ask10Volume":15684,"rawPayload":"{\"stream\":\"ethusdt@depth@100ms\",\"data\":{\"e\":\"depthUpdate\",\"E\":1784430184284,\"s\":\"ETHUSDT\",\"U\":2806178259,\"u\":2806178259,\"b\":[],\"a\":[[\"1871.12000000\",\"1.06180000\"],[\"1871.15000000\",\"0.00000000\"]]}}"}
{"mode":"v10-framework-compare","workers":4,"sequenceNumber":478,"symbol":"ETHUSDT","exchangeEventTimeMillis":1784430184384,"localReceivedEpochMillis":1784430184374,"topSpreadTicks":-23,"bid5Volume":5426,"ask5Volume":3807,"bid10Volume":9336,"ask10Volume":15684,"rawPayload":"{\"stream\":\"ethusdt@depth@100ms\",\"data\":{\"e\":\"depthUpdate\",\"E\":1784430184384,\"s\":\"ETHUSDT\",\"U\":2806178260,\"u\":2806178260,\"b\":[[\"1870.60000000\",\"1.06800000\"]],\"a\":[]}}"}
{"mode":"v10-framework-compare","workers":4,"sequenceNumber":479,"symbol":"BTCUSDT","exchangeEventTimeMillis":1784430184384,"localReceivedEpochMillis":1784430184374,"topSpreadTicks":-318,"bid5Volume":191,"ask5Volume":134,"bid10Volume":380,"ask10Volume":606,"rawPayload":"{\"stream\":\"btcusdt@depth@100ms\",\"data\":{\"e\":\"depthUpdate\",\"E\":1784430184384,\"s\":\"BTCUSDT\",\"U\":3244441463,\"u\":3244441463,\"b\":[],\"a\":[[\"64914.49000000\",\"0.00000000\"]]}}"}
{"mode":"v10-framework-compare","workers":4,"sequenceNumber":480,"symbol":"BTCUSDT","exchangeEventTimeMillis":1784430184484,"localReceivedEpochMillis":1784430184474,"topSpreadTicks":-436,"bid5Volume":191,"ask5Volume":92,"bid10Volume":380,"ask10Volume":578,"rawPayload":"{\"stream\":\"btcusdt@depth@100ms\",\"data\":{\"e\":\"depthUpdate\",\"E\":1784430184484,\"s\":\"BTCUSDT\",\"U\":3244441464,\"u\":3244441472,\"b\":[[\"64783.04000000\",\"0.00000000\"],[\"64781.10000000\",\"0.02800000\"],[\"64775.90000000\",\"0.00401000\"],[\"64765.53000000\",\"0.04261000\"],[\"64729.25000000\",\"0.26572000\"]],\"a\":[[\"64798.59000000\",\"0.00401000\"],[\"64808.96000000\",\"0.04258000\"],[\"64845.24000000\",\"0.26524000\"],[\"64914.49000000\",\"0.00011000\"],[\"80999.45000000\",\"0.00030000\"],[\"81055.16000000\",\"0.00045000\"]]}}"}
{"mode":"v10-framework-compare","workers":4,"sequenceNumber":481,"symbol":"SOLUSDT","exchangeEventTimeMillis":1784430184584,"localReceivedEpochMillis":1784430184573,"topSpreadTicks":-3,"bid5Volume":218835,"ask5Volume":192658,"bid10Volume":455455,"ask10Volume":1057617,"rawPayload":"{\"stream\":\"solusdt@depth@100ms\",\"data\":{\"e\":\"depthUpdate\",\"E\":1784430184584,\"s\":\"SOLUSDT\",\"U\":1609580178,\"u\":1609580178,\"b\":[],\"a\":[[\"76.22000000\",\"84.81800000\"],[\"76.23000000\",\"20.13000000\"]]}}"}
{"mode":"v10-framework-compare","workers":4,"sequenceNumber":482,"symbol":"ETHUSDT","exchangeEventTimeMillis":1784430184584,"localReceivedEpochMillis":1784430184574,"topSpreadTicks":-23,"bid5Volume":5426,"ask5Volume":3807,"bid10Volume":9336,"ask10Volume":15684,"rawPayload":"{\"stream\":\"ethusdt@depth@100ms\",\"data\":{\"e\":\"depthUpdate\",\"E\":1784430184584,\"s\":\"ETHUSDT\",\"U\":2806178261,\"u\":2806178261,\"b\":[],\"a\":[[\"1870.65000000\",\"0.00000000\"],[\"1870.66000000\",\"0.13890000\"]]}}"}
{"mode":"v10-framework-compare","workers":4,"sequenceNumber":483,"symbol":"SOLUSDT","exchangeEventTimeMillis":1784430184684,"localReceivedEpochMillis":1784430184674,"topSpreadTicks":-3,"bid5Volume":200204,"ask5Volume":159739,"bid10Volume":436824,"ask10Volume":1038097,"rawPayload":"{\"stream\":\"solusdt@depth@100ms\",\"data\":{\"e\":\"depthUpdate\",\"E\":1784430184684,\"s\":\"SOLUSDT\",\"U\":1609580179,\"u\":1609580182,\"b\":[[\"76.19000000\",\"14.35000000\"]],\"a\":[[\"76.22000000\",\"66.18300000\"],[\"76.24000000\",\"33.47800000\"],[\"76.25000000\",\"79.79200000\"]]}}"}
{"mode":"v10-framework-compare","workers":4,"sequenceNumber":484,"symbol":"ETHUSDT","exchangeEventTimeMillis":1784430184685,"localReceivedEpochMillis":1784430184674,"topSpreadTicks":-23,"bid5Volume":5124,"ask5Volume":3807,"bid10Volume":9248,"ask10Volume":16262,"rawPayload":"{\"stream\":\"ethusdt@depth@100ms\",\"data\":{\"e\":\"depthUpdate\",\"E\":1784430184685,\"s\":\"ETHUSDT\",\"U\":2806178262,\"u\":2806178263,\"b\":[[\"1870.60000000\",\"0.00000000\"]],\"a\":[[\"1871.12000000\",\"0.00000000\"]]}}"}
{"mode":"v10-framework-compare","workers":4,"sequenceNumber":485,"symbol":"BNBUSDT","exchangeEventTimeMillis":1784430184685,"localReceivedEpochMillis":1784430184674,"topSpreadTicks":4,"bid5Volume":4364,"ask5Volume":5084,"bid10Volume":26818,"ask10Volume":257496,"rawPayload":"{\"stream\":\"bnbusdt@depth@100ms\",\"data\":{\"e\":\"depthUpdate\",\"E\":1784430184685,\"s\":\"BNBUSDT\",\"U\":1236331398,\"u\":1236331399,\"b\":[[\"570.32000000\",\"0.00000000\"]],\"a\":[[\"570.58000000\",\"0.00000000\"]]}}"}
{"mode":"v10-framework-compare","workers":4,"sequenceNumber":486,"symbol":"BTCUSDT","exchangeEventTimeMillis":1784430184685,"localReceivedEpochMillis":1784430184674,"topSpreadTicks":-436,"bid5Volume":191,"ask5Volume":104,"bid10Volume":356,"ask10Volume":619,"rawPayload":"{\"stream\":\"btcusdt@depth@100ms\",\"data\":{\"e\":\"depthUpdate\",\"E\":1784430184685,\"s\":\"BTCUSDT\",\"U\":3244441473,\"u\":3244441474,\"b\":[[\"64781.10000000\",\"0.00000000\"]],\"a\":[[\"64801.09000000\",\"0.00000000\"]]}}"}
{"mode":"v10-framework-compare","workers":4,"sequenceNumber":487,"symbol":"XRPUSDT","exchangeEventTimeMillis":1784430184685,"localReceivedEpochMillis":1784430184674,"topSpreadTicks":0,"bid5Volume":8428200,"ask5Volume":28901200,"bid10Volume":18707400,"ask10Volume":30107700,"rawPayload":"{\"stream\":\"xrpusdt@depth@100ms\",\"data\":{\"e\":\"depthUpdate\",\"E\":1784430184685,\"s\":\"XRPUSDT\",\"U\":752705596,\"u\":752705597,\"b\":[[\"1.09610000\",\"3278.20000000\"]],\"a\":[[\"1.09650000\",\"3893.90000000\"]]}}"}
{"mode":"v10-framework-compare","workers":4,"sequenceNumber":488,"symbol":"ETHUSDT","exchangeEventTimeMillis":1784430184785,"localReceivedEpochMillis":1784430184773,"topSpreadTicks":-23,"bid5Volume":5058,"ask5Volume":3313,"bid10Volume":9182,"ask10Volume":16289,"rawPayload":"{\"stream\":\"ethusdt@depth@100ms\",\"data\":{\"e\":\"depthUpdate\",\"E\":1784430184785,\"s\":\"ETHUSDT\",\"U\":2806178264,\"u\":2806178267,\"b\":[[\"1870.35000000\",\"0.00000000\"],[\"1870.28000000\",\"1.10930000\"]],\"a\":[[\"1870.85000000\",\"1.14580000\"],[\"1870.92000000\",\"0.00000000\"]]}}"}
{"mode":"v10-framework-compare","workers":4,"sequenceNumber":489,"symbol":"SOLUSDT","exchangeEventTimeMillis":1784430185085,"localReceivedEpochMillis":1784430185074,"topSpreadTicks":-3,"bid5Volume":200204,"ask5Volume":174036,"bid10Volume":436824,"ask10Volume":1038995,"rawPayload":"{\"stream\":\"solusdt@depth@100ms\",\"data\":{\"e\":\"depthUpdate\",\"E\":1784430185085,\"s\":\"SOLUSDT\",\"U\":1609580183,\"u\":1609580184,\"b\":[],\"a\":[[\"76.24000000\",\"47.77500000\"],[\"76.25000000\",\"66.39300000\"]]}}"}
{"mode":"v10-framework-compare","workers":4,"sequenceNumber":490,"symbol":"SOLUSDT","exchangeEventTimeMillis":1784430185185,"localReceivedEpochMillis":1784430185173,"topSpreadTicks":-3,"bid5Volume":200204,"ask5Volume":159739,"bid10Volume":436824,"ask10Volume":1039351,"rawPayload":"{\"stream\":\"solusdt@depth@100ms\",\"data\":{\"e\":\"depthUpdate\",\"E\":1784430185185,\"s\":\"SOLUSDT\",\"U\":1609580185,\"u\":1609580186,\"b\":[],\"a\":[[\"76.24000000\",\"33.47800000\"],[\"76.25000000\",\"81.04600000\"]]}}"}
{"mode":"v10-framework-compare","workers":4,"sequenceNumber":491,"symbol":"XRPUSDT","exchangeEventTimeMillis":1784430185285,"localReceivedEpochMillis":1784430185274,"topSpreadTicks":0,"bid5Volume":18006200,"ask5Volume":47645100,"bid10Volume":28285400,"ask10Volume":48851600,"rawPayload":"{\"stream\":\"xrpusdt@depth@100ms\",\"data\":{\"e\":\"depthUpdate\",\"E\":1784430185285,\"s\":\"XRPUSDT\",\"U\":752705598,\"u\":752705612,\"b\":[[\"1.09620000\",\"3233.60000000\"],[\"1.09610000\",\"227.80000000\"],[\"1.09600000\",\"0.00000000\"],[\"1.09500000\",\"547.50000000\"],[\"1.09450000\",\"12856.20000000\"]],\"a\":[[\"1.09660000\",\"237.10000000\"],[\"1.09670000\",\"332.50000000\"],[\"1.09680000\",\"3201.30000000\"],[\"1.09870000\",\"12653.00000000\"],[\"1.09930000\",\"22637.80000000\"]]}}"}
{"mode":"v10-framework-compare","workers":4,"sequenceNumber":492,"symbol":"ETHUSDT","exchangeEventTimeMillis":1784430185385,"localReceivedEpochMillis":1784430185375,"topSpreadTicks":-23,"bid5Volume":5058,"ask5Volume":3313,"bid10Volume":9182,"ask10Volume":16289,"rawPayload":"{\"stream\":\"ethusdt@depth@100ms\",\"data\":{\"e\":\"depthUpdate\",\"E\":1784430185385,\"s\":\"ETHUSDT\",\"U\":2806178268,\"u\":2806178273,\"b\":[[\"1868.49000000\",\"0.00000000\"],[\"1868.47000000\",\"7.36480000\"],[\"1867.36000000\",\"0.00000000\"],[\"1867.35000000\",\"3.06430000\"],[\"1866.24000000\",\"0.00000000\"],[\"1866.23000000\",\"6.29250000\"],[\"1864.00000000\",\"0.00000000\"],[\"1863.98000000\",\"13.86920000\"]],\"a\":[[\"1872.97000000\",\"1.97600000\"],[\"1872.98000000\",\"0.00000000\"],[\"1875.21000000\",\"6.19570000\"],[\"1875.23000000\",\"0.00000000\"]]}}"}
{"mode":"v10-framework-compare","workers":4,"sequenceNumber":493,"symbol":"XRPUSDT","exchangeEventTimeMillis":1784430185385,"localReceivedEpochMillis":1784430185375,"topSpreadTicks":0,"bid5Volume":41820900,"ask5Volume":16355200,"bid10Volume":52100100,"ask10Volume":17561700,"rawPayload":"{\"stream\":\"xrpusdt@depth@100ms\",\"data\":{\"e\":\"depthUpdate\",\"E\":1784430185385,\"s\":\"XRPUSDT\",\"U\":752705613,\"u\":752705623,\"b\":[[\"1.09610000\",\"182.50000000\"],[\"1.09460000\",\"12693.90000000\"],[\"1.09150000\",\"36670.90000000\"]],\"a\":[[\"1.09640000\",\"0.00000000\"],[\"1.09650000\",\"0.00000000\"],[\"1.09660000\",\"2518.50000000\"],[\"1.09670000\",\"1944.80000000\"],[\"1.09700000\",\"5084.80000000\"],[\"1.09800000\",\"154.40000000\"],[\"1.10040000\",\"15894.10000000\"]]}}"}
{"mode":"v10-framework-compare","workers":4,"sequenceNumber":494,"symbol":"XRPUSDT","exchangeEventTimeMillis":1784430185485,"localReceivedEpochMillis":1784430185484,"topSpreadTicks":0,"bid5Volume":7397900,"ask5Volume":16246000,"bid10Volume":17677100,"ask10Volume":17452500,"rawPayload":"{\"stream\":\"xrpusdt@depth@100ms\",\"data\":{\"e\":\"depthUpdate\",\"E\":1784430185485,\"s\":\"XRPUSDT\",\"U\":752705624,\"u\":752705627,\"b\":[[\"1.09620000\",\"3279.10000000\"],[\"1.09610000\",\"407.50000000\"],[\"1.09580000\",\"2247.90000000\"]],\"a\":[[\"1.09650000\",\"45.20000000\"]]}}"}
{"mode":"v10-framework-compare","workers":4,"sequenceNumber":495,"symbol":"SOLUSDT","exchangeEventTimeMillis":1784430185585,"localReceivedEpochMillis":1784430185574,"topSpreadTicks":-3,"bid5Volume":200204,"ask5Volume":173932,"bid10Volume":436824,"ask10Volume":1038891,"rawPayload":"{\"stream\":\"solusdt@depth@100ms\",\"data\":{\"e\":\"depthUpdate\",\"E\":1784430185585,\"s\":\"SOLUSDT\",\"U\":1609580187,\"u\":1609580188,\"b\":[],\"a\":[[\"76.24000000\",\"47.67100000\"],[\"76.25000000\",\"66.39300000\"]]}}"}
{"mode":"v10-framework-compare","workers":4,"sequenceNumber":496,"symbol":"SOLUSDT","exchangeEventTimeMillis":1784430185685,"localReceivedEpochMillis":1784430185675,"topSpreadTicks":-3,"bid5Volume":200204,"ask5Volume":159739,"bid10Volume":436824,"ask10Volume":1038129,"rawPayload":"{\"stream\":\"solusdt@depth@100ms\",\"data\":{\"e\":\"depthUpdate\",\"E\":1784430185685,\"s\":\"SOLUSDT\",\"U\":1609580189,\"u\":1609580190,\"b\":[],\"a\":[[\"76.24000000\",\"33.47800000\"],[\"76.25000000\",\"79.82400000\"]]}}"}
{"mode":"v10-framework-compare","workers":4,"sequenceNumber":497,"symbol":"BTCUSDT","exchangeEventTimeMillis":1784430185985,"localReceivedEpochMillis":1784430185975,"topSpreadTicks":-436,"bid5Volume":194,"ask5Volume":104,"bid10Volume":359,"ask10Volume":619,"rawPayload":"{\"stream\":\"btcusdt@depth@100ms\",\"data\":{\"e\":\"depthUpdate\",\"E\":1784430185985,\"s\":\"BTCUSDT\",\"U\":3244441475,\"u\":3244441476,\"b\":[[\"64789.37000000\",\"0.02486000\"],[\"64787.54000000\",\"0.00000000\"]],\"a\":[]}}"}
{"mode":"v10-framework-compare","workers":4,"sequenceNumber":498,"symbol":"SOLUSDT","exchangeEventTimeMillis":1784430186085,"localReceivedEpochMillis":1784430186074,"topSpreadTicks":-3,"bid5Volume":200204,"ask5Volume":173272,"bid10Volume":436824,"ask10Volume":1038231,"rawPayload":"{\"stream\":\"solusdt@depth@100ms\",\"data\":{\"e\":\"depthUpdate\",\"E\":1784430186085,\"s\":\"SOLUSDT\",\"U\":1609580191,\"u\":1609580192,\"b\":[],\"a\":[[\"76.24000000\",\"47.01100000\"],[\"76.25000000\",\"66.39300000\"]]}}"}
{"mode":"v10-framework-compare","workers":4,"sequenceNumber":499,"symbol":"BNBUSDT","exchangeEventTimeMillis":1784430186085,"localReceivedEpochMillis":1784430186074,"topSpreadTicks":4,"bid5Volume":4176,"ask5Volume":251607,"bid10Volume":31183,"ask10Volume":259920,"rawPayload":"{\"stream\":\"bnbusdt@depth@100ms\",\"data\":{\"e\":\"depthUpdate\",\"E\":1784430186085,\"s\":\"BNBUSDT\",\"U\":1236331400,\"u\":1236331401,\"b\":[[\"570.29000000\",\"0.00000000\"]],\"a\":[[\"570.70000000\",\"0.00000000\"]]}}"}
{"mode":"v10-framework-compare","workers":4,"sequenceNumber":500,"symbol":"SOLUSDT","exchangeEventTimeMillis":1784430186185,"localReceivedEpochMillis":1784430186175,"topSpreadTicks":-3,"bid5Volume":200204,"ask5Volume":159739,"bid10Volume":436824,"ask10Volume":1039316,"rawPayload":"{\"stream\":\"solusdt@depth@100ms\",\"data\":{\"e\":\"depthUpdate\",\"E\":1784430186185,\"s\":\"SOLUSDT\",\"U\":1609580193,\"u\":1609580194,\"b\":[],\"a\":[[\"76.24000000\",\"33.47800000\"],[\"76.25000000\",\"81.01100000\"]]}}"}
